# Ancient Warfare Structure Template File
# Auto-generated structure template file. created on: 12/12/2023 at: 11:46:49
# Lines beginning with # denote comments

header:
version=2.11
name=SarkonidTownGenMainOasis
mods=
size=15,17,22
offset=8,5,21
:endheader

#### VALIDATION ####
validation:
type=ground
structureAuthor=TheOddlySeagull
survival=false
worldGenEnabled=false
unique=false
preserveBlocks=false
preventNaturalHostileSpawns=true
selectionWeight=1
clusterValue=1
minDuplicateDistance=1
dimensionWhiteList=true
dimensionList=
biomeGroupList=
biomeWhiteList=true
biomeList=
leveling=0
fill=0
border=0
blockSwap=false
territoryName=
biomeReplacement=minecraft:
minGenerationHeight=0
maxGenerationHeight=255
:endvalidation

#### LAYERS ####
layer: 0
1,1,1,1,1,1,1,1,1,1,1,1,1,1,1
1,1,1,1,1,1,1,1,1,1,1,1,1,1,1
1,1,1,1,1,1,1,1,1,1,1,1,1,1,1
1,1,1,1,1,1,1,1,1,1,1,1,1,1,1
1,1,1,1,1,1,1,1,1,1,1,1,1,1,1
1,1,1,1,1,1,1,1,1,1,1,1,1,1,1
1,1,1,1,1,1,1,1,1,1,1,1,1,1,1
1,1,1,1,1,1,1,1,1,1,1,1,1,1,1
1,1,1,1,1,1,1,1,1,1,1,1,1,1,1
1,1,1,1,1,1,1,1,1,1,1,1,1,1,1
1,1,1,1,1,1,1,1,1,1,1,1,1,1,1
1,1,1,1,1,1,1,1,1,1,1,1,1,1,1
1,1,1,1,1,1,1,1,1,1,1,1,1,1,1
1,1,1,1,1,1,1,1,1,1,1,1,1,1,1
1,1,1,1,1,1,1,1,1,1,1,1,1,1,1
1,1,1,1,1,1,1,1,1,1,1,1,1,1,1
1,1,1,1,1,1,1,1,1,1,1,1,1,1,1
1,1,1,1,1,1,1,1,1,1,1,1,1,1,1
1,1,1,1,1,1,1,1,1,1,1,1,1,1,1
1,1,1,1,1,1,1,1,1,1,1,1,1,1,1
1,1,1,1,1,1,1,1,1,1,1,1,1,1,1
1,1,1,1,1,1,1,1,1,1,1,1,1,1,1
:endlayer
layer: 1
1,1,3,1,1,2,2,1,1,1,1,1,1,1,2
3,3,3,2,1,3,3,2,2,1,3,3,2,1,2
2,3,1,3,2,3,2,3,1,2,2,3,3,2,1
3,1,1,2,1,2,3,1,3,1,1,2,3,2,1
1,1,2,2,2,3,2,2,1,2,1,2,2,3,3
1,2,2,3,2,1,3,3,3,1,2,3,2,1,1
3,1,1,1,3,3,1,1,3,2,2,3,3,3,3
1,3,2,2,2,3,1,1,2,2,3,2,1,3,2
2,2,1,2,1,1,3,3,1,2,3,2,1,2,2
2,1,3,2,2,3,1,2,1,1,2,3,1,3,2
2,1,2,1,1,2,2,2,3,2,3,1,2,1,3
2,1,3,1,1,2,3,3,2,2,1,1,3,2,2
3,3,2,2,1,1,3,3,1,2,1,1,2,3,3
1,3,1,2,2,3,3,1,3,2,3,1,3,3,3
2,2,1,3,2,1,2,3,1,3,3,1,1,3,2
2,1,1,1,1,2,3,3,3,2,1,1,2,1,2
2,2,3,3,3,2,3,1,2,2,2,3,2,2,1
3,3,1,3,2,2,2,1,1,1,3,1,2,2,3
2,1,1,1,1,3,1,1,3,3,2,1,1,2,3
1,3,3,2,2,2,3,3,3,3,3,2,1,2,1
3,2,3,2,2,2,3,3,2,1,3,2,2,1,3
2,3,1,2,3,3,2,3,3,1,1,1,3,2,1
:endlayer
layer: 2
1,2,2,1,2,1,2,2,3,2,1,3,1,3,3
1,1,2,2,2,2,2,3,2,3,3,2,1,3,1
3,3,3,3,2,2,3,2,2,3,2,1,1,1,1
1,3,1,1,2,3,2,2,3,3,3,2,2,1,3
2,3,1,1,3,2,2,3,1,2,3,1,3,3,2
3,2,3,3,2,3,1,2,1,3,1,1,2,3,1
2,3,1,2,2,2,5,4,1,2,2,1,3,1,2
1,2,2,2,3,4,4,4,3,2,1,3,3,2,2
3,1,1,1,3,4,4,4,4,3,2,1,3,3,2
1,1,2,1,1,4,4,4,4,3,1,1,3,3,3
3,2,3,1,2,1,4,5,4,3,3,1,2,2,2
3,3,1,2,3,3,3,4,4,1,3,2,1,3,1
1,1,3,3,1,3,2,4,4,4,1,3,1,2,1
2,1,3,1,1,1,2,4,4,4,1,3,3,2,3
3,1,3,2,2,2,1,1,1,2,1,3,1,3,1
2,3,1,3,3,2,2,3,1,2,1,3,2,1,3
1,2,2,2,1,3,3,1,3,3,2,2,2,3,3
3,1,2,3,1,1,1,3,1,2,2,3,2,3,3
1,1,3,3,3,3,2,3,2,2,2,3,1,2,2
1,2,1,2,2,1,1,3,3,1,1,2,3,3,3
1,1,1,3,3,1,3,1,1,3,2,2,3,3,1
3,2,3,2,2,2,1,2,3,1,1,1,2,2,1
:endlayer
layer: 3
2,1,1,2,2,1,1,1,1,2,2,3,2,1,2
1,2,1,2,3,1,1,2,1,3,2,1,2,2,3
3,1,2,2,2,1,3,2,3,3,3,2,3,1,2
2,2,1,1,5,4,4,3,1,1,1,3,2,3,2
2,2,2,4,4,4,4,4,4,1,2,3,1,3,2
2,3,1,4,4,4,4,4,4,4,4,1,1,2,1
1,2,3,4,4,5,4,4,4,4,5,4,2,1,2
3,1,1,3,4,4,4,4,4,4,4,4,1,3,3
3,1,2,2,4,4,4,4,4,4,4,1,2,1,2
3,2,3,4,4,4,4,4,4,4,1,3,3,2,3
1,3,1,4,4,4,4,4,4,4,4,3,1,2,3
2,3,3,4,4,4,4,4,4,4,4,4,1,1,2
1,3,3,3,4,4,4,4,4,4,4,4,2,2,3
3,3,2,2,4,4,4,4,4,4,4,4,3,1,3
2,2,1,3,4,4,4,4,4,5,4,3,1,3,1
3,3,1,1,4,4,4,4,4,4,4,3,1,3,2
3,2,2,3,1,4,4,4,4,4,4,1,2,2,1
2,1,1,2,1,1,5,4,4,4,4,2,1,2,3
2,3,2,3,1,3,3,4,4,4,2,2,2,2,1
1,1,3,3,2,2,2,2,1,3,3,1,1,2,3
2,2,1,1,3,1,3,3,1,3,1,1,2,2,2
3,1,2,2,1,1,2,3,3,1,1,3,3,1,1
:endlayer
layer: 4
3,3,2,6,2,6,6,2,6,6,3,2,3,3,3
3,3,6,3,6,4,4,4,3,6,6,3,3,2,2
3,6,8,4,4,4,4,4,4,4,6,6,6,3,3
3,6,4,4,4,4,4,4,4,4,4,4,6,6,6
2,6,4,4,4,4,4,4,4,4,4,4,5,6,2
6,6,4,4,4,4,4,4,4,4,4,4,4,4,6
6,4,4,4,4,4,4,4,4,4,4,4,4,4,6
3,4,4,4,4,4,4,4,4,4,4,4,4,4,6
6,4,4,4,4,4,4,4,4,4,4,4,4,6,6
3,3,4,4,4,4,4,4,4,4,4,4,4,8,3
6,8,4,4,4,4,4,4,4,4,4,4,4,6,6
3,6,4,4,4,4,4,4,4,4,4,4,4,3,2
2,3,5,4,4,4,4,4,4,4,4,4,4,6,6
6,6,6,4,4,4,4,4,4,4,4,4,4,6,6
6,3,6,4,4,4,4,4,4,4,4,4,4,2,3
3,6,6,4,4,4,4,4,4,4,4,4,4,2,2
6,6,6,4,4,4,4,4,4,4,4,4,4,6,3
6,6,2,4,4,4,4,4,4,4,4,4,4,6,6
2,3,3,6,4,4,4,4,4,4,4,4,3,6,2
3,6,6,7,6,4,4,4,4,4,6,6,7,6,3
3,2,6,6,6,6,4,4,4,3,3,6,6,3,3
3,3,3,6,2,6,6,6,3,6,2,3,3,2,3
:endlayer
layer: 5
0,0,0,12,0,12,12,0,0,12,0,0,0,0,0
0,0,12,0,12,0,0,0,16,16,16,0,19,0,0
0,12,8,0,0,0,0,0,0,0,12,12,19,19,0
0,13,0,0,0,0,0,0,0,0,0,0,0,12,12
0,12,0,0,0,0,0,0,0,0,0,0,0,12,0
12,0,0,0,0,0,0,0,0,0,0,0,0,0,18
20,0,0,0,0,0,0,0,0,0,0,0,0,0,12
20,0,0,0,0,0,0,0,0,0,0,0,0,0,12
20,0,0,0,0,0,0,0,0,0,0,0,0,12,12
0,0,0,0,0,0,0,0,0,0,0,0,0,8,0
12,8,0,0,0,0,0,0,0,0,0,0,0,12,12
0,12,0,0,0,0,0,0,0,0,0,0,0,20,0
0,5,0,0,0,0,0,0,0,0,0,0,0,20,12
13,12,0,0,0,0,0,0,0,0,0,0,0,20,12
12,19,12,0,0,0,0,0,0,0,0,0,0,0,0
0,19,19,0,0,0,0,0,0,0,0,0,0,0,0
12,19,12,0,0,0,0,0,0,0,0,0,0,16,0
18,12,0,0,0,0,9,15,15,9,0,0,0,17,12
0,5,0,12,0,0,0,15,15,0,0,0,0,16,0
0,0,12,8,12,0,9,15,15,9,12,12,8,12,0
0,0,12,12,12,12,0,14,14,0,0,13,12,0,0
0,0,0,12,0,11,9,10,10,9,0,0,0,0,0
:endlayer
layer: 6
0,0,0,0,0,0,0,0,0,0,0,0,0,0,0
0,0,0,0,0,0,0,0,0,0,0,0,19,0,0
0,0,8,0,0,0,0,0,0,0,0,0,19,0,0
0,0,0,0,0,0,0,0,0,0,0,0,0,0,0
0,0,0,0,0,0,0,0,0,0,0,0,0,0,0
0,0,0,0,0,0,0,0,0,0,0,0,0,0,0
0,0,0,0,0,0,0,0,0,0,0,0,0,0,0
0,0,0,0,0,0,0,0,0,0,0,0,0,0,0
0,0,0,0,0,0,0,0,0,0,0,0,0,0,0
0,0,0,0,0,0,0,0,0,0,0,0,0,8,0
0,8,0,0,0,0,0,0,0,0,0,0,0,0,0
0,0,0,0,0,0,0,0,0,0,0,0,0,0,0
0,0,0,0,0,0,0,0,0,0,0,0,0,0,0
0,0,0,0,0,0,0,0,0,0,0,0,0,0,0
0,19,0,0,0,0,0,0,0,0,0,0,0,0,0
0,19,0,0,0,0,0,0,0,0,0,0,0,0,0
0,0,0,0,0,0,0,0,0,0,0,0,0,0,0
0,0,0,0,0,0,9,0,0,9,0,0,0,0,0
0,0,0,0,0,0,9,0,0,9,0,0,0,0,0
0,0,0,8,0,0,9,0,0,9,0,0,8,0,0
0,0,0,0,0,0,9,0,0,9,0,0,0,0,0
0,0,0,0,0,0,9,0,0,9,0,0,0,0,0
:endlayer
layer: 7
0,0,0,0,0,0,0,0,0,0,0,0,0,0,0
0,0,0,0,0,0,0,0,0,0,0,0,0,0,0
0,0,8,0,0,0,0,0,0,0,0,0,19,0,0
0,0,0,0,0,0,0,0,0,0,0,0,0,0,0
0,0,0,0,0,0,0,0,0,0,0,0,0,0,0
0,0,0,0,0,0,0,0,0,0,0,0,0,0,0
0,0,0,0,0,0,0,0,0,0,0,0,0,0,0
0,0,0,0,0,0,0,0,0,0,0,0,0,0,0
0,0,0,0,0,0,0,0,0,0,0,0,0,0,0
0,0,0,0,0,0,0,0,0,0,0,0,8,0,0
0,8,0,0,0,0,0,0,0,0,0,0,0,0,0
0,0,0,0,0,0,0,0,0,0,0,0,0,0,0
0,0,0,0,0,0,0,0,0,0,0,0,0,0,0
0,0,0,0,0,0,0,0,0,0,0,0,0,0,0
0,0,0,0,0,0,0,0,0,0,0,0,0,0,0
0,19,0,0,0,0,0,0,0,0,0,0,0,0,0
0,0,0,0,0,0,0,0,0,0,0,0,0,0,0
0,0,0,0,0,0,0,0,0,0,0,0,0,0,0
0,0,0,0,0,0,0,0,0,0,0,0,0,0,0
0,0,0,8,0,0,0,0,0,0,0,0,8,0,0
0,0,0,0,0,0,0,0,0,0,0,0,0,0,0
0,0,0,0,0,0,0,0,0,0,0,0,0,0,0
:endlayer
layer: 8
0,0,0,0,0,0,0,0,0,0,0,0,0,0,0
0,0,0,0,0,0,0,0,0,0,0,0,0,0,0
0,0,0,8,0,0,0,0,0,0,0,0,0,0,0
0,0,0,0,0,0,0,0,0,0,0,0,0,0,0
0,0,0,0,0,0,0,0,0,0,0,0,0,0,0
0,0,0,0,0,0,0,0,0,0,0,0,0,0,0
0,0,0,0,0,0,0,0,0,0,0,0,0,0,0
0,0,0,0,0,0,0,0,0,0,0,0,0,0,0
0,0,0,0,0,0,0,0,0,0,0,0,0,0,0
0,0,0,0,0,0,0,0,0,0,0,0,8,0,0
0,0,8,0,0,0,0,0,0,0,0,0,0,0,0
0,0,0,0,0,0,0,0,0,0,0,0,0,0,0
0,0,0,0,0,0,0,0,0,0,0,0,0,0,0
0,0,0,0,0,0,0,0,0,0,0,0,0,0,0
0,0,0,0,0,0,0,0,0,0,0,0,0,0,0
0,0,0,0,0,0,0,0,0,0,0,0,0,0,0
0,0,0,0,0,0,0,0,0,0,0,0,0,0,0
0,0,0,0,0,0,0,0,0,0,0,0,0,0,0
0,0,0,8,0,0,0,0,0,0,0,0,8,0,0
0,0,0,0,0,0,0,0,0,0,0,0,0,0,0
0,0,0,0,0,0,0,0,0,0,0,0,0,0,0
0,0,0,0,0,0,0,0,0,0,0,0,0,0,0
:endlayer
layer: 9
0,0,0,0,0,0,0,0,0,0,0,0,0,0,0
0,0,0,0,0,0,0,0,0,0,0,0,0,0,0
0,0,0,8,0,0,0,0,0,0,0,0,0,0,0
0,0,0,0,0,0,0,0,0,0,0,0,0,0,0
0,0,0,0,0,0,0,0,0,0,0,0,0,0,0
0,0,0,0,0,0,0,0,0,0,0,0,0,0,0
0,0,0,0,0,0,0,0,0,0,0,0,0,0,0
0,0,0,0,0,0,0,0,0,0,0,0,0,0,0
0,0,0,0,0,0,0,0,0,0,0,0,0,0,0
0,0,0,0,0,0,0,0,0,0,0,0,8,0,0
0,0,8,0,0,0,0,0,0,0,0,0,0,0,0
0,0,0,0,0,0,0,0,0,0,0,0,0,0,0
0,0,0,0,0,0,0,0,0,0,0,0,0,0,0
0,0,0,0,0,0,0,0,0,0,0,0,0,0,0
0,0,0,0,0,0,0,0,0,0,0,0,0,0,0
0,0,0,0,0,0,0,0,0,0,0,0,0,0,0
0,0,0,0,0,0,0,0,0,0,0,0,0,0,0
0,0,0,0,0,0,0,0,0,0,0,0,0,0,0
0,0,0,8,0,0,0,0,0,0,0,0,8,0,0
0,0,0,0,0,0,0,0,0,0,0,0,0,0,0
0,0,0,0,0,0,0,0,0,0,0,0,0,0,0
0,0,0,0,0,0,0,0,0,0,0,0,0,0,0
:endlayer
layer: 10
0,0,0,0,0,0,0,0,0,0,0,0,0,0,0
0,0,0,0,0,0,0,0,0,0,0,0,0,0,0
0,0,0,8,0,0,0,0,0,0,0,0,0,0,0
0,0,0,0,0,0,0,0,0,0,0,0,0,0,0
0,0,0,0,0,0,0,0,0,0,0,0,0,0,0
0,0,0,0,0,0,0,0,0,0,0,0,0,0,0
0,0,0,0,0,0,0,0,0,0,0,0,0,0,0
0,0,0,0,0,0,0,0,0,0,0,0,0,0,0
0,0,19,0,0,0,0,0,0,0,0,0,0,0,0
0,0,0,0,0,0,0,0,0,0,0,8,0,0,0
19,0,8,0,19,0,0,0,0,0,0,0,0,0,0
0,0,0,0,0,0,0,0,0,0,0,0,0,0,0
0,0,19,0,0,0,0,0,0,0,0,0,0,0,0
0,0,0,0,0,0,0,0,0,0,0,0,0,0,0
0,0,0,0,0,0,0,0,0,0,0,0,0,0,0
0,0,0,0,0,0,0,0,0,0,0,0,0,0,0
0,0,0,0,0,0,0,0,0,0,0,0,0,0,0
0,0,0,0,0,0,0,0,0,0,0,0,0,0,0
0,0,0,8,0,0,0,0,0,0,0,0,8,0,0
0,0,0,0,0,0,0,0,0,0,0,0,0,0,0
0,0,0,0,0,0,0,0,0,0,0,0,0,0,0
0,0,0,0,0,0,0,0,0,0,0,0,0,0,0
:endlayer
layer: 11
0,0,0,0,0,0,0,0,0,0,0,0,0,0,0
0,0,0,0,0,0,0,0,0,0,0,0,0,0,0
0,0,0,0,0,0,0,0,0,0,0,0,0,0,0
0,0,0,8,0,0,0,0,0,0,0,0,0,0,0
0,0,0,0,0,0,0,0,0,0,0,0,0,0,0
0,0,0,0,0,0,0,0,0,0,0,0,0,0,0
0,0,0,0,0,0,0,0,0,0,0,0,0,0,0
0,0,0,0,0,0,0,0,0,0,0,0,0,0,0
0,0,19,0,0,0,0,0,0,0,0,0,0,0,0
0,0,19,0,0,0,0,0,0,0,0,8,0,0,0
19,19,19,19,19,0,0,0,0,0,0,0,0,0,0
0,0,19,0,0,0,0,0,0,0,0,0,0,0,0
0,0,19,0,0,0,0,0,0,0,0,0,0,0,0
0,0,0,0,0,0,0,0,0,0,0,0,0,0,0
0,0,0,0,0,0,0,0,0,0,0,0,0,0,0
0,0,0,0,0,0,0,0,0,0,0,0,0,0,0
0,0,0,0,0,0,0,0,0,0,0,0,0,0,0
0,0,0,8,0,0,0,0,0,0,0,8,0,0,0
0,0,0,0,0,0,0,0,0,0,0,0,0,0,0
0,0,0,0,0,0,0,0,0,0,0,0,0,0,0
0,0,0,0,0,0,0,0,0,0,0,0,0,0,0
0,0,0,0,0,0,0,0,0,0,0,0,0,0,0
:endlayer
layer: 12
0,0,0,19,0,0,0,0,0,0,0,0,0,0,0
0,0,0,19,0,0,0,0,0,0,0,0,0,0,0
0,0,0,0,0,0,0,0,0,0,0,0,0,0,0
19,19,0,8,0,19,19,0,0,0,0,0,0,0,0
0,0,0,0,0,0,0,0,0,0,0,0,0,0,0
0,0,0,19,0,0,0,0,0,0,0,0,0,0,0
0,0,0,19,0,0,0,0,0,0,0,0,0,0,0
0,0,0,0,0,0,0,0,0,0,0,0,0,0,0
0,0,0,0,0,0,0,0,0,0,0,0,0,0,0
0,0,0,0,0,0,0,0,0,0,0,8,0,0,0
0,0,19,0,0,0,0,0,0,0,0,0,0,0,0
0,0,0,0,0,0,0,0,0,0,0,0,0,0,0
0,0,0,0,0,0,0,0,0,0,0,0,0,0,0
0,0,0,0,0,0,0,0,0,0,0,0,0,0,0
0,0,0,0,0,0,0,0,0,0,0,0,0,0,0
0,0,0,0,0,0,0,0,0,0,0,0,0,0,0
0,0,0,0,0,0,0,0,0,0,0,0,0,0,0
0,0,0,8,0,0,0,0,0,0,0,8,0,0,0
0,0,0,0,0,0,0,0,0,0,0,0,0,0,0
0,0,0,0,0,0,0,0,0,0,0,0,0,0,0
0,0,0,0,0,0,0,0,0,0,0,0,0,0,0
0,0,0,0,0,0,0,0,0,0,0,0,0,0,0
:endlayer
layer: 13
0,0,0,0,0,0,0,0,0,0,0,0,0,0,0
0,0,0,19,0,0,0,0,0,0,0,0,0,0,0
0,0,19,19,19,0,0,0,0,0,0,0,0,0,0
0,19,19,19,19,19,0,0,0,0,0,0,0,0,0
0,0,19,19,19,0,0,0,0,0,0,0,0,0,0
0,0,0,19,0,0,0,0,0,0,0,0,0,0,0
0,0,0,0,0,0,0,0,0,0,0,0,0,0,0
0,0,0,0,0,0,0,0,0,0,0,0,0,0,0
0,0,0,0,0,0,0,0,0,0,0,0,0,0,0
0,0,0,0,0,0,0,0,0,0,8,0,0,0,0
0,0,0,0,0,0,0,0,0,0,0,0,0,0,0
0,0,0,0,0,0,0,0,0,0,0,0,0,0,0
0,0,0,0,0,0,0,0,0,0,0,0,0,0,0
0,0,0,0,0,0,0,0,0,0,0,0,0,0,0
0,0,0,19,0,0,0,0,0,0,0,19,0,0,0
0,0,0,19,0,0,0,0,0,0,0,19,0,0,0
0,0,0,0,0,0,0,0,0,0,0,0,0,0,0
19,19,0,8,0,19,19,0,19,19,0,8,0,19,19
0,0,0,0,0,0,0,0,0,0,0,0,0,0,0
0,0,0,19,0,0,0,0,0,0,0,19,0,0,0
0,0,0,19,0,0,0,0,0,0,0,19,0,0,0
0,0,0,0,0,0,0,0,0,0,0,0,0,0,0
:endlayer
layer: 14
0,0,0,0,0,0,0,0,0,0,0,0,0,0,0
0,0,0,0,0,0,0,0,0,0,0,0,0,0,0
0,0,0,0,0,0,0,0,0,0,0,0,0,0,0
0,0,0,19,0,0,0,0,0,0,0,0,0,0,0
0,0,0,0,0,0,0,0,0,0,0,0,0,0,0
0,0,0,0,0,0,0,0,0,0,19,0,0,0,0
0,0,0,0,0,0,0,21,0,0,21,0,0,21,0
0,0,0,0,0,0,0,0,21,0,0,0,21,0,0
0,0,0,0,0,0,0,0,0,0,0,0,0,0,0
0,0,0,0,0,0,19,21,0,0,8,0,0,21,19
0,0,0,0,0,0,0,0,0,0,0,0,0,0,0
0,0,0,0,0,0,0,0,21,0,0,0,21,0,0
0,0,0,0,0,0,0,21,0,0,21,0,0,21,0
0,0,0,0,0,0,0,0,0,0,21,0,0,0,0
0,0,0,0,0,0,0,0,0,0,0,0,0,0,0
0,0,0,19,0,0,0,0,0,0,0,19,0,0,0
0,0,19,19,19,0,0,0,0,0,19,19,19,0,0
0,19,19,19,21,21,0,0,0,19,19,19,19,19,0
0,0,19,19,19,0,0,0,0,0,19,19,19,0,0
0,0,0,19,0,0,0,0,0,0,0,19,0,0,0
0,0,0,0,0,0,0,0,0,0,0,0,0,0,0
0,0,0,0,0,0,0,0,0,0,0,0,0,0,0
:endlayer
layer: 15
0,0,0,0,0,0,0,0,0,0,0,0,0,0,0
0,0,0,0,0,0,0,0,0,0,0,0,0,0,0
0,0,0,0,0,0,0,0,0,0,0,0,0,0,0
0,0,0,0,0,0,0,0,0,0,0,0,0,0,0
0,0,0,0,0,0,0,0,0,0,0,0,0,0,0
0,0,0,0,0,0,0,0,0,0,0,0,0,0,0
0,0,0,0,0,0,0,0,0,0,21,0,0,0,0
0,0,0,0,0,0,0,0,21,0,21,0,21,0,0
0,0,0,0,0,0,0,0,0,21,21,21,0,0,0
0,0,0,0,0,0,0,21,21,21,21,21,21,21,0
0,0,0,0,0,0,0,0,0,21,21,21,0,0,0
0,0,0,0,0,0,0,0,21,0,21,0,19,0,0
0,0,0,0,0,0,0,0,0,0,21,0,0,0,0
0,0,0,0,0,0,0,0,0,0,0,0,0,0,0
0,0,0,0,0,0,0,0,0,0,0,0,0,0,0
0,0,0,0,0,0,0,0,0,0,0,0,0,0,0
0,0,0,0,0,0,0,0,0,0,0,0,0,0,0
0,0,0,19,0,0,0,0,0,0,0,19,0,0,0
0,0,0,0,0,0,0,0,0,0,0,0,0,0,0
0,0,0,0,0,0,0,0,0,0,0,0,0,0,0
0,0,0,0,0,0,0,0,0,0,0,0,0,0,0
0,0,0,0,0,0,0,0,0,0,0,0,0,0,0
:endlayer
layer: 16
0,0,0,0,0,0,0,0,0,0,0,0,0,0,0
0,0,0,0,0,0,0,0,0,0,0,0,0,0,0
0,0,0,0,0,0,0,0,0,0,0,0,0,0,0
0,0,0,0,0,0,0,0,0,0,0,0,0,0,0
0,0,0,0,0,0,0,0,0,0,0,0,0,0,0
0,0,0,0,0,0,0,0,0,0,0,0,0,0,0
0,0,0,0,0,0,0,0,0,0,0,0,0,0,0
0,0,0,0,0,0,0,0,0,0,0,0,0,0,0
0,0,0,0,0,0,0,0,0,0,0,0,0,0,0
0,0,0,0,0,0,0,0,0,0,19,0,0,0,0
0,0,0,0,0,0,0,0,0,0,0,0,0,0,0
0,0,0,0,0,0,0,0,0,0,0,0,0,0,0
0,0,0,0,0,0,0,0,0,0,0,0,0,0,0
0,0,0,0,0,0,0,0,0,0,0,0,0,0,0
0,0,0,0,0,0,0,0,0,0,0,0,0,0,0
0,0,0,0,0,0,0,0,0,0,0,0,0,0,0
0,0,0,0,0,0,0,0,0,0,0,0,0,0,0
0,0,0,0,0,0,0,0,0,0,0,0,0,0,0
0,0,0,0,0,0,0,0,0,0,0,0,0,0,0
0,0,0,0,0,0,0,0,0,0,0,0,0,0,0
0,0,0,0,0,0,0,0,0,0,0,0,0,0,0
0,0,0,0,0,0,0,0,0,0,0,0,0,0,0
:endlayer

#### RULES ####
rule:
plugin=vanillaBlocks
number=1
data:
JSON:{blockState:{blockName:"minecraft:sandstone",properties:{type:"sandstone"}}}
:enddata
:endrule

rule:
plugin=vanillaBlocks
number=2
data:
JSON:{blockState:{blockName:"minecraft:dirt",properties:{variant:"coarse_dirt",snowy:"false"}}}
:enddata
:endrule

rule:
plugin=vanillaBlocks
number=3
data:
JSON:{blockState:{blockName:"minecraft:sand",properties:{variant:"sand"}}}
:enddata
:endrule

rule:
plugin=fluid
number=4
data:
JSON:{blockState:{blockName:"minecraft:water",properties:{level:"0"}}}
:enddata
:endrule

rule:
plugin=vanillaBlocks
number=5
data:
JSON:{blockState:{blockName:"minecraft:mossy_cobblestone"}}
:enddata
:endrule

rule:
plugin=vanillaBlocks
number=6
data:
JSON:{blockState:{blockName:"minecraft:grass",properties:{snowy:"false"}}}
:enddata
:endrule

rule:
plugin=vanillaBlocks
number=7
data:
JSON:{blockState:{blockName:"minecraft:dirt",properties:{variant:"dirt",snowy:"false"}}}
:enddata
:endrule

rule:
plugin=vanillaBlocks
number=8
data:
JSON:{blockState:{blockName:"minecraft:log",properties:{variant:"jungle",axis:"y"}}}
:enddata
:endrule

rule:
plugin=vanillaBlocks
number=9
data:
JSON:{blockState:{blockName:"minecraft:fence",properties:{east:"false",south:"false",north:"false",west:"false"}}}
:enddata
:endrule

rule:
plugin=vanillaBlocks
number=10
data:
JSON:{blockState:{blockName:"minecraft:oak_stairs",properties:{half:"bottom",shape:"straight",facing:"north"}}}
:enddata
:endrule

rule:
plugin=vanillaBlocks
number=11
data:
JSON:{blockState:{blockName:"minecraft:yellow_flower",properties:{type:"dandelion"}}}
:enddata
:endrule

rule:
plugin=vanillaBlocks
number=12
data:
JSON:{blockState:{blockName:"minecraft:tallgrass",properties:{type:"tall_grass"}}}
:enddata
:endrule

rule:
plugin=vanillaBlocks
number=13
data:
JSON:{blockState:{blockName:"minecraft:red_flower",properties:{type:"oxeye_daisy"}}}
:enddata
:endrule

rule:
plugin=vanillaBlocks
number=14
data:
JSON:{blockState:{blockName:"minecraft:oak_stairs",properties:{half:"top",shape:"straight",facing:"south"}}}
:enddata
:endrule

rule:
plugin=vanillaBlocks
number=15
data:
JSON:{blockState:{blockName:"minecraft:wooden_slab",properties:{half:"top",variant:"oak"}}}
:enddata
:endrule

rule:
plugin=vanillaBlocks
number=16
data:
JSON:{blockState:{blockName:"ancientwarfarestructure:bench",properties:{legs:"none",variant:"spruce",axis:"x"}}}
:enddata
:endrule

rule:
plugin=vanillaBlocks
number=17
data:
JSON:{blockState:{blockName:"ancientwarfarestructure:table",properties:{leg_southwest:"true",leg_northwest:"true",variant:"spruce",leg_northeast:"true",leg_southeast:"true"}}}
:enddata
:endrule

rule:
plugin=vanillaBlocks
number=18
data:
JSON:{blockState:{blockName:"minecraft:red_flower",properties:{type:"houstonia"}}}
:enddata
:endrule

rule:
plugin=vanillaBlocks
number=19
data:
JSON:{blockState:{blockName:"minecraft:leaves",properties:{check_decay:"false",decayable:"false",variant:"jungle"}}}
:enddata
:endrule

rule:
plugin=vanillaBlocks
number=20
data:
JSON:{blockState:{blockName:"ancientwarfarestructure:bench",properties:{legs:"none",variant:"spruce",axis:"z"}}}
:enddata
:endrule

rule:
plugin=vanillaBlocks
number=21
data:
JSON:{blockState:{blockName:"minecraft:leaves",properties:{check_decay:"true",decayable:"false",variant:"jungle"}}}
:enddata
:endrule

#### ENTITIES ####
