# Ancient Warfare Structure Template File
# Auto-generated structure template file. created on: 12/12/2023 at: 12:3:14
# Lines beginning with # denote comments

header:
version=2.11
name=SarkonidTownGenBank
mods=
size=28,27,32
offset=13,5,31
:endheader

#### VALIDATION ####
validation:
type=ground
structureAuthor=TheOddlySeagull
survival=false
worldGenEnabled=false
unique=false
preserveBlocks=false
preventNaturalHostileSpawns=true
selectionWeight=1
clusterValue=1
minDuplicateDistance=1
dimensionWhiteList=true
dimensionList=
biomeGroupList=
biomeWhiteList=true
biomeList=
leveling=0
fill=0
border=0
blockSwap=false
territoryName=
biomeReplacement=minecraft:
minGenerationHeight=0
maxGenerationHeight=255
:endvalidation

#### LAYERS ####
layer: 0
1,1,1,1,1,1,1,1,1,1,1,1,1,1,1,1,1,1,1,1,1,1,1,1,1,1,1,1
1,1,1,1,1,1,1,1,1,1,1,1,1,1,1,1,1,1,1,1,1,1,1,1,1,1,1,1
1,1,1,1,1,1,1,1,1,1,1,1,1,1,1,1,1,1,1,1,1,1,1,1,1,1,1,1
1,1,1,1,1,1,1,1,1,1,1,1,1,1,1,1,1,1,1,1,1,1,1,1,1,1,1,1
1,1,1,1,1,1,1,1,1,1,1,1,1,1,1,1,1,1,1,1,1,1,1,1,1,1,1,1
1,1,1,1,1,1,1,1,1,1,1,1,1,1,1,1,1,1,1,1,1,1,1,1,1,1,1,1
1,1,1,1,1,1,1,1,1,1,1,1,1,1,1,1,1,1,1,1,1,1,1,1,1,1,1,1
1,1,1,1,1,1,1,1,1,1,1,1,1,1,1,1,1,1,1,1,1,1,1,1,1,1,1,1
1,1,1,1,1,1,1,1,1,1,1,1,1,1,1,1,1,1,1,1,1,1,1,1,1,1,1,1
1,1,1,1,1,1,1,1,1,1,1,1,1,1,1,1,1,1,1,1,1,1,1,1,1,1,1,1
1,1,1,1,1,1,1,1,1,1,1,1,1,1,1,1,1,1,1,1,1,1,1,1,1,1,1,1
1,1,1,1,1,1,1,1,1,1,1,1,1,1,1,1,1,1,1,1,1,1,1,1,1,1,1,1
1,1,1,1,1,1,1,1,1,1,1,1,1,1,1,1,1,1,1,1,1,1,1,1,1,1,1,1
1,1,1,1,1,1,1,1,1,1,1,1,1,1,1,1,1,1,1,1,1,1,1,1,1,1,1,1
1,1,1,1,1,1,1,1,1,1,1,1,1,1,1,1,1,1,1,1,1,1,1,1,1,1,1,1
1,1,1,1,1,1,1,1,1,1,1,1,1,1,1,1,1,1,1,1,1,1,1,1,1,1,1,1
1,1,1,1,1,1,1,1,1,1,1,1,1,1,1,1,1,1,1,1,1,1,1,1,1,1,1,1
1,1,1,1,1,1,1,1,1,1,1,1,1,1,1,1,1,1,1,1,1,1,1,1,1,1,1,1
1,1,1,1,1,1,1,1,1,1,1,1,1,1,1,1,1,1,1,1,1,1,1,1,1,1,1,1
1,1,1,1,1,1,1,1,1,1,1,1,1,1,1,1,1,1,1,1,1,1,1,1,1,1,1,1
1,1,1,1,1,1,1,1,1,1,1,1,1,1,1,1,1,1,1,1,1,1,1,1,1,1,1,1
1,1,1,1,1,1,1,1,1,1,1,1,1,1,1,1,1,1,1,1,1,1,1,1,1,1,1,1
1,1,1,1,1,1,1,1,1,1,1,1,1,1,1,1,1,1,1,1,1,1,1,1,1,1,1,1
1,1,1,1,1,1,1,1,1,1,1,1,1,1,1,1,1,1,1,1,1,1,1,1,1,1,1,1
1,1,1,1,1,1,1,1,1,1,1,1,1,1,1,1,1,1,1,1,1,1,1,1,1,1,1,1
1,1,1,1,1,1,1,1,1,1,1,1,1,1,1,1,1,1,1,1,1,1,1,1,1,1,1,1
1,1,1,1,1,1,1,1,1,1,1,1,1,1,1,1,1,1,1,1,1,1,1,1,1,1,1,1
1,1,1,1,1,1,1,1,1,1,1,1,1,1,1,1,1,1,1,1,1,1,1,1,1,1,1,1
1,1,1,1,1,1,1,1,1,1,1,1,1,1,1,1,1,1,1,1,1,1,1,1,1,1,1,1
1,1,1,1,1,1,1,1,1,1,1,1,1,1,1,1,1,1,1,1,1,1,1,1,1,1,1,1
1,1,1,1,1,1,1,1,1,1,1,1,1,1,1,1,1,1,1,1,1,1,1,1,1,1,1,1
1,1,1,1,1,1,1,1,1,1,1,1,1,1,1,1,1,1,1,1,1,1,1,1,1,1,1,1
:endlayer
layer: 1
1,1,1,1,1,1,1,1,1,1,1,1,1,1,1,1,1,1,1,1,1,1,1,1,1,1,1,1
1,1,1,1,1,1,1,1,1,1,1,1,1,1,1,1,1,1,1,1,1,1,1,1,1,1,1,1
1,1,1,1,1,1,1,1,1,1,1,1,1,1,1,1,1,1,1,1,1,1,1,1,1,1,1,1
1,1,1,1,1,1,1,1,1,1,1,1,1,1,1,1,1,1,1,1,1,1,1,1,1,1,1,1
1,1,1,1,1,1,1,1,1,1,1,1,1,1,1,1,1,1,1,1,1,1,1,1,1,1,1,1
1,1,1,1,1,1,1,1,1,1,1,1,1,1,1,1,1,1,1,1,1,1,1,1,1,1,1,1
1,1,1,1,1,1,1,1,1,1,1,1,1,1,1,1,1,1,1,1,1,1,1,1,1,1,1,1
1,1,1,1,1,1,1,1,1,1,1,1,1,1,1,1,1,1,1,1,1,1,1,1,1,1,1,1
1,1,1,1,1,1,1,1,1,1,1,1,1,1,1,1,1,1,1,1,1,1,1,1,1,1,1,1
1,1,1,1,1,1,1,1,1,1,1,1,1,1,1,1,1,1,1,1,1,1,1,1,1,1,1,1
1,1,1,1,1,1,1,1,1,1,1,1,1,1,1,1,1,1,1,1,1,1,1,1,1,1,1,1
1,1,1,1,1,1,1,1,1,1,1,1,1,1,1,1,1,1,1,1,1,1,1,1,1,1,1,1
1,1,1,1,1,1,1,1,1,1,1,1,1,1,1,1,1,1,1,1,1,1,1,1,1,1,1,1
1,1,1,1,1,1,1,1,1,1,1,1,1,1,1,1,1,1,1,1,1,1,1,1,1,1,1,1
1,1,1,1,1,1,1,1,1,1,1,1,1,1,1,1,1,1,1,1,1,1,1,1,1,1,1,1
1,1,1,1,1,1,1,1,1,1,1,1,1,1,1,1,1,1,1,1,1,1,1,1,1,1,1,1
1,1,1,1,1,1,1,1,1,1,1,1,1,1,1,1,1,1,1,1,1,1,1,1,1,1,1,1
1,1,1,1,1,1,1,1,1,1,1,1,1,1,1,1,1,1,1,1,1,1,1,1,1,1,1,1
1,1,1,1,1,1,1,1,1,1,1,1,1,1,1,1,1,1,1,1,1,1,1,1,1,1,1,1
1,1,1,1,1,1,1,1,1,1,1,1,1,1,1,1,1,1,1,1,1,1,1,1,1,1,1,1
1,1,1,1,1,1,1,1,1,1,1,1,1,1,1,1,1,1,1,1,1,1,1,1,1,1,1,1
1,1,1,1,1,1,1,1,1,1,1,1,1,1,1,1,1,1,1,1,1,1,1,1,1,1,1,1
1,1,1,1,1,1,1,1,1,1,1,1,1,1,1,1,1,1,1,1,1,1,1,1,1,1,1,1
1,1,1,1,1,1,1,1,1,1,1,1,1,1,1,1,1,1,1,1,1,1,1,1,1,1,1,1
1,1,1,1,1,1,1,1,1,1,1,1,1,1,1,1,1,1,1,1,1,1,1,1,1,1,1,1
1,1,1,1,1,1,1,1,1,1,1,1,1,1,1,1,1,1,1,1,1,1,1,1,1,1,1,1
1,1,1,1,1,1,1,1,1,1,1,1,1,1,1,1,1,1,1,1,1,1,1,1,1,1,1,1
1,1,1,1,1,1,1,1,1,1,1,1,1,1,1,1,1,1,1,1,1,1,1,1,1,1,1,1
1,1,1,1,1,1,1,1,1,1,1,1,1,1,1,1,1,1,1,1,1,1,1,1,1,1,1,1
1,1,1,1,1,1,1,1,1,1,1,1,1,1,1,1,1,1,1,1,1,1,1,1,1,1,1,1
1,1,1,1,1,1,1,1,1,1,1,1,1,1,1,1,1,1,1,1,1,1,1,1,1,1,1,1
1,1,1,1,1,1,1,1,1,1,1,1,1,1,1,1,1,1,1,1,1,1,1,1,1,1,1,1
:endlayer
layer: 2
1,1,1,1,1,1,1,1,1,1,1,1,1,1,1,1,1,1,1,1,1,1,1,1,1,1,1,1
1,1,1,1,1,1,1,1,1,1,1,1,1,1,1,1,1,1,1,1,1,1,1,1,1,1,1,1
1,1,1,1,1,1,1,1,1,1,1,1,1,1,1,1,1,1,1,1,1,1,1,1,1,1,1,1
1,1,1,1,1,1,1,1,1,1,1,1,1,1,1,1,1,1,1,1,1,1,1,1,1,1,1,1
1,1,1,1,1,1,1,1,1,1,1,1,1,1,1,1,1,1,1,1,1,1,1,1,1,1,1,1
1,1,1,1,1,1,1,1,1,1,1,1,1,1,1,1,1,1,1,1,1,1,1,1,1,1,1,1
1,1,1,1,1,1,1,1,1,1,1,1,1,1,1,1,1,1,1,1,1,1,1,1,1,1,1,1
1,1,1,1,1,1,1,1,1,1,1,1,1,1,1,1,1,1,1,1,1,1,1,1,1,1,1,1
1,1,1,1,1,1,1,1,1,1,1,1,1,1,1,1,1,1,1,1,1,1,1,1,1,1,1,1
1,1,1,1,1,1,1,1,1,1,1,1,1,1,1,1,1,1,1,1,1,1,1,1,1,1,1,1
1,1,1,1,1,1,1,1,1,1,1,1,1,1,1,1,1,1,1,1,1,1,1,1,1,1,1,1
1,1,1,1,1,1,1,1,1,1,1,1,1,1,1,1,1,1,1,1,1,1,1,1,1,1,1,1
1,1,1,1,1,1,1,1,1,1,1,1,1,1,1,1,1,1,1,1,1,1,1,1,1,1,1,1
1,1,1,1,1,1,1,1,1,1,1,1,1,1,1,1,1,1,1,1,1,1,1,1,1,1,1,1
1,1,1,1,1,1,1,1,1,1,1,1,1,1,1,1,1,1,1,1,1,1,1,1,1,1,1,1
1,1,1,1,1,1,1,1,1,1,1,1,1,1,1,1,1,1,1,1,1,1,1,1,1,1,1,1
1,1,1,1,1,1,1,1,1,1,1,1,1,1,1,1,1,1,1,1,1,1,1,1,1,1,1,1
1,1,1,1,1,1,1,1,1,1,1,1,1,1,1,1,1,1,1,1,1,1,1,1,1,1,1,1
1,1,1,1,1,1,1,1,1,1,1,1,1,1,1,1,1,1,1,1,1,1,1,1,1,1,1,1
1,1,1,1,1,1,1,1,1,1,1,1,1,1,1,1,1,1,1,1,1,1,1,1,1,1,1,1
1,1,1,1,1,1,1,1,1,1,1,1,1,1,1,1,1,1,1,1,1,1,1,1,1,1,1,1
1,1,1,1,1,1,1,1,1,1,1,1,1,1,1,1,1,1,1,1,1,1,1,1,1,1,1,1
1,1,1,1,1,1,1,1,1,1,1,1,1,1,1,1,1,1,1,1,1,1,1,1,1,1,1,1
1,1,1,1,1,1,1,1,1,1,1,1,1,1,1,1,1,1,1,1,1,1,1,1,1,1,1,1
1,1,1,1,1,1,1,1,1,1,1,1,1,1,1,1,1,1,1,1,1,1,1,1,1,1,1,1
1,1,1,1,1,1,1,1,1,1,1,1,1,1,1,1,1,1,1,1,1,1,1,1,1,1,1,1
1,1,1,1,1,1,1,1,1,1,1,1,1,1,1,1,1,1,1,1,1,1,1,1,1,1,1,1
1,1,1,1,1,1,1,1,1,1,1,1,1,1,1,1,1,1,1,1,1,1,1,1,1,1,1,1
1,1,1,1,1,1,1,1,1,1,1,1,1,1,1,1,1,1,1,1,1,1,1,1,1,1,1,1
1,1,1,1,1,1,1,1,1,1,1,1,1,1,1,1,1,1,1,1,1,1,1,1,1,1,1,1
1,1,1,1,1,1,1,1,1,1,1,1,1,1,1,1,1,1,1,1,1,1,1,1,1,1,1,1
1,1,1,1,1,1,1,1,1,1,1,1,1,1,1,1,1,1,1,1,1,1,1,1,1,1,1,1
:endlayer
layer: 3
2,2,2,2,2,2,2,2,2,2,2,2,2,2,2,2,2,2,2,2,2,2,2,2,2,2,2,2
2,2,2,2,2,2,2,2,2,2,2,2,2,2,2,2,2,2,2,2,2,2,2,2,2,2,2,2
2,2,2,2,2,2,2,2,2,2,2,2,2,2,2,2,2,2,2,2,2,2,2,2,2,2,2,2
2,2,1,1,1,1,1,1,1,2,2,2,2,2,2,2,2,2,2,1,1,1,1,1,1,1,2,2
2,2,1,2,2,2,2,2,1,2,2,2,2,2,2,2,2,2,2,1,2,2,2,2,2,1,2,2
2,2,1,2,2,2,2,2,1,1,1,1,1,1,1,1,1,1,1,1,2,2,2,2,2,1,2,2
2,2,1,2,2,2,2,2,2,2,2,2,2,2,2,2,2,2,2,2,2,2,2,2,2,1,2,2
2,2,1,2,2,2,2,2,2,2,2,2,2,2,2,2,2,2,2,2,2,2,2,2,2,1,2,2
2,2,1,2,2,2,2,2,2,2,2,2,2,2,2,2,2,2,2,2,2,2,2,2,2,1,2,2
2,2,1,1,1,2,2,2,2,1,2,2,2,2,2,2,2,2,1,1,1,1,1,1,1,1,2,2
2,2,2,2,1,2,2,2,2,1,2,2,2,2,2,2,2,2,1,2,2,2,2,1,2,2,2,2
2,2,2,2,1,2,2,2,2,2,2,2,2,2,2,2,2,2,1,2,2,2,2,1,2,2,2,2
2,2,2,2,1,2,2,2,2,2,2,2,2,2,2,2,2,2,1,2,2,2,2,1,2,2,2,2
2,2,2,2,1,2,2,2,2,2,2,2,2,2,2,2,2,2,1,2,2,2,2,1,2,2,2,2
2,2,2,2,1,1,1,1,1,1,2,2,2,2,2,2,2,2,1,2,2,2,2,1,2,2,2,2
2,2,2,2,1,2,2,2,2,1,2,2,2,2,2,2,2,2,1,2,2,2,2,1,2,2,2,2
2,2,2,2,1,2,2,2,2,1,2,2,2,2,2,2,2,2,1,2,2,2,2,1,2,2,2,2
2,2,2,2,1,2,2,2,2,1,2,2,2,2,2,2,2,2,1,2,2,2,2,1,2,2,2,2
2,2,2,2,1,2,2,2,2,1,2,2,2,2,2,2,2,2,1,2,2,2,2,1,2,2,2,2
2,2,2,2,1,2,2,2,1,1,1,1,1,1,1,1,1,1,1,1,2,2,2,1,2,2,2,2
2,2,2,2,1,2,2,2,1,1,2,2,2,2,2,2,2,2,1,1,2,2,2,1,2,2,2,2
2,2,2,2,1,2,2,2,2,2,2,2,2,2,2,2,2,2,2,2,2,2,2,1,2,2,2,2
2,2,2,2,1,2,2,2,2,2,2,2,2,2,2,2,2,2,2,2,2,2,2,1,2,2,2,2
2,2,1,1,1,1,1,1,1,2,2,2,2,2,2,2,2,2,2,1,1,1,1,1,1,1,2,2
2,2,1,2,2,2,2,2,1,2,2,2,2,2,2,2,2,2,2,1,2,2,2,2,2,1,2,2
2,2,1,2,2,2,2,2,1,2,2,2,2,2,2,2,2,2,2,1,2,2,2,2,2,1,2,2
2,2,1,2,2,2,2,2,1,2,2,2,2,2,2,2,2,2,2,1,2,2,2,2,2,1,2,2
2,2,1,2,2,2,2,2,1,1,1,1,1,1,1,1,1,1,1,1,2,2,2,2,2,1,2,2
2,2,1,2,2,2,2,2,1,2,2,2,2,2,2,2,2,2,2,1,2,2,2,2,2,1,2,2
2,2,1,1,1,1,1,1,1,2,2,2,2,2,2,2,2,2,2,1,1,1,1,1,1,1,2,2
2,2,2,2,2,2,2,2,2,2,2,2,2,2,2,2,2,2,2,2,2,2,2,2,2,2,2,2
2,2,2,2,2,2,2,2,2,2,2,2,2,2,2,2,2,2,2,2,2,2,2,2,2,2,2,2
:endlayer
layer: 4
2,2,2,2,2,2,2,2,2,2,2,2,2,1,1,2,2,2,2,2,2,2,2,2,2,2,2,2
2,2,2,2,2,2,2,2,2,2,2,2,2,1,1,2,2,2,2,2,2,2,2,2,2,2,2,2
2,2,3,3,3,3,3,3,3,3,2,2,2,1,1,2,2,2,3,3,3,3,3,3,3,3,2,2
2,2,1,1,1,1,1,1,1,3,2,2,2,1,1,2,2,2,3,1,1,1,1,1,1,1,2,2
2,2,1,2,2,2,2,2,1,2,2,2,2,1,1,2,2,2,2,1,2,2,2,2,2,1,2,2
2,2,1,2,2,2,2,2,1,1,1,1,1,1,1,1,1,1,1,1,2,2,2,2,2,1,2,2
2,2,1,2,2,2,2,2,1,1,1,1,1,1,1,1,1,1,1,1,2,2,2,2,2,1,2,2
2,2,1,2,2,2,2,2,1,1,1,1,1,1,1,1,1,1,1,1,2,2,2,2,2,1,2,2
2,2,1,2,2,2,2,2,1,1,1,1,1,1,1,1,1,1,1,1,2,2,2,2,2,1,2,2
2,2,1,1,1,1,1,1,1,1,1,1,1,1,1,1,1,1,1,1,1,1,1,1,1,1,2,2
2,2,2,2,1,1,1,1,1,1,1,1,1,1,1,1,1,1,1,2,2,2,2,1,2,2,2,2
2,2,2,2,1,1,1,1,1,1,1,1,1,1,1,1,1,1,1,2,2,2,2,1,2,2,2,2
2,2,2,2,1,1,1,1,1,1,1,1,1,1,1,1,1,1,1,2,2,2,2,1,2,2,2,2
2,2,2,2,1,1,1,1,1,1,1,1,1,1,1,1,1,1,1,2,2,2,2,1,2,2,2,2
2,2,2,2,1,1,1,1,1,1,1,1,1,1,1,1,1,1,1,2,2,2,2,1,2,2,2,2
2,2,2,2,1,2,2,2,2,1,1,1,4,4,4,4,1,5,1,2,2,2,2,1,2,2,2,2
2,2,2,2,1,2,2,2,2,1,5,4,4,4,4,4,4,5,1,2,2,2,2,1,2,2,2,2
2,2,2,2,1,2,2,2,2,1,5,5,4,4,4,4,5,5,1,2,2,2,2,1,2,2,2,2
2,2,2,2,1,2,2,2,2,1,5,5,5,4,4,5,5,5,1,2,2,2,2,1,2,2,2,2
2,2,2,2,1,2,2,2,1,1,1,1,1,4,4,1,1,1,1,1,2,2,2,1,2,2,2,2
2,2,2,2,1,2,2,2,1,1,3,3,6,6,6,6,3,3,1,1,2,2,2,1,2,2,2,2
2,2,2,2,1,2,2,2,2,2,3,3,7,6,6,7,3,3,2,2,2,2,2,1,2,2,2,2
2,2,2,2,1,2,2,2,2,2,3,3,7,7,7,7,3,3,2,2,2,2,2,1,2,2,2,2
2,2,1,1,1,1,1,1,1,2,3,3,7,7,7,7,3,3,2,1,1,1,1,1,1,1,2,2
2,2,1,2,2,2,2,2,1,2,7,7,7,7,7,7,7,7,2,1,2,2,2,2,2,1,2,2
2,2,1,2,2,2,2,2,1,2,7,7,7,7,7,7,7,7,2,1,2,2,2,2,2,1,2,2
2,2,1,2,2,2,2,2,1,2,3,3,7,7,7,7,3,3,2,1,2,2,2,2,2,1,2,2
2,2,1,2,2,2,2,2,1,1,1,1,1,1,1,1,1,1,1,1,2,2,2,2,2,1,2,2
2,2,1,2,2,2,2,2,1,2,6,7,7,7,7,7,7,6,2,1,2,2,2,2,2,1,2,2
2,1,1,1,1,1,1,1,1,3,6,7,7,7,7,7,7,6,3,1,1,1,1,1,1,1,1,2
2,1,3,3,3,3,3,3,3,3,6,7,7,7,7,7,7,6,3,3,3,3,3,3,3,3,1,2
2,1,3,3,3,3,3,3,3,3,6,7,7,7,7,7,7,6,3,3,3,3,3,3,3,3,1,2
:endlayer
layer: 5
0,0,0,0,0,0,0,0,0,0,0,0,0,0,0,0,0,0,0,0,0,0,0,0,0,0,0,0
0,0,0,0,0,0,0,0,0,0,8,0,0,0,0,0,8,0,0,0,0,0,0,0,0,0,0,0
0,0,9,9,9,9,9,9,9,9,0,0,0,0,0,0,0,0,9,9,9,9,9,9,9,9,0,0
0,0,1,1,1,1,1,1,1,9,0,8,0,0,0,0,0,0,9,1,1,1,1,1,1,1,0,0
0,0,1,1,1,1,1,1,1,6,0,0,0,0,0,0,0,0,6,1,1,1,1,1,1,1,0,0
0,0,1,1,10,1,10,1,1,1,1,11,1,12,12,1,11,1,1,1,1,10,1,10,1,1,0,0
0,0,1,1,1,10,1,1,13,0,0,0,0,0,0,0,0,0,0,14,1,1,10,1,1,1,0,0
0,0,1,1,10,1,10,1,13,0,0,0,0,0,0,0,0,0,0,14,1,10,1,10,1,1,0,0
0,0,1,1,1,1,1,1,13,0,0,0,0,0,0,15,0,0,0,14,1,1,1,1,1,1,0,0
0,0,1,1,1,1,16,16,1,17,18,18,17,18,18,6,18,18,17,1,16,16,16,1,1,1,0,0
0,0,0,1,1,0,0,0,0,1,1,1,1,1,1,1,1,1,1,0,0,0,0,1,1,0,0,0
0,0,0,19,1,0,0,0,0,20,6,0,0,0,0,0,0,6,1,0,0,0,0,1,19,0,0,0
0,0,0,19,1,0,0,0,0,1,0,0,0,0,0,0,0,0,1,0,0,0,0,1,19,0,0,0
0,0,0,19,1,0,0,0,0,21,0,0,0,22,0,0,0,0,1,0,0,0,0,1,19,0,0,0
0,0,0,1,1,1,0,0,1,1,0,23,23,23,23,23,23,0,1,0,0,0,0,1,1,0,0,0
0,0,0,19,1,0,0,0,0,1,23,23,0,0,0,0,23,24,1,0,0,8,0,1,19,0,0,0
0,0,0,19,1,0,0,0,0,1,0,0,0,0,0,0,0,0,1,0,0,0,0,1,19,0,0,0
0,0,0,19,1,0,0,0,0,1,0,0,0,0,0,0,0,0,1,0,0,0,0,1,19,0,0,0
0,0,0,1,1,0,0,8,0,1,0,0,0,0,0,0,0,0,1,0,8,0,0,1,1,0,0,0
0,0,0,19,1,0,8,0,1,1,1,25,1,26,26,1,25,1,1,1,0,0,0,1,19,0,0,0
0,0,0,19,1,0,0,0,6,1,0,27,28,0,0,29,0,27,1,6,0,0,0,1,19,0,0,0
0,0,0,19,1,0,8,0,0,19,27,27,0,0,0,0,27,27,19,0,0,0,0,1,19,0,0,0
0,0,0,1,1,0,0,0,0,19,27,27,0,0,0,0,27,27,19,0,0,0,0,1,1,0,0,0
0,0,1,1,1,1,1,1,1,13,27,27,0,0,0,0,0,27,14,1,1,1,1,1,1,1,0,0
0,0,1,1,1,1,1,1,1,13,0,0,0,0,0,0,0,0,14,1,1,1,1,1,1,1,0,0
0,0,1,1,10,1,10,1,1,13,0,0,0,0,0,0,0,0,14,1,1,10,1,10,1,1,0,0
0,0,1,1,1,10,1,1,1,13,30,0,0,0,0,0,0,30,14,1,1,1,10,1,1,1,0,0
0,0,1,1,10,1,10,1,1,1,1,31,32,33,34,35,36,1,1,1,1,10,1,10,1,1,0,0
0,0,1,1,1,1,1,1,1,6,19,0,0,0,0,0,0,19,6,1,1,1,1,1,1,1,0,0
0,19,1,1,1,1,1,1,1,9,19,0,0,0,0,0,0,19,9,1,1,1,1,1,1,1,19,0
0,19,9,9,9,9,9,9,9,0,19,0,0,0,0,0,0,19,27,9,9,9,9,9,9,9,19,0
0,19,0,27,27,27,27,27,27,37,19,0,0,0,0,0,0,19,27,27,0,27,27,27,38,0,19,0
:endlayer
layer: 6
0,0,0,0,0,0,0,0,0,0,0,0,0,0,0,0,0,0,0,0,0,0,0,0,0,0,0,0
0,0,0,0,0,0,0,0,0,0,8,0,0,0,0,0,8,0,0,0,0,0,0,0,0,0,0,0
0,0,9,9,9,9,9,9,39,9,0,0,0,0,0,0,0,0,9,39,9,9,9,9,9,9,0,0
0,0,1,11,1,11,1,11,1,39,0,8,0,0,0,0,0,0,39,1,11,1,11,1,11,1,0,0
0,0,20,0,0,0,0,0,1,6,0,0,0,0,0,0,0,0,6,1,0,0,0,0,0,40,0,0
0,0,1,0,0,0,0,0,1,1,1,41,1,42,43,1,41,1,1,1,0,0,0,0,0,1,0,0
0,0,20,0,0,44,0,0,0,0,0,0,0,0,0,0,0,0,0,0,0,0,45,0,0,40,0,0
0,0,1,0,0,0,0,0,0,0,0,0,0,0,0,0,0,0,0,0,0,0,0,0,0,1,0,0
0,0,20,0,0,0,0,0,0,0,0,0,0,0,0,15,0,0,0,0,0,0,0,0,0,40,0,0
0,0,1,1,1,1,0,0,1,17,46,47,17,48,49,6,50,51,17,1,0,0,0,1,1,1,0,0
0,0,0,1,1,0,0,0,0,1,1,1,1,1,1,1,1,1,1,0,0,0,0,1,1,0,0,0
0,0,0,0,1,0,0,0,0,52,6,0,0,0,0,0,0,6,1,0,0,0,0,1,0,0,0,0
0,0,0,0,41,0,0,0,0,1,0,0,0,0,0,0,0,0,1,0,0,0,0,41,0,0,0,0
0,0,0,0,1,0,0,0,0,43,0,0,0,0,0,0,0,0,1,0,0,0,0,1,0,0,0,0
0,0,0,1,1,1,0,0,1,1,0,17,0,0,0,0,17,0,1,0,0,0,0,1,1,0,0,0
0,0,0,0,1,0,0,0,0,1,0,17,0,0,0,0,17,0,1,0,0,8,0,1,0,0,0,0
0,0,0,0,41,0,0,0,0,1,0,0,0,0,0,0,0,0,1,0,0,0,0,41,0,0,0,0
0,0,0,0,1,0,0,0,0,1,0,0,0,0,0,0,0,0,1,0,0,0,0,1,0,0,0,0
0,0,0,1,1,0,0,8,0,1,0,0,0,0,0,0,0,0,1,0,8,0,0,1,1,0,0,0
0,0,0,0,1,0,8,0,1,1,1,41,1,53,54,1,41,1,1,1,0,0,0,1,0,0,0,0
0,0,0,0,41,0,0,0,6,1,0,0,0,0,0,0,0,0,1,6,0,0,0,41,0,0,0,0
0,0,0,0,1,0,55,0,0,0,0,0,0,0,0,0,0,0,0,0,0,0,0,1,0,0,0,0
0,0,0,1,1,0,0,0,0,0,0,0,0,0,0,0,0,0,0,0,0,0,0,1,1,0,0,0
0,0,1,1,1,1,1,1,1,0,0,0,0,0,0,0,0,0,0,1,1,1,1,1,1,1,0,0
0,0,20,0,0,0,0,0,0,0,0,0,0,0,0,0,0,0,0,0,0,0,0,0,0,40,0,0
0,0,1,0,0,0,0,0,0,0,0,0,0,0,0,0,0,0,0,0,0,0,0,0,0,1,0,0
0,0,20,0,0,56,0,0,0,0,30,0,0,0,0,0,0,30,0,0,0,0,57,0,0,40,0,0
0,0,1,0,0,0,0,0,1,1,1,58,59,60,61,62,63,1,1,1,0,0,0,0,0,1,0,0
0,0,20,0,0,0,0,0,1,6,64,0,0,0,0,0,0,65,6,1,0,0,0,0,0,40,0,0
0,0,1,25,1,25,1,25,1,9,0,0,0,0,0,0,0,0,9,1,25,1,25,1,25,1,0,0
0,0,9,9,9,9,9,9,9,0,0,0,0,0,0,0,0,0,0,9,9,9,9,9,9,9,0,0
0,0,0,0,0,0,0,0,0,0,0,0,0,0,0,0,0,0,0,0,0,0,0,0,0,0,0,0
:endlayer
layer: 7
0,0,0,0,0,0,0,0,0,0,0,0,0,0,0,0,0,0,0,0,0,0,0,0,0,0,0,0
0,0,0,0,0,0,0,0,0,0,8,0,0,0,0,0,8,0,0,0,0,0,0,0,0,0,0,0
0,0,0,0,0,0,0,0,0,0,0,0,0,0,0,0,0,0,0,0,0,0,0,0,0,0,0,0
0,0,1,41,1,41,1,41,1,0,0,8,0,0,0,0,0,0,0,1,41,1,41,1,41,1,0,0
0,0,41,0,0,0,0,0,1,6,0,0,0,0,0,0,0,0,6,1,0,0,0,0,0,41,0,0
0,0,1,0,0,0,0,0,1,1,1,41,1,11,11,1,41,1,1,1,0,0,0,0,0,1,0,0
0,0,41,0,0,0,0,0,0,0,0,0,0,0,0,0,0,0,0,0,0,0,0,0,0,41,0,0
0,0,1,0,0,0,0,0,0,0,0,0,0,0,0,0,0,0,0,0,0,0,0,0,0,1,0,0
0,0,41,0,0,0,0,0,0,0,0,0,0,0,0,15,0,0,0,0,0,0,0,0,0,41,0,0
0,0,1,1,1,1,0,0,1,17,18,18,17,18,18,6,18,18,17,1,0,0,0,1,1,1,0,0
0,0,0,1,1,0,0,0,0,1,1,1,1,1,1,1,1,1,1,0,0,0,0,1,1,0,0,0
0,0,0,0,1,0,0,0,0,52,6,0,0,0,0,0,0,6,10,0,0,0,0,1,0,0,0,0
0,0,0,0,41,0,0,0,0,1,0,0,0,0,0,0,0,0,1,0,0,0,0,41,0,0,0,0
0,0,0,0,1,0,0,0,0,1,0,0,0,0,0,0,0,0,41,0,0,0,0,1,0,0,0,0
0,0,0,1,1,1,0,0,1,1,0,17,0,0,0,0,17,0,1,0,0,0,0,1,1,0,0,0
0,0,0,0,1,0,0,0,0,41,0,17,0,0,0,0,17,0,41,0,0,8,0,1,0,0,0,0
0,0,0,0,41,0,0,0,0,1,66,0,0,0,0,0,0,67,1,0,0,0,0,41,0,0,0,0
0,0,0,0,1,0,0,0,0,41,0,0,0,0,0,0,0,0,41,0,0,0,0,1,0,0,0,0
0,0,0,1,1,0,0,8,0,1,0,0,0,0,0,0,0,0,1,0,8,0,0,1,1,0,0,0
0,0,0,0,1,0,8,0,1,1,1,41,1,25,25,1,41,1,1,1,0,0,0,1,0,0,0,0
0,0,0,0,41,0,0,0,6,1,0,0,0,0,0,0,0,0,1,6,0,0,0,41,0,0,0,0
0,0,0,0,1,0,8,0,0,0,0,0,0,0,0,0,0,0,0,0,0,0,0,1,0,0,0,0
0,0,0,1,1,0,0,0,0,0,0,0,0,0,0,0,0,0,0,0,0,0,0,1,1,0,0,0
0,0,1,1,1,1,1,1,1,0,0,0,0,0,0,0,0,0,0,1,1,1,1,1,1,1,0,0
0,0,41,0,0,0,0,0,0,0,0,0,0,0,0,0,0,0,0,0,0,0,0,0,0,41,0,0
0,0,1,0,0,0,0,0,0,0,0,0,0,0,0,0,0,0,0,0,0,0,0,0,0,1,0,0
0,0,41,0,0,0,0,0,0,0,30,0,0,0,0,0,0,30,0,0,0,0,0,0,0,41,0,0
0,0,1,0,0,0,0,0,1,1,1,68,69,70,71,72,73,1,1,1,0,0,0,0,0,1,0,0
0,0,41,0,0,0,0,0,1,6,0,0,0,0,0,0,0,0,6,1,0,0,0,0,0,41,0,0
0,0,1,41,1,41,1,41,1,9,0,0,0,0,0,0,0,0,9,1,41,1,41,1,41,1,0,0
0,0,0,0,0,0,0,0,0,0,0,0,0,0,0,0,0,0,0,0,0,0,0,0,0,0,0,0
0,0,0,0,0,0,0,0,0,0,0,0,0,0,0,0,0,0,0,0,0,0,0,0,0,0,0,0
:endlayer
layer: 8
0,0,0,0,0,0,0,0,0,0,0,0,0,0,0,0,0,0,0,0,0,0,0,0,0,0,0,0
0,0,0,0,0,0,0,0,0,0,0,0,0,0,0,0,0,0,0,0,0,0,0,0,0,0,0,0
0,0,0,0,0,0,0,0,0,0,0,0,0,0,0,0,0,0,0,0,0,0,0,0,0,0,0,0
0,0,1,41,1,41,1,41,1,0,0,0,0,0,0,0,0,0,0,1,41,1,41,1,41,1,0,0
0,0,41,0,0,0,0,0,1,6,0,0,0,0,0,0,0,0,6,1,0,0,0,0,0,41,0,0
0,0,1,0,0,0,0,0,1,1,1,41,1,41,41,1,41,1,1,1,0,0,0,0,0,1,0,0
0,0,41,0,0,0,0,0,74,0,0,0,0,0,0,0,0,0,0,74,0,0,0,0,0,41,0,0
0,0,1,0,0,0,0,0,0,0,0,0,0,0,0,0,0,0,0,0,0,0,0,0,0,1,0,0
0,0,41,0,0,0,0,0,75,0,0,0,0,0,0,15,0,0,0,75,0,0,0,0,0,41,0,0
0,0,1,1,1,1,76,77,1,17,78,79,17,80,81,6,82,83,17,1,76,0,77,1,1,1,0,0
0,0,0,1,1,0,0,0,0,1,1,1,1,1,1,1,1,1,1,0,0,0,0,1,1,0,0,0
0,0,0,74,1,0,0,0,0,84,6,85,0,0,0,0,84,6,1,0,0,0,0,1,74,0,0,0
0,0,0,0,1,0,0,0,0,1,86,0,0,0,0,0,0,86,1,0,0,0,0,1,0,0,0,0
0,0,0,75,1,0,0,0,0,1,0,0,87,0,0,87,0,0,1,0,0,0,0,1,75,0,0,0
0,0,0,1,1,1,76,77,1,1,0,88,89,18,18,89,88,0,1,0,0,0,0,1,1,0,0,0
0,0,0,74,1,0,0,0,0,1,88,88,0,0,0,0,88,88,1,0,0,0,0,1,74,0,0,0
0,0,0,0,1,0,0,0,0,1,0,0,0,0,0,0,0,0,1,0,0,0,0,1,0,0,0,0
0,0,0,75,1,0,0,0,0,1,0,0,0,0,0,0,0,0,1,0,0,0,0,1,75,0,0,0
0,0,0,1,1,0,0,0,0,1,87,0,87,0,0,87,0,87,1,0,0,0,0,1,1,0,0,0
0,0,0,74,1,0,0,0,1,1,1,41,1,41,41,1,41,1,1,1,0,0,0,1,74,0,0,0
0,0,0,0,1,0,0,0,10,1,0,0,90,0,0,90,0,0,1,10,0,0,0,1,0,0,0,0
0,0,0,75,1,0,0,0,0,0,0,0,0,0,0,0,0,0,0,0,0,0,0,1,75,0,0,0
0,0,0,1,1,0,0,0,0,0,0,0,0,0,0,0,0,0,0,0,0,0,0,1,1,0,0,0
0,0,1,1,1,1,1,1,1,0,0,0,0,0,0,0,0,0,0,1,1,1,1,1,1,1,0,0
0,0,41,0,0,0,0,0,74,0,0,0,0,0,0,0,0,0,0,74,0,0,0,0,0,41,0,0
0,0,1,0,0,0,0,0,0,0,0,0,0,0,0,0,0,0,0,0,0,0,0,0,0,1,0,0
0,0,41,0,0,0,0,0,75,0,75,0,0,0,0,0,0,75,0,75,0,0,0,0,0,41,0,0
0,0,1,0,0,0,0,0,1,1,1,91,92,93,94,95,96,1,1,1,0,0,0,0,0,1,0,0
0,0,41,0,0,0,0,0,1,6,0,0,0,0,0,0,0,0,6,1,0,0,0,0,0,41,0,0
0,0,1,41,1,41,1,41,1,0,0,0,0,0,0,0,0,0,0,1,41,1,41,1,41,1,0,0
0,0,0,0,0,0,0,0,0,0,0,0,0,0,0,0,0,0,0,0,0,0,0,0,0,0,0,0
0,0,0,0,0,0,0,0,0,0,0,0,0,0,0,0,0,0,0,0,0,0,0,0,0,0,0,0
:endlayer
layer: 9
0,0,0,0,0,0,0,0,0,0,0,0,0,0,0,0,0,0,0,0,0,0,0,0,0,0,0,0
0,0,0,0,0,0,0,0,0,0,0,0,0,0,0,0,0,0,0,0,0,0,0,0,0,0,0,0
0,0,0,0,0,0,0,0,0,0,0,0,0,0,0,0,0,0,0,0,0,0,0,0,0,0,0,0
0,0,1,41,1,41,1,41,1,0,0,0,0,0,0,0,0,0,0,1,41,1,41,1,41,1,0,0
0,0,41,0,86,0,86,0,1,6,97,97,97,97,97,97,97,97,6,1,0,86,0,86,0,41,0,0
0,0,1,66,0,0,0,67,1,1,1,1,1,1,1,1,1,1,1,1,66,0,0,0,67,1,0,0
0,0,41,0,0,0,0,0,1,90,90,90,90,90,90,90,90,90,90,1,0,0,0,0,0,41,0,0
0,0,1,66,0,0,0,67,1,85,0,0,0,0,0,0,0,0,84,1,66,0,0,0,67,1,0,0
0,0,41,0,87,0,87,0,1,85,0,0,0,0,0,15,0,0,84,1,0,87,0,87,0,41,0,0
0,0,1,1,1,1,1,1,1,85,98,98,98,98,98,6,98,98,84,1,1,1,1,1,1,1,0,0
0,0,77,1,1,85,90,90,90,1,1,1,1,1,1,1,1,1,1,99,0,0,0,1,1,76,0,0
0,0,99,1,1,85,0,0,84,1,6,6,6,6,6,6,6,6,1,85,0,0,0,1,1,99,0,0
0,0,0,1,1,85,0,0,84,1,76,99,99,99,99,99,99,77,1,99,0,0,0,1,1,0,0,0
0,0,99,1,1,98,98,98,98,1,76,99,0,0,0,0,99,77,1,85,0,0,0,1,1,99,0,0
0,0,77,1,1,1,1,1,1,1,76,99,0,0,0,0,99,77,1,99,0,0,0,1,1,76,0,0
0,0,99,1,1,0,0,0,99,1,76,99,0,0,0,0,99,77,1,99,0,0,0,1,1,99,0,0
0,0,0,1,1,0,0,0,84,1,76,99,0,0,0,0,99,77,1,85,0,0,0,1,1,0,0,0
0,0,99,1,1,0,0,0,99,1,76,99,99,99,99,99,99,77,1,99,0,0,0,1,1,99,0,0
0,0,77,1,1,0,0,0,84,1,75,75,75,75,75,75,75,77,1,85,0,0,0,1,1,76,0,0
0,0,99,1,1,0,0,0,10,1,1,1,1,1,1,1,1,1,1,10,0,0,0,1,1,99,0,0
0,0,0,1,1,0,0,0,10,10,90,99,6,6,6,6,99,90,10,10,0,0,0,1,1,0,0,0
0,0,99,1,1,0,0,0,0,99,99,99,90,99,99,90,99,99,99,0,0,0,0,1,1,99,0,0
0,0,77,1,1,0,0,0,0,0,0,0,99,99,99,99,0,0,0,0,0,0,0,1,1,76,0,0
0,0,1,1,1,1,1,1,1,0,0,0,0,0,0,0,0,0,0,1,1,1,1,1,1,1,0,0
0,0,41,0,86,0,86,0,1,0,0,0,0,0,0,0,0,0,0,1,0,86,0,86,0,41,0,0
0,0,1,66,0,0,0,67,1,0,0,0,0,0,0,0,0,0,0,1,66,0,0,0,67,1,0,0
0,0,41,0,0,0,0,0,1,0,0,19,19,99,99,19,19,0,0,1,0,0,0,0,0,41,0,0
0,0,1,66,0,0,0,67,1,1,1,1,1,1,1,1,1,1,1,1,66,0,0,0,67,1,0,0
0,0,41,0,87,0,87,0,1,6,85,0,0,0,0,0,0,84,6,1,0,87,0,87,0,41,0,0
0,0,1,41,1,41,1,41,1,0,0,0,0,0,0,0,0,0,0,1,41,1,41,1,41,1,0,0
0,0,0,0,0,0,0,0,0,0,0,0,0,0,0,0,0,0,0,0,0,0,0,0,0,0,0,0
0,0,0,0,0,0,0,0,0,0,0,0,0,0,0,0,0,0,0,0,0,0,0,0,0,0,0,0
:endlayer
layer: 10
0,0,0,0,0,0,0,0,0,0,0,0,0,0,0,0,0,0,0,0,0,0,0,0,0,0,0,0
0,0,0,0,0,0,0,0,0,0,0,0,0,0,0,0,0,0,0,0,0,0,0,0,0,0,0,0
0,99,98,99,98,99,98,99,98,99,0,0,0,0,0,0,0,0,99,98,99,98,99,98,99,98,99,0
0,84,100,100,100,100,100,100,100,85,0,0,0,0,0,0,0,0,84,100,100,100,100,100,100,100,85,0
0,99,100,85,90,90,90,90,100,6,98,99,98,99,99,98,99,98,6,100,90,90,90,90,84,100,99,0
0,84,100,85,0,0,0,84,100,100,100,100,100,100,100,100,100,100,100,100,85,0,0,0,84,100,85,0
0,99,100,85,0,0,0,84,100,1,1,1,1,1,1,1,1,1,1,100,85,0,0,0,84,100,99,0
0,84,100,85,0,0,0,84,100,1,1,1,1,1,1,1,1,1,1,100,85,0,0,0,84,100,85,0
0,99,100,85,98,98,98,84,100,1,1,1,1,1,1,15,1,1,1,100,85,98,98,98,84,100,99,0
0,84,100,100,100,100,100,100,100,1,1,1,1,1,1,1,1,1,1,100,100,100,100,100,100,100,85,0
0,99,6,100,100,1,1,1,1,1,1,1,1,1,1,1,1,1,1,100,99,90,99,100,100,6,99,0
0,0,0,100,100,1,1,1,1,1,1,1,1,1,1,1,1,1,1,6,0,0,99,100,100,0,0,0
0,0,19,100,100,1,1,1,1,1,1,1,1,1,1,1,1,1,1,100,0,0,99,100,100,19,0,0
0,0,0,100,100,1,1,1,1,1,1,1,1,1,1,1,1,1,1,6,0,0,99,100,100,0,0,0
0,0,19,100,100,1,1,1,100,1,1,1,1,1,1,1,1,1,1,100,0,0,99,100,100,19,0,0
0,0,0,100,100,85,0,0,100,1,1,1,1,1,1,1,1,1,1,100,0,0,99,100,100,0,0,0
0,0,19,100,100,99,0,0,6,1,1,1,1,1,1,1,1,1,1,6,0,0,99,100,100,19,0,0
0,0,0,100,100,85,0,0,100,1,1,1,1,1,1,1,1,1,1,100,0,0,99,100,100,0,0,0
0,0,19,100,100,99,0,0,6,1,1,1,1,1,1,1,1,1,1,6,0,0,99,100,100,19,0,0
0,0,0,100,100,85,0,0,100,1,1,1,1,1,1,1,1,1,1,100,0,0,99,100,100,0,0,0
0,0,19,100,100,99,0,0,6,100,6,100,6,100,100,6,100,6,100,6,0,0,99,100,100,19,0,0
0,0,0,100,100,85,0,0,0,16,101,16,1,1,1,1,16,101,16,0,0,0,99,100,100,0,0,0
0,99,6,100,100,99,98,99,98,99,0,0,101,16,16,101,0,0,99,98,99,98,99,100,100,6,99,0
0,84,100,100,100,100,100,100,100,85,0,0,0,0,0,0,0,0,84,100,100,100,100,100,100,100,85,0
0,99,100,85,90,90,90,84,100,99,0,0,0,0,0,0,0,0,99,100,85,90,90,90,90,100,99,0
0,84,100,85,0,0,0,84,100,85,0,0,0,0,0,0,0,0,84,100,85,0,0,0,84,100,85,0
0,99,100,85,0,0,0,84,100,99,98,99,98,99,99,98,99,98,99,100,85,0,0,0,84,100,99,0
0,84,100,85,0,0,0,84,100,100,100,100,100,100,100,100,100,100,100,100,85,0,0,0,84,100,85,0
0,99,100,85,98,98,98,98,100,6,6,6,6,6,6,6,6,6,6,100,85,98,98,98,98,100,99,0
0,84,100,100,100,100,100,100,100,85,0,0,0,0,0,0,0,0,84,100,100,100,100,100,100,100,85,0
0,99,90,99,90,99,90,99,90,99,0,0,0,0,0,0,0,0,99,90,99,90,99,90,99,90,99,0
0,0,0,0,0,0,0,0,0,0,0,0,0,0,0,0,0,0,0,0,0,0,0,0,0,0,0,0
:endlayer
layer: 11
0,0,0,0,0,0,0,0,0,0,0,0,0,0,0,0,0,0,0,0,0,0,0,0,0,0,0,0
0,0,0,0,0,0,0,0,0,0,0,0,0,0,0,0,0,0,0,0,0,0,0,0,0,0,0,0
0,1,102,1,102,1,102,1,102,1,0,0,0,0,0,0,0,0,1,102,1,102,1,102,1,102,1,0
0,14,1,1,1,1,1,1,1,13,0,0,0,0,0,0,0,0,14,1,1,1,1,1,1,1,13,0
0,1,1,1,1,1,1,1,1,1,102,1,102,1,1,102,1,102,1,1,1,1,1,1,1,1,1,0
0,14,1,1,1,1,1,1,1,1,1,1,1,1,1,1,1,1,1,1,1,1,1,1,1,1,13,0
0,1,1,1,1,1,1,1,1,13,0,0,0,0,0,0,0,0,14,1,1,1,1,1,1,1,1,0
0,14,1,1,1,1,1,1,1,13,0,0,0,0,0,0,0,0,14,1,1,1,1,1,1,1,13,0
0,1,1,1,1,1,1,1,1,13,0,0,0,0,0,103,0,0,14,1,1,1,1,1,1,1,1,0
0,14,1,1,1,1,1,1,1,6,1,11,1,12,12,1,11,1,6,1,1,1,1,1,1,1,13,0
0,1,16,1,1,1,16,1,6,104,0,0,0,0,0,105,106,107,108,6,1,16,1,1,1,16,1,0
0,0,0,14,1,13,0,0,1,0,0,0,0,0,0,0,0,0,0,1,0,0,14,1,13,0,0,0
0,0,0,1,1,13,0,0,21,0,0,52,52,52,52,52,52,0,0,40,0,0,1,1,1,0,0,0
0,0,0,14,1,13,0,0,1,0,0,0,0,0,0,0,0,0,0,1,0,0,14,1,13,0,0,0
0,0,0,1,1,1,19,19,20,0,0,0,109,0,110,0,0,0,0,40,0,0,1,1,1,0,0,0
0,0,0,14,1,13,0,0,20,0,0,107,107,107,107,107,0,0,0,40,0,0,14,1,13,0,0,0
0,0,0,1,1,1,0,0,1,0,111,107,107,107,107,107,112,0,0,1,0,0,1,1,1,0,0,0
0,0,0,14,1,13,0,0,20,0,0,107,107,107,107,107,0,0,0,40,0,0,14,1,13,0,0,0
0,0,0,1,1,1,0,0,1,113,0,0,114,0,115,0,0,0,116,1,0,0,1,1,1,0,0,0
0,0,0,14,1,13,0,0,20,117,0,0,0,0,0,0,0,0,118,40,0,0,14,1,13,0,0,0
0,0,0,1,1,1,0,0,1,25,1,25,1,25,25,1,25,1,25,1,0,0,1,1,1,0,0,0
0,0,0,14,1,13,0,0,0,0,0,0,0,101,101,0,0,0,0,0,0,0,14,1,13,0,0,0
0,1,102,1,1,1,102,1,102,1,0,0,0,0,0,0,0,0,1,102,1,102,1,1,1,102,1,0
0,14,1,1,1,1,1,1,1,13,0,0,0,0,0,0,0,0,14,1,1,1,1,1,1,1,13,0
0,1,1,1,1,1,1,1,1,1,0,0,0,0,0,0,0,0,1,1,1,1,1,1,1,1,1,0
0,14,1,1,1,1,1,1,1,13,0,0,0,0,0,0,0,0,14,1,1,1,1,1,1,1,13,0
0,1,1,1,1,1,1,1,1,1,102,1,102,1,1,102,1,102,1,1,1,1,1,1,1,1,1,0
0,14,1,1,1,1,1,1,1,1,1,1,1,1,1,1,1,1,1,1,1,1,1,1,1,1,13,0
0,1,1,1,1,1,1,1,1,1,16,1,16,1,1,16,1,16,1,1,1,1,1,1,1,1,1,0
0,14,1,1,1,1,1,1,1,13,0,0,0,0,0,0,0,0,14,1,1,1,1,1,1,1,13,0
0,1,16,1,16,1,16,1,16,1,0,0,0,0,0,0,0,0,1,16,1,16,1,16,1,16,1,0
0,0,0,0,0,0,0,0,0,0,0,0,0,0,0,0,0,0,0,0,0,0,0,0,0,0,0,0
:endlayer
layer: 12
0,0,0,0,0,0,0,0,0,0,0,0,0,0,0,0,0,0,0,0,0,0,0,0,0,0,0,0
0,0,0,0,0,0,0,0,0,0,0,0,0,0,0,0,0,0,0,0,0,0,0,0,0,0,0,0
0,19,0,19,0,19,0,19,0,19,0,0,0,0,0,0,0,0,19,0,19,0,19,0,19,0,19,0
0,0,19,0,0,0,0,0,19,0,0,0,0,0,0,0,0,0,0,19,0,0,0,0,0,19,0,0
0,19,0,19,1,6,1,19,0,19,0,19,0,19,19,0,19,0,19,0,19,1,6,1,19,0,19,0
0,0,0,1,1,1,1,1,0,0,119,0,0,0,0,0,0,120,0,0,1,1,1,1,1,0,0,0
0,19,0,6,1,1,1,6,0,0,0,0,0,0,0,0,0,0,0,0,6,1,1,1,6,0,19,0
0,0,0,1,1,1,1,1,0,0,0,0,0,0,0,0,0,0,0,0,1,1,1,1,1,0,0,0
0,19,0,19,1,6,1,19,0,0,0,0,0,0,0,0,0,0,0,0,19,1,6,1,19,0,19,0
0,0,19,0,0,0,0,0,1,11,1,41,1,42,43,1,41,1,11,1,0,0,0,0,0,19,0,0
0,19,0,19,0,19,0,19,20,0,0,0,0,0,0,0,0,0,0,40,19,0,19,0,19,0,19,0
0,0,0,0,0,0,0,0,1,0,0,0,0,0,0,0,0,0,0,1,0,0,0,0,0,0,0,0
0,0,0,19,0,0,0,0,43,0,0,52,52,52,52,52,52,0,0,41,0,0,19,0,19,0,0,0
0,0,0,0,0,0,0,0,1,0,0,0,0,0,0,0,0,0,0,1,0,0,0,0,0,0,0,0
0,0,0,19,0,19,0,0,41,0,0,0,121,0,122,0,0,0,0,41,0,0,19,0,19,0,0,0
0,0,0,0,0,0,0,0,41,0,0,0,0,0,0,0,0,0,0,41,0,0,0,0,0,0,0,0
0,0,0,19,123,19,0,0,1,0,124,0,0,125,0,0,126,0,0,1,0,0,19,127,19,0,0,0
0,0,0,0,0,0,0,0,41,0,0,0,0,0,0,0,0,0,0,41,0,0,0,0,0,0,0,0
0,0,0,19,0,19,0,0,1,0,0,0,128,0,129,0,0,0,0,1,0,0,19,0,19,0,0,0
0,0,0,0,0,0,0,0,41,0,0,0,0,0,0,0,0,0,0,41,0,0,0,0,0,0,0,0
0,0,0,19,0,19,0,0,1,41,1,41,1,41,41,1,41,1,41,1,0,0,19,0,19,0,0,0
0,0,0,0,0,0,0,0,0,0,0,0,0,0,0,0,0,0,0,0,0,0,0,0,0,0,0,0
0,19,0,19,0,19,0,19,0,19,0,0,0,0,0,0,0,0,19,0,19,0,19,0,19,0,19,0
0,0,19,0,0,0,0,0,19,0,0,0,0,0,0,0,0,0,0,19,0,0,0,0,0,19,0,0
0,19,0,19,1,6,1,19,0,19,0,0,0,0,0,0,0,0,19,0,19,1,6,1,19,0,19,0
0,0,0,1,1,1,1,1,0,0,0,0,0,0,0,0,0,0,0,0,1,1,1,1,1,0,0,0
0,19,0,6,1,1,1,6,0,19,0,19,0,19,19,0,19,0,19,0,6,1,1,1,6,0,19,0
0,0,0,1,1,1,1,1,0,130,0,0,0,0,0,0,0,0,131,0,1,1,1,1,1,0,0,0
0,19,0,19,1,6,1,19,0,19,0,19,0,19,19,0,19,0,19,0,19,1,6,1,19,0,19,0
0,0,19,0,0,0,0,0,19,0,0,0,0,0,0,0,0,0,0,19,0,0,0,0,0,19,0,0
0,19,0,19,0,19,0,19,0,19,0,0,0,0,0,0,0,0,19,0,19,0,19,0,19,0,19,0
0,0,0,0,0,0,0,0,0,0,0,0,0,0,0,0,0,0,0,0,0,0,0,0,0,0,0,0
:endlayer
layer: 13
0,0,0,0,0,0,0,0,0,0,0,0,0,0,0,0,0,0,0,0,0,0,0,0,0,0,0,0
0,0,0,0,0,0,0,0,0,0,0,0,0,0,0,0,0,0,0,0,0,0,0,0,0,0,0,0
0,0,0,0,0,0,0,0,0,0,0,0,0,0,0,0,0,0,0,0,0,0,0,0,0,0,0,0
0,0,0,0,99,132,99,0,0,0,0,0,0,0,0,0,0,0,0,0,0,99,132,99,0,0,0,0
0,0,0,132,132,1,132,132,0,0,0,0,0,0,0,0,0,0,0,0,132,132,1,132,132,0,0,0
0,0,99,132,1,1,1,132,99,0,0,0,0,0,0,0,0,0,0,99,132,1,1,1,132,99,0,0
0,0,132,1,1,1,1,1,132,0,0,0,0,0,0,0,0,0,0,132,1,1,1,1,1,132,0,0
0,0,99,132,1,1,1,132,99,0,0,0,0,0,0,0,0,0,0,99,132,1,1,1,132,99,0,0
0,0,0,132,132,1,132,132,0,0,0,0,0,0,0,0,0,0,0,0,132,132,1,132,132,0,0,0
0,0,0,0,99,132,99,0,133,41,133,41,133,11,11,133,41,133,41,133,0,99,132,99,0,0,0,0
0,0,0,0,0,0,0,0,41,0,0,0,0,0,0,0,0,0,0,41,0,0,0,0,0,0,0,0
0,0,0,0,0,0,0,0,133,0,0,0,0,0,0,0,0,0,0,133,0,0,0,0,0,0,0,0
0,0,0,0,0,0,0,0,6,0,0,52,52,52,52,52,52,0,0,41,0,0,0,0,0,0,0,0
0,0,0,0,0,0,0,0,133,0,0,0,0,0,0,0,0,0,0,133,0,0,0,0,0,0,0,0
0,0,0,0,0,0,0,0,41,0,0,0,0,0,0,0,0,0,0,41,0,0,0,0,0,0,0,0
0,0,0,0,0,0,0,0,41,0,0,0,0,0,0,0,0,0,0,41,0,0,0,0,0,0,0,0
0,0,0,0,0,0,0,0,133,0,0,0,0,0,0,0,0,0,0,133,0,0,0,0,0,0,0,0
0,0,0,0,0,0,0,0,41,0,0,0,0,0,0,0,0,0,0,41,0,0,0,0,0,0,0,0
0,0,0,0,0,0,0,0,133,0,0,0,0,0,0,0,0,0,0,133,0,0,0,0,0,0,0,0
0,0,0,0,0,0,0,0,41,0,0,0,0,0,0,0,0,0,0,41,0,0,0,0,0,0,0,0
0,0,0,0,0,0,0,0,133,41,133,41,133,41,41,133,41,133,41,133,0,0,0,0,0,0,0,0
0,0,0,0,0,0,0,0,0,0,0,0,0,0,0,0,0,0,0,0,0,0,0,0,0,0,0,0
0,0,0,0,0,0,0,0,0,0,0,0,0,0,0,0,0,0,0,0,0,0,0,0,0,0,0,0
0,0,0,0,99,132,99,0,0,0,0,0,0,0,0,0,0,0,0,0,0,99,132,99,0,0,0,0
0,0,0,132,132,1,132,132,0,0,0,0,0,0,0,0,0,0,0,0,132,132,1,132,132,0,0,0
0,0,99,132,1,1,1,132,99,0,0,0,0,0,0,0,0,0,0,99,132,1,1,1,132,99,0,0
0,0,132,1,1,1,1,1,132,0,0,0,0,0,0,0,0,0,0,132,1,1,1,1,1,132,0,0
0,0,99,132,1,1,1,132,99,0,0,0,0,0,0,0,0,0,0,99,132,1,1,1,132,99,0,0
0,0,0,132,132,1,132,132,0,0,0,0,0,0,0,0,0,0,0,0,132,132,1,132,132,0,0,0
0,0,0,0,99,132,99,0,0,0,0,0,0,0,0,0,0,0,0,0,0,99,132,99,0,0,0,0
0,0,0,0,0,0,0,0,0,0,0,0,0,0,0,0,0,0,0,0,0,0,0,0,0,0,0,0
0,0,0,0,0,0,0,0,0,0,0,0,0,0,0,0,0,0,0,0,0,0,0,0,0,0,0,0
:endlayer
layer: 14
0,0,0,0,0,0,0,0,0,0,0,0,0,0,0,0,0,0,0,0,0,0,0,0,0,0,0,0
0,0,0,0,0,0,0,0,0,0,0,0,0,0,0,0,0,0,0,0,0,0,0,0,0,0,0,0
0,0,0,0,0,0,0,0,0,0,0,0,0,0,0,0,0,0,0,0,0,0,0,0,0,0,0,0
0,0,0,0,132,132,132,0,0,0,0,0,0,0,0,0,0,0,0,0,0,132,132,132,0,0,0,0
0,0,0,132,132,132,132,132,0,0,0,0,0,0,0,0,0,0,0,0,132,132,132,132,132,0,0,0
0,0,132,132,132,132,132,132,132,0,0,0,0,0,0,0,0,0,0,132,132,132,132,132,132,132,0,0
0,0,132,132,132,132,132,132,132,0,0,0,0,0,0,0,0,0,0,132,132,132,132,132,132,132,0,0
0,0,132,132,132,132,132,132,132,0,0,0,0,0,0,0,0,0,0,132,132,132,132,132,132,132,0,0
0,0,0,132,132,132,132,132,0,0,0,0,0,0,0,0,0,0,0,0,132,132,132,132,132,0,0,0
0,0,0,0,132,132,132,0,1,41,1,41,1,41,41,1,41,1,41,1,0,132,132,132,0,0,0,0
0,0,0,0,0,0,0,0,41,0,0,0,86,0,0,86,0,0,0,41,0,0,0,0,0,0,0,0
0,0,0,0,0,0,0,0,1,0,0,0,0,0,0,0,0,0,0,1,0,0,0,0,0,0,0,0
0,0,0,0,0,0,0,0,41,0,0,0,0,0,0,0,0,0,0,41,0,0,0,0,0,0,0,0
0,0,0,0,0,0,0,0,1,66,0,0,0,0,0,0,0,0,67,1,0,0,0,0,0,0,0,0
0,0,0,0,0,0,0,0,41,0,0,0,0,0,0,0,0,0,0,41,0,0,0,0,0,0,0,0
0,0,0,0,0,0,0,0,41,0,0,0,0,0,0,0,0,0,0,41,0,0,0,0,0,0,0,0
0,0,0,0,0,0,0,0,1,66,0,0,0,0,0,0,0,0,67,1,0,0,0,0,0,0,0,0
0,0,0,0,0,0,0,0,41,0,0,0,0,0,0,0,0,0,0,41,0,0,0,0,0,0,0,0
0,0,0,0,0,0,0,0,1,0,0,0,0,0,0,0,0,0,0,1,0,0,0,0,0,0,0,0
0,0,0,0,0,0,0,0,41,0,0,0,87,0,0,87,0,0,0,41,0,0,0,0,0,0,0,0
0,0,0,0,0,0,0,0,1,41,1,41,1,41,41,1,41,1,41,1,0,0,0,0,0,0,0,0
0,0,0,0,0,0,0,0,0,0,0,0,0,0,0,0,0,0,0,0,0,0,0,0,0,0,0,0
0,0,0,0,0,0,0,0,0,0,0,0,0,0,0,0,0,0,0,0,0,0,0,0,0,0,0,0
0,0,0,0,132,132,132,0,0,0,0,0,0,0,0,0,0,0,0,0,0,132,132,132,0,0,0,0
0,0,0,132,132,132,132,132,0,0,0,0,0,0,0,0,0,0,0,0,132,132,132,132,132,0,0,0
0,0,132,132,132,132,132,132,132,0,0,0,0,0,0,0,0,0,0,132,132,132,132,132,132,132,0,0
0,0,132,132,132,132,132,132,132,0,0,0,0,0,0,0,0,0,0,132,132,132,132,132,132,132,0,0
0,0,132,132,132,132,132,132,132,0,0,0,0,0,0,0,0,0,0,132,132,132,132,132,132,132,0,0
0,0,0,132,132,132,132,132,0,0,0,0,0,0,0,0,0,0,0,0,132,132,132,132,132,0,0,0
0,0,0,0,132,132,132,0,0,0,0,0,0,0,0,0,0,0,0,0,0,132,132,132,0,0,0,0
0,0,0,0,0,0,0,0,0,0,0,0,0,0,0,0,0,0,0,0,0,0,0,0,0,0,0,0
0,0,0,0,0,0,0,0,0,0,0,0,0,0,0,0,0,0,0,0,0,0,0,0,0,0,0,0
:endlayer
layer: 15
0,0,0,0,0,0,0,0,0,0,0,0,0,0,0,0,0,0,0,0,0,0,0,0,0,0,0,0
0,0,0,0,0,0,0,0,0,0,0,0,0,0,0,0,0,0,0,0,0,0,0,0,0,0,0,0
0,0,0,0,0,0,0,0,0,0,0,0,0,0,0,0,0,0,0,0,0,0,0,0,0,0,0,0
0,0,0,0,19,132,19,0,0,0,0,0,0,0,0,0,0,0,0,0,0,19,132,19,0,0,0,0
0,0,0,132,132,132,132,132,0,0,0,0,0,0,0,0,0,0,0,0,132,132,132,132,132,0,0,0
0,0,19,132,132,132,132,132,19,0,0,0,0,0,0,0,0,0,0,19,132,132,132,132,132,19,0,0
0,0,132,132,132,132,132,132,132,0,0,0,0,0,0,0,0,0,0,132,132,132,132,132,132,132,0,0
0,0,19,132,132,132,132,132,19,0,0,0,0,0,0,0,0,0,0,19,132,132,132,132,132,19,0,0
0,0,0,132,132,132,132,132,99,99,99,99,99,99,99,99,99,99,99,99,132,132,132,132,132,0,0,0
0,0,0,0,19,132,19,99,1,6,1,6,1,6,6,1,6,1,6,1,99,19,132,19,0,0,0,0
0,0,0,0,0,0,0,99,6,76,74,74,74,74,74,74,74,74,74,6,99,0,0,0,0,0,0,0
0,0,0,0,0,0,0,99,1,76,99,0,0,0,0,0,0,99,77,1,99,0,0,0,0,0,0,0
0,0,0,0,0,0,0,99,6,76,0,99,0,0,0,0,99,0,77,6,99,0,0,0,0,0,0,0
0,0,0,0,0,0,0,99,1,76,0,0,99,97,97,99,0,0,77,1,99,0,0,0,0,0,0,0
0,0,0,0,0,0,0,99,6,76,0,0,97,97,97,97,0,0,77,6,99,0,0,0,0,0,0,0
0,0,0,0,0,0,0,99,6,76,0,0,97,97,97,97,0,0,77,6,99,0,0,0,0,0,0,0
0,0,0,0,0,0,0,99,1,76,0,0,99,97,97,99,0,0,77,1,99,0,0,0,0,0,0,0
0,0,0,0,0,0,0,99,6,76,0,99,0,0,0,0,99,0,77,6,99,0,0,0,0,0,0,0
0,0,0,0,0,0,0,99,1,76,99,0,0,0,0,0,0,99,77,1,99,0,0,0,0,0,0,0
0,0,0,0,0,0,0,99,6,75,75,75,75,75,75,75,75,75,75,6,99,0,0,0,0,0,0,0
0,0,0,0,0,0,0,99,1,6,1,6,1,6,6,1,6,1,6,1,99,0,0,0,0,0,0,0
0,0,0,0,0,0,0,0,99,99,99,99,99,99,99,99,99,99,99,99,0,0,0,0,0,0,0,0
0,0,0,0,0,0,0,0,0,0,0,0,0,0,0,0,0,0,0,0,0,0,0,0,0,0,0,0
0,0,0,0,19,132,19,0,0,0,0,0,0,0,0,0,0,0,0,0,0,19,132,19,0,0,0,0
0,0,0,132,132,132,132,132,0,0,0,0,0,0,0,0,0,0,0,0,132,132,132,132,132,0,0,0
0,0,19,132,132,132,132,132,19,0,0,0,0,0,0,0,0,0,0,19,132,132,132,132,132,19,0,0
0,0,132,132,132,132,132,132,132,0,0,0,0,0,0,0,0,0,0,132,132,132,132,132,132,132,0,0
0,0,19,132,132,132,132,132,19,0,0,0,0,0,0,0,0,0,0,19,132,132,132,132,132,19,0,0
0,0,0,132,132,132,132,132,0,0,0,0,0,0,0,0,0,0,0,0,132,132,132,132,132,0,0,0
0,0,0,0,19,132,19,0,0,0,0,0,0,0,0,0,0,0,0,0,0,19,132,19,0,0,0,0
0,0,0,0,0,0,0,0,0,0,0,0,0,0,0,0,0,0,0,0,0,0,0,0,0,0,0,0
0,0,0,0,0,0,0,0,0,0,0,0,0,0,0,0,0,0,0,0,0,0,0,0,0,0,0,0
:endlayer
layer: 16
0,0,0,0,0,0,0,0,0,0,0,0,0,0,0,0,0,0,0,0,0,0,0,0,0,0,0,0
0,0,0,0,0,0,0,0,0,0,0,0,0,0,0,0,0,0,0,0,0,0,0,0,0,0,0,0
0,0,0,0,0,0,0,0,0,0,0,0,0,0,0,0,0,0,0,0,0,0,0,0,0,0,0,0
0,0,0,0,0,0,0,0,0,0,0,0,0,0,0,0,0,0,0,0,0,0,0,0,0,0,0,0
0,0,0,0,19,19,19,0,0,0,0,0,0,0,0,0,0,0,0,0,0,19,19,19,0,0,0,0
0,0,0,19,132,132,132,19,0,0,0,0,0,0,0,0,0,0,0,0,19,132,132,132,19,0,0,0
0,0,0,19,132,132,132,19,0,0,0,0,0,0,0,0,0,0,0,0,19,132,132,132,19,0,0,0
0,0,0,19,132,132,132,19,0,0,0,0,0,0,0,0,0,0,0,0,19,132,132,132,19,0,0,0
0,0,0,0,19,19,19,0,97,75,97,75,97,75,75,97,75,97,75,97,0,19,19,19,0,0,0,0
0,0,0,0,0,0,0,97,10,10,10,10,10,10,10,10,10,10,10,10,97,0,0,0,0,0,0,0
0,0,0,0,0,0,0,77,10,1,1,1,1,1,1,1,1,1,1,10,76,0,0,0,0,0,0,0
0,0,0,0,0,0,0,97,10,1,1,1,1,1,1,1,1,1,1,10,97,0,0,0,0,0,0,0
0,0,0,0,0,0,0,77,10,1,1,1,1,1,1,1,1,1,1,10,76,0,0,0,0,0,0,0
0,0,0,0,0,0,0,97,10,1,1,1,1,1,1,1,1,1,1,10,97,0,0,0,0,0,0,0
0,0,0,0,0,0,0,77,10,1,1,1,1,1,1,1,1,1,1,10,76,0,0,0,0,0,0,0
0,0,0,0,0,0,0,77,10,1,1,1,1,1,1,1,1,1,1,10,76,0,0,0,0,0,0,0
0,0,0,0,0,0,0,97,10,1,1,1,1,1,1,1,1,1,1,10,97,0,0,0,0,0,0,0
0,0,0,0,0,0,0,77,10,1,1,1,1,1,1,1,1,1,1,10,76,0,0,0,0,0,0,0
0,0,0,0,0,0,0,97,10,1,1,1,1,1,1,1,1,1,1,10,97,0,0,0,0,0,0,0
0,0,0,0,0,0,0,77,10,1,1,1,1,1,1,1,1,1,1,10,76,0,0,0,0,0,0,0
0,0,0,0,0,0,0,97,10,10,10,10,10,10,10,10,10,10,10,10,97,0,0,0,0,0,0,0
0,0,0,0,0,0,0,0,97,74,97,74,97,74,74,97,74,97,74,97,0,0,0,0,0,0,0,0
0,0,0,0,0,0,0,0,0,0,0,0,0,0,0,0,0,0,0,0,0,0,0,0,0,0,0,0
0,0,0,0,0,0,0,0,0,0,0,0,0,0,0,0,0,0,0,0,0,0,0,0,0,0,0,0
0,0,0,0,19,19,19,0,0,0,0,0,0,0,0,0,0,0,0,0,0,19,19,19,0,0,0,0
0,0,0,19,132,132,132,19,0,0,0,0,0,0,0,0,0,0,0,0,19,132,132,132,19,0,0,0
0,0,0,19,132,132,132,19,0,0,0,0,0,0,0,0,0,0,0,0,19,132,132,132,19,0,0,0
0,0,0,19,132,132,132,19,0,0,0,0,0,0,0,0,0,0,0,0,19,132,132,132,19,0,0,0
0,0,0,0,19,19,19,0,0,0,0,0,0,0,0,0,0,0,0,0,0,19,19,19,0,0,0,0
0,0,0,0,0,0,0,0,0,0,0,0,0,0,0,0,0,0,0,0,0,0,0,0,0,0,0,0
0,0,0,0,0,0,0,0,0,0,0,0,0,0,0,0,0,0,0,0,0,0,0,0,0,0,0,0
0,0,0,0,0,0,0,0,0,0,0,0,0,0,0,0,0,0,0,0,0,0,0,0,0,0,0,0
:endlayer
layer: 17
0,0,0,0,0,0,0,0,0,0,0,0,0,0,0,0,0,0,0,0,0,0,0,0,0,0,0,0
0,0,0,0,0,0,0,0,0,0,0,0,0,0,0,0,0,0,0,0,0,0,0,0,0,0,0,0
0,0,0,0,0,0,0,0,0,0,0,0,0,0,0,0,0,0,0,0,0,0,0,0,0,0,0,0
0,0,0,0,0,0,0,0,0,0,0,0,0,0,0,0,0,0,0,0,0,0,0,0,0,0,0,0
0,0,0,0,0,0,0,0,0,0,0,0,0,0,0,0,0,0,0,0,0,0,0,0,0,0,0,0
0,0,0,0,0,0,0,0,0,0,0,0,0,0,0,0,0,0,0,0,0,0,0,0,0,0,0,0
0,0,0,0,0,6,0,0,0,0,0,0,0,0,0,0,0,0,0,0,0,0,6,0,0,0,0,0
0,0,0,0,0,0,0,0,0,0,0,0,0,0,0,0,0,0,0,0,0,0,0,0,0,0,0,0
0,0,0,0,0,0,0,0,6,13,19,19,19,19,19,19,19,19,14,6,0,0,0,0,0,0,0,0
0,0,0,0,0,0,0,6,0,0,0,0,0,0,0,0,0,0,0,0,6,0,0,0,0,0,0,0
0,0,0,0,0,0,0,16,0,0,0,0,0,0,0,0,0,0,0,0,16,0,0,0,0,0,0,0
0,0,0,0,0,0,0,19,0,0,30,1,1,6,6,1,1,30,0,0,19,0,0,0,0,0,0,0
0,0,0,0,0,0,0,19,0,0,1,1,1,1,1,1,1,1,0,0,19,0,0,0,0,0,0,0
0,0,0,0,0,0,0,19,0,0,1,1,1,1,1,1,1,1,0,0,19,0,0,0,0,0,0,0
0,0,0,0,0,0,0,19,0,0,6,1,1,1,1,1,1,6,0,0,19,0,0,0,0,0,0,0
0,0,0,0,0,0,0,19,0,0,6,1,1,1,1,1,1,6,0,0,19,0,0,0,0,0,0,0
0,0,0,0,0,0,0,19,0,0,1,1,1,1,1,1,1,1,0,0,19,0,0,0,0,0,0,0
0,0,0,0,0,0,0,19,0,0,1,1,1,1,1,1,1,1,0,0,19,0,0,0,0,0,0,0
0,0,0,0,0,0,0,19,0,0,30,1,1,6,6,1,1,30,0,0,19,0,0,0,0,0,0,0
0,0,0,0,0,0,0,102,0,0,0,0,0,0,0,0,0,0,0,0,102,0,0,0,0,0,0,0
0,0,0,0,0,0,0,6,0,0,0,0,0,0,0,0,0,0,0,0,6,0,0,0,0,0,0,0
0,0,0,0,0,0,0,0,6,13,19,19,19,19,19,19,19,19,14,6,0,0,0,0,0,0,0,0
0,0,0,0,0,0,0,0,0,0,0,0,0,0,0,0,0,0,0,0,0,0,0,0,0,0,0,0
0,0,0,0,0,0,0,0,0,0,0,0,0,0,0,0,0,0,0,0,0,0,0,0,0,0,0,0
0,0,0,0,0,0,0,0,0,0,0,0,0,0,0,0,0,0,0,0,0,0,0,0,0,0,0,0
0,0,0,0,0,0,0,0,0,0,0,0,0,0,0,0,0,0,0,0,0,0,0,0,0,0,0,0
0,0,0,0,0,6,0,0,0,0,0,0,0,0,0,0,0,0,0,0,0,0,6,0,0,0,0,0
0,0,0,0,0,0,0,0,0,0,0,0,0,0,0,0,0,0,0,0,0,0,0,0,0,0,0,0
0,0,0,0,0,0,0,0,0,0,0,0,0,0,0,0,0,0,0,0,0,0,0,0,0,0,0,0
0,0,0,0,0,0,0,0,0,0,0,0,0,0,0,0,0,0,0,0,0,0,0,0,0,0,0,0
0,0,0,0,0,0,0,0,0,0,0,0,0,0,0,0,0,0,0,0,0,0,0,0,0,0,0,0
0,0,0,0,0,0,0,0,0,0,0,0,0,0,0,0,0,0,0,0,0,0,0,0,0,0,0,0
:endlayer
layer: 18
0,0,0,0,0,0,0,0,0,0,0,0,0,0,0,0,0,0,0,0,0,0,0,0,0,0,0,0
0,0,0,0,0,0,0,0,0,0,0,0,0,0,0,0,0,0,0,0,0,0,0,0,0,0,0,0
0,0,0,0,0,0,0,0,0,0,0,0,0,0,0,0,0,0,0,0,0,0,0,0,0,0,0,0
0,0,0,0,0,0,0,0,0,0,0,0,0,0,0,0,0,0,0,0,0,0,0,0,0,0,0,0
0,0,0,0,0,0,0,0,0,0,0,0,0,0,0,0,0,0,0,0,0,0,0,0,0,0,0,0
0,0,0,0,0,0,0,0,0,0,0,0,0,0,0,0,0,0,0,0,0,0,0,0,0,0,0,0
0,0,0,0,0,134,0,0,0,0,0,0,0,0,0,0,0,0,0,0,0,0,134,0,0,0,0,0
0,0,0,0,0,0,0,0,0,0,0,0,0,0,0,0,0,0,0,0,0,0,0,0,0,0,0,0
0,0,0,0,0,0,0,0,101,0,0,0,0,0,0,0,0,0,0,101,0,0,0,0,0,0,0,0
0,0,0,0,0,0,0,101,0,0,0,0,0,0,0,0,0,0,0,0,101,0,0,0,0,0,0,0
0,0,0,0,0,0,0,0,0,0,0,99,132,132,132,132,99,0,0,0,0,0,0,0,0,0,0,0
0,0,0,0,0,0,0,0,0,0,30,1,1,6,6,1,1,30,0,0,0,0,0,0,0,0,0,0
0,0,0,0,0,0,0,0,0,99,1,1,1,1,1,1,1,1,99,0,0,0,0,0,0,0,0,0
0,0,0,0,0,0,0,0,0,132,1,1,1,1,1,1,1,1,132,0,0,0,0,0,0,0,0,0
0,0,0,0,0,0,0,0,0,132,6,1,1,1,1,1,1,6,132,0,0,0,0,0,0,0,0,0
0,0,0,0,0,0,0,0,0,132,6,1,1,1,1,1,1,6,132,0,0,0,0,0,0,0,0,0
0,0,0,0,0,0,0,0,0,132,1,1,1,1,1,1,1,1,132,0,0,0,0,0,0,0,0,0
0,0,0,0,0,0,0,0,0,99,1,1,1,1,1,1,1,1,99,0,0,0,0,0,0,0,0,0
0,0,0,0,0,0,0,0,0,0,30,1,1,6,6,1,1,30,0,0,0,0,0,0,0,0,0,0
0,0,0,0,0,0,0,0,0,0,0,99,132,132,132,132,99,0,0,0,0,0,0,0,0,0,0,0
0,0,0,0,0,0,0,101,0,0,0,0,0,0,0,0,0,0,0,0,101,0,0,0,0,0,0,0
0,0,0,0,0,0,0,0,101,0,0,0,0,0,0,0,0,0,0,101,0,0,0,0,0,0,0,0
0,0,0,0,0,0,0,0,0,0,0,0,0,0,0,0,0,0,0,0,0,0,0,0,0,0,0,0
0,0,0,0,0,0,0,0,0,0,0,0,0,0,0,0,0,0,0,0,0,0,0,0,0,0,0,0
0,0,0,0,0,0,0,0,0,0,0,0,0,0,0,0,0,0,0,0,0,0,0,0,0,0,0,0
0,0,0,0,0,0,0,0,0,0,0,0,0,0,0,0,0,0,0,0,0,0,0,0,0,0,0,0
0,0,0,0,0,134,0,0,0,0,0,0,0,0,0,0,0,0,0,0,0,0,134,0,0,0,0,0
0,0,0,0,0,0,0,0,0,0,0,0,0,0,0,0,0,0,0,0,0,0,0,0,0,0,0,0
0,0,0,0,0,0,0,0,0,0,0,0,0,0,0,0,0,0,0,0,0,0,0,0,0,0,0,0
0,0,0,0,0,0,0,0,0,0,0,0,0,0,0,0,0,0,0,0,0,0,0,0,0,0,0,0
0,0,0,0,0,0,0,0,0,0,0,0,0,0,0,0,0,0,0,0,0,0,0,0,0,0,0,0
0,0,0,0,0,0,0,0,0,0,0,0,0,0,0,0,0,0,0,0,0,0,0,0,0,0,0,0
:endlayer
layer: 19
0,0,0,0,0,0,0,0,0,0,0,0,0,0,0,0,0,0,0,0,0,0,0,0,0,0,0,0
0,0,0,0,0,0,0,0,0,0,0,0,0,0,0,0,0,0,0,0,0,0,0,0,0,0,0,0
0,0,0,0,0,0,0,0,0,0,0,0,0,0,0,0,0,0,0,0,0,0,0,0,0,0,0,0
0,0,0,0,0,0,0,0,0,0,0,0,0,0,0,0,0,0,0,0,0,0,0,0,0,0,0,0
0,0,0,0,0,0,0,0,0,0,0,0,0,0,0,0,0,0,0,0,0,0,0,0,0,0,0,0
0,0,0,0,0,0,0,0,0,0,0,0,0,0,0,0,0,0,0,0,0,0,0,0,0,0,0,0
0,0,0,0,0,135,0,0,0,0,0,0,0,0,0,0,0,0,0,0,0,0,135,0,0,0,0,0
0,0,0,0,0,0,0,0,0,0,0,0,0,0,0,0,0,0,0,0,0,0,0,0,0,0,0,0
0,0,0,0,0,0,0,0,0,0,0,0,0,0,0,0,0,0,0,0,0,0,0,0,0,0,0,0
0,0,0,0,0,0,0,0,0,0,0,0,0,0,0,0,0,0,0,0,0,0,0,0,0,0,0,0
0,0,0,0,0,0,0,0,0,0,0,132,6,132,132,6,132,0,0,0,0,0,0,0,0,0,0,0
0,0,0,0,0,0,0,0,0,0,6,132,132,132,132,132,132,6,0,0,0,0,0,0,0,0,0,0
0,0,0,0,0,0,0,0,0,132,132,132,132,132,132,132,132,132,132,0,0,0,0,0,0,0,0,0
0,0,0,0,0,0,0,0,0,6,132,132,132,132,132,132,132,132,6,0,0,0,0,0,0,0,0,0
0,0,0,0,0,0,0,0,0,132,132,132,132,132,132,132,132,132,132,0,0,0,0,0,0,0,0,0
0,0,0,0,0,0,0,0,0,132,132,132,132,132,132,132,132,132,132,0,0,0,0,0,0,0,0,0
0,0,0,0,0,0,0,0,0,6,132,132,132,132,132,132,132,132,6,0,0,0,0,0,0,0,0,0
0,0,0,0,0,0,0,0,0,132,132,132,132,132,132,132,132,132,132,0,0,0,0,0,0,0,0,0
0,0,0,0,0,0,0,0,0,0,6,132,132,132,132,132,132,6,0,0,0,0,0,0,0,0,0,0
0,0,0,0,0,0,0,0,0,0,0,132,6,132,132,6,132,0,0,0,0,0,0,0,0,0,0,0
0,0,0,0,0,0,0,0,0,0,0,0,0,0,0,0,0,0,0,0,0,0,0,0,0,0,0,0
0,0,0,0,0,0,0,0,0,0,0,0,0,0,0,0,0,0,0,0,0,0,0,0,0,0,0,0
0,0,0,0,0,0,0,0,0,0,0,0,0,0,0,0,0,0,0,0,0,0,0,0,0,0,0,0
0,0,0,0,0,0,0,0,0,0,0,0,0,0,0,0,0,0,0,0,0,0,0,0,0,0,0,0
0,0,0,0,0,0,0,0,0,0,0,0,0,0,0,0,0,0,0,0,0,0,0,0,0,0,0,0
0,0,0,0,0,0,0,0,0,0,0,0,0,0,0,0,0,0,0,0,0,0,0,0,0,0,0,0
0,0,0,0,0,135,0,0,0,0,0,0,0,0,0,0,0,0,0,0,0,0,135,0,0,0,0,0
0,0,0,0,0,0,0,0,0,0,0,0,0,0,0,0,0,0,0,0,0,0,0,0,0,0,0,0
0,0,0,0,0,0,0,0,0,0,0,0,0,0,0,0,0,0,0,0,0,0,0,0,0,0,0,0
0,0,0,0,0,0,0,0,0,0,0,0,0,0,0,0,0,0,0,0,0,0,0,0,0,0,0,0
0,0,0,0,0,0,0,0,0,0,0,0,0,0,0,0,0,0,0,0,0,0,0,0,0,0,0,0
0,0,0,0,0,0,0,0,0,0,0,0,0,0,0,0,0,0,0,0,0,0,0,0,0,0,0,0
:endlayer
layer: 20
0,0,0,0,0,0,0,0,0,0,0,0,0,0,0,0,0,0,0,0,0,0,0,0,0,0,0,0
0,0,0,0,0,0,0,0,0,0,0,0,0,0,0,0,0,0,0,0,0,0,0,0,0,0,0,0
0,0,0,0,0,0,0,0,0,0,0,0,0,0,0,0,0,0,0,0,0,0,0,0,0,0,0,0
0,0,0,0,0,0,0,0,0,0,0,0,0,0,0,0,0,0,0,0,0,0,0,0,0,0,0,0
0,0,0,0,0,0,0,0,0,0,0,0,0,0,0,0,0,0,0,0,0,0,0,0,0,0,0,0
0,0,0,0,0,0,0,0,0,0,0,0,0,0,0,0,0,0,0,0,0,0,0,0,0,0,0,0
0,0,0,0,0,136,137,137,0,0,0,0,0,0,0,0,0,0,0,0,0,0,136,137,137,0,0,0
0,0,0,0,0,0,0,0,137,0,0,0,0,0,0,0,0,0,0,0,0,0,0,0,0,137,137,0
0,0,0,0,0,0,0,0,0,0,0,0,0,0,0,0,0,0,0,0,0,0,0,0,0,0,0,0
0,0,0,0,0,0,0,0,0,0,0,0,0,0,0,0,0,0,0,0,0,0,0,0,0,0,0,0
0,0,0,0,0,0,0,0,0,0,0,132,132,6,6,132,132,0,0,0,0,0,0,0,0,0,0,0
0,0,0,0,0,0,0,0,0,0,132,132,132,132,132,132,132,132,0,0,0,0,0,0,0,0,0,0
0,0,0,0,0,0,0,0,0,132,132,132,132,132,132,132,132,132,132,0,0,0,0,0,0,0,0,0
0,0,0,0,0,0,0,0,0,132,132,132,132,132,132,132,132,132,132,0,0,0,0,0,0,0,0,0
0,0,0,0,0,0,0,0,0,6,132,132,132,132,132,132,132,132,6,0,0,0,0,0,0,0,0,0
0,0,0,0,0,0,0,0,0,6,132,132,132,132,132,132,132,132,6,0,0,0,0,0,0,0,0,0
0,0,0,0,0,0,0,0,0,132,132,132,132,132,132,132,132,132,132,0,0,0,0,0,0,0,0,0
0,0,0,0,0,0,0,0,0,132,132,132,132,132,132,132,132,132,132,0,0,0,0,0,0,0,0,0
0,0,0,0,0,0,0,0,0,0,132,132,132,132,132,132,132,132,0,0,0,0,0,0,0,0,0,0
0,0,0,0,0,0,0,0,0,0,0,132,132,6,6,132,132,0,0,0,0,0,0,0,0,0,0,0
0,0,0,0,0,0,0,0,0,0,0,0,0,0,0,0,0,0,0,0,0,0,0,0,0,0,0,0
0,0,0,0,0,0,0,0,0,0,0,0,0,0,0,0,0,0,0,0,0,0,0,0,0,0,0,0
0,0,0,0,0,0,0,0,0,0,0,0,0,0,0,0,0,0,0,0,0,0,0,0,0,0,0,0
0,0,0,0,0,0,0,0,0,0,0,0,0,0,0,0,0,0,0,0,0,0,0,0,0,0,0,0
0,0,0,0,0,0,0,0,0,0,0,0,0,0,0,0,0,0,0,0,0,0,0,0,0,0,0,0
0,0,0,0,0,0,0,0,0,0,0,0,0,0,0,0,0,0,0,0,0,0,0,0,0,0,0,0
0,0,0,0,0,136,137,0,0,0,0,0,0,0,0,0,0,0,0,0,0,0,136,137,0,0,0,0
0,0,0,0,0,0,0,137,137,137,0,0,0,0,0,0,0,0,0,0,0,0,0,0,137,137,0,0
0,0,0,0,0,0,0,0,0,0,0,0,0,0,0,0,0,0,0,0,0,0,0,0,0,0,0,0
0,0,0,0,0,0,0,0,0,0,0,0,0,0,0,0,0,0,0,0,0,0,0,0,0,0,0,0
0,0,0,0,0,0,0,0,0,0,0,0,0,0,0,0,0,0,0,0,0,0,0,0,0,0,0,0
0,0,0,0,0,0,0,0,0,0,0,0,0,0,0,0,0,0,0,0,0,0,0,0,0,0,0,0
:endlayer
layer: 21
0,0,0,0,0,0,0,0,0,0,0,0,0,0,0,0,0,0,0,0,0,0,0,0,0,0,0,0
0,0,0,0,0,0,0,0,0,0,0,0,0,0,0,0,0,0,0,0,0,0,0,0,0,0,0,0
0,0,0,0,0,0,0,0,0,0,0,0,0,0,0,0,0,0,0,0,0,0,0,0,0,0,0,0
0,0,0,0,0,0,0,0,0,0,0,0,0,0,0,0,0,0,0,0,0,0,0,0,0,0,0,0
0,0,0,0,0,0,0,0,0,0,0,0,0,0,0,0,0,0,0,0,0,0,0,0,0,0,0,0
0,0,0,0,0,0,0,0,0,0,0,0,0,0,0,0,0,0,0,0,0,0,0,0,0,0,0,0
0,0,0,0,0,138,137,0,0,0,0,0,0,0,0,0,0,0,0,0,0,0,138,137,0,0,0,0
0,0,0,0,0,0,0,137,137,137,0,0,0,0,0,0,0,0,0,0,0,0,0,0,137,137,0,0
0,0,0,0,0,0,0,0,0,0,0,0,0,0,0,0,0,0,0,0,0,0,0,0,0,0,0,0
0,0,0,0,0,0,0,0,0,0,0,0,0,0,0,0,0,0,0,0,0,0,0,0,0,0,0,0
0,0,0,0,0,0,0,0,0,0,0,19,132,132,132,132,19,0,0,0,0,0,0,0,0,0,0,0
0,0,0,0,0,0,0,0,0,0,0,132,132,132,132,132,132,0,0,0,0,0,0,0,0,0,0,0
0,0,0,0,0,0,0,0,0,19,132,132,132,132,132,132,132,132,19,0,0,0,0,0,0,0,0,0
0,0,0,0,0,0,0,0,0,132,132,132,132,132,132,132,132,132,132,0,0,0,0,0,0,0,0,0
0,0,0,0,0,0,0,0,0,132,132,132,132,132,132,132,132,132,132,0,0,0,0,0,0,0,0,0
0,0,0,0,0,0,0,0,0,132,132,132,132,132,132,132,132,132,132,0,0,0,0,0,0,0,0,0
0,0,0,0,0,0,0,0,0,132,132,132,132,132,132,132,132,132,132,0,0,0,0,0,0,0,0,0
0,0,0,0,0,0,0,0,0,19,132,132,132,132,132,132,132,132,19,0,0,0,0,0,0,0,0,0
0,0,0,0,0,0,0,0,0,0,0,132,132,132,132,132,132,0,0,0,0,0,0,0,0,0,0,0
0,0,0,0,0,0,0,0,0,0,0,19,132,132,132,132,19,0,0,0,0,0,0,0,0,0,0,0
0,0,0,0,0,0,0,0,0,0,0,0,0,0,0,0,0,0,0,0,0,0,0,0,0,0,0,0
0,0,0,0,0,0,0,0,0,0,0,0,0,0,0,0,0,0,0,0,0,0,0,0,0,0,0,0
0,0,0,0,0,0,0,0,0,0,0,0,0,0,0,0,0,0,0,0,0,0,0,0,0,0,0,0
0,0,0,0,0,0,0,0,0,0,0,0,0,0,0,0,0,0,0,0,0,0,0,0,0,0,0,0
0,0,0,0,0,0,0,0,0,0,0,0,0,0,0,0,0,0,0,0,0,0,0,0,0,0,0,0
0,0,0,0,0,0,0,0,0,0,0,0,0,0,0,0,0,0,0,0,0,0,0,0,0,0,0,0
0,0,0,0,0,138,137,137,0,0,0,0,0,0,0,0,0,0,0,0,0,0,138,137,137,0,0,0
0,0,0,0,0,0,0,0,137,0,0,0,0,0,0,0,0,0,0,0,0,0,0,0,0,137,137,0
0,0,0,0,0,0,0,0,0,0,0,0,0,0,0,0,0,0,0,0,0,0,0,0,0,0,0,0
0,0,0,0,0,0,0,0,0,0,0,0,0,0,0,0,0,0,0,0,0,0,0,0,0,0,0,0
0,0,0,0,0,0,0,0,0,0,0,0,0,0,0,0,0,0,0,0,0,0,0,0,0,0,0,0
0,0,0,0,0,0,0,0,0,0,0,0,0,0,0,0,0,0,0,0,0,0,0,0,0,0,0,0
:endlayer
layer: 22
0,0,0,0,0,0,0,0,0,0,0,0,0,0,0,0,0,0,0,0,0,0,0,0,0,0,0,0
0,0,0,0,0,0,0,0,0,0,0,0,0,0,0,0,0,0,0,0,0,0,0,0,0,0,0,0
0,0,0,0,0,0,0,0,0,0,0,0,0,0,0,0,0,0,0,0,0,0,0,0,0,0,0,0
0,0,0,0,0,0,0,0,0,0,0,0,0,0,0,0,0,0,0,0,0,0,0,0,0,0,0,0
0,0,0,0,0,0,0,0,0,0,0,0,0,0,0,0,0,0,0,0,0,0,0,0,0,0,0,0
0,0,0,0,0,0,0,0,0,0,0,0,0,0,0,0,0,0,0,0,0,0,0,0,0,0,0,0
0,0,0,0,0,0,0,0,0,0,0,0,0,0,0,0,0,0,0,0,0,0,0,0,0,0,0,0
0,0,0,0,0,0,0,0,0,0,0,0,0,0,0,0,0,0,0,0,0,0,0,0,0,0,0,0
0,0,0,0,0,0,0,0,0,0,0,0,0,0,0,0,0,0,0,0,0,0,0,0,0,0,0,0
0,0,0,0,0,0,0,0,0,0,0,0,0,0,0,0,0,0,0,0,0,0,0,0,0,0,0,0
0,0,0,0,0,0,0,0,0,0,0,0,0,0,0,0,0,0,0,0,0,0,0,0,0,0,0,0
0,0,0,0,0,0,0,0,0,0,0,0,19,132,132,19,0,0,0,0,0,0,0,0,0,0,0,0
0,0,0,0,0,0,0,0,0,0,0,132,132,132,132,132,132,0,0,0,0,0,0,0,0,0,0,0
0,0,0,0,0,0,0,0,0,0,19,132,132,132,132,132,132,19,0,0,0,0,0,0,0,0,0,0
0,0,0,0,0,0,0,0,0,0,132,132,132,132,132,132,132,132,0,0,0,0,0,0,0,0,0,0
0,0,0,0,0,0,0,0,0,0,132,132,132,132,132,132,132,132,0,0,0,0,0,0,0,0,0,0
0,0,0,0,0,0,0,0,0,0,19,132,132,132,132,132,132,19,0,0,0,0,0,0,0,0,0,0
0,0,0,0,0,0,0,0,0,0,0,132,132,132,132,132,132,0,0,0,0,0,0,0,0,0,0,0
0,0,0,0,0,0,0,0,0,0,0,0,19,132,132,19,0,0,0,0,0,0,0,0,0,0,0,0
0,0,0,0,0,0,0,0,0,0,0,0,0,0,0,0,0,0,0,0,0,0,0,0,0,0,0,0
0,0,0,0,0,0,0,0,0,0,0,0,0,0,0,0,0,0,0,0,0,0,0,0,0,0,0,0
0,0,0,0,0,0,0,0,0,0,0,0,0,0,0,0,0,0,0,0,0,0,0,0,0,0,0,0
0,0,0,0,0,0,0,0,0,0,0,0,0,0,0,0,0,0,0,0,0,0,0,0,0,0,0,0
0,0,0,0,0,0,0,0,0,0,0,0,0,0,0,0,0,0,0,0,0,0,0,0,0,0,0,0
0,0,0,0,0,0,0,0,0,0,0,0,0,0,0,0,0,0,0,0,0,0,0,0,0,0,0,0
0,0,0,0,0,0,0,0,0,0,0,0,0,0,0,0,0,0,0,0,0,0,0,0,0,0,0,0
0,0,0,0,0,0,0,0,0,0,0,0,0,0,0,0,0,0,0,0,0,0,0,0,0,0,0,0
0,0,0,0,0,0,0,0,0,0,0,0,0,0,0,0,0,0,0,0,0,0,0,0,0,0,0,0
0,0,0,0,0,0,0,0,0,0,0,0,0,0,0,0,0,0,0,0,0,0,0,0,0,0,0,0
0,0,0,0,0,0,0,0,0,0,0,0,0,0,0,0,0,0,0,0,0,0,0,0,0,0,0,0
0,0,0,0,0,0,0,0,0,0,0,0,0,0,0,0,0,0,0,0,0,0,0,0,0,0,0,0
0,0,0,0,0,0,0,0,0,0,0,0,0,0,0,0,0,0,0,0,0,0,0,0,0,0,0,0
:endlayer
layer: 23
0,0,0,0,0,0,0,0,0,0,0,0,0,0,0,0,0,0,0,0,0,0,0,0,0,0,0,0
0,0,0,0,0,0,0,0,0,0,0,0,0,0,0,0,0,0,0,0,0,0,0,0,0,0,0,0
0,0,0,0,0,0,0,0,0,0,0,0,0,0,0,0,0,0,0,0,0,0,0,0,0,0,0,0
0,0,0,0,0,0,0,0,0,0,0,0,0,0,0,0,0,0,0,0,0,0,0,0,0,0,0,0
0,0,0,0,0,0,0,0,0,0,0,0,0,0,0,0,0,0,0,0,0,0,0,0,0,0,0,0
0,0,0,0,0,0,0,0,0,0,0,0,0,0,0,0,0,0,0,0,0,0,0,0,0,0,0,0
0,0,0,0,0,0,0,0,0,0,0,0,0,0,0,0,0,0,0,0,0,0,0,0,0,0,0,0
0,0,0,0,0,0,0,0,0,0,0,0,0,0,0,0,0,0,0,0,0,0,0,0,0,0,0,0
0,0,0,0,0,0,0,0,0,0,0,0,0,0,0,0,0,0,0,0,0,0,0,0,0,0,0,0
0,0,0,0,0,0,0,0,0,0,0,0,0,0,0,0,0,0,0,0,0,0,0,0,0,0,0,0
0,0,0,0,0,0,0,0,0,0,0,0,0,0,0,0,0,0,0,0,0,0,0,0,0,0,0,0
0,0,0,0,0,0,0,0,0,0,0,0,0,0,0,0,0,0,0,0,0,0,0,0,0,0,0,0
0,0,0,0,0,0,0,0,0,0,0,0,0,19,19,0,0,0,0,0,0,0,0,0,0,0,0,0
0,0,0,0,0,0,0,0,0,0,0,0,19,132,132,19,0,0,0,0,0,0,0,0,0,0,0,0
0,0,0,0,0,0,0,0,0,0,0,19,132,132,132,132,19,0,0,0,0,0,0,0,0,0,0,0
0,0,0,0,0,0,0,0,0,0,0,19,132,132,132,132,19,0,0,0,0,0,0,0,0,0,0,0
0,0,0,0,0,0,0,0,0,0,0,0,19,132,132,19,0,0,0,0,0,0,0,0,0,0,0,0
0,0,0,0,0,0,0,0,0,0,0,0,0,19,19,0,0,0,0,0,0,0,0,0,0,0,0,0
0,0,0,0,0,0,0,0,0,0,0,0,0,0,0,0,0,0,0,0,0,0,0,0,0,0,0,0
0,0,0,0,0,0,0,0,0,0,0,0,0,0,0,0,0,0,0,0,0,0,0,0,0,0,0,0
0,0,0,0,0,0,0,0,0,0,0,0,0,0,0,0,0,0,0,0,0,0,0,0,0,0,0,0
0,0,0,0,0,0,0,0,0,0,0,0,0,0,0,0,0,0,0,0,0,0,0,0,0,0,0,0
0,0,0,0,0,0,0,0,0,0,0,0,0,0,0,0,0,0,0,0,0,0,0,0,0,0,0,0
0,0,0,0,0,0,0,0,0,0,0,0,0,0,0,0,0,0,0,0,0,0,0,0,0,0,0,0
0,0,0,0,0,0,0,0,0,0,0,0,0,0,0,0,0,0,0,0,0,0,0,0,0,0,0,0
0,0,0,0,0,0,0,0,0,0,0,0,0,0,0,0,0,0,0,0,0,0,0,0,0,0,0,0
0,0,0,0,0,0,0,0,0,0,0,0,0,0,0,0,0,0,0,0,0,0,0,0,0,0,0,0
0,0,0,0,0,0,0,0,0,0,0,0,0,0,0,0,0,0,0,0,0,0,0,0,0,0,0,0
0,0,0,0,0,0,0,0,0,0,0,0,0,0,0,0,0,0,0,0,0,0,0,0,0,0,0,0
0,0,0,0,0,0,0,0,0,0,0,0,0,0,0,0,0,0,0,0,0,0,0,0,0,0,0,0
0,0,0,0,0,0,0,0,0,0,0,0,0,0,0,0,0,0,0,0,0,0,0,0,0,0,0,0
0,0,0,0,0,0,0,0,0,0,0,0,0,0,0,0,0,0,0,0,0,0,0,0,0,0,0,0
:endlayer
layer: 24
0,0,0,0,0,0,0,0,0,0,0,0,0,0,0,0,0,0,0,0,0,0,0,0,0,0,0,0
0,0,0,0,0,0,0,0,0,0,0,0,0,0,0,0,0,0,0,0,0,0,0,0,0,0,0,0
0,0,0,0,0,0,0,0,0,0,0,0,0,0,0,0,0,0,0,0,0,0,0,0,0,0,0,0
0,0,0,0,0,0,0,0,0,0,0,0,0,0,0,0,0,0,0,0,0,0,0,0,0,0,0,0
0,0,0,0,0,0,0,0,0,0,0,0,0,0,0,0,0,0,0,0,0,0,0,0,0,0,0,0
0,0,0,0,0,0,0,0,0,0,0,0,0,0,0,0,0,0,0,0,0,0,0,0,0,0,0,0
0,0,0,0,0,0,0,0,0,0,0,0,0,0,0,0,0,0,0,0,0,0,0,0,0,0,0,0
0,0,0,0,0,0,0,0,0,0,0,0,0,0,0,0,0,0,0,0,0,0,0,0,0,0,0,0
0,0,0,0,0,0,0,0,0,0,0,0,0,0,0,0,0,0,0,0,0,0,0,0,0,0,0,0
0,0,0,0,0,0,0,0,0,0,0,0,0,0,0,0,0,0,0,0,0,0,0,0,0,0,0,0
0,0,0,0,0,0,0,0,0,0,0,0,0,0,0,0,0,0,0,0,0,0,0,0,0,0,0,0
0,0,0,0,0,0,0,0,0,0,0,0,0,0,0,0,0,0,0,0,0,0,0,0,0,0,0,0
0,0,0,0,0,0,0,0,0,0,0,0,0,0,0,0,0,0,0,0,0,0,0,0,0,0,0,0
0,0,0,0,0,0,0,0,0,0,0,0,0,0,0,0,0,0,0,0,0,0,0,0,0,0,0,0
0,0,0,0,0,0,0,0,0,0,0,0,0,30,30,0,0,0,0,0,0,0,0,0,0,0,0,0
0,0,0,0,0,0,0,0,0,0,0,0,0,30,30,0,0,0,0,0,0,0,0,0,0,0,0,0
0,0,0,0,0,0,0,0,0,0,0,0,0,0,0,0,0,0,0,0,0,0,0,0,0,0,0,0
0,0,0,0,0,0,0,0,0,0,0,0,0,0,0,0,0,0,0,0,0,0,0,0,0,0,0,0
0,0,0,0,0,0,0,0,0,0,0,0,0,0,0,0,0,0,0,0,0,0,0,0,0,0,0,0
0,0,0,0,0,0,0,0,0,0,0,0,0,0,0,0,0,0,0,0,0,0,0,0,0,0,0,0
0,0,0,0,0,0,0,0,0,0,0,0,0,0,0,0,0,0,0,0,0,0,0,0,0,0,0,0
0,0,0,0,0,0,0,0,0,0,0,0,0,0,0,0,0,0,0,0,0,0,0,0,0,0,0,0
0,0,0,0,0,0,0,0,0,0,0,0,0,0,0,0,0,0,0,0,0,0,0,0,0,0,0,0
0,0,0,0,0,0,0,0,0,0,0,0,0,0,0,0,0,0,0,0,0,0,0,0,0,0,0,0
0,0,0,0,0,0,0,0,0,0,0,0,0,0,0,0,0,0,0,0,0,0,0,0,0,0,0,0
0,0,0,0,0,0,0,0,0,0,0,0,0,0,0,0,0,0,0,0,0,0,0,0,0,0,0,0
0,0,0,0,0,0,0,0,0,0,0,0,0,0,0,0,0,0,0,0,0,0,0,0,0,0,0,0
0,0,0,0,0,0,0,0,0,0,0,0,0,0,0,0,0,0,0,0,0,0,0,0,0,0,0,0
0,0,0,0,0,0,0,0,0,0,0,0,0,0,0,0,0,0,0,0,0,0,0,0,0,0,0,0
0,0,0,0,0,0,0,0,0,0,0,0,0,0,0,0,0,0,0,0,0,0,0,0,0,0,0,0
0,0,0,0,0,0,0,0,0,0,0,0,0,0,0,0,0,0,0,0,0,0,0,0,0,0,0,0
0,0,0,0,0,0,0,0,0,0,0,0,0,0,0,0,0,0,0,0,0,0,0,0,0,0,0,0
:endlayer
layer: 25
0,0,0,0,0,0,0,0,0,0,0,0,0,0,0,0,0,0,0,0,0,0,0,0,0,0,0,0
0,0,0,0,0,0,0,0,0,0,0,0,0,0,0,0,0,0,0,0,0,0,0,0,0,0,0,0
0,0,0,0,0,0,0,0,0,0,0,0,0,0,0,0,0,0,0,0,0,0,0,0,0,0,0,0
0,0,0,0,0,0,0,0,0,0,0,0,0,0,0,0,0,0,0,0,0,0,0,0,0,0,0,0
0,0,0,0,0,0,0,0,0,0,0,0,0,0,0,0,0,0,0,0,0,0,0,0,0,0,0,0
0,0,0,0,0,0,0,0,0,0,0,0,0,0,0,0,0,0,0,0,0,0,0,0,0,0,0,0
0,0,0,0,0,0,0,0,0,0,0,0,0,0,0,0,0,0,0,0,0,0,0,0,0,0,0,0
0,0,0,0,0,0,0,0,0,0,0,0,0,0,0,0,0,0,0,0,0,0,0,0,0,0,0,0
0,0,0,0,0,0,0,0,0,0,0,0,0,0,0,0,0,0,0,0,0,0,0,0,0,0,0,0
0,0,0,0,0,0,0,0,0,0,0,0,0,0,0,0,0,0,0,0,0,0,0,0,0,0,0,0
0,0,0,0,0,0,0,0,0,0,0,0,0,0,0,0,0,0,0,0,0,0,0,0,0,0,0,0
0,0,0,0,0,0,0,0,0,0,0,0,0,0,0,0,0,0,0,0,0,0,0,0,0,0,0,0
0,0,0,0,0,0,0,0,0,0,0,0,0,0,0,0,0,0,0,0,0,0,0,0,0,0,0,0
0,0,0,0,0,0,0,0,0,0,0,0,0,0,0,0,0,0,0,0,0,0,0,0,0,0,0,0
0,0,0,0,0,0,0,0,0,0,0,0,0,30,30,0,0,0,0,0,0,0,0,0,0,0,0,0
0,0,0,0,0,0,0,0,0,0,0,0,0,30,30,0,0,0,0,0,0,0,0,0,0,0,0,0
0,0,0,0,0,0,0,0,0,0,0,0,0,0,0,0,0,0,0,0,0,0,0,0,0,0,0,0
0,0,0,0,0,0,0,0,0,0,0,0,0,0,0,0,0,0,0,0,0,0,0,0,0,0,0,0
0,0,0,0,0,0,0,0,0,0,0,0,0,0,0,0,0,0,0,0,0,0,0,0,0,0,0,0
0,0,0,0,0,0,0,0,0,0,0,0,0,0,0,0,0,0,0,0,0,0,0,0,0,0,0,0
0,0,0,0,0,0,0,0,0,0,0,0,0,0,0,0,0,0,0,0,0,0,0,0,0,0,0,0
0,0,0,0,0,0,0,0,0,0,0,0,0,0,0,0,0,0,0,0,0,0,0,0,0,0,0,0
0,0,0,0,0,0,0,0,0,0,0,0,0,0,0,0,0,0,0,0,0,0,0,0,0,0,0,0
0,0,0,0,0,0,0,0,0,0,0,0,0,0,0,0,0,0,0,0,0,0,0,0,0,0,0,0
0,0,0,0,0,0,0,0,0,0,0,0,0,0,0,0,0,0,0,0,0,0,0,0,0,0,0,0
0,0,0,0,0,0,0,0,0,0,0,0,0,0,0,0,0,0,0,0,0,0,0,0,0,0,0,0
0,0,0,0,0,0,0,0,0,0,0,0,0,0,0,0,0,0,0,0,0,0,0,0,0,0,0,0
0,0,0,0,0,0,0,0,0,0,0,0,0,0,0,0,0,0,0,0,0,0,0,0,0,0,0,0
0,0,0,0,0,0,0,0,0,0,0,0,0,0,0,0,0,0,0,0,0,0,0,0,0,0,0,0
0,0,0,0,0,0,0,0,0,0,0,0,0,0,0,0,0,0,0,0,0,0,0,0,0,0,0,0
0,0,0,0,0,0,0,0,0,0,0,0,0,0,0,0,0,0,0,0,0,0,0,0,0,0,0,0
0,0,0,0,0,0,0,0,0,0,0,0,0,0,0,0,0,0,0,0,0,0,0,0,0,0,0,0
:endlayer
layer: 26
0,0,0,0,0,0,0,0,0,0,0,0,0,0,0,0,0,0,0,0,0,0,0,0,0,0,0,0
0,0,0,0,0,0,0,0,0,0,0,0,0,0,0,0,0,0,0,0,0,0,0,0,0,0,0,0
0,0,0,0,0,0,0,0,0,0,0,0,0,0,0,0,0,0,0,0,0,0,0,0,0,0,0,0
0,0,0,0,0,0,0,0,0,0,0,0,0,0,0,0,0,0,0,0,0,0,0,0,0,0,0,0
0,0,0,0,0,0,0,0,0,0,0,0,0,0,0,0,0,0,0,0,0,0,0,0,0,0,0,0
0,0,0,0,0,0,0,0,0,0,0,0,0,0,0,0,0,0,0,0,0,0,0,0,0,0,0,0
0,0,0,0,0,0,0,0,0,0,0,0,0,0,0,0,0,0,0,0,0,0,0,0,0,0,0,0
0,0,0,0,0,0,0,0,0,0,0,0,0,0,0,0,0,0,0,0,0,0,0,0,0,0,0,0
0,0,0,0,0,0,0,0,0,0,0,0,0,0,0,0,0,0,0,0,0,0,0,0,0,0,0,0
0,0,0,0,0,0,0,0,0,0,0,0,0,0,0,0,0,0,0,0,0,0,0,0,0,0,0,0
0,0,0,0,0,0,0,0,0,0,0,0,0,0,0,0,0,0,0,0,0,0,0,0,0,0,0,0
0,0,0,0,0,0,0,0,0,0,0,0,0,0,0,0,0,0,0,0,0,0,0,0,0,0,0,0
0,0,0,0,0,0,0,0,0,0,0,0,0,0,0,0,0,0,0,0,0,0,0,0,0,0,0,0
0,0,0,0,0,0,0,0,0,0,0,0,0,0,0,0,0,0,0,0,0,0,0,0,0,0,0,0
0,0,0,0,0,0,0,0,0,0,0,0,0,30,30,0,0,0,0,0,0,0,0,0,0,0,0,0
0,0,0,0,0,0,0,0,0,0,0,0,0,30,30,0,0,0,0,0,0,0,0,0,0,0,0,0
0,0,0,0,0,0,0,0,0,0,0,0,0,0,0,0,0,0,0,0,0,0,0,0,0,0,0,0
0,0,0,0,0,0,0,0,0,0,0,0,0,0,0,0,0,0,0,0,0,0,0,0,0,0,0,0
0,0,0,0,0,0,0,0,0,0,0,0,0,0,0,0,0,0,0,0,0,0,0,0,0,0,0,0
0,0,0,0,0,0,0,0,0,0,0,0,0,0,0,0,0,0,0,0,0,0,0,0,0,0,0,0
0,0,0,0,0,0,0,0,0,0,0,0,0,0,0,0,0,0,0,0,0,0,0,0,0,0,0,0
0,0,0,0,0,0,0,0,0,0,0,0,0,0,0,0,0,0,0,0,0,0,0,0,0,0,0,0
0,0,0,0,0,0,0,0,0,0,0,0,0,0,0,0,0,0,0,0,0,0,0,0,0,0,0,0
0,0,0,0,0,0,0,0,0,0,0,0,0,0,0,0,0,0,0,0,0,0,0,0,0,0,0,0
0,0,0,0,0,0,0,0,0,0,0,0,0,0,0,0,0,0,0,0,0,0,0,0,0,0,0,0
0,0,0,0,0,0,0,0,0,0,0,0,0,0,0,0,0,0,0,0,0,0,0,0,0,0,0,0
0,0,0,0,0,0,0,0,0,0,0,0,0,0,0,0,0,0,0,0,0,0,0,0,0,0,0,0
0,0,0,0,0,0,0,0,0,0,0,0,0,0,0,0,0,0,0,0,0,0,0,0,0,0,0,0
0,0,0,0,0,0,0,0,0,0,0,0,0,0,0,0,0,0,0,0,0,0,0,0,0,0,0,0
0,0,0,0,0,0,0,0,0,0,0,0,0,0,0,0,0,0,0,0,0,0,0,0,0,0,0,0
0,0,0,0,0,0,0,0,0,0,0,0,0,0,0,0,0,0,0,0,0,0,0,0,0,0,0,0
0,0,0,0,0,0,0,0,0,0,0,0,0,0,0,0,0,0,0,0,0,0,0,0,0,0,0,0
:endlayer

#### RULES ####
rule:
plugin=vanillaBlocks
number=1
data:
JSON:{blockState:{blockName:"minecraft:sandstone",properties:{type:"sandstone"}}}
:enddata
:endrule

rule:
plugin=vanillaBlocks
number=2
data:
JSON:{blockState:{blockName:"minecraft:sand",properties:{variant:"sand"}}}
:enddata
:endrule

rule:
plugin=vanillaBlocks
number=3
data:
JSON:{blockState:{blockName:"minecraft:grass",properties:{snowy:"false"}}}
:enddata
:endrule

rule:
plugin=vanillaBlocks
number=4
data:
JSON:{blockState:{blockName:"minecraft:stained_hardened_clay",properties:{color:"red"}}}
:enddata
:endrule

rule:
plugin=vanillaBlocks
number=5
data:
JSON:{blockState:{blockName:"minecraft:hardened_clay"}}
:enddata
:endrule

rule:
plugin=vanillaBlocks
number=6
data:
JSON:{blockState:{blockName:"minecraft:red_sandstone",properties:{type:"red_sandstone"}}}
:enddata
:endrule

rule:
plugin=vanillaBlocks
number=7
data:
JSON:{blockState:{blockName:"minecraft:grass_path"}}
:enddata
:endrule

rule:
plugin=vanillaBlocks
number=8
data:
JSON:{blockState:{blockName:"minecraft:cactus",properties:{age:"0"}}}
:enddata
:endrule

rule:
plugin=vanillaBlocks
number=9
data:
JSON:{blockState:{blockName:"minecraft:leaves",properties:{check_decay:"false",decayable:"false",variant:"oak"}}}
:enddata
:endrule

rule:
plugin=vanillaBlocks
number=10
data:
JSON:{blockState:{blockName:"minecraft:stained_hardened_clay",properties:{color:"light_blue"}}}
:enddata
:endrule

rule:
plugin=vanillaBlocks
number=11
data:
JSON:{blockState:{blockName:"minecraft:red_sandstone_stairs",properties:{half:"bottom",shape:"straight",facing:"south"}}}
:enddata
:endrule

rule:
plugin=doors
number=12
data:
JSON:{blockState:{blockName:"minecraft:spruce_door",properties:{hinge:"left",half:"lower",powered:"false",facing:"south",open:"false"}}}
:enddata
:endrule

rule:
plugin=vanillaBlocks
number=13
data:
JSON:{blockState:{blockName:"minecraft:sandstone_stairs",properties:{half:"bottom",shape:"straight",facing:"west"}}}
:enddata
:endrule

rule:
plugin=vanillaBlocks
number=14
data:
JSON:{blockState:{blockName:"minecraft:sandstone_stairs",properties:{half:"bottom",shape:"straight",facing:"east"}}}
:enddata
:endrule

rule:
plugin=vanillaBlocks
number=15
data:
JSON:{blockState:{blockName:"minecraft:ladder",properties:{facing:"north"}}}
:enddata
:endrule

rule:
plugin=vanillaBlocks
number=16
data:
JSON:{blockState:{blockName:"minecraft:sandstone_stairs",properties:{half:"bottom",shape:"straight",facing:"north"}}}
:enddata
:endrule

rule:
plugin=vanillaBlocks
number=17
data:
JSON:{blockState:{blockName:"minecraft:dark_oak_fence",properties:{east:"false",south:"false",north:"false",west:"false"}}}
:enddata
:endrule

rule:
plugin=vanillaBlocks
number=18
data:
JSON:{blockState:{blockName:"minecraft:wooden_slab",properties:{half:"top",variant:"dark_oak"}}}
:enddata
:endrule

rule:
plugin=vanillaBlocks
number=19
data:
JSON:{blockState:{blockName:"minecraft:stone_slab2",properties:{half:"bottom",variant:"red_sandstone"}}}
:enddata
:endrule

rule:
plugin=vanillaBlocks
number=20
data:
JSON:{blockState:{blockName:"minecraft:red_sandstone_stairs",properties:{half:"bottom",shape:"straight",facing:"east"}}}
:enddata
:endrule

rule:
plugin=doors
number=21
data:
JSON:{blockState:{blockName:"minecraft:spruce_door",properties:{hinge:"left",half:"lower",powered:"false",facing:"east",open:"false"}}}
:enddata
:endrule

rule:
plugin=blockTile
number=22
data:
JSON:{blockState:{blockName:"ancientwarfarestructure:advanced_spawner",properties:{transparent:"true"}},teData:{id:"ancientwarfarestructure:advanced_spawner_tile",spawnerSettings:{minDelay:10,spawnDelay:5,lightSensitive:0b,spawnGroups:[{settingsList:[{remainingSpawnCount:1,hostile:1b,customTag:{ArmorDropChances:[0.085f,0.085f,0.085f,0.085f],hasCustomEquipment:0b,ArmorItems:[{},{},{},{}],skinSettings:{npcTypeName:"custom",skinTypeSelected:"default"},HandDropChances:[0.085f,0.085f],factionName:"sarkonid",tradeList:{tradeList:[{refillFrequency:6000,currentAvailable:200,inputItems:[{id:"ancientwarfarenpc:coin",Count:9b,tag:{metal:"copper"},slot:4,Damage:0s}],outputItems:[{id:"ancientwarfarenpc:coin",Count:1b,tag:{metal:"silver"},slot:4,Damage:0s}],refillTime:5603383L,maxAvailable:200},{refillFrequency:6000,currentAvailable:200,inputItems:[{id:"ancientwarfarenpc:coin",Count:1b,tag:{metal:"silver"},slot:4,Damage:0s}],outputItems:[{id:"ancientwarfarenpc:coin",Count:8b,tag:{metal:"copper"},slot:4,Damage:0s}],refillTime:5603383L,maxAvailable:200},{refillFrequency:6000,currentAvailable:200,inputItems:[{id:"ancientwarfarenpc:coin",Count:1b,tag:{metal:"gold"},slot:4,Damage:0s}],outputItems:[{id:"ancientwarfarenpc:coin",Count:8b,tag:{metal:"silver"},slot:4,Damage:0s}],refillTime:5603383L,maxAvailable:200},{refillFrequency:6000,currentAvailable:200,inputItems:[{id:"ancientwarfarenpc:coin",Count:9b,tag:{metal:"silver"},slot:4,Damage:0s}],outputItems:[{id:"ancientwarfarenpc:coin",Count:1b,tag:{metal:"gold"},slot:4,Damage:0s}],refillTime:5603383L,maxAvailable:200}]},HandItems:[{id:"minecraft:book",Count:1b,Damage:0s},{}]},maxToSpawn:1,entityId:"ancientwarfarenpc:faction.trader",minToSpawn:1}],groupWeight:1}],playerRange:16,respondToRedstone:0b,inventory:{Size:9,Items:[]},spawnRange:0,transparent:1b,maxDelay:10,spawnYOffset:0,xpToDrop:0,mobRange:0,debugMode:0b,maxNearbyMonsters:0}}}
:enddata
:endrule

rule:
plugin=vanillaBlocks
number=23
data:
JSON:{blockState:{blockName:"minecraft:planks",properties:{variant:"dark_oak"}}}
:enddata
:endrule

rule:
plugin=vanillaBlocks
number=24
data:
JSON:{blockState:{blockName:"minecraft:trapdoor",properties:{half:"top",facing:"west",open:"false"}}}
:enddata
:endrule

rule:
plugin=vanillaBlocks
number=25
data:
JSON:{blockState:{blockName:"minecraft:red_sandstone_stairs",properties:{half:"bottom",shape:"straight",facing:"north"}}}
:enddata
:endrule

rule:
plugin=doors
number=26
data:
JSON:{blockState:{blockName:"minecraft:dark_oak_door",properties:{hinge:"left",half:"lower",powered:"false",facing:"north",open:"true"}}}
:enddata
:endrule

rule:
plugin=vanillaBlocks
number=27
data:
JSON:{blockState:{blockName:"minecraft:tallgrass",properties:{type:"tall_grass"}}}
:enddata
:endrule

rule:
plugin=blockTile
number=28
data:
JSON:{blockState:{blockName:"ancientwarfarestructure:advanced_spawner",properties:{transparent:"true"}},teData:{id:"ancientwarfarestructure:advanced_spawner_tile",spawnerSettings:{minDelay:10,spawnDelay:10,lightSensitive:0b,spawnGroups:[{settingsList:[{remainingSpawnCount:1,hostile:1b,customTag:{ArmorDropChances:[0.085f,0.085f,0.085f,0.085f],hasCustomEquipment:0b,ArmorItems:[{},{},{},{}],skinSettings:{npcTypeName:"custom",skinTypeSelected:"default"},HandDropChances:[0.085f,0.085f],factionName:"sarkonid",HandItems:[{id:"ancientwarfarenpc:golden_spear",Count:1b,Damage:0s},{id:"ancientwarfarenpc:gold_shield",Count:1b,Damage:0s}]},maxToSpawn:1,entityId:"ancientwarfarenpc:faction.soldier",minToSpawn:1}],groupWeight:1}],playerRange:16,respondToRedstone:0b,inventory:{Size:9,Items:[]},spawnRange:0,transparent:1b,maxDelay:10,spawnYOffset:0,xpToDrop:0,mobRange:0,debugMode:0b,maxNearbyMonsters:0}}}
:enddata
:endrule

rule:
plugin=blockTile
number=29
data:
JSON:{blockState:{blockName:"ancientwarfarestructure:advanced_spawner",properties:{transparent:"true"}},teData:{id:"ancientwarfarestructure:advanced_spawner_tile",spawnerSettings:{minDelay:10,spawnDelay:7,lightSensitive:0b,spawnGroups:[{settingsList:[{remainingSpawnCount:1,hostile:1b,customTag:{ArmorDropChances:[0.085f,0.085f,0.085f,0.085f],hasCustomEquipment:0b,ArmorItems:[{},{},{},{}],skinSettings:{npcTypeName:"custom",skinTypeSelected:"default"},HandDropChances:[0.085f,0.085f],factionName:"sarkonid",HandItems:[{id:"ancientwarfarenpc:golden_spear",Count:1b,Damage:0s},{id:"ancientwarfarenpc:gold_shield",Count:1b,Damage:0s}]},maxToSpawn:1,entityId:"ancientwarfarenpc:faction.soldier",minToSpawn:1}],groupWeight:1}],playerRange:16,respondToRedstone:0b,inventory:{Size:9,Items:[]},spawnRange:0,transparent:1b,maxDelay:10,spawnYOffset:0,xpToDrop:0,mobRange:0,debugMode:0b,maxNearbyMonsters:0}}}
:enddata
:endrule

rule:
plugin=vanillaBlocks
number=30
data:
JSON:{blockState:{blockName:"minecraft:acacia_fence",properties:{east:"false",south:"false",north:"false",west:"false"}}}
:enddata
:endrule

rule:
plugin=blockTile
number=31
data:
JSON:{blockState:{blockName:"ancientwarfarestructure:gate_proxy"},teData:{lsb:-8212995647518127210L,id:"ancientwarfarestructure:gate_proxy_tile",msb:-3891632789406068878L,render:1b}}
:enddata
:endrule

rule:
plugin=blockTile
number=32
data:
JSON:{blockState:{blockName:"ancientwarfarestructure:gate_proxy"},teData:{lsb:-8212995647518127210L,id:"ancientwarfarestructure:gate_proxy_tile",msb:-3891632789406068878L,render:0b}}
:enddata
:endrule

rule:
plugin=blockTile
number=33
data:
JSON:{blockState:{blockName:"ancientwarfarestructure:gate_proxy"},teData:{lsb:-8212995647518127210L,id:"ancientwarfarestructure:gate_proxy_tile",msb:-3891632789406068878L,render:0b}}
:enddata
:endrule

rule:
plugin=blockTile
number=34
data:
JSON:{blockState:{blockName:"ancientwarfarestructure:gate_proxy"},teData:{lsb:-8212995647518127210L,id:"ancientwarfarestructure:gate_proxy_tile",msb:-3891632789406068878L,render:0b}}
:enddata
:endrule

rule:
plugin=blockTile
number=35
data:
JSON:{blockState:{blockName:"ancientwarfarestructure:gate_proxy"},teData:{lsb:-8212995647518127210L,id:"ancientwarfarestructure:gate_proxy_tile",msb:-3891632789406068878L,render:0b}}
:enddata
:endrule

rule:
plugin=blockTile
number=36
data:
JSON:{blockState:{blockName:"ancientwarfarestructure:gate_proxy"},teData:{lsb:-8212995647518127210L,id:"ancientwarfarestructure:gate_proxy_tile",msb:-3891632789406068878L,render:0b}}
:enddata
:endrule

rule:
plugin=vanillaBlocks
number=37
data:
JSON:{blockState:{blockName:"minecraft:red_flower",properties:{type:"orange_tulip"}}}
:enddata
:endrule

rule:
plugin=vanillaBlocks
number=38
data:
JSON:{blockState:{blockName:"minecraft:red_flower",properties:{type:"poppy"}}}
:enddata
:endrule

rule:
plugin=vanillaBlocks
number=39
data:
JSON:{blockState:{blockName:"minecraft:leaves",properties:{check_decay:"true",decayable:"false",variant:"oak"}}}
:enddata
:endrule

rule:
plugin=vanillaBlocks
number=40
data:
JSON:{blockState:{blockName:"minecraft:red_sandstone_stairs",properties:{half:"bottom",shape:"straight",facing:"west"}}}
:enddata
:endrule

rule:
plugin=vanillaBlocks
number=41
data:
JSON:{blockState:{blockName:"minecraft:stained_glass_pane",properties:{east:"false",color:"light_blue",south:"false",north:"false",west:"false"}}}
:enddata
:endrule

rule:
plugin=doors
number=42
data:
JSON:{blockState:{blockName:"minecraft:spruce_door",properties:{hinge:"right",half:"upper",powered:"false",facing:"north",open:"false"}}}
:enddata
:endrule

rule:
plugin=doors
number=43
data:
JSON:{blockState:{blockName:"minecraft:spruce_door",properties:{hinge:"left",half:"upper",powered:"false",facing:"north",open:"false"}}}
:enddata
:endrule

rule:
plugin=blockTile
number=44
data:
JSON:{blockState:{blockName:"ancientwarfarestructure:advanced_spawner",properties:{transparent:"true"}},teData:{id:"ancientwarfarestructure:advanced_spawner_tile",spawnerSettings:{minDelay:10,spawnDelay:2,lightSensitive:0b,spawnGroups:[{settingsList:[{remainingSpawnCount:1,hostile:1b,customTag:{ArmorDropChances:[0.085f,0.085f,0.085f,0.085f],hasCustomEquipment:0b,ArmorItems:[{},{},{},{}],skinSettings:{npcTypeName:"custom",skinTypeSelected:"default"},HandDropChances:[0.085f,0.085f],factionName:"sarkonid",HandItems:[{id:"ancientwarfarenpc:golden_lance",Count:1b,Damage:0s},{}]},maxToSpawn:1,entityId:"ancientwarfarenpc:faction.cavalry",minToSpawn:1}],groupWeight:1}],playerRange:16,respondToRedstone:0b,inventory:{Size:9,Items:[]},spawnRange:0,transparent:1b,maxDelay:10,spawnYOffset:0,xpToDrop:0,mobRange:0,debugMode:0b,maxNearbyMonsters:0}}}
:enddata
:endrule

rule:
plugin=blockTile
number=45
data:
JSON:{blockState:{blockName:"ancientwarfarestructure:advanced_spawner",properties:{transparent:"true"}},teData:{id:"ancientwarfarestructure:advanced_spawner_tile",spawnerSettings:{minDelay:10,spawnDelay:6,lightSensitive:0b,spawnGroups:[{settingsList:[{remainingSpawnCount:1,hostile:1b,customTag:{ArmorDropChances:[0.085f,0.085f,0.085f,0.085f],hasCustomEquipment:0b,ArmorItems:[{},{},{},{}],skinSettings:{npcTypeName:"custom",skinTypeSelected:"default"},HandDropChances:[0.085f,0.085f],factionName:"sarkonid",HandItems:[{id:"ancientwarfarenpc:golden_lance",Count:1b,Damage:0s},{}]},maxToSpawn:1,entityId:"ancientwarfarenpc:faction.cavalry",minToSpawn:1}],groupWeight:1}],playerRange:16,respondToRedstone:0b,inventory:{Size:9,Items:[]},spawnRange:0,transparent:1b,maxDelay:10,spawnYOffset:0,xpToDrop:0,mobRange:0,debugMode:0b,maxNearbyMonsters:0}}}
:enddata
:endrule

rule:
plugin=inventory
number=46
data:
JSON:{blockState:{blockName:"minecraft:chest",properties:{facing:"north"}},lootLevel:0,teData:{Items:[],id:"minecraft:chest",Lock:""},inventoryData:{length:0,inventoryContents:[]},legacyFeatures:1b}
:enddata
:endrule

rule:
plugin=inventory
number=47
data:
JSON:{blockState:{blockName:"minecraft:chest",properties:{facing:"north"}},lootLevel:0,teData:{Items:[],id:"minecraft:chest",Lock:""},inventoryData:{length:0,inventoryContents:[]},legacyFeatures:1b}
:enddata
:endrule

rule:
plugin=inventory
number=48
data:
JSON:{blockState:{blockName:"minecraft:chest",properties:{facing:"north"}},lootLevel:0,teData:{Items:[],id:"minecraft:chest",Lock:""},inventoryData:{length:0,inventoryContents:[]},legacyFeatures:1b}
:enddata
:endrule

rule:
plugin=inventory
number=49
data:
JSON:{blockState:{blockName:"minecraft:chest",properties:{facing:"north"}},lootLevel:0,teData:{Items:[],id:"minecraft:chest",Lock:""},inventoryData:{length:0,inventoryContents:[]},legacyFeatures:1b}
:enddata
:endrule

rule:
plugin=inventory
number=50
data:
JSON:{blockState:{blockName:"minecraft:chest",properties:{facing:"north"}},lootLevel:0,teData:{Items:[],id:"minecraft:chest",Lock:""},inventoryData:{length:0,inventoryContents:[]},legacyFeatures:1b}
:enddata
:endrule

rule:
plugin=inventory
number=51
data:
JSON:{blockState:{blockName:"minecraft:chest",properties:{facing:"north"}},lootLevel:0,teData:{Items:[],id:"minecraft:chest",Lock:""},inventoryData:{length:0,inventoryContents:[]},legacyFeatures:1b}
:enddata
:endrule

rule:
plugin=vanillaBlocks
number=52
data:
JSON:{blockState:{blockName:"minecraft:bookshelf"}}
:enddata
:endrule

rule:
plugin=doors
number=53
data:
JSON:{blockState:{blockName:"minecraft:dark_oak_door",properties:{hinge:"left",half:"upper",powered:"false",facing:"north",open:"false"}}}
:enddata
:endrule

rule:
plugin=doors
number=54
data:
JSON:{blockState:{blockName:"minecraft:dark_oak_door",properties:{hinge:"right",half:"upper",powered:"false",facing:"north",open:"false"}}}
:enddata
:endrule

rule:
plugin=vanillaBlocks
number=55
data:
JSON:{blockState:{blockName:"minecraft:cactus",properties:{age:"13"}}}
:enddata
:endrule

rule:
plugin=blockTile
number=56
data:
JSON:{blockState:{blockName:"ancientwarfarestructure:advanced_spawner",properties:{transparent:"true"}},teData:{id:"ancientwarfarestructure:advanced_spawner_tile",spawnerSettings:{minDelay:10,spawnDelay:10,lightSensitive:0b,spawnGroups:[{settingsList:[{remainingSpawnCount:1,hostile:1b,customTag:{ArmorDropChances:[0.085f,0.085f,0.085f,0.085f],hasCustomEquipment:0b,ArmorItems:[{},{},{},{}],skinSettings:{npcTypeName:"custom",skinTypeSelected:"default"},HandDropChances:[0.085f,0.085f],factionName:"sarkonid",HandItems:[{id:"ancientwarfarenpc:golden_lance",Count:1b,Damage:0s},{}]},maxToSpawn:1,entityId:"ancientwarfarenpc:faction.cavalry",minToSpawn:1}],groupWeight:1}],playerRange:16,respondToRedstone:0b,inventory:{Size:9,Items:[]},spawnRange:0,transparent:1b,maxDelay:10,spawnYOffset:0,xpToDrop:0,mobRange:0,debugMode:0b,maxNearbyMonsters:0}}}
:enddata
:endrule

rule:
plugin=blockTile
number=57
data:
JSON:{blockState:{blockName:"ancientwarfarestructure:advanced_spawner",properties:{transparent:"true"}},teData:{id:"ancientwarfarestructure:advanced_spawner_tile",spawnerSettings:{minDelay:10,spawnDelay:5,lightSensitive:0b,spawnGroups:[{settingsList:[{remainingSpawnCount:1,hostile:1b,customTag:{ArmorDropChances:[0.085f,0.085f,0.085f,0.085f],hasCustomEquipment:0b,ArmorItems:[{},{},{},{}],skinSettings:{npcTypeName:"custom",skinTypeSelected:"default"},HandDropChances:[0.085f,0.085f],factionName:"sarkonid",HandItems:[{id:"ancientwarfarenpc:golden_lance",Count:1b,Damage:0s},{}]},maxToSpawn:1,entityId:"ancientwarfarenpc:faction.cavalry",minToSpawn:1}],groupWeight:1}],playerRange:16,respondToRedstone:0b,inventory:{Size:9,Items:[]},spawnRange:0,transparent:1b,maxDelay:10,spawnYOffset:0,xpToDrop:0,mobRange:0,debugMode:0b,maxNearbyMonsters:0}}}
:enddata
:endrule

rule:
plugin=blockTile
number=58
data:
JSON:{blockState:{blockName:"ancientwarfarestructure:gate_proxy"},teData:{lsb:-8212995647518127210L,id:"ancientwarfarestructure:gate_proxy_tile",msb:-3891632789406068878L,render:0b}}
:enddata
:endrule

rule:
plugin=blockTile
number=59
data:
JSON:{blockState:{blockName:"ancientwarfarestructure:gate_proxy"},teData:{lsb:-8212995647518127210L,id:"ancientwarfarestructure:gate_proxy_tile",msb:-3891632789406068878L,render:0b}}
:enddata
:endrule

rule:
plugin=blockTile
number=60
data:
JSON:{blockState:{blockName:"ancientwarfarestructure:gate_proxy"},teData:{lsb:-8212995647518127210L,id:"ancientwarfarestructure:gate_proxy_tile",msb:-3891632789406068878L,render:0b}}
:enddata
:endrule

rule:
plugin=blockTile
number=61
data:
JSON:{blockState:{blockName:"ancientwarfarestructure:gate_proxy"},teData:{lsb:-8212995647518127210L,id:"ancientwarfarestructure:gate_proxy_tile",msb:-3891632789406068878L,render:0b}}
:enddata
:endrule

rule:
plugin=blockTile
number=62
data:
JSON:{blockState:{blockName:"ancientwarfarestructure:gate_proxy"},teData:{lsb:-8212995647518127210L,id:"ancientwarfarestructure:gate_proxy_tile",msb:-3891632789406068878L,render:0b}}
:enddata
:endrule

rule:
plugin=blockTile
number=63
data:
JSON:{blockState:{blockName:"ancientwarfarestructure:gate_proxy"},teData:{lsb:-8212995647518127210L,id:"ancientwarfarestructure:gate_proxy_tile",msb:-3891632789406068878L,render:0b}}
:enddata
:endrule

rule:
plugin=blockTile
number=64
data:
JSON:{blockState:{blockName:"ancientwarfarestructure:advanced_spawner",properties:{transparent:"true"}},teData:{id:"ancientwarfarestructure:advanced_spawner_tile",spawnerSettings:{minDelay:10,spawnDelay:9,lightSensitive:0b,spawnGroups:[{settingsList:[{remainingSpawnCount:1,hostile:1b,customTag:{ArmorDropChances:[0.085f,0.085f,0.085f,0.085f],hasCustomEquipment:0b,ArmorItems:[{},{},{},{}],skinSettings:{npcTypeName:"custom",skinTypeSelected:"default"},HandDropChances:[0.085f,0.085f],factionName:"sarkonid",HandItems:[{id:"ancientwarfarenpc:golden_spear",Count:1b,Damage:0s},{id:"ancientwarfarenpc:gold_shield",Count:1b,Damage:0s}]},maxToSpawn:1,entityId:"ancientwarfarenpc:faction.soldier",minToSpawn:1}],groupWeight:1}],playerRange:16,respondToRedstone:0b,inventory:{Size:9,Items:[]},spawnRange:0,transparent:1b,maxDelay:10,spawnYOffset:0,xpToDrop:0,mobRange:0,debugMode:0b,maxNearbyMonsters:0}}}
:enddata
:endrule

rule:
plugin=blockTile
number=65
data:
JSON:{blockState:{blockName:"ancientwarfarestructure:advanced_spawner",properties:{transparent:"true"}},teData:{id:"ancientwarfarestructure:advanced_spawner_tile",spawnerSettings:{minDelay:10,spawnDelay:10,lightSensitive:0b,spawnGroups:[{settingsList:[{remainingSpawnCount:1,hostile:1b,customTag:{ArmorDropChances:[0.085f,0.085f,0.085f,0.085f],hasCustomEquipment:0b,ArmorItems:[{},{},{},{}],skinSettings:{npcTypeName:"custom",skinTypeSelected:"default"},HandDropChances:[0.085f,0.085f],factionName:"sarkonid",HandItems:[{id:"ancientwarfarenpc:golden_spear",Count:1b,Damage:0s},{id:"ancientwarfarenpc:gold_shield",Count:1b,Damage:0s}]},maxToSpawn:1,entityId:"ancientwarfarenpc:faction.soldier",minToSpawn:1}],groupWeight:1}],playerRange:16,respondToRedstone:0b,inventory:{Size:9,Items:[]},spawnRange:0,transparent:1b,maxDelay:10,spawnYOffset:0,xpToDrop:0,mobRange:0,debugMode:0b,maxNearbyMonsters:0}}}
:enddata
:endrule

rule:
plugin=vanillaBlocks
number=66
data:
JSON:{blockState:{blockName:"minecraft:torch",properties:{facing:"east"}}}
:enddata
:endrule

rule:
plugin=vanillaBlocks
number=67
data:
JSON:{blockState:{blockName:"minecraft:torch",properties:{facing:"west"}}}
:enddata
:endrule

rule:
plugin=blockTile
number=68
data:
JSON:{blockState:{blockName:"ancientwarfarestructure:gate_proxy"},teData:{lsb:-8212995647518127210L,id:"ancientwarfarestructure:gate_proxy_tile",msb:-3891632789406068878L,render:0b}}
:enddata
:endrule

rule:
plugin=blockTile
number=69
data:
JSON:{blockState:{blockName:"ancientwarfarestructure:gate_proxy"},teData:{lsb:-8212995647518127210L,id:"ancientwarfarestructure:gate_proxy_tile",msb:-3891632789406068878L,render:0b}}
:enddata
:endrule

rule:
plugin=blockTile
number=70
data:
JSON:{blockState:{blockName:"ancientwarfarestructure:gate_proxy"},teData:{lsb:-8212995647518127210L,id:"ancientwarfarestructure:gate_proxy_tile",msb:-3891632789406068878L,render:0b}}
:enddata
:endrule

rule:
plugin=blockTile
number=71
data:
JSON:{blockState:{blockName:"ancientwarfarestructure:gate_proxy"},teData:{lsb:-8212995647518127210L,id:"ancientwarfarestructure:gate_proxy_tile",msb:-3891632789406068878L,render:0b}}
:enddata
:endrule

rule:
plugin=blockTile
number=72
data:
JSON:{blockState:{blockName:"ancientwarfarestructure:gate_proxy"},teData:{lsb:-8212995647518127210L,id:"ancientwarfarestructure:gate_proxy_tile",msb:-3891632789406068878L,render:0b}}
:enddata
:endrule

rule:
plugin=blockTile
number=73
data:
JSON:{blockState:{blockName:"ancientwarfarestructure:gate_proxy"},teData:{lsb:-8212995647518127210L,id:"ancientwarfarestructure:gate_proxy_tile",msb:-3891632789406068878L,render:0b}}
:enddata
:endrule

rule:
plugin=vanillaBlocks
number=74
data:
JSON:{blockState:{blockName:"minecraft:sandstone_stairs",properties:{half:"top",shape:"straight",facing:"north"}}}
:enddata
:endrule

rule:
plugin=vanillaBlocks
number=75
data:
JSON:{blockState:{blockName:"minecraft:sandstone_stairs",properties:{half:"top",shape:"straight",facing:"south"}}}
:enddata
:endrule

rule:
plugin=vanillaBlocks
number=76
data:
JSON:{blockState:{blockName:"minecraft:sandstone_stairs",properties:{half:"top",shape:"straight",facing:"west"}}}
:enddata
:endrule

rule:
plugin=vanillaBlocks
number=77
data:
JSON:{blockState:{blockName:"minecraft:sandstone_stairs",properties:{half:"top",shape:"straight",facing:"east"}}}
:enddata
:endrule

rule:
plugin=inventory
number=78
data:
JSON:{blockState:{blockName:"minecraft:chest",properties:{facing:"north"}},lootLevel:0,teData:{Items:[],id:"minecraft:chest",Lock:""},inventoryData:{length:0,inventoryContents:[]},legacyFeatures:1b}
:enddata
:endrule

rule:
plugin=inventory
number=79
data:
JSON:{blockState:{blockName:"minecraft:chest",properties:{facing:"north"}},lootLevel:0,teData:{Items:[],id:"minecraft:chest",Lock:""},inventoryData:{length:0,inventoryContents:[]},legacyFeatures:1b}
:enddata
:endrule

rule:
plugin=inventory
number=80
data:
JSON:{blockState:{blockName:"minecraft:chest",properties:{facing:"north"}},lootLevel:0,teData:{Items:[],id:"minecraft:chest",Lock:""},inventoryData:{length:0,inventoryContents:[]},legacyFeatures:1b}
:enddata
:endrule

rule:
plugin=inventory
number=81
data:
JSON:{blockState:{blockName:"minecraft:chest",properties:{facing:"north"}},lootLevel:0,teData:{Items:[],id:"minecraft:chest",Lock:""},inventoryData:{length:0,inventoryContents:[]},legacyFeatures:1b}
:enddata
:endrule

rule:
plugin=inventory
number=82
data:
JSON:{blockState:{blockName:"minecraft:chest",properties:{facing:"north"}},lootLevel:0,teData:{Items:[],id:"minecraft:chest",Lock:""},inventoryData:{length:0,inventoryContents:[]},legacyFeatures:1b}
:enddata
:endrule

rule:
plugin=inventory
number=83
data:
JSON:{blockState:{blockName:"minecraft:chest",properties:{facing:"north"}},lootLevel:0,teData:{Items:[],id:"minecraft:chest",Lock:""},inventoryData:{length:0,inventoryContents:[]},legacyFeatures:1b}
:enddata
:endrule

rule:
plugin=vanillaBlocks
number=84
data:
JSON:{blockState:{blockName:"minecraft:red_sandstone_stairs",properties:{half:"top",shape:"straight",facing:"east"}}}
:enddata
:endrule

rule:
plugin=vanillaBlocks
number=85
data:
JSON:{blockState:{blockName:"minecraft:red_sandstone_stairs",properties:{half:"top",shape:"straight",facing:"west"}}}
:enddata
:endrule

rule:
plugin=vanillaBlocks
number=86
data:
JSON:{blockState:{blockName:"minecraft:torch",properties:{facing:"south"}}}
:enddata
:endrule

rule:
plugin=vanillaBlocks
number=87
data:
JSON:{blockState:{blockName:"minecraft:torch",properties:{facing:"north"}}}
:enddata
:endrule

rule:
plugin=vanillaBlocks
number=88
data:
JSON:{blockState:{blockName:"minecraft:wooden_slab",properties:{half:"bottom",variant:"dark_oak"}}}
:enddata
:endrule

rule:
plugin=vanillaBlocks
number=89
data:
JSON:{blockState:{blockName:"minecraft:double_wooden_slab",properties:{variant:"dark_oak"}}}
:enddata
:endrule

rule:
plugin=vanillaBlocks
number=90
data:
JSON:{blockState:{blockName:"minecraft:red_sandstone_stairs",properties:{half:"top",shape:"straight",facing:"north"}}}
:enddata
:endrule

rule:
plugin=blockTile
number=91
data:
JSON:{blockState:{blockName:"ancientwarfarestructure:gate_proxy"},teData:{lsb:-8212995647518127210L,id:"ancientwarfarestructure:gate_proxy_tile",msb:-3891632789406068878L,render:0b}}
:enddata
:endrule

rule:
plugin=blockTile
number=92
data:
JSON:{blockState:{blockName:"ancientwarfarestructure:gate_proxy"},teData:{lsb:-8212995647518127210L,id:"ancientwarfarestructure:gate_proxy_tile",msb:-3891632789406068878L,render:0b}}
:enddata
:endrule

rule:
plugin=blockTile
number=93
data:
JSON:{blockState:{blockName:"ancientwarfarestructure:gate_proxy"},teData:{lsb:-8212995647518127210L,id:"ancientwarfarestructure:gate_proxy_tile",msb:-3891632789406068878L,render:0b}}
:enddata
:endrule

rule:
plugin=blockTile
number=94
data:
JSON:{blockState:{blockName:"ancientwarfarestructure:gate_proxy"},teData:{lsb:-8212995647518127210L,id:"ancientwarfarestructure:gate_proxy_tile",msb:-3891632789406068878L,render:0b}}
:enddata
:endrule

rule:
plugin=blockTile
number=95
data:
JSON:{blockState:{blockName:"ancientwarfarestructure:gate_proxy"},teData:{lsb:-8212995647518127210L,id:"ancientwarfarestructure:gate_proxy_tile",msb:-3891632789406068878L,render:0b}}
:enddata
:endrule

rule:
plugin=blockTile
number=96
data:
JSON:{blockState:{blockName:"ancientwarfarestructure:gate_proxy"},teData:{lsb:-8212995647518127210L,id:"ancientwarfarestructure:gate_proxy_tile",msb:-3891632789406068878L,render:0b}}
:enddata
:endrule

rule:
plugin=vanillaBlocks
number=97
data:
JSON:{blockState:{blockName:"minecraft:stone_slab",properties:{half:"top",variant:"sandstone"}}}
:enddata
:endrule

rule:
plugin=vanillaBlocks
number=98
data:
JSON:{blockState:{blockName:"minecraft:red_sandstone_stairs",properties:{half:"top",shape:"straight",facing:"south"}}}
:enddata
:endrule

rule:
plugin=vanillaBlocks
number=99
data:
JSON:{blockState:{blockName:"minecraft:stone_slab2",properties:{half:"top",variant:"red_sandstone"}}}
:enddata
:endrule

rule:
plugin=vanillaBlocks
number=100
data:
JSON:{blockState:{blockName:"minecraft:stained_hardened_clay",properties:{color:"blue"}}}
:enddata
:endrule

rule:
plugin=vanillaBlocks
number=101
data:
JSON:{blockState:{blockName:"minecraft:stone_slab",properties:{half:"bottom",variant:"sandstone"}}}
:enddata
:endrule

rule:
plugin=vanillaBlocks
number=102
data:
JSON:{blockState:{blockName:"minecraft:sandstone_stairs",properties:{half:"bottom",shape:"straight",facing:"south"}}}
:enddata
:endrule

rule:
plugin=vanillaBlocks
number=103
data:
JSON:{blockState:{blockName:"minecraft:trapdoor",properties:{half:"bottom",facing:"north",open:"false"}}}
:enddata
:endrule

rule:
plugin=blockTile
number=104
data:
JSON:{blockState:{blockName:"minecraft:jukebox",properties:{has_record:"false"}},teData:{id:"minecraft:jukebox"}}
:enddata
:endrule

rule:
plugin=vanillaBlocks
number=105
data:
JSON:{blockState:{blockName:"minecraft:crafting_table"}}
:enddata
:endrule

rule:
plugin=inventory
number=106
data:
JSON:{blockState:{blockName:"minecraft:chest",properties:{facing:"south"}},lootLevel:0,teData:{Items:[],id:"minecraft:chest",Lock:""},inventoryData:{length:0,inventoryContents:[]},legacyFeatures:1b}
:enddata
:endrule

rule:
plugin=vanillaBlocks
number=107
data:
JSON:{blockState:{blockName:"ancientwarfarestructure:table",properties:{leg_southwest:"true",leg_northwest:"true",variant:"oak",leg_northeast:"true",leg_southeast:"true"}}}
:enddata
:endrule

rule:
plugin=blockTile
number=108
data:
JSON:{blockState:{blockName:"ancientwarfarestructure:advanced_loot_chest",properties:{facing:"south"}},teData:{lootSettings:{lootRolls:1,splashPotion:0b,hasMessage:0b,hasLoot:1b,lootTableName:"ancientwarfare:chests/castle_treasury_high_value",spawnEntity:0b,entity:"minecraft:"},Items:[],id:"ancientwarfarestructure:advanced_loot_chest_tile",Lock:""}}
:enddata
:endrule

rule:
plugin=blockTile
number=109
data:
JSON:{blockState:{blockName:"ancientwarfarestructure:chair",properties:{visible:"true",variant:"oak",facing:"north"}},facing:"south",teData:{facing:"south",id:"ancientwarfarestructure:chair_tile"}}
:enddata
:endrule

rule:
plugin=blockTile
number=110
data:
JSON:{blockState:{blockName:"ancientwarfarestructure:chair",properties:{visible:"true",variant:"oak",facing:"north"}},facing:"south",teData:{facing:"south",id:"ancientwarfarestructure:chair_tile"}}
:enddata
:endrule

rule:
plugin=blockTile
number=111
data:
JSON:{blockState:{blockName:"ancientwarfarestructure:chair",properties:{visible:"true",variant:"oak",facing:"north"}},facing:"east",teData:{facing:"east",id:"ancientwarfarestructure:chair_tile"}}
:enddata
:endrule

rule:
plugin=blockTile
number=112
data:
JSON:{blockState:{blockName:"ancientwarfarestructure:chair",properties:{visible:"true",variant:"oak",facing:"north"}},facing:"west",teData:{facing:"west",id:"ancientwarfarestructure:chair_tile"}}
:enddata
:endrule

rule:
plugin=inventory
number=113
data:
JSON:{blockState:{blockName:"minecraft:chest",properties:{facing:"east"}},lootLevel:0,teData:{Items:[],id:"minecraft:chest",Lock:""},inventoryData:{length:0,inventoryContents:[]},legacyFeatures:1b}
:enddata
:endrule

rule:
plugin=blockTile
number=114
data:
JSON:{blockState:{blockName:"ancientwarfarestructure:chair",properties:{visible:"true",variant:"oak",facing:"north"}},facing:"north",teData:{facing:"north",id:"ancientwarfarestructure:chair_tile"}}
:enddata
:endrule

rule:
plugin=blockTile
number=115
data:
JSON:{blockState:{blockName:"ancientwarfarestructure:chair",properties:{visible:"true",variant:"oak",facing:"north"}},facing:"north",teData:{facing:"north",id:"ancientwarfarestructure:chair_tile"}}
:enddata
:endrule

rule:
plugin=inventory
number=116
data:
JSON:{blockState:{blockName:"minecraft:chest",properties:{facing:"west"}},lootLevel:0,teData:{Items:[],id:"minecraft:chest",Lock:""},inventoryData:{length:0,inventoryContents:[]},legacyFeatures:1b}
:enddata
:endrule

rule:
plugin=inventory
number=117
data:
JSON:{blockState:{blockName:"minecraft:chest",properties:{facing:"east"}},lootLevel:0,teData:{Items:[],id:"minecraft:chest",Lock:""},inventoryData:{length:0,inventoryContents:[]},legacyFeatures:1b}
:enddata
:endrule

rule:
plugin=inventory
number=118
data:
JSON:{blockState:{blockName:"minecraft:chest",properties:{facing:"west"}},lootLevel:0,teData:{Items:[],id:"minecraft:chest",Lock:""},inventoryData:{length:0,inventoryContents:[]},legacyFeatures:1b}
:enddata
:endrule

rule:
plugin=blockTile
number=119
data:
JSON:{blockState:{blockName:"ancientwarfarestructure:advanced_spawner",properties:{transparent:"true"}},teData:{id:"ancientwarfarestructure:advanced_spawner_tile",spawnerSettings:{minDelay:10,spawnDelay:6,lightSensitive:0b,spawnGroups:[{settingsList:[{remainingSpawnCount:1,hostile:1b,customTag:{ArmorDropChances:[0.085f,0.085f,0.085f,0.085f],hasCustomEquipment:0b,ArmorItems:[{},{},{},{}],skinSettings:{npcTypeName:"custom",skinTypeSelected:"default"},HandDropChances:[0.085f,0.085f],factionName:"sarkonid",HandItems:[{id:"minecraft:bow",Count:1b,Damage:0s},{}]},maxToSpawn:1,entityId:"ancientwarfarenpc:faction.archer",minToSpawn:1}],groupWeight:1}],playerRange:32,respondToRedstone:0b,inventory:{Size:9,Items:[]},spawnRange:0,transparent:1b,maxDelay:10,spawnYOffset:0,xpToDrop:0,mobRange:0,debugMode:0b,maxNearbyMonsters:0}}}
:enddata
:endrule

rule:
plugin=blockTile
number=120
data:
JSON:{blockState:{blockName:"ancientwarfarestructure:advanced_spawner",properties:{transparent:"true"}},teData:{id:"ancientwarfarestructure:advanced_spawner_tile",spawnerSettings:{minDelay:10,spawnDelay:8,lightSensitive:0b,spawnGroups:[{settingsList:[{remainingSpawnCount:1,hostile:1b,customTag:{ArmorDropChances:[0.085f,0.085f,0.085f,0.085f],hasCustomEquipment:0b,ArmorItems:[{},{},{},{}],skinSettings:{npcTypeName:"custom",skinTypeSelected:"default"},HandDropChances:[0.085f,0.085f],factionName:"sarkonid",HandItems:[{id:"minecraft:bow",Count:1b,Damage:0s},{}]},maxToSpawn:1,entityId:"ancientwarfarenpc:faction.archer",minToSpawn:1}],groupWeight:1}],playerRange:32,respondToRedstone:0b,inventory:{Size:9,Items:[]},spawnRange:0,transparent:1b,maxDelay:10,spawnYOffset:0,xpToDrop:0,mobRange:0,debugMode:0b,maxNearbyMonsters:0}}}
:enddata
:endrule

rule:
plugin=blockTile
number=121
data:
JSON:{blockState:{blockName:"ancientwarfarestructure:chair",properties:{visible:"false",variant:"oak",facing:"north"}},facing:"south",teData:{facing:"south",id:"ancientwarfarestructure:chair_tile",mainBlockPos:-190489181553492L}}
:enddata
:endrule

rule:
plugin=blockTile
number=122
data:
JSON:{blockState:{blockName:"ancientwarfarestructure:chair",properties:{visible:"false",variant:"oak",facing:"north"}},facing:"south",teData:{facing:"south",id:"ancientwarfarestructure:chair_tile",mainBlockPos:-189939425739604L}}
:enddata
:endrule

rule:
plugin=blockTile
number=123
data:
JSON:{blockState:{blockName:"ancientwarfarestructure:advanced_spawner",properties:{transparent:"true"}},teData:{id:"ancientwarfarestructure:advanced_spawner_tile",spawnerSettings:{minDelay:10,spawnDelay:9,lightSensitive:0b,spawnGroups:[{settingsList:[{remainingSpawnCount:1,hostile:1b,customTag:{ArmorDropChances:[0.085f,0.085f,0.085f,0.085f],hasCustomEquipment:0b,ArmorItems:[{},{},{},{}],skinSettings:{npcTypeName:"custom",skinTypeSelected:"default"},HandDropChances:[0.085f,0.085f],factionName:"sarkonid",HandItems:[{id:"minecraft:bow",Count:1b,Damage:0s},{}]},maxToSpawn:1,entityId:"ancientwarfarenpc:faction.archer",minToSpawn:1}],groupWeight:1}],playerRange:32,respondToRedstone:0b,inventory:{Size:9,Items:[]},spawnRange:0,transparent:1b,maxDelay:10,spawnYOffset:0,xpToDrop:0,mobRange:0,debugMode:0b,maxNearbyMonsters:0}}}
:enddata
:endrule

rule:
plugin=blockTile
number=124
data:
JSON:{blockState:{blockName:"ancientwarfarestructure:chair",properties:{visible:"false",variant:"oak",facing:"north"}},facing:"east",teData:{facing:"east",id:"ancientwarfarestructure:chair_tile",mainBlockPos:-191038937367378L}}
:enddata
:endrule

rule:
plugin=vanillaBlocks
number=125
data:
JSON:{blockState:{blockName:"minecraft:torch",properties:{facing:"up"}}}
:enddata
:endrule

rule:
plugin=blockTile
number=126
data:
JSON:{blockState:{blockName:"ancientwarfarestructure:chair",properties:{visible:"false",variant:"oak",facing:"north"}},facing:"west",teData:{facing:"west",id:"ancientwarfarestructure:chair_tile",mainBlockPos:-189389669925714L}}
:enddata
:endrule

rule:
plugin=blockTile
number=127
data:
JSON:{blockState:{blockName:"ancientwarfarestructure:advanced_spawner",properties:{transparent:"true"}},teData:{id:"ancientwarfarestructure:advanced_spawner_tile",spawnerSettings:{minDelay:10,spawnDelay:6,lightSensitive:0b,spawnGroups:[{settingsList:[{remainingSpawnCount:1,hostile:1b,customTag:{ArmorDropChances:[0.085f,0.085f,0.085f,0.085f],hasCustomEquipment:0b,ArmorItems:[{},{},{},{}],skinSettings:{npcTypeName:"custom",skinTypeSelected:"default"},HandDropChances:[0.085f,0.085f],factionName:"sarkonid",HandItems:[{id:"minecraft:bow",Count:1b,Damage:0s},{}]},maxToSpawn:1,entityId:"ancientwarfarenpc:faction.archer",minToSpawn:1}],groupWeight:1}],playerRange:32,respondToRedstone:0b,inventory:{Size:9,Items:[]},spawnRange:0,transparent:1b,maxDelay:10,spawnYOffset:0,xpToDrop:0,mobRange:0,debugMode:0b,maxNearbyMonsters:0}}}
:enddata
:endrule

rule:
plugin=blockTile
number=128
data:
JSON:{blockState:{blockName:"ancientwarfarestructure:chair",properties:{visible:"false",variant:"oak",facing:"north"}},facing:"north",teData:{facing:"north",id:"ancientwarfarestructure:chair_tile",mainBlockPos:-190489181553488L}}
:enddata
:endrule

rule:
plugin=blockTile
number=129
data:
JSON:{blockState:{blockName:"ancientwarfarestructure:chair",properties:{visible:"false",variant:"oak",facing:"north"}},facing:"north",teData:{facing:"north",id:"ancientwarfarestructure:chair_tile",mainBlockPos:-189939425739600L}}
:enddata
:endrule

rule:
plugin=blockTile
number=130
data:
JSON:{blockState:{blockName:"ancientwarfarestructure:advanced_spawner",properties:{transparent:"true"}},teData:{id:"ancientwarfarestructure:advanced_spawner_tile",spawnerSettings:{minDelay:10,spawnDelay:6,lightSensitive:0b,spawnGroups:[{settingsList:[{remainingSpawnCount:1,hostile:1b,customTag:{ArmorDropChances:[0.085f,0.085f,0.085f,0.085f],hasCustomEquipment:0b,ArmorItems:[{},{},{},{}],skinSettings:{npcTypeName:"custom",skinTypeSelected:"default"},HandDropChances:[0.085f,0.085f],factionName:"sarkonid",HandItems:[{id:"minecraft:bow",Count:1b,Damage:0s},{}]},maxToSpawn:1,entityId:"ancientwarfarenpc:faction.archer",minToSpawn:1}],groupWeight:1}],playerRange:32,respondToRedstone:0b,inventory:{Size:9,Items:[]},spawnRange:0,transparent:1b,maxDelay:10,spawnYOffset:0,xpToDrop:0,mobRange:0,debugMode:0b,maxNearbyMonsters:0}}}
:enddata
:endrule

rule:
plugin=blockTile
number=131
data:
JSON:{blockState:{blockName:"ancientwarfarestructure:advanced_spawner",properties:{transparent:"true"}},teData:{id:"ancientwarfarestructure:advanced_spawner_tile",spawnerSettings:{minDelay:10,spawnDelay:8,lightSensitive:0b,spawnGroups:[{settingsList:[{remainingSpawnCount:1,hostile:1b,customTag:{ArmorDropChances:[0.085f,0.085f,0.085f,0.085f],hasCustomEquipment:0b,ArmorItems:[{},{},{},{}],skinSettings:{npcTypeName:"custom",skinTypeSelected:"default"},HandDropChances:[0.085f,0.085f],factionName:"sarkonid",HandItems:[{id:"minecraft:bow",Count:1b,Damage:0s},{}]},maxToSpawn:1,entityId:"ancientwarfarenpc:faction.archer",minToSpawn:1}],groupWeight:1}],playerRange:32,respondToRedstone:0b,inventory:{Size:9,Items:[]},spawnRange:0,transparent:1b,maxDelay:10,spawnYOffset:0,xpToDrop:0,mobRange:0,debugMode:0b,maxNearbyMonsters:0}}}
:enddata
:endrule

rule:
plugin=vanillaBlocks
number=132
data:
JSON:{blockState:{blockName:"minecraft:stained_hardened_clay",properties:{color:"pink"}}}
:enddata
:endrule

rule:
plugin=vanillaBlocks
number=133
data:
JSON:{blockState:{blockName:"minecraft:sandstone",properties:{type:"smooth_sandstone"}}}
:enddata
:endrule

rule:
plugin=vanillaBlocks
number=134
data:
JSON:{blockState:{blockName:"ancientwarfarestructure:wooden_post",properties:{visible:"true",part:"bottom",facing:"east"}}}
:enddata
:endrule

rule:
plugin=vanillaBlocks
number=135
data:
JSON:{blockState:{blockName:"ancientwarfarestructure:wooden_post",properties:{visible:"false",part:"bottom",facing:"east"}}}
:enddata
:endrule

rule:
plugin=vanillaBlocks
number=136
data:
JSON:{blockState:{blockName:"ancientwarfarestructure:wooden_post",properties:{visible:"true",part:"top",facing:"east"}}}
:enddata
:endrule

rule:
plugin=vanillaBlocks
number=137
data:
JSON:{blockState:{blockName:"minecraft:wool",properties:{color:"red"}}}
:enddata
:endrule

rule:
plugin=vanillaBlocks
number=138
data:
JSON:{blockState:{blockName:"ancientwarfarestructure:wooden_post",properties:{visible:"false",part:"top",facing:"east"}}}
:enddata
:endrule

#### ENTITIES ####
entity:
plugin=vanillaHangingEntity
number=0
data:
JSON:{yOffset:0.5f,xOffset:-0.0f,rotation:0.0f,mobID:"minecraft:painting",zOffset:0.03125f,position:3848760459275L,entityData:{Motion:[0.0d,0.0d,0.0d],Facing:0b,ForgeData:{},Invulnerable:0b,Air:300s,OnGround:0b,Dimension:0,PortalCooldown:0,Rotation:[0.0f,0.0f],UpdateBlocked:0b,FallDistance:0.0f,Motive:"Skeleton",Pos:[-691.0d,13.5d,-854.96875d],Fire:-1s,ForgeCaps:{},TileY:13,TileX:-692,TileZ:-855},direction:0b,hangingOffset:-274877906944L}
:enddata
:endentity

entity:
plugin=awGate
number=1
data:
JSON:{owner:"",orientation:2b,pos1:{x:-3,y:0,z:0},pos2:{x:2,y:3,z:0},position:3848626241563L,gateType:"gate.doubleWood"}
:enddata
:endentity

