# Ancient Warfare Structure Template File
# Auto-generated structure template file. created on: 12/12/2023 at: 12:0:47
# Lines beginning with # denote comments

header:
version=2.11
name=SarkonidTownGenInn
mods=
size=26,17,33
offset=14,5,31
:endheader

#### VALIDATION ####
validation:
type=ground
structureAuthor=TheOddlySeagull
survival=false
worldGenEnabled=false
unique=false
preserveBlocks=false
preventNaturalHostileSpawns=true
selectionWeight=1
clusterValue=1
minDuplicateDistance=1
dimensionWhiteList=true
dimensionList=
biomeGroupList=
biomeWhiteList=true
biomeList=
leveling=0
fill=0
border=0
blockSwap=false
territoryName=
biomeReplacement=minecraft:
minGenerationHeight=0
maxGenerationHeight=255
:endvalidation

#### LAYERS ####
layer: 0
1,1,1,1,1,1,1,1,1,1,1,1,1,1,1,1,1,1,1,1,1,1,1,1,1,1
1,1,1,1,1,1,1,1,1,1,1,1,1,1,1,1,1,1,1,1,1,1,1,1,1,1
1,1,1,1,1,1,1,1,1,1,1,1,1,1,1,1,1,1,1,1,1,1,1,1,1,1
1,1,1,1,1,1,1,1,1,1,1,1,1,1,1,1,1,1,1,1,1,1,1,1,1,1
1,1,1,1,1,1,1,1,1,1,1,1,1,1,1,1,1,1,1,1,1,1,1,1,1,1
1,1,1,1,1,1,1,1,1,1,1,1,1,1,1,1,1,1,1,1,1,1,1,1,1,1
1,1,1,1,1,1,1,1,1,1,1,1,1,1,1,1,1,1,1,1,1,1,1,1,1,1
1,1,1,1,1,1,1,1,1,1,1,1,1,1,1,1,1,1,1,1,1,1,1,1,1,1
1,1,1,1,1,1,1,1,1,1,1,1,1,1,1,1,1,1,1,1,1,1,1,1,1,1
1,1,1,1,1,1,1,1,1,1,1,1,1,1,1,1,1,1,1,1,1,1,1,1,1,1
1,1,1,1,1,1,1,1,1,1,1,1,1,1,1,1,1,1,1,1,1,1,1,1,1,1
1,1,1,1,1,1,1,1,1,1,1,1,1,1,1,1,1,1,1,1,1,1,1,1,1,1
1,1,1,1,1,1,1,1,1,1,1,1,1,1,1,1,1,1,1,1,1,1,1,1,1,1
1,1,1,1,1,1,1,1,1,1,1,1,1,1,1,1,1,1,1,1,1,1,1,1,1,1
1,1,1,1,1,1,1,1,1,1,1,1,1,1,1,1,1,1,1,1,1,1,1,1,1,1
1,1,1,1,1,1,1,1,1,1,1,1,1,1,1,1,1,1,1,1,1,1,1,1,1,1
1,1,1,1,1,1,1,1,1,1,1,1,1,1,1,1,1,1,1,1,1,1,1,1,1,1
1,1,1,1,1,1,1,1,1,1,1,1,1,1,1,1,1,1,1,1,1,1,1,1,1,1
1,1,1,1,1,1,1,1,1,1,1,1,1,1,1,1,1,1,1,1,1,1,1,1,1,1
1,1,1,1,1,1,1,1,1,1,1,1,1,1,1,1,1,1,1,1,1,1,1,1,1,1
1,1,1,1,1,1,1,1,1,1,1,1,1,1,1,1,1,1,1,1,1,1,1,1,1,1
1,1,1,1,1,1,1,1,1,1,1,1,1,1,1,1,1,1,1,1,1,1,1,1,1,1
1,1,1,1,1,1,1,1,1,1,1,1,1,1,1,1,1,1,1,1,1,1,1,1,1,1
1,1,1,1,1,1,1,1,1,1,1,1,1,1,1,1,1,1,1,1,1,1,1,1,1,1
1,1,1,1,1,1,1,1,1,1,1,1,1,1,1,1,1,1,1,1,1,1,1,1,1,1
1,1,1,1,1,1,1,1,1,1,1,1,1,1,1,1,1,1,1,1,1,1,1,1,1,1
1,1,1,1,1,1,1,1,1,1,1,1,1,1,1,1,1,1,1,1,1,1,1,1,1,1
1,1,1,1,1,1,1,1,1,1,1,1,1,1,1,1,1,1,1,1,1,1,1,1,1,1
1,1,1,1,1,1,1,1,1,1,1,1,1,1,1,1,1,1,1,1,1,1,1,1,1,1
1,1,1,1,1,1,1,1,1,1,1,1,1,1,1,1,1,1,1,1,1,1,1,1,1,1
1,1,1,1,1,1,1,1,1,1,1,1,1,1,1,1,1,1,1,1,1,1,1,1,1,1
1,1,1,1,1,1,1,1,1,1,1,1,1,1,1,1,1,1,1,1,1,1,1,1,1,1
1,1,1,1,1,1,1,1,1,1,1,1,1,1,1,1,1,1,1,1,1,1,1,1,1,1
:endlayer
layer: 1
1,1,1,1,1,1,1,1,1,1,1,1,1,1,1,1,1,1,1,1,1,1,1,1,1,1
1,1,1,1,1,1,1,1,1,1,1,1,1,1,1,1,1,1,1,1,1,1,1,1,1,1
1,1,1,1,1,1,1,1,1,1,1,1,1,1,1,1,1,1,1,1,1,1,1,1,1,1
1,1,1,1,1,1,1,1,1,1,1,1,1,1,1,1,1,1,1,1,1,1,1,1,1,1
1,1,1,1,1,1,1,1,1,1,1,1,1,1,1,1,1,1,1,1,1,1,1,1,1,1
1,1,1,1,1,1,1,1,1,1,1,1,1,1,1,1,1,1,1,1,1,1,1,1,1,1
1,1,1,1,1,1,1,1,1,1,1,1,1,1,1,1,1,1,1,1,1,1,1,1,1,1
1,1,1,1,1,1,1,1,1,1,1,1,1,1,1,1,1,1,1,1,1,1,1,1,1,1
1,1,1,1,1,1,1,1,1,1,1,1,1,1,1,1,1,1,1,1,1,1,1,1,1,1
1,1,1,1,1,1,1,1,1,1,1,1,1,1,1,1,1,1,1,1,1,1,1,1,1,1
1,1,1,1,1,1,1,1,1,1,1,1,1,1,1,1,1,1,1,1,1,1,1,1,1,1
1,1,1,1,1,1,1,1,1,1,1,1,1,1,1,1,1,1,1,1,1,1,1,1,1,1
1,1,1,1,1,1,1,1,1,1,1,1,1,1,1,1,1,1,1,1,1,1,1,1,1,1
1,1,1,1,1,1,1,1,1,1,1,1,1,1,1,1,1,1,1,1,1,1,1,1,1,1
1,1,1,1,1,1,1,1,1,1,1,1,1,1,1,1,1,1,1,1,1,1,1,1,1,1
1,1,1,1,1,1,1,1,1,1,1,1,1,1,1,1,1,1,1,1,1,1,1,1,1,1
1,1,1,1,1,1,1,1,1,1,1,1,1,1,1,1,1,1,1,1,1,1,1,1,1,1
1,1,1,1,1,1,1,1,1,1,1,1,1,1,1,1,1,1,1,1,1,1,1,1,1,1
1,1,1,1,1,1,1,1,1,1,1,1,1,1,1,1,1,1,1,1,1,1,1,1,1,1
1,1,1,1,1,1,1,1,1,1,1,1,1,1,1,1,1,1,1,1,1,1,1,1,1,1
1,1,1,1,1,1,1,1,1,1,1,1,1,1,1,1,1,1,1,1,1,1,1,1,1,1
1,1,1,1,1,1,1,1,1,1,1,1,1,1,1,1,1,1,1,1,1,1,1,1,1,1
1,1,1,1,1,1,1,1,1,1,1,1,1,1,1,1,1,1,1,1,1,1,1,1,1,1
1,1,1,1,1,1,1,1,1,1,1,1,1,1,1,1,1,1,1,1,1,1,1,1,1,1
1,1,1,1,1,1,1,1,1,1,1,1,1,1,1,1,1,1,1,1,1,1,1,1,1,1
1,1,1,1,1,1,1,1,1,1,1,1,1,1,1,1,1,1,1,2,1,1,1,1,1,1
1,1,1,1,1,1,1,1,1,1,1,1,1,1,1,1,1,1,2,2,1,1,1,1,1,1
1,1,1,1,1,1,1,1,1,1,1,1,1,1,1,1,1,1,1,1,1,1,1,1,1,1
1,1,1,1,1,1,1,1,1,1,1,1,1,1,1,1,1,1,1,1,1,1,1,1,1,1
1,1,1,1,1,1,1,1,1,1,1,1,1,1,1,1,1,1,1,1,1,1,1,1,1,1
1,1,1,1,1,1,1,1,1,1,1,1,1,1,1,1,1,1,1,1,1,1,1,1,1,1
1,1,1,1,1,1,1,1,1,1,1,1,1,1,1,1,1,1,1,1,1,1,1,1,1,1
1,1,1,1,1,1,1,1,1,1,1,1,1,1,1,1,1,1,1,1,1,1,1,1,1,1
:endlayer
layer: 2
1,1,1,1,1,1,1,1,1,1,1,1,1,1,1,1,1,1,1,1,1,1,1,1,1,1
1,1,1,1,1,1,1,1,1,1,1,1,1,1,1,1,1,1,1,1,1,1,1,1,1,1
1,1,1,1,1,1,1,1,1,1,1,1,1,1,1,1,1,1,1,1,1,1,1,1,1,1
1,1,1,1,1,1,1,1,1,1,1,1,1,1,1,1,1,1,1,1,1,1,1,1,1,1
1,1,1,1,1,1,1,1,1,1,1,1,1,1,1,1,1,1,1,1,1,1,1,1,1,1
1,1,1,1,1,1,1,1,1,1,1,1,1,1,1,1,1,1,1,1,1,1,1,1,1,1
1,1,1,1,1,1,1,1,1,1,1,1,1,1,1,1,1,1,1,1,1,1,1,1,1,1
1,1,1,1,1,1,1,1,1,1,1,1,1,1,1,1,1,1,1,1,1,1,1,1,1,1
1,1,1,1,1,1,1,1,1,1,1,1,1,1,1,1,1,1,1,1,1,1,1,1,1,1
1,1,1,1,1,1,1,1,1,1,1,1,1,1,1,1,1,1,1,1,1,1,1,1,1,1
1,1,1,1,1,1,1,1,1,1,1,1,1,1,1,1,1,1,1,1,1,1,1,1,1,1
1,1,1,1,1,1,1,1,1,1,1,1,1,1,1,1,1,1,1,1,1,1,1,1,1,1
1,1,1,1,1,1,1,1,1,1,1,1,1,1,1,1,1,1,1,1,1,1,1,1,1,1
1,1,1,1,1,1,1,1,1,1,1,1,1,1,1,1,1,1,1,1,1,1,1,1,1,1
1,1,1,1,1,1,1,1,1,1,1,1,1,1,1,1,1,1,1,1,1,1,1,1,1,1
1,1,1,1,1,1,1,1,1,1,1,1,1,1,1,1,1,1,1,1,1,1,1,1,1,1
1,1,1,1,1,1,1,1,1,1,1,1,1,1,1,1,1,1,1,1,1,1,1,1,1,1
1,1,1,1,1,1,1,1,1,1,1,1,1,1,1,1,1,1,1,1,1,1,1,1,1,1
1,1,1,1,1,1,1,1,1,1,1,1,1,1,1,1,1,1,1,1,1,1,1,1,1,1
1,1,1,1,1,1,1,1,1,1,1,1,1,1,1,1,1,1,1,1,1,1,1,1,1,1
1,1,1,1,1,1,1,1,1,1,1,1,1,1,1,1,1,1,1,1,1,1,1,1,1,1
1,1,1,1,1,1,1,1,1,1,1,1,1,1,1,1,1,1,1,1,1,1,1,1,1,1
1,1,1,1,1,1,1,1,1,1,1,1,1,1,1,1,1,1,1,1,1,1,1,1,1,1
1,1,1,1,1,1,1,1,1,1,1,1,1,1,1,1,1,1,1,1,1,1,1,1,1,1
1,1,1,1,1,1,1,1,1,1,1,1,1,1,1,1,1,1,1,1,1,1,1,1,1,1
1,1,1,1,1,1,1,1,1,1,1,1,1,1,1,1,1,1,2,2,1,1,1,1,1,1
1,1,1,1,1,1,1,1,1,1,1,1,1,1,1,1,1,1,2,2,1,1,1,1,1,1
1,1,1,1,1,1,1,1,1,1,1,1,1,1,1,1,1,1,1,1,1,1,1,1,1,1
1,1,1,1,1,1,1,1,1,1,1,1,1,1,1,1,1,1,1,1,1,1,1,1,1,1
1,1,1,1,1,1,1,1,1,1,1,1,1,1,1,1,1,1,1,1,1,1,1,1,1,1
1,1,1,1,1,1,1,1,1,1,1,1,1,1,1,1,1,1,1,1,1,1,1,1,1,1
1,1,1,1,1,1,1,1,1,1,1,1,1,1,1,1,1,1,1,1,1,1,1,1,1,1
1,1,1,1,1,1,1,1,1,1,1,1,1,1,1,1,1,1,1,1,1,1,1,1,1,1
:endlayer
layer: 3
3,3,3,3,3,3,3,3,3,3,3,3,3,3,3,3,3,3,3,3,3,3,3,3,3,3
3,3,3,3,3,3,3,3,3,3,3,3,3,3,3,3,3,3,3,3,3,3,3,3,3,3
3,3,3,3,3,3,3,3,3,3,3,3,3,3,3,3,3,3,3,3,3,3,3,3,3,3
3,3,3,3,3,3,3,3,3,3,3,3,3,3,3,3,3,3,3,3,1,1,1,1,3,3
3,3,3,3,3,3,3,3,3,3,3,3,3,3,3,3,3,3,3,3,3,3,3,1,3,3
3,3,3,3,3,3,3,3,3,3,3,3,3,3,3,3,3,3,3,3,3,3,3,1,3,3
3,3,3,1,1,1,1,1,1,3,3,3,3,3,3,3,3,3,3,3,1,1,1,1,3,3
3,3,3,1,3,3,3,3,1,3,3,3,3,3,3,3,3,3,3,3,3,3,3,1,3,3
3,3,3,1,3,3,3,3,1,3,3,3,3,3,3,3,3,3,3,3,3,3,3,1,3,3
3,3,3,1,3,3,3,3,1,1,1,1,1,1,1,3,3,3,1,1,1,1,1,1,3,3
3,3,3,1,3,3,3,3,1,3,3,3,3,3,1,3,3,3,1,3,3,3,3,1,3,3
3,3,3,1,3,3,3,3,1,3,3,3,3,3,1,3,3,3,1,3,3,3,3,1,3,3
3,3,3,1,1,1,1,1,1,3,3,3,3,3,1,3,3,3,1,3,3,3,3,1,3,3
3,3,3,1,3,3,3,3,1,3,3,3,3,3,1,3,3,3,1,3,3,3,3,1,3,3
3,3,3,1,3,3,3,3,1,1,1,1,1,1,1,3,3,3,1,3,3,3,3,1,3,3
3,3,3,1,3,3,3,3,1,3,3,3,3,3,3,3,3,3,1,3,3,3,3,1,3,3
3,3,3,1,3,3,3,3,1,3,3,3,3,3,3,3,3,3,1,3,3,3,3,1,3,3
3,3,3,1,3,3,3,3,1,3,3,3,3,3,3,3,3,3,1,3,3,3,3,1,3,3
3,3,1,1,1,1,1,1,1,3,3,3,3,3,3,3,3,3,1,1,1,1,1,1,3,3
3,3,1,3,3,3,3,1,3,3,3,3,3,3,3,3,3,3,3,3,3,3,3,1,3,3
3,3,1,3,3,3,3,1,3,3,3,3,3,3,3,3,3,3,3,3,3,3,3,1,3,3
3,3,1,3,3,3,3,1,3,3,3,3,3,3,3,3,3,3,3,3,3,3,3,1,3,3
3,3,1,3,3,3,3,1,3,3,3,3,3,3,3,3,3,3,3,3,3,3,3,1,3,3
3,3,1,3,3,3,3,1,3,3,3,3,3,3,3,3,3,3,3,3,3,3,3,1,3,3
3,3,1,1,1,1,1,1,1,1,3,3,3,3,3,3,3,1,1,1,1,3,3,1,3,3
3,3,3,3,1,3,3,3,3,1,3,3,3,3,3,3,3,1,2,2,1,3,3,1,3,3
3,3,3,3,1,3,3,3,3,1,3,3,3,3,3,3,3,1,2,2,1,3,3,1,3,3
3,3,3,3,1,3,3,3,3,1,3,3,3,3,3,3,3,1,1,1,1,3,3,1,3,3
3,3,3,3,1,3,3,3,3,1,3,3,3,3,3,3,3,3,3,3,3,3,3,1,3,3
3,3,3,3,1,3,3,3,3,1,3,3,3,3,3,3,3,3,3,3,3,3,3,1,3,3
3,3,3,3,1,1,1,1,1,1,1,1,1,3,3,3,3,1,1,1,1,1,1,1,3,3
3,3,3,3,3,3,3,3,3,3,3,3,3,3,3,3,3,3,3,3,3,3,3,3,3,3
3,3,3,3,3,3,3,3,3,3,3,3,3,3,3,3,3,3,3,3,3,3,3,3,3,3
:endlayer
layer: 4
3,3,3,1,3,1,3,1,3,3,3,3,3,3,3,3,3,3,3,3,3,3,3,3,3,3
3,3,1,1,3,1,1,3,1,3,3,3,3,3,3,3,3,3,3,3,3,3,3,3,3,3
3,3,1,1,3,3,1,1,1,3,3,3,3,3,3,3,3,1,3,3,3,3,3,3,3,3
3,3,1,1,3,1,1,1,1,3,3,3,3,3,3,1,1,3,3,3,1,1,1,1,3,3
3,3,3,1,1,3,3,3,3,3,3,3,1,1,3,1,3,3,3,1,3,1,1,1,3,3
3,3,3,3,3,1,1,3,1,1,3,3,1,1,3,3,3,3,3,3,1,4,4,1,3,3
3,3,3,1,1,1,1,1,1,3,3,1,3,1,1,3,1,3,3,3,1,1,1,1,3,3
3,3,3,1,1,1,1,1,1,3,1,1,1,1,1,1,3,1,1,3,3,1,1,1,3,3
3,3,3,1,1,1,1,1,1,3,3,1,3,3,3,3,1,3,3,1,4,3,4,1,3,3
3,3,3,1,1,1,1,1,1,1,1,1,1,1,1,1,3,1,1,1,1,1,1,1,3,3
3,3,3,1,1,1,1,1,1,1,1,1,1,1,1,3,3,3,1,1,1,1,1,1,3,3
3,3,3,1,1,1,1,1,1,1,1,1,1,1,1,3,1,3,1,1,1,1,1,1,3,3
3,3,3,1,1,1,1,1,1,1,1,1,1,1,1,3,1,1,1,1,1,1,1,1,3,3
3,3,3,1,1,1,1,1,1,1,1,1,1,1,1,3,3,1,1,1,1,1,1,1,3,3
3,3,3,1,1,1,1,1,1,1,1,1,1,1,1,3,3,3,1,1,1,1,1,1,3,3
3,3,3,1,1,1,1,1,1,1,1,1,1,1,1,3,3,1,1,1,1,1,1,1,3,3
3,3,3,1,1,1,1,1,1,1,1,1,3,1,3,3,1,3,1,1,1,1,1,1,3,3
3,3,3,1,1,1,1,1,1,3,1,3,3,3,3,3,1,1,1,1,1,1,1,1,3,3
3,3,1,1,1,1,1,1,1,3,3,1,3,1,1,1,1,1,1,1,1,1,1,1,3,3
3,3,1,1,1,1,1,1,3,1,3,1,1,1,1,3,1,1,1,1,1,1,1,1,3,3
3,3,1,1,1,1,1,1,1,3,3,3,3,1,3,3,1,1,1,1,1,1,1,1,3,3
3,3,1,1,1,1,1,1,3,3,3,3,3,1,3,3,1,3,1,3,1,3,3,1,3,3
3,3,1,1,1,1,1,1,3,3,1,3,1,3,1,5,3,3,3,5,5,3,5,1,3,3
3,3,1,1,1,1,1,1,1,1,1,1,3,1,1,3,3,3,1,3,5,3,3,1,3,3
3,3,1,1,1,1,1,1,1,1,1,1,1,1,1,3,1,1,1,1,1,5,1,1,3,3
3,3,3,3,1,1,1,1,1,1,3,1,3,1,3,3,1,1,2,2,1,3,1,1,3,3
3,3,3,3,1,1,1,1,1,1,3,1,1,3,1,3,3,1,2,2,1,3,5,1,3,3
3,3,3,3,1,1,1,1,1,1,3,3,3,3,1,1,3,1,1,1,1,1,1,1,3,3
3,3,3,3,1,1,1,1,1,1,3,1,3,1,3,3,5,1,1,1,3,1,5,1,3,3
3,3,3,3,1,1,1,1,1,1,1,1,1,1,1,5,1,3,5,5,3,1,5,1,3,3
3,3,3,3,1,1,1,1,1,1,1,1,1,3,1,1,3,1,1,1,1,1,1,1,3,3
3,3,3,3,3,3,3,3,3,3,3,3,3,1,3,1,1,3,3,3,3,3,3,3,3,3
3,3,3,3,3,3,3,3,3,3,3,3,3,3,1,1,3,3,3,3,3,3,3,3,3,3
:endlayer
layer: 5
0,0,0,6,0,0,0,6,0,0,0,0,0,0,0,0,0,0,0,0,0,0,0,0,0,0
0,0,0,0,7,8,8,7,0,0,9,0,0,0,0,0,0,10,0,0,0,0,0,11,0,0
0,0,0,0,7,8,8,7,0,0,0,0,0,0,0,0,0,0,0,11,0,0,12,0,0,0
0,0,0,0,7,8,8,7,13,0,0,0,11,0,0,0,14,0,0,0,1,1,1,1,0,0
0,11,0,6,0,0,0,6,0,0,0,0,0,0,0,0,0,0,0,0,15,0,0,1,0,0
0,0,0,0,0,0,0,16,6,0,0,0,0,17,0,0,0,0,0,0,15,0,0,1,0,0
0,0,0,1,1,1,1,1,1,0,0,0,0,0,0,0,18,0,0,0,1,1,1,1,0,0
0,0,0,1,8,8,19,0,20,0,0,0,0,0,0,0,0,0,0,0,15,0,0,1,0,0
0,0,0,1,8,8,19,0,21,0,0,0,0,0,0,0,0,0,0,0,15,0,0,1,0,0
0,0,0,1,0,0,0,0,1,1,1,1,1,1,1,0,0,0,1,1,1,1,1,1,0,0
0,0,0,1,0,22,22,0,1,8,8,19,0,23,1,0,0,0,1,24,0,25,0,1,0,0
0,0,0,1,26,27,27,28,1,8,8,0,29,30,1,0,0,0,31,32,33,33,32,34,0,0
0,0,0,1,1,1,1,1,1,19,0,0,29,30,1,0,35,0,31,36,36,36,36,34,0,0
0,0,0,1,37,38,38,26,1,0,0,0,0,26,1,0,0,0,1,36,0,0,36,1,0,0
0,11,0,1,0,39,39,0,1,1,40,1,1,1,1,0,0,0,1,41,36,0,41,1,0,0
0,0,0,1,0,0,0,0,1,0,0,0,0,0,0,0,0,0,42,0,0,43,36,34,0,0
0,0,0,1,8,8,19,0,1,0,0,0,0,0,0,0,0,0,44,0,0,0,0,34,0,0
0,0,0,1,8,8,19,0,21,0,0,0,0,0,0,0,0,0,1,0,36,41,36,1,0,0
0,0,1,1,1,1,1,1,1,45,0,46,0,0,0,0,0,0,1,1,47,47,1,1,0,0
0,0,1,8,8,0,0,1,0,0,0,0,0,0,0,0,0,0,0,0,0,0,0,48,0,0
0,0,1,8,8,19,0,1,0,0,0,0,0,0,0,11,0,0,0,0,0,0,0,1,0,0
0,0,1,19,0,0,0,21,0,0,0,0,0,0,0,0,0,0,0,11,0,0,0,1,0,0
0,0,1,0,22,22,0,1,49,0,0,0,17,0,0,0,0,0,0,0,0,0,0,1,0,0
0,0,1,26,27,27,50,1,0,0,0,0,0,0,0,0,0,0,0,0,0,0,0,1,0,0
0,0,1,1,1,1,1,1,1,1,0,0,0,0,51,0,0,48,52,52,48,0,0,1,0,0
0,0,0,0,1,53,38,38,26,1,0,0,0,0,0,0,0,31,0,0,34,0,0,1,0,0
0,0,0,0,1,0,39,39,0,1,0,0,0,54,0,0,0,31,0,0,34,0,0,1,0,0
0,11,0,0,1,19,0,0,0,1,0,0,0,0,0,0,0,48,47,47,48,0,0,1,0,0
0,0,0,0,1,8,8,19,0,21,0,0,0,0,0,0,0,0,0,0,0,0,0,1,0,0
0,0,11,0,1,8,8,0,0,1,0,0,0,0,0,0,0,0,0,0,0,0,0,1,0,0
0,0,0,0,1,1,1,1,1,1,48,1,48,0,0,0,0,48,1,1,1,1,1,48,0,0
0,0,0,0,0,0,0,0,0,0,0,0,55,0,0,0,0,56,0,0,0,0,0,0,11,0
0,0,0,0,0,0,0,0,0,0,0,0,0,0,0,0,0,0,0,0,0,0,0,0,0,0
:endlayer
layer: 6
0,0,0,6,0,0,0,6,0,0,0,0,0,0,0,0,0,0,0,0,0,0,0,0,0,0
0,0,0,0,0,0,0,0,0,0,0,0,0,0,0,0,0,0,0,0,0,0,0,11,0,0
0,0,0,0,0,0,0,0,0,0,0,0,0,0,0,0,0,0,0,11,0,0,0,0,0,0
0,0,0,0,0,0,0,0,0,0,0,0,11,0,0,0,0,0,0,0,1,6,1,1,0,0
0,11,0,6,0,0,0,6,0,0,0,0,0,0,0,0,0,0,0,0,0,0,0,1,0,0
0,0,0,0,0,0,0,16,6,0,0,0,0,17,0,0,0,0,0,0,0,0,0,1,0,0
0,0,0,1,1,57,57,1,1,0,0,0,0,0,0,0,0,0,0,0,1,6,1,1,0,0
0,0,0,57,0,0,0,0,58,0,0,0,0,0,0,0,0,0,0,0,0,0,0,1,0,0
0,0,0,1,0,0,0,0,59,0,0,0,0,0,0,0,0,0,0,0,0,0,0,1,0,0
0,0,0,57,0,0,0,0,1,1,57,1,57,1,1,0,0,0,1,1,1,1,1,1,0,0
0,0,0,1,0,0,0,0,1,0,0,0,0,0,1,0,0,0,1,0,0,0,0,1,0,0
0,0,0,57,60,0,0,0,1,0,0,0,0,0,57,0,0,0,57,0,0,0,0,57,0,0
0,0,0,1,1,1,1,1,1,0,0,0,0,0,57,0,0,0,57,0,0,0,0,57,0,0
0,0,0,57,0,0,0,60,1,0,0,0,0,60,1,0,0,0,1,0,0,0,0,1,0,0
0,11,0,1,0,0,0,0,1,1,58,1,57,1,1,0,0,0,1,0,0,0,0,1,0,0
0,0,0,57,0,0,0,0,57,0,0,0,0,0,0,0,0,0,59,0,0,0,0,57,0,0
0,0,0,1,0,0,0,0,1,0,0,0,0,0,0,0,0,0,58,0,0,0,0,57,0,0
0,0,0,57,0,0,0,0,58,0,0,0,0,0,0,0,0,0,1,0,0,0,0,1,0,0
0,0,1,1,1,1,1,1,1,0,0,0,0,0,0,0,0,0,1,1,57,57,1,1,0,0
0,0,57,0,0,0,0,57,0,0,0,0,0,0,0,0,0,0,0,0,0,0,0,48,61,0
0,0,1,0,0,0,0,1,0,0,0,0,0,0,0,11,0,0,0,0,0,0,0,6,0,0
0,0,57,0,0,0,0,58,0,0,0,0,0,0,0,0,0,0,0,11,0,0,0,6,0,0
0,0,1,0,0,0,0,1,0,0,0,0,17,0,0,0,0,0,0,0,0,0,0,6,0,0
0,0,57,60,0,0,0,57,0,0,0,0,0,0,0,0,0,0,0,0,0,0,0,6,0,0
0,0,1,57,1,1,1,1,1,1,0,0,0,0,0,0,0,6,0,0,6,0,0,6,0,0
0,0,0,0,1,0,0,0,60,1,0,0,0,0,0,0,0,0,0,0,0,0,0,6,0,0
0,0,0,0,57,0,0,0,0,57,0,0,0,0,0,0,0,0,0,0,0,0,0,6,0,0
0,11,0,0,1,0,0,0,0,1,0,0,0,0,0,0,0,6,0,0,6,0,0,6,0,0
0,0,0,0,57,0,0,0,0,59,0,0,0,0,0,0,0,0,0,0,0,0,0,6,0,0
0,0,11,0,1,0,0,0,0,1,0,0,0,0,0,0,0,0,0,0,0,0,0,6,0,0
0,0,0,0,1,1,57,57,1,1,48,6,48,0,0,0,0,48,6,6,6,6,6,48,61,0
0,0,0,0,0,0,0,0,0,0,62,0,62,0,0,0,0,62,0,0,0,0,0,62,11,0
0,0,0,0,0,0,0,0,0,0,0,0,0,0,0,0,0,0,0,0,0,0,0,0,0,0
:endlayer
layer: 7
0,0,0,6,0,0,0,6,0,0,0,0,0,0,0,0,0,0,0,0,0,0,0,0,0,0
0,0,0,0,0,0,0,0,0,0,0,0,0,0,0,0,0,0,0,0,0,0,0,11,0,0
0,0,0,0,0,0,0,0,0,0,0,0,0,0,0,0,0,0,0,11,0,0,0,0,0,0
0,0,0,0,0,0,0,0,0,0,0,0,11,0,0,0,0,0,0,0,1,1,1,1,0,0
0,11,0,6,0,0,0,6,0,0,0,0,0,0,0,0,0,0,0,0,0,0,0,1,0,0
0,0,0,63,0,0,0,16,6,0,0,0,0,17,0,0,0,0,0,0,0,0,0,1,0,0
0,0,64,1,1,57,57,1,1,61,0,0,0,0,0,0,0,0,0,0,1,1,1,1,0,0
0,0,0,57,0,0,0,0,48,0,0,0,0,0,0,0,0,0,0,0,0,0,0,1,0,0
0,0,0,1,0,0,0,0,48,0,0,0,0,0,63,0,0,0,0,0,0,0,0,1,0,0
0,0,0,57,0,0,0,0,1,1,57,1,57,1,1,61,0,0,1,1,1,1,1,1,0,0
0,0,0,1,0,0,0,0,1,0,0,62,0,0,1,0,0,0,1,0,0,0,0,1,0,0
0,0,0,57,0,0,0,0,1,0,0,0,0,0,57,0,0,0,57,0,0,0,0,57,0,0
0,0,0,1,1,1,1,1,1,0,0,0,0,0,57,0,0,0,57,0,0,0,0,57,0,0
0,0,0,57,0,0,0,0,1,0,0,63,0,0,1,0,0,0,1,0,0,0,0,1,0,0
0,11,0,1,0,0,0,0,1,1,48,1,57,1,1,61,0,0,1,0,0,0,0,1,0,0
0,0,0,57,0,0,0,0,57,0,0,0,0,0,62,0,0,0,1,0,0,0,0,57,0,0
0,0,0,1,0,0,0,0,1,0,0,0,0,0,0,0,0,0,1,0,0,0,0,57,0,0
0,0,63,57,0,0,0,0,48,0,0,0,0,0,0,0,0,0,1,0,0,0,0,1,0,0
0,64,1,1,1,1,1,1,1,61,0,0,0,0,0,0,0,0,1,1,57,57,1,1,0,0
0,0,57,0,0,0,0,57,62,0,0,0,0,0,0,0,0,0,0,0,0,0,0,65,0,0
0,0,1,0,0,0,0,1,0,0,0,0,0,0,0,11,0,0,0,0,0,0,0,0,0,0
0,0,57,0,0,0,0,48,0,0,0,0,0,0,0,0,0,0,0,11,0,0,0,0,0,0
0,0,1,0,0,0,0,1,0,0,0,0,17,0,0,0,0,0,0,0,0,0,0,0,0,0
0,0,57,0,0,0,0,57,0,63,0,0,0,0,0,0,0,0,0,0,0,0,0,0,0,0
0,64,1,57,1,1,1,1,1,1,61,0,0,0,0,0,0,6,0,0,6,0,0,0,0,0
0,0,62,0,1,0,0,0,0,1,0,0,0,0,0,0,0,0,0,0,0,0,0,0,0,0
0,0,0,0,57,0,0,0,0,57,0,0,0,0,0,0,0,0,0,0,0,0,0,0,0,0
0,11,0,0,1,0,0,0,0,1,0,0,0,0,0,0,0,6,0,0,6,0,0,0,0,0
0,0,0,0,57,0,0,0,0,48,0,0,0,0,0,0,0,0,0,0,0,0,0,0,0,0
0,0,11,0,1,0,0,0,0,1,0,0,0,0,0,0,0,0,0,0,0,0,0,0,0,0
0,0,0,64,1,1,57,57,1,1,65,0,65,0,0,0,0,65,0,0,0,0,0,65,0,0
0,0,0,0,62,0,0,0,0,62,0,0,0,0,0,0,0,0,0,0,0,0,0,0,11,0
0,0,0,0,0,0,0,0,0,0,0,0,0,0,0,0,0,0,0,0,0,0,0,0,0,0
:endlayer
layer: 8
0,0,0,66,66,66,66,66,0,0,0,0,0,0,0,0,0,0,0,0,0,0,0,0,0,0
0,0,0,66,67,68,67,66,0,0,0,0,0,0,0,0,0,0,0,0,0,0,0,0,0,0
0,0,0,66,67,68,67,66,0,0,0,0,0,0,0,0,0,0,0,0,0,0,0,0,0,0
0,0,0,66,67,68,67,66,0,0,0,0,0,0,0,0,0,0,0,64,69,69,69,69,61,0
0,0,0,66,66,66,66,66,0,0,0,0,0,0,0,0,0,0,0,0,6,70,70,69,0,0
0,0,0,0,0,0,0,16,6,0,0,0,17,0,0,0,0,0,0,0,6,70,70,69,0,0
0,0,0,1,1,48,48,1,1,0,0,0,0,0,0,0,0,0,0,64,69,69,69,69,61,0
0,0,0,48,0,0,0,0,48,0,0,0,0,0,0,0,0,0,0,0,6,70,70,69,0,0
0,0,0,1,61,0,0,64,48,71,72,71,72,71,72,0,0,0,63,0,6,70,70,69,0,0
0,0,0,48,0,0,0,0,1,69,69,69,69,69,69,72,0,64,1,1,1,1,1,1,61,0
0,0,0,1,61,0,0,64,1,1,1,1,1,1,69,73,0,0,1,61,0,0,64,1,0,0
0,0,0,48,0,0,0,0,1,1,1,1,1,1,69,72,0,0,1,74,74,74,74,1,0,0
0,0,0,1,1,1,1,1,1,1,1,1,1,1,69,72,0,0,1,0,0,0,0,1,0,0
0,0,0,48,0,0,0,0,1,1,1,1,1,1,69,73,0,0,1,0,0,0,0,1,0,0
0,0,0,1,61,0,0,64,1,69,69,69,69,69,69,72,0,0,1,0,0,0,0,1,0,0
0,0,0,48,0,0,0,0,48,75,72,75,72,75,72,0,0,0,1,0,0,0,0,1,0,0
0,0,0,1,61,0,0,64,1,0,0,0,0,0,0,0,0,0,1,0,0,0,0,1,0,0
0,0,76,48,0,0,0,0,48,0,0,0,0,0,0,0,0,0,1,61,0,0,64,1,0,0
0,77,1,1,1,1,1,1,1,0,0,0,0,0,0,0,0,64,1,1,1,1,1,1,61,0
0,72,48,0,0,0,0,48,72,0,0,0,0,0,0,0,0,0,62,0,0,0,0,62,0,0
0,77,1,61,0,0,64,1,78,0,0,0,0,0,0,0,0,0,0,0,0,0,0,0,0,0
0,72,48,0,0,0,0,48,72,0,0,0,0,0,0,0,0,0,0,0,0,0,0,0,0,0
0,77,1,61,0,0,64,1,78,0,0,0,0,0,0,0,0,0,0,0,0,0,0,0,0,0
0,72,48,0,0,0,0,48,72,0,0,0,17,0,0,0,0,0,0,0,0,0,0,0,0,0
0,77,1,48,1,1,1,1,1,1,0,0,0,0,0,0,0,70,70,70,70,0,0,0,0,0
0,0,79,72,1,0,0,0,0,1,0,0,0,0,0,0,0,70,1,1,70,0,0,0,0,0
0,0,0,0,48,61,0,0,64,48,0,0,0,0,0,0,0,70,1,1,70,0,0,0,0,0
0,0,0,0,1,0,0,0,0,1,0,0,0,0,0,0,0,70,70,70,70,0,0,0,0,0
0,0,0,0,48,61,0,0,64,1,0,0,0,0,0,0,0,0,0,0,0,0,0,0,0,0
0,0,0,0,1,0,0,0,0,1,0,0,0,0,0,0,0,0,0,0,0,0,0,0,0,0
0,0,0,0,1,1,48,48,1,1,0,0,0,0,0,0,0,0,0,0,0,0,0,0,0,0
0,0,0,0,0,0,0,0,0,0,0,0,0,0,0,0,0,0,0,0,0,0,0,0,0,0
0,0,0,0,0,0,0,0,0,0,0,0,0,0,0,0,0,0,0,0,0,0,0,0,0,0
:endlayer
layer: 9
0,0,0,0,0,0,0,0,0,0,0,0,0,0,0,0,0,0,0,0,0,0,0,0,0,0
0,0,0,0,0,0,0,0,0,0,0,0,0,0,0,0,0,0,0,0,0,0,0,0,0,0
0,0,0,0,0,0,0,0,0,0,0,0,0,0,0,0,0,0,0,0,0,0,0,0,0,0
0,0,0,0,0,0,0,0,0,0,0,0,0,0,0,0,0,0,0,0,0,0,0,0,0,0
0,0,0,0,0,0,0,0,0,0,0,0,0,0,0,0,0,0,0,0,0,0,0,0,0,0
0,0,0,71,80,71,71,16,71,0,0,0,17,0,0,0,0,0,0,0,0,0,0,0,0,0
0,0,81,82,82,82,82,82,82,73,0,0,0,0,0,0,0,0,0,0,0,0,0,0,0,0
0,0,80,82,1,1,1,1,82,80,0,0,0,0,0,0,0,0,0,0,0,0,0,0,0,0
0,0,81,82,1,1,1,1,82,48,65,65,65,65,1,0,0,0,80,71,80,80,71,80,0,0
0,0,80,82,1,1,1,1,82,83,70,70,70,70,70,1,0,80,82,82,82,82,82,82,80,0
0,0,81,82,1,1,1,1,82,73,0,0,0,0,70,65,0,81,82,1,1,1,1,82,73,0
0,0,80,82,1,1,1,1,82,80,0,0,0,0,70,65,0,80,82,1,1,1,1,82,80,0
0,0,81,1,1,1,1,1,82,73,0,0,0,0,70,65,0,81,82,1,1,1,1,82,73,0
0,0,80,1,0,0,0,0,1,0,0,0,0,0,70,65,0,80,82,1,1,1,1,82,80,0
0,0,0,1,0,0,0,0,1,70,70,70,70,70,70,1,0,80,82,1,1,1,1,82,80,0
0,0,0,1,0,0,0,0,1,1,65,65,65,65,1,0,0,81,82,1,1,1,1,82,73,0
0,0,0,1,0,0,0,0,1,0,0,0,0,0,0,0,0,80,82,1,1,1,1,82,80,0
0,0,48,1,0,0,0,0,1,0,0,0,0,0,0,0,0,81,82,1,1,1,1,82,73,0
0,48,69,1,1,1,1,1,1,0,0,0,0,0,0,0,0,80,82,82,82,82,82,82,80,0
0,70,69,1,1,1,1,69,48,0,0,0,0,0,0,0,0,0,80,75,80,80,75,80,0,0
0,70,69,1,1,1,1,69,70,0,0,0,0,0,0,0,0,0,0,0,0,0,0,0,0,0
0,70,69,1,1,1,1,69,70,0,0,0,0,0,0,0,0,0,0,0,0,0,0,0,0,0
0,70,69,1,1,1,1,69,70,0,0,0,0,0,0,0,0,0,0,0,0,0,0,0,0,0
0,70,69,1,1,1,1,69,48,80,0,0,17,0,0,0,0,0,0,0,0,0,0,0,0,0
0,48,69,69,1,1,1,1,1,1,80,0,84,0,0,0,0,0,0,0,0,0,0,0,0,0
0,0,48,48,1,0,0,0,0,1,73,0,0,0,0,0,0,0,0,0,0,0,0,0,0,0
0,0,0,80,1,0,0,0,0,1,80,0,0,0,0,0,0,0,0,0,0,0,0,0,0,0
0,0,0,81,1,0,0,0,0,1,73,0,0,0,0,0,0,0,0,0,0,0,0,0,0,0
0,0,0,80,1,0,0,0,0,1,80,0,0,0,0,0,0,0,0,0,0,0,0,0,0,0
0,0,0,81,1,0,0,0,0,1,73,0,0,0,0,0,0,0,0,0,0,0,0,0,0,0
0,0,0,80,1,1,1,1,1,1,80,0,0,0,0,0,0,0,0,0,0,0,0,0,0,0
0,0,0,0,80,75,80,80,75,80,0,0,0,0,0,0,0,0,0,0,0,0,0,0,0,0
0,0,0,0,0,0,0,0,0,0,0,0,0,0,0,0,0,0,0,0,0,0,0,0,0,0
:endlayer
layer: 10
0,0,0,0,0,0,0,0,0,0,0,0,0,0,0,0,0,0,0,0,0,0,0,0,0,0
0,0,0,0,0,0,0,0,0,0,0,0,0,0,0,0,0,0,0,0,0,0,0,0,0,0
0,0,0,0,0,0,0,0,0,0,0,0,0,0,0,0,0,0,0,0,0,0,0,0,0,0
0,0,0,0,0,0,0,0,0,0,0,0,0,0,0,0,0,0,0,0,0,0,0,0,0,0
0,0,0,0,0,0,0,0,0,0,0,0,0,0,0,0,0,0,0,0,0,0,0,0,0,0
0,0,0,65,0,0,0,0,65,0,0,0,17,0,0,0,0,0,0,0,0,0,0,0,0,0
0,0,65,65,65,65,65,65,65,65,0,0,0,0,0,0,0,0,0,0,0,0,0,0,0,0
0,0,0,65,0,0,0,0,65,0,0,0,0,0,0,0,0,0,0,0,0,0,0,0,0,0
0,0,0,65,0,0,0,0,65,0,0,0,0,0,0,0,0,0,0,0,0,0,0,0,0,0
0,0,0,65,0,0,0,0,65,0,0,0,0,0,0,0,0,0,1,85,1,1,85,1,0,0
0,0,0,65,0,0,0,0,65,0,0,0,0,0,0,0,0,0,86,0,0,0,0,87,0,0
0,0,0,88,76,72,72,76,88,0,0,0,0,0,0,0,0,0,1,0,0,0,0,1,0,0
0,0,72,89,89,89,89,89,89,88,0,0,0,0,0,0,0,0,86,0,0,0,0,87,0,0
0,0,1,89,1,1,1,1,89,78,0,0,0,0,0,0,0,0,1,0,0,0,0,1,0,0
0,0,72,89,1,1,1,1,89,72,0,0,0,0,0,0,0,0,1,0,0,0,0,1,0,0
0,0,77,89,1,1,1,1,89,78,0,0,0,0,0,0,0,0,86,0,0,0,0,87,0,0
0,0,72,89,1,1,1,1,89,72,0,0,0,0,0,0,0,0,1,0,0,0,0,1,0,0
0,0,77,89,1,1,1,1,89,78,0,0,0,0,0,0,0,0,86,0,0,0,0,87,0,0
0,0,88,89,89,89,89,89,89,72,0,0,0,0,0,0,0,0,1,90,1,1,90,1,0,0
0,0,65,72,79,72,72,1,72,0,0,0,0,0,0,0,0,0,0,0,0,0,0,0,0,0
0,0,65,0,0,0,0,65,0,0,0,0,91,0,0,0,0,0,0,0,0,0,0,0,0,0
0,0,65,0,0,0,0,65,0,0,91,0,91,0,91,0,0,0,0,0,0,0,0,0,0,0
0,0,65,0,0,0,0,65,0,0,0,0,0,0,0,0,0,0,0,0,0,0,0,0,0,0
0,0,65,0,0,0,0,65,0,1,92,0,17,93,91,92,0,0,0,0,0,0,0,0,0,0
0,0,65,1,82,82,82,82,82,82,1,0,0,0,0,0,0,0,0,0,0,0,0,0,0,0
0,0,0,65,82,1,1,1,1,82,65,0,91,0,91,0,0,0,0,0,0,0,0,0,0,0
0,0,0,65,82,1,1,1,1,82,65,0,91,0,0,0,0,0,0,0,0,0,0,0,0,0
0,0,0,65,82,1,1,1,1,82,65,0,0,0,0,0,0,0,0,0,0,0,0,0,0,0
0,0,0,65,82,1,1,1,1,82,65,0,0,0,0,0,0,0,0,0,0,0,0,0,0,0
0,0,0,65,82,1,1,1,1,82,65,0,0,0,0,0,0,0,0,0,0,0,0,0,0,0
0,0,0,1,82,82,82,82,82,82,1,0,0,0,0,0,0,0,0,0,0,0,0,0,0,0
0,0,0,0,1,65,65,65,65,1,0,0,0,0,0,0,0,0,0,0,0,0,0,0,0,0
0,0,0,0,0,0,0,0,0,0,0,0,0,0,0,0,0,0,0,0,0,0,0,0,0,0
:endlayer
layer: 11
0,0,0,0,0,0,0,0,0,0,0,0,0,0,0,0,0,0,0,0,0,0,0,0,0,0
0,0,0,0,0,0,0,0,0,0,0,0,0,0,0,0,0,0,0,0,0,0,0,0,0,0
0,0,0,0,0,0,0,0,0,0,0,0,0,0,0,0,0,0,0,0,0,0,0,0,0,0
0,0,0,0,0,0,0,0,0,0,0,0,0,0,0,0,0,0,0,0,0,0,0,0,0,0
0,0,0,0,0,0,0,0,0,0,0,0,0,0,0,0,0,0,0,0,0,0,0,0,0,0
0,0,0,0,0,0,0,0,0,0,0,0,17,0,0,0,0,0,0,0,0,0,0,0,0,0
0,0,0,0,0,0,0,0,0,0,0,0,0,0,0,0,0,0,0,0,0,0,0,0,0,0
0,0,0,0,0,0,0,0,0,0,0,0,0,0,0,0,0,0,0,0,0,0,0,0,0,0
0,0,0,0,0,0,0,0,0,0,0,0,0,0,0,0,0,0,0,0,0,0,0,0,0,0
0,0,0,0,0,0,0,0,0,0,0,0,0,0,0,0,0,0,70,0,70,70,0,70,0,0
0,0,0,0,0,0,0,0,0,0,0,0,0,0,0,0,0,0,0,0,0,0,0,0,0,0
0,0,0,48,70,70,70,70,48,0,0,0,0,0,0,0,0,0,70,0,0,0,0,70,0,0
0,0,48,65,65,65,65,65,65,48,0,0,0,0,0,0,0,0,0,0,0,0,0,0,0,0
0,0,70,65,0,0,0,0,65,70,0,0,0,0,0,0,0,0,70,0,0,0,0,70,0,0
0,0,70,65,0,0,0,0,65,70,0,0,0,0,0,0,0,0,70,0,0,0,0,70,0,0
0,0,70,65,0,0,0,0,65,70,0,0,0,0,0,0,0,0,0,0,0,0,0,0,0,0
0,0,70,65,0,0,0,0,65,70,0,0,0,0,0,0,0,0,70,0,0,0,0,70,0,0
0,0,70,65,0,0,0,0,65,70,0,0,0,0,0,0,0,0,0,0,0,0,0,0,0,0
0,0,48,65,65,65,65,65,65,48,0,0,0,0,0,0,0,0,70,0,70,70,0,70,0,0
0,0,0,48,70,70,70,70,48,0,0,0,0,0,0,0,0,0,0,0,0,0,0,0,0,0
0,0,0,0,0,0,0,0,0,0,0,0,0,0,0,0,0,0,0,0,0,0,0,0,0,0
0,0,0,0,0,0,0,0,0,0,0,0,91,0,0,0,0,0,0,0,0,0,0,0,0,0
0,0,0,0,0,0,0,0,0,0,0,91,91,91,0,0,0,0,0,0,0,0,0,0,0,0
0,0,0,0,0,0,0,0,0,0,92,92,92,91,91,0,0,0,0,0,0,0,0,0,0,0
0,0,0,0,70,0,0,0,0,70,0,92,91,91,0,0,0,0,0,0,0,0,0,0,0,0
0,0,0,0,0,0,0,0,0,0,92,0,91,0,0,0,0,0,0,0,0,0,0,0,0,0
0,0,0,0,0,0,0,0,0,0,0,0,0,0,0,0,0,0,0,0,0,0,0,0,0,0
0,0,0,0,0,0,0,0,0,0,0,0,0,0,0,0,0,0,0,0,0,0,0,0,0,0
0,0,0,0,0,0,0,0,0,0,0,0,0,0,0,0,0,0,0,0,0,0,0,0,0,0
0,0,0,0,0,0,0,0,0,0,0,0,0,0,0,0,0,0,0,0,0,0,0,0,0,0
0,0,0,0,70,0,0,0,0,70,0,0,0,0,0,0,0,0,0,0,0,0,0,0,0,0
0,0,0,0,0,0,0,0,0,0,0,0,0,0,0,0,0,0,0,0,0,0,0,0,0,0
0,0,0,0,0,0,0,0,0,0,0,0,0,0,0,0,0,0,0,0,0,0,0,0,0,0
:endlayer
layer: 12
0,0,0,0,0,0,0,0,0,0,0,0,0,0,0,0,0,0,0,0,0,0,0,0,0,0
0,0,0,0,0,0,0,0,0,0,0,0,0,0,0,0,0,0,0,0,0,0,0,0,0,0
0,0,0,0,0,0,0,0,0,0,0,0,0,0,0,0,0,0,0,0,0,0,0,0,0,0
0,0,0,0,0,0,0,0,0,0,0,0,0,0,0,0,0,0,0,0,0,0,0,0,0,0
0,0,0,0,0,0,0,0,0,0,0,0,17,0,0,0,0,0,0,0,0,0,0,0,0,0
0,0,0,0,0,0,0,0,0,0,0,0,0,0,0,0,0,0,0,0,0,0,0,0,0,0
0,0,0,0,0,0,0,0,0,0,0,0,0,0,0,0,0,0,0,0,0,0,0,0,0,0
0,0,0,0,0,0,0,0,0,0,0,0,0,0,0,0,0,0,0,0,0,0,0,0,0,0
0,0,0,0,0,0,0,0,0,0,0,0,0,0,0,0,0,0,0,0,0,0,0,0,0,0
0,0,0,0,0,0,0,0,0,0,0,0,0,0,0,0,0,0,0,0,0,0,0,0,0,0
0,0,0,0,0,0,0,0,0,0,0,0,0,0,0,0,0,0,0,0,0,0,0,0,0,0
0,0,0,0,0,0,0,0,0,0,0,0,0,0,0,0,0,0,0,0,0,0,0,0,0,0
0,0,0,0,0,0,0,0,0,0,0,0,0,0,0,0,0,0,0,0,0,0,0,0,0,0
0,0,0,0,0,0,0,0,0,0,0,0,0,0,0,0,0,0,0,0,0,0,0,0,0,0
0,0,0,0,0,0,0,0,0,0,0,0,0,0,0,0,0,0,0,0,0,0,0,0,0,0
0,0,0,0,0,0,0,0,0,0,0,0,0,0,0,0,0,0,0,0,0,0,0,0,0,0
0,0,0,0,0,0,0,0,0,0,0,0,0,0,0,0,0,0,0,0,0,0,0,0,0,0
0,0,0,0,0,0,0,0,0,0,0,0,0,0,0,0,0,0,0,0,0,0,0,0,0,0
0,0,0,0,0,0,0,0,0,0,0,0,0,0,0,0,0,0,0,0,0,0,0,0,0,0
0,0,0,0,0,0,0,0,0,0,0,0,0,0,0,0,0,0,0,0,0,0,0,0,0,0
0,0,0,0,0,0,0,0,0,0,0,0,0,0,0,0,0,0,0,0,0,0,0,0,0,0
0,0,0,0,0,0,0,0,0,0,0,0,0,0,0,0,0,0,0,0,0,0,0,0,0,0
0,0,0,0,0,0,0,0,0,0,0,0,0,0,0,0,0,0,0,0,0,0,0,0,0,0
0,0,0,0,0,0,0,0,0,0,0,0,92,0,0,0,0,0,0,0,0,0,0,0,0,0
0,0,0,0,0,0,0,0,0,0,0,0,0,0,0,0,0,0,0,0,0,0,0,0,0,0
0,0,0,0,0,0,0,0,0,0,0,0,0,0,0,0,0,0,0,0,0,0,0,0,0,0
0,0,0,0,0,0,0,0,0,0,0,0,0,0,0,0,0,0,0,0,0,0,0,0,0,0
0,0,0,0,0,0,0,0,0,0,0,0,0,0,0,0,0,0,0,0,0,0,0,0,0,0
0,0,0,0,0,0,0,0,0,0,0,0,0,0,0,0,0,0,0,0,0,0,0,0,0,0
0,0,0,0,0,0,0,0,0,0,0,0,0,0,0,0,0,0,0,0,0,0,0,0,0,0
0,0,0,0,0,0,0,0,0,0,0,0,0,0,0,0,0,0,0,0,0,0,0,0,0,0
0,0,0,0,0,0,0,0,0,0,0,0,0,0,0,0,0,0,0,0,0,0,0,0,0,0
0,0,0,0,0,0,0,0,0,0,0,0,0,0,0,0,0,0,0,0,0,0,0,0,0,0
:endlayer
layer: 13
0,0,0,0,0,0,0,0,0,0,0,0,0,0,0,0,0,0,0,0,0,0,0,0,0,0
0,0,0,0,0,0,0,0,0,0,0,0,0,0,0,0,0,0,0,0,0,0,0,0,0,0
0,0,0,0,0,0,0,0,0,0,0,0,0,0,0,0,0,0,0,0,0,0,0,0,0,0
0,0,0,0,0,0,0,0,0,0,0,0,94,0,0,0,0,0,0,0,0,0,0,0,0,0
0,0,0,0,0,0,0,0,0,0,0,0,17,0,0,0,0,0,0,0,0,0,0,0,0,0
0,0,0,0,0,0,0,0,0,0,0,0,0,0,0,0,0,0,0,0,0,0,0,0,0,0
0,0,0,0,0,0,0,0,0,0,0,0,0,0,0,0,0,0,0,0,0,0,0,0,0,0
0,0,0,0,0,0,0,0,0,0,0,0,0,0,0,0,0,0,0,0,0,0,0,0,0,0
0,0,0,0,0,0,0,0,0,0,0,0,0,0,0,0,0,0,0,0,0,0,0,0,0,0
0,0,0,0,0,0,0,0,0,0,0,0,0,0,0,0,0,0,0,0,0,0,0,0,0,0
0,0,0,0,0,0,0,0,0,0,0,0,0,0,0,0,0,0,0,0,0,0,0,0,0,0
0,0,0,0,0,0,0,0,0,0,0,0,0,0,0,0,0,0,0,0,0,0,0,0,0,0
0,0,0,0,0,0,0,0,0,0,0,0,0,0,0,0,0,0,0,0,0,0,0,0,0,0
0,0,0,0,0,0,0,0,0,0,0,0,0,0,0,0,0,0,0,0,0,0,0,0,0,0
0,0,0,0,0,0,0,0,0,0,0,0,0,0,0,0,0,0,0,0,0,0,0,0,0,0
0,0,0,0,0,0,0,0,0,0,0,0,0,0,0,0,0,0,0,0,0,0,0,0,0,0
0,0,0,0,0,0,0,0,0,0,0,0,0,0,0,0,0,0,0,0,0,0,0,0,0,0
0,0,0,0,0,0,0,0,0,0,0,0,0,0,0,0,0,0,0,0,0,0,0,0,0,0
0,0,0,0,0,0,0,0,0,0,0,0,0,0,0,0,0,0,0,0,0,0,0,0,0,0
0,0,0,0,0,0,0,0,0,0,0,0,0,0,0,0,0,0,0,0,0,0,0,0,0,0
0,0,0,0,0,0,0,0,0,0,0,0,0,0,0,0,0,0,0,0,0,0,0,0,0,0
0,0,0,0,0,0,0,0,0,0,0,0,0,0,0,0,0,0,0,0,0,0,0,0,0,0
0,0,0,0,0,0,0,0,0,0,0,0,0,0,0,0,0,0,0,0,0,0,0,0,0,0
0,0,0,0,0,0,0,0,0,0,0,0,0,0,0,0,0,0,0,0,0,0,0,0,0,0
0,0,0,0,0,0,0,0,0,0,0,0,0,0,0,0,0,0,0,0,0,0,0,0,0,0
0,0,0,0,0,0,0,0,0,0,0,0,0,0,0,0,0,0,0,0,0,0,0,0,0,0
0,0,0,0,0,0,0,0,0,0,0,0,0,0,0,0,0,0,0,0,0,0,0,0,0,0
0,0,0,0,0,0,0,0,0,0,0,0,0,0,0,0,0,0,0,0,0,0,0,0,0,0
0,0,0,0,0,0,0,0,0,0,0,0,0,0,0,0,0,0,0,0,0,0,0,0,0,0
0,0,0,0,0,0,0,0,0,0,0,0,0,0,0,0,0,0,0,0,0,0,0,0,0,0
0,0,0,0,0,0,0,0,0,0,0,0,0,0,0,0,0,0,0,0,0,0,0,0,0,0
0,0,0,0,0,0,0,0,0,0,0,0,0,0,0,0,0,0,0,0,0,0,0,0,0,0
0,0,0,0,0,0,0,0,0,0,0,0,0,0,0,0,0,0,0,0,0,0,0,0,0,0
:endlayer
layer: 14
0,0,0,0,0,0,0,0,0,0,0,0,92,0,0,0,0,0,0,0,0,0,0,0,0,0
0,0,0,0,0,0,0,0,0,91,0,0,91,0,0,91,0,0,0,0,0,0,0,0,0,0
0,0,0,0,0,0,0,0,0,0,91,0,0,0,91,0,0,0,0,0,0,0,0,0,0,0
0,0,0,0,0,0,0,0,0,0,0,0,0,0,0,0,0,0,0,0,0,0,0,0,0,0
0,0,0,0,0,0,0,0,92,91,0,95,17,93,0,92,92,0,0,0,0,0,0,0,0,0
0,0,0,0,0,0,0,0,0,0,0,0,84,0,0,0,0,0,0,0,0,0,0,0,0,0
0,0,0,0,0,0,0,0,0,0,91,0,0,0,91,0,0,0,0,0,0,0,0,0,0,0
0,0,0,0,0,0,0,0,0,91,0,0,91,0,0,91,0,0,0,0,0,0,0,0,0,0
0,0,0,0,0,0,0,0,0,0,0,0,92,0,0,0,0,0,0,0,0,0,0,0,0,0
0,0,0,0,0,0,0,0,0,0,0,0,0,0,0,0,0,0,0,0,0,0,0,0,0,0
0,0,0,0,0,0,0,0,0,0,0,0,0,0,0,0,0,0,0,0,0,0,0,0,0,0
0,0,0,0,0,0,0,0,0,0,0,0,0,0,0,0,0,0,0,0,0,0,0,0,0,0
0,0,0,0,0,0,0,0,0,0,0,0,0,0,0,0,0,0,0,0,0,0,0,0,0,0
0,0,0,0,0,0,0,0,0,0,0,0,0,0,0,0,0,0,0,0,0,0,0,0,0,0
0,0,0,0,0,0,0,0,0,0,0,0,0,0,0,0,0,0,0,0,0,0,0,0,0,0
0,0,0,0,0,0,0,0,0,0,0,0,0,0,0,0,0,0,0,0,0,0,0,0,0,0
0,0,0,0,0,0,0,0,0,0,0,0,0,0,0,0,0,0,0,0,0,0,0,0,0,0
0,0,0,0,0,0,0,0,0,0,0,0,0,0,0,0,0,0,0,0,0,0,0,0,0,0
0,0,0,0,0,0,0,0,0,0,0,0,0,0,0,0,0,0,0,0,0,0,0,0,0,0
0,0,0,0,0,0,0,0,0,0,0,0,0,0,0,0,0,0,0,0,0,0,0,0,0,0
0,0,0,0,0,0,0,0,0,0,0,0,0,0,0,0,0,0,0,0,0,0,0,0,0,0
0,0,0,0,0,0,0,0,0,0,0,0,0,0,0,0,0,0,0,0,0,0,0,0,0,0
0,0,0,0,0,0,0,0,0,0,0,0,0,0,0,0,0,0,0,0,0,0,0,0,0,0
0,0,0,0,0,0,0,0,0,0,0,0,0,0,0,0,0,0,0,0,0,0,0,0,0,0
0,0,0,0,0,0,0,0,0,0,0,0,0,0,0,0,0,0,0,0,0,0,0,0,0,0
0,0,0,0,0,0,0,0,0,0,0,0,0,0,0,0,0,0,0,0,0,0,0,0,0,0
0,0,0,0,0,0,0,0,0,0,0,0,0,0,0,0,0,0,0,0,0,0,0,0,0,0
0,0,0,0,0,0,0,0,0,0,0,0,0,0,0,0,0,0,0,0,0,0,0,0,0,0
0,0,0,0,0,0,0,0,0,0,0,0,0,0,0,0,0,0,0,0,0,0,0,0,0,0
0,0,0,0,0,0,0,0,0,0,0,0,0,0,0,0,0,0,0,0,0,0,0,0,0,0
0,0,0,0,0,0,0,0,0,0,0,0,0,0,0,0,0,0,0,0,0,0,0,0,0,0
0,0,0,0,0,0,0,0,0,0,0,0,0,0,0,0,0,0,0,0,0,0,0,0,0,0
0,0,0,0,0,0,0,0,0,0,0,0,0,0,0,0,0,0,0,0,0,0,0,0,0,0
:endlayer
layer: 15
0,0,0,0,0,0,0,0,0,0,0,0,0,0,0,0,0,0,0,0,0,0,0,0,0,0
0,0,0,0,0,0,0,0,0,0,0,0,91,0,0,0,0,0,0,0,0,0,0,0,0,0
0,0,0,0,0,0,0,0,0,0,91,0,91,0,91,0,0,0,0,0,0,0,0,0,0,0
0,0,0,0,0,0,0,0,0,0,0,91,91,91,0,0,0,0,0,0,0,0,0,0,0,0
0,0,0,0,0,0,0,0,0,91,91,91,91,91,91,92,0,0,0,0,0,0,0,0,0,0
0,0,0,0,0,0,0,0,0,0,0,91,91,91,0,0,0,0,0,0,0,0,0,0,0,0
0,0,0,0,0,0,0,0,0,0,91,0,91,0,91,0,0,0,0,0,0,0,0,0,0,0
0,0,0,0,0,0,0,0,0,0,0,0,91,0,0,0,0,0,0,0,0,0,0,0,0,0
0,0,0,0,0,0,0,0,0,0,0,0,0,0,0,0,0,0,0,0,0,0,0,0,0,0
0,0,0,0,0,0,0,0,0,0,0,0,0,0,0,0,0,0,0,0,0,0,0,0,0,0
0,0,0,0,0,0,0,0,0,0,0,0,0,0,0,0,0,0,0,0,0,0,0,0,0,0
0,0,0,0,0,0,0,0,0,0,0,0,0,0,0,0,0,0,0,0,0,0,0,0,0,0
0,0,0,0,0,0,0,0,0,0,0,0,0,0,0,0,0,0,0,0,0,0,0,0,0,0
0,0,0,0,0,0,0,0,0,0,0,0,0,0,0,0,0,0,0,0,0,0,0,0,0,0
0,0,0,0,0,0,0,0,0,0,0,0,0,0,0,0,0,0,0,0,0,0,0,0,0,0
0,0,0,0,0,0,0,0,0,0,0,0,0,0,0,0,0,0,0,0,0,0,0,0,0,0
0,0,0,0,0,0,0,0,0,0,0,0,0,0,0,0,0,0,0,0,0,0,0,0,0,0
0,0,0,0,0,0,0,0,0,0,0,0,0,0,0,0,0,0,0,0,0,0,0,0,0,0
0,0,0,0,0,0,0,0,0,0,0,0,0,0,0,0,0,0,0,0,0,0,0,0,0,0
0,0,0,0,0,0,0,0,0,0,0,0,0,0,0,0,0,0,0,0,0,0,0,0,0,0
0,0,0,0,0,0,0,0,0,0,0,0,0,0,0,0,0,0,0,0,0,0,0,0,0,0
0,0,0,0,0,0,0,0,0,0,0,0,0,0,0,0,0,0,0,0,0,0,0,0,0,0
0,0,0,0,0,0,0,0,0,0,0,0,0,0,0,0,0,0,0,0,0,0,0,0,0,0
0,0,0,0,0,0,0,0,0,0,0,0,0,0,0,0,0,0,0,0,0,0,0,0,0,0
0,0,0,0,0,0,0,0,0,0,0,0,0,0,0,0,0,0,0,0,0,0,0,0,0,0
0,0,0,0,0,0,0,0,0,0,0,0,0,0,0,0,0,0,0,0,0,0,0,0,0,0
0,0,0,0,0,0,0,0,0,0,0,0,0,0,0,0,0,0,0,0,0,0,0,0,0,0
0,0,0,0,0,0,0,0,0,0,0,0,0,0,0,0,0,0,0,0,0,0,0,0,0,0
0,0,0,0,0,0,0,0,0,0,0,0,0,0,0,0,0,0,0,0,0,0,0,0,0,0
0,0,0,0,0,0,0,0,0,0,0,0,0,0,0,0,0,0,0,0,0,0,0,0,0,0
0,0,0,0,0,0,0,0,0,0,0,0,0,0,0,0,0,0,0,0,0,0,0,0,0,0
0,0,0,0,0,0,0,0,0,0,0,0,0,0,0,0,0,0,0,0,0,0,0,0,0,0
0,0,0,0,0,0,0,0,0,0,0,0,0,0,0,0,0,0,0,0,0,0,0,0,0,0
:endlayer
layer: 16
0,0,0,0,0,0,0,0,0,0,0,0,0,0,0,0,0,0,0,0,0,0,0,0,0,0
0,0,0,0,0,0,0,0,0,0,0,0,0,0,0,0,0,0,0,0,0,0,0,0,0,0
0,0,0,0,0,0,0,0,0,0,0,0,0,0,0,0,0,0,0,0,0,0,0,0,0,0
0,0,0,0,0,0,0,0,0,0,0,0,0,0,0,0,0,0,0,0,0,0,0,0,0,0
0,0,0,0,0,0,0,0,0,0,0,0,91,0,0,0,0,0,0,0,0,0,0,0,0,0
0,0,0,0,0,0,0,0,0,0,0,0,0,0,0,0,0,0,0,0,0,0,0,0,0,0
0,0,0,0,0,0,0,0,0,0,0,0,0,0,0,0,0,0,0,0,0,0,0,0,0,0
0,0,0,0,0,0,0,0,0,0,0,0,0,0,0,0,0,0,0,0,0,0,0,0,0,0
0,0,0,0,0,0,0,0,0,0,0,0,0,0,0,0,0,0,0,0,0,0,0,0,0,0
0,0,0,0,0,0,0,0,0,0,0,0,0,0,0,0,0,0,0,0,0,0,0,0,0,0
0,0,0,0,0,0,0,0,0,0,0,0,0,0,0,0,0,0,0,0,0,0,0,0,0,0
0,0,0,0,0,0,0,0,0,0,0,0,0,0,0,0,0,0,0,0,0,0,0,0,0,0
0,0,0,0,0,0,0,0,0,0,0,0,0,0,0,0,0,0,0,0,0,0,0,0,0,0
0,0,0,0,0,0,0,0,0,0,0,0,0,0,0,0,0,0,0,0,0,0,0,0,0,0
0,0,0,0,0,0,0,0,0,0,0,0,0,0,0,0,0,0,0,0,0,0,0,0,0,0
0,0,0,0,0,0,0,0,0,0,0,0,0,0,0,0,0,0,0,0,0,0,0,0,0,0
0,0,0,0,0,0,0,0,0,0,0,0,0,0,0,0,0,0,0,0,0,0,0,0,0,0
0,0,0,0,0,0,0,0,0,0,0,0,0,0,0,0,0,0,0,0,0,0,0,0,0,0
0,0,0,0,0,0,0,0,0,0,0,0,0,0,0,0,0,0,0,0,0,0,0,0,0,0
0,0,0,0,0,0,0,0,0,0,0,0,0,0,0,0,0,0,0,0,0,0,0,0,0,0
0,0,0,0,0,0,0,0,0,0,0,0,0,0,0,0,0,0,0,0,0,0,0,0,0,0
0,0,0,0,0,0,0,0,0,0,0,0,0,0,0,0,0,0,0,0,0,0,0,0,0,0
0,0,0,0,0,0,0,0,0,0,0,0,0,0,0,0,0,0,0,0,0,0,0,0,0,0
0,0,0,0,0,0,0,0,0,0,0,0,0,0,0,0,0,0,0,0,0,0,0,0,0,0
0,0,0,0,0,0,0,0,0,0,0,0,0,0,0,0,0,0,0,0,0,0,0,0,0,0
0,0,0,0,0,0,0,0,0,0,0,0,0,0,0,0,0,0,0,0,0,0,0,0,0,0
0,0,0,0,0,0,0,0,0,0,0,0,0,0,0,0,0,0,0,0,0,0,0,0,0,0
0,0,0,0,0,0,0,0,0,0,0,0,0,0,0,0,0,0,0,0,0,0,0,0,0,0
0,0,0,0,0,0,0,0,0,0,0,0,0,0,0,0,0,0,0,0,0,0,0,0,0,0
0,0,0,0,0,0,0,0,0,0,0,0,0,0,0,0,0,0,0,0,0,0,0,0,0,0
0,0,0,0,0,0,0,0,0,0,0,0,0,0,0,0,0,0,0,0,0,0,0,0,0,0
0,0,0,0,0,0,0,0,0,0,0,0,0,0,0,0,0,0,0,0,0,0,0,0,0,0
0,0,0,0,0,0,0,0,0,0,0,0,0,0,0,0,0,0,0,0,0,0,0,0,0,0
:endlayer

#### RULES ####
rule:
plugin=vanillaBlocks
number=1
data:
JSON:{blockState:{blockName:"minecraft:sandstone",properties:{type:"sandstone"}}}
:enddata
:endrule

rule:
plugin=fluid
number=2
data:
JSON:{blockState:{blockName:"minecraft:water",properties:{level:"0"}}}
:enddata
:endrule

rule:
plugin=vanillaBlocks
number=3
data:
JSON:{blockState:{blockName:"minecraft:sand",properties:{variant:"sand"}}}
:enddata
:endrule

rule:
plugin=vanillaBlocks
number=4
data:
JSON:{blockState:{blockName:"minecraft:dirt",properties:{variant:"coarse_dirt",snowy:"false"}}}
:enddata
:endrule

rule:
plugin=vanillaBlocks
number=5
data:
JSON:{blockState:{blockName:"minecraft:grass",properties:{snowy:"false"}}}
:enddata
:endrule

rule:
plugin=vanillaBlocks
number=6
data:
JSON:{blockState:{blockName:"minecraft:birch_fence",properties:{east:"false",south:"false",north:"false",west:"false"}}}
:enddata
:endrule

rule:
plugin=vanillaBlocks
number=7
data:
JSON:{blockState:{blockName:"ancientwarfarestructure:bench",properties:{legs:"none",variant:"oak",axis:"z"}}}
:enddata
:endrule

rule:
plugin=vanillaBlocks
number=8
data:
JSON:{blockState:{blockName:"ancientwarfarestructure:table",properties:{leg_southwest:"true",leg_northwest:"true",variant:"oak",leg_northeast:"true",leg_southeast:"true"}}}
:enddata
:endrule

rule:
plugin=blockTile
number=9
data:
JSON:{blockState:{blockName:"ancientwarfarestructure:advanced_spawner",properties:{transparent:"true"}},teData:{id:"ancientwarfarestructure:advanced_spawner_tile",spawnerSettings:{minDelay:10,spawnDelay:6,lightSensitive:0b,spawnGroups:[{settingsList:[{remainingSpawnCount:1,hostile:1b,customTag:{ArmorDropChances:[0.085f,0.085f,0.085f,0.085f],hasCustomEquipment:0b,ArmorItems:[{},{},{},{}],skinSettings:{npcTypeName:"custom",skinTypeSelected:"default"},HandDropChances:[0.085f,0.085f],factionName:"sarkonid",HandItems:[{id:"ancientwarfarenpc:golden_spear",Count:1b,Damage:0s},{id:"ancientwarfarenpc:gold_shield",Count:1b,Damage:0s}]},maxToSpawn:1,entityId:"ancientwarfarenpc:faction.soldier",minToSpawn:1}],groupWeight:1}],playerRange:16,respondToRedstone:0b,inventory:{Size:9,Items:[]},spawnRange:0,transparent:1b,maxDelay:10,spawnYOffset:0,xpToDrop:0,mobRange:0,debugMode:0b,maxNearbyMonsters:0}}}
:enddata
:endrule

rule:
plugin=blockTile
number=10
data:
JSON:{blockState:{blockName:"ancientwarfarestructure:advanced_spawner",properties:{transparent:"true"}},teData:{id:"ancientwarfarestructure:advanced_spawner_tile",spawnerSettings:{minDelay:10,spawnDelay:6,lightSensitive:0b,spawnGroups:[{settingsList:[{remainingSpawnCount:1,hostile:1b,customTag:{ArmorDropChances:[0.085f,0.085f,0.085f,0.085f],hasCustomEquipment:0b,ArmorItems:[{},{},{},{}],skinSettings:{npcTypeName:"custom",skinTypeSelected:"default"},HandDropChances:[0.085f,0.085f],factionName:"sarkonid",HandItems:[{id:"ancientwarfarenpc:golden_spear",Count:1b,Damage:0s},{id:"ancientwarfarenpc:gold_shield",Count:1b,Damage:0s}]},maxToSpawn:1,entityId:"ancientwarfarenpc:faction.soldier",minToSpawn:1}],groupWeight:1}],playerRange:16,respondToRedstone:0b,inventory:{Size:9,Items:[]},spawnRange:0,transparent:1b,maxDelay:10,spawnYOffset:0,xpToDrop:0,mobRange:0,debugMode:0b,maxNearbyMonsters:0}}}
:enddata
:endrule

rule:
plugin=vanillaBlocks
number=11
data:
JSON:{blockState:{blockName:"minecraft:cactus",properties:{age:"0"}}}
:enddata
:endrule

rule:
plugin=blockTile
number=12
data:
JSON:{blockState:{blockName:"ancientwarfarestructure:advanced_loot_chest",properties:{facing:"north"}},teData:{lootSettings:{lootRolls:1,splashPotion:0b,hasMessage:0b,hasLoot:1b,lootTableName:"minecraft:chests/simple_dungeon",spawnEntity:0b},Items:[],id:"ancientwarfarestructure:advanced_loot_chest_tile",Lock:""}}
:enddata
:endrule

rule:
plugin=blockTile
number=13
data:
JSON:{blockState:{blockName:"ancientwarfarestructure:advanced_spawner",properties:{transparent:"true"}},teData:{id:"ancientwarfarestructure:advanced_spawner_tile",spawnerSettings:{minDelay:10,spawnDelay:9,lightSensitive:0b,spawnGroups:[{settingsList:[{remainingSpawnCount:1,hostile:1b,customTag:{ArmorDropChances:[0.085f,0.085f,0.085f,0.085f],hasCustomEquipment:0b,ArmorItems:[{},{},{},{}],skinSettings:{npcTypeName:"custom",skinTypeSelected:"default"},HandDropChances:[0.085f,0.085f],factionName:"sarkonid",HandItems:[{},{}]},maxToSpawn:1,entityId:"ancientwarfarenpc:faction.civilian.male",minToSpawn:1}],groupWeight:1}],playerRange:16,respondToRedstone:0b,inventory:{Size:9,Items:[]},spawnRange:0,transparent:1b,maxDelay:10,spawnYOffset:0,xpToDrop:0,mobRange:0,debugMode:0b,maxNearbyMonsters:0}}}
:enddata
:endrule

rule:
plugin=blockTile
number=14
data:
JSON:{blockState:{blockName:"ancientwarfarestructure:advanced_spawner",properties:{transparent:"true"}},teData:{id:"ancientwarfarestructure:advanced_spawner_tile",spawnerSettings:{minDelay:10,spawnDelay:8,lightSensitive:0b,spawnGroups:[{settingsList:[{remainingSpawnCount:1,hostile:1b,customTag:{ArmorDropChances:[0.085f,0.085f,0.085f,0.085f],hasCustomEquipment:0b,ArmorItems:[{},{},{},{}],skinSettings:{npcTypeName:"custom",skinTypeSelected:"default"},HandDropChances:[0.085f,0.085f],factionName:"sarkonid",HandItems:[{},{}]},maxToSpawn:1,entityId:"ancientwarfarenpc:faction.civilian.female",minToSpawn:1}],groupWeight:1}],playerRange:16,respondToRedstone:0b,inventory:{Size:9,Items:[]},spawnRange:0,transparent:1b,maxDelay:10,spawnYOffset:0,xpToDrop:0,mobRange:0,debugMode:0b,maxNearbyMonsters:0}}}
:enddata
:endrule

rule:
plugin=vanillaBlocks
number=15
data:
JSON:{blockState:{blockName:"minecraft:birch_fence_gate",properties:{in_wall:"false",powered:"false",facing:"east",open:"false"}}}
:enddata
:endrule

rule:
plugin=vanillaBlocks
number=16
data:
JSON:{blockState:{blockName:"minecraft:ladder",properties:{facing:"north"}}}
:enddata
:endrule

rule:
plugin=vanillaBlocks
number=17
data:
JSON:{blockState:{blockName:"minecraft:log",properties:{variant:"jungle",axis:"y"}}}
:enddata
:endrule

rule:
plugin=blockTile
number=18
data:
JSON:{blockState:{blockName:"ancientwarfarestructure:advanced_spawner",properties:{transparent:"true"}},teData:{id:"ancientwarfarestructure:advanced_spawner_tile",spawnerSettings:{minDelay:10,spawnDelay:5,lightSensitive:0b,spawnGroups:[{settingsList:[{remainingSpawnCount:1,hostile:1b,customTag:{ArmorDropChances:[0.085f,0.085f,0.085f,0.085f],hasCustomEquipment:0b,ArmorItems:[{},{},{},{}],skinSettings:{npcTypeName:"custom",skinTypeSelected:"default"},HandDropChances:[0.085f,0.085f],factionName:"sarkonid",HandItems:[{id:"minecraft:bow",Count:1b,Damage:0s},{}]},maxToSpawn:1,entityId:"ancientwarfarenpc:faction.mounted_archer",minToSpawn:1}],groupWeight:1}],playerRange:32,respondToRedstone:0b,inventory:{Size:9,Items:[]},spawnRange:0,transparent:1b,maxDelay:10,spawnYOffset:0,xpToDrop:0,mobRange:0,debugMode:0b,maxNearbyMonsters:0}}}
:enddata
:endrule

rule:
plugin=vanillaBlocks
number=19
data:
JSON:{blockState:{blockName:"ancientwarfarestructure:stool",properties:{variant:"oak"}}}
:enddata
:endrule

rule:
plugin=doors
number=20
data:
JSON:{blockState:{blockName:"minecraft:wooden_door",properties:{hinge:"right",half:"lower",powered:"false",facing:"west",open:"false"}}}
:enddata
:endrule

rule:
plugin=doors
number=21
data:
JSON:{blockState:{blockName:"minecraft:wooden_door",properties:{hinge:"left",half:"lower",powered:"false",facing:"west",open:"false"}}}
:enddata
:endrule

rule:
plugin=bed
number=22
data:
JSON:{blockState:{blockName:"minecraft:bed",properties:{part:"foot",facing:"south",occupied:"false"}},bedColor:14}
:enddata
:endrule

rule:
plugin=blockTile
number=23
data:
JSON:{blockState:{blockName:"ancientwarfarestructure:advanced_loot_chest",properties:{facing:"west"}},teData:{lootSettings:{lootRolls:1,splashPotion:0b,hasMessage:0b,hasLoot:1b,lootTableName:"ancientwarfare:chests/citizen_high_value",spawnEntity:0b},Items:[],id:"ancientwarfarestructure:advanced_loot_chest_tile",Lock:""}}
:enddata
:endrule

rule:
plugin=blockTile
number=24
data:
JSON:{blockState:{blockName:"ancientwarfarestructure:advanced_loot_chest",properties:{facing:"east"}},teData:{lootSettings:{lootRolls:1,splashPotion:0b,hasMessage:0b,hasLoot:1b,lootTableName:"ancientwarfare:chests/sarkonid",spawnEntity:0b},Items:[],id:"ancientwarfarestructure:advanced_loot_chest_tile",Lock:""}}
:enddata
:endrule

rule:
plugin=blockTile
number=25
data:
JSON:{blockState:{blockName:"ancientwarfarestructure:advanced_spawner",properties:{transparent:"true"}},teData:{id:"ancientwarfarestructure:advanced_spawner_tile",spawnerSettings:{minDelay:10,spawnDelay:8,lightSensitive:0b,spawnGroups:[{settingsList:[{remainingSpawnCount:1,hostile:1b,customTag:{ArmorDropChances:[0.085f,0.085f,0.085f,0.085f],CustomName:"Inn Owner",hasCustomEquipment:1b,ArmorItems:[{},{},{},{}],skinSettings:{npcTypeName:"custom",skinTypeSelected:"default"},HandDropChances:[0.085f,0.085f],factionName:"sarkonid",tradeList:{tradeList:[{refillFrequency:6000,currentAvailable:11,inputItems:[{id:"ancientwarfarenpc:coin",Count:1b,tag:{metal:"silver"},slot:4,Damage:0s}],outputItems:[{id:"minecraft:potion",Count:1b,tag:{CustomPotionEffects:[{ShowParticles:0b,Duration:600,Id:1b,Amplifier:1b},{ShowParticles:0b,Duration:400,Id:23b,Amplifier:1b}],CustomPotionColor:16769311,HideFlags:32,display:{Lore:["*burp*"],Name:"Good Ol' Beer"}},slot:4,Damage:0s}],refillTime:-1L,maxAvailable:11},{refillFrequency:6000,currentAvailable:7,inputItems:[{id:"ancientwarfarenpc:coin",Count:5b,tag:{metal:"silver"},slot:4,Damage:0s}],outputItems:[{id:"minecraft:potion",Count:1b,tag:{CustomPotionEffects:[{ShowParticles:0b,Duration:600,Id:1b,Amplifier:1b},{ShowParticles:0b,Duration:600,Id:3b,Amplifier:1b},{ShowParticles:0b,Duration:1,Id:7b,Amplifier:0b}],CustomPotionColor:10033817,HideFlags:32,display:{Lore:["spicy!"],Name:"local desert brew"}},slot:4,Damage:0s}],refillTime:-1L,maxAvailable:7},{refillFrequency:6000,currentAvailable:6,inputItems:[{id:"ancientwarfarenpc:coin",Count:5b,tag:{metal:"silver"},slot:4,Damage:0s}],outputItems:[{id:"minecraft:potion",Count:1b,tag:{CustomPotionEffects:[{ShowParticles:0b,Duration:1,Id:7b,Amplifier:0b},{ShowParticles:0b,Duration:400,Id:15b,Amplifier:1b},{ShowParticles:0b,Duration:100,Id:19b,Amplifier:1b},{ShowParticles:0b,Duration:400,Id:23b,Amplifier:1b},{ShowParticles:0b,Duration:600,Id:26b,Amplifier:1b}],CustomPotionColor:10064427,HideFlags:32,display:{Lore:["They are known to be dangerous."],Name:"Sarkonid's speciality"}},slot:4,Damage:0s}],refillTime:-1L,maxAvailable:6},{refillFrequency:6000,currentAvailable:17,inputItems:[{id:"ancientwarfarenpc:coin",Count:3b,tag:{metal:"silver"},slot:4,Damage:0s}],outputItems:[{id:"minecraft:potion",Count:1b,tag:{CustomPotionEffects:[{ShowParticles:0b,Duration:2400,Id:1b,Amplifier:1b},{ShowParticles:0b,Duration:1200,Id:11b,Amplifier:0b},{ShowParticles:0b,Duration:200,Id:23b,Amplifier:0b}],CustomPotionColor:13041592,HideFlags:32,display:{Lore:["made from green grapes"],Name:"Green Wine"}},slot:4,Damage:0s}],refillTime:-1L,maxAvailable:17},{refillFrequency:6000,currentAvailable:19,inputItems:[{id:"ancientwarfarenpc:coin",Count:3b,tag:{metal:"silver"},slot:4,Damage:0s}],outputItems:[{id:"minecraft:potion",Count:1b,tag:{CustomPotionEffects:[{ShowParticles:0b,Duration:2400,Id:1b,Amplifier:1b},{ShowParticles:0b,Duration:1200,Id:11b,Amplifier:0b},{ShowParticles:0b,Duration:200,Id:23b,Amplifier:0b}],CustomPotionColor:5373952,HideFlags:32,display:{Lore:["made from red grapes"],Name:"Red Wine"}},slot:4,Damage:0s}],refillTime:-1L,maxAvailable:19},{refillFrequency:6000,currentAvailable:18,inputItems:[{id:"ancientwarfarenpc:coin",Count:3b,tag:{metal:"silver"},slot:4,Damage:0s}],outputItems:[{id:"minecraft:potion",Count:1b,tag:{CustomPotionEffects:[{ShowParticles:0b,Duration:2400,Id:1b,Amplifier:1b},{ShowParticles:0b,Duration:1200,Id:11b,Amplifier:0b},{ShowParticles:0b,Duration:200,Id:23b,Amplifier:0b}],CustomPotionColor:14277081,HideFlags:32,display:{Lore:["made from white grapes"],Name:"White Wine"}},slot:4,Damage:0s}],refillTime:-1L,maxAvailable:18}]},HandItems:[{id:"minecraft:glass_bottle",Count:1b,Damage:0s},{}]},maxToSpawn:1,entityId:"ancientwarfarenpc:faction.trader",minToSpawn:1}],groupWeight:1}],playerRange:16,respondToRedstone:0b,inventory:{Size:9,Items:[]},spawnRange:0,transparent:1b,maxDelay:10,spawnYOffset:0,xpToDrop:0,mobRange:0,debugMode:0b,maxNearbyMonsters:0}}}
:enddata
:endrule

rule:
plugin=vanillaBlocks
number=26
data:
JSON:{blockState:{blockName:"minecraft:crafting_table"}}
:enddata
:endrule

rule:
plugin=bed
number=27
data:
JSON:{blockState:{blockName:"minecraft:bed",properties:{part:"head",facing:"south",occupied:"false"}},bedColor:14}
:enddata
:endrule

rule:
plugin=blockTile
number=28
data:
JSON:{blockState:{blockName:"ancientwarfarestructure:advanced_loot_chest",properties:{facing:"north"}},teData:{lootSettings:{lootRolls:1,splashPotion:0b,hasMessage:0b,hasLoot:1b,lootTableName:"ancientwarfare:chests/citizen_high_value",spawnEntity:0b},Items:[],id:"ancientwarfarestructure:advanced_loot_chest_tile",Lock:""}}
:enddata
:endrule

rule:
plugin=bed
number=29
data:
JSON:{blockState:{blockName:"minecraft:bed",properties:{part:"foot",facing:"east",occupied:"false"}},bedColor:14}
:enddata
:endrule

rule:
plugin=bed
number=30
data:
JSON:{blockState:{blockName:"minecraft:bed",properties:{part:"head",facing:"east",occupied:"false"}},bedColor:14}
:enddata
:endrule

rule:
plugin=vanillaBlocks
number=31
data:
JSON:{blockState:{blockName:"minecraft:red_sandstone_stairs",properties:{half:"bottom",shape:"straight",facing:"east"}}}
:enddata
:endrule

rule:
plugin=vanillaBlocks
number=32
data:
JSON:{blockState:{blockName:"minecraft:planks",properties:{variant:"spruce"}}}
:enddata
:endrule

rule:
plugin=vanillaBlocks
number=33
data:
JSON:{blockState:{blockName:"minecraft:wooden_slab",properties:{half:"top",variant:"spruce"}}}
:enddata
:endrule

rule:
plugin=vanillaBlocks
number=34
data:
JSON:{blockState:{blockName:"minecraft:red_sandstone_stairs",properties:{half:"bottom",shape:"straight",facing:"west"}}}
:enddata
:endrule

rule:
plugin=blockTile
number=35
data:
JSON:{blockState:{blockName:"ancientwarfarestructure:advanced_spawner",properties:{transparent:"true"}},teData:{id:"ancientwarfarestructure:advanced_spawner_tile",spawnerSettings:{minDelay:10,spawnDelay:2,lightSensitive:0b,spawnGroups:[{settingsList:[{remainingSpawnCount:1,hostile:1b,customTag:{ArmorDropChances:[0.085f,0.085f,0.085f,0.085f],hasCustomEquipment:0b,ArmorItems:[{},{},{},{}],skinSettings:{npcTypeName:"custom",skinTypeSelected:"default"},HandDropChances:[0.085f,0.085f],factionName:"sarkonid",HandItems:[{id:"ancientwarfarenpc:golden_spear",Count:1b,Damage:0s},{id:"ancientwarfarenpc:gold_shield",Count:1b,Damage:0s}]},maxToSpawn:1,entityId:"ancientwarfarenpc:faction.soldier",minToSpawn:1}],groupWeight:1}],playerRange:16,respondToRedstone:0b,inventory:{Size:9,Items:[]},spawnRange:0,transparent:1b,maxDelay:10,spawnYOffset:0,xpToDrop:0,mobRange:0,debugMode:0b,maxNearbyMonsters:0}}}
:enddata
:endrule

rule:
plugin=vanillaBlocks
number=36
data:
JSON:{blockState:{blockName:"ancientwarfarestructure:stool",properties:{variant:"spruce"}}}
:enddata
:endrule

rule:
plugin=blockTile
number=37
data:
JSON:{blockState:{blockName:"ancientwarfarestructure:advanced_loot_chest",properties:{facing:"south"}},teData:{lootSettings:{lootRolls:1,splashPotion:0b,hasMessage:0b,hasLoot:1b,lootTableName:"ancientwarfare:chests/citizen_high_value",spawnEntity:0b},Items:[],id:"ancientwarfarestructure:advanced_loot_chest_tile",Lock:""}}
:enddata
:endrule

rule:
plugin=bed
number=38
data:
JSON:{blockState:{blockName:"minecraft:bed",properties:{part:"head",facing:"north",occupied:"false"}},bedColor:14}
:enddata
:endrule

rule:
plugin=bed
number=39
data:
JSON:{blockState:{blockName:"minecraft:bed",properties:{part:"foot",facing:"north",occupied:"false"}},bedColor:14}
:enddata
:endrule

rule:
plugin=doors
number=40
data:
JSON:{blockState:{blockName:"minecraft:wooden_door",properties:{hinge:"left",half:"lower",powered:"false",facing:"north",open:"false"}}}
:enddata
:endrule

rule:
plugin=vanillaBlocks
number=41
data:
JSON:{blockState:{blockName:"ancientwarfarestructure:table",properties:{leg_southwest:"true",leg_northwest:"true",variant:"spruce",leg_northeast:"true",leg_southeast:"true"}}}
:enddata
:endrule

rule:
plugin=doors
number=42
data:
JSON:{blockState:{blockName:"minecraft:wooden_door",properties:{hinge:"left",half:"lower",powered:"false",facing:"east",open:"false"}}}
:enddata
:endrule

rule:
plugin=blockTile
number=43
data:
JSON:{blockState:{blockName:"ancientwarfarestructure:advanced_spawner",properties:{transparent:"true"}},teData:{id:"ancientwarfarestructure:advanced_spawner_tile",spawnerSettings:{minDelay:10,spawnDelay:8,lightSensitive:0b,spawnGroups:[{settingsList:[{remainingSpawnCount:1,hostile:1b,customTag:{ArmorDropChances:[0.085f,0.085f,0.085f,0.085f],hasCustomEquipment:0b,ArmorItems:[{},{},{},{}],skinSettings:{npcTypeName:"custom",skinTypeSelected:"default"},HandDropChances:[0.085f,0.085f],factionName:"sarkonid",HandItems:[{},{}]},maxToSpawn:1,entityId:"ancientwarfarenpc:faction.civilian.male",minToSpawn:1}],groupWeight:1}],playerRange:16,respondToRedstone:0b,inventory:{Size:9,Items:[]},spawnRange:0,transparent:1b,maxDelay:10,spawnYOffset:0,xpToDrop:0,mobRange:0,debugMode:0b,maxNearbyMonsters:0}}}
:enddata
:endrule

rule:
plugin=doors
number=44
data:
JSON:{blockState:{blockName:"minecraft:wooden_door",properties:{hinge:"right",half:"lower",powered:"false",facing:"east",open:"false"}}}
:enddata
:endrule

rule:
plugin=blockTile
number=45
data:
JSON:{blockState:{blockName:"ancientwarfarestructure:advanced_spawner",properties:{transparent:"true"}},teData:{id:"ancientwarfarestructure:advanced_spawner_tile",spawnerSettings:{minDelay:10,spawnDelay:9,lightSensitive:0b,spawnGroups:[{settingsList:[{remainingSpawnCount:1,hostile:1b,customTag:{ArmorDropChances:[0.085f,0.085f,0.085f,0.085f],hasCustomEquipment:0b,ArmorItems:[{},{},{},{}],skinSettings:{npcTypeName:"custom",skinTypeSelected:"default"},HandDropChances:[0.085f,0.085f],factionName:"sarkonid",HandItems:[{},{}]},maxToSpawn:1,entityId:"ancientwarfarenpc:faction.civilian.male",minToSpawn:1}],groupWeight:1}],playerRange:16,respondToRedstone:0b,inventory:{Size:9,Items:[]},spawnRange:0,transparent:1b,maxDelay:10,spawnYOffset:0,xpToDrop:0,mobRange:0,debugMode:0b,maxNearbyMonsters:0}}}
:enddata
:endrule

rule:
plugin=blockTile
number=46
data:
JSON:{blockState:{blockName:"ancientwarfarestructure:advanced_spawner",properties:{transparent:"true"}},teData:{id:"ancientwarfarestructure:advanced_spawner_tile",spawnerSettings:{minDelay:10,spawnDelay:5,lightSensitive:0b,spawnGroups:[{settingsList:[{remainingSpawnCount:1,hostile:1b,customTag:{ArmorDropChances:[0.085f,0.085f,0.085f,0.085f],hasCustomEquipment:0b,ArmorItems:[{},{},{},{}],skinSettings:{npcTypeName:"custom",skinTypeSelected:"default"},HandDropChances:[0.085f,0.085f],factionName:"sarkonid",HandItems:[{id:"minecraft:golden_sword",Count:1b,Damage:0s},{id:"minecraft:golden_sword",Count:1b,Damage:0s}]},maxToSpawn:1,entityId:"ancientwarfarenpc:faction.soldier.elite",minToSpawn:1}],groupWeight:1}],playerRange:16,respondToRedstone:0b,inventory:{Size:9,Items:[]},spawnRange:0,transparent:1b,maxDelay:10,spawnYOffset:0,xpToDrop:0,mobRange:0,debugMode:0b,maxNearbyMonsters:0}}}
:enddata
:endrule

rule:
plugin=vanillaBlocks
number=47
data:
JSON:{blockState:{blockName:"minecraft:red_sandstone_stairs",properties:{half:"bottom",shape:"straight",facing:"north"}}}
:enddata
:endrule

rule:
plugin=vanillaBlocks
number=48
data:
JSON:{blockState:{blockName:"minecraft:red_sandstone",properties:{type:"red_sandstone"}}}
:enddata
:endrule

rule:
plugin=blockTile
number=49
data:
JSON:{blockState:{blockName:"ancientwarfarestructure:advanced_spawner",properties:{transparent:"true"}},teData:{id:"ancientwarfarestructure:advanced_spawner_tile",spawnerSettings:{minDelay:10,spawnDelay:9,lightSensitive:0b,spawnGroups:[{settingsList:[{remainingSpawnCount:1,hostile:1b,customTag:{ArmorDropChances:[0.085f,0.085f,0.085f,0.085f],hasCustomEquipment:0b,ArmorItems:[{},{},{},{}],skinSettings:{npcTypeName:"custom",skinTypeSelected:"default"},HandDropChances:[0.085f,0.085f],factionName:"sarkonid",HandItems:[{id:"ancientwarfarenpc:golden_spear",Count:1b,Damage:0s},{id:"ancientwarfarenpc:gold_shield",Count:1b,Damage:0s}]},maxToSpawn:1,entityId:"ancientwarfarenpc:faction.soldier",minToSpawn:1}],groupWeight:1}],playerRange:16,respondToRedstone:0b,inventory:{Size:9,Items:[]},spawnRange:0,transparent:1b,maxDelay:10,spawnYOffset:0,xpToDrop:0,mobRange:0,debugMode:0b,maxNearbyMonsters:0}}}
:enddata
:endrule

rule:
plugin=blockTile
number=50
data:
JSON:{blockState:{blockName:"ancientwarfarestructure:advanced_loot_chest",properties:{facing:"north"}},teData:{lootSettings:{lootRolls:1,splashPotion:0b,hasMessage:0b,hasLoot:1b,lootTableName:"ancientwarfare:chests/citizen_medium_value",spawnEntity:0b},Items:[],id:"ancientwarfarestructure:advanced_loot_chest_tile",Lock:""}}
:enddata
:endrule

rule:
plugin=blockTile
number=51
data:
JSON:{blockState:{blockName:"ancientwarfarestructure:advanced_spawner",properties:{transparent:"true"}},teData:{id:"ancientwarfarestructure:advanced_spawner_tile",spawnerSettings:{minDelay:10,spawnDelay:5,lightSensitive:0b,spawnGroups:[{settingsList:[{remainingSpawnCount:1,hostile:1b,customTag:{ArmorDropChances:[0.085f,0.085f,0.085f,0.085f],hasCustomEquipment:0b,ArmorItems:[{},{},{},{}],skinSettings:{npcTypeName:"custom",skinTypeSelected:"default"},HandDropChances:[0.085f,0.085f],factionName:"sarkonid",HandItems:[{id:"ancientwarfarenpc:golden_lance",Count:1b,Damage:0s},{}]},maxToSpawn:1,entityId:"ancientwarfarenpc:faction.cavalry",minToSpawn:1}],groupWeight:1}],playerRange:16,respondToRedstone:0b,inventory:{Size:9,Items:[]},spawnRange:0,transparent:1b,maxDelay:10,spawnYOffset:0,xpToDrop:0,mobRange:0,debugMode:0b,maxNearbyMonsters:0}}}
:enddata
:endrule

rule:
plugin=vanillaBlocks
number=52
data:
JSON:{blockState:{blockName:"minecraft:red_sandstone_stairs",properties:{half:"bottom",shape:"straight",facing:"south"}}}
:enddata
:endrule

rule:
plugin=blockTile
number=53
data:
JSON:{blockState:{blockName:"ancientwarfarestructure:advanced_loot_chest",properties:{facing:"east"}},teData:{lootSettings:{lootRolls:1,splashPotion:0b,hasMessage:0b,hasLoot:1b,lootTableName:"ancientwarfare:chests/citizen_medium_value",spawnEntity:0b},Items:[],id:"ancientwarfarestructure:advanced_loot_chest_tile",Lock:""}}
:enddata
:endrule

rule:
plugin=blockTile
number=54
data:
JSON:{blockState:{blockName:"ancientwarfarestructure:advanced_spawner",properties:{transparent:"true"}},teData:{id:"ancientwarfarestructure:advanced_spawner_tile",spawnerSettings:{minDelay:10,spawnDelay:8,lightSensitive:0b,spawnGroups:[{settingsList:[{remainingSpawnCount:1,hostile:1b,customTag:{ArmorDropChances:[0.085f,0.085f,0.085f,0.085f],hasCustomEquipment:0b,ArmorItems:[{},{},{},{}],skinSettings:{npcTypeName:"custom",skinTypeSelected:"default"},HandDropChances:[0.085f,0.085f],factionName:"sarkonid",HandItems:[{},{}]},maxToSpawn:1,entityId:"ancientwarfarenpc:faction.civilian.female",minToSpawn:1}],groupWeight:1}],playerRange:16,respondToRedstone:0b,inventory:{Size:9,Items:[]},spawnRange:0,transparent:1b,maxDelay:10,spawnYOffset:0,xpToDrop:0,mobRange:0,debugMode:0b,maxNearbyMonsters:0}}}
:enddata
:endrule

rule:
plugin=blockTile
number=55
data:
JSON:{blockState:{blockName:"ancientwarfarestructure:advanced_spawner",properties:{transparent:"true"}},teData:{id:"ancientwarfarestructure:advanced_spawner_tile",spawnerSettings:{minDelay:10,spawnDelay:5,lightSensitive:0b,spawnGroups:[{settingsList:[{remainingSpawnCount:1,hostile:1b,customTag:{ArmorDropChances:[0.085f,0.085f,0.085f,0.085f],hasCustomEquipment:0b,ArmorItems:[{},{},{},{}],skinSettings:{npcTypeName:"custom",skinTypeSelected:"default"},HandDropChances:[0.085f,0.085f],factionName:"sarkonid",HandItems:[{id:"ancientwarfarenpc:golden_spear",Count:1b,Damage:0s},{id:"ancientwarfarenpc:gold_shield",Count:1b,Damage:0s}]},maxToSpawn:1,entityId:"ancientwarfarenpc:faction.soldier",minToSpawn:1}],groupWeight:1}],playerRange:16,respondToRedstone:0b,inventory:{Size:9,Items:[]},spawnRange:0,transparent:1b,maxDelay:10,spawnYOffset:0,xpToDrop:0,mobRange:0,debugMode:0b,maxNearbyMonsters:0}}}
:enddata
:endrule

rule:
plugin=blockTile
number=56
data:
JSON:{blockState:{blockName:"ancientwarfarestructure:advanced_spawner",properties:{transparent:"true"}},teData:{id:"ancientwarfarestructure:advanced_spawner_tile",spawnerSettings:{minDelay:10,spawnDelay:8,lightSensitive:0b,spawnGroups:[{settingsList:[{remainingSpawnCount:1,hostile:1b,customTag:{ArmorDropChances:[0.085f,0.085f,0.085f,0.085f],hasCustomEquipment:0b,ArmorItems:[{},{},{},{}],skinSettings:{npcTypeName:"custom",skinTypeSelected:"default"},HandDropChances:[0.085f,0.085f],factionName:"sarkonid",HandItems:[{id:"ancientwarfarenpc:golden_spear",Count:1b,Damage:0s},{id:"ancientwarfarenpc:gold_shield",Count:1b,Damage:0s}]},maxToSpawn:1,entityId:"ancientwarfarenpc:faction.soldier",minToSpawn:1}],groupWeight:1}],playerRange:16,respondToRedstone:0b,inventory:{Size:9,Items:[]},spawnRange:0,transparent:1b,maxDelay:10,spawnYOffset:0,xpToDrop:0,mobRange:0,debugMode:0b,maxNearbyMonsters:0}}}
:enddata
:endrule

rule:
plugin=vanillaBlocks
number=57
data:
JSON:{blockState:{blockName:"minecraft:glass_pane",properties:{east:"false",south:"false",north:"false",west:"false"}}}
:enddata
:endrule

rule:
plugin=doors
number=58
data:
JSON:{blockState:{blockName:"minecraft:wooden_door",properties:{hinge:"right",half:"upper",powered:"false",facing:"north",open:"false"}}}
:enddata
:endrule

rule:
plugin=doors
number=59
data:
JSON:{blockState:{blockName:"minecraft:wooden_door",properties:{hinge:"left",half:"upper",powered:"false",facing:"north",open:"false"}}}
:enddata
:endrule

rule:
plugin=vanillaBlocks
number=60
data:
JSON:{blockState:{blockName:"minecraft:torch",properties:{facing:"up"}}}
:enddata
:endrule

rule:
plugin=vanillaBlocks
number=61
data:
JSON:{blockState:{blockName:"minecraft:torch",properties:{facing:"east"}}}
:enddata
:endrule

rule:
plugin=vanillaBlocks
number=62
data:
JSON:{blockState:{blockName:"minecraft:torch",properties:{facing:"south"}}}
:enddata
:endrule

rule:
plugin=vanillaBlocks
number=63
data:
JSON:{blockState:{blockName:"minecraft:torch",properties:{facing:"north"}}}
:enddata
:endrule

rule:
plugin=vanillaBlocks
number=64
data:
JSON:{blockState:{blockName:"minecraft:torch",properties:{facing:"west"}}}
:enddata
:endrule

rule:
plugin=vanillaBlocks
number=65
data:
JSON:{blockState:{blockName:"minecraft:stone_slab",properties:{half:"bottom",variant:"sandstone"}}}
:enddata
:endrule

rule:
plugin=vanillaBlocks
number=66
data:
JSON:{blockState:{blockName:"minecraft:wooden_slab",properties:{half:"bottom",variant:"birch"}}}
:enddata
:endrule

rule:
plugin=vanillaBlocks
number=67
data:
JSON:{blockState:{blockName:"minecraft:wool",properties:{color:"red"}}}
:enddata
:endrule

rule:
plugin=vanillaBlocks
number=68
data:
JSON:{blockState:{blockName:"minecraft:wool",properties:{color:"cyan"}}}
:enddata
:endrule

rule:
plugin=vanillaBlocks
number=69
data:
JSON:{blockState:{blockName:"minecraft:stained_hardened_clay",properties:{color:"pink"}}}
:enddata
:endrule

rule:
plugin=vanillaBlocks
number=70
data:
JSON:{blockState:{blockName:"minecraft:stone_slab2",properties:{half:"bottom",variant:"red_sandstone"}}}
:enddata
:endrule

rule:
plugin=vanillaBlocks
number=71
data:
JSON:{blockState:{blockName:"minecraft:red_sandstone_stairs",properties:{half:"top",shape:"straight",facing:"south"}}}
:enddata
:endrule

rule:
plugin=vanillaBlocks
number=72
data:
JSON:{blockState:{blockName:"minecraft:stone_slab",properties:{half:"top",variant:"sandstone"}}}
:enddata
:endrule

rule:
plugin=vanillaBlocks
number=73
data:
JSON:{blockState:{blockName:"minecraft:red_sandstone_stairs",properties:{half:"top",shape:"straight",facing:"west"}}}
:enddata
:endrule

rule:
plugin=vanillaBlocks
number=74
data:
JSON:{blockState:{blockName:"minecraft:wooden_slab",properties:{half:"bottom",variant:"spruce"}}}
:enddata
:endrule

rule:
plugin=vanillaBlocks
number=75
data:
JSON:{blockState:{blockName:"minecraft:red_sandstone_stairs",properties:{half:"top",shape:"straight",facing:"north"}}}
:enddata
:endrule

rule:
plugin=vanillaBlocks
number=76
data:
JSON:{blockState:{blockName:"minecraft:sandstone_stairs",properties:{half:"top",shape:"straight",facing:"south"}}}
:enddata
:endrule

rule:
plugin=vanillaBlocks
number=77
data:
JSON:{blockState:{blockName:"minecraft:sandstone_stairs",properties:{half:"top",shape:"straight",facing:"east"}}}
:enddata
:endrule

rule:
plugin=vanillaBlocks
number=78
data:
JSON:{blockState:{blockName:"minecraft:sandstone_stairs",properties:{half:"top",shape:"straight",facing:"west"}}}
:enddata
:endrule

rule:
plugin=vanillaBlocks
number=79
data:
JSON:{blockState:{blockName:"minecraft:sandstone_stairs",properties:{half:"top",shape:"straight",facing:"north"}}}
:enddata
:endrule

rule:
plugin=vanillaBlocks
number=80
data:
JSON:{blockState:{blockName:"minecraft:stone_slab2",properties:{half:"top",variant:"red_sandstone"}}}
:enddata
:endrule

rule:
plugin=vanillaBlocks
number=81
data:
JSON:{blockState:{blockName:"minecraft:red_sandstone_stairs",properties:{half:"top",shape:"straight",facing:"east"}}}
:enddata
:endrule

rule:
plugin=vanillaBlocks
number=82
data:
JSON:{blockState:{blockName:"minecraft:stained_hardened_clay",properties:{color:"red"}}}
:enddata
:endrule

rule:
plugin=vanillaBlocks
number=83
data:
JSON:{blockState:{blockName:"minecraft:double_stone_slab2",properties:{seamless:"false",variant:"red_sandstone"}}}
:enddata
:endrule

rule:
plugin=vanillaBlocks
number=84
data:
JSON:{blockState:{blockName:"minecraft:cocoa",properties:{facing:"north",age:"2"}}}
:enddata
:endrule

rule:
plugin=vanillaBlocks
number=85
data:
JSON:{blockState:{blockName:"minecraft:sandstone_stairs",properties:{half:"bottom",shape:"straight",facing:"south"}}}
:enddata
:endrule

rule:
plugin=vanillaBlocks
number=86
data:
JSON:{blockState:{blockName:"minecraft:sandstone_stairs",properties:{half:"bottom",shape:"straight",facing:"east"}}}
:enddata
:endrule

rule:
plugin=vanillaBlocks
number=87
data:
JSON:{blockState:{blockName:"minecraft:sandstone_stairs",properties:{half:"bottom",shape:"straight",facing:"west"}}}
:enddata
:endrule

rule:
plugin=vanillaBlocks
number=88
data:
JSON:{blockState:{blockName:"minecraft:double_stone_slab",properties:{seamless:"false",variant:"sandstone"}}}
:enddata
:endrule

rule:
plugin=vanillaBlocks
number=89
data:
JSON:{blockState:{blockName:"minecraft:stained_hardened_clay",properties:{color:"orange"}}}
:enddata
:endrule

rule:
plugin=vanillaBlocks
number=90
data:
JSON:{blockState:{blockName:"minecraft:sandstone_stairs",properties:{half:"bottom",shape:"straight",facing:"north"}}}
:enddata
:endrule

rule:
plugin=vanillaBlocks
number=91
data:
JSON:{blockState:{blockName:"minecraft:leaves",properties:{check_decay:"true",decayable:"false",variant:"jungle"}}}
:enddata
:endrule

rule:
plugin=vanillaBlocks
number=92
data:
JSON:{blockState:{blockName:"minecraft:leaves",properties:{check_decay:"false",decayable:"false",variant:"jungle"}}}
:enddata
:endrule

rule:
plugin=vanillaBlocks
number=93
data:
JSON:{blockState:{blockName:"minecraft:cocoa",properties:{facing:"west",age:"2"}}}
:enddata
:endrule

rule:
plugin=vanillaBlocks
number=94
data:
JSON:{blockState:{blockName:"minecraft:cocoa",properties:{facing:"south",age:"2"}}}
:enddata
:endrule

rule:
plugin=vanillaBlocks
number=95
data:
JSON:{blockState:{blockName:"minecraft:cocoa",properties:{facing:"east",age:"2"}}}
:enddata
:endrule

#### ENTITIES ####
