# Ancient Warfare Structure Template File
# Auto-generated structure template file. created on: 5/12/2021 at: 11:47:2
# Lines beginning with # denote comments

header:
version=2.11
name=SurvivalBuildStoneChurch
mods=
size=15,16,25
offset=14,1,24
:endheader

#### VALIDATION ####
validation:
type=ground
structureAuthor=Loki61089
survival=true
worldGenEnabled=false
unique=false
preserveBlocks=false
preventNaturalHostileSpawns=false
selectionWeight=1
clusterValue=1
minDuplicateDistance=1
dimensionWhiteList=true
dimensionList=
biomeGroupList=
biomeWhiteList=true
biomeList=
leveling=0
fill=0
border=0
blockSwap=false
territoryName=
biomeReplacement=minecraft:
minGenerationHeight=0
maxGenerationHeight=255
:endvalidation

#### LAYERS ####
layer: 0
1,1,1,1,1,1,1,1,1,1,1,1,1,1,1
1,1,1,2,2,2,2,2,2,2,2,2,1,1,1
1,1,1,2,3,3,4,4,4,3,3,2,1,1,1
1,1,1,2,3,3,4,4,4,3,3,2,1,1,1
1,1,1,2,3,4,4,4,4,4,3,2,1,1,1
1,1,1,2,3,4,4,4,4,4,3,2,1,1,1
1,1,1,2,4,4,4,4,4,4,4,2,1,1,1
1,1,1,2,4,4,4,4,4,4,4,2,1,1,1
1,1,1,2,3,4,4,4,4,4,3,2,1,1,1
1,2,2,3,2,4,4,4,4,4,2,3,2,2,1
1,2,3,3,3,4,4,4,4,4,3,3,3,2,1
1,2,3,5,5,5,5,5,5,5,5,5,3,2,1
1,2,3,4,4,4,5,5,5,4,4,4,3,2,1
1,2,3,4,4,4,5,5,5,4,4,4,3,2,1
1,2,3,4,4,4,5,5,5,4,4,4,3,2,1
1,2,3,4,4,4,5,5,5,4,4,4,3,2,1
1,2,3,4,4,4,5,5,5,4,4,4,3,2,1
1,2,3,4,4,4,5,5,5,4,4,4,3,2,1
1,2,3,4,4,4,5,5,5,4,4,4,3,2,1
1,2,5,5,5,5,5,5,5,5,5,5,5,2,1
1,2,3,3,3,4,5,5,5,4,3,3,3,2,1
1,2,3,3,3,2,4,4,4,2,3,3,3,2,1
1,1,2,2,2,2,3,3,3,2,2,2,2,1,1
1,1,1,1,1,2,2,2,2,2,1,1,1,1,1
1,1,1,1,1,1,1,1,1,1,1,1,1,1,1
:endlayer
layer: 1
0,0,0,0,0,0,0,0,0,0,0,0,0,0,0
0,0,0,2,2,2,2,2,2,2,2,2,0,0,0
0,0,0,8,2,4,4,4,4,4,2,7,0,0,0
0,0,0,8,2,4,4,4,4,4,2,7,0,0,0
0,0,0,8,2,4,4,4,4,4,2,7,0,0,0
0,0,0,2,2,4,4,4,4,4,2,2,0,0,0
0,0,0,8,2,4,4,4,4,4,2,7,0,0,0
0,0,0,8,2,4,4,4,4,4,2,7,0,0,0
0,0,0,8,2,4,4,4,4,4,2,7,0,0,0
0,2,11,2,2,4,4,4,4,4,2,2,11,2,0
0,8,2,2,2,10,4,4,4,10,2,2,2,7,0
0,8,2,0,0,0,0,0,0,0,0,0,2,7,0
0,8,2,0,0,0,0,0,0,0,0,0,2,7,0
0,2,2,0,0,0,0,0,0,0,0,0,2,2,0
0,8,2,0,0,0,0,0,0,0,0,0,2,7,0
0,8,2,0,0,0,0,0,0,0,0,0,2,7,0
0,8,2,0,0,0,0,0,0,0,0,0,2,7,0
0,2,2,0,0,0,0,0,0,0,0,0,2,2,0
0,8,2,0,0,0,0,0,0,0,0,0,2,7,0
0,0,9,0,0,0,0,0,0,0,0,0,9,0,0
0,8,2,2,2,2,0,0,0,2,2,2,2,7,0
0,2,2,2,2,2,0,0,0,2,2,2,2,2,0
0,0,2,2,2,2,2,2,2,2,2,2,2,0,0
0,0,0,0,0,2,6,6,6,2,0,0,0,0,0
0,0,0,0,0,0,0,0,0,0,0,0,0,0,0
:endlayer
layer: 2
0,0,0,18,0,0,0,0,0,0,0,18,0,0,0
0,0,15,2,13,13,13,13,13,13,13,2,14,0,0
0,0,0,0,13,0,0,0,0,0,13,0,0,0,0
0,0,0,0,13,0,0,0,0,0,13,0,0,0,0
0,0,0,0,13,0,0,0,0,0,13,0,0,0,0
0,0,15,2,2,0,0,0,0,0,2,2,14,0,0
0,0,0,0,13,0,0,0,0,0,13,0,0,0,0
0,0,0,0,13,0,0,0,0,0,13,0,0,0,0
0,0,0,0,13,0,0,0,0,0,13,0,0,18,0
15,2,0,2,2,0,0,0,0,0,2,2,0,2,14
0,0,13,2,2,0,0,0,0,0,2,2,13,0,0
0,0,17,0,0,0,0,0,0,0,0,0,17,0,0
0,0,13,0,0,0,0,0,0,0,0,0,13,0,0
15,2,2,14,0,0,0,0,0,0,0,15,2,2,14
0,0,13,0,0,0,0,0,0,0,0,0,13,0,0
0,0,17,0,0,0,0,0,0,0,0,0,17,0,0
0,0,13,0,0,0,0,0,0,0,0,0,13,0,0
15,2,2,14,0,0,0,0,0,0,0,15,2,2,14
0,0,13,0,0,0,0,0,0,0,0,0,13,0,0
0,0,16,0,0,0,0,0,0,0,0,0,16,0,0
0,0,13,13,13,2,0,0,0,2,13,13,13,0,0
15,2,13,13,13,2,0,0,0,2,13,13,13,2,14
0,0,2,13,13,13,13,13,13,13,13,13,2,0,0
0,0,12,0,0,2,0,0,0,2,0,0,12,0,0
0,0,0,0,0,12,0,0,0,12,0,0,0,0,0
:endlayer
layer: 3
0,0,0,0,0,0,0,0,0,0,0,0,0,0,0
0,0,0,2,13,13,13,22,13,13,13,2,0,0,0
0,0,0,0,13,0,12,0,12,0,13,0,0,0,0
0,0,0,0,21,0,0,0,0,0,21,0,0,0,0
0,0,0,0,13,0,0,0,0,0,13,0,0,0,0
0,0,0,2,2,0,0,0,0,0,2,2,0,0,0
0,0,0,0,13,0,0,0,0,0,13,0,0,0,0
0,0,0,0,21,0,0,0,0,0,21,0,0,0,0
0,0,0,0,13,0,0,0,0,0,13,0,0,0,0
0,2,0,2,2,14,0,0,0,15,2,2,0,2,0
0,0,13,2,2,0,0,0,0,0,2,2,13,0,0
0,0,17,0,12,0,0,0,0,0,12,0,17,0,0
0,0,13,0,0,0,0,0,0,0,0,0,13,0,0
0,2,2,20,0,0,0,0,0,0,0,19,2,2,0
0,0,13,0,0,0,0,0,0,0,0,0,13,0,0
0,0,17,0,0,0,0,0,0,0,0,0,17,0,0
0,0,13,0,0,0,0,0,0,0,0,0,13,0,0
0,2,2,20,0,0,0,0,0,0,0,19,2,2,0
0,0,13,0,0,0,0,0,0,0,0,0,13,0,0
0,0,13,0,0,18,0,0,0,18,0,0,13,0,0
0,0,13,13,13,2,0,0,0,2,13,13,13,0,0
0,2,13,13,13,2,0,0,0,2,13,13,13,2,0
0,0,2,13,13,13,13,17,13,13,13,13,2,0,0
0,0,0,0,0,2,0,0,0,2,0,0,0,0,0
0,0,0,0,0,0,0,0,0,0,0,0,0,0,0
:endlayer
layer: 4
0,0,0,0,0,0,0,0,0,0,0,0,0,0,0
0,0,0,2,13,13,22,21,22,13,13,2,0,0,0
0,0,0,0,13,0,0,0,0,0,13,0,0,0,0
0,0,0,0,22,0,0,0,0,0,22,0,0,0,0
0,0,0,0,13,0,0,0,0,0,13,0,0,0,0
0,0,0,2,2,14,0,0,0,15,2,2,0,0,0
0,0,0,0,13,0,0,0,0,0,13,0,0,0,0
0,0,0,0,22,0,0,0,0,0,22,0,0,0,0
0,0,0,0,13,0,0,0,0,0,13,0,0,0,0
0,2,0,2,2,20,0,0,0,19,2,2,0,2,0
0,0,13,2,2,20,0,0,0,19,2,2,13,0,0
0,0,13,23,0,0,0,0,0,0,0,23,13,0,0
0,0,13,25,0,0,0,0,0,0,0,25,13,0,0
0,2,2,2,14,0,0,0,0,0,15,2,2,2,0
0,0,13,24,0,0,0,0,0,0,0,24,13,0,0
0,0,13,23,0,0,0,0,0,0,0,23,13,0,0
0,0,13,25,0,0,0,0,0,0,0,25,13,0,0
0,2,2,2,14,0,0,0,0,0,15,2,2,2,0
0,0,13,24,0,0,0,0,0,0,0,24,13,0,0
0,0,13,23,0,0,0,0,0,0,0,23,13,0,0
0,0,13,13,13,2,0,0,0,2,13,13,13,0,0
0,2,13,13,13,2,0,0,0,2,13,13,13,2,0
0,0,2,13,13,13,13,17,13,13,13,13,2,0,0
0,0,0,0,0,2,0,0,0,2,0,0,0,0,0
0,0,0,0,0,0,0,0,0,0,0,0,0,0,0
:endlayer
layer: 5
0,0,0,0,0,0,0,0,0,0,0,0,0,0,0
0,0,26,2,13,13,21,28,21,13,13,2,26,0,0
0,0,0,24,13,0,0,0,0,0,13,24,0,0,0
0,0,0,23,13,0,0,0,0,0,13,23,0,0,0
0,0,0,25,13,0,0,0,0,0,13,25,0,0,0
0,0,0,2,2,0,0,0,0,0,2,2,26,0,0
0,0,0,24,13,0,0,0,0,0,13,24,0,0,0
0,0,0,23,13,0,0,0,0,0,13,23,0,0,0
0,0,0,25,13,0,0,0,0,0,13,25,0,0,0
26,2,25,2,2,2,2,23,2,2,2,2,25,2,26
0,24,13,2,2,2,2,23,2,2,2,2,13,24,0
0,23,13,27,0,0,0,0,0,0,0,27,13,23,0
0,25,13,11,0,0,0,0,0,0,0,11,13,25,0
26,2,2,7,0,0,0,0,0,0,0,8,2,2,26
0,24,13,6,0,0,0,0,0,0,0,6,13,24,0
0,23,13,27,0,0,0,0,0,0,0,27,13,23,0
0,25,13,11,0,0,0,0,0,0,0,11,13,25,0
26,2,2,7,0,0,0,0,0,0,0,8,2,2,26
0,24,13,6,0,0,0,0,0,0,0,6,13,24,0
0,23,13,2,25,25,20,0,19,25,25,2,13,23,0
0,25,13,13,13,2,20,0,19,2,13,13,13,25,0
26,2,13,13,13,2,20,25,19,2,13,13,13,2,26
0,0,2,2,2,2,13,13,13,2,2,2,2,0,0
0,0,0,0,0,2,20,23,19,2,0,0,0,0,0
0,0,0,0,0,0,0,0,0,0,0,0,0,0,0
:endlayer
layer: 6
0,0,0,0,0,0,0,0,0,0,0,0,0,0,0
0,0,27,2,13,13,22,21,22,13,13,2,27,0,0
0,0,0,30,13,0,0,0,0,0,13,29,0,0,0
0,0,0,30,13,0,0,0,0,0,13,29,0,0,0
0,0,0,30,13,0,0,0,0,0,13,29,0,0,0
0,0,27,2,2,32,0,0,0,31,13,2,27,0,0
0,0,0,30,13,0,0,0,0,0,13,29,0,0,0
0,0,0,30,13,0,0,0,0,0,13,29,0,0,0
0,0,0,30,13,0,0,0,0,0,13,29,0,0,0
27,2,13,13,13,2,2,2,2,2,13,13,13,2,27
0,30,13,2,2,2,2,2,2,2,2,2,13,29,0
0,30,13,0,0,0,0,0,0,0,0,0,13,29,0
0,30,13,0,0,0,0,0,0,0,0,0,13,29,0
27,2,13,32,0,0,0,0,0,0,0,31,13,2,27
0,30,13,0,0,0,0,0,0,0,0,0,13,29,0
0,30,13,0,0,0,0,0,0,0,0,0,13,29,0
0,30,13,0,0,0,0,0,0,0,0,0,13,29,0
27,2,13,32,0,0,0,0,0,0,0,31,13,2,27
0,30,13,0,0,0,0,0,0,0,0,0,13,29,0
0,30,13,2,2,2,2,0,2,2,2,2,13,29,0
0,30,13,13,13,2,7,0,8,2,13,13,13,29,0
27,2,13,13,13,13,2,11,2,13,13,13,13,2,27
0,26,2,13,13,13,13,13,13,13,13,13,2,26,0
0,0,0,0,0,2,7,0,8,2,0,0,0,0,0
0,0,0,0,0,0,0,0,0,0,0,0,0,0,0
:endlayer
layer: 7
0,0,0,0,0,0,0,0,0,0,0,0,0,0,0
0,0,0,27,2,13,13,22,13,13,2,27,0,0,0
0,0,0,0,30,34,0,0,0,33,29,0,0,0,0
0,0,0,0,30,34,0,0,0,33,29,0,0,0,0
0,0,0,0,30,34,0,0,0,33,29,0,0,0,0
0,0,0,27,2,4,32,0,31,4,2,27,0,0,0
0,0,0,0,30,34,0,0,0,33,29,0,0,0,0
0,0,0,0,30,34,0,0,0,33,29,0,0,0,0
0,0,0,0,30,34,0,0,0,33,29,0,0,0,0
0,27,2,13,13,2,2,2,2,2,13,13,2,27,0
0,0,30,2,2,2,2,2,2,2,2,2,29,0,0
0,0,30,34,0,0,0,0,0,0,0,33,29,0,0
0,0,30,34,0,0,0,0,0,0,0,33,29,0,0
0,27,2,4,32,0,0,0,0,0,31,4,2,27,0
0,0,30,34,0,0,0,0,0,0,0,33,29,0,0
0,0,30,34,0,0,0,0,0,0,0,33,29,0,0
0,0,30,34,0,0,0,0,0,0,0,33,29,0,0
0,27,2,4,32,0,0,0,0,0,31,4,2,27,0
0,0,30,34,0,0,0,0,0,0,0,33,29,0,0
0,0,30,2,2,2,2,0,2,2,2,2,29,0,0
0,0,30,13,13,13,0,0,0,13,13,13,29,0,0
0,27,2,13,13,13,2,0,2,13,13,13,2,27,0
0,27,2,13,13,13,13,17,13,13,13,13,2,27,0
0,0,0,0,0,2,0,0,0,2,0,0,0,0,0
0,0,0,0,0,0,0,0,0,0,0,0,0,0,0
:endlayer
layer: 8
0,0,0,0,0,0,0,0,0,0,0,0,0,0,0
0,0,0,0,27,2,13,13,13,2,27,0,0,0,0
0,0,0,0,0,30,34,35,33,29,0,0,0,0,0
0,0,0,0,0,30,34,35,33,29,0,0,0,0,0
0,0,0,0,0,30,34,35,33,29,0,0,0,0,0
0,0,0,0,27,2,4,4,4,2,27,0,0,0,0
0,0,0,0,0,30,34,35,33,29,0,0,0,0,0
0,0,0,0,0,30,34,35,33,29,0,0,0,0,0
0,0,0,0,0,30,34,35,33,29,0,0,0,0,0
0,0,27,2,13,13,2,2,2,13,13,2,27,0,0
0,0,0,30,2,2,2,2,2,2,2,29,0,0,0
0,0,0,30,34,0,0,0,0,0,33,29,0,0,0
0,0,0,30,34,0,0,0,0,0,33,29,0,0,0
0,0,27,2,4,32,0,0,0,31,4,2,27,0,0
0,0,0,30,34,0,0,0,0,0,33,29,0,0,0
0,0,0,30,34,0,0,0,0,0,33,29,0,0,0
0,0,0,30,34,0,0,0,0,0,33,29,0,0,0
0,0,27,2,4,32,0,0,0,31,4,2,27,0,0
0,0,0,30,34,0,0,0,0,0,33,29,0,0,0
0,0,0,30,2,2,2,0,2,2,2,29,0,0,0
0,0,0,30,13,13,0,0,0,13,13,29,0,0,0
0,0,27,2,13,13,2,0,2,13,13,2,27,0,0
0,0,27,2,13,13,13,17,13,13,13,2,27,0,0
0,0,0,0,0,2,0,0,0,2,0,0,0,0,0
0,0,0,0,0,0,0,0,0,0,0,0,0,0,0
:endlayer
layer: 9
0,0,0,0,0,0,0,0,0,0,0,0,0,0,0
0,0,0,0,0,27,2,2,2,27,0,0,0,0,0
0,0,0,0,0,0,36,36,36,0,0,0,0,0,0
0,0,0,0,0,0,36,36,36,0,0,0,0,0,0
0,0,0,0,0,0,36,36,36,0,0,0,0,0,0
0,0,0,0,0,27,2,2,2,27,0,0,0,0,0
0,0,0,0,0,0,36,36,36,0,0,0,0,0,0
0,0,0,0,0,0,36,36,36,0,0,0,0,0,0
0,0,0,0,0,0,36,36,36,0,0,0,0,0,0
0,0,0,27,2,13,13,13,13,13,2,27,0,0,0
0,0,0,0,30,2,2,2,2,2,29,0,0,0,0
0,0,0,0,30,34,0,0,0,33,29,0,0,0,0
0,0,0,0,30,34,0,0,0,33,29,0,0,0,0
0,0,0,27,2,4,32,0,31,4,2,27,0,0,0
0,0,0,0,30,34,0,0,0,33,29,0,0,0,0
0,0,0,0,30,34,0,0,0,33,29,0,0,0,0
0,0,0,0,30,34,0,0,0,33,29,0,0,0,0
0,0,0,27,2,4,32,0,31,4,2,27,0,0,0
0,0,0,0,30,34,0,0,0,33,29,0,0,0,0
0,0,0,0,30,2,2,23,2,2,29,0,0,0,0
0,0,0,0,30,2,20,23,19,2,29,0,0,0,0
0,0,0,27,2,2,2,25,2,2,2,27,0,0,0
0,0,0,27,2,2,13,13,13,2,2,27,0,0,0
0,0,0,0,0,2,20,23,19,2,0,0,0,0,0
0,0,0,0,0,0,0,0,0,0,0,0,0,0,0
:endlayer
layer: 10
0,0,0,0,0,0,0,0,0,0,0,0,0,0,0
0,0,0,0,0,0,27,2,27,0,0,0,0,0,0
0,0,0,0,0,0,0,0,0,0,0,0,0,0,0
0,0,0,0,0,0,0,0,0,0,0,0,0,0,0
0,0,0,0,0,0,0,0,0,0,0,0,0,0,0
0,0,0,0,0,0,27,27,27,0,0,0,0,0,0
0,0,0,0,0,0,0,0,0,0,0,0,0,0,0
0,0,0,0,0,0,0,0,0,0,0,0,0,0,0
0,0,0,0,0,0,0,0,0,0,0,0,0,0,0
0,0,0,0,27,2,13,13,13,2,27,0,0,0,0
0,0,0,0,0,30,2,2,2,29,0,0,0,0,0
0,0,0,0,0,30,34,35,33,29,0,0,0,0,0
0,0,0,0,0,30,34,35,33,29,0,0,0,0,0
0,0,0,0,27,2,4,4,4,2,27,0,0,0,0
0,0,0,0,0,30,34,35,33,29,0,0,0,0,0
0,0,0,0,0,30,34,35,33,29,0,0,0,0,0
0,0,0,0,0,30,34,35,33,29,0,0,0,0,0
0,0,0,0,27,2,4,4,4,2,27,0,0,0,0
0,0,0,0,0,30,34,35,33,29,0,0,0,0,0
0,0,0,0,0,2,13,13,13,2,0,0,0,0,0
0,0,0,0,0,13,13,13,13,13,0,0,0,0,0
0,0,0,0,27,13,13,13,13,13,27,0,0,0,0
0,0,0,0,27,13,13,13,13,13,27,0,0,0,0
0,0,0,0,0,2,7,0,8,2,0,0,0,0,0
0,0,0,0,0,0,0,0,0,0,0,0,0,0,0
:endlayer
layer: 11
0,0,0,0,0,0,0,0,0,0,0,0,0,0,0
0,0,0,0,0,0,0,26,0,0,0,0,0,0,0
0,0,0,0,0,0,0,0,0,0,0,0,0,0,0
0,0,0,0,0,0,0,0,0,0,0,0,0,0,0
0,0,0,0,0,0,0,0,0,0,0,0,0,0,0
0,0,0,0,0,0,0,0,0,0,0,0,0,0,0
0,0,0,0,0,0,0,0,0,0,0,0,0,0,0
0,0,0,0,0,0,0,0,0,0,0,0,0,0,0
0,0,0,0,0,0,0,0,0,0,0,0,0,0,0
0,0,0,0,0,27,2,2,2,27,0,0,0,0,0
0,0,0,0,0,0,36,36,36,0,0,0,0,0,0
0,0,0,0,0,0,36,36,36,0,0,0,0,0,0
0,0,0,0,0,0,36,36,36,0,0,0,0,0,0
0,0,0,0,0,27,2,2,2,27,0,0,0,0,0
0,0,0,0,0,0,36,36,36,0,0,0,0,0,0
0,0,0,0,0,0,36,36,36,0,0,0,0,0,0
0,0,0,0,0,0,36,36,36,0,0,0,0,0,0
0,0,0,0,0,27,2,2,2,27,0,0,0,0,0
0,0,0,0,0,0,36,36,36,0,0,0,0,0,0
0,0,0,0,0,2,13,13,13,2,0,0,0,0,0
0,0,0,0,0,13,13,13,13,13,0,0,0,0,0
0,0,0,0,0,0,13,13,13,0,0,0,0,0,0
0,0,0,0,0,13,13,0,13,13,0,0,0,0,0
0,0,0,0,0,2,0,0,0,2,0,0,0,0,0
0,0,0,0,0,0,0,0,0,0,0,0,0,0,0
:endlayer
layer: 12
0,0,0,0,0,0,0,0,0,0,0,0,0,0,0
0,0,0,0,0,0,0,0,0,0,0,0,0,0,0
0,0,0,0,0,0,0,0,0,0,0,0,0,0,0
0,0,0,0,0,0,0,0,0,0,0,0,0,0,0
0,0,0,0,0,0,0,0,0,0,0,0,0,0,0
0,0,0,0,0,0,0,0,0,0,0,0,0,0,0
0,0,0,0,0,0,0,0,0,0,0,0,0,0,0
0,0,0,0,0,0,0,0,0,0,0,0,0,0,0
0,0,0,0,0,0,0,0,0,0,0,0,0,0,0
0,0,0,0,0,0,27,2,27,0,0,0,0,0,0
0,0,0,0,0,0,0,0,0,0,0,0,0,0,0
0,0,0,0,0,0,0,0,0,0,0,0,0,0,0
0,0,0,0,0,0,0,0,0,0,0,0,0,0,0
0,0,0,0,0,0,27,27,27,0,0,0,0,0,0
0,0,0,0,0,0,0,0,0,0,0,0,0,0,0
0,0,0,0,0,0,0,0,0,0,0,0,0,0,0
0,0,0,0,0,0,0,0,0,0,0,0,0,0,0
0,0,0,0,0,0,27,27,27,0,0,0,0,0,0
0,0,0,0,0,0,0,0,0,0,0,0,0,0,0
0,0,0,0,0,2,13,13,13,2,0,0,0,0,0
0,0,0,0,0,13,13,13,13,13,0,0,0,0,0
0,0,0,0,0,37,13,13,13,37,0,0,0,0,0
0,0,0,0,0,13,13,37,13,13,0,0,0,0,0
0,0,0,0,0,2,0,0,0,2,0,0,0,0,0
0,0,0,0,0,0,0,0,0,0,0,0,0,0,0
:endlayer
layer: 13
0,0,0,0,0,0,0,0,0,0,0,0,0,0,0
0,0,0,0,0,0,0,0,0,0,0,0,0,0,0
0,0,0,0,0,0,0,0,0,0,0,0,0,0,0
0,0,0,0,0,0,0,0,0,0,0,0,0,0,0
0,0,0,0,0,0,0,0,0,0,0,0,0,0,0
0,0,0,0,0,0,0,0,0,0,0,0,0,0,0
0,0,0,0,0,0,0,0,0,0,0,0,0,0,0
0,0,0,0,0,0,0,0,0,0,0,0,0,0,0
0,0,0,0,0,0,0,0,0,0,0,0,0,0,0
0,0,0,0,0,0,0,26,0,0,0,0,0,0,0
0,0,0,0,0,0,0,0,0,0,0,0,0,0,0
0,0,0,0,0,0,0,0,0,0,0,0,0,0,0
0,0,0,0,0,0,0,0,0,0,0,0,0,0,0
0,0,0,0,0,0,0,0,0,0,0,0,0,0,0
0,0,0,0,0,0,0,0,0,0,0,0,0,0,0
0,0,0,0,0,0,0,0,0,0,0,0,0,0,0
0,0,0,0,0,0,0,0,0,0,0,0,0,0,0
0,0,0,0,0,0,0,0,0,0,0,0,0,0,0
0,0,0,0,0,0,0,0,0,0,0,0,0,0,0
0,0,0,0,0,2,2,2,2,2,0,0,0,0,0
0,0,0,0,0,2,13,13,13,2,0,0,0,0,0
0,0,0,0,0,2,13,13,13,2,0,0,0,0,0
0,0,0,0,0,2,13,13,13,2,0,0,0,0,0
0,0,0,0,0,2,20,23,19,2,0,0,0,0,0
0,0,0,0,0,0,0,0,0,0,0,0,0,0,0
:endlayer
layer: 14
0,0,0,0,0,0,0,0,0,0,0,0,0,0,0
0,0,0,0,0,0,0,0,0,0,0,0,0,0,0
0,0,0,0,0,0,0,0,0,0,0,0,0,0,0
0,0,0,0,0,0,0,0,0,0,0,0,0,0,0
0,0,0,0,0,0,0,0,0,0,0,0,0,0,0
0,0,0,0,0,0,0,0,0,0,0,0,0,0,0
0,0,0,0,0,0,0,0,0,0,0,0,0,0,0
0,0,0,0,0,0,0,0,0,0,0,0,0,0,0
0,0,0,0,0,0,0,0,0,0,0,0,0,0,0
0,0,0,0,0,0,0,0,0,0,0,0,0,0,0
0,0,0,0,0,0,0,0,0,0,0,0,0,0,0
0,0,0,0,0,0,0,0,0,0,0,0,0,0,0
0,0,0,0,0,0,0,0,0,0,0,0,0,0,0
0,0,0,0,0,0,0,0,0,0,0,0,0,0,0
0,0,0,0,0,0,0,0,0,0,0,0,0,0,0
0,0,0,0,0,0,0,0,0,0,0,0,0,0,0
0,0,0,0,0,0,0,0,0,0,0,0,0,0,0
0,0,0,0,0,0,0,0,0,0,0,0,0,0,0
0,0,0,0,0,0,0,0,0,0,0,0,0,0,0
0,0,0,0,0,2,0,2,0,2,0,0,0,0,0
0,0,0,0,0,0,13,13,13,0,0,0,0,0,0
0,0,0,0,0,2,13,13,13,2,0,0,0,0,0
0,0,0,0,0,0,13,13,13,0,0,0,0,0,0
0,0,0,0,0,2,0,2,0,2,0,0,0,0,0
0,0,0,0,0,0,0,0,0,0,0,0,0,0,0
:endlayer
layer: 15
0,0,0,0,0,0,0,0,0,0,0,0,0,0,0
0,0,0,0,0,0,0,0,0,0,0,0,0,0,0
0,0,0,0,0,0,0,0,0,0,0,0,0,0,0
0,0,0,0,0,0,0,0,0,0,0,0,0,0,0
0,0,0,0,0,0,0,0,0,0,0,0,0,0,0
0,0,0,0,0,0,0,0,0,0,0,0,0,0,0
0,0,0,0,0,0,0,0,0,0,0,0,0,0,0
0,0,0,0,0,0,0,0,0,0,0,0,0,0,0
0,0,0,0,0,0,0,0,0,0,0,0,0,0,0
0,0,0,0,0,0,0,0,0,0,0,0,0,0,0
0,0,0,0,0,0,0,0,0,0,0,0,0,0,0
0,0,0,0,0,0,0,0,0,0,0,0,0,0,0
0,0,0,0,0,0,0,0,0,0,0,0,0,0,0
0,0,0,0,0,0,0,0,0,0,0,0,0,0,0
0,0,0,0,0,0,0,0,0,0,0,0,0,0,0
0,0,0,0,0,0,0,0,0,0,0,0,0,0,0
0,0,0,0,0,0,0,0,0,0,0,0,0,0,0
0,0,0,0,0,0,0,0,0,0,0,0,0,0,0
0,0,0,0,0,0,0,0,0,0,0,0,0,0,0
0,0,0,0,0,2,27,2,27,2,0,0,0,0,0
0,0,0,0,0,27,0,0,0,27,0,0,0,0,0
0,0,0,0,0,2,0,0,0,2,0,0,0,0,0
0,0,0,0,0,27,0,0,0,27,0,0,0,0,0
0,0,0,0,0,2,27,2,27,2,0,0,0,0,0
0,0,0,0,0,0,0,0,0,0,0,0,0,0,0
:endlayer

#### RULES ####
rule:
plugin=vanillaBlocks
number=1
data:
JSON:{blockState:{blockName:"minecraft:grass",properties:{snowy:"false"}}}
:enddata
:endrule

rule:
plugin=vanillaBlocks
number=2
data:
JSON:{blockState:{blockName:"minecraft:stonebrick",properties:{variant:"stonebrick"}}}
:enddata
:endrule

rule:
plugin=vanillaBlocks
number=3
data:
JSON:{blockState:{blockName:"minecraft:dirt",properties:{variant:"dirt",snowy:"false"}}}
:enddata
:endrule

rule:
plugin=vanillaBlocks
number=4
data:
JSON:{blockState:{blockName:"minecraft:planks",properties:{variant:"spruce"}}}
:enddata
:endrule

rule:
plugin=vanillaBlocks
number=5
data:
JSON:{blockState:{blockName:"minecraft:wool",properties:{color:"red"}}}
:enddata
:endrule

rule:
plugin=vanillaBlocks
number=6
data:
JSON:{blockState:{blockName:"minecraft:stone_brick_stairs",properties:{half:"bottom",shape:"straight",facing:"north"}}}
:enddata
:endrule

rule:
plugin=vanillaBlocks
number=7
data:
JSON:{blockState:{blockName:"minecraft:stone_brick_stairs",properties:{half:"bottom",shape:"straight",facing:"west"}}}
:enddata
:endrule

rule:
plugin=vanillaBlocks
number=8
data:
JSON:{blockState:{blockName:"minecraft:stone_brick_stairs",properties:{half:"bottom",shape:"straight",facing:"east"}}}
:enddata
:endrule

rule:
plugin=doors
number=9
data:
JSON:{blockState:{blockName:"minecraft:wooden_door",properties:{hinge:"left",half:"lower",powered:"false",facing:"west",open:"false"}}}
:enddata
:endrule

rule:
plugin=vanillaBlocks
number=10
data:
JSON:{blockState:{blockName:"minecraft:spruce_stairs",properties:{half:"bottom",shape:"straight",facing:"north"}}}
:enddata
:endrule

rule:
plugin=vanillaBlocks
number=11
data:
JSON:{blockState:{blockName:"minecraft:stone_brick_stairs",properties:{half:"bottom",shape:"straight",facing:"south"}}}
:enddata
:endrule

rule:
plugin=vanillaBlocks
number=12
data:
JSON:{blockState:{blockName:"minecraft:torch",properties:{facing:"south"}}}
:enddata
:endrule

rule:
plugin=vanillaBlocks
number=13
data:
JSON:{blockState:{blockName:"minecraft:stone",properties:{variant:"andesite"}}}
:enddata
:endrule

rule:
plugin=vanillaBlocks
number=14
data:
JSON:{blockState:{blockName:"minecraft:torch",properties:{facing:"east"}}}
:enddata
:endrule

rule:
plugin=vanillaBlocks
number=15
data:
JSON:{blockState:{blockName:"minecraft:torch",properties:{facing:"west"}}}
:enddata
:endrule

rule:
plugin=doors
number=16
data:
JSON:{blockState:{blockName:"minecraft:wooden_door",properties:{hinge:"right",half:"upper",powered:"false",facing:"south",open:"false"}}}
:enddata
:endrule

rule:
plugin=vanillaBlocks
number=17
data:
JSON:{blockState:{blockName:"minecraft:stained_glass_pane",properties:{east:"false",color:"white",south:"false",north:"false",west:"false"}}}
:enddata
:endrule

rule:
plugin=vanillaBlocks
number=18
data:
JSON:{blockState:{blockName:"minecraft:torch",properties:{facing:"north"}}}
:enddata
:endrule

rule:
plugin=vanillaBlocks
number=19
data:
JSON:{blockState:{blockName:"minecraft:stone_brick_stairs",properties:{half:"top",shape:"straight",facing:"east"}}}
:enddata
:endrule

rule:
plugin=vanillaBlocks
number=20
data:
JSON:{blockState:{blockName:"minecraft:stone_brick_stairs",properties:{half:"top",shape:"straight",facing:"west"}}}
:enddata
:endrule

rule:
plugin=vanillaBlocks
number=21
data:
JSON:{blockState:{blockName:"minecraft:stained_glass_pane",properties:{east:"false",color:"light_blue",south:"false",north:"false",west:"false"}}}
:enddata
:endrule

rule:
plugin=vanillaBlocks
number=22
data:
JSON:{blockState:{blockName:"minecraft:stained_glass_pane",properties:{east:"false",color:"red",south:"false",north:"false",west:"false"}}}
:enddata
:endrule

rule:
plugin=vanillaBlocks
number=23
data:
JSON:{blockState:{blockName:"minecraft:stone_slab",properties:{half:"top",variant:"stone_brick"}}}
:enddata
:endrule

rule:
plugin=vanillaBlocks
number=24
data:
JSON:{blockState:{blockName:"minecraft:stone_brick_stairs",properties:{half:"top",shape:"straight",facing:"north"}}}
:enddata
:endrule

rule:
plugin=vanillaBlocks
number=25
data:
JSON:{blockState:{blockName:"minecraft:stone_brick_stairs",properties:{half:"top",shape:"straight",facing:"south"}}}
:enddata
:endrule

rule:
plugin=vanillaBlocks
number=26
data:
JSON:{blockState:{blockName:"minecraft:cobblestone_wall",properties:{east:"false",south:"false",north:"false",variant:"cobblestone",west:"false",up:"false"}}}
:enddata
:endrule

rule:
plugin=vanillaBlocks
number=27
data:
JSON:{blockState:{blockName:"minecraft:stone_slab",properties:{half:"bottom",variant:"stone_brick"}}}
:enddata
:endrule

rule:
plugin=vanillaBlocks
number=28
data:
JSON:{blockState:{blockName:"minecraft:stained_glass_pane",properties:{east:"false",color:"yellow",south:"false",north:"false",west:"false"}}}
:enddata
:endrule

rule:
plugin=vanillaBlocks
number=29
data:
JSON:{blockState:{blockName:"minecraft:dark_oak_stairs",properties:{half:"bottom",shape:"straight",facing:"west"}}}
:enddata
:endrule

rule:
plugin=vanillaBlocks
number=30
data:
JSON:{blockState:{blockName:"minecraft:dark_oak_stairs",properties:{half:"bottom",shape:"straight",facing:"east"}}}
:enddata
:endrule

rule:
plugin=vanillaBlocks
number=31
data:
JSON:{blockState:{blockName:"minecraft:spruce_stairs",properties:{half:"top",shape:"straight",facing:"east"}}}
:enddata
:endrule

rule:
plugin=vanillaBlocks
number=32
data:
JSON:{blockState:{blockName:"minecraft:spruce_stairs",properties:{half:"top",shape:"straight",facing:"west"}}}
:enddata
:endrule

rule:
plugin=vanillaBlocks
number=33
data:
JSON:{blockState:{blockName:"minecraft:dark_oak_stairs",properties:{half:"top",shape:"straight",facing:"east"}}}
:enddata
:endrule

rule:
plugin=vanillaBlocks
number=34
data:
JSON:{blockState:{blockName:"minecraft:dark_oak_stairs",properties:{half:"top",shape:"straight",facing:"west"}}}
:enddata
:endrule

rule:
plugin=vanillaBlocks
number=35
data:
JSON:{blockState:{blockName:"minecraft:wooden_slab",properties:{half:"top",variant:"dark_oak"}}}
:enddata
:endrule

rule:
plugin=vanillaBlocks
number=36
data:
JSON:{blockState:{blockName:"minecraft:wooden_slab",properties:{half:"bottom",variant:"dark_oak"}}}
:enddata
:endrule

rule:
plugin=vanillaBlocks
number=37
data:
JSON:{blockState:{blockName:"minecraft:iron_block"}}
:enddata
:endrule

#### ENTITIES ####
