# Ancient Warfare Structure Template File
# Auto-generated structure template file. created on: 5/12/2021 at: 11:51:13
# Lines beginning with # denote comments

header:
version=2.11
name=SurvivalBuildShopAEmpty
mods=
size=12,20,23
offset=11,4,22
:endheader

#### VALIDATION ####
validation:
type=ground
structureAuthor=Loki61089
survival=true
worldGenEnabled=false
unique=false
preserveBlocks=false
preventNaturalHostileSpawns=false
selectionWeight=1
clusterValue=1
minDuplicateDistance=1
dimensionWhiteList=true
dimensionList=
biomeGroupList=
biomeWhiteList=true
biomeList=
leveling=0
fill=0
border=0
blockSwap=false
territoryName=
biomeReplacement=minecraft:
minGenerationHeight=0
maxGenerationHeight=255
:endvalidation

#### LAYERS ####
layer: 0
1,1,1,1,1,1,1,1,1,1,1,1
1,1,1,1,1,1,1,1,1,1,1,1
1,1,1,1,1,1,1,1,1,1,1,1
1,1,1,1,1,1,1,1,1,1,1,1
1,1,1,1,1,1,1,1,1,1,1,1
1,1,1,1,1,1,1,1,1,1,1,1
1,1,1,1,1,1,1,1,1,1,1,1
1,1,1,1,1,1,1,1,1,1,1,1
1,1,1,1,1,1,1,1,1,1,1,1
1,1,1,1,1,1,1,1,1,1,1,1
1,1,1,1,1,1,1,1,1,1,1,1
1,1,1,1,1,1,1,1,1,1,1,1
1,1,1,1,1,1,1,1,1,1,1,1
1,1,1,1,1,1,1,1,1,1,1,1
1,1,1,1,1,1,1,1,1,1,1,1
1,1,1,1,1,1,1,1,1,1,1,1
1,1,1,1,1,1,1,1,1,1,1,1
1,1,1,1,1,1,1,1,1,1,1,1
1,1,1,1,1,1,1,1,1,1,1,1
1,1,1,1,1,1,1,1,1,1,1,1
1,1,1,1,1,1,1,1,1,1,1,1
1,1,1,1,1,1,1,1,1,1,1,1
1,1,1,1,1,1,1,1,1,1,1,1
:endlayer
layer: 1
1,1,1,1,1,1,1,1,1,1,1,1
1,1,1,1,1,1,1,1,1,1,1,1
1,1,1,1,1,1,1,1,1,1,1,1
1,1,1,1,1,1,1,1,1,1,1,1
1,0,0,0,0,0,0,0,1,1,1,1
1,0,0,0,0,0,0,0,1,1,1,1
1,0,0,0,0,0,0,0,1,3,1,1
1,0,0,0,1,0,0,0,1,0,1,1
1,0,0,0,0,0,0,0,0,0,1,1
1,0,0,0,0,0,0,0,0,0,1,1
1,0,0,0,0,0,0,0,0,0,1,1
1,0,0,0,0,0,0,0,0,0,1,1
1,0,0,0,0,0,0,0,0,0,1,1
1,0,0,0,1,0,0,0,1,0,1,1
1,0,0,0,0,0,0,0,1,2,1,1
1,0,0,0,0,0,0,0,1,1,1,1
1,0,0,0,0,0,0,0,1,1,1,1
1,1,1,1,1,1,1,1,1,1,1,1
1,1,1,1,1,1,1,1,1,1,1,1
1,1,1,1,1,1,1,1,1,1,1,1
1,1,1,1,1,1,1,1,1,1,1,1
1,1,1,1,1,1,1,1,1,1,1,1
1,1,1,1,1,1,1,1,1,1,1,1
:endlayer
layer: 2
1,1,1,1,1,1,1,1,1,1,1,1
1,1,1,1,1,1,1,1,1,1,1,1
1,1,1,1,1,1,1,1,1,1,1,1
1,1,1,1,1,1,1,1,1,1,1,1
1,0,0,0,0,0,0,0,1,1,1,1
1,0,0,0,0,0,0,0,1,3,1,1
1,0,0,0,0,0,0,0,1,0,1,1
1,0,0,5,1,4,0,0,1,0,1,1
1,0,0,0,0,0,0,0,7,0,1,1
1,0,0,0,0,0,0,0,0,0,1,1
1,0,0,0,0,0,0,0,0,0,1,1
1,0,0,0,0,0,0,0,0,0,1,1
1,0,0,0,0,0,0,0,6,0,1,1
1,0,0,5,1,4,0,0,1,0,1,1
1,0,0,0,0,0,0,0,1,0,1,1
1,0,0,0,0,0,0,0,1,2,1,1
1,0,0,0,0,0,0,0,1,1,1,1
1,1,1,1,1,1,1,1,1,1,1,1
1,1,1,1,1,1,1,1,1,1,1,1
1,1,1,1,1,1,1,1,1,1,1,1
1,1,1,1,1,1,1,1,1,1,1,1
1,1,1,1,1,1,1,1,1,1,1,1
1,1,1,1,1,1,1,1,1,1,1,1
:endlayer
layer: 3
1,1,1,1,1,1,1,1,1,1,1,1
1,1,1,1,1,1,1,1,1,1,1,1
1,1,1,1,1,1,1,1,1,1,1,1
1,1,1,1,1,1,1,1,1,1,1,1
1,1,1,1,1,1,1,1,1,3,1,1
1,1,1,1,1,1,1,1,1,0,1,1
1,1,1,1,1,1,1,1,1,0,1,1
1,1,1,1,1,1,1,1,1,0,1,1
1,1,1,1,1,1,1,1,1,9,1,1
1,1,1,1,1,1,1,1,1,1,1,1
1,1,1,1,1,1,1,1,1,1,1,1
1,1,1,1,1,1,1,1,1,1,1,1
1,1,1,1,1,1,1,1,1,8,1,1
1,1,1,1,1,1,1,1,1,0,1,1
1,1,1,1,1,1,1,1,1,0,1,1
1,1,1,1,1,1,1,1,1,0,1,1
1,1,1,1,1,1,1,1,1,2,1,1
1,1,1,1,1,1,1,1,1,1,1,1
1,1,1,1,1,1,1,1,1,1,1,1
1,1,1,1,1,1,1,1,1,1,1,1
1,1,1,1,1,1,1,1,1,1,1,1
1,1,1,1,1,1,1,1,1,1,1,1
1,1,1,1,1,1,1,1,1,1,1,1
:endlayer
layer: 4
0,0,0,0,0,0,0,0,0,0,0,0
0,0,0,0,0,1,1,1,0,0,0,0
0,10,12,11,11,11,19,11,11,11,10,0
0,11,0,0,0,0,0,0,0,0,11,0
0,11,0,0,0,0,0,0,0,13,11,0
0,11,0,0,0,0,0,0,0,13,11,0
0,11,0,0,0,0,0,0,0,13,11,0
0,10,12,11,10,11,11,11,11,18,10,0
0,11,0,0,11,0,0,0,0,0,11,0
0,11,0,0,11,0,0,0,0,0,11,0
0,11,0,0,12,0,0,0,0,0,17,0
0,11,0,0,11,0,0,0,0,0,11,0
0,11,0,0,11,16,16,15,0,0,11,0
0,10,12,12,10,11,11,11,11,14,10,0
0,11,0,0,12,0,0,0,10,13,11,0
0,11,0,0,11,0,0,0,10,13,11,0
0,11,0,0,11,0,0,0,10,13,11,0
0,11,0,0,11,0,0,0,0,0,11,0
0,10,12,12,10,11,11,11,11,11,10,0
0,0,0,0,0,0,0,0,0,0,0,0
0,10,0,0,10,0,0,0,0,0,10,0
0,0,0,0,0,0,0,0,0,0,0,0
0,0,0,0,0,0,0,0,0,0,0,0
:endlayer
layer: 5
0,0,0,0,0,0,6,0,0,0,0,0
0,6,0,0,0,1,1,1,0,0,6,0
0,10,23,1,21,1,1,1,21,1,10,0
0,1,0,0,0,0,7,0,0,0,1,0
0,1,0,0,0,0,0,0,0,0,1,0
0,1,0,0,0,0,0,0,0,0,1,0
0,1,0,0,0,0,6,0,0,0,1,0
0,10,23,1,10,1,1,1,1,1,10,0
0,1,0,0,1,0,0,0,0,0,1,0
0,1,0,0,1,0,0,0,0,0,1,0
0,1,4,0,23,0,0,0,0,0,1,0
0,1,0,0,1,0,0,0,0,0,1,0
0,1,0,0,1,16,15,0,0,0,1,0
0,10,22,23,10,1,1,1,1,1,10,0
0,1,0,0,23,0,0,0,0,0,1,0
0,1,4,0,1,0,0,0,0,0,1,0
0,1,0,0,1,0,0,0,0,0,1,0
0,1,0,0,1,0,0,0,24,0,1,0
0,10,23,22,10,21,21,21,1,1,10,0
0,0,0,0,20,0,0,0,0,0,0,0
0,10,0,0,10,0,0,0,0,0,10,0
0,7,0,0,7,0,0,0,0,0,7,0
0,0,0,0,0,0,0,0,0,0,0,0
:endlayer
layer: 6
0,0,0,0,0,0,0,0,0,0,0,0
0,0,0,0,0,26,1,25,0,0,0,0
0,10,1,1,1,1,1,1,1,1,10,0
0,1,0,0,0,0,0,0,0,0,1,0
0,1,0,0,0,0,0,0,0,0,1,0
0,1,0,0,0,0,0,0,0,0,1,0
0,1,0,0,0,0,0,0,0,0,1,0
0,10,1,1,10,1,1,1,1,1,10,0
0,1,0,0,1,0,0,0,0,0,1,0
0,1,0,0,1,4,0,0,0,5,1,0
0,1,0,0,1,0,0,0,0,0,1,0
0,1,0,0,1,0,0,0,0,5,1,0
0,1,0,0,1,15,0,0,0,0,1,0
0,10,1,1,10,1,1,1,1,1,10,0
0,1,0,0,1,0,0,7,0,0,1,0
0,1,0,0,1,0,0,0,0,0,1,0
0,1,0,0,1,0,0,0,0,0,1,0
0,1,0,0,1,0,0,0,6,0,1,0
0,10,1,1,10,21,21,21,1,1,10,0
0,0,0,0,0,0,0,0,0,0,0,0
0,10,0,0,10,0,0,0,0,0,10,0
0,0,0,0,0,0,0,0,0,0,0,0
0,0,0,0,0,0,0,0,0,0,0,0
:endlayer
layer: 7
0,0,0,0,0,0,0,0,0,0,0,0
0,0,0,0,0,0,1,0,0,0,0,0
0,10,30,30,30,30,30,30,30,30,10,0
0,27,29,29,29,29,29,29,29,29,27,0
0,27,28,28,28,28,28,28,28,28,27,0
0,27,28,28,28,28,28,28,28,28,27,0
0,27,33,33,33,33,33,33,33,33,27,0
0,10,30,30,10,30,30,30,30,30,10,0
0,27,28,28,27,0,0,0,0,0,27,0
0,27,28,28,27,0,0,0,0,0,27,0
0,27,28,28,27,0,0,0,0,0,1,0
0,27,28,28,27,0,0,0,0,0,27,0
0,27,28,28,15,0,0,0,0,0,27,0
0,10,30,30,10,30,30,30,30,30,10,0
0,27,28,28,27,32,28,28,28,31,27,0
0,27,28,28,27,32,28,28,28,31,27,0
0,27,28,28,27,32,28,28,28,31,27,0
0,27,28,28,27,32,28,28,28,31,27,0
0,10,30,30,10,30,30,30,30,30,10,0
0,27,29,29,27,29,29,29,29,29,27,0
0,27,28,28,27,28,28,28,28,28,27,0
0,0,0,0,0,0,0,0,0,0,0,0
0,0,0,0,16,0,0,0,0,0,0,0
:endlayer
layer: 8
0,0,0,0,0,0,0,0,0,0,0,0
0,0,0,0,0,0,1,0,0,0,0,0
0,10,35,35,35,35,37,35,35,35,10,0
0,35,0,0,0,0,0,0,0,0,35,0
0,35,0,0,0,0,0,0,0,0,35,0
0,35,0,0,0,0,0,0,0,0,35,0
0,35,0,0,0,0,0,0,0,0,35,0
0,10,36,12,10,36,36,36,36,36,10,0
0,35,0,0,34,0,0,0,0,0,35,0
0,35,0,0,34,0,0,0,0,0,35,0
0,35,0,0,34,0,0,0,0,0,1,0
0,35,0,0,34,0,0,0,0,0,35,0
0,35,0,0,0,0,0,0,0,0,35,0
0,10,36,12,10,36,36,36,36,36,10,0
0,35,0,0,0,0,0,0,0,0,35,0
0,35,0,0,0,0,0,0,0,0,35,0
0,35,0,0,0,0,0,0,0,0,35,0
0,35,0,0,0,0,0,0,0,0,35,0
0,10,0,0,0,0,0,0,0,0,10,0
0,35,0,0,0,0,0,0,0,0,35,0
0,10,35,35,10,35,35,35,35,35,10,0
0,0,0,0,34,0,0,0,0,0,0,0
0,0,0,0,34,0,0,0,0,0,0,0
:endlayer
layer: 9
0,0,0,0,0,0,0,0,0,0,0,0
0,0,0,0,0,0,38,0,0,0,0,0
0,10,35,21,21,35,1,35,21,35,10,0
0,35,0,0,0,0,0,0,0,0,35,0
0,35,0,0,0,0,0,0,0,0,35,0
0,35,0,0,0,0,0,0,0,0,35,0
0,35,0,0,6,0,0,0,6,0,35,0
0,10,36,22,10,36,36,36,36,36,10,0
0,35,0,0,0,0,0,0,0,0,35,0
0,35,4,0,0,0,0,0,0,0,35,0
0,35,0,0,0,0,0,0,0,0,1,0
0,35,4,0,0,0,0,0,0,0,35,0
0,35,0,0,0,0,0,0,0,0,35,0
0,10,36,23,10,36,36,36,36,36,10,0
0,35,0,0,7,0,0,0,7,0,35,0
0,35,0,0,0,0,0,0,0,0,35,0
0,35,0,0,0,0,0,0,0,0,35,0
0,35,0,0,0,0,0,0,0,0,35,0
0,10,4,0,0,0,0,0,0,5,10,0
0,35,0,0,0,0,0,0,0,0,35,0
0,10,35,35,10,21,21,35,35,35,10,0
0,0,0,0,0,0,0,0,0,0,0,0
0,0,0,0,0,0,0,0,0,0,0,0
:endlayer
layer: 10
0,0,0,0,0,0,0,0,0,0,0,0
0,0,0,0,0,0,0,0,0,0,0,0
0,10,35,35,35,35,1,35,35,35,10,0
0,35,0,0,0,0,0,0,0,0,35,0
0,35,0,0,0,0,0,0,0,0,35,0
0,35,0,0,0,0,0,0,0,0,35,0
0,35,0,0,0,0,0,0,0,0,35,0
0,10,36,36,10,36,36,36,36,36,10,0
0,35,0,0,0,0,0,0,0,0,35,0
0,35,0,0,0,0,0,0,0,0,35,0
0,35,0,0,0,0,0,0,0,0,1,0
0,35,0,0,0,0,0,0,0,0,35,0
0,35,0,0,0,0,0,0,0,0,35,0
0,10,36,36,10,36,36,36,36,36,10,0
0,35,0,0,0,0,0,0,0,0,35,0
0,35,0,0,0,0,0,0,0,0,35,0
0,35,0,0,0,0,0,0,0,0,35,0
0,35,0,0,0,0,0,0,0,0,35,0
0,10,0,0,0,0,0,0,0,0,10,0
0,35,0,0,0,0,0,0,0,0,35,0
0,10,35,35,10,35,35,35,35,35,10,0
0,0,0,0,0,0,0,0,0,0,0,0
0,0,0,0,0,0,0,0,0,0,0,0
:endlayer
layer: 11
0,0,0,0,0,0,0,0,0,0,0,0
42,41,0,0,0,0,0,0,0,0,40,39
42,10,30,30,30,30,1,30,30,30,10,39
42,27,0,0,0,0,0,0,0,0,27,39
42,27,0,0,0,0,0,0,0,0,27,39
42,27,0,0,0,0,0,0,0,0,27,39
42,27,0,0,0,0,0,0,0,0,27,39
42,10,30,30,10,30,30,30,30,30,10,39
42,27,0,0,27,0,0,0,0,0,27,39
42,27,0,0,27,0,0,0,0,0,27,39
42,27,0,0,27,0,0,0,0,0,1,39
42,27,0,0,27,0,0,0,0,0,27,39
42,27,0,0,27,0,0,0,0,0,27,39
42,10,30,30,10,30,30,30,30,30,10,39
42,27,0,0,0,0,0,0,0,0,27,39
42,27,0,0,0,0,0,0,0,0,27,39
42,27,0,0,0,0,0,0,0,0,27,39
42,27,0,0,6,0,0,6,0,0,27,39
42,10,30,30,10,30,30,30,30,30,10,39
42,27,0,0,0,0,0,0,0,0,27,39
42,10,30,30,10,30,30,30,30,30,10,39
42,41,0,0,0,0,0,0,0,0,40,39
0,0,0,0,0,0,0,0,0,0,0,0
:endlayer
layer: 12
0,0,0,0,0,0,0,0,0,0,0,0
0,42,41,0,0,0,0,0,0,40,39,0
0,42,35,35,10,35,1,10,35,35,39,0
0,42,32,0,0,0,0,0,0,31,39,0
0,42,32,0,0,0,0,0,0,31,39,0
0,42,32,0,0,0,0,0,0,31,39,0
0,42,32,0,0,0,0,0,0,31,39,0
0,42,36,36,10,36,36,10,36,36,39,0
0,42,32,0,0,0,0,0,0,31,39,0
0,42,32,0,0,0,0,0,0,31,39,0
0,42,32,0,0,0,0,0,0,31,1,0
0,42,32,0,0,0,0,0,0,31,39,0
0,42,32,0,0,0,0,0,0,31,39,0
0,42,36,36,10,36,36,10,36,36,39,0
0,42,32,0,0,0,0,0,0,31,39,0
0,42,32,0,0,0,0,0,0,31,39,0
0,42,32,0,0,0,0,0,0,31,39,0
0,42,32,0,0,0,0,0,0,31,39,0
0,42,32,0,10,0,0,10,0,31,39,0
0,42,32,0,0,0,0,0,0,31,39,0
0,42,35,35,10,35,35,10,35,35,39,0
0,42,41,0,0,0,0,0,0,40,39,0
0,0,0,0,0,0,0,0,0,0,0,0
:endlayer
layer: 13
0,0,0,0,0,0,0,0,0,0,0,0
0,0,42,41,0,0,0,0,40,39,0,0
0,0,42,35,10,35,1,10,35,39,0,0
0,0,42,32,0,0,0,0,31,39,0,0
0,0,42,32,0,0,0,0,31,39,0,0
0,0,42,32,0,0,0,0,31,39,0,0
0,0,42,32,0,0,0,0,31,39,0,0
0,0,42,36,10,36,36,10,36,39,0,0
0,0,42,32,0,0,0,0,31,39,0,0
0,0,42,32,0,0,0,0,31,39,0,0
0,0,42,32,0,0,0,0,31,39,1,0
0,0,42,32,0,0,0,0,31,39,0,0
0,0,42,32,0,0,0,0,31,39,0,0
0,0,42,36,10,36,36,10,36,39,0,0
0,0,42,32,0,0,0,0,31,39,0,0
0,0,42,32,0,0,0,0,31,39,0,0
0,0,42,32,0,0,0,0,31,39,0,0
0,0,42,32,0,0,0,0,31,39,0,0
0,0,42,32,10,0,0,10,31,39,0,0
0,0,42,32,0,0,0,0,31,39,0,0
0,0,42,35,10,35,35,10,35,39,0,0
0,0,42,41,0,0,0,0,40,39,0,0
0,0,0,0,0,0,0,0,0,0,0,0
:endlayer
layer: 14
0,0,0,0,0,0,0,0,0,0,0,0
0,0,0,42,41,0,0,40,39,0,0,0
0,0,0,42,10,30,1,10,39,0,0,0
0,0,0,42,27,0,0,27,39,0,0,0
0,0,0,42,27,0,0,27,39,0,0,0
0,0,0,42,27,0,0,27,39,0,0,0
0,0,0,42,27,0,0,27,39,0,0,0
0,0,0,42,10,36,36,10,39,0,0,0
0,0,0,42,27,0,0,27,39,0,0,0
0,0,0,42,27,0,0,27,39,0,0,0
0,0,0,42,27,0,0,27,39,0,1,0
0,0,0,42,27,0,0,27,39,0,0,0
0,0,0,42,27,0,0,27,39,0,0,0
0,0,0,42,10,36,36,10,39,0,0,0
0,0,0,42,27,0,0,27,39,0,0,0
0,0,0,42,27,0,0,27,39,0,0,0
0,0,0,42,27,0,0,27,39,0,0,0
0,0,0,42,27,0,0,27,39,0,0,0
0,0,0,42,30,30,30,30,39,0,0,0
0,0,0,42,27,0,0,27,39,0,0,0
0,0,0,42,30,30,30,30,39,0,0,0
0,0,0,42,41,0,0,40,39,0,0,0
0,0,0,0,0,0,0,0,0,0,0,0
:endlayer
layer: 15
0,0,0,0,0,0,0,0,0,0,0,0
0,0,0,0,42,41,40,39,0,0,0,0
0,0,0,0,42,35,1,39,0,0,0,0
0,0,0,0,42,32,31,39,0,0,0,0
0,0,0,0,42,32,31,39,0,0,0,0
0,0,0,0,42,32,31,39,0,0,0,0
0,0,0,0,42,32,31,39,0,0,0,0
0,0,0,0,42,36,36,39,0,0,0,0
0,0,0,0,42,32,31,39,0,0,0,0
0,0,0,0,42,32,31,39,0,0,0,0
0,0,0,0,42,32,31,39,0,0,43,0
0,0,0,0,42,32,31,39,0,0,0,0
0,0,0,0,42,32,31,39,0,0,0,0
0,0,0,0,42,36,36,39,0,0,0,0
0,0,0,0,42,32,31,39,0,0,0,0
0,0,0,0,42,32,31,39,0,0,0,0
0,0,0,0,42,32,31,39,0,0,0,0
0,0,0,0,42,32,31,39,0,0,0,0
0,0,0,0,42,36,36,39,0,0,0,0
0,0,0,0,42,32,31,39,0,0,0,0
0,0,0,0,42,35,35,39,0,0,0,0
0,0,0,0,42,41,40,39,0,0,0,0
0,0,0,0,0,0,0,0,0,0,0,0
:endlayer
layer: 16
0,0,0,0,0,0,0,0,0,0,0,0
0,0,0,0,0,42,39,0,0,0,0,0
0,0,0,0,0,42,1,0,0,0,0,0
0,0,0,0,0,42,39,0,0,0,0,0
0,0,0,0,0,42,39,0,0,0,0,0
0,0,0,0,0,42,39,0,0,0,0,0
0,0,0,0,0,42,39,0,0,0,0,0
0,0,0,0,0,42,39,0,0,0,0,0
0,0,0,0,0,42,39,0,0,0,0,0
0,0,0,0,0,42,39,0,0,0,0,0
0,0,0,0,0,42,39,0,0,0,0,0
0,0,0,0,0,42,39,0,0,0,0,0
0,0,0,0,0,42,39,0,0,0,0,0
0,0,0,0,0,42,39,0,0,0,0,0
0,0,0,0,0,42,39,0,0,0,0,0
0,0,0,0,0,42,39,0,0,0,0,0
0,0,0,0,0,42,39,0,0,0,0,0
0,0,0,0,0,42,39,0,0,0,0,0
0,0,0,0,0,42,39,0,0,0,0,0
0,0,0,0,0,42,39,0,0,0,0,0
0,0,0,0,0,42,39,0,0,0,0,0
0,0,0,0,0,42,39,0,0,0,0,0
0,0,0,0,0,0,0,0,0,0,0,0
:endlayer
layer: 17
0,0,0,0,0,0,0,0,0,0,0,0
0,0,0,0,0,0,0,0,0,0,0,0
0,0,0,0,0,0,1,0,0,0,0,0
0,0,0,0,0,0,0,0,0,0,0,0
0,0,0,0,0,0,0,0,0,0,0,0
0,0,0,0,0,0,0,0,0,0,0,0
0,0,0,0,0,0,0,0,0,0,0,0
0,0,0,0,0,0,0,0,0,0,0,0
0,0,0,0,0,0,0,0,0,0,0,0
0,0,0,0,0,0,0,0,0,0,0,0
0,0,0,0,0,0,0,0,0,0,0,0
0,0,0,0,0,0,0,0,0,0,0,0
0,0,0,0,0,0,0,0,0,0,0,0
0,0,0,0,0,0,0,0,0,0,0,0
0,0,0,0,0,0,0,0,0,0,0,0
0,0,0,0,0,0,0,0,0,0,0,0
0,0,0,0,0,0,0,0,0,0,0,0
0,0,0,0,0,0,0,0,0,0,0,0
0,0,0,0,0,0,0,0,0,0,0,0
0,0,0,0,0,0,0,0,0,0,0,0
0,0,0,0,0,0,0,0,0,0,0,0
0,0,0,0,0,0,0,0,0,0,0,0
0,0,0,0,0,0,0,0,0,0,0,0
:endlayer
layer: 18
0,0,0,0,0,0,0,0,0,0,0,0
0,0,0,0,0,0,0,0,0,0,0,0
0,0,0,0,0,0,1,0,0,0,0,0
0,0,0,0,0,0,0,0,0,0,0,0
0,0,0,0,0,0,0,0,0,0,0,0
0,0,0,0,0,0,0,0,0,0,0,0
0,0,0,0,0,0,0,0,0,0,0,0
0,0,0,0,0,0,0,0,0,0,0,0
0,0,0,0,0,0,0,0,0,0,0,0
0,0,0,0,0,0,0,0,0,0,0,0
0,0,0,0,0,0,0,0,0,0,0,0
0,0,0,0,0,0,0,0,0,0,0,0
0,0,0,0,0,0,0,0,0,0,0,0
0,0,0,0,0,0,0,0,0,0,0,0
0,0,0,0,0,0,0,0,0,0,0,0
0,0,0,0,0,0,0,0,0,0,0,0
0,0,0,0,0,0,0,0,0,0,0,0
0,0,0,0,0,0,0,0,0,0,0,0
0,0,0,0,0,0,0,0,0,0,0,0
0,0,0,0,0,0,0,0,0,0,0,0
0,0,0,0,0,0,0,0,0,0,0,0
0,0,0,0,0,0,0,0,0,0,0,0
0,0,0,0,0,0,0,0,0,0,0,0
:endlayer
layer: 19
0,0,0,0,0,0,0,0,0,0,0,0
0,0,0,0,0,0,0,0,0,0,0,0
0,0,0,0,0,0,43,0,0,0,0,0
0,0,0,0,0,0,0,0,0,0,0,0
0,0,0,0,0,0,0,0,0,0,0,0
0,0,0,0,0,0,0,0,0,0,0,0
0,0,0,0,0,0,0,0,0,0,0,0
0,0,0,0,0,0,0,0,0,0,0,0
0,0,0,0,0,0,0,0,0,0,0,0
0,0,0,0,0,0,0,0,0,0,0,0
0,0,0,0,0,0,0,0,0,0,0,0
0,0,0,0,0,0,0,0,0,0,0,0
0,0,0,0,0,0,0,0,0,0,0,0
0,0,0,0,0,0,0,0,0,0,0,0
0,0,0,0,0,0,0,0,0,0,0,0
0,0,0,0,0,0,0,0,0,0,0,0
0,0,0,0,0,0,0,0,0,0,0,0
0,0,0,0,0,0,0,0,0,0,0,0
0,0,0,0,0,0,0,0,0,0,0,0
0,0,0,0,0,0,0,0,0,0,0,0
0,0,0,0,0,0,0,0,0,0,0,0
0,0,0,0,0,0,0,0,0,0,0,0
0,0,0,0,0,0,0,0,0,0,0,0
:endlayer

#### RULES ####
rule:
plugin=vanillaBlocks
number=1
data:
JSON:{blockState:{blockName:"minecraft:cobblestone"}}
:enddata
:endrule

rule:
plugin=vanillaBlocks
number=2
data:
JSON:{blockState:{blockName:"minecraft:stone_brick_stairs",properties:{half:"bottom",shape:"straight",facing:"south"}}}
:enddata
:endrule

rule:
plugin=vanillaBlocks
number=3
data:
JSON:{blockState:{blockName:"minecraft:stone_brick_stairs",properties:{half:"bottom",shape:"straight",facing:"north"}}}
:enddata
:endrule

rule:
plugin=vanillaBlocks
number=4
data:
JSON:{blockState:{blockName:"minecraft:torch",properties:{facing:"east"}}}
:enddata
:endrule

rule:
plugin=vanillaBlocks
number=5
data:
JSON:{blockState:{blockName:"minecraft:torch",properties:{facing:"west"}}}
:enddata
:endrule

rule:
plugin=vanillaBlocks
number=6
data:
JSON:{blockState:{blockName:"minecraft:torch",properties:{facing:"north"}}}
:enddata
:endrule

rule:
plugin=vanillaBlocks
number=7
data:
JSON:{blockState:{blockName:"minecraft:torch",properties:{facing:"south"}}}
:enddata
:endrule

rule:
plugin=vanillaBlocks
number=8
data:
JSON:{blockState:{blockName:"minecraft:stone_stairs",properties:{half:"top",shape:"straight",facing:"north"}}}
:enddata
:endrule

rule:
plugin=vanillaBlocks
number=9
data:
JSON:{blockState:{blockName:"minecraft:stone_stairs",properties:{half:"top",shape:"straight",facing:"south"}}}
:enddata
:endrule

rule:
plugin=vanillaBlocks
number=10
data:
JSON:{blockState:{blockName:"minecraft:log",properties:{variant:"oak",axis:"y"}}}
:enddata
:endrule

rule:
plugin=vanillaBlocks
number=11
data:
JSON:{blockState:{blockName:"minecraft:stonebrick",properties:{variant:"stonebrick"}}}
:enddata
:endrule

rule:
plugin=doors
number=12
data:
JSON:{blockState:{blockName:"minecraft:wooden_door",properties:{hinge:"left",half:"lower",powered:"false",facing:"west",open:"false"}}}
:enddata
:endrule

rule:
plugin=vanillaBlocks
number=13
data:
JSON:{blockState:{blockName:"minecraft:trapdoor",properties:{half:"bottom",facing:"west",open:"false"}}}
:enddata
:endrule

rule:
plugin=vanillaBlocks
number=14
data:
JSON:{blockState:{blockName:"minecraft:stone_brick_stairs",properties:{half:"top",shape:"straight",facing:"north"}}}
:enddata
:endrule

rule:
plugin=vanillaBlocks
number=15
data:
JSON:{blockState:{blockName:"minecraft:birch_stairs",properties:{half:"bottom",shape:"straight",facing:"west"}}}
:enddata
:endrule

rule:
plugin=vanillaBlocks
number=16
data:
JSON:{blockState:{blockName:"minecraft:planks",properties:{variant:"birch"}}}
:enddata
:endrule

rule:
plugin=inventory
number=17
data:
JSON:{blockState:{blockName:"minecraft:furnace",properties:{facing:"west"}},lootLevel:0,teData:{CookTime:0,ForgeData:{generatedInventory:1b},BurnTime:0,Items:[],id:"minecraft:furnace",CookTimeTotal:0,Lock:""},inventoryData:{length:0,inventoryContents:[]},legacyFeatures:0b}
:enddata
:endrule

rule:
plugin=vanillaBlocks
number=18
data:
JSON:{blockState:{blockName:"minecraft:stone_brick_stairs",properties:{half:"top",shape:"straight",facing:"south"}}}
:enddata
:endrule

rule:
plugin=inventory
number=19
data:
JSON:{blockState:{blockName:"minecraft:furnace",properties:{facing:"south"}},lootLevel:0,teData:{CookTime:0,ForgeData:{generatedInventory:1b},BurnTime:0,Items:[],id:"minecraft:furnace",CookTimeTotal:0,Lock:""},inventoryData:{length:0,inventoryContents:[]},legacyFeatures:0b}
:enddata
:endrule

rule:
plugin=vanillaSign
number=20
data:
JSON:{signContents0:"",blockState:{blockName:"minecraft:wall_sign",properties:{facing:"south"}},signContents2:"",signContents1:"",signContents3:"",rotation:0}
:enddata
:endrule

rule:
plugin=vanillaBlocks
number=21
data:
JSON:{blockState:{blockName:"minecraft:stained_glass_pane",properties:{east:"false",color:"white",south:"false",north:"false",west:"false"}}}
:enddata
:endrule

rule:
plugin=doors
number=22
data:
JSON:{blockState:{blockName:"minecraft:wooden_door",properties:{hinge:"left",half:"upper",powered:"false",facing:"south",open:"false"}}}
:enddata
:endrule

rule:
plugin=doors
number=23
data:
JSON:{blockState:{blockName:"minecraft:wooden_door",properties:{hinge:"right",half:"upper",powered:"false",facing:"south",open:"false"}}}
:enddata
:endrule

rule:
plugin=vanillaBlocks
number=24
data:
JSON:{blockState:{blockName:"minecraft:trapdoor",properties:{half:"bottom",facing:"north",open:"false"}}}
:enddata
:endrule

rule:
plugin=vanillaBlocks
number=25
data:
JSON:{blockState:{blockName:"minecraft:stone_stairs",properties:{half:"bottom",shape:"straight",facing:"west"}}}
:enddata
:endrule

rule:
plugin=vanillaBlocks
number=26
data:
JSON:{blockState:{blockName:"minecraft:stone_stairs",properties:{half:"bottom",shape:"straight",facing:"east"}}}
:enddata
:endrule

rule:
plugin=vanillaBlocks
number=27
data:
JSON:{blockState:{blockName:"minecraft:log",properties:{variant:"oak",axis:"z"}}}
:enddata
:endrule

rule:
plugin=vanillaBlocks
number=28
data:
JSON:{blockState:{blockName:"minecraft:wooden_slab",properties:{half:"top",variant:"oak"}}}
:enddata
:endrule

rule:
plugin=vanillaBlocks
number=29
data:
JSON:{blockState:{blockName:"minecraft:oak_stairs",properties:{half:"top",shape:"straight",facing:"north"}}}
:enddata
:endrule

rule:
plugin=vanillaBlocks
number=30
data:
JSON:{blockState:{blockName:"minecraft:log",properties:{variant:"oak",axis:"x"}}}
:enddata
:endrule

rule:
plugin=vanillaBlocks
number=31
data:
JSON:{blockState:{blockName:"minecraft:oak_stairs",properties:{half:"top",shape:"straight",facing:"east"}}}
:enddata
:endrule

rule:
plugin=vanillaBlocks
number=32
data:
JSON:{blockState:{blockName:"minecraft:oak_stairs",properties:{half:"top",shape:"straight",facing:"west"}}}
:enddata
:endrule

rule:
plugin=vanillaBlocks
number=33
data:
JSON:{blockState:{blockName:"minecraft:oak_stairs",properties:{half:"top",shape:"straight",facing:"south"}}}
:enddata
:endrule

rule:
plugin=vanillaBlocks
number=34
data:
JSON:{blockState:{blockName:"minecraft:birch_fence",properties:{east:"false",south:"false",north:"false",west:"false"}}}
:enddata
:endrule

rule:
plugin=vanillaBlocks
number=35
data:
JSON:{blockState:{blockName:"minecraft:stained_hardened_clay",properties:{color:"white"}}}
:enddata
:endrule

rule:
plugin=vanillaBlocks
number=36
data:
JSON:{blockState:{blockName:"minecraft:planks",properties:{variant:"oak"}}}
:enddata
:endrule

rule:
plugin=inventory
number=37
data:
JSON:{blockState:{blockName:"minecraft:furnace",properties:{facing:"south"}},lootLevel:0,teData:{CookTime:0,ForgeData:{generatedInventory:1b},BurnTime:0,Items:[],id:"minecraft:furnace",CookTimeTotal:0,Lock:""},inventoryData:{length:0,inventoryContents:[]},legacyFeatures:0b}
:enddata
:endrule

rule:
plugin=vanillaBlocks
number=38
data:
JSON:{blockState:{blockName:"minecraft:stone_stairs",properties:{half:"bottom",shape:"straight",facing:"south"}}}
:enddata
:endrule

rule:
plugin=vanillaBlocks
number=39
data:
JSON:{blockState:{blockName:"minecraft:stone_brick_stairs",properties:{half:"bottom",shape:"straight",facing:"west"}}}
:enddata
:endrule

rule:
plugin=vanillaBlocks
number=40
data:
JSON:{blockState:{blockName:"minecraft:stone_brick_stairs",properties:{half:"top",shape:"straight",facing:"east"}}}
:enddata
:endrule

rule:
plugin=vanillaBlocks
number=41
data:
JSON:{blockState:{blockName:"minecraft:stone_brick_stairs",properties:{half:"top",shape:"straight",facing:"west"}}}
:enddata
:endrule

rule:
plugin=vanillaBlocks
number=42
data:
JSON:{blockState:{blockName:"minecraft:stone_brick_stairs",properties:{half:"bottom",shape:"straight",facing:"east"}}}
:enddata
:endrule

rule:
plugin=vanillaBlocks
number=43
data:
JSON:{blockState:{blockName:"minecraft:cobblestone_wall",properties:{east:"false",south:"false",north:"false",variant:"cobblestone",west:"false",up:"false"}}}
:enddata
:endrule

#### ENTITIES ####
