# Ancient Warfare Structure Template File
# Auto-generated structure template file. created on: 5/12/2021 at: 11:52:42
# Lines beginning with # denote comments

header:
version=2.11
name=SurvivalBuildShopStripAEmpty
mods=
size=31,18,22
offset=30,4,21
:endheader

#### VALIDATION ####
validation:
type=ground
structureAuthor=Loki61089
survival=true
worldGenEnabled=false
unique=false
preserveBlocks=false
preventNaturalHostileSpawns=false
selectionWeight=1
clusterValue=1
minDuplicateDistance=1
dimensionWhiteList=true
dimensionList=
biomeGroupList=
biomeWhiteList=true
biomeList=
leveling=0
fill=0
border=0
blockSwap=false
territoryName=
biomeReplacement=minecraft:
minGenerationHeight=0
maxGenerationHeight=255
:endvalidation

#### LAYERS ####
layer: 0
1,1,1,1,1,1,1,1,1,1,1,1,1,1,1,1,1,1,1,1,1,1,1,1,1,1,1,1,1,1,1
1,1,1,1,1,1,1,1,1,1,1,1,1,1,1,1,1,1,1,1,1,1,1,1,1,1,1,1,1,1,1
1,1,1,1,1,1,1,1,1,1,1,1,1,1,1,1,1,1,1,1,1,1,1,1,1,1,1,1,1,1,1
1,1,1,1,1,1,1,1,1,1,1,1,1,1,1,1,1,1,1,1,1,1,1,1,1,1,1,1,1,1,1
1,1,1,1,1,1,1,1,1,1,1,1,1,1,1,1,1,1,1,1,1,1,1,1,1,1,1,1,1,1,1
1,1,1,1,1,1,1,1,1,1,1,1,1,1,1,1,1,1,1,1,1,1,1,1,1,1,1,1,1,1,1
1,1,1,1,1,1,1,1,1,1,1,1,1,1,1,1,1,1,1,1,1,1,1,1,1,1,1,1,1,1,1
1,1,1,1,1,1,1,1,1,1,1,1,1,1,1,1,1,1,1,1,1,1,1,1,1,1,1,1,1,1,1
1,1,1,1,1,1,1,1,1,1,1,1,1,1,1,1,1,1,1,1,1,1,1,1,1,1,1,1,1,1,1
1,1,1,1,1,1,1,1,1,1,1,1,1,1,1,1,1,1,1,1,1,1,1,1,1,1,1,1,1,1,1
1,1,1,1,1,1,1,1,1,1,1,1,1,1,1,1,1,1,1,1,1,1,1,1,1,1,1,1,1,1,1
1,1,1,1,1,1,1,1,1,1,1,1,1,1,1,1,1,1,1,1,1,1,1,1,1,1,1,1,1,1,1
1,1,1,1,1,1,1,1,1,1,1,1,1,1,1,1,1,1,1,1,1,1,1,1,1,1,1,1,1,1,1
1,1,1,1,1,1,1,1,1,1,1,1,1,1,1,1,1,1,1,1,1,1,1,1,1,1,1,1,1,1,1
1,1,1,1,1,1,1,1,1,1,1,1,1,1,1,1,1,1,1,1,1,1,1,1,1,1,1,1,1,1,1
1,1,1,1,1,1,1,1,1,1,1,1,1,1,1,1,1,1,1,1,1,1,1,1,1,1,1,1,1,1,1
1,1,1,1,1,1,1,1,1,1,1,1,1,1,1,1,1,1,1,1,1,1,1,1,1,1,1,1,1,1,1
1,1,1,1,1,1,1,1,1,1,1,1,1,1,1,1,1,1,1,1,1,1,1,1,1,1,1,1,1,1,1
1,1,1,1,1,1,1,1,1,1,1,1,1,1,1,1,1,1,1,1,1,1,1,1,1,1,1,1,1,1,1
1,1,1,1,1,1,1,1,1,1,1,1,1,1,1,1,1,1,1,1,1,1,1,1,1,1,1,1,1,1,1
1,1,1,1,1,1,1,1,1,1,1,1,1,1,1,1,1,1,1,1,1,1,1,1,1,1,1,1,1,1,1
1,1,1,1,1,1,1,1,1,1,1,1,1,1,1,1,1,1,1,1,1,1,1,1,1,1,1,1,1,1,1
:endlayer
layer: 1
1,1,1,1,1,1,1,1,1,1,1,1,1,1,1,1,1,1,1,1,1,1,1,1,1,1,1,1,1,1,1
1,2,2,2,2,2,2,2,2,2,2,2,2,2,2,2,2,2,2,2,2,2,2,2,2,2,2,2,2,2,1
1,2,0,6,2,2,2,2,2,2,2,2,2,2,2,2,2,2,2,2,2,2,2,2,2,2,2,2,2,2,1
1,2,5,2,2,2,2,2,2,2,2,2,2,2,2,2,2,2,2,2,2,2,2,2,2,2,2,2,2,2,1
1,2,0,0,0,0,0,0,0,0,0,2,2,2,2,2,2,2,2,2,2,2,2,2,2,2,2,2,2,2,1
1,2,0,0,0,0,0,0,0,0,0,2,2,2,2,2,2,2,2,2,2,2,2,2,2,2,2,2,2,2,1
1,2,0,0,0,0,0,0,0,0,0,2,2,2,2,2,2,2,2,2,2,2,2,2,2,2,2,2,2,2,1
1,2,0,0,0,0,0,0,0,0,0,2,2,2,2,2,2,2,2,2,2,2,2,2,2,2,2,2,2,2,1
1,2,0,0,0,0,0,0,0,0,0,2,2,2,2,2,2,2,2,2,2,2,2,2,2,2,2,2,2,2,1
1,2,0,0,0,0,0,0,0,0,0,2,2,2,2,2,2,2,2,2,2,2,2,2,2,2,2,2,2,2,1
1,2,2,2,2,2,2,2,2,2,2,2,2,0,0,0,0,0,0,2,2,2,2,2,2,2,2,2,2,2,1
1,2,0,0,0,0,2,0,0,0,0,2,2,0,0,0,0,0,0,2,0,0,0,0,2,0,0,0,0,2,1
1,2,0,0,0,0,2,0,0,0,0,2,2,0,0,0,0,0,0,2,0,0,0,0,2,0,0,0,0,2,1
1,2,0,0,0,0,2,0,0,0,0,2,2,0,0,0,0,0,0,2,0,0,0,0,2,0,0,0,0,2,1
1,2,0,0,0,0,2,0,0,0,0,4,2,2,2,0,2,2,2,4,0,0,0,0,2,0,0,0,0,2,1
1,2,0,0,0,0,2,0,0,0,0,0,0,0,0,0,0,0,0,0,0,0,0,0,2,0,0,0,0,2,1
1,2,0,0,0,5,2,0,0,0,0,0,0,0,0,5,0,0,0,0,0,0,0,0,2,0,0,0,0,2,1
1,2,2,2,4,0,4,2,2,2,2,4,2,2,4,0,4,2,2,4,2,2,2,2,2,2,2,4,5,4,1
1,2,2,2,2,3,2,2,2,2,2,2,2,2,2,3,2,2,2,2,2,2,2,2,2,2,2,2,3,2,1
1,2,2,2,2,2,2,2,2,2,2,2,2,2,2,2,2,2,2,2,2,2,2,2,2,2,2,2,2,2,1
1,2,2,2,2,2,2,2,2,2,2,2,2,2,2,2,2,2,2,2,2,2,2,2,2,2,2,2,2,2,1
1,1,1,1,1,1,1,1,1,1,1,1,1,1,1,1,1,1,1,1,1,1,1,1,1,1,1,1,1,1,1
:endlayer
layer: 2
1,1,1,1,1,1,1,1,1,1,1,1,1,1,1,1,1,1,1,1,1,1,1,1,1,1,1,1,1,1,1
1,2,2,2,2,2,2,2,2,2,2,2,2,2,2,2,2,2,2,2,2,2,2,2,2,2,2,2,2,2,1
1,2,0,0,6,2,2,2,2,2,2,2,2,2,2,2,2,2,2,2,2,2,2,2,2,2,2,2,2,2,1
1,2,8,2,2,2,2,2,2,2,2,2,2,2,2,2,2,2,2,2,2,2,2,2,2,2,2,2,2,2,1
1,2,0,0,10,0,0,0,10,0,0,2,2,2,2,2,2,2,2,2,2,2,2,2,2,2,2,2,2,2,1
1,2,11,0,0,0,0,0,0,0,12,2,2,2,2,2,2,2,2,2,2,2,2,2,2,2,2,2,2,2,1
1,2,0,0,0,0,0,0,0,0,0,2,2,2,2,2,2,2,2,2,2,1,1,2,2,2,2,2,2,2,1
1,2,0,0,0,0,0,0,0,0,0,2,2,2,2,2,2,2,2,2,2,1,1,2,2,2,2,2,2,2,1
1,2,11,0,0,0,0,0,0,0,12,2,2,2,2,2,2,2,2,2,2,2,2,2,2,2,2,2,2,2,1
1,2,0,0,9,0,0,0,9,0,0,2,2,2,2,2,2,2,2,2,2,2,2,2,2,2,2,2,2,2,1
1,2,2,2,2,2,2,2,2,2,2,2,2,0,0,0,0,0,0,2,2,2,2,2,2,2,2,2,2,2,1
1,2,0,0,0,0,2,0,0,0,0,2,2,0,0,0,0,0,0,2,0,0,0,0,2,0,0,0,0,2,1
1,2,0,0,0,12,2,0,0,0,0,2,2,0,0,0,0,0,0,2,0,0,0,0,2,0,0,0,0,2,1
1,2,0,0,0,0,2,0,0,0,12,2,2,0,9,0,0,9,0,2,11,0,0,0,2,0,0,0,0,2,1
1,2,0,0,0,0,2,0,0,0,0,4,2,2,2,0,2,2,2,4,0,0,0,0,2,0,0,0,0,2,1
1,2,0,0,0,0,2,0,0,0,0,10,0,0,0,0,0,0,0,10,0,0,0,0,2,0,0,0,0,2,1
1,2,0,0,9,8,2,0,0,0,0,0,0,0,0,8,0,0,0,0,0,0,0,0,2,0,0,0,0,2,1
1,2,2,2,4,0,4,2,2,2,2,4,2,2,4,0,4,2,2,4,2,2,2,2,2,2,2,4,7,4,1
1,2,2,2,2,0,2,2,2,2,2,2,2,2,2,0,2,2,2,2,2,2,2,2,2,2,2,2,0,2,1
1,2,2,2,2,3,2,2,2,2,2,2,2,2,2,3,2,2,2,2,2,2,2,2,2,2,2,2,3,2,1
1,2,2,2,2,2,2,2,2,2,2,2,2,2,2,2,2,2,2,2,2,2,2,2,2,2,2,2,2,2,1
1,1,1,1,1,1,1,1,1,1,1,1,1,1,1,1,1,1,1,1,1,1,1,1,1,1,1,1,1,1,1
:endlayer
layer: 3
1,1,1,1,1,1,1,1,1,1,1,1,1,1,1,1,1,1,1,1,1,1,1,1,1,1,1,1,1,1,1
1,4,13,13,4,13,13,13,13,13,13,4,1,1,1,1,1,1,1,1,1,1,1,1,1,1,1,1,1,1,1
1,14,0,0,0,6,20,20,20,20,20,14,1,1,1,1,1,1,1,1,1,1,1,1,1,1,1,1,1,1,1
1,14,20,20,20,20,20,20,20,20,20,4,1,1,4,13,13,13,13,13,13,13,13,13,13,13,13,13,13,4,1
1,14,16,19,19,19,19,19,19,19,19,14,20,20,14,1,1,1,1,1,1,1,1,1,1,1,1,1,1,14,1
1,14,16,18,18,18,18,18,18,18,17,14,20,20,14,1,1,1,1,1,23,25,25,21,1,1,1,1,1,14,1
1,14,16,18,18,18,18,18,18,18,17,20,20,20,1,1,1,1,1,1,23,24,24,21,1,1,1,1,1,14,1
1,14,16,18,18,18,18,18,18,18,17,14,20,20,1,1,1,1,1,1,23,24,24,21,1,1,1,1,1,14,1
1,14,16,18,18,18,18,18,18,18,17,14,20,20,14,1,1,1,1,1,23,22,22,21,1,1,1,1,1,14,1
1,14,15,15,15,15,15,15,15,15,15,14,20,20,14,1,1,1,1,1,1,1,1,1,1,1,1,1,1,14,1
1,4,13,13,13,13,4,13,13,13,13,4,20,19,4,13,13,13,13,4,13,13,13,13,4,13,13,13,13,4,1
1,14,16,19,19,17,14,16,19,19,17,14,20,16,14,19,19,19,17,14,16,19,19,19,14,16,19,19,17,14,1
1,14,16,18,18,17,14,16,18,18,17,14,20,16,14,16,18,18,17,14,16,18,18,17,14,16,18,18,17,14,1
1,14,16,18,18,17,14,16,18,18,17,14,20,15,14,15,15,15,17,14,16,18,18,17,14,16,18,18,17,14,1
1,14,16,18,18,17,14,16,18,18,17,14,20,20,14,20,20,20,20,14,16,18,18,17,14,16,18,18,17,14,1
1,14,16,18,18,17,14,16,18,18,17,14,19,19,14,19,19,19,19,14,16,18,18,17,14,16,18,18,17,14,1
1,14,15,15,15,17,14,15,15,15,15,14,15,15,14,15,15,15,15,14,16,15,15,17,14,16,15,15,15,14,1
1,4,1,13,13,0,4,13,13,13,1,4,1,1,4,0,13,13,1,4,13,13,13,1,4,1,13,13,0,4,1
1,1,1,1,1,0,1,1,1,1,1,1,1,1,1,0,1,1,1,1,1,1,1,1,1,1,1,1,0,1,1
1,1,1,1,1,0,1,1,1,1,1,1,1,1,1,0,1,1,1,1,1,1,1,1,1,1,1,1,0,1,1
1,1,1,1,1,3,1,1,1,1,1,1,1,1,1,3,1,1,1,1,1,1,1,1,1,1,1,1,3,1,1
1,1,1,1,1,1,1,1,1,1,1,1,1,1,1,1,1,1,1,1,1,1,1,1,1,1,1,1,1,1,1
:endlayer
layer: 4
0,0,0,0,0,0,0,0,0,0,0,0,0,0,0,0,0,0,0,0,0,0,0,0,0,0,0,0,0,0,0
0,4,2,2,4,2,2,2,2,2,2,4,0,0,0,0,0,0,0,0,0,0,0,0,0,0,0,0,0,0,0
0,2,34,34,34,34,0,0,0,0,0,2,0,0,0,0,0,0,0,0,0,0,0,0,0,0,0,0,0,0,0
0,2,0,0,0,0,0,0,0,0,0,4,5,5,4,2,2,2,2,4,2,2,2,2,4,2,2,2,2,4,0
0,2,0,0,0,0,0,0,0,0,0,2,0,0,2,0,0,0,0,0,0,0,0,0,0,0,0,0,0,2,0
0,4,5,5,4,2,4,0,0,0,0,2,0,0,2,0,0,0,0,0,0,0,0,0,0,0,0,0,0,2,0
0,2,0,0,2,20,2,0,0,0,0,5,0,0,0,0,0,0,0,0,0,0,0,0,0,0,0,0,0,2,0
0,2,0,0,2,20,2,0,0,0,0,2,0,0,0,0,0,0,0,0,0,0,0,0,0,0,0,0,0,2,0
0,2,0,0,2,20,2,0,0,0,0,2,0,0,2,0,0,0,0,0,0,0,0,0,0,0,0,0,0,2,0
0,2,0,0,6,31,2,2,33,32,2,2,0,0,2,0,0,0,0,0,0,0,0,0,0,0,0,0,0,2,0
0,4,2,2,2,2,4,2,2,2,2,4,0,0,4,2,2,2,2,4,2,2,2,2,4,2,2,2,2,4,0
0,2,0,0,0,0,2,0,0,0,0,2,0,0,2,31,31,0,0,2,0,0,29,30,2,0,29,28,0,2,0
0,2,0,0,0,0,2,0,0,0,0,2,0,0,2,27,0,0,0,2,0,0,0,27,2,0,0,0,0,2,0
0,2,0,0,0,0,2,0,0,0,0,2,0,0,2,0,0,0,0,2,0,0,0,0,2,0,0,0,0,2,0
0,2,0,0,0,0,2,0,0,0,0,2,0,0,2,0,0,0,0,2,0,0,0,0,2,0,0,0,0,2,0
0,2,0,0,0,0,2,0,0,0,0,2,0,0,2,0,0,0,0,2,0,0,0,0,2,0,0,0,0,2,0
0,2,0,0,0,0,2,0,0,0,0,2,0,0,2,0,0,0,0,2,0,0,0,0,2,0,0,0,0,2,0
0,4,5,2,2,2,4,2,2,2,5,4,5,5,4,2,2,2,5,4,2,2,2,5,4,5,2,2,2,4,0
0,0,0,0,0,26,0,0,0,0,0,0,0,0,0,26,0,0,0,0,0,0,0,0,0,0,0,0,26,0,0
0,0,0,0,0,26,0,0,0,0,0,0,0,0,0,26,0,0,0,0,0,0,0,0,0,0,0,0,26,0,0
0,0,0,0,0,26,0,0,0,0,0,0,0,0,0,26,0,0,0,0,0,0,0,0,0,0,0,0,26,0,0
0,0,0,0,0,0,0,0,0,0,0,0,0,0,0,0,0,0,0,0,0,0,0,0,0,0,0,0,0,0,0
:endlayer
layer: 5
0,9,0,0,9,0,0,0,0,0,0,9,0,0,0,0,0,0,0,0,0,0,0,0,0,0,0,0,0,0,0
0,4,1,1,4,1,1,1,1,1,1,4,0,0,0,0,0,0,0,0,0,0,0,0,0,0,0,0,0,0,0
0,1,0,0,10,0,0,0,0,0,0,1,0,0,9,0,0,0,0,9,0,0,0,0,9,0,0,0,0,9,0
0,1,0,0,0,0,0,0,0,0,0,4,7,8,4,1,40,40,1,4,1,1,1,1,4,1,40,40,1,4,0
0,1,0,0,9,0,0,0,0,0,0,1,0,0,1,0,0,0,0,10,0,0,0,0,10,0,0,0,0,1,0
0,4,8,7,4,1,4,11,0,0,12,1,0,12,1,11,0,0,0,0,0,0,0,0,0,0,0,0,12,1,0
0,1,0,0,1,20,1,0,0,0,0,7,0,0,0,0,0,0,0,0,0,0,0,0,0,0,0,0,0,1,0
0,1,0,12,1,30,1,0,0,0,0,1,0,0,0,0,0,0,0,0,0,0,0,0,0,0,0,0,0,1,0
0,1,0,0,1,27,1,0,0,0,0,1,11,12,1,11,0,0,0,0,0,0,0,0,0,0,0,0,12,1,0
0,1,0,0,0,0,1,21,1,1,23,1,0,0,1,0,0,0,0,9,0,0,0,0,9,0,0,0,0,1,0
0,4,1,1,1,1,4,1,1,1,1,4,0,0,4,1,1,1,1,4,1,1,1,1,4,1,1,1,1,4,0
0,1,0,0,0,0,1,0,0,0,0,1,0,0,1,0,6,31,0,1,0,29,28,0,1,29,28,0,0,1,0
0,1,0,0,0,0,1,0,0,0,0,1,0,0,1,0,0,0,0,1,0,0,0,0,1,41,0,0,0,1,0
0,1,11,0,0,12,1,11,0,0,12,1,0,0,1,0,0,0,0,1,0,0,0,0,1,11,0,0,12,1,0
0,1,0,0,0,0,1,0,0,0,0,1,11,12,1,11,0,0,12,1,11,0,0,12,1,0,0,0,0,1,0
0,1,0,0,0,0,1,0,0,0,0,1,0,0,1,0,0,0,0,1,0,0,0,0,1,0,0,0,0,1,0
0,1,0,0,0,0,1,0,0,0,0,1,0,0,1,0,0,0,0,1,0,0,0,0,1,0,0,0,0,1,0
0,4,7,1,40,40,4,40,40,1,8,4,8,7,4,40,40,1,8,4,40,40,1,7,4,7,1,40,40,4,0
0,10,0,39,0,0,10,0,0,38,0,10,0,0,10,0,0,37,0,10,0,0,36,0,10,0,35,0,0,10,0
0,0,0,0,0,0,0,0,0,0,0,0,0,0,0,0,0,0,0,0,0,0,0,0,0,0,0,0,0,0,0
0,0,0,0,0,0,0,0,0,0,0,0,0,0,0,0,0,0,0,0,0,0,0,0,0,0,0,0,0,0,0
0,0,0,0,0,0,0,0,0,0,0,0,0,0,0,0,0,0,0,0,0,0,0,0,0,0,0,0,0,0,0
:endlayer
layer: 6
0,0,0,0,0,0,0,0,0,0,0,0,0,0,0,0,0,0,0,0,0,0,0,0,0,0,0,0,0,0,0
0,4,1,1,4,1,1,1,1,1,1,4,0,0,0,0,0,0,0,0,0,0,0,0,0,0,0,0,0,0,0
0,1,0,0,0,0,0,0,0,0,0,1,0,0,0,0,0,0,0,0,0,0,0,0,0,0,0,0,0,0,0
0,1,0,0,0,0,0,0,0,0,0,4,1,1,4,1,40,40,1,4,1,1,1,1,4,1,40,40,1,4,0
0,1,0,0,0,0,0,0,0,0,0,1,0,0,1,0,0,0,0,0,0,0,0,0,0,0,0,0,0,1,0
0,4,1,1,4,1,4,0,0,0,0,1,0,0,1,0,0,0,0,0,0,0,0,0,0,0,0,0,0,1,0
0,1,0,0,1,29,1,0,0,0,0,1,0,0,1,0,0,0,0,0,0,0,0,0,0,0,0,0,0,1,0
0,1,0,0,1,27,1,0,0,0,0,1,0,0,1,0,0,0,0,0,0,0,0,0,0,0,0,0,0,1,0
0,1,0,0,1,0,1,0,0,0,0,1,0,0,1,0,0,0,0,0,0,0,0,0,0,0,0,0,0,1,0
0,1,0,0,0,0,1,0,1,1,0,1,0,0,1,0,0,0,0,0,0,0,0,0,0,0,0,0,0,1,0
0,4,1,1,1,1,4,1,1,1,1,4,0,0,4,1,1,1,1,4,1,1,1,1,4,1,1,1,1,4,0
0,1,0,0,0,0,1,0,0,0,0,1,0,0,1,0,0,6,31,1,29,28,0,0,1,0,0,0,0,1,0
0,1,0,0,0,0,1,0,0,0,0,1,0,0,1,0,0,0,41,1,41,0,0,0,1,43,0,0,0,1,0
0,1,0,0,0,0,1,0,0,0,0,1,0,0,1,0,0,0,0,1,0,0,0,0,1,41,0,0,0,1,0
0,1,0,0,0,0,1,0,0,0,0,1,0,0,1,0,0,0,0,1,0,0,0,0,1,0,0,0,0,1,0
0,1,0,0,0,0,1,0,0,0,0,1,0,0,1,0,0,0,0,1,0,0,0,0,1,0,0,0,0,1,0
0,1,0,0,0,0,1,0,0,0,0,1,0,0,1,0,0,0,0,1,0,0,0,0,1,0,0,0,0,1,0
0,4,1,1,40,40,4,40,40,1,1,4,1,1,4,40,40,1,1,4,40,40,1,1,4,1,1,40,40,4,0
0,0,0,0,0,0,0,0,0,0,0,0,42,0,0,0,0,0,0,0,0,0,0,0,0,0,0,0,0,0,0
0,0,0,0,0,0,0,0,0,0,0,0,0,0,0,0,0,0,0,0,0,0,0,0,0,0,0,0,0,0,0
0,0,0,0,0,0,0,0,0,0,0,0,0,0,0,0,0,0,0,0,0,0,0,0,0,0,0,0,0,0,0
0,0,0,0,0,0,0,0,0,0,0,0,0,0,0,0,0,0,0,0,0,0,0,0,0,0,0,0,0,0,0
:endlayer
layer: 7
0,0,0,0,0,0,0,0,0,0,0,0,0,0,0,0,0,0,0,0,0,0,0,0,0,0,0,0,0,0,0
0,4,13,13,4,13,13,13,13,13,13,4,0,0,0,0,0,0,0,0,0,0,0,0,0,0,0,0,0,0,0
0,14,16,19,19,19,19,19,19,19,17,14,0,0,0,0,0,0,0,0,0,0,0,0,0,0,0,0,0,0,0
0,14,16,18,18,18,18,18,18,18,17,4,13,13,4,13,13,13,13,4,13,13,13,13,4,13,13,13,13,4,0
0,14,15,15,15,15,15,15,18,18,17,14,0,0,14,0,0,0,0,0,0,0,0,0,0,0,0,0,0,14,0
0,4,20,20,4,13,4,16,18,18,17,14,0,0,14,0,0,0,0,0,0,0,0,0,0,0,0,0,0,14,0
0,14,16,17,28,0,14,16,18,18,17,14,0,0,14,0,0,0,0,0,0,0,0,0,0,0,0,0,0,14,0
0,14,16,17,14,0,14,16,18,18,17,14,0,0,14,0,0,0,0,0,0,0,0,0,0,0,0,0,0,14,0
0,14,16,17,14,0,14,16,18,18,17,14,0,0,14,0,0,0,0,0,0,0,0,0,0,0,0,0,0,14,0
0,14,16,17,16,0,14,18,1,1,18,14,0,0,14,0,0,0,0,0,0,0,0,0,0,0,0,0,0,14,0
0,4,20,20,13,13,4,13,13,13,13,4,0,0,4,13,13,13,13,4,13,13,13,13,4,13,13,13,13,4,0
0,14,16,18,18,17,20,16,18,18,17,14,0,0,14,0,0,0,0,14,0,0,0,0,14,0,0,0,0,14,0
0,14,16,18,18,17,20,16,18,18,17,14,0,0,14,19,19,19,43,14,43,19,19,19,14,0,18,18,18,14,0
0,14,16,18,18,17,20,16,18,18,17,14,0,0,14,18,18,18,18,14,18,18,18,18,14,43,18,18,18,14,0
0,14,16,18,18,17,20,16,18,18,17,14,0,0,14,18,18,18,18,14,18,18,18,18,14,18,18,18,18,14,0
0,14,16,18,18,17,20,16,18,18,17,14,0,0,14,18,18,18,18,14,18,18,18,18,14,18,18,18,18,14,0
0,14,16,18,18,17,20,16,18,18,17,14,0,0,14,15,15,15,15,14,15,15,15,15,14,15,15,15,15,14,0
0,4,13,13,13,13,4,13,13,13,13,4,13,13,4,13,13,13,13,4,13,13,13,13,4,13,13,13,13,4,0
0,0,0,0,45,0,0,0,45,0,0,0,0,0,0,0,45,0,0,0,0,45,0,0,0,0,0,45,0,0,0
0,0,0,0,44,0,0,0,44,0,0,0,0,0,0,0,44,0,0,0,0,44,0,0,0,0,0,44,0,0,0
0,0,0,0,0,0,0,0,0,0,0,0,0,0,0,0,0,0,0,0,0,0,0,0,0,0,0,0,0,0,0
0,0,0,0,0,0,0,0,0,0,0,0,0,0,0,0,0,0,0,0,0,0,0,0,0,0,0,0,0,0,0
:endlayer
layer: 8
0,0,0,0,0,0,0,0,0,0,0,0,0,0,0,0,0,0,0,0,0,0,0,0,0,0,0,0,0,0,0
0,4,20,20,4,20,20,20,20,20,20,4,0,0,0,0,0,0,0,0,0,0,0,0,0,0,0,0,0,0,0
0,20,0,0,0,0,0,0,0,0,0,20,0,0,0,0,0,0,0,0,0,0,0,0,0,0,0,0,0,0,0
0,20,0,0,0,0,0,0,0,0,0,4,20,20,4,20,20,20,20,4,20,20,20,20,4,20,20,20,20,4,0
0,20,0,0,0,0,0,0,0,0,0,20,0,0,20,0,0,0,0,0,0,0,0,0,0,0,0,0,0,20,0
0,4,5,5,4,20,4,0,0,0,0,20,0,0,20,0,0,0,0,0,0,0,0,0,0,0,0,0,0,20,0
0,20,0,0,0,0,20,0,0,0,0,20,0,0,20,0,0,0,0,0,0,0,0,0,0,0,0,0,0,20,0
0,20,0,0,20,0,20,0,0,0,0,20,0,0,20,0,0,0,0,0,0,0,0,0,0,0,0,0,0,20,0
0,20,0,0,20,0,20,0,0,0,0,20,0,0,20,0,0,0,0,0,0,0,0,0,0,0,0,0,0,20,0
0,20,0,0,20,0,20,1,48,47,1,20,0,0,20,0,0,0,0,0,0,0,0,0,0,0,0,0,0,20,0
0,4,5,5,20,20,4,1,1,1,1,4,0,0,4,20,20,20,20,4,20,20,20,20,4,20,20,20,20,4,0
0,20,0,0,0,0,0,0,0,0,0,20,0,0,20,0,0,0,0,20,0,0,0,0,20,0,0,0,0,20,0
0,20,0,0,0,0,0,0,0,0,0,20,0,0,20,45,45,45,0,20,0,45,45,45,20,0,45,45,45,20,0
0,20,0,0,0,0,0,0,0,0,0,20,0,0,20,0,0,0,0,20,0,0,0,0,20,0,0,0,0,20,0
0,20,0,0,0,0,0,0,0,0,0,20,0,0,20,0,0,0,0,20,0,0,0,0,20,0,0,0,0,20,0
0,20,0,0,0,0,0,0,0,0,0,20,0,0,20,0,0,0,0,20,0,0,0,0,20,0,0,0,0,20,0
0,20,0,0,0,0,0,0,0,0,0,20,0,0,20,0,0,0,0,20,0,0,0,0,20,0,0,0,0,20,0
0,4,46,46,46,46,4,46,46,46,46,4,46,46,4,46,46,46,46,4,46,46,46,46,4,46,46,46,46,4,0
0,0,0,0,0,0,0,0,0,0,0,0,0,0,0,0,0,0,0,0,0,0,0,0,0,0,0,0,0,0,0
0,0,0,0,0,0,0,0,0,0,0,0,0,0,0,0,0,0,0,0,0,0,0,0,0,0,0,0,0,0,0
0,0,0,0,0,0,0,0,0,0,0,0,0,0,0,0,0,0,0,0,0,0,0,0,0,0,0,0,0,0,0
0,0,0,0,0,0,0,0,0,0,0,0,0,0,0,0,0,0,0,0,0,0,0,0,0,0,0,0,0,0,0
:endlayer
layer: 9
0,0,0,0,0,0,0,0,0,0,0,0,0,0,0,0,0,0,0,0,0,0,0,0,0,0,0,0,0,0,0
0,4,20,20,4,20,40,40,40,40,20,4,0,0,0,0,0,0,0,0,0,0,0,0,0,0,0,0,0,0,0
0,20,0,0,10,0,0,0,0,0,0,20,0,0,0,0,0,0,0,0,0,0,0,0,0,0,0,0,0,0,0
0,20,0,0,0,0,0,0,0,0,0,4,20,20,4,20,20,20,20,4,20,20,20,20,4,20,20,20,20,4,0
0,20,0,0,0,0,9,0,0,0,0,20,0,0,20,0,0,0,0,0,0,0,0,0,0,0,0,0,0,20,0
0,4,8,7,4,20,4,11,0,0,12,20,0,0,20,0,0,0,0,0,0,0,0,0,0,0,0,0,0,20,0
0,20,0,0,0,0,20,0,0,0,0,20,0,0,20,0,0,0,0,0,0,0,0,0,0,0,0,0,0,20,0
0,20,11,0,20,0,20,0,0,0,0,20,0,0,20,0,0,0,0,0,0,0,0,0,0,0,0,0,0,20,0
0,20,0,0,20,0,20,0,0,0,0,20,0,0,20,0,0,0,0,0,0,0,0,0,0,0,0,0,0,20,0
0,20,0,0,20,0,20,21,1,1,23,20,0,0,20,0,0,0,0,0,0,0,0,0,0,0,0,0,0,20,0
0,4,7,8,20,20,4,1,1,1,1,4,0,0,4,20,20,20,20,4,20,20,20,20,4,20,20,20,20,4,0
0,20,0,0,0,0,10,0,0,0,0,20,0,0,20,0,0,0,0,20,0,0,0,0,20,0,0,0,0,20,0
0,20,11,0,0,0,0,0,0,0,12,20,0,0,20,0,0,0,0,20,0,0,0,0,20,0,0,0,0,20,0
0,20,0,0,0,0,0,0,0,0,0,20,0,0,20,11,0,0,12,20,11,0,0,12,20,0,0,0,0,20,0
0,20,0,0,0,0,0,0,0,0,0,20,0,0,20,0,0,0,0,20,0,0,0,0,20,11,0,0,12,20,0
0,20,11,0,0,0,0,0,0,0,12,20,0,0,20,0,0,0,0,20,0,0,0,0,20,0,0,0,0,20,0
0,20,0,0,0,0,9,0,0,0,0,20,0,0,20,0,0,0,0,20,0,0,0,0,20,0,0,0,0,20,0
0,4,46,40,40,46,4,46,40,40,46,4,40,40,4,46,40,40,46,4,46,40,40,46,4,46,40,40,46,4,0
0,0,0,0,0,0,0,0,0,0,0,0,0,0,0,0,0,0,0,0,0,0,0,0,0,0,0,0,0,0,0
0,0,0,0,0,0,0,0,0,0,0,0,0,0,0,0,0,0,0,0,0,0,0,0,0,0,0,0,0,0,0
0,0,0,0,0,0,0,0,0,0,0,0,0,0,0,0,0,0,0,0,0,0,0,0,0,0,0,0,0,0,0
0,0,0,0,0,0,0,0,0,0,0,0,0,0,0,0,0,0,0,0,0,0,0,0,0,0,0,0,0,0,0
:endlayer
layer: 10
0,0,0,0,0,0,0,0,0,0,0,0,0,0,0,0,0,0,0,0,0,0,0,0,0,0,0,0,0,0,0
0,4,20,20,4,20,20,20,20,20,20,4,0,0,0,0,0,0,0,0,0,0,0,0,0,0,0,0,0,0,0
0,20,0,0,0,0,0,0,0,0,0,20,0,0,0,0,0,0,0,0,0,0,0,0,0,0,0,0,0,0,0
0,20,0,0,0,0,0,0,0,0,0,4,20,20,4,20,20,20,20,4,20,20,20,20,4,20,20,20,20,4,0
0,20,0,0,0,0,0,0,0,0,0,20,0,0,20,0,0,0,0,0,0,0,0,0,0,0,0,0,0,20,0
0,4,20,20,4,20,4,0,0,0,0,20,0,0,20,0,0,0,0,0,0,0,0,0,0,0,0,0,0,20,0
0,20,0,0,0,0,20,0,0,0,0,20,0,0,20,0,0,0,0,0,0,0,0,0,0,0,0,0,0,20,0
0,20,0,0,20,0,20,0,0,0,0,20,0,0,20,0,0,0,0,0,0,0,0,0,0,0,0,0,0,20,0
0,20,0,0,20,0,20,0,0,0,0,20,0,0,20,0,0,0,0,0,0,0,0,0,0,0,0,0,0,20,0
0,20,0,0,20,0,20,0,1,1,0,20,0,0,20,0,0,0,0,0,0,0,0,0,0,0,0,0,0,20,0
0,4,20,20,20,20,4,1,1,1,1,4,0,0,4,20,20,20,20,4,20,20,20,20,4,20,20,20,20,4,0
0,20,0,0,0,0,0,0,0,0,0,20,0,0,20,0,0,0,0,20,0,0,0,0,20,0,0,0,0,20,0
0,20,0,0,0,0,0,0,0,0,0,20,0,0,20,0,0,0,0,20,0,0,0,0,20,0,0,0,0,20,0
0,20,0,0,0,0,0,0,0,0,0,20,0,0,20,0,0,0,0,20,0,0,0,0,20,0,0,0,0,20,0
0,20,0,0,0,0,0,0,0,0,0,20,0,0,20,0,0,0,0,20,0,0,0,0,20,0,0,0,0,20,0
0,20,0,0,0,0,0,0,0,0,0,20,0,0,20,0,0,0,0,20,0,0,0,0,20,0,0,0,0,20,0
0,20,0,0,0,0,0,0,0,0,0,20,0,0,20,0,0,0,0,20,0,0,0,0,20,0,0,0,0,20,0
0,4,46,46,46,46,4,46,46,46,46,4,46,46,4,46,46,46,46,4,46,46,46,46,4,46,46,46,46,4,0
0,0,0,0,0,0,0,0,0,0,0,0,0,0,0,0,0,0,0,0,0,0,0,0,0,0,0,0,0,0,0
0,0,0,0,0,0,0,0,0,0,0,0,0,0,0,0,0,0,0,0,0,0,0,0,0,0,0,0,0,0,0
0,0,0,0,0,0,0,0,0,0,0,0,0,0,0,0,0,0,0,0,0,0,0,0,0,0,0,0,0,0,0
0,0,0,0,0,0,0,0,0,0,0,0,0,0,0,0,0,0,0,0,0,0,0,0,0,0,0,0,0,0,0
:endlayer
layer: 11
53,56,56,56,56,56,56,56,56,56,56,56,49,0,0,0,0,0,0,0,0,0,0,0,0,0,0,0,0,0,0
53,4,13,13,4,13,13,13,13,13,13,4,49,0,0,0,0,0,0,0,0,0,0,0,0,0,0,0,0,0,0
56,14,0,0,0,0,0,0,0,0,0,14,56,56,56,56,56,56,56,56,56,56,56,56,56,56,56,56,56,56,56
52,14,0,0,0,0,0,0,0,0,0,4,13,13,4,13,13,13,13,4,13,13,13,13,4,13,13,13,13,4,52
0,14,0,0,0,0,0,0,0,0,0,14,0,0,14,0,0,0,0,14,0,0,0,0,14,0,0,0,0,14,0
0,4,13,13,4,13,4,0,0,0,0,14,0,0,14,0,0,0,0,14,0,0,0,0,14,0,0,0,0,14,0
0,14,0,0,14,0,14,0,0,0,0,14,0,0,14,0,0,0,0,14,0,0,0,0,14,0,0,0,0,14,0
0,14,0,0,14,0,14,0,0,0,0,14,0,0,14,0,0,0,0,14,0,0,0,0,14,0,0,0,0,14,0
0,14,0,0,14,0,14,0,0,0,0,14,0,0,14,0,0,0,0,14,0,0,0,0,14,0,0,0,0,14,0
0,14,0,0,14,0,14,0,1,1,0,14,0,0,14,0,0,0,0,14,0,0,0,0,14,0,0,0,0,14,0
55,4,13,13,13,13,4,13,13,13,13,4,13,13,4,13,13,13,13,4,13,13,13,13,4,13,13,13,13,4,55
54,14,0,0,0,0,14,0,0,0,0,14,16,17,14,20,20,20,20,14,0,0,0,0,14,0,0,0,0,14,54
53,14,0,0,0,0,14,0,0,0,0,14,16,17,14,20,20,20,20,14,0,0,0,0,14,0,0,0,0,14,49
53,14,0,0,0,0,14,0,0,0,0,14,16,17,14,20,20,20,20,14,0,0,0,0,14,0,0,0,0,14,49
53,14,0,0,0,0,14,0,0,0,0,14,16,17,14,20,20,20,20,14,0,0,0,0,14,0,0,0,0,14,49
53,14,0,0,0,0,14,0,0,0,0,14,16,17,14,20,20,20,20,14,0,0,0,0,14,0,0,0,0,14,49
53,14,0,0,0,0,14,0,0,0,0,14,16,17,14,20,20,20,20,14,0,0,0,0,14,0,0,0,0,14,49
53,4,13,13,13,13,4,13,13,13,13,4,13,13,4,13,13,13,13,4,13,13,13,13,4,13,13,13,13,4,49
53,51,0,0,0,0,0,0,0,0,0,50,52,52,51,0,0,0,0,0,0,0,0,0,0,0,0,0,0,50,49
0,0,0,0,0,0,0,0,0,0,0,0,0,0,0,0,0,0,0,0,0,0,0,0,0,0,0,0,0,0,0
0,0,0,0,0,0,0,0,0,0,0,0,0,0,0,0,0,0,0,0,0,0,0,0,0,0,0,0,0,0,0
0,0,0,0,0,0,0,0,0,0,0,0,0,0,0,0,0,0,0,0,0,0,0,0,0,0,0,0,0,0,0
:endlayer
layer: 12
0,0,0,0,0,0,0,0,0,0,0,0,0,0,0,0,0,0,0,0,0,0,0,0,0,0,0,0,0,0,0
0,57,57,57,57,57,57,57,57,57,57,57,0,0,0,0,0,0,0,0,0,0,0,0,0,0,0,0,0,0,0
0,57,57,57,57,57,57,57,57,57,57,57,0,0,0,0,0,0,0,0,0,0,0,0,0,0,0,0,0,0,0
56,56,56,56,56,56,56,56,56,56,56,56,56,56,56,56,56,56,56,56,56,56,56,56,56,56,56,56,56,56,56
52,20,20,20,20,20,20,20,20,20,20,20,19,19,20,19,19,19,19,19,19,19,19,19,19,19,19,19,19,20,52
0,20,20,20,20,20,20,20,20,20,20,20,0,0,20,0,0,0,0,0,0,0,0,0,0,0,0,0,0,20,0
0,20,20,20,20,20,20,20,20,20,20,20,0,0,20,0,0,0,0,0,0,0,0,0,0,0,0,0,0,20,0
0,20,20,20,20,20,20,20,20,20,20,20,0,0,20,0,0,0,0,0,0,0,0,0,0,0,0,0,0,20,0
0,20,20,20,20,20,20,20,20,20,20,20,0,0,20,0,0,0,0,0,0,0,0,0,0,0,0,0,0,20,0
55,20,20,20,20,20,20,20,1,1,20,20,15,15,20,15,15,15,15,15,15,15,15,15,15,15,15,15,15,20,55
54,54,20,20,20,20,20,20,20,20,20,54,54,54,54,20,20,20,20,20,20,20,20,20,20,20,20,20,20,54,54
0,53,20,20,20,20,20,20,20,20,20,49,57,57,53,20,20,20,20,20,20,20,20,20,20,20,20,20,20,49,0
0,53,20,20,20,20,20,20,20,20,20,49,57,57,53,20,20,20,20,20,20,20,20,20,20,20,20,20,20,49,0
0,53,20,20,20,20,20,20,20,20,20,49,57,57,53,20,20,20,20,20,20,20,20,20,20,20,20,20,20,49,0
0,53,20,20,20,20,20,20,20,20,20,49,57,57,53,20,20,20,20,20,20,20,20,20,20,20,20,20,20,49,0
0,53,20,20,20,20,20,20,20,20,20,49,57,57,53,20,20,20,20,20,20,20,20,20,20,20,20,20,20,49,0
0,53,20,20,20,20,20,20,20,20,20,49,57,57,53,20,20,20,20,20,20,20,20,20,20,20,20,20,20,49,0
0,53,46,46,46,46,20,46,46,46,46,49,57,57,53,46,46,46,46,20,46,46,46,46,20,46,46,46,46,49,0
0,53,51,0,0,50,52,51,0,0,50,49,57,57,53,51,0,0,50,52,51,0,0,50,52,51,0,0,50,49,0
0,0,0,0,0,0,0,0,0,0,0,0,0,0,0,0,0,0,0,0,0,0,0,0,0,0,0,0,0,0,0
0,0,0,0,0,0,0,0,0,0,0,0,0,0,0,0,0,0,0,0,0,0,0,0,0,0,0,0,0,0,0
0,0,0,0,0,0,0,0,0,0,0,0,0,0,0,0,0,0,0,0,0,0,0,0,0,0,0,0,0,0,0
:endlayer
layer: 13
0,0,0,0,0,0,0,0,0,0,0,0,0,0,0,0,0,0,0,0,0,0,0,0,0,0,0,0,0,0,0
0,0,0,0,0,0,0,0,0,0,0,0,0,0,0,0,0,0,0,0,0,0,0,0,0,0,0,0,0,0,0
0,0,0,0,0,0,0,0,0,0,0,0,0,0,0,0,0,0,0,0,0,0,0,0,0,0,0,0,0,0,0
0,0,0,0,0,0,0,0,0,0,0,0,0,0,0,0,0,0,0,0,0,0,0,0,0,0,0,0,0,0,0
56,56,56,56,56,56,56,56,56,56,56,56,56,56,56,56,56,56,56,56,56,56,56,56,56,56,56,56,56,56,56
52,20,20,20,20,20,20,20,20,20,20,20,19,19,20,19,19,19,19,19,19,19,19,19,19,19,19,19,19,20,52
0,20,20,20,20,20,20,20,20,20,20,20,0,0,20,0,0,0,0,0,0,0,0,0,0,0,0,0,0,20,0
0,20,20,20,20,20,20,20,20,20,20,20,0,0,20,0,0,0,0,0,0,0,0,0,0,0,0,0,0,20,0
55,20,20,20,20,20,20,20,20,20,20,20,15,15,20,15,15,15,15,15,15,15,15,15,15,15,15,15,15,20,55
54,54,53,20,20,49,54,53,1,1,54,54,54,54,54,53,20,20,49,54,53,20,20,54,54,54,20,20,49,54,54
0,0,53,20,20,49,57,53,20,20,49,0,0,0,0,53,20,20,49,57,53,20,20,49,57,53,20,20,49,0,0
0,0,53,20,20,49,57,53,20,20,49,0,0,0,0,53,20,20,49,57,53,20,20,49,57,53,20,20,49,0,0
0,0,53,20,20,49,57,53,20,20,49,0,0,0,0,53,20,20,49,57,53,20,20,49,57,53,20,20,49,0,0
0,0,53,20,20,49,57,53,20,20,49,0,0,0,0,53,20,20,49,57,53,20,20,49,57,53,20,20,49,0,0
0,0,53,20,20,49,57,53,20,20,49,0,0,0,0,53,20,20,49,57,53,20,20,49,57,53,20,20,49,0,0
0,0,53,20,20,49,57,53,20,20,49,0,0,0,0,53,20,20,49,57,53,20,20,49,57,53,20,20,49,0,0
0,0,53,20,20,49,57,53,20,20,49,0,0,0,0,53,20,20,49,57,53,20,20,49,57,53,20,20,49,0,0
0,0,53,46,46,49,57,53,46,46,49,0,0,0,0,53,46,46,49,57,53,46,46,49,57,53,46,46,49,0,0
0,0,53,51,50,49,57,53,51,50,49,0,0,0,0,53,51,50,49,57,53,51,50,49,57,53,51,50,49,0,0
0,0,0,0,0,0,0,0,0,0,0,0,0,0,0,0,0,0,0,0,0,0,0,0,0,0,0,0,0,0,0
0,0,0,0,0,0,0,0,0,0,0,0,0,0,0,0,0,0,0,0,0,0,0,0,0,0,0,0,0,0,0
0,0,0,0,0,0,0,0,0,0,0,0,0,0,0,0,0,0,0,0,0,0,0,0,0,0,0,0,0,0,0
:endlayer
layer: 14
0,0,0,0,0,0,0,0,0,0,0,0,0,0,0,0,0,0,0,0,0,0,0,0,0,0,0,0,0,0,0
0,0,0,0,0,0,0,0,0,0,0,0,0,0,0,0,0,0,0,0,0,0,0,0,0,0,0,0,0,0,0
0,0,0,0,0,0,0,0,0,0,0,0,0,0,0,0,0,0,0,0,0,0,0,0,0,0,0,0,0,0,0
0,0,0,0,0,0,0,0,0,0,0,0,0,0,0,0,0,0,0,0,0,0,0,0,0,0,0,0,0,0,0
0,0,0,0,0,0,0,0,0,0,0,0,0,0,0,0,0,0,0,0,0,0,0,0,0,0,0,0,0,0,0
56,56,56,56,56,56,56,56,56,56,56,56,56,56,56,56,56,56,56,56,56,56,56,56,56,56,56,56,56,56,56
52,20,20,20,20,20,20,20,20,20,20,20,19,19,20,19,19,19,19,19,19,19,19,19,19,19,19,19,19,20,52
55,20,20,20,20,20,20,20,20,20,20,20,15,15,20,15,15,15,15,15,15,15,15,15,15,15,15,15,15,20,55
54,54,54,53,49,54,54,54,54,54,54,54,54,54,54,54,54,49,54,54,54,53,49,54,54,54,53,54,54,54,54
0,0,0,53,49,0,0,0,1,1,0,0,0,0,0,0,53,49,0,0,0,53,49,0,0,0,53,49,0,0,0
0,0,0,53,49,0,0,0,53,49,0,0,0,0,0,0,53,49,0,0,0,53,49,0,0,0,53,49,0,0,0
0,0,0,53,49,0,0,0,53,49,0,0,0,0,0,0,53,49,0,0,0,53,49,0,0,0,53,49,0,0,0
0,0,0,53,49,0,0,0,53,49,0,0,0,0,0,0,53,49,0,0,0,53,49,0,0,0,53,49,0,0,0
0,0,0,53,49,0,0,0,53,49,0,0,0,0,0,0,53,49,0,0,0,53,49,0,0,0,53,49,0,0,0
0,0,0,53,49,0,0,0,53,49,0,0,0,0,0,0,53,49,0,0,0,53,49,0,0,0,53,49,0,0,0
0,0,0,53,49,0,0,0,53,49,0,0,0,0,0,0,53,49,0,0,0,53,49,0,0,0,53,49,0,0,0
0,0,0,53,49,0,0,0,53,49,0,0,0,0,0,0,53,49,0,0,0,53,49,0,0,0,53,49,0,0,0
0,0,0,53,49,0,0,0,53,49,0,0,0,0,0,0,53,49,0,0,0,53,49,0,0,0,53,49,0,0,0
0,0,0,53,49,0,0,0,53,49,0,0,0,0,0,0,53,49,0,0,0,53,49,0,0,0,53,49,0,0,0
0,0,0,0,0,0,0,0,0,0,0,0,0,0,0,0,0,0,0,0,0,0,0,0,0,0,0,0,0,0,0
0,0,0,0,0,0,0,0,0,0,0,0,0,0,0,0,0,0,0,0,0,0,0,0,0,0,0,0,0,0,0
0,0,0,0,0,0,0,0,0,0,0,0,0,0,0,0,0,0,0,0,0,0,0,0,0,0,0,0,0,0,0
:endlayer
layer: 15
0,0,0,0,0,0,0,0,0,0,0,0,0,0,0,0,0,0,0,0,0,0,0,0,0,0,0,0,0,0,0
0,0,0,0,0,0,0,0,0,0,0,0,0,0,0,0,0,0,0,0,0,0,0,0,0,0,0,0,0,0,0
0,0,0,0,0,0,0,0,0,0,0,0,0,0,0,0,0,0,0,0,0,0,0,0,0,0,0,0,0,0,0
0,0,0,0,0,0,0,0,0,0,0,0,0,0,0,0,0,0,0,0,0,0,0,0,0,0,0,0,0,0,0
0,0,0,0,0,0,0,0,0,0,0,0,0,0,0,0,0,0,0,0,0,0,0,0,0,0,0,0,0,0,0
0,0,0,0,0,0,0,0,0,0,0,0,0,0,0,0,0,0,0,0,0,0,0,0,0,0,0,0,0,0,0
56,56,56,56,56,56,56,56,56,56,56,56,56,56,56,56,56,56,56,56,56,56,56,56,56,56,56,56,56,56,56
54,54,54,54,54,54,54,54,54,54,54,54,54,54,54,54,54,54,54,54,54,54,54,54,54,54,54,54,54,54,54
0,0,0,0,0,0,0,0,0,0,0,0,0,0,0,0,0,0,0,0,0,0,0,0,0,0,0,0,0,0,0
0,0,0,0,0,0,0,0,1,1,0,0,0,0,0,0,0,0,0,0,0,0,0,0,0,0,0,0,0,0,0
0,0,0,0,0,0,0,0,0,0,0,0,0,0,0,0,0,0,0,0,0,0,0,0,0,0,0,0,0,0,0
0,0,0,0,0,0,0,0,0,0,0,0,0,0,0,0,0,0,0,0,0,0,0,0,0,0,0,0,0,0,0
0,0,0,0,0,0,0,0,0,0,0,0,0,0,0,0,0,0,0,0,0,0,0,0,0,0,0,0,0,0,0
0,0,0,0,0,0,0,0,0,0,0,0,0,0,0,0,0,0,0,0,0,0,0,0,0,0,0,0,0,0,0
0,0,0,0,0,0,0,0,0,0,0,0,0,0,0,0,0,0,0,0,0,0,0,0,0,0,0,0,0,0,0
0,0,0,0,0,0,0,0,0,0,0,0,0,0,0,0,0,0,0,0,0,0,0,0,0,0,0,0,0,0,0
0,0,0,0,0,0,0,0,0,0,0,0,0,0,0,0,0,0,0,0,0,0,0,0,0,0,0,0,0,0,0
0,0,0,0,0,0,0,0,0,0,0,0,0,0,0,0,0,0,0,0,0,0,0,0,0,0,0,0,0,0,0
0,0,0,0,0,0,0,0,0,0,0,0,0,0,0,0,0,0,0,0,0,0,0,0,0,0,0,0,0,0,0
0,0,0,0,0,0,0,0,0,0,0,0,0,0,0,0,0,0,0,0,0,0,0,0,0,0,0,0,0,0,0
0,0,0,0,0,0,0,0,0,0,0,0,0,0,0,0,0,0,0,0,0,0,0,0,0,0,0,0,0,0,0
0,0,0,0,0,0,0,0,0,0,0,0,0,0,0,0,0,0,0,0,0,0,0,0,0,0,0,0,0,0,0
:endlayer
layer: 16
0,0,0,0,0,0,0,0,0,0,0,0,0,0,0,0,0,0,0,0,0,0,0,0,0,0,0,0,0,0,0
0,0,0,0,0,0,0,0,0,0,0,0,0,0,0,0,0,0,0,0,0,0,0,0,0,0,0,0,0,0,0
0,0,0,0,0,0,0,0,0,0,0,0,0,0,0,0,0,0,0,0,0,0,0,0,0,0,0,0,0,0,0
0,0,0,0,0,0,0,0,0,0,0,0,0,0,0,0,0,0,0,0,0,0,0,0,0,0,0,0,0,0,0
0,0,0,0,0,0,0,0,0,0,0,0,0,0,0,0,0,0,0,0,0,0,0,0,0,0,0,0,0,0,0
0,0,0,0,0,0,0,0,0,0,0,0,0,0,0,0,0,0,0,0,0,0,0,0,0,0,0,0,0,0,0
0,0,0,0,0,0,0,0,0,0,0,0,0,0,0,0,0,0,0,0,0,0,0,0,0,0,0,0,0,0,0
0,0,0,0,0,0,0,0,0,0,0,0,0,0,0,0,0,0,0,0,0,0,0,0,0,0,0,0,0,0,0
0,0,0,0,0,0,0,0,0,0,0,0,0,0,0,0,0,0,0,0,0,0,0,0,0,0,0,0,0,0,0
0,0,0,0,0,0,0,0,1,1,0,0,0,0,0,0,0,0,0,0,0,0,0,0,0,0,0,0,0,0,0
0,0,0,0,0,0,0,0,0,0,0,0,0,0,0,0,0,0,0,0,0,0,0,0,0,0,0,0,0,0,0
0,0,0,0,0,0,0,0,0,0,0,0,0,0,0,0,0,0,0,0,0,0,0,0,0,0,0,0,0,0,0
0,0,0,0,0,0,0,0,0,0,0,0,0,0,0,0,0,0,0,0,0,0,0,0,0,0,0,0,0,0,0
0,0,0,0,0,0,0,0,0,0,0,0,0,0,0,0,0,0,0,0,0,0,0,0,0,0,0,0,0,0,0
0,0,0,0,0,0,0,0,0,0,0,0,0,0,0,0,0,0,0,0,0,0,0,0,0,0,0,0,0,0,0
0,0,0,0,0,0,0,0,0,0,0,0,0,0,0,0,0,0,0,0,0,0,0,0,0,0,0,0,0,0,0
0,0,0,0,0,0,0,0,0,0,0,0,0,0,0,0,0,0,0,0,0,0,0,0,0,0,0,0,0,0,0
0,0,0,0,0,0,0,0,0,0,0,0,0,0,0,0,0,0,0,0,0,0,0,0,0,0,0,0,0,0,0
0,0,0,0,0,0,0,0,0,0,0,0,0,0,0,0,0,0,0,0,0,0,0,0,0,0,0,0,0,0,0
0,0,0,0,0,0,0,0,0,0,0,0,0,0,0,0,0,0,0,0,0,0,0,0,0,0,0,0,0,0,0
0,0,0,0,0,0,0,0,0,0,0,0,0,0,0,0,0,0,0,0,0,0,0,0,0,0,0,0,0,0,0
0,0,0,0,0,0,0,0,0,0,0,0,0,0,0,0,0,0,0,0,0,0,0,0,0,0,0,0,0,0,0
:endlayer
layer: 17
0,0,0,0,0,0,0,0,0,0,0,0,0,0,0,0,0,0,0,0,0,0,0,0,0,0,0,0,0,0,0
0,0,0,0,0,0,0,0,0,0,0,0,0,0,0,0,0,0,0,0,0,0,0,0,0,0,0,0,0,0,0
0,0,0,0,0,0,0,0,0,0,0,0,0,0,0,0,0,0,0,0,0,0,0,0,0,0,0,0,0,0,0
0,0,0,0,0,0,0,0,0,0,0,0,0,0,0,0,0,0,0,0,0,0,0,0,0,0,0,0,0,0,0
0,0,0,0,0,0,0,0,0,0,0,0,0,0,0,0,0,0,0,0,0,0,0,0,0,0,0,0,0,0,0
0,0,0,0,0,0,0,0,0,0,0,0,0,0,0,0,0,0,0,0,0,0,0,0,0,0,0,0,0,0,0
0,0,0,0,0,0,0,0,0,0,0,0,0,0,0,0,0,0,0,0,0,0,0,0,0,0,0,0,0,0,0
0,0,0,0,0,0,0,0,0,0,0,0,0,0,0,0,0,0,0,0,0,0,0,0,0,0,0,0,0,0,0
0,0,0,0,0,0,0,0,0,0,0,0,0,0,0,0,0,0,0,0,0,0,0,0,0,0,0,0,0,0,0
0,0,0,0,0,0,0,0,58,58,0,0,0,0,0,0,0,0,0,0,0,0,0,0,0,0,0,0,0,0,0
0,0,0,0,0,0,0,0,0,0,0,0,0,0,0,0,0,0,0,0,0,0,0,0,0,0,0,0,0,0,0
0,0,0,0,0,0,0,0,0,0,0,0,0,0,0,0,0,0,0,0,0,0,0,0,0,0,0,0,0,0,0
0,0,0,0,0,0,0,0,0,0,0,0,0,0,0,0,0,0,0,0,0,0,0,0,0,0,0,0,0,0,0
0,0,0,0,0,0,0,0,0,0,0,0,0,0,0,0,0,0,0,0,0,0,0,0,0,0,0,0,0,0,0
0,0,0,0,0,0,0,0,0,0,0,0,0,0,0,0,0,0,0,0,0,0,0,0,0,0,0,0,0,0,0
0,0,0,0,0,0,0,0,0,0,0,0,0,0,0,0,0,0,0,0,0,0,0,0,0,0,0,0,0,0,0
0,0,0,0,0,0,0,0,0,0,0,0,0,0,0,0,0,0,0,0,0,0,0,0,0,0,0,0,0,0,0
0,0,0,0,0,0,0,0,0,0,0,0,0,0,0,0,0,0,0,0,0,0,0,0,0,0,0,0,0,0,0
0,0,0,0,0,0,0,0,0,0,0,0,0,0,0,0,0,0,0,0,0,0,0,0,0,0,0,0,0,0,0
0,0,0,0,0,0,0,0,0,0,0,0,0,0,0,0,0,0,0,0,0,0,0,0,0,0,0,0,0,0,0
0,0,0,0,0,0,0,0,0,0,0,0,0,0,0,0,0,0,0,0,0,0,0,0,0,0,0,0,0,0,0
0,0,0,0,0,0,0,0,0,0,0,0,0,0,0,0,0,0,0,0,0,0,0,0,0,0,0,0,0,0,0
:endlayer

#### RULES ####
rule:
plugin=vanillaBlocks
number=1
data:
JSON:{blockState:{blockName:"minecraft:cobblestone"}}
:enddata
:endrule

rule:
plugin=vanillaBlocks
number=2
data:
JSON:{blockState:{blockName:"minecraft:stonebrick",properties:{variant:"stonebrick"}}}
:enddata
:endrule

rule:
plugin=vanillaBlocks
number=3
data:
JSON:{blockState:{blockName:"minecraft:oak_stairs",properties:{half:"bottom",shape:"straight",facing:"south"}}}
:enddata
:endrule

rule:
plugin=vanillaBlocks
number=4
data:
JSON:{blockState:{blockName:"minecraft:log",properties:{variant:"oak",axis:"y"}}}
:enddata
:endrule

rule:
plugin=doors
number=5
data:
JSON:{blockState:{blockName:"minecraft:wooden_door",properties:{hinge:"left",half:"lower",powered:"false",facing:"west",open:"false"}}}
:enddata
:endrule

rule:
plugin=vanillaBlocks
number=6
data:
JSON:{blockState:{blockName:"minecraft:birch_stairs",properties:{half:"bottom",shape:"straight",facing:"east"}}}
:enddata
:endrule

rule:
plugin=doors
number=7
data:
JSON:{blockState:{blockName:"minecraft:wooden_door",properties:{hinge:"left",half:"upper",powered:"false",facing:"south",open:"false"}}}
:enddata
:endrule

rule:
plugin=doors
number=8
data:
JSON:{blockState:{blockName:"minecraft:wooden_door",properties:{hinge:"right",half:"upper",powered:"false",facing:"south",open:"false"}}}
:enddata
:endrule

rule:
plugin=vanillaBlocks
number=9
data:
JSON:{blockState:{blockName:"minecraft:torch",properties:{facing:"north"}}}
:enddata
:endrule

rule:
plugin=vanillaBlocks
number=10
data:
JSON:{blockState:{blockName:"minecraft:torch",properties:{facing:"south"}}}
:enddata
:endrule

rule:
plugin=vanillaBlocks
number=11
data:
JSON:{blockState:{blockName:"minecraft:torch",properties:{facing:"east"}}}
:enddata
:endrule

rule:
plugin=vanillaBlocks
number=12
data:
JSON:{blockState:{blockName:"minecraft:torch",properties:{facing:"west"}}}
:enddata
:endrule

rule:
plugin=vanillaBlocks
number=13
data:
JSON:{blockState:{blockName:"minecraft:log",properties:{variant:"oak",axis:"x"}}}
:enddata
:endrule

rule:
plugin=vanillaBlocks
number=14
data:
JSON:{blockState:{blockName:"minecraft:log",properties:{variant:"oak",axis:"z"}}}
:enddata
:endrule

rule:
plugin=vanillaBlocks
number=15
data:
JSON:{blockState:{blockName:"minecraft:oak_stairs",properties:{half:"top",shape:"straight",facing:"south"}}}
:enddata
:endrule

rule:
plugin=vanillaBlocks
number=16
data:
JSON:{blockState:{blockName:"minecraft:oak_stairs",properties:{half:"top",shape:"straight",facing:"west"}}}
:enddata
:endrule

rule:
plugin=vanillaBlocks
number=17
data:
JSON:{blockState:{blockName:"minecraft:oak_stairs",properties:{half:"top",shape:"straight",facing:"east"}}}
:enddata
:endrule

rule:
plugin=vanillaBlocks
number=18
data:
JSON:{blockState:{blockName:"minecraft:wooden_slab",properties:{half:"top",variant:"oak"}}}
:enddata
:endrule

rule:
plugin=vanillaBlocks
number=19
data:
JSON:{blockState:{blockName:"minecraft:oak_stairs",properties:{half:"top",shape:"straight",facing:"north"}}}
:enddata
:endrule

rule:
plugin=vanillaBlocks
number=20
data:
JSON:{blockState:{blockName:"minecraft:planks",properties:{variant:"oak"}}}
:enddata
:endrule

rule:
plugin=vanillaBlocks
number=21
data:
JSON:{blockState:{blockName:"minecraft:stone_stairs",properties:{half:"bottom",shape:"straight",facing:"east"}}}
:enddata
:endrule

rule:
plugin=vanillaBlocks
number=22
data:
JSON:{blockState:{blockName:"minecraft:stone_stairs",properties:{half:"bottom",shape:"straight",facing:"south"}}}
:enddata
:endrule

rule:
plugin=vanillaBlocks
number=23
data:
JSON:{blockState:{blockName:"minecraft:stone_stairs",properties:{half:"bottom",shape:"straight",facing:"west"}}}
:enddata
:endrule

rule:
plugin=vanillaBlocks
number=24
data:
JSON:{blockState:{blockName:"minecraft:torch",properties:{facing:"up"}}}
:enddata
:endrule

rule:
plugin=vanillaBlocks
number=25
data:
JSON:{blockState:{blockName:"minecraft:stone_stairs",properties:{half:"bottom",shape:"straight",facing:"north"}}}
:enddata
:endrule

rule:
plugin=vanillaBlocks
number=26
data:
JSON:{blockState:{blockName:"minecraft:trapdoor",properties:{half:"bottom",facing:"west",open:"false"}}}
:enddata
:endrule

rule:
plugin=vanillaBlocks
number=27
data:
JSON:{blockState:{blockName:"minecraft:birch_stairs",properties:{half:"bottom",shape:"straight",facing:"north"}}}
:enddata
:endrule

rule:
plugin=vanillaBlocks
number=28
data:
JSON:{blockState:{blockName:"minecraft:birch_stairs",properties:{half:"bottom",shape:"straight",facing:"west"}}}
:enddata
:endrule

rule:
plugin=vanillaBlocks
number=29
data:
JSON:{blockState:{blockName:"minecraft:birch_stairs",properties:{half:"top",shape:"straight",facing:"east"}}}
:enddata
:endrule

rule:
plugin=vanillaBlocks
number=30
data:
JSON:{blockState:{blockName:"minecraft:birch_stairs",properties:{half:"top",shape:"straight",facing:"south"}}}
:enddata
:endrule

rule:
plugin=vanillaBlocks
number=31
data:
JSON:{blockState:{blockName:"minecraft:birch_stairs",properties:{half:"top",shape:"straight",facing:"west"}}}
:enddata
:endrule

rule:
plugin=inventory
number=32
data:
JSON:{blockState:{blockName:"minecraft:furnace",properties:{facing:"north"}},lootLevel:0,teData:{CookTime:0,ForgeData:{generatedInventory:1b},BurnTime:0,Items:[],id:"minecraft:furnace",CookTimeTotal:0,Lock:""},inventoryData:{length:0,inventoryContents:[]},legacyFeatures:0b}
:enddata
:endrule

rule:
plugin=inventory
number=33
data:
JSON:{blockState:{blockName:"minecraft:furnace",properties:{facing:"north"}},lootLevel:0,teData:{CookTime:0,ForgeData:{generatedInventory:1b},BurnTime:0,Items:[],id:"minecraft:furnace",CookTimeTotal:0,Lock:""},inventoryData:{length:0,inventoryContents:[]},legacyFeatures:0b}
:enddata
:endrule

rule:
plugin=vanillaBlocks
number=34
data:
JSON:{blockState:{blockName:"minecraft:trapdoor",properties:{half:"bottom",facing:"south",open:"false"}}}
:enddata
:endrule

rule:
plugin=vanillaSign
number=35
data:
JSON:{signContents0:"",blockState:{blockName:"minecraft:wall_sign",properties:{facing:"south"}},signContents2:"",signContents1:"",signContents3:"",rotation:0}
:enddata
:endrule

rule:
plugin=vanillaSign
number=36
data:
JSON:{signContents0:"",blockState:{blockName:"minecraft:wall_sign",properties:{facing:"south"}},signContents2:"",signContents1:"",signContents3:"",rotation:0}
:enddata
:endrule

rule:
plugin=vanillaSign
number=37
data:
JSON:{signContents0:"",blockState:{blockName:"minecraft:wall_sign",properties:{facing:"south"}},signContents2:"",signContents1:"",signContents3:"",rotation:0}
:enddata
:endrule

rule:
plugin=vanillaSign
number=38
data:
JSON:{signContents0:"",blockState:{blockName:"minecraft:wall_sign",properties:{facing:"south"}},signContents2:"",signContents1:"",signContents3:"",rotation:0}
:enddata
:endrule

rule:
plugin=vanillaSign
number=39
data:
JSON:{signContents0:"",blockState:{blockName:"minecraft:wall_sign",properties:{facing:"south"}},signContents2:"",signContents1:"",signContents3:"",rotation:0}
:enddata
:endrule

rule:
plugin=vanillaBlocks
number=40
data:
JSON:{blockState:{blockName:"minecraft:stained_glass_pane",properties:{east:"false",color:"white",south:"false",north:"false",west:"false"}}}
:enddata
:endrule

rule:
plugin=vanillaBlocks
number=41
data:
JSON:{blockState:{blockName:"minecraft:birch_stairs",properties:{half:"top",shape:"straight",facing:"north"}}}
:enddata
:endrule

rule:
plugin=vanillaSign
number=42
data:
JSON:{signContents0:"",blockState:{blockName:"minecraft:wall_sign",properties:{facing:"south"}},signContents2:"",signContents1:"",signContents3:"",rotation:0}
:enddata
:endrule

rule:
plugin=vanillaBlocks
number=43
data:
JSON:{blockState:{blockName:"minecraft:birch_stairs",properties:{half:"bottom",shape:"straight",facing:"south"}}}
:enddata
:endrule

rule:
plugin=vanillaBlocks
number=44
data:
JSON:{blockState:{blockName:"minecraft:planks",properties:{variant:"birch"}}}
:enddata
:endrule

rule:
plugin=vanillaBlocks
number=45
data:
JSON:{blockState:{blockName:"minecraft:birch_fence",properties:{east:"false",south:"false",north:"false",west:"false"}}}
:enddata
:endrule

rule:
plugin=vanillaBlocks
number=46
data:
JSON:{blockState:{blockName:"minecraft:stained_hardened_clay",properties:{color:"white"}}}
:enddata
:endrule

rule:
plugin=inventory
number=47
data:
JSON:{blockState:{blockName:"minecraft:furnace",properties:{facing:"north"}},lootLevel:0,teData:{CookTime:0,ForgeData:{generatedInventory:1b},BurnTime:0,Items:[],id:"minecraft:furnace",CookTimeTotal:0,Lock:""},inventoryData:{length:0,inventoryContents:[]},legacyFeatures:0b}
:enddata
:endrule

rule:
plugin=inventory
number=48
data:
JSON:{blockState:{blockName:"minecraft:furnace",properties:{facing:"north"}},lootLevel:0,teData:{CookTime:0,ForgeData:{generatedInventory:1b},BurnTime:0,Items:[],id:"minecraft:furnace",CookTimeTotal:0,Lock:""},inventoryData:{length:0,inventoryContents:[]},legacyFeatures:0b}
:enddata
:endrule

rule:
plugin=vanillaBlocks
number=49
data:
JSON:{blockState:{blockName:"minecraft:stone_brick_stairs",properties:{half:"bottom",shape:"straight",facing:"west"}}}
:enddata
:endrule

rule:
plugin=vanillaBlocks
number=50
data:
JSON:{blockState:{blockName:"minecraft:stone_brick_stairs",properties:{half:"top",shape:"straight",facing:"east"}}}
:enddata
:endrule

rule:
plugin=vanillaBlocks
number=51
data:
JSON:{blockState:{blockName:"minecraft:stone_brick_stairs",properties:{half:"top",shape:"straight",facing:"west"}}}
:enddata
:endrule

rule:
plugin=vanillaBlocks
number=52
data:
JSON:{blockState:{blockName:"minecraft:stone_brick_stairs",properties:{half:"top",shape:"straight",facing:"north"}}}
:enddata
:endrule

rule:
plugin=vanillaBlocks
number=53
data:
JSON:{blockState:{blockName:"minecraft:stone_brick_stairs",properties:{half:"bottom",shape:"straight",facing:"east"}}}
:enddata
:endrule

rule:
plugin=vanillaBlocks
number=54
data:
JSON:{blockState:{blockName:"minecraft:stone_brick_stairs",properties:{half:"bottom",shape:"straight",facing:"north"}}}
:enddata
:endrule

rule:
plugin=vanillaBlocks
number=55
data:
JSON:{blockState:{blockName:"minecraft:stone_brick_stairs",properties:{half:"top",shape:"straight",facing:"south"}}}
:enddata
:endrule

rule:
plugin=vanillaBlocks
number=56
data:
JSON:{blockState:{blockName:"minecraft:stone_brick_stairs",properties:{half:"bottom",shape:"straight",facing:"south"}}}
:enddata
:endrule

rule:
plugin=vanillaBlocks
number=57
data:
JSON:{blockState:{blockName:"minecraft:stone_slab",properties:{half:"bottom",variant:"stone_brick"}}}
:enddata
:endrule

rule:
plugin=vanillaBlocks
number=58
data:
JSON:{blockState:{blockName:"minecraft:cobblestone_wall",properties:{east:"false",south:"false",north:"false",variant:"cobblestone",west:"false",up:"false"}}}
:enddata
:endrule

#### ENTITIES ####
