# Ancient Warfare Structure Template File
# Auto-generated structure template file. created on: 12/12/2023 at: 12:46:1
# Lines beginning with # denote comments

header:
version=2.11
name=SarkonidGenTownWallCorner
mods=
size=16,25,16
offset=15,5,15
:endheader

#### VALIDATION ####
validation:
type=ground
structureAuthor=TheOddlySeagull
survival=false
worldGenEnabled=false
unique=false
preserveBlocks=false
preventNaturalHostileSpawns=true
selectionWeight=1
clusterValue=1
minDuplicateDistance=1
dimensionWhiteList=true
dimensionList=
biomeGroupList=
biomeWhiteList=true
biomeList=
leveling=0
fill=0
border=0
blockSwap=false
territoryName=
biomeReplacement=minecraft:
minGenerationHeight=0
maxGenerationHeight=255
:endvalidation

#### LAYERS ####
layer: 0
1,1,1,1,1,1,1,1,1,1,1,1,1,1,1,1
1,1,1,1,1,1,1,1,1,1,1,1,1,1,1,1
1,1,1,1,1,1,1,1,1,1,1,1,1,1,1,1
1,1,1,1,1,1,1,1,1,1,1,1,1,1,1,1
1,1,1,1,1,1,1,1,1,1,1,1,1,1,1,1
1,1,1,1,1,1,1,1,1,1,1,1,1,1,1,1
1,1,1,1,1,1,1,1,1,1,1,1,1,1,1,1
1,1,1,1,1,1,1,1,1,1,1,1,1,1,1,1
1,1,1,1,1,1,1,1,1,1,1,1,1,1,1,1
1,1,1,1,1,1,1,1,1,1,1,1,1,1,1,1
1,1,1,1,1,1,1,1,1,1,1,1,1,1,1,1
1,1,1,1,1,1,1,1,1,1,1,1,1,1,1,1
1,1,1,1,1,1,1,1,1,1,1,1,1,1,1,1
1,1,1,1,1,1,1,1,1,1,1,1,1,1,1,1
1,1,1,1,1,1,1,1,1,1,1,1,1,1,1,1
1,1,1,1,1,1,1,1,1,1,1,1,1,1,1,1
:endlayer
layer: 1
1,1,1,1,1,1,1,1,1,1,1,1,1,1,1,1
1,1,1,1,1,1,1,1,1,1,1,1,1,1,1,1
1,1,1,1,1,1,1,1,1,1,1,1,1,1,1,1
1,1,1,1,1,1,1,1,1,1,1,1,1,1,1,1
1,1,1,1,1,1,1,1,1,1,1,1,1,1,1,1
1,1,1,1,1,1,1,1,1,1,1,1,1,1,1,1
1,1,1,1,1,1,1,1,1,1,1,1,1,1,1,1
1,1,1,1,1,1,1,1,1,1,1,1,1,1,1,1
1,1,1,1,1,1,1,1,1,1,1,1,1,1,1,1
1,1,1,1,1,1,1,1,1,1,1,1,1,1,1,1
1,1,1,1,1,1,1,1,1,1,1,1,1,1,1,1
1,1,1,1,1,1,1,1,1,1,1,1,1,1,1,1
1,1,1,1,1,1,1,1,1,1,1,1,1,1,1,1
1,1,1,1,1,1,1,1,1,1,1,1,1,1,1,1
1,1,1,1,1,1,1,1,1,1,1,1,1,1,1,1
1,1,1,1,1,1,1,1,1,1,1,1,1,1,1,1
:endlayer
layer: 2
1,1,1,1,1,1,1,1,1,1,1,1,1,1,1,1
1,1,1,1,1,1,1,1,1,1,1,1,1,1,1,1
1,1,1,1,1,1,1,1,1,1,1,1,1,1,1,1
1,1,1,1,1,1,1,1,1,1,1,1,1,1,1,1
1,1,1,1,1,1,1,1,1,1,1,1,1,1,1,1
1,1,1,1,1,1,1,1,1,1,1,1,1,1,1,1
1,1,1,1,1,1,1,1,1,1,1,1,1,1,1,1
1,1,1,1,1,1,1,1,1,1,1,1,1,1,1,1
1,1,1,1,1,1,1,1,1,1,1,1,1,1,1,1
1,1,1,1,1,1,1,1,1,1,1,1,1,1,1,1
1,1,1,1,1,1,1,1,1,1,1,1,1,1,1,1
1,1,1,1,1,1,1,1,1,1,1,1,1,1,1,1
1,1,1,1,1,1,1,1,1,1,1,1,1,1,1,1
1,1,1,1,1,1,1,1,1,1,1,1,1,1,1,1
1,1,1,1,1,1,1,1,1,1,1,1,1,1,1,1
1,1,1,1,1,1,1,1,1,1,1,1,1,1,1,1
:endlayer
layer: 3
1,1,1,1,1,1,1,1,1,1,1,1,2,2,2,2
1,1,1,1,1,1,1,1,1,1,1,1,2,2,2,2
1,1,1,1,1,1,1,1,1,1,1,1,2,2,2,2
1,1,1,1,1,1,1,1,1,1,1,1,2,2,2,2
1,1,1,1,1,1,1,1,1,1,1,1,2,2,2,2
1,1,1,1,1,1,1,1,1,1,1,1,2,2,2,2
1,1,1,1,1,1,1,1,1,1,1,1,2,2,2,2
1,1,1,1,1,1,1,1,1,1,1,1,1,1,2,2
1,1,1,1,1,1,1,1,1,1,1,1,1,1,2,2
1,1,1,1,1,1,1,1,1,1,1,1,1,1,2,2
1,1,1,1,1,1,1,1,1,1,1,1,1,1,2,2
1,1,1,1,1,1,1,1,1,1,1,1,1,1,2,2
2,2,2,2,2,2,2,1,1,1,1,1,1,1,2,2
2,2,2,2,2,2,2,1,1,1,1,1,1,1,2,2
2,2,2,2,2,2,2,2,2,2,2,2,2,2,2,2
2,2,2,2,2,2,2,2,2,2,2,2,2,2,2,2
:endlayer
layer: 4
2,3,1,1,4,1,1,1,1,1,1,1,2,2,2,2
5,3,1,1,4,1,1,1,1,1,1,1,2,2,2,2
1,1,1,1,4,1,1,1,1,1,1,1,2,2,2,2
1,1,1,1,4,1,1,1,1,1,1,1,2,2,2,2
6,6,6,6,4,1,1,1,1,1,1,1,2,2,2,2
1,1,1,1,1,1,1,1,1,1,1,1,2,2,2,2
1,1,1,1,1,1,1,1,1,1,1,1,2,2,2,2
1,1,1,1,1,1,1,1,1,1,1,1,1,1,2,2
1,1,1,1,1,1,1,1,1,1,1,1,1,1,2,2
1,1,1,1,1,1,1,1,1,1,1,1,1,1,2,2
1,1,1,1,1,1,1,1,1,1,1,1,1,1,2,2
1,1,1,1,1,1,1,1,1,1,1,1,1,1,2,2
2,2,2,2,2,2,2,1,1,1,1,1,1,1,2,2
2,2,2,2,2,2,2,1,1,1,1,1,1,1,2,2
2,2,2,2,2,2,2,2,2,2,2,2,2,2,2,2
2,2,2,2,2,2,2,2,2,2,2,2,2,2,2,2
:endlayer
layer: 5
0,0,0,0,0,6,6,1,0,0,0,1,7,0,0,0
0,0,0,0,0,1,1,1,0,0,0,1,0,0,0,0
0,0,0,0,0,8,1,1,0,0,0,1,0,0,0,0
0,0,0,0,0,1,1,1,0,0,0,1,0,0,0,0
0,0,0,0,0,1,1,1,0,0,0,1,0,0,0,0
4,1,8,1,1,7,0,7,0,0,0,1,0,0,0,0
4,1,1,1,1,0,0,0,0,0,0,1,6,6,6,0
1,1,1,1,1,7,0,0,0,0,0,1,1,1,3,0
0,0,0,0,0,0,0,0,9,10,0,0,7,1,3,0
0,0,0,0,0,0,0,0,0,11,0,0,0,1,3,0
0,0,0,0,0,0,0,0,0,0,0,0,12,1,3,0
1,1,1,1,1,1,1,1,0,0,0,0,0,1,3,0
7,0,0,0,0,0,4,1,7,0,0,0,7,1,3,0
0,0,0,0,0,0,4,1,1,1,1,1,1,1,3,0
0,0,0,0,0,0,5,5,5,5,5,5,5,5,3,0
0,0,0,0,0,0,0,0,0,0,0,0,0,0,0,0
:endlayer
layer: 6
0,0,0,0,0,0,0,1,0,0,0,1,7,0,0,0
0,0,0,0,0,6,6,1,0,0,0,1,0,0,0,0
0,0,0,0,0,1,1,1,0,0,0,1,0,0,0,0
0,0,0,0,0,8,1,1,0,0,0,1,0,0,0,0
0,0,0,0,0,1,1,1,0,0,0,1,0,0,0,0
0,4,1,8,1,7,0,7,0,0,0,1,0,0,0,0
0,4,1,1,1,0,0,0,0,0,0,1,0,0,0,0
1,1,1,1,1,7,0,0,0,0,0,1,1,1,0,0
0,0,0,0,0,0,0,0,0,0,9,0,7,1,0,0
0,0,0,0,0,0,0,0,0,11,10,0,0,1,0,0
0,0,0,0,0,0,0,0,0,0,0,0,0,1,0,0
1,1,1,1,1,1,1,1,0,0,0,0,0,1,0,0
7,0,0,0,0,0,0,1,7,0,0,0,7,1,0,0
0,0,0,0,0,0,0,1,1,1,1,1,1,1,0,0
0,0,0,0,0,0,0,0,0,0,0,0,0,0,0,0
0,0,0,0,0,0,0,0,0,0,0,0,0,0,0,0
:endlayer
layer: 7
0,0,0,0,0,0,0,1,0,0,0,11,7,0,0,0
0,0,0,0,0,0,0,1,0,0,0,11,0,0,0,0
0,0,0,0,0,6,6,1,0,0,0,11,0,0,0,0
0,0,0,0,0,1,1,1,0,0,0,11,0,0,0,0
0,0,0,0,0,8,1,1,0,0,0,11,0,0,0,0
0,0,4,1,8,1,10,13,0,0,0,11,0,0,0,0
0,0,4,1,1,10,10,14,0,0,0,11,0,0,0,0
1,1,1,1,1,15,14,14,14,14,16,1,1,11,0,0
0,0,0,0,0,0,0,14,0,0,0,0,7,1,0,0
0,0,0,0,0,0,0,14,0,11,0,0,0,1,0,0
0,0,0,0,0,0,0,17,0,10,9,0,18,11,0,0
11,11,11,11,11,11,11,1,0,0,0,0,0,1,0,0
7,0,0,0,0,0,0,1,7,0,19,0,7,1,0,0
0,0,0,0,0,0,0,11,1,1,11,1,1,11,0,0
0,0,0,0,0,0,0,0,0,0,0,0,0,0,0,0
0,0,0,0,0,0,0,0,0,0,0,0,0,0,0,0
:endlayer
layer: 8
0,0,0,0,0,0,0,1,0,0,0,20,15,0,0,0
0,0,0,0,0,0,0,1,0,0,0,20,0,0,0,0
0,0,0,0,0,0,0,1,0,0,0,20,15,0,0,0
0,0,0,0,0,6,6,1,0,0,0,20,0,0,0,0
0,0,0,0,0,1,1,1,0,0,0,20,0,0,0,0
0,0,0,4,1,1,1,1,0,0,0,20,15,0,0,0
0,0,0,4,1,1,1,1,0,19,0,20,0,0,0,0
1,1,1,1,1,1,1,11,20,20,20,20,20,20,0,0
0,0,0,0,0,0,0,20,14,14,0,14,8,20,0,0
0,0,0,0,0,0,18,20,10,11,0,0,14,20,0,0
0,0,0,0,0,0,0,20,9,0,0,0,14,20,0,0
20,20,20,20,20,20,20,20,14,0,0,0,14,20,0,0
13,0,13,0,0,13,0,20,8,14,14,14,8,20,0,0
0,0,0,0,0,0,0,20,20,20,20,20,20,20,0,0
0,0,0,0,0,0,0,0,0,0,0,0,0,0,0,0
0,0,0,0,0,0,0,0,0,0,0,0,0,0,0,0
:endlayer
layer: 9
0,0,0,0,0,0,0,1,1,1,1,1,9,0,0,0
0,0,0,0,0,0,0,1,1,1,1,1,9,0,0,0
0,0,0,0,0,0,0,1,1,1,1,1,9,0,0,0
0,0,0,0,0,0,0,1,1,1,1,1,9,0,0,0
0,0,0,0,0,6,6,1,1,1,1,1,9,0,0,0
0,0,0,0,4,1,1,1,1,1,1,1,9,0,0,0
0,0,0,0,4,1,1,1,1,1,1,1,9,0,0,0
1,1,1,1,1,1,1,1,1,1,1,1,6,1,0,0
1,1,1,1,1,1,1,1,9,10,10,1,1,3,0,0
1,1,1,1,1,1,1,1,0,11,0,1,1,1,0,0
1,1,1,1,1,1,1,1,0,0,0,1,1,1,0,0
1,1,1,1,1,1,1,1,1,1,1,1,1,1,0,0
9,9,9,9,9,9,9,4,1,1,1,1,1,3,0,0
0,0,0,0,0,0,0,1,5,1,1,1,5,1,0,0
0,0,0,0,0,0,0,0,0,0,0,0,0,0,0,0
0,0,0,0,0,0,0,0,0,0,0,0,0,0,0,0
:endlayer
layer: 10
0,0,0,0,0,0,0,21,0,0,0,8,0,0,0,0
0,0,0,0,0,0,0,22,0,0,0,23,0,0,0,0
0,0,0,0,0,0,0,22,0,0,18,8,0,0,0,0
0,0,0,0,0,0,0,22,0,0,0,23,0,0,0,0
0,0,0,0,0,0,0,22,0,0,24,23,0,0,0,0
0,0,0,0,0,0,0,0,0,0,18,8,0,0,0,0
0,0,0,0,0,0,0,0,0,0,0,23,0,0,0,0
23,22,22,22,22,0,0,1,1,0,0,1,0,1,0,0
0,0,0,0,0,0,0,1,0,0,0,25,9,0,0,0
0,0,0,0,0,0,0,1,0,11,9,0,0,1,0,0
0,0,19,26,0,19,0,1,0,0,10,0,27,3,0,0
8,21,8,21,21,8,21,1,0,0,0,0,0,1,0,0
0,0,0,0,0,0,0,0,9,0,28,0,9,0,0,0
0,0,0,0,0,0,0,1,0,1,5,1,0,1,0,0
0,0,0,0,0,0,0,0,0,0,0,0,0,0,0,0
0,0,0,0,0,0,0,0,0,0,0,0,0,0,0,0
:endlayer
layer: 11
0,0,0,0,0,0,0,0,0,0,0,9,0,0,0,0
0,0,0,0,0,0,0,0,0,0,0,0,0,0,0,0
0,0,0,0,0,0,0,0,0,0,0,9,0,0,0,0
0,0,0,0,0,0,0,0,0,0,0,0,0,0,0,0
0,0,0,0,0,0,0,0,0,0,0,0,0,0,0,0
0,0,0,0,0,0,0,0,0,0,0,9,0,0,0,0
0,0,0,0,0,0,0,0,0,0,0,0,0,0,0,0
0,0,0,0,0,0,0,1,1,0,0,1,0,1,0,0
0,0,0,0,0,0,0,1,0,0,0,0,0,0,0,0
0,0,0,0,0,0,0,1,0,11,0,0,0,1,0,0
0,0,0,0,0,0,0,1,10,9,0,0,0,0,0,0
9,0,9,0,0,9,0,1,0,0,0,0,0,1,0,0
0,0,0,0,0,0,0,0,0,0,0,0,0,0,0,0
0,0,0,0,0,0,0,1,0,1,0,1,0,1,0,0
0,0,0,0,0,0,0,0,0,0,0,0,0,0,0,0
0,0,0,0,0,0,0,0,0,0,0,0,0,0,0,0
:endlayer
layer: 12
0,0,0,0,0,0,0,0,0,0,0,0,0,0,0,0
0,0,0,0,0,0,0,0,0,0,0,0,0,0,0,0
0,0,0,0,0,0,0,0,0,0,0,0,0,0,0,0
0,0,0,0,0,0,0,0,0,0,0,0,0,0,0,0
0,0,0,0,0,0,0,0,0,0,0,0,0,0,0,0
0,0,0,0,0,0,0,0,0,0,0,0,0,0,0,0
0,0,0,0,0,0,0,0,0,0,0,0,0,0,0,0
0,0,0,0,0,0,0,1,1,1,1,1,29,1,0,0
0,0,0,0,0,0,0,1,10,0,0,0,0,30,0,0
0,0,0,0,0,0,0,1,9,11,0,0,0,1,0,0
0,0,0,0,0,0,0,1,0,0,0,0,0,30,0,0
0,0,0,0,0,0,0,1,0,0,0,0,0,1,0,0
0,0,0,0,0,0,0,31,0,0,0,0,0,30,0,0
0,0,0,0,0,0,0,1,32,1,32,1,32,1,0,0
0,0,0,0,0,0,0,0,0,0,0,0,0,0,0,0
0,0,0,0,0,0,0,0,0,0,0,0,0,0,0,0
:endlayer
layer: 13
0,0,0,0,0,0,0,0,0,0,0,0,0,0,0,0
0,0,0,0,0,0,0,0,0,0,0,0,0,0,0,0
0,0,0,0,0,0,0,0,0,0,0,0,0,0,0,0
0,0,0,0,0,0,0,0,0,0,0,0,0,0,0,0
0,0,0,0,0,0,0,0,0,0,0,0,0,0,0,0
0,0,0,0,0,0,0,0,0,0,0,0,0,0,0,0
0,0,0,0,0,0,0,19,17,0,17,0,17,0,0,0
0,0,0,0,0,0,18,1,1,1,1,1,1,1,0,0
0,0,0,0,0,0,16,1,0,9,10,0,0,1,15,0
0,0,0,0,0,0,0,1,0,11,0,0,0,1,0,0
0,0,0,0,0,0,16,1,33,0,0,0,18,1,15,0
0,0,0,0,0,0,0,1,0,0,0,0,0,1,0,0
0,0,0,0,0,0,16,1,0,0,19,0,0,1,15,0
0,0,0,0,0,0,0,1,1,1,1,1,1,1,0,0
0,0,0,0,0,0,0,0,13,0,13,0,13,0,0,0
0,0,0,0,0,0,0,0,0,0,0,0,0,0,0,0
:endlayer
layer: 14
0,0,0,0,0,0,0,0,0,0,0,0,0,0,0,0
0,0,0,0,0,0,0,0,0,0,0,0,0,0,0,0
0,0,0,0,0,0,0,0,0,0,0,0,0,0,0,0
0,0,0,0,0,0,0,0,0,0,0,0,0,0,0,0
0,0,0,0,0,0,0,0,0,0,0,0,0,0,0,0
0,0,0,0,0,0,0,0,0,0,0,0,0,0,0,0
0,0,0,0,0,0,0,22,22,22,22,22,22,22,0,0
0,0,0,0,0,0,22,20,20,20,20,20,20,20,22,0
0,0,0,0,0,0,22,20,0,0,0,0,0,20,22,0
0,0,0,0,0,0,22,20,0,11,9,0,0,20,22,0
0,0,0,0,0,0,22,20,0,0,10,0,0,20,22,0
0,0,0,0,0,0,22,20,0,0,0,0,0,20,22,0
0,0,0,0,0,0,22,20,0,0,0,0,0,20,22,0
0,0,0,0,0,0,22,20,20,20,20,20,20,20,22,0
0,0,0,0,0,0,0,22,22,22,22,22,22,22,0,0
0,0,0,0,0,0,0,0,0,0,0,0,0,0,0,0
:endlayer
layer: 15
0,0,0,0,0,0,0,0,0,0,0,0,0,0,0,0
0,0,0,0,0,0,0,0,0,0,0,0,0,0,0,0
0,0,0,0,0,0,0,0,0,0,0,0,0,0,0,0
0,0,0,0,0,0,0,0,0,0,0,0,0,0,0,0
0,0,0,0,0,0,0,0,0,0,0,0,0,0,0,0
0,0,0,0,0,0,0,0,0,0,0,0,0,0,0,0
0,0,0,0,0,0,0,0,0,0,0,0,0,0,0,0
0,0,0,0,0,0,0,11,1,1,11,1,1,11,0,0
0,0,0,0,0,0,0,1,10,0,0,1,1,1,0,0
0,0,0,0,0,0,0,1,10,11,0,1,1,1,0,0
0,0,0,0,0,0,0,11,10,9,0,1,1,11,0,0
0,0,0,0,0,0,0,1,1,1,1,1,1,1,0,0
0,0,0,0,0,0,0,1,1,1,1,1,1,1,0,0
0,0,0,0,0,0,0,11,1,1,11,1,1,11,0,0
0,0,0,0,0,0,0,0,0,0,0,0,0,0,0,0
0,0,0,0,0,0,0,0,0,0,0,0,0,0,0,0
:endlayer
layer: 16
0,0,0,0,0,0,0,0,0,0,0,0,0,0,0,0
0,0,0,0,0,0,0,0,0,0,0,0,0,0,0,0
0,0,0,0,0,0,0,0,0,0,0,0,0,0,0,0
0,0,0,0,0,0,0,0,0,0,0,0,0,0,0,0
0,0,0,0,0,0,0,0,0,0,0,0,0,0,0,0
0,0,0,0,0,0,0,0,0,0,0,0,0,0,0,0
0,0,0,0,0,0,0,0,0,0,0,0,0,0,0,0
0,0,0,0,0,0,0,1,6,6,1,6,6,1,0,0
0,0,0,0,0,0,0,4,0,9,10,0,34,3,0,0
0,0,0,0,0,0,0,4,0,11,0,0,0,3,0,0
0,0,0,0,0,0,0,1,0,0,0,0,35,1,0,0
0,0,0,0,0,0,0,4,0,0,0,0,0,3,0,0
0,0,0,0,0,0,0,4,36,0,0,0,37,3,0,0
0,0,0,0,0,0,0,1,5,5,1,5,5,1,0,0
0,0,0,0,0,0,0,0,0,0,0,0,0,0,0,0
0,0,0,0,0,0,0,0,0,0,0,0,0,0,0,0
:endlayer
layer: 17
0,0,0,0,0,0,0,0,0,0,0,0,0,0,0,0
0,0,0,0,0,0,0,0,0,0,0,0,0,0,0,0
0,0,0,0,0,0,0,0,0,0,0,0,0,0,0,0
0,0,0,0,0,0,0,0,0,0,0,0,0,0,0,0
0,0,0,0,0,0,0,0,0,0,0,0,0,0,0,0
0,0,0,0,0,0,0,0,0,0,0,0,0,0,0,0
0,0,0,0,0,0,0,0,0,0,0,0,0,0,0,0
0,0,0,0,0,0,0,1,0,0,1,0,0,1,0,0
0,0,0,0,0,0,0,0,0,0,0,0,0,0,0,0
0,0,0,0,0,0,0,0,0,11,9,0,0,0,0,0
0,0,0,0,0,0,0,1,0,0,10,0,0,1,0,0
0,0,0,0,0,0,0,0,0,0,0,0,0,0,0,0
0,0,0,0,0,0,0,0,0,0,0,0,0,0,0,0
0,0,0,0,0,0,0,1,0,0,1,0,0,1,0,0
0,0,0,0,0,0,0,0,0,0,0,0,0,0,0,0
0,0,0,0,0,0,0,0,0,0,0,0,0,0,0,0
:endlayer
layer: 18
0,0,0,0,0,0,0,0,0,0,0,0,0,0,0,0
0,0,0,0,0,0,0,0,0,0,0,0,0,0,0,0
0,0,0,0,0,0,0,0,0,0,0,0,0,0,0,0
0,0,0,0,0,0,0,0,0,0,0,0,0,0,0,0
0,0,0,0,0,0,0,0,0,0,0,0,0,0,0,0
0,0,0,0,0,0,0,0,0,0,0,0,0,0,0,0
0,0,0,0,0,0,0,0,0,0,0,0,0,0,0,0
0,0,0,0,0,0,0,1,0,0,1,0,0,1,0,0
0,0,0,0,0,0,0,0,0,0,0,0,0,0,0,0
0,0,0,0,0,0,0,0,0,11,0,0,0,0,0,0
0,0,0,0,0,0,0,1,10,9,0,0,0,1,0,0
0,0,0,0,0,0,0,0,0,0,0,0,0,0,0,0
0,0,0,0,0,0,0,0,0,0,0,0,0,0,0,0
0,0,0,0,0,0,0,1,0,0,1,0,0,1,0,0
0,0,0,0,0,0,0,0,0,0,0,0,0,0,0,0
0,0,0,0,0,0,0,0,0,0,0,0,0,0,0,0
:endlayer
layer: 19
0,0,0,0,0,0,0,0,0,0,0,0,0,0,0,0
0,0,0,0,0,0,0,0,0,0,0,0,0,0,0,0
0,0,0,0,0,0,0,0,0,0,0,0,0,0,0,0
0,0,0,0,0,0,0,0,0,0,0,0,0,0,0,0
0,0,0,0,0,0,0,0,0,0,0,0,0,0,0,0
0,0,0,0,0,0,0,0,0,0,0,0,0,0,0,0
0,0,0,0,0,0,0,29,0,0,29,0,0,29,0,0
0,0,0,0,0,0,31,1,15,16,1,15,16,1,30,0
0,0,0,0,0,0,0,13,10,0,38,0,0,13,0,0
0,0,0,0,0,0,0,17,9,11,0,0,0,17,0,0
0,0,0,0,0,0,31,1,33,0,0,0,18,1,30,0
0,0,0,0,0,0,0,13,0,0,0,0,0,13,0,0
0,0,0,0,0,0,0,17,0,0,19,0,0,17,0,0
0,0,0,0,0,0,31,1,15,16,1,15,16,1,30,0
0,0,0,0,0,0,0,32,0,0,32,0,0,32,0,0
0,0,0,0,0,0,0,0,0,0,0,0,0,0,0,0
:endlayer
layer: 20
0,0,0,0,0,0,0,0,0,0,0,0,0,0,0,0
0,0,0,0,0,0,0,0,0,0,0,0,0,0,0,0
0,0,0,0,0,0,0,0,0,0,0,0,0,0,0,0
0,0,0,0,0,0,0,0,0,0,0,0,0,0,0,0
0,0,0,0,0,0,0,0,0,0,0,0,0,0,0,0
0,0,0,0,0,0,0,0,0,0,0,0,0,0,0,0
0,0,0,0,0,0,0,9,9,9,9,9,9,9,0,0
0,0,0,0,0,0,9,11,11,11,11,11,11,11,9,0
0,0,0,0,0,0,9,11,0,9,10,1,1,11,9,0
0,0,0,0,0,0,9,11,0,8,10,1,1,11,9,0
0,0,0,0,0,0,9,11,0,0,10,1,1,11,9,0
0,0,0,0,0,0,9,11,1,1,1,1,1,11,9,0
0,0,0,0,0,0,9,11,1,1,1,1,1,11,9,0
0,0,0,0,0,0,9,11,11,11,11,11,11,11,9,0
0,0,0,0,0,0,0,9,9,9,9,9,9,9,0,0
0,0,0,0,0,0,0,0,0,0,0,0,0,0,0,0
:endlayer
layer: 21
0,0,0,0,0,0,0,0,0,0,0,0,0,0,0,0
0,0,0,0,0,0,0,0,0,0,0,0,0,0,0,0
0,0,0,0,0,0,0,0,0,0,0,0,0,0,0,0
0,0,0,0,0,0,0,0,0,0,0,0,0,0,0,0
0,0,0,0,0,0,0,0,0,0,0,0,0,0,0,0
0,0,0,0,0,0,0,0,0,0,0,0,0,0,0,0
0,0,0,0,0,0,0,0,0,0,0,0,0,0,0,0
0,0,0,0,0,0,0,8,22,0,22,0,22,8,0,0
0,0,0,0,0,0,0,22,0,0,0,39,7,22,0,0
0,0,0,0,0,0,0,0,0,7,0,40,39,0,0,0
0,0,0,0,0,0,0,22,0,0,41,0,0,22,0,0
0,0,0,0,0,0,0,0,39,42,0,0,39,0,0,0
0,0,0,0,0,0,0,22,7,39,0,39,7,22,0,0
0,0,0,0,0,0,0,8,22,0,22,0,22,8,0,0
0,0,0,0,0,0,0,0,0,0,0,0,0,0,0,0
0,0,0,0,0,0,0,0,0,0,0,0,0,0,0,0
:endlayer
layer: 22
0,0,0,0,0,0,0,0,0,0,0,0,0,0,0,0
0,0,0,0,0,0,0,0,0,0,0,0,0,0,0,0
0,0,0,0,0,0,0,0,0,0,0,0,0,0,0,0
0,0,0,0,0,0,0,0,0,0,0,0,0,0,0,0
0,0,0,0,0,0,0,0,0,0,0,0,0,0,0,0
0,0,0,0,0,0,0,0,0,0,0,0,0,0,0,0
0,0,0,0,0,0,0,0,0,0,0,0,0,0,0,0
0,0,0,0,0,0,0,0,0,0,0,0,0,0,0,0
0,0,0,0,0,0,0,0,0,0,0,0,7,0,0,0
0,0,0,0,0,0,0,0,0,7,0,0,0,0,0,0
0,0,0,0,0,0,0,0,0,0,0,0,0,0,0,0
0,0,0,0,0,0,0,0,0,0,0,0,0,0,0,0
0,0,0,0,0,0,0,0,7,0,0,0,7,0,0,0
0,0,0,0,0,0,0,0,0,0,0,0,0,0,0,0
0,0,0,0,0,0,0,0,0,0,0,0,0,0,0,0
0,0,0,0,0,0,0,0,0,0,0,0,0,0,0,0
:endlayer
layer: 23
0,0,0,0,0,0,0,0,0,0,0,0,0,0,0,0
0,0,0,0,0,0,0,0,0,0,0,0,0,0,0,0
0,0,0,0,0,0,0,0,0,0,0,0,0,0,0,0
0,0,0,0,0,0,0,0,0,0,0,0,0,0,0,0
0,0,0,0,0,0,0,0,0,0,0,0,0,0,0,0
0,0,0,0,0,0,0,0,0,0,0,0,0,0,0,0
0,0,0,0,0,0,0,0,0,0,0,0,0,0,0,0
0,0,0,0,0,0,0,0,0,0,0,0,0,0,0,0
0,0,0,0,0,0,0,0,0,0,0,0,7,0,0,0
0,0,0,0,0,0,0,0,0,7,0,0,0,0,0,0
0,0,0,0,0,0,0,0,0,0,0,0,0,0,0,0
0,0,0,0,0,0,0,0,0,0,0,0,0,0,0,0
0,0,0,0,0,0,0,0,7,0,0,0,7,0,0,0
0,0,0,0,0,0,0,0,0,0,0,0,0,0,0,0
0,0,0,0,0,0,0,0,0,0,0,0,0,0,0,0
0,0,0,0,0,0,0,0,0,0,0,0,0,0,0,0
:endlayer
layer: 24
0,0,0,0,0,0,0,0,0,0,0,0,0,0,0,0
0,0,0,0,0,0,0,0,0,0,0,0,0,0,0,0
0,0,0,0,0,0,0,0,0,0,0,0,0,0,0,0
0,0,0,0,0,0,0,0,0,0,0,0,0,0,0,0
0,0,0,0,0,0,0,0,0,0,0,0,0,0,0,0
0,0,0,0,0,0,0,0,0,0,0,0,0,0,0,0
0,0,0,0,0,0,0,0,0,0,0,0,0,0,0,0
0,0,0,0,0,0,0,0,0,0,0,0,0,0,0,0
0,0,0,0,0,0,0,0,9,9,9,9,9,0,0,0
0,0,0,0,0,0,0,0,9,43,43,43,9,0,0,0
0,0,0,0,0,0,0,0,9,44,44,44,9,0,0,0
0,0,0,0,0,0,0,0,9,43,43,43,9,0,0,0
0,0,0,0,0,0,0,0,9,9,9,9,9,0,0,0
0,0,0,0,0,0,0,0,0,0,0,0,0,0,0,0
0,0,0,0,0,0,0,0,0,0,0,0,0,0,0,0
0,0,0,0,0,0,0,0,0,0,0,0,0,0,0,0
:endlayer

#### RULES ####
rule:
plugin=vanillaBlocks
number=1
data:
JSON:{blockState:{blockName:"minecraft:sandstone",properties:{type:"sandstone"}}}
:enddata
:endrule

rule:
plugin=vanillaBlocks
number=2
data:
JSON:{blockState:{blockName:"minecraft:sand",properties:{variant:"sand"}}}
:enddata
:endrule

rule:
plugin=vanillaBlocks
number=3
data:
JSON:{blockState:{blockName:"minecraft:sandstone_stairs",properties:{half:"bottom",shape:"straight",facing:"west"}}}
:enddata
:endrule

rule:
plugin=vanillaBlocks
number=4
data:
JSON:{blockState:{blockName:"minecraft:sandstone_stairs",properties:{half:"bottom",shape:"straight",facing:"east"}}}
:enddata
:endrule

rule:
plugin=vanillaBlocks
number=5
data:
JSON:{blockState:{blockName:"minecraft:sandstone_stairs",properties:{half:"bottom",shape:"straight",facing:"north"}}}
:enddata
:endrule

rule:
plugin=vanillaBlocks
number=6
data:
JSON:{blockState:{blockName:"minecraft:sandstone_stairs",properties:{half:"bottom",shape:"straight",facing:"south"}}}
:enddata
:endrule

rule:
plugin=vanillaBlocks
number=7
data:
JSON:{blockState:{blockName:"minecraft:birch_fence",properties:{east:"false",south:"false",north:"false",west:"false"}}}
:enddata
:endrule

rule:
plugin=vanillaBlocks
number=8
data:
JSON:{blockState:{blockName:"minecraft:red_sandstone",properties:{type:"smooth_red_sandstone"}}}
:enddata
:endrule

rule:
plugin=vanillaBlocks
number=9
data:
JSON:{blockState:{blockName:"minecraft:stone_slab",properties:{half:"bottom",variant:"sandstone"}}}
:enddata
:endrule

rule:
plugin=vanillaBlocks
number=10
data:
JSON:{blockState:{blockName:"minecraft:stone_slab",properties:{half:"top",variant:"sandstone"}}}
:enddata
:endrule

rule:
plugin=vanillaBlocks
number=11
data:
JSON:{blockState:{blockName:"minecraft:stained_hardened_clay",properties:{color:"red"}}}
:enddata
:endrule

rule:
plugin=blockTile
number=12
data:
JSON:{blockState:{blockName:"ancientwarfarestructure:advanced_loot_chest",properties:{facing:"west"}},teData:{lootSettings:{lootRolls:1,splashPotion:0b,hasMessage:0b,hasLoot:1b,lootTableName:"ancientwarfare:chests/sarkonid",spawnEntity:0b,entity:"minecraft:"},Items:[],id:"ancientwarfarestructure:advanced_loot_chest_tile",Lock:""}}
:enddata
:endrule

rule:
plugin=vanillaBlocks
number=13
data:
JSON:{blockState:{blockName:"minecraft:red_sandstone_stairs",properties:{half:"top",shape:"straight",facing:"north"}}}
:enddata
:endrule

rule:
plugin=vanillaBlocks
number=14
data:
JSON:{blockState:{blockName:"minecraft:stone_slab2",properties:{half:"top",variant:"red_sandstone"}}}
:enddata
:endrule

rule:
plugin=vanillaBlocks
number=15
data:
JSON:{blockState:{blockName:"minecraft:red_sandstone_stairs",properties:{half:"top",shape:"straight",facing:"west"}}}
:enddata
:endrule

rule:
plugin=vanillaBlocks
number=16
data:
JSON:{blockState:{blockName:"minecraft:red_sandstone_stairs",properties:{half:"top",shape:"straight",facing:"east"}}}
:enddata
:endrule

rule:
plugin=vanillaBlocks
number=17
data:
JSON:{blockState:{blockName:"minecraft:red_sandstone_stairs",properties:{half:"top",shape:"straight",facing:"south"}}}
:enddata
:endrule

rule:
plugin=vanillaBlocks
number=18
data:
JSON:{blockState:{blockName:"minecraft:torch",properties:{facing:"west"}}}
:enddata
:endrule

rule:
plugin=vanillaBlocks
number=19
data:
JSON:{blockState:{blockName:"minecraft:torch",properties:{facing:"north"}}}
:enddata
:endrule

rule:
plugin=vanillaBlocks
number=20
data:
JSON:{blockState:{blockName:"minecraft:hardened_clay"}}
:enddata
:endrule

rule:
plugin=vanillaBlocks
number=21
data:
JSON:{blockState:{blockName:"minecraft:red_sandstone_stairs",properties:{half:"bottom",shape:"straight",facing:"north"}}}
:enddata
:endrule

rule:
plugin=vanillaBlocks
number=22
data:
JSON:{blockState:{blockName:"minecraft:stone_slab2",properties:{half:"bottom",variant:"red_sandstone"}}}
:enddata
:endrule

rule:
plugin=vanillaBlocks
number=23
data:
JSON:{blockState:{blockName:"minecraft:red_sandstone_stairs",properties:{half:"bottom",shape:"straight",facing:"west"}}}
:enddata
:endrule

rule:
plugin=blockTile
number=24
data:
JSON:{blockState:{blockName:"ancientwarfarestructure:advanced_spawner",properties:{transparent:"true"}},teData:{id:"ancientwarfarestructure:advanced_spawner_tile",spawnerSettings:{minDelay:10,spawnDelay:1,lightSensitive:0b,spawnGroups:[{settingsList:[{remainingSpawnCount:1,hostile:1b,customTag:{ArmorDropChances:[0.085f,0.085f,0.085f,0.085f],hasCustomEquipment:0b,ArmorItems:[{},{},{},{}],skinSettings:{npcTypeName:"custom",skinTypeSelected:"default"},HandDropChances:[0.085f,0.085f],factionName:"sarkonid",HandItems:[{id:"minecraft:bow",Count:1b,Damage:0s},{}]},maxToSpawn:1,entityId:"ancientwarfarenpc:faction.archer",minToSpawn:1}],groupWeight:1}],playerRange:32,respondToRedstone:0b,inventory:{Size:9,Items:[]},spawnRange:0,transparent:1b,maxDelay:10,spawnYOffset:0,xpToDrop:0,mobRange:0,debugMode:0b,maxNearbyMonsters:0}}}
:enddata
:endrule

rule:
plugin=blockTile
number=25
data:
JSON:{blockState:{blockName:"ancientwarfarestructure:advanced_loot_chest",properties:{facing:"west"}},teData:{lootSettings:{lootRolls:1,splashPotion:0b,hasMessage:0b,hasLoot:1b,lootTableName:"ancientwarfare:chests/sarkonid",spawnEntity:0b,entity:"minecraft:"},Items:[],id:"ancientwarfarestructure:advanced_loot_chest_tile",Lock:""}}
:enddata
:endrule

rule:
plugin=blockTile
number=26
data:
JSON:{blockState:{blockName:"ancientwarfarestructure:advanced_spawner",properties:{transparent:"true"}},teData:{id:"ancientwarfarestructure:advanced_spawner_tile",spawnerSettings:{minDelay:10,spawnDelay:10,lightSensitive:0b,spawnGroups:[{settingsList:[{remainingSpawnCount:1,hostile:1b,customTag:{ArmorDropChances:[0.085f,0.085f,0.085f,0.085f],hasCustomEquipment:0b,ArmorItems:[{},{},{},{}],skinSettings:{npcTypeName:"custom",skinTypeSelected:"default"},HandDropChances:[0.085f,0.085f],factionName:"sarkonid",HandItems:[{id:"minecraft:bow",Count:1b,Damage:0s},{}]},maxToSpawn:1,entityId:"ancientwarfarenpc:faction.archer",minToSpawn:1}],groupWeight:1}],playerRange:32,respondToRedstone:0b,inventory:{Size:9,Items:[]},spawnRange:0,transparent:1b,maxDelay:10,spawnYOffset:0,xpToDrop:0,mobRange:0,debugMode:0b,maxNearbyMonsters:0}}}
:enddata
:endrule

rule:
plugin=blockTile
number=27
data:
JSON:{blockState:{blockName:"ancientwarfarestructure:advanced_spawner",properties:{transparent:"true"}},teData:{id:"ancientwarfarestructure:advanced_spawner_tile",spawnerSettings:{minDelay:10,spawnDelay:9,lightSensitive:0b,spawnGroups:[{settingsList:[{remainingSpawnCount:1,hostile:1b,customTag:{ArmorDropChances:[0.085f,0.085f,0.085f,0.085f],hasCustomEquipment:0b,ArmorItems:[{},{},{},{}],skinSettings:{npcTypeName:"custom",skinTypeSelected:"default"},HandDropChances:[0.085f,0.085f],factionName:"sarkonid",HandItems:[{id:"minecraft:bow",Count:1b,Damage:0s},{}]},maxToSpawn:1,entityId:"ancientwarfarenpc:faction.archer",minToSpawn:1}],groupWeight:1}],playerRange:32,respondToRedstone:0b,inventory:{Size:9,Items:[]},spawnRange:0,transparent:1b,maxDelay:10,spawnYOffset:0,xpToDrop:0,mobRange:0,debugMode:0b,maxNearbyMonsters:0}}}
:enddata
:endrule

rule:
plugin=blockTile
number=28
data:
JSON:{blockState:{blockName:"ancientwarfarestructure:advanced_spawner",properties:{transparent:"true"}},teData:{id:"ancientwarfarestructure:advanced_spawner_tile",spawnerSettings:{minDelay:10,spawnDelay:7,lightSensitive:0b,spawnGroups:[{settingsList:[{remainingSpawnCount:1,hostile:1b,customTag:{ArmorDropChances:[0.085f,0.085f,0.085f,0.085f],hasCustomEquipment:0b,ArmorItems:[{},{},{},{}],skinSettings:{npcTypeName:"custom",skinTypeSelected:"default"},HandDropChances:[0.085f,0.085f],factionName:"sarkonid",HandItems:[{id:"minecraft:bow",Count:1b,Damage:0s},{}]},maxToSpawn:1,entityId:"ancientwarfarenpc:faction.archer",minToSpawn:1}],groupWeight:1}],playerRange:32,respondToRedstone:0b,inventory:{Size:9,Items:[]},spawnRange:0,transparent:1b,maxDelay:10,spawnYOffset:0,xpToDrop:0,mobRange:0,debugMode:0b,maxNearbyMonsters:0}}}
:enddata
:endrule

rule:
plugin=vanillaBlocks
number=29
data:
JSON:{blockState:{blockName:"minecraft:sandstone_stairs",properties:{half:"top",shape:"straight",facing:"south"}}}
:enddata
:endrule

rule:
plugin=vanillaBlocks
number=30
data:
JSON:{blockState:{blockName:"minecraft:sandstone_stairs",properties:{half:"top",shape:"straight",facing:"west"}}}
:enddata
:endrule

rule:
plugin=vanillaBlocks
number=31
data:
JSON:{blockState:{blockName:"minecraft:sandstone_stairs",properties:{half:"top",shape:"straight",facing:"east"}}}
:enddata
:endrule

rule:
plugin=vanillaBlocks
number=32
data:
JSON:{blockState:{blockName:"minecraft:sandstone_stairs",properties:{half:"top",shape:"straight",facing:"north"}}}
:enddata
:endrule

rule:
plugin=vanillaBlocks
number=33
data:
JSON:{blockState:{blockName:"minecraft:torch",properties:{facing:"east"}}}
:enddata
:endrule

rule:
plugin=blockTile
number=34
data:
JSON:{blockState:{blockName:"ancientwarfarestructure:advanced_spawner",properties:{transparent:"true"}},teData:{id:"ancientwarfarestructure:advanced_spawner_tile",spawnerSettings:{minDelay:10,spawnDelay:2,lightSensitive:0b,spawnGroups:[{settingsList:[{remainingSpawnCount:1,hostile:1b,customTag:{ArmorDropChances:[0.085f,0.085f,0.085f,0.085f],hasCustomEquipment:0b,ArmorItems:[{},{},{},{}],skinSettings:{npcTypeName:"custom",skinTypeSelected:"default"},HandDropChances:[0.085f,0.085f],factionName:"sarkonid",HandItems:[{id:"minecraft:bow",Count:1b,Damage:0s},{}]},maxToSpawn:1,entityId:"ancientwarfarenpc:faction.archer",minToSpawn:1}],groupWeight:1}],playerRange:32,respondToRedstone:0b,inventory:{Size:9,Items:[]},spawnRange:0,transparent:1b,maxDelay:10,spawnYOffset:0,xpToDrop:0,mobRange:0,debugMode:0b,maxNearbyMonsters:0}}}
:enddata
:endrule

rule:
plugin=blockTile
number=35
data:
JSON:{blockState:{blockName:"ancientwarfarestructure:advanced_loot_chest",properties:{facing:"west"}},teData:{lootSettings:{lootRolls:1,splashPotion:0b,hasMessage:0b,hasLoot:1b,lootTableName:"ancientwarfare:chests/ammo_cannon",spawnEntity:0b,entity:"minecraft:"},Items:[],id:"ancientwarfarestructure:advanced_loot_chest_tile",Lock:""}}
:enddata
:endrule

rule:
plugin=blockTile
number=36
data:
JSON:{blockState:{blockName:"ancientwarfarestructure:advanced_spawner",properties:{transparent:"true"}},teData:{id:"ancientwarfarestructure:advanced_spawner_tile",spawnerSettings:{minDelay:10,spawnDelay:9,lightSensitive:0b,spawnGroups:[{settingsList:[{remainingSpawnCount:1,hostile:1b,customTag:{ArmorDropChances:[0.085f,0.085f,0.085f,0.085f],hasCustomEquipment:0b,ArmorItems:[{},{},{},{}],skinSettings:{npcTypeName:"custom",skinTypeSelected:"default"},HandDropChances:[0.085f,0.085f],factionName:"sarkonid",HandItems:[{id:"minecraft:bow",Count:1b,Damage:0s},{}]},maxToSpawn:1,entityId:"ancientwarfarenpc:faction.archer",minToSpawn:1}],groupWeight:1}],playerRange:32,respondToRedstone:0b,inventory:{Size:9,Items:[]},spawnRange:0,transparent:1b,maxDelay:10,spawnYOffset:0,xpToDrop:0,mobRange:0,debugMode:0b,maxNearbyMonsters:0}}}
:enddata
:endrule

rule:
plugin=blockTile
number=37
data:
JSON:{blockState:{blockName:"ancientwarfarestructure:advanced_spawner",properties:{transparent:"true"}},teData:{id:"ancientwarfarestructure:advanced_spawner_tile",spawnerSettings:{minDelay:10,spawnDelay:2,lightSensitive:0b,spawnGroups:[{settingsList:[{remainingSpawnCount:1,hostile:1b,customTag:{ArmorDropChances:[0.085f,0.085f,0.085f,0.085f],hasCustomEquipment:0b,ArmorItems:[{},{},{},{}],skinSettings:{npcTypeName:"custom",skinTypeSelected:"default"},HandDropChances:[0.085f,0.085f],factionName:"sarkonid",HandItems:[{id:"minecraft:bow",Count:1b,Damage:0s},{}]},maxToSpawn:1,entityId:"ancientwarfarenpc:faction.archer",minToSpawn:1}],groupWeight:1}],playerRange:32,respondToRedstone:0b,inventory:{Size:9,Items:[]},spawnRange:0,transparent:1b,maxDelay:10,spawnYOffset:0,xpToDrop:0,mobRange:0,debugMode:0b,maxNearbyMonsters:0}}}
:enddata
:endrule

rule:
plugin=vanillaBlocks
number=38
data:
JSON:{blockState:{blockName:"minecraft:torch",properties:{facing:"south"}}}
:enddata
:endrule

rule:
plugin=vanillaBlocks
number=39
data:
JSON:{blockState:{blockName:"minecraft:torch",properties:{facing:"up"}}}
:enddata
:endrule

rule:
plugin=blockTile
number=40
data:
JSON:{blockState:{blockName:"ancientwarfarestructure:advanced_spawner",properties:{transparent:"true"}},teData:{id:"ancientwarfarestructure:advanced_spawner_tile",spawnerSettings:{minDelay:10,spawnDelay:6,lightSensitive:0b,spawnGroups:[{settingsList:[{remainingSpawnCount:1,hostile:1b,customTag:{ArmorDropChances:[0.085f,0.085f,0.085f,0.085f],hasCustomEquipment:0b,ArmorItems:[{},{},{},{}],skinSettings:{npcTypeName:"custom",skinTypeSelected:"default"},HandDropChances:[0.085f,0.085f],factionName:"sarkonid",HandItems:[{},{}]},maxToSpawn:1,entityId:"ancientwarfarenpc:faction.siege_engineer",minToSpawn:1}],groupWeight:1}],playerRange:48,respondToRedstone:0b,inventory:{Size:9,Items:[]},spawnRange:0,transparent:1b,maxDelay:10,spawnYOffset:0,xpToDrop:0,mobRange:0,debugMode:0b,maxNearbyMonsters:0}}}
:enddata
:endrule

rule:
plugin=blockTile
number=41
data:
JSON:{blockState:{blockName:"ancientwarfarestructure:advanced_loot_chest",properties:{facing:"north"}},teData:{lootSettings:{lootRolls:1,splashPotion:0b,hasMessage:0b,hasLoot:1b,lootTableName:"ancientwarfare:chests/ammo_cannon",spawnEntity:0b,entity:"minecraft:"},Items:[],id:"ancientwarfarestructure:advanced_loot_chest_tile",Lock:""}}
:enddata
:endrule

rule:
plugin=blockTile
number=42
data:
JSON:{blockState:{blockName:"ancientwarfarestructure:advanced_spawner",properties:{transparent:"true"}},teData:{id:"ancientwarfarestructure:advanced_spawner_tile",spawnerSettings:{minDelay:10,spawnDelay:4,lightSensitive:0b,spawnGroups:[{settingsList:[{remainingSpawnCount:1,hostile:1b,customTag:{ArmorDropChances:[0.085f,0.085f,0.085f,0.085f],hasCustomEquipment:0b,ArmorItems:[{},{},{},{}],skinSettings:{npcTypeName:"custom",skinTypeSelected:"default"},HandDropChances:[0.085f,0.085f],factionName:"sarkonid",HandItems:[{},{}]},maxToSpawn:1,entityId:"ancientwarfarenpc:faction.siege_engineer",minToSpawn:1}],groupWeight:1}],playerRange:48,respondToRedstone:0b,inventory:{Size:9,Items:[]},spawnRange:0,transparent:1b,maxDelay:10,spawnYOffset:0,xpToDrop:0,mobRange:0,debugMode:0b,maxNearbyMonsters:0}}}
:enddata
:endrule

rule:
plugin=vanillaBlocks
number=43
data:
JSON:{blockState:{blockName:"minecraft:wool",properties:{color:"red"}}}
:enddata
:endrule

rule:
plugin=vanillaBlocks
number=44
data:
JSON:{blockState:{blockName:"minecraft:wool",properties:{color:"white"}}}
:enddata
:endrule

#### ENTITIES ####
entity:
plugin=AWVehicle
number=0
data:
JSON:{yOffset:0.0f,xOffset:0.5874909f,rotation:270.0896f,mobID:"ancientwarfarevehicle:vehicle",zOffset:0.55394816f,position:3299944169482L,turretRotation:270.0896f,entityData:{ForgeData:{},Invulnerable:0b,PortalCooldown:0,inventory:{storageInventory:{Size:0,Items:[]},armorInventory:{Size:3,Items:[]},ammoInventory:{Size:6,Items:[]},upgradeInventory:{Size:3,Items:[]}},upgrades:{armors:[],upgrades:[]},FallDistance:0.0f,ForgeCaps:{},fire:{rt:0,r:0b,f:0b,l:0b},vars:{fT:0},Motion:[0.0d,0.0d,-0.0d],move:{fi:0b,si:0b,ri:0b,pi:0b,tr:0.0f},ammo:{list:[{count:0,type:"ancientwarfarevehicle:ammo_canister_shot_10"},{count:0,type:"ancientwarfarevehicle:ammo_canister_shot_15"},{count:0,type:"ancientwarfarevehicle:ammo_canister_shot_25"},{count:0,type:"ancientwarfarevehicle:ammo_canister_shot_5"},{count:0,type:"ancientwarfarevehicle:ammo_grape_shot_10"},{count:0,type:"ancientwarfarevehicle:ammo_grape_shot_15"},{count:0,type:"ancientwarfarevehicle:ammo_grape_shot_25"},{count:0,type:"ancientwarfarevehicle:ammo_grape_shot_5"},{count:0,type:"ancientwarfarevehicle:ammo_iron_shot_10"},{count:0,type:"ancientwarfarevehicle:ammo_iron_shot_15"},{count:0,type:"ancientwarfarevehicle:ammo_iron_shot_25"},{count:0,type:"ancientwarfarevehicle:ammo_iron_shot_5"}]},trd:270.0896f,vehType:10,health:140.0f,tpd:15.0f,Air:300s,OnGround:1b,Dimension:0,Rotation:[270.0896f,0.0f],UpdateBlocked:0b,matLvl:3,turHome:270.0896f,Pos:[-611.4125090800985d,27.0d,-901.4460518771411d],Fire:-1s,lc:40.0f,setup:0b,tp:15.0f,tr:270.0896f}}
:enddata
:endentity

entity:
plugin=AWVehicle
number=1
data:
JSON:{yOffset:0.0f,xOffset:0.37380135f,rotation:177.53958f,mobID:"ancientwarfarevehicle:vehicle",zOffset:0.41241217f,position:2750188355596L,turretRotation:177.53958f,entityData:{ForgeData:{},Invulnerable:0b,PortalCooldown:0,inventory:{storageInventory:{Size:0,Items:[]},armorInventory:{Size:3,Items:[]},ammoInventory:{Size:6,Items:[]},upgradeInventory:{Size:3,Items:[]}},upgrades:{armors:[],upgrades:[]},FallDistance:0.0f,ForgeCaps:{},fire:{rt:0,r:0b,f:0b,l:0b},vars:{fT:0},Motion:[-0.0d,0.0d,0.0d],move:{fi:0b,si:0b,ri:0b,pi:0b,tr:0.0f},ammo:{list:[{count:0,type:"ancientwarfarevehicle:ammo_canister_shot_10"},{count:0,type:"ancientwarfarevehicle:ammo_canister_shot_15"},{count:0,type:"ancientwarfarevehicle:ammo_canister_shot_25"},{count:0,type:"ancientwarfarevehicle:ammo_canister_shot_5"},{count:0,type:"ancientwarfarevehicle:ammo_grape_shot_10"},{count:0,type:"ancientwarfarevehicle:ammo_grape_shot_15"},{count:0,type:"ancientwarfarevehicle:ammo_grape_shot_25"},{count:0,type:"ancientwarfarevehicle:ammo_grape_shot_5"},{count:0,type:"ancientwarfarevehicle:ammo_iron_shot_10"},{count:0,type:"ancientwarfarevehicle:ammo_iron_shot_15"},{count:0,type:"ancientwarfarevehicle:ammo_iron_shot_25"},{count:0,type:"ancientwarfarevehicle:ammo_iron_shot_5"}]},trd:177.53958f,vehType:10,health:140.0f,tpd:15.0f,Air:300s,OnGround:1b,Dimension:0,Rotation:[177.53958f,0.0f],UpdateBlocked:0b,matLvl:3,turHome:177.53958f,Pos:[-613.6261986584215d,27.0d,-899.5875878427204d],Fire:-1s,lc:40.0f,setup:0b,tp:15.0f,tr:177.53958f}}
:enddata
:endentity

