# Ancient Warfare Structure Template File
# Auto-generated structure template file. created on: 5/16/2021 at: 8:48:45
# Lines beginning with # denote comments

header:
version=2.11
name=SurvivalBuildHarborJettyFortified
mods=
size=16,32,16
offset=15,6,15
:endheader

#### VALIDATION ####
validation:
type=ground
structureAuthor=Loki61089
survival=true
worldGenEnabled=false
unique=false
preserveBlocks=true
preventNaturalHostileSpawns=false
selectionWeight=1
clusterValue=1
minDuplicateDistance=1
dimensionWhiteList=true
dimensionList=
biomeGroupList=
biomeWhiteList=true
biomeList=
leveling=0
fill=0
border=0
blockSwap=false
territoryName=
biomeReplacement=minecraft:
minGenerationHeight=0
maxGenerationHeight=255
:endvalidation

#### LAYERS ####
layer: 0
3,3,3,3,3,3,3,3,3,3,3,3,3,3,3,3
3,3,3,3,3,3,3,3,3,3,3,3,3,3,3,3
3,3,3,3,3,3,3,3,3,3,3,3,3,3,3,3
3,3,3,3,3,3,3,3,3,3,3,3,3,3,3,3
3,3,3,3,3,3,3,3,3,3,3,3,3,3,3,3
3,3,3,3,3,3,3,3,3,3,3,3,3,3,3,3
3,3,3,3,3,3,3,3,3,3,3,3,3,3,3,3
2,3,0,0,0,3,3,0,0,3,3,0,0,0,3,2
2,3,3,3,3,3,3,0,0,3,3,3,3,3,3,2
2,2,2,2,2,2,3,0,0,3,2,2,2,2,2,2
1,0,0,0,0,1,3,0,0,3,1,0,0,0,0,1
0,0,0,0,0,1,3,0,0,3,1,0,0,0,0,0
0,0,0,0,0,1,3,0,0,3,1,0,0,0,0,0
0,0,0,0,0,1,3,0,0,3,1,0,0,0,0,0
0,0,0,0,0,1,3,0,0,3,1,0,0,0,0,0
0,0,0,0,0,1,1,1,1,1,1,0,0,0,0,0
:endlayer
layer: 1
3,3,3,3,3,3,3,3,3,3,3,3,3,3,3,3
3,3,3,3,3,3,3,3,3,3,3,3,3,3,3,3
3,3,3,3,3,3,3,3,3,3,3,3,3,3,3,3
3,3,3,3,3,3,3,3,3,3,3,3,3,3,3,3
3,3,3,3,3,3,3,3,3,3,3,3,3,3,3,3
3,3,3,3,3,3,3,3,3,3,3,3,3,3,3,3
3,3,3,3,3,3,3,3,3,3,3,3,3,3,3,3
2,3,0,0,0,3,3,0,0,3,3,0,0,0,3,2
2,3,3,3,3,3,3,0,0,3,3,3,3,3,3,2
2,2,2,2,2,2,3,0,0,3,2,2,2,2,2,2
1,0,0,0,0,1,3,0,0,3,1,0,0,0,0,1
0,0,0,0,0,1,3,0,0,3,1,0,0,0,0,0
0,0,0,0,0,1,3,0,0,3,1,0,0,0,0,0
0,0,0,0,0,1,3,0,0,3,1,0,0,0,0,0
0,0,0,0,0,1,3,0,0,3,1,0,0,0,0,0
0,0,0,0,0,1,1,1,1,1,1,0,0,0,0,0
:endlayer
layer: 2
3,3,3,3,3,3,3,3,3,3,3,3,3,3,3,3
3,3,3,3,3,3,3,3,3,3,3,3,3,3,3,3
3,3,3,3,3,3,3,3,3,3,3,3,3,3,3,3
3,3,3,3,3,3,3,3,3,3,3,3,3,3,3,3
3,3,3,3,3,3,3,3,3,3,3,3,3,3,3,3
3,3,3,3,3,3,3,3,3,3,3,3,3,3,3,3
3,3,3,3,3,3,3,3,3,3,3,3,3,3,3,3
2,1,0,0,0,1,1,0,0,1,1,0,0,0,1,2
2,1,1,1,1,1,1,0,0,1,1,1,1,1,1,2
2,2,2,2,2,2,1,0,0,1,2,2,2,2,2,2
1,0,0,0,0,1,1,0,0,1,1,0,0,0,0,1
0,0,0,0,0,1,1,0,0,1,1,0,0,0,0,0
0,0,0,0,0,1,1,0,0,1,1,0,0,0,0,0
0,0,0,0,0,1,1,0,0,1,1,0,0,0,0,0
0,0,0,0,0,1,1,0,0,1,1,0,0,0,0,0
0,0,0,0,0,1,1,1,1,1,1,0,0,0,0,0
:endlayer
layer: 3
3,3,3,3,3,3,3,3,3,3,3,3,3,3,3,3
3,3,3,3,3,3,3,3,3,3,3,3,3,3,3,3
3,3,3,3,3,3,3,3,3,3,3,3,3,3,3,3
3,3,3,3,3,3,3,3,3,3,3,3,3,3,3,3
3,3,3,3,3,3,3,3,3,3,3,3,3,3,3,3
3,3,3,3,3,3,3,3,3,3,3,3,3,3,3,3
3,3,3,3,3,3,3,3,3,3,3,3,3,3,3,3
2,3,0,0,0,3,3,0,0,3,3,0,0,0,3,2
2,3,3,3,3,3,3,0,0,3,3,3,3,3,3,2
2,2,2,2,2,2,3,0,0,3,2,2,2,2,2,2
1,0,0,0,0,1,3,0,0,3,1,0,0,0,0,1
0,0,0,0,0,1,3,0,0,3,1,0,0,0,0,0
0,0,0,0,0,1,3,0,0,3,1,0,0,0,0,0
0,0,0,0,0,1,3,0,0,3,1,0,0,0,0,0
0,0,0,0,0,1,3,0,0,3,1,0,0,0,0,0
0,0,0,0,0,1,1,1,1,1,1,0,0,0,0,0
:endlayer
layer: 4
3,3,3,3,3,3,3,3,3,3,3,3,3,3,3,3
3,3,3,3,3,3,3,3,3,3,3,3,3,3,3,3
3,3,3,3,3,3,3,3,3,3,3,3,3,3,3,3
3,3,3,3,3,3,3,3,3,3,3,3,3,3,3,3
3,3,3,3,3,3,3,3,3,3,3,3,3,3,3,3
3,3,3,3,3,3,3,3,3,3,3,3,3,3,3,3
3,3,3,3,3,3,3,3,3,3,3,3,3,3,3,3
2,3,0,0,0,3,3,0,0,3,3,0,0,0,3,2
2,3,3,3,3,3,3,0,0,3,3,3,3,3,3,2
2,2,2,2,2,2,3,0,0,3,2,2,2,2,2,2
1,0,0,0,0,1,3,0,0,3,1,0,0,0,0,1
0,0,0,0,0,1,3,0,0,3,1,0,0,0,0,0
0,0,0,0,0,1,3,0,0,3,1,0,0,0,0,0
0,0,0,0,0,1,3,0,0,3,1,0,0,0,0,0
0,0,0,0,0,1,3,0,0,3,1,0,0,0,0,0
0,0,0,0,0,1,1,1,1,1,1,0,0,0,0,0
:endlayer
layer: 5
3,3,3,3,3,3,3,3,3,3,3,3,3,3,3,3
3,3,3,3,3,3,3,3,3,3,3,3,3,3,3,3
3,3,3,3,3,3,3,3,3,3,3,3,3,3,3,3
3,3,3,3,3,3,3,3,3,3,3,3,3,3,3,3
3,3,3,3,3,3,3,3,3,3,3,3,3,3,3,3
3,3,3,3,3,3,3,3,3,3,3,3,3,3,3,3
3,3,3,3,3,3,3,3,3,3,3,3,3,3,3,3
2,3,3,3,3,3,3,3,3,3,3,3,3,3,3,2
2,3,3,3,3,3,3,3,3,3,3,3,3,3,3,2
2,2,2,2,2,2,3,3,3,3,2,2,2,2,2,2
1,0,0,0,0,1,3,3,3,3,1,0,0,0,0,1
0,0,0,0,0,1,3,3,3,3,1,0,0,0,0,0
0,0,0,0,0,1,3,3,3,3,1,0,0,0,0,0
0,0,0,0,0,1,3,3,3,3,1,0,0,0,0,0
0,0,0,0,0,1,3,3,3,3,1,0,0,0,0,0
0,0,0,0,0,1,1,1,1,1,1,0,0,0,0,0
:endlayer
layer: 6
2,2,2,2,2,2,2,2,2,2,2,2,2,2,2,2
2,3,3,3,3,3,3,3,3,3,3,3,3,3,3,2
2,3,3,3,3,3,3,3,3,3,3,3,3,3,3,2
2,3,3,3,3,3,3,3,3,3,3,3,3,3,3,2
2,3,3,3,3,3,3,3,3,3,3,3,3,3,3,2
2,3,3,3,3,2,3,3,3,3,2,3,3,3,3,2
2,3,3,3,3,2,3,3,3,3,2,3,3,3,3,2
2,3,3,3,3,2,3,3,3,3,2,3,3,3,3,2
2,3,3,3,3,2,3,3,3,3,2,3,3,3,3,2
1,2,2,2,2,1,3,3,3,3,1,2,2,2,2,1
1,0,0,0,0,1,3,3,3,3,1,0,0,0,0,1
0,0,0,0,0,1,3,3,3,3,1,0,0,0,0,0
0,0,0,0,0,1,3,3,3,3,1,0,0,0,0,0
0,0,0,0,0,1,3,3,3,3,1,0,0,0,0,0
0,0,0,0,0,1,3,3,3,3,1,0,0,0,0,0
0,0,0,0,0,1,1,1,1,1,1,0,0,0,0,0
:endlayer
layer: 7
2,2,2,2,2,2,2,2,2,2,2,2,2,2,2,2
2,3,3,3,3,3,3,3,3,3,3,3,3,3,3,2
2,3,3,3,3,3,3,3,3,3,3,3,3,3,3,2
2,3,3,3,3,3,3,3,3,3,3,3,3,3,3,2
2,3,3,3,3,3,3,3,3,3,3,3,3,3,3,2
2,3,3,3,3,2,3,3,3,3,2,3,3,3,3,2
2,3,3,3,3,2,3,3,3,3,2,3,3,3,3,2
2,3,3,3,3,2,3,3,3,3,2,3,3,3,3,2
1,2,2,2,2,1,3,3,3,3,1,2,2,2,2,1
1,2,2,2,2,1,3,3,3,3,1,2,2,2,2,1
1,0,0,0,0,1,3,3,3,3,1,0,0,0,0,1
4,0,0,0,0,1,3,3,3,3,1,0,0,0,0,4
0,0,0,0,0,1,3,3,3,3,1,0,0,0,0,0
0,0,0,0,0,1,3,3,3,3,1,0,0,0,0,0
0,0,0,0,0,1,3,3,3,3,1,0,0,0,0,0
0,0,0,0,5,1,1,1,1,1,1,6,0,0,0,0
:endlayer
layer: 8
2,2,2,2,2,2,2,2,2,2,2,2,2,2,2,2
2,3,3,3,3,3,3,3,3,3,3,3,3,3,3,2
2,3,3,3,3,3,3,3,3,3,3,3,3,3,3,2
2,3,3,3,3,3,3,3,3,3,3,3,3,3,3,2
2,3,3,3,3,3,3,3,3,3,3,3,3,3,3,2
2,3,3,3,3,2,3,3,3,3,2,3,3,3,3,2
2,3,3,3,3,2,3,3,3,3,2,3,3,3,3,2
1,2,2,2,2,1,3,3,3,3,1,2,2,2,2,1
1,2,2,2,2,1,3,3,3,3,1,2,2,2,2,1
1,2,2,2,2,1,3,3,3,3,1,2,2,2,2,1
1,7,0,0,8,1,3,3,3,3,1,7,0,0,8,1
0,0,0,0,0,1,3,3,3,3,1,0,0,0,0,0
0,0,0,0,0,1,3,3,3,3,1,0,0,0,0,0
0,0,0,0,0,1,3,3,3,3,1,0,0,0,0,0
0,0,0,0,0,1,3,3,3,3,1,0,0,0,0,0
0,0,0,0,0,1,1,1,1,1,1,0,0,0,0,0
:endlayer
layer: 9
2,2,2,2,2,2,2,2,2,2,2,2,2,2,2,2
2,2,2,2,2,2,2,2,2,2,2,2,2,2,2,2
2,1,2,2,2,2,2,2,2,2,2,2,2,2,2,2
2,2,2,2,2,2,2,2,2,2,2,2,2,2,2,2
2,2,2,2,2,2,2,2,2,2,2,2,2,2,2,2
2,2,2,2,2,2,2,2,2,2,2,2,2,2,2,2
2,2,2,2,2,2,2,2,2,2,2,2,2,2,2,2
2,2,2,2,2,2,2,2,2,2,2,2,2,2,2,2
2,2,2,2,2,2,2,2,2,2,2,2,2,2,2,2
2,2,2,2,2,2,2,2,2,2,2,2,2,2,2,2
9,9,9,9,9,9,2,2,2,2,9,9,9,9,9,9
0,0,0,0,0,9,2,2,2,2,9,0,0,0,0,0
0,0,0,0,0,9,2,2,2,2,9,0,0,0,0,0
0,0,0,0,0,9,2,2,2,2,9,0,0,0,0,0
0,0,0,0,0,9,2,2,2,2,9,0,0,0,0,0
0,0,0,0,0,9,2,2,2,2,9,0,0,0,0,0
:endlayer
layer: 10
0,0,0,0,0,0,0,0,0,0,0,0,0,0,0,0
0,0,0,0,0,0,0,0,0,0,0,0,0,0,0,0
0,1,2,2,2,1,0,0,0,0,1,2,2,2,1,0
0,2,0,0,1,0,0,0,0,0,0,1,0,0,2,0
0,2,0,0,1,1,0,0,0,0,1,1,0,0,2,0
0,1,10,1,1,0,0,0,0,0,0,1,0,0,1,0
0,2,0,0,12,0,0,0,0,0,0,14,0,0,2,0
0,2,0,11,1,0,0,0,0,0,0,1,0,0,2,0
0,2,0,1,1,1,0,0,0,0,1,1,0,0,2,0
0,2,1,1,1,0,0,0,0,0,0,1,0,0,2,0
0,1,2,2,1,1,0,0,0,0,1,1,2,2,1,0
0,0,0,0,0,0,0,0,0,0,0,0,0,0,0,0
0,0,0,0,0,0,0,0,0,0,0,0,0,0,0,0
0,0,0,0,0,13,0,0,0,0,13,0,0,0,0,0
0,0,0,0,0,0,0,0,0,0,0,0,0,0,0,0
0,0,0,0,0,0,0,0,0,0,0,0,0,0,0,0
:endlayer
layer: 11
0,0,0,0,0,0,0,0,0,0,0,0,0,0,0,0
0,0,0,0,0,0,0,0,0,0,0,0,0,0,0,0
0,1,2,2,2,1,0,0,0,0,1,2,2,2,1,0
0,2,0,0,1,0,0,0,0,0,0,1,0,0,2,0
0,2,0,0,1,1,0,0,0,0,1,1,0,0,2,0
0,1,16,1,1,6,0,0,0,0,5,1,6,0,1,0
0,2,0,0,16,0,0,0,0,0,0,16,0,0,2,0
0,2,0,0,1,6,0,0,0,0,5,1,6,0,2,0
0,2,15,11,1,1,0,0,0,0,1,1,0,0,2,0
0,2,1,1,1,0,0,0,0,0,0,1,0,0,2,0
0,1,2,2,1,1,0,0,0,0,1,1,2,2,1,0
0,0,0,0,0,0,0,0,0,0,0,0,0,0,0,0
0,0,0,0,0,0,0,0,0,0,0,0,0,0,0,0
0,0,0,0,0,0,0,0,0,0,0,0,0,0,0,0
0,0,0,0,0,0,0,0,0,0,0,0,0,0,0,0
0,0,0,0,0,0,0,0,0,0,0,0,0,0,0,0
:endlayer
layer: 12
0,0,0,0,0,0,0,0,0,0,0,0,0,0,0,0
0,17,0,0,0,17,0,0,0,0,17,0,0,0,17,0
0,1,2,2,2,1,0,0,0,0,1,2,2,2,1,6
0,2,0,0,1,0,0,0,0,0,0,1,0,0,2,0
0,2,0,17,1,1,0,0,0,0,1,1,0,0,2,0
5,1,1,1,1,0,0,0,0,0,0,1,0,0,1,6
0,2,0,0,7,0,0,0,0,0,0,8,0,0,2,0
0,2,15,0,1,0,0,0,0,0,0,1,0,0,2,0
0,2,18,0,1,1,0,0,0,0,1,1,0,0,2,0
0,2,0,0,1,0,0,0,0,0,0,1,0,0,2,0
5,1,2,2,1,1,0,0,0,0,1,1,2,2,1,6
0,4,0,0,0,4,0,0,0,0,4,0,0,0,4,0
0,0,0,0,0,0,0,0,0,0,0,0,0,0,0,0
0,0,0,0,0,0,0,0,0,0,0,0,0,0,0,0
0,0,0,0,0,0,0,0,0,0,0,0,0,0,0,0
0,0,0,0,0,0,0,0,0,0,0,0,0,0,0,0
:endlayer
layer: 13
0,0,0,0,0,0,0,0,0,0,0,0,0,0,0,0
0,0,0,0,0,0,0,0,0,0,0,0,0,0,0,0
0,1,2,2,2,1,7,0,0,8,1,2,2,2,1,0
0,2,0,0,1,0,0,0,0,0,0,1,0,0,2,0
0,2,0,0,1,1,7,0,0,8,1,1,0,0,2,0
0,1,1,1,1,19,19,0,0,19,19,1,0,0,1,0
0,2,15,0,1,7,0,0,0,0,8,1,0,0,2,0
0,2,18,0,1,15,15,0,0,15,15,1,0,0,2,0
0,2,0,0,1,1,7,0,0,8,1,1,0,0,2,0
0,2,0,0,1,0,0,0,0,0,0,1,0,0,2,0
0,1,2,2,1,1,7,0,0,8,1,1,2,2,1,0
0,0,0,0,0,0,0,0,0,0,0,0,0,0,0,0
0,0,0,0,0,0,0,0,0,0,0,0,0,0,0,0
0,0,0,0,0,0,0,0,0,0,0,0,0,0,0,0
0,0,0,0,0,0,0,0,0,0,0,0,0,0,0,0
0,0,0,0,0,0,0,0,0,0,0,0,0,0,0,0
:endlayer
layer: 14
0,0,0,0,0,0,0,0,0,0,0,0,0,0,0,0
15,15,15,15,15,15,15,15,15,15,15,15,15,15,15,7
8,2,2,2,2,2,2,2,2,2,2,2,2,2,2,7
8,2,2,2,2,2,2,2,2,2,2,2,2,2,2,7
8,2,2,2,2,2,2,2,2,2,2,2,2,2,2,7
8,2,2,2,2,20,23,24,23,23,23,2,2,2,2,7
8,2,18,19,2,20,22,24,20,25,24,2,2,2,2,7
8,2,0,0,2,20,21,21,20,21,21,2,2,2,2,7
8,2,0,0,1,2,2,2,2,2,2,2,2,2,2,7
8,2,0,0,2,2,2,2,2,2,2,2,2,2,2,7
8,2,2,2,2,2,2,2,2,2,2,2,2,2,2,7
19,19,19,19,19,19,19,19,19,19,19,19,19,19,19,19
0,0,0,0,0,0,0,0,0,0,0,0,0,0,0,0
0,0,0,0,0,0,0,0,0,0,0,0,0,0,0,0
0,0,0,0,0,0,0,0,0,0,0,0,0,0,0,0
0,0,0,0,0,0,0,0,0,0,0,0,0,0,0,0
:endlayer
layer: 15
0,0,0,0,0,0,0,0,0,0,0,0,0,0,0,0
1,2,21,2,1,2,21,2,2,21,2,1,2,21,2,1
2,0,0,0,2,0,0,0,0,0,0,2,0,0,0,2
24,0,0,0,26,0,0,0,0,0,0,14,0,0,0,20
2,0,0,0,1,2,1,0,0,1,2,1,0,0,0,2
24,0,0,0,2,0,0,0,0,0,0,2,0,0,0,20
1,0,0,11,2,0,0,0,0,0,0,2,0,0,0,1
24,0,0,19,2,0,0,0,0,0,0,2,0,0,0,20
2,0,0,5,1,2,1,0,0,1,2,1,0,0,0,2
24,0,0,0,2,0,0,0,0,0,0,14,0,0,0,20
2,0,0,0,26,0,0,0,0,0,0,2,0,0,0,2
1,2,23,2,1,2,23,2,2,23,2,1,2,23,2,1
0,0,0,0,0,0,0,0,0,0,0,0,0,0,0,0
0,0,0,0,0,0,0,0,0,0,0,0,0,0,0,0
0,0,0,0,0,0,0,0,0,0,0,0,0,0,0,0
0,0,0,0,0,0,0,0,0,0,0,0,0,0,0,0
:endlayer
layer: 16
0,0,0,0,0,0,0,0,0,0,0,0,0,0,0,0
1,2,29,2,1,2,29,2,2,29,2,1,2,29,2,1
2,0,0,0,2,0,0,0,0,0,0,2,0,0,0,2
27,0,0,0,30,0,17,0,0,17,0,30,0,0,0,31
2,0,0,5,1,2,1,0,0,1,2,1,6,0,0,2
27,0,0,0,2,0,0,0,0,0,0,2,0,0,0,31
1,0,0,0,2,0,0,0,0,0,0,2,0,0,0,1
27,0,0,11,2,0,0,0,0,0,0,2,0,0,0,31
2,0,0,19,1,2,1,0,0,1,2,1,6,0,0,2
27,0,0,0,2,0,4,0,0,4,0,16,0,0,0,31
2,0,0,0,30,0,0,0,0,0,0,2,0,0,0,2
1,2,28,2,1,2,28,2,2,28,2,1,2,28,2,1
0,0,0,0,0,0,0,0,0,0,0,0,0,0,0,0
0,0,0,0,0,0,0,0,0,0,0,0,0,0,0,0
0,0,0,0,0,0,0,0,0,0,0,0,0,0,0,0
0,0,0,0,0,0,0,0,0,0,0,0,0,0,0,0
:endlayer
layer: 17
0,0,0,0,0,0,0,0,0,0,0,0,0,0,0,0
1,2,34,2,1,2,34,2,2,34,2,1,2,34,2,1
2,0,0,0,2,0,0,0,0,0,0,2,0,0,0,2
32,0,0,0,2,0,0,0,0,0,0,2,0,0,0,36
2,0,0,0,1,2,1,36,32,1,2,1,0,0,0,2
32,0,0,0,2,0,0,0,0,0,0,2,0,0,0,36
1,0,0,0,2,0,0,0,0,0,0,2,0,0,0,1
32,0,0,0,2,0,0,0,0,0,0,2,0,0,0,36
2,0,0,0,35,2,1,36,32,1,2,1,0,0,0,2
32,0,0,0,2,0,0,0,0,0,0,2,0,0,0,36
2,0,0,0,2,0,0,0,0,0,0,2,0,0,0,2
1,2,33,2,1,2,33,2,2,33,2,1,2,33,2,1
0,0,0,0,0,0,0,0,0,0,0,0,0,0,0,0
0,0,0,0,0,0,0,0,0,0,0,0,0,0,0,0
0,0,0,0,0,0,0,0,0,0,0,0,0,0,0,0
0,0,0,0,0,0,0,0,0,0,0,0,0,0,0,0
:endlayer
layer: 18
0,0,0,0,0,0,0,0,0,0,0,0,0,0,0,0
8,15,15,15,15,15,15,15,15,15,15,15,15,15,15,15
8,2,2,2,2,2,2,2,2,2,2,2,2,2,2,7
8,2,2,2,2,2,2,2,2,2,2,2,2,2,2,7
8,2,2,2,2,2,2,2,2,2,2,2,2,2,2,7
8,2,2,33,2,2,2,2,2,2,2,2,2,2,2,7
8,2,2,0,2,2,2,2,2,2,2,2,2,2,2,7
8,2,2,0,2,2,2,2,2,2,2,2,2,2,2,7
8,2,2,0,0,35,2,2,2,2,2,2,2,2,2,7
8,2,2,2,2,2,2,2,2,2,2,2,2,2,2,7
8,2,2,2,2,2,2,2,2,2,2,2,2,2,2,7
19,19,19,19,19,19,19,19,19,19,19,19,19,19,19,19
0,0,0,0,0,0,0,0,0,0,0,0,0,0,0,0
0,0,0,0,0,0,0,0,0,0,0,0,0,0,0,0
0,0,0,0,0,0,0,0,0,0,0,0,0,0,0,0
0,0,0,0,0,0,0,0,0,0,0,0,0,0,0,0
:endlayer
layer: 19
0,0,0,0,0,0,0,0,0,0,0,0,0,0,0,0
1,18,1,18,1,18,1,18,18,1,18,1,18,1,18,1
37,0,0,0,0,0,0,0,0,0,0,0,0,0,0,35
1,0,13,0,0,0,0,0,0,0,0,0,13,0,0,1
37,0,0,0,0,0,0,0,0,0,0,0,0,0,0,35
1,0,0,0,0,0,0,39,11,39,0,0,0,0,0,1
37,0,0,25,0,0,13,35,1,37,0,0,0,0,0,35
1,0,0,25,0,0,0,39,18,39,0,0,0,0,0,1
37,0,0,25,38,38,0,0,0,0,0,0,0,0,0,35
1,0,13,0,0,0,0,0,0,0,0,0,0,13,0,1
37,0,0,0,0,0,0,0,0,0,0,0,0,0,0,35
1,11,1,11,1,11,1,11,11,1,11,1,11,1,11,1
0,0,0,0,0,0,0,0,0,0,0,0,0,0,0,0
0,0,0,0,0,0,0,0,0,0,0,0,0,0,0,0
0,0,0,0,0,0,0,0,0,0,0,0,0,0,0,0
0,0,0,0,0,0,0,0,0,0,0,0,0,0,0,0
:endlayer
layer: 20
0,0,0,0,0,0,0,0,0,0,0,0,0,0,0,0
39,0,39,0,39,0,39,0,0,39,0,39,0,39,0,39
0,0,0,0,0,0,0,0,0,0,0,0,0,0,0,0
39,0,0,0,0,0,0,0,0,0,0,0,0,0,0,39
0,0,0,0,0,0,0,0,0,0,0,0,0,0,0,0
39,0,0,0,0,0,0,0,0,0,0,0,0,0,0,39
0,0,0,0,0,0,0,0,1,0,0,0,0,0,0,0
39,0,0,0,0,0,0,0,0,0,0,0,0,0,0,39
0,0,0,0,0,0,0,0,0,0,0,0,0,0,0,0
39,0,0,0,0,0,0,0,0,0,0,0,0,0,0,39
0,0,0,0,0,0,0,0,0,0,0,0,0,0,0,0
39,0,39,0,39,0,39,0,0,39,0,39,0,39,0,39
0,0,0,0,0,0,0,0,0,0,0,0,0,0,0,0
0,0,0,0,0,0,0,0,0,0,0,0,0,0,0,0
0,0,0,0,0,0,0,0,0,0,0,0,0,0,0,0
0,0,0,0,0,0,0,0,0,0,0,0,0,0,0,0
:endlayer
layer: 21
0,0,0,0,0,0,0,0,0,0,0,0,0,0,0,0
0,0,0,0,0,0,0,0,0,0,0,0,0,0,0,0
0,0,0,0,0,0,0,0,0,0,0,0,0,0,0,0
0,0,0,0,0,0,0,0,0,0,0,0,0,0,0,0
0,0,0,0,0,0,0,0,0,0,0,0,0,0,0,0
0,0,0,0,0,0,0,0,0,0,0,0,0,0,0,0
0,0,0,0,0,0,0,0,1,0,0,0,0,0,0,0
0,0,0,0,0,0,0,0,0,0,0,0,0,0,0,0
0,0,0,0,0,0,0,0,0,0,0,0,0,0,0,0
0,0,0,0,0,0,0,0,0,0,0,0,0,0,0,0
0,0,0,0,0,0,0,0,0,0,0,0,0,0,0,0
0,0,0,0,0,0,0,0,0,0,0,0,0,0,0,0
0,0,0,0,0,0,0,0,0,0,0,0,0,0,0,0
0,0,0,0,0,0,0,0,0,0,0,0,0,0,0,0
0,0,0,0,0,0,0,0,0,0,0,0,0,0,0,0
0,0,0,0,0,0,0,0,0,0,0,0,0,0,0,0
:endlayer
layer: 22
0,0,0,0,0,0,0,0,0,0,0,0,0,0,0,0
0,0,0,0,0,0,0,0,0,0,0,0,0,0,0,0
0,0,0,0,0,0,0,0,0,0,0,0,0,0,0,0
0,0,0,0,0,0,0,0,0,0,0,0,0,0,0,0
0,0,0,0,0,0,0,0,0,0,0,0,0,0,0,0
0,0,0,0,0,0,0,0,0,0,0,0,0,0,0,0
0,0,0,0,0,0,0,0,40,0,0,0,0,0,0,0
0,0,0,0,0,0,0,0,0,0,0,0,0,0,0,0
0,0,0,0,0,0,0,0,0,0,0,0,0,0,0,0
0,0,0,0,0,0,0,0,0,0,0,0,0,0,0,0
0,0,0,0,0,0,0,0,0,0,0,0,0,0,0,0
0,0,0,0,0,0,0,0,0,0,0,0,0,0,0,0
0,0,0,0,0,0,0,0,0,0,0,0,0,0,0,0
0,0,0,0,0,0,0,0,0,0,0,0,0,0,0,0
0,0,0,0,0,0,0,0,0,0,0,0,0,0,0,0
0,0,0,0,0,0,0,0,0,0,0,0,0,0,0,0
:endlayer
layer: 23
0,0,0,0,0,0,0,0,0,0,0,0,0,0,0,0
0,0,0,0,0,0,0,0,0,0,0,0,0,0,0,0
0,0,0,0,0,0,0,0,0,0,0,0,0,0,0,0
0,0,0,0,0,0,0,0,0,0,0,0,0,0,0,0
0,0,0,0,0,0,0,0,0,0,0,0,0,0,0,0
0,0,0,0,0,0,0,0,0,0,0,0,0,0,0,0
0,0,0,0,0,0,0,0,40,0,0,0,0,0,0,0
0,0,0,0,0,0,0,0,0,0,0,0,0,0,0,0
0,0,0,0,0,0,0,0,0,0,0,0,0,0,0,0
0,0,0,0,0,0,0,0,0,0,0,0,0,0,0,0
0,0,0,0,0,0,0,0,0,0,0,0,0,0,0,0
0,0,0,0,0,0,0,0,0,0,0,0,0,0,0,0
0,0,0,0,0,0,0,0,0,0,0,0,0,0,0,0
0,0,0,0,0,0,0,0,0,0,0,0,0,0,0,0
0,0,0,0,0,0,0,0,0,0,0,0,0,0,0,0
0,0,0,0,0,0,0,0,0,0,0,0,0,0,0,0
:endlayer
layer: 24
0,0,0,0,0,0,0,0,0,0,0,0,0,0,0,0
0,0,0,0,0,0,0,0,0,0,0,0,0,0,0,0
0,0,0,0,0,0,0,0,0,0,0,0,0,0,0,0
0,0,0,0,0,0,0,0,0,0,0,0,0,0,0,0
0,0,0,0,0,0,0,0,0,0,0,0,0,0,0,0
0,0,0,0,0,0,0,0,0,0,0,0,0,0,0,0
0,0,0,0,0,0,0,0,40,0,0,0,0,0,0,0
0,0,0,0,0,0,0,0,0,0,0,0,0,0,0,0
0,0,0,0,0,0,0,0,0,0,0,0,0,0,0,0
0,0,0,0,0,0,0,0,0,0,0,0,0,0,0,0
0,0,0,0,0,0,0,0,0,0,0,0,0,0,0,0
0,0,0,0,0,0,0,0,0,0,0,0,0,0,0,0
0,0,0,0,0,0,0,0,0,0,0,0,0,0,0,0
0,0,0,0,0,0,0,0,0,0,0,0,0,0,0,0
0,0,0,0,0,0,0,0,0,0,0,0,0,0,0,0
0,0,0,0,0,0,0,0,0,0,0,0,0,0,0,0
:endlayer
layer: 25
0,0,0,0,0,0,0,0,0,0,0,0,0,0,0,0
0,0,0,0,0,0,0,0,0,0,0,0,0,0,0,0
0,0,0,0,0,0,0,0,0,0,0,0,0,0,0,0
0,0,0,0,0,0,0,0,0,0,0,0,0,0,0,0
0,0,0,0,0,0,0,0,0,0,0,0,0,0,0,0
0,0,0,0,0,0,0,0,0,0,0,0,0,0,0,0
0,0,0,0,0,0,0,0,41,0,0,0,0,0,0,0
0,0,0,0,0,0,0,0,0,0,0,0,0,0,0,0
0,0,0,0,0,0,0,0,0,0,0,0,0,0,0,0
0,0,0,0,0,0,0,0,0,0,0,0,0,0,0,0
0,0,0,0,0,0,0,0,0,0,0,0,0,0,0,0
0,0,0,0,0,0,0,0,0,0,0,0,0,0,0,0
0,0,0,0,0,0,0,0,0,0,0,0,0,0,0,0
0,0,0,0,0,0,0,0,0,0,0,0,0,0,0,0
0,0,0,0,0,0,0,0,0,0,0,0,0,0,0,0
0,0,0,0,0,0,0,0,0,0,0,0,0,0,0,0
:endlayer
layer: 26
0,0,0,0,0,0,0,0,0,0,0,0,0,0,0,0
0,0,0,0,0,0,0,0,0,0,0,0,0,0,0,0
0,0,0,0,0,0,0,0,0,0,0,0,0,0,0,0
0,0,0,0,0,0,0,0,0,0,0,0,0,0,0,0
0,0,0,0,0,0,0,0,0,0,0,0,0,0,0,0
0,0,0,0,0,0,0,0,0,0,0,0,0,0,0,0
0,0,0,0,0,0,0,0,41,0,0,0,0,0,0,0
0,0,0,0,0,0,0,0,0,0,0,0,0,0,0,0
0,0,0,0,0,0,0,0,0,0,0,0,0,0,0,0
0,0,0,0,0,0,0,0,0,0,0,0,0,0,0,0
0,0,0,0,0,0,0,0,0,0,0,0,0,0,0,0
0,0,0,0,0,0,0,0,0,0,0,0,0,0,0,0
0,0,0,0,0,0,0,0,0,0,0,0,0,0,0,0
0,0,0,0,0,0,0,0,0,0,0,0,0,0,0,0
0,0,0,0,0,0,0,0,0,0,0,0,0,0,0,0
0,0,0,0,0,0,0,0,0,0,0,0,0,0,0,0
:endlayer
layer: 27
0,0,0,0,0,0,0,0,0,0,0,0,0,0,0,0
0,0,0,0,0,0,0,0,0,0,0,0,0,0,0,0
0,0,0,0,0,0,0,0,0,0,0,0,0,0,0,0
0,0,0,0,0,0,0,0,0,0,0,0,0,0,0,0
0,0,0,0,0,0,0,0,0,0,0,0,0,0,0,0
0,0,0,0,0,0,0,0,0,0,0,0,0,0,0,0
0,0,0,0,0,0,0,0,41,0,0,0,0,0,0,0
0,0,0,0,0,0,0,0,0,0,0,0,0,0,0,0
0,0,0,0,0,0,0,0,0,0,0,0,0,0,0,0
0,0,0,0,0,0,0,0,0,0,0,0,0,0,0,0
0,0,0,0,0,0,0,0,0,0,0,0,0,0,0,0
0,0,0,0,0,0,0,0,0,0,0,0,0,0,0,0
0,0,0,0,0,0,0,0,0,0,0,0,0,0,0,0
0,0,0,0,0,0,0,0,0,0,0,0,0,0,0,0
0,0,0,0,0,0,0,0,0,0,0,0,0,0,0,0
0,0,0,0,0,0,0,0,0,0,0,0,0,0,0,0
:endlayer
layer: 28
0,0,0,0,0,0,0,0,0,0,0,0,0,0,0,0
0,0,0,0,0,0,0,0,0,0,0,0,0,0,0,0
0,0,0,0,0,0,0,0,0,0,0,0,0,0,0,0
0,0,0,0,0,0,0,0,0,0,0,0,0,0,0,0
0,0,0,0,0,0,0,0,0,0,0,0,0,0,0,0
0,0,0,0,0,0,0,0,0,0,0,0,0,0,0,0
0,0,0,0,0,0,0,0,41,0,0,0,0,0,0,0
0,0,0,0,0,0,0,0,0,0,0,0,0,0,0,0
0,0,0,0,0,0,0,0,0,0,0,0,0,0,0,0
0,0,0,0,0,0,0,0,0,0,0,0,0,0,0,0
0,0,0,0,0,0,0,0,0,0,0,0,0,0,0,0
0,0,0,0,0,0,0,0,0,0,0,0,0,0,0,0
0,0,0,0,0,0,0,0,0,0,0,0,0,0,0,0
0,0,0,0,0,0,0,0,0,0,0,0,0,0,0,0
0,0,0,0,0,0,0,0,0,0,0,0,0,0,0,0
0,0,0,0,0,0,0,0,0,0,0,0,0,0,0,0
:endlayer
layer: 29
0,0,0,0,0,0,0,0,0,0,0,0,0,0,0,0
0,0,0,0,0,0,0,0,0,0,0,0,0,0,0,0
0,0,0,0,0,0,0,0,0,0,0,0,0,0,0,0
0,0,0,0,0,0,0,0,0,0,0,0,0,0,0,0
0,0,0,0,0,0,0,0,0,0,0,0,0,0,0,0
0,0,0,0,0,0,0,0,0,0,0,0,0,0,0,0
0,0,0,0,0,0,0,0,41,0,0,0,0,0,0,0
0,0,0,0,0,0,0,0,0,0,0,0,0,0,0,0
0,0,0,0,0,0,0,0,0,0,0,0,0,0,0,0
0,0,0,0,0,0,0,0,0,0,0,0,0,0,0,0
0,0,0,0,0,0,0,0,0,0,0,0,0,0,0,0
0,0,0,0,0,0,0,0,0,0,0,0,0,0,0,0
0,0,0,0,0,0,0,0,0,0,0,0,0,0,0,0
0,0,0,0,0,0,0,0,0,0,0,0,0,0,0,0
0,0,0,0,0,0,0,0,0,0,0,0,0,0,0,0
0,0,0,0,0,0,0,0,0,0,0,0,0,0,0,0
:endlayer
layer: 30
0,0,0,0,0,0,0,0,0,0,0,0,0,0,0,0
0,0,0,0,0,0,0,0,0,0,0,0,0,0,0,0
0,0,0,0,0,0,0,0,0,0,0,0,0,0,0,0
0,0,0,0,0,0,0,0,0,0,0,0,0,0,0,0
0,0,0,0,0,0,0,0,0,0,0,0,0,0,0,0
0,0,0,0,0,0,0,0,0,0,0,0,0,0,0,0
0,0,0,0,0,0,0,0,41,0,0,0,0,0,0,0
0,0,0,0,0,0,0,0,0,0,0,0,0,0,0,0
0,0,0,0,0,0,0,0,0,0,0,0,0,0,0,0
0,0,0,0,0,0,0,0,0,0,0,0,0,0,0,0
0,0,0,0,0,0,0,0,0,0,0,0,0,0,0,0
0,0,0,0,0,0,0,0,0,0,0,0,0,0,0,0
0,0,0,0,0,0,0,0,0,0,0,0,0,0,0,0
0,0,0,0,0,0,0,0,0,0,0,0,0,0,0,0
0,0,0,0,0,0,0,0,0,0,0,0,0,0,0,0
0,0,0,0,0,0,0,0,0,0,0,0,0,0,0,0
:endlayer
layer: 31
0,0,0,0,0,0,0,0,0,0,0,0,0,0,0,0
0,0,0,0,0,0,0,0,0,0,0,0,0,0,0,0
0,0,0,0,0,0,0,0,0,0,0,0,0,0,0,0
0,0,0,0,0,0,0,0,0,0,0,0,0,0,0,0
0,0,0,0,0,0,0,0,0,0,0,0,0,0,0,0
0,0,0,0,0,0,0,0,0,0,0,0,0,0,0,0
0,0,0,0,0,0,0,0,41,0,0,0,0,0,0,0
0,0,0,0,0,0,0,0,0,0,0,0,0,0,0,0
0,0,0,0,0,0,0,0,0,0,0,0,0,0,0,0
0,0,0,0,0,0,0,0,0,0,0,0,0,0,0,0
0,0,0,0,0,0,0,0,0,0,0,0,0,0,0,0
0,0,0,0,0,0,0,0,0,0,0,0,0,0,0,0
0,0,0,0,0,0,0,0,0,0,0,0,0,0,0,0
0,0,0,0,0,0,0,0,0,0,0,0,0,0,0,0
0,0,0,0,0,0,0,0,0,0,0,0,0,0,0,0
0,0,0,0,0,0,0,0,0,0,0,0,0,0,0,0
:endlayer

#### RULES ####
rule:
plugin=vanillaBlocks
number=1
data:
JSON:{blockState:{blockName:"minecraft:stonebrick",properties:{variant:"stonebrick"}}}
:enddata
:endrule

rule:
plugin=vanillaBlocks
number=2
data:
JSON:{blockState:{blockName:"minecraft:cobblestone"}}
:enddata
:endrule

rule:
plugin=vanillaBlocks
number=3
data:
JSON:{blockState:{blockName:"minecraft:dirt",properties:{variant:"dirt",snowy:"false"}}}
:enddata
:endrule

rule:
plugin=vanillaBlocks
number=4
data:
JSON:{blockState:{blockName:"minecraft:torch",properties:{facing:"south"}}}
:enddata
:endrule

rule:
plugin=vanillaBlocks
number=5
data:
JSON:{blockState:{blockName:"minecraft:torch",properties:{facing:"west"}}}
:enddata
:endrule

rule:
plugin=vanillaBlocks
number=6
data:
JSON:{blockState:{blockName:"minecraft:torch",properties:{facing:"east"}}}
:enddata
:endrule

rule:
plugin=vanillaBlocks
number=7
data:
JSON:{blockState:{blockName:"minecraft:stone_brick_stairs",properties:{half:"top",shape:"straight",facing:"west"}}}
:enddata
:endrule

rule:
plugin=vanillaBlocks
number=8
data:
JSON:{blockState:{blockName:"minecraft:stone_brick_stairs",properties:{half:"top",shape:"straight",facing:"east"}}}
:enddata
:endrule

rule:
plugin=vanillaBlocks
number=9
data:
JSON:{blockState:{blockName:"minecraft:stone",properties:{variant:"smooth_andesite"}}}
:enddata
:endrule

rule:
plugin=doors
number=10
data:
JSON:{blockState:{blockName:"minecraft:wooden_door",properties:{hinge:"left",half:"lower",powered:"false",facing:"north",open:"false"}}}
:enddata
:endrule

rule:
plugin=vanillaBlocks
number=11
data:
JSON:{blockState:{blockName:"minecraft:stone_brick_stairs",properties:{half:"bottom",shape:"straight",facing:"south"}}}
:enddata
:endrule

rule:
plugin=doors
number=12
data:
JSON:{blockState:{blockName:"minecraft:wooden_door",properties:{hinge:"left",half:"lower",powered:"false",facing:"east",open:"true"}}}
:enddata
:endrule

rule:
plugin=vanillaBlocks
number=13
data:
JSON:{blockState:{blockName:"minecraft:torch",properties:{facing:"up"}}}
:enddata
:endrule

rule:
plugin=doors
number=14
data:
JSON:{blockState:{blockName:"minecraft:wooden_door",properties:{hinge:"left",half:"lower",powered:"false",facing:"east",open:"false"}}}
:enddata
:endrule

rule:
plugin=vanillaBlocks
number=15
data:
JSON:{blockState:{blockName:"minecraft:stone_brick_stairs",properties:{half:"top",shape:"straight",facing:"south"}}}
:enddata
:endrule

rule:
plugin=doors
number=16
data:
JSON:{blockState:{blockName:"minecraft:wooden_door",properties:{hinge:"left",half:"upper",powered:"false",facing:"west",open:"false"}}}
:enddata
:endrule

rule:
plugin=vanillaBlocks
number=17
data:
JSON:{blockState:{blockName:"minecraft:torch",properties:{facing:"north"}}}
:enddata
:endrule

rule:
plugin=vanillaBlocks
number=18
data:
JSON:{blockState:{blockName:"minecraft:stone_brick_stairs",properties:{half:"bottom",shape:"straight",facing:"north"}}}
:enddata
:endrule

rule:
plugin=vanillaBlocks
number=19
data:
JSON:{blockState:{blockName:"minecraft:stone_brick_stairs",properties:{half:"top",shape:"straight",facing:"north"}}}
:enddata
:endrule

rule:
plugin=vanillaBlocks
number=20
data:
JSON:{blockState:{blockName:"minecraft:stone_stairs",properties:{half:"bottom",shape:"straight",facing:"west"}}}
:enddata
:endrule

rule:
plugin=vanillaBlocks
number=21
data:
JSON:{blockState:{blockName:"minecraft:stone_stairs",properties:{half:"bottom",shape:"straight",facing:"south"}}}
:enddata
:endrule

rule:
plugin=vanillaBlocks
number=22
data:
JSON:{blockState:{blockName:"minecraft:trapdoor",properties:{half:"bottom",facing:"west",open:"false"}}}
:enddata
:endrule

rule:
plugin=vanillaBlocks
number=23
data:
JSON:{blockState:{blockName:"minecraft:stone_stairs",properties:{half:"bottom",shape:"straight",facing:"north"}}}
:enddata
:endrule

rule:
plugin=vanillaBlocks
number=24
data:
JSON:{blockState:{blockName:"minecraft:stone_stairs",properties:{half:"bottom",shape:"straight",facing:"east"}}}
:enddata
:endrule

rule:
plugin=vanillaBlocks
number=25
data:
JSON:{blockState:{blockName:"minecraft:trapdoor",properties:{half:"bottom",facing:"east",open:"false"}}}
:enddata
:endrule

rule:
plugin=doors
number=26
data:
JSON:{blockState:{blockName:"minecraft:wooden_door",properties:{hinge:"left",half:"lower",powered:"false",facing:"west",open:"false"}}}
:enddata
:endrule

rule:
plugin=vanillaBlocks
number=27
data:
JSON:{blockState:{blockName:"minecraft:trapdoor",properties:{half:"top",facing:"west",open:"true"}}}
:enddata
:endrule

rule:
plugin=vanillaBlocks
number=28
data:
JSON:{blockState:{blockName:"minecraft:trapdoor",properties:{half:"top",facing:"south",open:"true"}}}
:enddata
:endrule

rule:
plugin=vanillaBlocks
number=29
data:
JSON:{blockState:{blockName:"minecraft:trapdoor",properties:{half:"top",facing:"north",open:"true"}}}
:enddata
:endrule

rule:
plugin=doors
number=30
data:
JSON:{blockState:{blockName:"minecraft:wooden_door",properties:{hinge:"right",half:"upper",powered:"false",facing:"west",open:"false"}}}
:enddata
:endrule

rule:
plugin=vanillaBlocks
number=31
data:
JSON:{blockState:{blockName:"minecraft:trapdoor",properties:{half:"top",facing:"east",open:"true"}}}
:enddata
:endrule

rule:
plugin=vanillaBlocks
number=32
data:
JSON:{blockState:{blockName:"minecraft:stone_stairs",properties:{half:"top",shape:"straight",facing:"east"}}}
:enddata
:endrule

rule:
plugin=vanillaBlocks
number=33
data:
JSON:{blockState:{blockName:"minecraft:stone_stairs",properties:{half:"top",shape:"straight",facing:"north"}}}
:enddata
:endrule

rule:
plugin=vanillaBlocks
number=34
data:
JSON:{blockState:{blockName:"minecraft:stone_stairs",properties:{half:"top",shape:"straight",facing:"south"}}}
:enddata
:endrule

rule:
plugin=vanillaBlocks
number=35
data:
JSON:{blockState:{blockName:"minecraft:stone_brick_stairs",properties:{half:"bottom",shape:"straight",facing:"east"}}}
:enddata
:endrule

rule:
plugin=vanillaBlocks
number=36
data:
JSON:{blockState:{blockName:"minecraft:stone_stairs",properties:{half:"top",shape:"straight",facing:"west"}}}
:enddata
:endrule

rule:
plugin=vanillaBlocks
number=37
data:
JSON:{blockState:{blockName:"minecraft:stone_brick_stairs",properties:{half:"bottom",shape:"straight",facing:"west"}}}
:enddata
:endrule

rule:
plugin=vanillaBlocks
number=38
data:
JSON:{blockState:{blockName:"minecraft:trapdoor",properties:{half:"bottom",facing:"north",open:"false"}}}
:enddata
:endrule

rule:
plugin=vanillaBlocks
number=39
data:
JSON:{blockState:{blockName:"minecraft:stone_slab",properties:{half:"bottom",variant:"stone_brick"}}}
:enddata
:endrule

rule:
plugin=vanillaBlocks
number=40
data:
JSON:{blockState:{blockName:"minecraft:cobblestone_wall",properties:{east:"false",south:"false",north:"false",variant:"cobblestone",west:"false",up:"false"}}}
:enddata
:endrule

rule:
plugin=vanillaBlocks
number=41
data:
JSON:{blockState:{blockName:"minecraft:fence",properties:{east:"false",south:"false",north:"false",west:"false"}}}
:enddata
:endrule

#### ENTITIES ####
