# Ancient Warfare Structure Template File
# Auto-generated structure template file. created on: 3/6/2024 at: 22:48:32
# Lines beginning with # denote comments

header:
version=2.11
name=SarkonidPashaCastle
mods=
size=41,37,31
offset=20,5,30
:endheader

#### VALIDATION ####
validation:
type=ground
structureAuthor=TheOddlySeagull
survival=false
worldGenEnabled=true
unique=false
preserveBlocks=false
preventNaturalHostileSpawns=true
selectionWeight=20
clusterValue=50
minDuplicateDistance=5000
dimensionWhiteList=true
dimensionList=0
biomeGroupList=sarkonid
biomeWhiteList=true
biomeList=environs:sandstone_ranges,nt:sahel,minecraft:desert,minecraft:mutated_desert,minecraft:desert_hills
leveling=10
fill=10
border=6
blockSwap=false
territoryName=sarkonid
biomeReplacement=minecraft:
minGenerationHeight=0
maxGenerationHeight=255
:endvalidation

#### LAYERS ####
layer: 0
1,1,1,1,1,1,1,1,1,1,1,1,1,1,1,1,1,1,1,1,1,1,1,1,1,1,1,1,1,1,1,1,1,1,1,1,1,1,1,1,1
1,1,1,1,1,1,1,1,1,1,1,1,1,1,1,1,1,1,1,1,1,1,1,1,1,1,1,1,1,1,1,1,1,1,1,1,1,1,1,1,1
1,1,1,1,1,1,1,1,1,1,1,1,1,1,1,1,1,1,1,1,1,1,1,1,1,1,1,1,1,1,1,1,1,1,1,1,1,1,1,1,1
1,1,1,1,1,1,1,1,1,1,1,1,1,1,1,1,1,1,1,1,1,1,1,1,1,1,1,1,1,1,1,1,1,1,1,1,1,1,1,1,1
1,1,1,1,1,1,1,1,1,1,1,1,1,1,1,1,1,1,1,1,1,1,1,1,1,1,1,1,1,1,1,1,1,1,1,1,1,1,1,1,1
1,1,1,1,1,1,1,1,1,1,1,1,1,1,1,1,1,1,1,1,1,1,1,1,1,1,1,1,1,1,1,1,1,1,1,1,1,1,1,1,1
1,1,1,1,1,1,1,1,1,1,1,1,1,1,1,1,1,1,1,1,1,1,1,1,1,1,1,1,1,1,1,1,1,1,1,1,1,1,1,1,1
1,1,1,1,1,1,1,1,1,1,1,1,1,1,1,1,1,1,1,1,1,1,1,1,1,1,1,1,1,1,1,1,1,1,1,1,1,1,1,1,1
1,1,1,1,1,1,1,1,1,1,1,1,1,1,1,1,1,1,1,1,1,1,1,1,1,1,1,1,1,1,1,1,1,1,1,1,1,1,1,1,1
1,1,1,1,1,1,1,1,1,1,1,1,1,1,1,1,1,1,1,1,1,1,1,1,1,1,1,1,1,1,1,1,1,1,1,1,1,1,1,1,1
1,1,1,1,1,1,1,1,1,1,1,1,1,1,1,1,1,1,1,1,1,1,1,1,1,1,1,1,1,1,1,1,1,1,1,1,1,1,1,1,1
1,1,1,1,1,1,1,1,1,1,1,1,1,1,1,1,1,1,1,1,1,1,1,1,1,1,1,1,1,1,1,1,1,1,1,1,1,1,1,1,1
1,1,1,1,1,1,1,1,1,1,1,1,1,1,1,1,1,1,1,1,1,1,1,1,1,1,1,1,1,1,1,1,1,1,1,1,1,1,1,1,1
1,1,1,1,1,1,1,1,1,1,1,1,1,1,1,1,1,1,1,1,1,1,1,1,1,1,1,1,1,1,1,1,1,1,1,1,1,1,1,1,1
1,1,1,1,1,1,1,1,1,1,1,1,1,1,1,1,1,1,1,1,1,1,1,1,1,1,1,1,1,1,1,1,1,1,1,1,1,1,1,1,1
1,1,1,1,1,1,1,1,1,1,1,1,1,1,1,1,1,1,1,1,1,1,1,1,1,1,1,1,1,1,1,1,1,1,1,1,1,1,1,1,1
1,1,1,1,1,1,1,1,1,1,1,1,1,1,1,1,1,1,1,1,1,1,1,1,1,1,1,1,1,1,1,1,1,1,1,1,1,1,1,1,1
1,1,1,1,1,1,1,1,1,1,1,1,1,1,1,1,1,1,1,1,1,1,1,1,1,1,1,1,1,1,1,1,1,1,1,1,1,1,1,1,1
1,1,1,1,1,1,1,1,1,1,1,1,1,1,1,1,1,1,1,1,1,1,1,1,1,1,1,1,1,1,1,1,1,1,1,1,1,1,1,1,1
1,1,1,1,1,1,1,1,1,1,1,1,1,1,1,1,1,1,1,1,1,1,1,1,1,1,1,1,1,1,1,1,1,1,1,1,1,1,1,1,1
1,1,1,1,1,1,1,1,1,1,1,1,1,1,1,1,1,1,1,1,1,1,1,1,1,1,1,1,1,1,1,1,1,1,1,1,1,1,1,1,1
1,1,1,1,1,1,1,1,1,1,1,1,1,1,1,1,1,1,1,1,1,1,1,1,1,1,1,1,1,1,1,1,1,1,1,1,1,1,1,1,1
1,1,1,1,1,1,1,1,1,1,1,1,1,1,1,1,1,1,1,1,1,1,1,1,1,1,1,1,1,1,1,1,1,1,1,1,1,1,1,1,1
1,1,1,1,1,1,1,1,1,1,1,1,1,1,1,1,1,1,1,1,1,1,1,1,1,1,1,1,1,1,1,1,1,1,1,1,1,1,1,1,1
1,1,1,1,1,1,1,1,1,1,1,1,1,1,1,1,1,1,1,1,1,1,1,1,1,1,1,1,1,1,1,1,1,1,1,1,1,1,1,1,1
1,1,1,1,1,1,1,1,1,1,1,1,1,1,1,1,1,1,1,1,1,1,1,1,1,1,1,1,1,1,1,1,1,1,1,1,1,1,1,1,1
1,1,1,1,1,1,1,1,1,1,1,1,1,1,1,1,1,1,1,1,1,1,1,1,1,1,1,1,1,1,1,1,1,1,1,1,1,1,1,1,1
1,1,1,1,1,1,1,1,1,1,1,1,1,1,1,1,1,1,1,1,1,1,1,1,1,1,1,1,1,1,1,1,1,1,1,1,1,1,1,1,1
1,1,1,1,1,1,1,1,1,1,1,1,1,1,1,1,1,1,1,1,1,1,1,1,1,1,1,1,1,1,1,1,1,1,1,1,1,1,1,1,1
1,1,1,1,1,1,1,1,1,1,1,1,1,1,1,1,1,1,1,1,1,1,1,1,1,1,1,1,1,1,1,1,1,1,1,1,1,1,1,1,1
1,1,1,1,1,1,1,1,1,1,1,1,1,1,1,1,1,1,1,1,1,1,1,1,1,1,1,1,1,1,1,1,1,1,1,1,1,1,1,1,1
:endlayer
layer: 1
1,1,1,1,1,1,1,1,1,1,1,1,1,1,1,1,1,1,1,1,1,1,1,1,1,1,1,1,1,1,1,1,1,1,1,1,1,1,1,1,1
1,1,1,1,1,1,1,1,1,1,1,1,1,1,1,1,1,1,1,1,1,1,1,1,1,1,1,1,1,1,1,1,1,1,1,1,1,1,1,1,1
1,1,1,1,1,1,1,1,1,1,1,1,1,1,1,1,1,1,1,1,1,1,1,1,1,1,1,1,1,1,1,1,1,1,1,1,1,1,1,1,1
1,1,1,1,1,1,1,1,1,1,1,1,1,1,1,1,1,1,1,1,1,1,1,1,1,1,1,1,1,1,1,1,1,1,1,1,1,1,1,1,1
1,1,1,1,1,1,1,1,1,1,1,1,1,1,1,1,1,1,1,1,1,1,1,1,1,1,1,1,1,1,1,1,1,1,1,1,1,1,1,1,1
1,1,1,1,1,1,1,1,1,1,1,1,1,1,1,1,1,1,1,1,1,1,1,1,1,1,1,1,1,1,1,1,1,1,1,1,1,1,1,1,1
1,1,1,1,1,1,1,1,1,1,1,1,1,1,1,1,1,1,1,1,1,1,1,1,1,1,1,1,1,1,1,1,1,1,1,1,1,1,1,1,1
1,1,1,1,1,1,1,1,1,1,1,1,1,1,1,1,1,1,1,1,1,1,1,1,1,1,1,1,1,1,1,1,1,1,1,1,1,1,1,1,1
1,1,1,1,1,1,1,1,1,1,1,1,1,1,1,1,1,1,1,1,1,1,1,1,1,1,1,1,1,1,1,1,1,1,1,1,1,1,1,1,1
1,1,1,1,1,1,1,1,1,1,1,1,1,1,1,1,1,1,1,1,1,1,1,1,1,1,1,1,1,1,1,1,1,1,1,1,1,1,1,1,1
1,1,1,1,1,1,1,1,1,1,1,1,1,1,1,1,1,1,1,1,1,1,1,1,1,1,1,1,1,1,1,1,1,1,1,1,1,1,1,1,1
1,1,1,1,1,1,1,1,1,1,1,1,1,1,1,1,1,1,1,1,1,1,1,1,1,1,1,1,1,1,1,1,1,1,1,1,1,1,1,1,1
1,1,1,1,1,1,1,1,1,1,1,1,1,1,1,1,1,1,1,1,1,1,1,1,1,1,1,1,1,1,1,1,1,1,1,1,1,1,1,1,1
1,1,1,1,1,1,1,1,1,1,1,1,1,1,1,1,1,1,1,1,1,1,1,1,1,1,1,1,1,1,1,1,1,1,1,1,1,1,1,1,1
1,1,1,1,1,1,1,1,1,1,1,1,1,1,1,1,1,1,1,1,1,1,1,1,1,1,1,1,1,1,1,1,1,1,1,1,1,1,1,1,1
1,1,1,1,1,1,1,1,1,1,1,1,1,1,1,1,1,1,1,1,1,1,1,1,1,1,1,1,1,1,1,1,1,1,1,1,1,1,1,1,1
1,1,1,1,1,1,1,1,1,1,1,1,1,1,1,1,1,1,1,1,1,1,1,1,1,1,1,1,1,1,1,1,1,1,1,1,1,1,1,1,1
1,1,1,1,1,1,1,1,1,1,1,1,1,1,1,1,1,1,1,1,1,1,1,1,1,1,1,1,1,1,1,1,1,1,1,1,1,1,1,1,1
1,1,1,1,1,1,1,1,1,1,1,1,1,1,1,1,1,1,1,1,1,1,1,1,1,1,1,1,1,1,1,1,1,1,1,1,1,1,1,1,1
1,1,1,1,1,1,1,1,1,1,1,1,1,1,1,1,1,1,1,1,1,1,1,1,1,1,1,1,1,1,1,1,1,1,1,1,1,1,1,1,1
1,1,1,1,1,1,1,1,1,1,1,1,1,1,1,1,1,1,1,1,1,1,1,1,1,1,1,1,1,1,1,1,1,1,1,1,1,1,1,1,1
1,1,1,1,1,1,1,1,1,1,1,1,1,1,1,1,1,1,1,1,1,1,1,1,1,1,1,1,1,1,1,1,1,1,1,1,1,1,1,1,1
1,1,1,1,1,1,1,1,1,1,1,1,1,1,1,1,1,1,1,1,1,1,1,1,1,1,1,1,1,1,1,1,1,1,1,1,1,1,1,1,1
1,1,1,1,1,1,1,1,1,1,1,1,1,1,1,1,1,1,1,1,1,1,1,1,1,1,1,1,1,1,1,1,1,1,1,1,1,1,1,1,1
1,1,1,1,1,1,1,1,1,1,1,1,1,1,1,1,1,1,1,1,1,1,1,1,1,1,1,1,1,1,1,1,1,1,1,1,1,1,1,1,1
1,1,1,1,1,1,1,1,1,1,1,1,1,1,1,1,1,1,1,1,1,1,1,1,1,1,1,1,1,1,1,1,1,1,1,1,1,1,1,1,1
1,1,1,1,1,1,1,1,1,1,1,1,1,1,1,1,1,1,1,1,1,1,1,1,1,1,1,1,1,1,1,1,1,1,1,1,1,1,1,1,1
1,1,1,1,1,1,1,1,1,1,1,1,1,1,1,1,1,1,1,1,1,1,1,1,1,1,1,1,1,1,1,1,1,1,1,1,1,1,1,1,1
1,1,1,1,1,1,1,1,1,1,1,1,1,1,1,1,1,1,1,1,1,1,1,1,1,1,1,1,1,1,1,1,1,1,1,1,1,1,1,1,1
1,1,1,1,1,1,1,1,1,1,1,1,1,1,1,1,1,1,1,1,1,1,1,1,1,1,1,1,1,1,1,1,1,1,1,1,1,1,1,1,1
1,1,1,1,1,1,1,1,1,1,1,1,1,1,1,1,1,1,1,1,1,1,1,1,1,1,1,1,1,1,1,1,1,1,1,1,1,1,1,1,1
:endlayer
layer: 2
1,1,1,1,1,1,1,1,1,1,1,1,1,1,1,1,1,1,1,1,1,1,1,1,1,1,1,1,1,1,1,1,1,1,1,1,1,1,1,1,1
1,1,1,1,1,1,1,1,1,1,1,1,1,1,1,1,1,1,1,1,1,1,1,1,1,1,1,1,1,1,1,1,1,1,1,1,1,1,1,1,1
1,1,1,1,1,1,1,1,1,1,1,1,1,1,1,1,1,1,1,1,1,1,1,1,1,1,1,1,1,1,1,1,1,1,1,1,1,1,1,1,1
1,1,1,1,1,1,1,1,1,1,1,1,1,1,1,1,1,1,1,1,1,1,1,1,1,1,1,1,1,1,1,1,1,1,1,1,1,1,1,1,1
1,1,1,1,1,1,1,1,1,1,1,1,1,1,1,1,1,1,1,1,1,1,1,1,1,1,1,1,1,1,1,1,1,1,1,1,1,1,1,1,1
1,1,1,1,1,1,1,1,1,1,1,1,1,1,1,1,1,1,1,1,1,1,1,1,1,1,1,1,1,1,1,1,1,1,1,1,1,1,1,1,1
1,1,1,1,1,1,1,1,1,1,1,1,1,1,1,1,1,1,1,1,1,1,1,1,1,1,1,1,1,1,1,1,1,1,1,1,1,1,1,1,1
1,1,1,1,1,1,1,1,1,1,1,1,1,1,1,1,1,1,1,1,1,1,1,1,1,1,1,1,1,1,1,1,1,1,1,1,1,1,1,1,1
1,1,1,1,1,1,1,1,1,1,1,1,1,1,1,1,1,1,1,1,1,1,1,1,1,1,1,1,1,1,1,1,1,1,1,1,1,1,1,1,1
1,1,1,1,1,1,1,1,1,1,1,1,1,1,1,1,1,1,1,1,1,1,1,1,1,1,1,1,1,1,1,1,1,1,1,1,1,1,1,1,1
1,1,1,1,1,1,1,1,1,1,1,1,1,1,1,1,1,1,1,1,1,1,1,1,1,1,1,1,1,1,1,1,1,1,1,1,1,1,1,1,1
1,1,1,1,1,1,1,1,1,1,1,1,1,1,1,1,1,1,1,1,1,1,1,1,1,1,1,1,1,1,1,1,1,1,1,1,1,1,1,1,1
1,1,1,1,1,1,1,1,1,1,1,1,1,1,1,1,1,1,1,1,1,1,1,1,1,1,1,1,1,1,1,1,1,1,1,1,1,1,1,1,1
1,1,1,1,1,1,1,1,1,1,1,1,1,1,1,1,1,1,1,1,1,1,1,1,1,1,1,1,1,1,1,1,1,1,1,1,1,1,1,1,1
1,1,1,1,1,1,1,1,1,1,1,1,1,1,1,1,1,1,1,1,1,1,1,1,1,1,1,1,1,1,1,1,1,1,1,1,1,1,1,1,1
1,1,1,1,1,1,1,1,1,1,1,1,1,1,1,1,1,1,1,1,1,1,1,1,1,1,1,1,1,1,1,1,1,1,1,1,1,1,1,1,1
1,1,1,1,1,1,1,1,1,1,1,1,1,1,1,1,1,1,1,1,1,1,1,1,1,1,1,1,1,1,1,1,1,1,1,1,1,1,1,1,1
1,1,1,1,1,1,1,1,1,1,1,1,1,1,1,1,1,1,1,1,1,1,1,1,1,1,1,1,1,1,1,1,1,1,1,1,1,1,1,1,1
1,1,1,1,1,1,1,1,1,1,1,1,1,1,1,1,1,1,1,1,1,1,1,1,1,1,1,1,1,1,1,1,1,1,1,1,1,1,1,1,1
1,1,1,1,1,1,1,1,1,1,1,1,1,1,1,1,1,1,1,1,1,1,1,1,1,1,1,1,1,1,1,1,1,1,1,1,1,1,1,1,1
1,1,1,1,1,1,1,1,1,1,1,1,1,1,1,1,1,1,1,1,1,1,1,1,1,1,1,1,1,1,1,1,1,1,1,1,1,1,1,1,1
1,1,1,1,1,1,1,1,1,1,1,1,1,1,1,1,1,1,1,1,1,1,1,1,1,1,1,1,1,1,1,1,1,1,1,1,1,1,1,1,1
1,1,1,1,1,1,1,1,1,1,1,1,1,1,1,1,1,1,1,1,1,1,1,1,1,1,1,1,1,1,1,1,1,1,1,1,1,1,1,1,1
1,1,1,1,1,1,1,1,1,1,1,1,1,1,1,1,1,1,1,1,1,1,1,1,1,1,1,1,1,1,1,1,1,1,1,1,1,1,1,1,1
1,1,1,1,1,1,1,1,1,1,1,1,1,1,1,1,1,1,1,1,1,1,1,1,1,1,1,1,1,1,1,1,1,1,1,1,1,1,1,1,1
1,1,1,1,1,1,1,1,1,1,1,1,1,1,1,1,1,1,1,1,1,1,1,1,1,1,1,1,1,1,1,1,1,1,1,1,1,1,1,1,1
1,1,1,1,1,1,1,1,1,1,1,1,1,1,1,1,1,1,1,1,1,1,1,1,1,1,1,1,1,1,1,1,1,1,1,1,1,1,1,1,1
1,1,1,1,1,1,1,1,1,1,1,1,1,1,1,1,1,1,1,1,1,1,1,1,1,1,1,1,1,1,1,1,1,1,1,1,1,1,1,1,1
1,1,1,1,1,1,1,1,1,1,1,1,1,1,1,1,1,1,1,1,1,1,1,1,1,1,1,1,1,1,1,1,1,1,1,1,1,1,1,1,1
1,1,1,1,1,1,1,1,1,1,1,1,1,1,1,1,1,1,1,1,1,1,1,1,1,1,1,1,1,1,1,1,1,1,1,1,1,1,1,1,1
1,1,1,1,1,1,1,1,1,1,1,1,1,1,1,1,1,1,1,1,1,1,1,1,1,1,1,1,1,1,1,1,1,1,1,1,1,1,1,1,1
:endlayer
layer: 3
2,2,2,2,2,2,2,2,2,2,2,2,2,2,2,2,2,2,2,2,2,2,2,2,2,2,2,2,2,2,2,2,2,2,2,2,2,2,2,2,2
2,2,2,2,2,2,2,2,2,2,2,2,2,2,2,2,2,2,2,2,2,2,2,2,2,2,2,2,2,2,2,2,2,2,2,2,2,2,2,2,2
2,2,1,1,1,1,1,1,1,2,2,2,2,2,2,2,2,2,2,2,2,2,2,2,2,2,2,2,2,2,2,2,1,1,1,1,1,1,1,2,2
2,2,1,2,2,2,2,2,1,2,2,1,1,1,1,1,2,2,2,2,2,2,2,2,2,1,1,1,1,1,2,2,1,2,2,2,2,2,1,2,2
2,2,1,2,2,2,2,2,1,1,1,1,1,1,1,1,1,1,2,2,2,2,2,1,1,1,1,1,1,1,1,1,1,2,2,2,2,2,1,2,2
2,2,1,2,2,2,2,2,1,2,2,2,2,2,2,2,2,2,2,2,2,2,2,2,2,2,2,2,2,2,2,2,1,2,2,2,2,2,1,2,2
2,2,1,2,2,2,2,2,1,1,1,1,1,1,1,1,1,1,1,1,1,1,1,1,1,1,1,1,1,1,1,1,1,2,2,2,2,2,1,2,2
2,2,1,2,2,2,2,2,1,2,2,2,2,1,1,1,1,1,1,1,1,1,1,1,1,1,1,1,2,2,2,2,1,2,2,2,2,2,1,2,2
2,2,1,1,1,1,1,1,1,2,2,2,2,1,1,1,1,1,1,1,1,1,1,1,1,1,1,1,2,2,2,2,1,1,1,1,1,1,1,2,2
2,2,2,2,1,2,1,2,2,2,2,2,1,1,1,1,1,1,1,1,1,1,1,1,1,1,1,1,1,2,2,2,2,2,1,2,1,2,2,2,2
2,2,2,2,1,2,1,2,2,2,2,2,1,2,2,2,2,2,2,2,2,2,2,2,2,2,2,2,1,2,2,2,2,2,1,2,1,2,2,2,2
2,2,2,2,1,2,1,2,2,2,2,2,1,2,2,2,2,2,2,2,2,2,2,2,2,2,2,2,1,2,2,2,2,2,1,2,1,2,2,2,2
2,2,2,2,1,2,1,2,2,2,2,2,1,2,2,2,2,2,2,2,2,2,2,2,2,2,2,2,1,2,2,2,2,2,1,2,1,2,2,2,2
2,2,2,1,1,2,1,2,2,2,2,1,1,2,2,2,2,2,2,2,2,2,2,2,2,2,2,2,1,1,2,2,2,2,1,2,1,1,2,2,2
2,2,2,1,1,2,1,2,2,2,2,1,2,2,2,2,2,2,2,2,2,2,2,2,2,2,2,2,2,1,2,2,2,2,1,2,1,1,2,2,2
2,2,2,1,1,2,1,2,2,2,2,1,2,2,2,2,2,2,2,2,2,2,2,2,2,2,2,2,2,1,2,2,2,2,1,2,1,1,2,2,2
2,2,2,1,1,2,1,2,2,2,2,1,2,2,2,2,2,2,2,2,2,2,2,2,2,2,2,2,2,1,2,2,2,2,1,2,1,1,2,2,2
2,2,2,1,1,2,1,2,2,2,2,1,2,2,2,2,2,1,1,1,1,1,1,1,2,2,2,2,2,1,2,2,2,2,1,2,1,1,2,2,2
2,2,2,2,1,2,1,2,2,2,2,1,2,2,2,2,2,1,2,2,2,2,2,1,2,2,2,2,2,1,2,2,2,2,1,2,1,2,2,2,2
2,2,2,2,1,2,1,2,2,2,2,1,1,1,1,1,1,1,2,2,2,2,2,1,1,1,1,1,1,1,2,2,2,2,1,2,1,2,2,2,2
2,2,2,2,1,2,1,2,2,2,2,2,2,2,2,2,2,2,2,2,2,2,2,2,2,2,2,2,2,2,2,2,2,2,1,2,1,2,2,2,2
2,2,2,2,1,2,1,2,2,2,2,2,2,2,2,2,2,2,2,2,2,2,2,2,2,2,2,2,2,2,2,2,2,2,1,2,1,2,2,2,2
2,2,1,1,1,1,1,1,1,2,2,2,2,2,2,2,2,2,2,2,2,2,2,2,2,2,2,2,2,2,2,2,1,1,1,1,1,1,1,2,2
2,2,1,2,2,2,2,2,1,2,2,1,2,2,2,1,2,2,2,2,2,2,2,2,2,1,2,2,2,1,2,2,1,2,2,2,2,2,1,2,2
2,2,1,2,2,2,2,2,1,1,1,2,2,2,2,2,1,1,1,1,1,1,1,1,1,2,2,2,2,2,1,1,1,2,2,2,2,2,1,2,2
2,2,1,2,2,2,2,2,1,2,2,2,2,2,2,2,2,2,2,2,2,2,2,2,2,2,2,2,2,2,2,2,1,2,2,2,2,2,1,2,2
2,2,1,2,2,2,2,2,1,1,1,1,1,1,1,1,1,1,2,2,2,2,2,1,1,1,1,1,1,1,1,1,1,2,2,2,2,2,1,2,2
2,2,1,2,2,2,2,2,1,2,2,1,1,1,1,1,2,2,2,2,2,2,2,2,2,1,1,1,1,1,2,2,1,2,2,2,2,2,1,2,2
2,2,1,1,1,1,1,1,1,2,2,2,2,2,2,2,2,2,2,2,2,2,2,2,2,2,2,2,2,2,2,2,1,1,1,1,1,1,1,2,2
2,2,2,2,2,2,2,2,2,2,2,2,2,2,2,2,2,2,2,2,2,2,2,2,2,2,2,2,2,2,2,2,2,2,2,2,2,2,2,2,2
2,2,2,2,2,2,2,2,2,2,2,2,2,2,2,2,2,2,2,2,2,2,2,2,2,2,2,2,2,2,2,2,2,2,2,2,2,2,2,2,2
:endlayer
layer: 4
2,2,2,2,2,2,2,2,2,2,2,2,2,2,2,2,2,2,2,2,2,2,2,2,2,2,2,2,2,2,2,2,2,2,2,2,2,2,2,2,2
2,2,2,2,2,2,2,2,2,2,2,2,2,2,2,2,2,2,2,2,2,2,2,2,2,2,2,2,2,2,2,2,2,2,2,2,2,2,2,2,2
2,2,1,1,1,1,1,1,1,2,2,2,2,2,2,2,2,2,2,2,2,2,2,2,2,2,2,2,2,2,2,2,1,1,1,1,1,1,1,2,2
2,2,1,1,1,1,1,1,1,2,2,1,1,1,1,1,2,2,2,2,2,2,2,2,2,1,1,1,1,1,2,2,1,1,1,1,1,1,1,2,2
2,2,1,1,1,1,1,1,1,1,1,1,1,1,1,1,1,1,2,2,2,2,2,1,1,1,1,1,1,1,1,1,1,1,1,1,1,1,1,2,2
2,2,1,1,1,1,1,1,1,1,1,1,1,1,1,1,1,1,1,1,1,1,1,1,1,1,1,1,1,1,1,1,1,1,1,1,1,1,1,2,2
2,2,1,1,1,1,1,1,1,1,1,1,1,1,1,1,1,1,1,1,1,1,1,1,1,1,1,1,1,1,1,1,1,1,1,1,1,1,1,2,2
2,2,1,1,1,1,1,1,1,3,3,3,3,1,1,1,1,1,1,1,1,1,1,1,1,1,1,1,3,3,3,3,1,1,1,1,1,1,1,2,2
2,2,1,1,1,1,1,1,1,3,3,3,3,1,1,1,1,1,1,1,1,1,1,1,1,1,1,1,3,3,3,3,1,1,1,1,1,1,1,2,2
2,2,2,2,1,1,1,3,3,4,4,4,1,1,1,1,1,1,1,1,1,1,1,1,1,1,1,1,1,4,4,4,3,3,1,1,1,2,2,2,2
2,2,2,2,1,1,1,3,3,4,4,4,1,5,5,5,5,5,5,5,5,5,6,6,5,5,5,5,1,4,4,4,3,3,1,1,1,2,2,2,2
2,2,2,2,1,1,1,3,3,4,4,4,1,5,6,6,6,6,6,5,5,5,5,5,5,6,6,5,1,4,4,4,3,3,1,1,1,2,2,2,2
2,2,2,2,1,1,1,3,3,4,4,4,1,5,6,6,6,6,6,5,5,5,6,6,6,6,6,5,1,4,4,4,3,3,1,1,1,2,2,2,2
2,2,2,1,1,1,1,3,3,4,4,1,1,5,6,6,6,6,6,5,5,5,6,6,6,6,6,5,1,1,4,4,3,3,1,1,1,1,2,2,2
2,2,2,1,1,1,1,3,3,4,4,1,5,5,6,6,6,6,6,5,5,5,6,6,6,6,6,5,5,1,4,4,3,3,1,1,1,1,2,2,2
2,2,2,1,1,1,1,3,3,4,4,1,5,6,6,6,6,6,6,5,5,5,6,6,6,6,6,6,5,1,4,4,3,3,1,1,1,1,2,2,2
2,2,2,1,1,1,1,3,3,4,4,1,5,6,6,6,5,5,5,5,5,5,5,5,5,6,6,6,5,1,4,4,3,3,1,1,1,1,2,2,2
2,2,2,1,1,1,1,3,3,4,4,1,5,6,6,6,5,1,1,1,1,1,1,1,5,6,6,6,5,1,4,4,3,3,1,1,1,1,2,2,2
2,2,2,2,1,1,1,3,3,4,4,1,5,5,5,5,5,1,4,3,3,3,4,1,5,5,5,5,5,1,4,4,3,3,1,1,1,2,2,2,2
2,2,2,2,1,1,1,3,3,4,4,1,1,1,1,1,1,1,4,3,3,3,4,1,1,1,1,1,1,1,4,4,3,3,1,1,1,2,2,2,2
2,2,2,2,1,1,1,3,3,4,4,4,4,4,4,4,4,4,4,3,3,3,4,4,4,4,4,4,4,4,4,4,3,3,1,1,1,2,2,2,2
2,2,2,2,1,1,1,3,3,4,4,4,4,4,4,4,4,4,4,3,3,3,4,4,4,4,4,4,4,4,4,4,3,3,1,1,1,2,2,2,2
2,2,1,1,1,1,1,1,1,3,3,3,3,3,3,3,3,3,3,3,3,3,3,3,3,3,3,3,3,3,3,3,1,1,1,1,1,1,1,2,2
2,2,1,1,1,1,1,1,1,3,4,1,1,1,1,1,4,4,4,3,3,3,4,4,4,1,1,1,1,1,4,3,1,1,1,1,1,1,1,2,2
2,2,1,1,1,1,1,1,1,1,1,1,1,1,1,1,1,1,1,1,1,1,1,1,1,1,1,1,1,1,1,1,1,1,1,1,1,1,1,2,2
2,2,1,1,1,1,1,1,1,7,7,1,1,1,1,1,8,8,8,8,8,8,8,8,8,1,1,1,1,1,7,7,1,1,1,1,1,1,1,2,2
2,2,1,1,1,1,1,1,1,1,1,1,1,1,1,1,1,1,1,1,1,1,1,1,1,1,1,1,1,1,1,1,1,1,1,1,1,1,1,2,2
2,2,1,1,1,1,1,1,1,2,2,1,1,1,1,1,2,2,2,2,2,2,2,2,2,1,1,1,1,1,2,2,1,1,1,1,1,1,1,2,2
2,2,1,1,1,1,1,1,1,2,2,2,2,2,2,2,2,2,2,2,2,2,2,2,2,2,2,2,2,2,2,2,1,1,1,1,1,1,1,2,2
2,2,2,2,2,2,2,2,2,2,2,2,2,2,2,2,2,2,2,2,2,2,2,2,2,2,2,2,2,2,2,2,2,2,2,2,2,2,2,2,2
2,2,2,2,2,2,2,2,2,2,2,2,2,2,2,2,2,2,2,2,2,2,2,2,2,2,2,2,2,2,2,2,2,2,2,2,2,2,2,2,2
:endlayer
layer: 5
0,0,0,0,0,0,0,0,0,0,0,0,0,0,0,0,0,0,0,0,0,0,0,0,0,0,0,0,0,0,0,0,0,0,0,0,0,0,0,0,0
0,9,0,0,0,0,0,0,0,0,0,0,0,0,0,0,0,0,0,0,0,0,0,0,0,0,0,0,0,0,0,0,0,0,0,0,0,0,0,10,0
0,0,1,1,1,1,1,1,1,0,0,0,0,0,0,0,0,0,0,0,0,0,0,0,0,0,0,0,0,0,0,0,1,1,1,1,1,1,1,0,0
0,0,1,11,11,11,11,11,1,0,12,1,1,1,1,1,12,0,0,0,0,0,0,0,12,1,1,1,1,1,12,0,1,11,11,11,11,11,1,0,0
0,0,1,13,0,0,0,0,1,1,1,14,14,14,14,14,1,1,1,1,1,1,1,1,1,14,14,14,14,14,1,1,1,0,0,0,0,15,1,0,0
0,0,1,13,0,16,0,0,1,17,0,0,0,0,0,0,0,0,0,0,0,0,0,0,0,0,0,0,0,0,0,18,1,0,0,19,0,15,1,0,0
0,0,1,13,0,0,0,0,1,1,1,1,20,1,1,1,1,1,1,0,0,0,1,1,1,1,1,1,20,1,1,1,1,0,0,0,0,15,1,0,0
0,0,1,13,0,0,0,0,0,0,0,0,0,15,1,1,1,1,21,0,22,0,23,1,1,1,1,13,0,0,0,0,0,0,0,0,0,15,1,0,0
0,0,1,1,1,1,1,0,0,0,0,0,0,15,1,1,1,1,24,0,0,0,23,1,1,1,1,13,0,0,0,0,0,0,1,1,1,1,1,0,0
0,0,0,0,1,25,1,0,0,0,0,0,1,1,1,1,1,1,1,0,0,0,1,1,1,1,1,1,1,0,0,0,0,0,1,26,1,0,0,0,0
0,0,0,0,1,0,1,0,0,0,0,0,27,0,0,0,0,0,0,0,0,0,15,1,28,28,28,28,29,0,0,0,0,0,1,0,1,0,0,0,0
0,0,0,0,1,0,30,0,0,0,0,0,27,0,31,32,32,33,0,0,0,0,0,0,34,35,35,36,29,0,0,0,0,0,37,0,1,0,0,0,0
0,0,0,12,1,0,1,0,0,0,0,12,1,0,38,32,32,39,0,0,0,0,0,0,0,0,35,36,1,12,0,0,0,0,1,0,1,12,0,0,0
0,0,0,1,29,0,29,0,0,0,0,1,1,0,40,32,32,41,0,0,42,0,0,32,32,0,35,36,1,1,0,0,0,0,27,0,27,1,0,0,0
0,0,0,1,29,0,1,0,0,0,0,1,0,0,43,32,32,44,0,0,0,0,0,32,32,0,45,36,46,1,0,0,0,0,1,0,27,1,0,0,0
0,0,0,1,29,0,29,0,0,0,0,27,47,47,47,47,47,0,0,0,0,0,0,0,0,0,0,0,0,29,0,0,0,0,27,0,27,1,0,0,0
0,0,0,1,29,0,1,0,0,0,0,27,47,47,47,47,47,0,0,0,0,0,48,0,0,0,0,0,0,29,0,0,0,0,1,0,27,1,0,0,0
0,0,0,1,29,0,29,0,0,0,0,27,47,47,47,47,47,1,1,49,50,51,1,1,0,0,0,0,0,29,0,0,0,0,27,0,27,1,0,0,0
0,0,0,12,1,0,1,0,0,0,0,1,52,53,32,54,55,1,12,0,0,0,56,1,57,58,32,59,60,1,0,0,0,0,1,0,1,12,0,0,0
0,0,0,0,1,0,30,0,0,0,0,1,1,14,14,14,1,1,61,0,0,0,62,1,1,14,14,14,1,1,0,0,0,0,37,0,1,0,0,0,0
0,0,0,0,1,0,1,0,0,0,0,0,0,0,0,0,0,0,0,0,0,0,0,0,0,0,0,0,0,0,0,0,0,0,1,0,1,0,0,0,0
0,0,0,0,1,63,1,0,0,0,0,0,0,0,0,0,0,0,0,0,0,0,0,0,0,0,0,0,0,0,0,0,0,0,1,64,1,0,0,0,0
0,0,1,1,1,1,1,0,0,0,0,0,0,0,0,0,0,0,0,0,0,0,0,0,0,0,0,0,0,0,0,0,0,0,1,1,1,1,1,0,0
0,0,1,13,0,0,0,0,0,0,12,1,0,0,0,1,12,48,0,0,0,0,0,48,12,1,0,0,0,1,12,0,0,0,0,0,0,15,1,0,0
0,0,1,13,0,0,0,0,1,1,1,0,0,65,0,0,1,1,66,67,68,69,70,1,1,0,0,71,0,0,1,1,1,0,0,0,0,15,1,0,0
0,0,1,13,0,72,0,0,1,73,0,0,0,0,0,74,27,48,0,0,0,0,0,56,29,75,0,0,0,0,0,76,1,0,0,77,0,15,1,0,0
0,0,1,13,0,0,0,0,1,1,1,78,78,78,78,78,1,1,79,80,81,82,83,1,1,78,78,78,78,78,1,1,1,0,0,0,0,15,1,0,0
0,0,1,84,84,84,84,84,1,0,12,1,1,1,1,1,12,56,0,0,0,0,0,56,12,1,1,1,1,1,12,0,1,84,84,84,84,84,1,0,0
0,0,1,1,1,1,1,1,1,0,0,0,0,0,0,0,0,0,0,0,0,0,0,0,0,0,0,0,0,0,0,0,1,1,1,1,1,1,1,0,0
0,85,0,0,0,0,0,0,0,0,0,0,0,86,0,0,0,87,0,0,0,0,0,88,0,0,0,89,0,0,0,0,0,0,0,0,0,0,0,90,0
0,0,0,0,0,0,0,0,0,0,0,0,0,0,0,0,0,0,0,0,0,0,0,0,0,0,0,0,0,0,0,0,0,0,0,0,0,0,0,0,0
:endlayer
layer: 6
0,0,0,0,0,0,0,0,0,0,0,0,0,0,0,0,0,0,0,0,0,0,0,0,0,0,0,0,0,0,0,0,0,0,0,0,0,0,0,0,0
0,0,0,0,0,0,0,0,0,0,0,0,0,0,0,0,0,0,0,0,0,0,0,0,0,0,0,0,0,0,0,0,0,0,0,0,0,0,0,0,0
0,0,1,84,1,84,1,84,1,0,0,0,0,0,0,0,0,0,0,0,0,0,0,0,0,0,0,0,0,0,0,0,1,84,1,84,1,84,1,0,0
0,0,15,91,0,0,0,0,1,0,12,8,78,8,78,8,12,0,0,0,0,0,0,0,12,8,78,8,78,8,12,0,1,0,0,0,0,92,13,0,0
0,0,1,0,0,0,0,0,1,1,1,0,0,0,0,0,1,1,78,1,78,1,78,1,1,0,0,0,0,0,1,1,1,0,0,0,0,0,1,0,0
0,0,15,0,0,0,0,0,1,93,0,0,0,0,0,0,0,0,0,0,0,0,0,0,0,0,0,0,0,0,0,94,1,0,0,0,0,0,13,0,0
0,0,1,0,0,0,0,0,1,1,1,1,95,1,1,1,1,1,1,0,0,0,1,1,1,1,1,1,96,1,1,1,1,0,0,0,0,0,1,0,0
0,0,15,0,0,0,0,0,0,0,0,0,0,0,15,1,1,1,97,0,0,0,98,1,1,1,13,0,0,0,0,0,0,0,0,0,0,0,13,0,0
0,0,1,1,1,1,1,0,0,0,0,0,0,99,15,1,1,1,100,0,0,0,98,1,1,1,13,101,0,0,0,0,0,0,1,1,1,1,1,0,0
0,0,0,0,1,102,1,0,0,0,0,0,1,1,1,1,1,1,1,0,0,0,1,1,1,1,1,1,1,0,0,0,0,0,1,103,1,0,0,0,0
0,0,0,0,1,0,1,0,0,0,0,0,104,0,0,0,0,0,0,0,0,0,0,15,105,0,0,0,104,0,0,0,0,0,1,0,1,0,0,0,0
0,0,0,0,1,0,96,0,0,0,0,0,104,0,106,0,0,107,0,0,0,0,0,0,0,0,0,0,104,0,0,0,0,0,95,0,1,0,0,0,0
0,0,0,12,1,0,1,0,0,0,0,12,1,0,108,0,0,109,0,0,0,0,0,0,0,0,0,0,1,12,0,0,0,0,1,0,1,12,0,0,0
0,0,0,8,0,0,104,0,0,0,0,1,1,0,110,0,0,111,0,0,0,0,0,0,0,0,0,0,1,1,0,0,0,0,104,0,0,8,0,0,0
0,0,0,27,0,0,1,0,0,0,0,1,0,0,112,0,0,113,0,0,0,0,0,0,0,0,0,0,47,1,0,0,0,0,1,0,0,29,0,0,0
0,0,0,8,114,0,104,0,0,0,0,104,0,0,0,0,0,0,0,0,0,0,0,0,0,0,0,0,0,104,0,0,0,0,104,0,115,8,0,0,0
0,0,0,27,0,0,1,0,0,0,0,104,0,0,0,0,0,0,0,0,0,0,0,0,0,0,0,0,0,104,0,0,0,0,1,0,0,29,0,0,0
0,0,0,8,0,0,104,0,0,0,0,104,0,0,0,0,0,1,1,116,117,118,1,1,0,0,0,0,0,104,0,0,0,0,104,0,0,8,0,0,0
0,0,0,12,1,0,1,0,0,0,0,1,0,0,119,0,0,1,12,0,0,0,12,1,0,0,120,0,0,1,0,0,0,0,1,0,1,12,0,0,0
0,0,0,0,1,0,95,0,0,0,0,1,1,104,104,104,1,1,0,0,0,0,0,1,1,104,104,104,1,1,0,0,0,0,96,0,1,0,0,0,0
0,0,0,0,1,0,1,0,0,0,0,0,0,0,0,0,0,0,0,0,0,0,0,0,0,0,0,0,0,0,0,0,0,0,1,0,1,0,0,0,0
0,0,0,0,1,121,1,0,0,0,0,0,0,0,0,0,0,0,0,0,0,0,0,0,0,0,0,0,0,0,0,0,0,0,1,122,1,0,0,0,0
0,0,1,1,1,1,1,0,0,0,0,0,0,0,0,0,0,0,0,0,0,0,0,0,0,0,0,0,0,0,0,0,0,0,1,1,1,1,1,0,0
0,0,15,0,0,0,0,0,0,0,12,1,0,0,0,1,12,0,0,0,0,0,0,0,12,1,0,0,0,1,12,0,0,0,0,0,0,0,13,0,0
0,0,1,0,0,0,0,0,1,1,1,0,0,0,0,0,1,1,123,124,125,126,127,1,1,0,0,0,0,0,1,1,1,0,0,0,0,0,1,0,0
0,0,15,0,0,0,0,0,1,128,0,0,0,0,0,0,0,0,0,0,0,0,0,0,0,0,0,0,0,0,0,129,1,0,0,0,0,0,13,0,0
0,0,1,0,0,0,0,0,1,1,1,0,0,0,0,0,1,1,130,131,132,133,134,1,1,0,0,0,0,0,1,1,1,0,0,0,0,0,1,0,0
0,0,15,135,0,0,0,0,1,0,12,8,14,8,14,8,12,0,0,0,0,0,0,0,12,8,14,8,14,8,12,0,1,0,0,0,0,136,13,0,0
0,0,1,11,1,11,1,11,1,0,0,0,0,0,0,0,0,0,0,0,0,0,0,0,0,0,0,0,0,0,0,0,1,11,1,11,1,11,1,0,0
0,0,0,0,0,0,0,0,0,0,0,0,0,0,0,0,0,0,0,0,0,0,0,0,0,0,0,0,0,0,0,0,0,0,0,0,0,0,0,0,0
0,0,0,0,0,0,0,0,0,0,0,0,0,0,0,0,0,0,0,0,0,0,0,0,0,0,0,0,0,0,0,0,0,0,0,0,0,0,0,0,0
:endlayer
layer: 7
0,0,0,0,0,0,0,0,0,0,0,0,0,0,0,0,0,0,0,0,0,0,0,0,0,0,0,0,0,0,0,0,0,0,0,0,0,0,0,0,0
0,0,0,0,0,0,0,0,0,0,0,0,0,0,0,0,0,0,0,0,0,0,0,0,0,0,0,0,0,0,0,0,0,0,0,0,0,0,0,0,0
0,0,1,0,1,0,1,0,1,0,0,0,0,0,0,0,0,0,0,0,0,0,0,0,0,0,0,0,0,0,0,0,1,0,1,0,1,0,1,0,0
0,0,0,0,0,0,0,0,1,0,12,8,0,8,0,8,12,0,0,0,0,0,0,0,12,8,0,8,0,8,12,0,1,0,0,0,0,0,0,0,0
0,0,1,0,0,0,0,0,1,1,1,0,0,0,0,0,1,1,0,1,0,1,0,1,1,0,0,0,0,0,1,1,1,0,0,0,0,0,1,0,0
0,0,0,0,0,0,0,0,1,137,1,0,0,0,0,0,0,0,0,0,0,0,0,0,0,0,0,0,0,0,1,138,1,0,0,0,0,0,0,0,0
0,0,1,0,0,0,0,0,1,1,1,1,1,1,1,1,1,1,1,0,0,0,1,1,1,1,1,1,1,1,1,1,1,0,0,0,0,0,1,0,0
0,0,0,0,0,0,0,0,139,0,0,0,0,0,0,15,1,1,98,0,0,0,0,1,1,13,0,0,0,0,0,0,139,0,0,0,0,0,0,0,0
0,0,1,1,1,1,1,140,0,0,0,0,0,0,0,15,1,1,98,0,0,0,0,1,1,13,0,0,0,0,0,0,0,141,1,1,1,1,1,0,0
0,0,0,0,1,142,1,0,0,0,0,0,1,1,1,1,1,1,1,0,0,0,1,1,1,1,1,1,1,0,0,0,0,0,1,142,1,0,0,0,0
0,0,0,0,1,1,1,0,0,0,0,0,104,0,0,0,0,0,0,0,0,0,0,0,15,105,0,0,104,0,0,0,0,0,1,1,1,0,0,0,0
0,0,0,0,1,0,1,0,0,0,0,0,104,0,0,0,0,0,0,0,0,0,0,0,0,0,0,0,104,0,0,0,0,0,1,0,1,0,0,0,0
0,0,0,12,1,0,1,0,0,0,0,12,1,0,0,0,0,0,0,0,0,0,0,0,0,0,0,0,1,12,0,0,0,0,1,0,1,12,0,0,0
0,0,0,8,0,0,104,0,0,0,0,1,1,0,0,0,0,0,0,0,0,0,0,0,0,0,0,0,1,1,0,0,0,0,104,0,0,8,0,0,0
0,0,0,0,0,0,1,0,0,0,0,1,0,0,0,0,0,0,0,0,0,0,0,0,0,0,0,0,0,1,0,0,0,0,1,0,0,0,0,0,0
0,0,0,8,0,0,104,0,0,0,0,104,0,0,0,0,0,0,0,0,0,0,0,0,0,0,0,0,0,104,0,0,0,0,104,0,0,8,0,0,0
0,0,0,0,0,0,1,0,0,0,0,104,0,0,0,0,0,0,0,0,0,0,0,0,0,0,0,0,0,104,0,0,0,0,1,0,0,0,0,0,0
0,0,0,8,0,0,104,0,0,0,0,104,0,0,0,0,0,1,1,143,144,145,1,1,0,0,0,0,0,104,0,0,0,0,104,0,0,8,0,0,0
0,0,0,12,1,0,1,0,0,0,0,1,0,0,0,0,0,1,12,0,0,0,12,1,0,0,0,0,0,1,0,0,0,0,1,0,1,12,0,0,0
0,0,0,0,1,0,1,0,0,0,0,1,1,104,104,104,1,1,0,0,0,0,0,1,1,104,104,104,1,1,0,0,0,0,1,0,1,0,0,0,0
0,0,0,0,1,1,1,0,0,0,0,0,0,0,0,0,0,0,0,0,0,0,0,0,0,0,0,0,0,0,0,0,0,0,1,1,1,0,0,0,0
0,0,0,0,1,146,1,0,0,0,0,0,0,0,0,0,0,0,0,0,0,0,0,0,0,0,0,0,0,0,0,0,0,0,1,146,1,0,0,0,0
0,0,1,1,1,1,1,140,0,0,0,0,0,0,0,0,0,0,0,0,0,0,0,0,0,0,0,0,0,0,0,0,0,141,1,1,1,1,1,0,0
0,0,0,0,0,0,0,0,147,0,12,1,105,0,148,1,12,0,0,0,0,0,0,0,12,1,105,0,148,1,12,0,147,0,0,0,0,0,0,0,0
0,0,1,0,0,0,0,0,1,1,1,0,0,0,0,0,1,1,149,150,151,152,153,1,1,0,0,0,0,0,1,1,1,0,0,0,0,0,1,0,0
0,0,0,0,0,0,0,0,1,137,8,0,0,0,0,0,0,140,0,0,0,0,0,141,0,0,0,0,0,0,8,138,1,0,0,0,0,0,0,0,0
0,0,1,0,0,0,0,0,1,1,1,0,0,0,0,0,1,1,154,155,156,157,158,1,1,0,0,0,0,0,1,1,1,0,0,0,0,0,1,0,0
0,0,0,0,0,0,0,0,1,0,12,8,0,8,0,8,12,142,0,0,0,0,0,142,12,8,0,8,0,8,12,0,1,0,0,0,0,0,0,0,0
0,0,1,0,1,0,1,0,1,0,0,0,0,0,0,0,0,0,0,0,0,0,0,0,0,0,0,0,0,0,0,0,1,0,1,0,1,0,1,0,0
0,0,0,0,0,0,0,0,0,0,0,0,0,0,0,0,0,0,0,0,0,0,0,0,0,0,0,0,0,0,0,0,0,0,0,0,0,0,0,0,0
0,0,0,0,0,0,0,0,0,0,0,0,0,0,0,0,0,0,0,0,0,0,0,0,0,0,0,0,0,0,0,0,0,0,0,0,0,0,0,0,0
:endlayer
layer: 8
0,0,0,0,0,0,0,0,0,0,0,0,0,0,0,0,0,0,0,0,0,0,0,0,0,0,0,0,0,0,0,0,0,0,0,0,0,0,0,0,0
0,0,0,0,0,0,0,0,0,0,0,0,0,0,0,0,0,0,0,0,0,0,0,0,0,0,0,0,0,0,0,0,0,0,0,0,0,0,0,0,0
0,0,1,159,1,159,1,159,1,0,0,0,0,0,0,0,0,0,0,0,0,0,0,0,0,0,0,0,0,0,0,0,1,159,1,159,1,159,1,0,0
0,0,148,0,0,0,0,0,1,0,12,8,0,8,0,8,12,0,0,0,0,0,0,0,12,8,0,8,0,8,12,0,1,0,0,0,0,0,105,0,0
0,0,1,0,0,0,0,0,1,1,1,0,0,0,0,0,1,1,147,1,147,1,147,1,1,0,0,0,0,0,1,1,1,0,0,0,0,0,1,0,0
0,0,148,0,0,0,0,0,1,1,1,0,0,0,0,0,0,0,0,0,0,0,0,0,0,0,0,0,0,0,1,1,1,0,0,0,0,0,105,0,0
0,0,1,0,0,0,0,0,1,1,1,1,1,1,1,1,1,1,1,1,1,1,1,1,1,1,1,1,1,1,1,1,1,0,0,0,0,0,1,0,0
0,0,148,0,0,0,0,0,1,0,0,0,142,0,0,0,15,1,105,0,142,0,148,1,13,0,0,0,142,0,0,0,1,0,0,0,0,0,105,0,0
0,0,1,1,1,1,1,1,8,0,0,0,0,0,0,0,15,1,105,0,146,0,148,1,13,0,0,0,0,0,0,0,8,1,1,1,1,1,1,0,0
0,0,0,0,1,1,1,0,0,0,0,0,1,1,1,1,1,1,1,1,1,1,1,1,1,1,1,1,1,0,0,0,0,0,1,1,1,0,0,0,0
0,0,0,0,1,1,1,0,0,0,0,0,104,0,0,0,0,0,142,0,0,0,142,0,0,15,105,0,104,0,0,0,0,0,1,1,1,0,0,0,0
0,0,0,0,1,0,1,137,0,0,0,0,104,0,0,0,0,0,0,0,0,0,0,0,0,0,0,0,104,0,0,0,0,138,1,0,1,0,0,0,0
0,0,0,12,1,0,1,0,0,0,0,12,1,0,0,0,0,0,0,0,0,0,0,0,0,0,0,0,1,12,0,0,0,0,1,0,1,12,0,0,0
0,0,0,8,0,0,140,0,0,0,0,1,1,0,0,0,0,0,0,0,0,0,0,0,0,0,0,0,1,1,0,0,0,0,141,0,0,8,0,0,0
0,0,0,0,0,0,1,0,0,0,0,1,142,0,0,0,0,0,0,0,0,0,0,0,0,0,0,0,142,1,0,0,0,0,1,0,0,0,0,0,0
0,0,0,8,0,0,140,0,0,0,0,104,0,0,0,0,0,0,0,0,0,0,0,0,0,0,0,0,0,104,0,0,0,0,141,0,0,8,0,0,0
0,0,0,0,0,0,1,0,0,0,0,104,0,0,0,0,0,0,146,0,0,0,146,0,0,0,0,0,0,104,0,0,0,0,1,0,0,0,0,0,0
0,0,0,8,0,0,140,0,0,0,0,104,0,0,0,0,0,1,1,160,161,162,1,1,0,0,0,0,0,104,0,0,0,0,141,0,0,8,0,0,0
0,0,0,12,1,0,1,0,0,0,0,1,146,0,0,0,146,1,12,0,0,0,12,1,146,0,0,0,146,1,0,0,0,0,1,0,1,12,0,0,0
0,0,0,0,1,0,1,137,0,0,0,1,1,104,104,104,1,1,0,0,0,0,0,1,1,104,104,104,1,1,0,0,0,138,1,0,1,0,0,0,0
0,0,0,0,1,1,1,0,0,0,0,0,0,0,0,0,0,0,0,0,0,0,0,0,0,0,0,0,0,0,0,0,0,0,1,1,1,0,0,0,0
0,0,0,0,1,1,1,0,0,0,0,0,0,0,0,0,0,0,0,0,0,0,0,0,0,0,0,0,0,0,0,0,0,0,1,1,1,0,0,0,0
0,0,1,1,1,1,1,1,8,0,0,163,0,146,0,163,0,0,0,0,0,0,0,0,0,163,0,146,0,163,0,0,8,1,1,1,1,1,1,0,0
0,0,148,0,0,0,0,0,1,0,12,1,1,1,1,1,12,0,0,0,0,0,0,0,12,1,1,1,1,1,12,0,1,0,0,0,0,0,105,0,0
0,0,1,0,0,0,0,0,1,1,1,0,0,0,0,0,1,1,164,165,166,167,168,1,1,0,0,0,0,0,1,1,1,0,0,0,0,0,1,0,0
0,0,148,0,0,0,0,0,1,8,8,0,0,0,0,0,141,1,140,163,163,163,141,1,140,0,0,0,0,0,8,8,1,0,0,0,0,0,105,0,0
0,0,1,0,0,0,0,0,1,1,1,0,0,146,0,0,1,1,169,170,171,172,173,1,1,0,0,146,0,0,1,1,1,0,0,0,0,0,1,0,0
0,0,148,0,0,0,0,0,1,0,12,8,0,8,0,8,12,163,0,0,0,0,0,163,12,8,0,8,0,8,12,0,1,0,0,0,0,0,105,0,0
0,0,1,174,1,174,1,174,1,0,0,0,0,0,0,0,0,0,0,0,0,0,0,0,0,0,0,0,0,0,0,0,1,174,1,174,1,174,1,0,0
0,0,0,0,0,0,0,0,0,0,0,0,0,0,0,0,0,0,0,0,0,0,0,0,0,0,0,0,0,0,0,0,0,0,0,0,0,0,0,0,0
0,0,0,0,0,0,0,0,0,0,0,0,0,0,0,0,0,0,0,0,0,0,0,0,0,0,0,0,0,0,0,0,0,0,0,0,0,0,0,0,0
:endlayer
layer: 9
0,0,0,0,0,0,0,0,0,0,0,0,0,0,0,0,0,0,0,0,0,0,0,0,0,0,0,0,0,0,0,0,0,0,0,0,0,0,0,0,0
0,0,0,0,0,146,0,0,0,0,0,0,0,0,0,0,0,0,0,0,0,0,0,0,0,0,0,0,0,0,0,0,0,0,0,146,0,0,0,0,0
0,0,5,1,5,1,5,1,5,0,0,0,0,146,0,0,0,0,0,0,0,0,0,0,0,0,0,146,0,0,0,0,5,1,5,1,5,1,5,0,0
0,0,1,0,0,142,0,0,1,0,12,8,147,8,147,8,12,0,0,0,146,0,0,0,12,8,147,8,147,8,12,0,1,0,0,142,0,0,1,0,0
0,0,5,0,0,0,0,0,1,1,1,0,0,142,0,0,1,1,1,1,1,1,1,1,1,0,0,142,0,0,1,1,1,0,0,0,0,0,5,0,0
0,138,1,137,0,0,0,138,1,1,1,0,0,0,0,0,0,0,0,0,0,0,0,0,0,0,0,0,0,0,1,1,1,137,0,0,0,138,1,137,0
0,0,5,0,0,0,0,0,1,1,1,1,1,1,1,1,1,1,1,1,1,1,1,1,1,1,1,1,1,1,1,1,1,0,0,0,0,0,5,0,0
0,0,1,0,0,146,0,0,1,0,0,0,0,0,0,0,0,15,1,1,1,1,1,13,0,0,0,0,0,0,0,0,1,0,0,146,0,0,1,0,0
0,0,5,1,1,1,1,1,1,0,0,0,0,0,0,0,0,15,1,1,1,1,1,13,0,0,0,0,0,0,0,0,1,1,1,1,1,1,5,0,0
0,0,0,0,1,1,1,0,0,0,0,141,1,1,1,1,1,1,1,1,1,1,1,1,1,1,1,1,1,140,0,0,0,0,1,1,1,0,0,0,0
0,0,0,0,1,1,1,0,0,0,0,0,1,7,7,7,7,7,7,7,7,105,0,0,0,0,15,7,1,0,0,0,0,0,1,1,1,0,0,0,0
0,0,0,0,1,0,1,0,0,0,0,141,1,7,6,147,6,7,7,7,7,7,7,7,7,7,7,7,1,140,0,0,0,0,1,0,1,0,0,0,0
0,0,0,12,1,0,1,0,0,0,0,12,1,7,141,175,140,7,7,6,147,6,7,6,6,6,6,7,1,12,0,0,0,0,1,0,1,12,0,0,0
0,0,0,8,0,0,1,0,0,0,141,1,1,7,6,139,6,7,7,141,175,140,7,6,6,6,6,7,1,1,140,0,0,0,1,0,0,8,0,0,0
0,0,0,141,0,0,1,0,0,0,0,1,7,7,7,7,7,7,7,6,139,6,7,6,7,7,7,7,7,1,0,0,0,0,1,0,0,140,0,0,0
0,0,138,8,137,0,1,0,0,0,141,1,7,6,147,6,7,7,7,7,7,7,7,6,7,6,147,6,7,1,140,0,0,0,1,0,138,8,137,0,0
0,0,0,141,0,0,1,0,0,0,0,1,7,141,175,140,7,7,7,7,7,7,7,7,7,141,175,140,7,1,0,0,0,0,1,0,0,140,0,0,0
0,0,0,8,0,0,1,0,0,0,141,1,7,6,139,6,7,1,1,1,1,1,1,1,7,6,139,6,7,1,140,0,0,0,1,0,0,8,0,0,0
0,0,0,12,1,0,1,0,0,0,0,1,7,7,7,7,7,1,12,0,142,0,12,1,7,7,7,7,7,1,0,0,0,0,1,0,1,12,0,0,0
0,0,0,0,1,0,1,0,0,0,141,1,1,1,1,1,1,1,0,0,0,0,0,1,1,1,1,1,1,1,140,0,0,0,1,0,1,0,0,0,0
0,0,0,0,1,1,1,0,0,0,0,139,0,139,0,139,0,139,0,0,0,0,0,139,0,139,0,139,0,139,0,0,0,0,1,1,1,0,0,0,0
0,0,0,0,1,1,1,0,0,0,0,0,0,0,0,0,0,0,0,0,0,0,0,0,0,0,0,0,0,0,0,0,0,0,1,1,1,0,0,0,0
0,0,5,1,1,1,1,1,1,0,0,0,176,176,176,0,0,0,0,0,0,0,0,0,0,0,176,176,176,0,0,0,1,1,1,1,1,1,5,0,0
0,0,1,0,0,142,0,0,1,0,12,1,1,1,1,1,12,0,0,0,0,0,0,0,12,1,1,1,1,1,12,0,1,0,0,142,0,0,1,0,0
0,0,5,0,0,0,0,0,1,1,1,177,177,174,177,177,1,1,1,1,1,1,1,1,1,177,177,174,177,177,1,1,1,0,0,0,0,0,5,0,0
0,138,1,137,0,0,0,138,1,8,8,140,0,0,0,141,8,1,1,1,1,1,1,1,8,140,0,0,0,141,8,8,1,137,0,0,0,138,1,137,0
0,0,5,0,0,0,0,0,1,1,1,177,177,159,177,177,1,1,1,1,1,1,1,1,1,177,177,159,177,177,1,1,1,0,0,0,0,0,5,0,0
0,0,1,0,0,146,0,0,1,0,12,8,139,8,139,8,12,0,176,176,176,176,176,0,12,8,139,8,139,8,12,0,1,0,0,146,0,0,1,0,0
0,0,5,1,5,1,5,1,5,0,0,0,0,142,0,0,0,0,0,0,0,0,0,0,0,0,0,142,0,0,0,0,5,1,5,1,5,1,5,0,0
0,0,0,0,0,142,0,0,0,0,0,0,0,0,0,0,0,0,0,0,0,0,0,0,0,0,0,0,0,0,0,0,0,0,0,142,0,0,0,0,0
0,0,0,0,0,0,0,0,0,0,0,0,0,0,0,0,0,0,0,0,0,0,0,0,0,0,0,0,0,0,0,0,0,0,0,0,0,0,0,0,0
:endlayer
layer: 10
0,0,0,0,0,0,0,0,0,0,0,0,0,0,0,0,0,0,0,0,0,0,0,0,0,0,0,0,0,0,0,0,0,0,0,0,0,0,0,0,0
0,0,0,0,0,0,0,0,0,0,0,0,0,0,0,0,0,0,0,0,0,0,0,0,0,0,0,0,0,0,0,0,0,0,0,0,0,0,0,0,0
0,0,7,7,7,7,7,7,7,0,0,159,0,159,0,159,0,0,0,0,0,0,0,0,0,159,0,159,0,159,0,0,7,7,7,7,7,7,7,0,0
0,0,7,0,0,0,0,0,7,159,159,5,5,5,5,5,159,0,159,0,159,0,159,0,159,5,5,5,5,5,159,159,7,0,0,0,0,0,7,0,0
0,0,7,0,0,0,0,0,7,5,5,0,0,0,0,0,5,5,5,5,5,5,5,5,5,0,0,0,0,0,5,5,7,0,0,0,0,0,7,0,0
0,0,7,0,0,0,0,0,7,8,5,0,0,0,0,0,0,0,0,0,0,0,0,0,0,0,0,0,0,0,5,8,7,0,0,0,0,0,7,0,0
0,0,7,0,0,0,0,0,7,5,5,5,5,5,5,5,5,5,5,5,5,5,5,5,5,5,5,5,5,5,5,5,7,0,0,0,0,0,7,0,0
0,0,7,0,0,0,0,0,7,139,0,139,0,139,0,0,0,0,15,1,1,1,13,0,0,0,0,139,0,139,0,139,7,0,0,0,0,0,7,0,0
0,0,7,7,7,7,7,7,7,0,0,0,0,0,0,0,0,0,15,1,1,1,13,0,0,0,0,0,0,0,0,0,7,7,7,7,7,7,7,0,0
0,0,0,148,5,7,5,140,0,0,0,178,7,7,7,7,7,7,7,7,7,7,7,7,7,7,7,7,7,178,0,0,0,141,5,7,5,105,0,0,0
0,0,0,0,5,7,5,0,0,0,0,178,7,1,1,1,1,1,1,1,1,1,105,0,0,0,0,15,7,178,0,0,0,0,5,7,5,0,0,0,0
0,0,0,0,5,7,5,140,0,0,0,178,7,1,1,1,1,1,1,1,1,1,1,1,1,1,1,1,7,178,0,0,0,141,5,7,5,0,0,0,0
0,0,0,148,5,7,5,0,0,0,0,178,7,1,1,1,1,1,1,1,1,1,1,1,1,1,1,1,7,178,0,0,0,0,5,7,5,105,0,0,0
0,0,148,5,7,7,5,140,0,0,178,7,7,1,1,8,8,8,1,1,1,1,1,8,8,8,1,1,7,7,178,0,0,141,5,7,7,5,105,0,0
0,0,0,5,7,7,5,0,0,0,178,7,179,179,179,179,179,8,1,1,1,1,1,8,180,180,1,1,1,7,178,0,0,0,5,7,7,5,0,0,0
0,0,148,5,7,7,5,140,0,0,178,7,1,1,1,1,1,8,1,1,1,1,1,8,180,180,180,180,1,7,178,0,0,141,5,7,7,5,105,0,0
0,0,0,5,7,7,5,0,0,0,178,7,1,1,1,1,1,1,1,1,1,1,1,1,1,180,1,180,1,7,178,0,0,0,5,7,7,5,0,0,0
0,0,148,5,7,7,5,140,0,0,178,7,1,1,1,1,1,7,7,7,7,7,7,7,1,180,180,180,1,7,178,0,0,141,5,7,7,5,105,0,0
0,0,0,148,5,7,5,0,0,0,178,7,1,1,1,1,1,7,139,163,139,163,139,7,1,1,1,1,1,7,178,0,0,0,5,7,5,105,0,0,0
0,0,0,0,5,7,5,140,0,0,178,7,7,7,7,7,7,7,163,163,163,163,163,7,7,7,7,7,7,7,178,0,0,141,5,7,5,0,0,0,0
0,0,0,0,5,7,5,0,0,0,0,178,178,178,178,178,178,178,0,0,0,0,0,178,178,178,178,178,178,178,0,0,0,0,5,7,5,0,0,0,0
0,0,0,148,5,7,5,140,0,0,0,0,0,0,0,0,0,0,0,0,0,0,0,0,0,0,0,0,0,0,0,0,0,141,5,7,5,105,0,0,0
0,0,7,7,7,7,7,7,7,0,0,0,147,0,147,0,0,0,0,0,0,0,0,0,0,0,147,0,147,0,0,0,7,7,7,7,7,7,7,0,0
0,0,7,0,0,0,0,0,7,147,147,5,5,5,5,5,147,0,147,0,147,0,147,0,147,5,5,5,5,5,147,147,7,0,0,0,0,0,7,0,0
0,0,7,0,0,0,0,0,7,5,5,1,1,1,1,1,5,5,5,5,5,5,5,5,5,1,1,1,1,1,5,5,7,0,0,0,0,0,7,0,0
0,0,7,0,0,0,0,0,7,8,8,8,8,8,8,8,8,8,8,8,8,8,8,8,8,8,8,8,8,8,8,8,7,0,0,0,0,0,7,0,0
0,0,7,0,0,0,0,0,7,5,5,1,1,1,1,1,5,5,5,5,5,5,5,5,5,1,1,1,1,1,5,5,7,0,0,0,0,0,7,0,0
0,0,7,0,0,0,0,0,7,174,174,5,5,5,5,5,174,0,174,0,174,0,174,0,174,5,5,5,5,5,174,174,7,0,0,0,0,0,7,0,0
0,0,7,7,7,7,7,7,7,0,0,174,0,174,0,174,0,0,0,0,0,0,0,0,0,174,0,174,0,174,0,0,7,7,7,7,7,7,7,0,0
0,0,0,0,0,0,0,0,0,0,0,0,0,0,0,0,0,0,0,0,0,0,0,0,0,0,0,0,0,0,0,0,0,0,0,0,0,0,0,0,0
0,0,0,0,0,0,0,0,0,0,0,0,0,0,0,0,0,0,0,0,0,0,0,0,0,0,0,0,0,0,0,0,0,0,0,0,0,0,0,0,0
:endlayer
layer: 11
0,0,0,0,0,0,0,0,0,0,0,0,0,0,0,0,0,0,0,0,0,0,0,0,0,0,0,0,0,0,0,0,0,0,0,0,0,0,0,0,0
0,0,159,0,159,0,159,0,159,0,0,0,0,0,0,0,0,0,0,0,0,0,0,0,0,0,0,0,0,0,0,0,159,0,159,0,159,0,159,0,0
0,148,1,1,1,1,1,1,1,105,0,8,8,8,8,8,0,0,0,0,0,0,0,0,0,8,8,8,8,8,0,148,1,1,1,1,1,1,1,105,0
0,0,1,1,1,1,1,1,1,8,8,1,1,1,1,1,8,8,8,8,8,8,8,8,8,1,1,1,1,1,8,8,1,1,1,1,1,1,1,0,0
0,148,1,1,1,1,1,1,1,1,1,1,1,1,1,1,1,1,1,1,1,1,1,1,1,1,1,1,1,1,1,1,1,1,1,1,1,1,1,105,0
0,0,1,1,1,1,1,1,1,1,1,1,1,1,1,1,1,1,1,1,1,1,1,1,1,1,1,1,1,1,1,1,1,1,1,1,1,1,1,0,0
0,148,1,1,1,1,1,1,1,1,1,1,1,8,8,8,8,8,8,14,14,14,8,8,8,8,8,8,1,1,1,1,1,1,1,1,1,1,1,105,0
0,0,1,1,1,1,1,1,1,8,8,8,8,8,0,0,0,0,0,0,181,0,0,0,0,0,0,8,8,8,8,8,1,1,1,1,1,1,1,0,0
0,148,1,1,1,1,1,1,1,0,0,0,0,0,0,0,0,0,0,0,0,0,0,0,0,0,0,0,0,0,0,0,1,1,1,1,1,1,1,105,0
0,0,174,8,1,1,1,8,0,0,0,0,1,78,78,1,1,78,1,1,182,1,1,78,1,1,78,78,1,0,0,0,0,8,1,1,1,8,174,0,0
0,0,0,8,1,1,1,8,0,0,0,0,27,183,0,0,0,0,0,0,0,0,15,105,0,0,0,0,29,0,0,0,0,8,1,1,1,8,0,0,0
0,0,0,8,1,1,1,8,0,0,0,0,27,184,0,0,0,0,0,0,0,0,185,185,185,185,0,0,29,0,0,0,0,8,1,1,1,8,0,0,0
0,0,0,8,1,1,1,8,0,0,0,0,1,186,185,0,0,0,0,187,188,189,0,0,0,0,0,185,1,0,0,0,0,8,1,1,1,8,0,0,0
0,0,8,1,1,1,1,8,0,0,0,1,1,1,1,0,0,0,190,191,191,191,0,0,0,0,1,1,1,1,0,0,0,8,1,1,1,1,8,0,0
0,0,8,1,1,1,1,8,0,0,0,1,185,0,0,0,0,0,0,191,191,191,0,0,192,0,186,186,186,1,0,0,0,8,1,1,1,1,8,0,0
0,0,8,1,1,1,1,8,0,0,0,27,35,35,35,35,35,0,0,193,194,195,0,0,0,0,0,0,186,29,0,0,0,8,1,1,1,1,8,0,0
0,0,8,1,1,1,1,8,0,0,0,27,35,180,180,180,35,1,185,0,0,0,185,1,186,0,196,0,186,29,0,0,0,8,1,1,1,1,8,0,0
0,0,8,1,1,1,1,8,0,0,0,27,35,180,180,180,35,1,1,0,0,0,1,1,186,0,0,0,186,29,0,0,0,8,1,1,1,1,8,0,0
0,0,0,8,1,1,1,8,0,0,0,1,45,197,197,197,45,1,0,0,0,0,0,1,186,186,186,186,186,1,0,0,0,8,1,1,1,8,0,0,0
0,0,0,8,1,1,1,8,0,0,0,1,1,14,14,14,1,1,105,105,7,148,148,1,1,14,14,14,1,1,0,0,0,8,1,1,1,8,0,0,0
0,0,0,8,1,1,1,8,0,0,0,0,0,0,0,0,0,0,0,0,0,0,0,0,0,0,0,0,0,0,0,0,0,8,1,1,1,8,0,0,0
0,0,159,8,1,1,1,8,0,0,0,0,0,0,0,0,0,0,0,0,0,0,0,0,0,0,0,0,0,0,0,0,0,8,1,1,1,8,159,0,0
0,148,1,1,1,1,1,1,1,0,0,178,178,178,178,178,0,0,0,0,0,0,0,0,0,178,178,178,178,178,0,0,1,1,1,1,1,1,1,105,0
0,0,1,1,1,1,1,1,1,8,8,8,8,8,8,8,8,8,8,8,8,8,8,8,8,8,8,8,8,8,8,8,1,1,1,1,1,1,1,0,0
0,148,1,1,1,1,1,1,1,1,1,1,1,1,1,1,1,1,1,1,1,1,1,1,1,1,1,1,1,1,1,1,1,1,1,1,1,1,1,105,0
0,0,1,1,1,1,1,1,1,1,1,1,1,1,1,1,1,1,1,1,1,1,1,1,1,1,1,1,1,1,1,1,1,1,1,1,1,1,1,0,0
0,148,1,1,1,1,1,1,1,1,1,1,1,1,1,1,1,1,1,1,1,1,1,1,1,1,1,1,1,1,1,1,1,1,1,1,1,1,1,105,0
0,0,1,1,1,1,1,1,1,8,8,1,1,1,1,1,8,8,8,8,8,8,8,8,8,1,1,1,1,1,8,8,1,1,1,1,1,1,1,0,0
0,148,1,1,1,1,1,1,1,105,0,8,8,8,8,8,0,0,0,0,0,0,0,0,0,8,8,8,8,8,0,148,1,1,1,1,1,1,1,105,0
0,0,174,0,174,0,174,0,174,0,0,0,0,0,0,0,0,0,0,0,0,0,0,0,0,0,0,0,0,0,0,0,174,0,174,0,174,0,174,0,0
0,0,0,0,0,0,0,0,0,0,0,0,0,0,0,0,0,0,0,0,0,0,0,0,0,0,0,0,0,0,0,0,0,0,0,0,0,0,0,0,0
:endlayer
layer: 12
0,0,0,0,0,0,0,0,0,0,0,0,0,0,0,0,0,0,0,0,0,0,0,0,0,0,0,0,0,0,0,0,0,0,0,0,0,0,0,0,0
0,0,176,176,176,176,176,176,176,0,0,0,0,0,0,0,0,0,0,0,0,0,0,0,0,0,0,0,0,0,0,0,176,176,176,176,176,176,176,0,0
0,176,1,1,1,1,1,1,1,176,0,84,1,84,1,84,0,0,0,0,0,0,0,0,0,84,1,84,1,84,0,176,1,1,1,1,1,1,1,176,0
0,176,1,198,0,0,0,0,1,84,1,11,0,199,0,11,1,84,1,84,1,84,1,84,1,11,0,199,0,11,1,84,1,0,0,0,0,200,1,176,0
0,176,1,0,0,0,0,0,1,0,0,0,0,201,0,0,0,202,0,0,199,0,0,203,0,0,0,204,0,0,0,0,1,0,0,0,0,0,1,176,0
0,176,1,0,0,205,0,0,0,0,0,0,0,0,0,0,0,0,0,0,206,0,0,0,0,0,0,0,0,0,0,0,0,0,0,207,0,0,1,176,0
0,176,1,0,0,0,0,0,1,0,0,0,0,84,1,11,1,11,1,0,0,0,1,11,1,11,1,84,0,0,0,0,1,0,0,0,0,0,1,176,0
0,176,1,0,0,0,208,209,1,11,1,11,1,11,0,0,0,0,0,0,0,0,0,0,0,0,0,11,1,11,1,11,1,210,208,0,0,0,1,176,0
0,176,1,1,1,0,1,1,1,0,0,0,0,0,0,0,0,0,0,0,0,0,0,0,0,0,0,0,0,0,0,0,1,1,1,0,1,1,1,176,0
0,0,176,15,0,0,0,13,0,0,0,0,1,104,104,1,1,104,1,1,95,1,1,104,1,1,104,104,1,0,0,0,0,15,0,0,0,13,176,0,0
0,0,0,1,0,0,0,1,0,0,0,0,104,0,0,0,0,0,0,0,0,0,0,15,105,0,0,0,104,0,0,0,0,1,0,0,0,1,0,0,0
0,0,0,15,211,0,0,13,0,0,0,0,104,0,0,0,0,0,0,0,0,0,0,0,0,0,0,0,104,0,0,0,0,15,0,0,212,13,0,0,0
0,0,0,1,0,0,0,1,0,0,0,0,1,186,185,0,0,0,0,213,214,215,0,0,0,0,0,185,1,0,0,0,0,1,0,0,0,1,0,0,0
0,0,15,13,0,0,0,13,0,0,0,1,1,1,1,0,0,0,0,0,0,0,0,0,0,0,1,1,1,1,0,0,0,15,0,0,0,15,13,0,0
0,0,1,0,0,0,0,1,0,0,0,1,185,0,0,0,0,0,0,0,0,0,0,0,0,0,186,186,185,1,0,0,0,1,0,0,0,0,1,0,0
0,0,15,199,216,0,217,13,0,0,0,104,0,0,0,0,0,0,0,218,219,220,0,0,0,0,0,0,221,104,0,0,0,15,222,0,223,199,13,0,0
0,0,1,0,0,0,0,1,0,0,0,104,0,0,224,224,0,1,185,0,0,0,185,1,186,0,0,0,221,104,0,0,0,1,0,0,0,0,1,0,0
0,0,15,13,0,0,0,13,0,0,0,104,0,0,0,224,0,1,1,0,0,0,1,1,186,0,0,0,221,104,0,0,0,15,0,0,0,15,13,0,0
0,0,0,1,0,0,0,1,0,0,0,1,185,221,0,0,185,1,0,0,0,0,0,1,185,221,221,221,185,1,0,0,0,1,0,0,0,1,0,0,0
0,0,0,15,225,0,0,13,0,0,0,1,1,104,104,104,1,1,176,176,176,176,176,1,1,104,104,104,1,1,0,0,0,15,0,0,226,13,0,0,0
0,0,0,1,0,0,0,1,0,0,0,0,0,0,0,0,0,0,0,0,0,0,0,0,0,0,0,0,0,0,0,0,0,1,0,0,0,1,0,0,0
0,0,176,15,0,0,0,13,0,0,0,0,0,0,0,0,0,0,0,0,0,0,0,0,0,0,0,0,0,0,0,0,0,15,0,0,0,13,176,0,0
0,176,1,1,1,0,1,1,1,0,0,0,0,0,0,0,0,0,0,0,0,0,0,0,0,0,0,0,0,0,0,0,1,1,1,0,1,1,1,176,0
0,176,1,0,0,0,227,228,1,84,1,84,1,84,1,84,1,84,1,84,1,84,1,84,1,84,1,84,1,84,1,84,1,229,227,0,0,0,1,176,0
0,176,1,0,0,0,0,0,1,0,0,0,0,0,0,0,0,0,0,0,230,0,0,0,0,0,0,0,0,0,0,0,1,0,0,0,0,0,1,176,0
0,176,1,0,0,231,0,0,0,0,0,0,0,0,0,0,0,0,0,0,0,0,0,0,0,0,0,0,0,0,0,0,0,0,0,232,0,0,1,176,0
0,176,1,0,0,0,0,0,1,0,0,0,0,233,0,0,0,234,0,0,199,0,0,235,0,0,0,236,0,0,0,0,1,0,0,0,0,0,1,176,0
0,176,1,237,0,0,0,0,1,11,1,84,0,199,0,84,1,11,1,11,1,11,1,11,1,84,0,199,0,84,1,11,1,0,0,0,0,238,1,176,0
0,176,1,1,1,1,1,1,1,176,0,11,1,11,1,11,0,0,0,0,0,0,0,0,0,11,1,11,1,11,0,176,1,1,1,1,1,1,1,176,0
0,0,176,176,176,176,176,176,176,0,0,0,0,0,0,0,0,0,0,0,0,0,0,0,0,0,0,0,0,0,0,0,176,176,176,176,176,176,176,0,0
0,0,0,0,0,0,0,0,0,0,0,0,0,0,0,0,0,0,0,0,0,0,0,0,0,0,0,0,0,0,0,0,0,0,0,0,0,0,0,0,0
:endlayer
layer: 13
0,0,0,0,0,0,0,0,0,0,0,0,0,0,0,0,0,0,0,0,0,0,0,0,0,0,0,0,0,0,0,0,0,0,0,0,0,0,0,0,0
0,0,0,0,0,0,0,0,0,0,0,0,0,0,0,0,0,0,0,0,0,0,0,0,0,0,0,0,0,0,0,0,0,0,0,0,0,0,0,0,0
0,0,1,0,1,0,1,0,1,0,0,0,176,0,176,0,0,0,0,0,0,0,0,0,0,0,176,0,176,0,0,0,1,0,1,0,1,0,1,0,0
0,0,0,0,0,0,0,0,0,0,176,0,0,0,0,0,176,0,176,0,176,0,176,0,176,0,0,0,0,0,176,0,0,0,0,0,0,0,0,0,0
0,0,1,0,0,0,0,0,1,0,0,0,0,0,0,0,0,0,0,0,0,0,0,0,0,0,0,0,0,0,0,0,1,0,0,0,0,0,1,0,0
0,0,0,0,0,0,0,0,0,0,0,0,0,0,0,0,0,0,0,0,0,0,0,0,0,0,0,0,0,0,0,0,0,0,0,0,0,0,0,0,0
0,0,1,0,0,0,0,0,1,0,0,0,0,0,176,0,176,0,176,0,0,0,176,0,176,0,176,0,0,0,0,0,1,0,0,0,0,0,1,0,0
0,0,0,0,0,0,208,0,0,0,176,0,176,0,0,0,0,0,0,0,0,0,0,0,0,0,0,0,176,0,176,0,0,0,208,0,0,0,0,0,0
0,0,1,0,1,0,1,0,1,0,0,0,0,0,0,0,0,0,0,0,146,0,0,0,0,0,0,0,0,0,0,0,1,0,1,0,1,0,1,0,0
0,0,0,0,0,0,0,0,0,0,0,0,1,104,104,1,1,104,1,1,1,1,1,104,1,1,104,104,1,0,0,0,0,0,0,0,0,0,0,0,0
0,0,0,176,0,0,0,176,0,0,0,0,104,0,0,0,0,0,0,0,0,0,0,0,15,105,0,0,104,0,0,0,0,176,0,0,0,176,0,0,0
0,0,0,0,0,0,0,0,0,0,0,0,104,0,0,0,0,0,0,0,0,0,0,0,0,0,0,0,104,0,0,0,0,0,0,0,0,0,0,0,0
0,0,0,176,0,0,0,176,0,0,0,0,1,186,185,0,0,0,0,0,0,0,0,0,0,0,0,185,1,0,0,0,0,176,0,0,0,176,0,0,0
0,0,0,0,0,0,0,0,0,0,0,1,1,1,1,137,0,0,0,0,0,0,0,0,0,138,1,1,1,1,0,0,0,0,0,0,0,0,0,0,0
0,0,176,0,0,0,0,176,0,0,0,1,185,0,0,0,0,0,0,0,0,0,0,0,0,0,186,186,185,1,0,0,0,176,0,0,0,0,176,0,0
0,0,0,0,0,0,0,0,0,0,0,104,0,0,0,0,0,146,0,0,0,0,0,146,0,0,0,0,0,104,0,0,0,0,0,0,0,0,0,0,0
0,0,176,0,0,0,0,176,0,0,0,104,0,0,0,0,0,1,185,0,0,0,185,1,186,0,0,0,0,104,0,0,0,176,0,0,0,0,176,0,0
0,0,0,0,0,0,0,0,0,0,0,104,0,0,0,0,0,1,1,140,0,141,1,1,186,0,0,0,0,104,0,0,0,0,0,0,0,0,0,0,0
0,0,0,176,0,0,0,176,0,0,0,1,185,0,0,0,185,1,0,0,0,0,0,1,185,0,0,0,185,1,0,0,0,176,0,0,0,176,0,0,0
0,0,0,0,0,0,0,0,0,0,0,1,1,104,104,104,1,1,0,0,0,0,0,1,1,104,104,104,1,1,0,0,0,0,0,0,0,0,0,0,0
0,0,0,176,0,0,0,176,0,0,0,0,0,0,0,0,0,0,0,0,0,0,0,0,0,0,0,0,0,0,0,0,0,176,0,0,0,176,0,0,0
0,0,0,0,0,0,0,0,0,0,0,0,0,0,0,0,0,0,0,0,0,0,0,0,0,0,0,0,0,0,0,0,0,0,0,0,0,0,0,0,0
0,0,1,0,1,0,1,0,1,0,0,0,0,0,0,0,0,0,0,0,0,0,0,0,0,0,0,0,0,0,0,0,1,0,1,0,1,0,1,0,0
0,0,0,0,0,0,227,0,0,0,176,0,176,0,176,0,176,0,176,0,176,0,176,0,176,0,176,0,176,0,176,0,0,0,227,0,0,0,0,0,0
0,0,1,0,0,0,0,0,1,0,0,0,0,0,0,0,0,0,0,0,0,0,0,0,0,0,0,0,0,0,0,0,1,0,0,0,0,0,1,0,0
0,0,0,0,0,0,0,0,0,0,0,0,0,0,0,0,0,0,0,0,0,0,0,0,0,0,0,0,0,0,0,0,0,0,0,0,0,0,0,0,0
0,0,1,0,0,0,0,0,1,0,0,0,0,0,0,0,0,0,0,0,0,0,0,0,0,0,0,0,0,0,0,0,1,0,0,0,0,0,1,0,0
0,0,0,0,0,0,0,0,0,0,176,0,0,0,0,0,176,0,176,0,176,0,176,0,176,0,0,0,0,0,176,0,0,0,0,0,0,0,0,0,0
0,0,1,0,1,0,1,0,1,0,0,0,176,0,176,0,0,0,0,0,0,0,0,0,0,0,176,0,176,0,0,0,1,0,1,0,1,0,1,0,0
0,0,0,0,0,0,0,0,0,0,0,0,0,0,0,0,0,0,0,0,0,0,0,0,0,0,0,0,0,0,0,0,0,0,0,0,0,0,0,0,0
0,0,0,0,0,0,0,0,0,0,0,0,0,0,0,0,0,0,0,0,0,0,0,0,0,0,0,0,0,0,0,0,0,0,0,0,0,0,0,0,0
:endlayer
layer: 14
0,0,0,0,0,0,0,0,0,0,0,0,0,0,0,0,0,0,0,0,0,0,0,0,0,0,0,0,0,0,0,0,0,0,0,0,0,0,0,0,0
0,0,0,0,0,0,0,0,0,0,0,0,0,0,0,0,0,0,0,0,0,0,0,0,0,0,0,0,0,0,0,0,0,0,0,0,0,0,0,0,0
0,0,1,0,1,0,1,0,1,0,0,0,0,0,0,0,0,0,0,0,0,0,0,0,0,0,0,0,0,0,0,0,1,0,1,0,1,0,1,0,0
0,0,0,0,0,0,0,0,0,0,0,0,0,0,0,0,0,0,0,0,0,0,0,0,0,0,0,0,0,0,0,0,0,0,0,0,0,0,0,0,0
0,0,1,0,0,0,0,0,1,0,0,0,0,0,0,0,0,0,0,0,0,0,0,0,0,0,0,0,0,0,0,0,1,0,0,0,0,0,1,0,0
0,0,0,0,0,0,0,0,29,0,0,0,0,0,0,0,0,0,0,0,0,0,0,0,0,0,0,0,0,0,0,0,27,0,0,0,0,0,0,0,0
0,0,1,0,0,0,0,0,1,0,0,0,0,0,0,0,0,0,0,0,0,0,0,0,0,0,0,0,0,0,0,0,1,0,0,0,0,0,1,0,0
0,0,0,0,0,0,208,0,0,0,0,0,0,0,0,0,0,0,0,0,0,0,0,0,0,0,0,0,0,0,0,0,0,0,208,0,0,0,0,0,0
0,0,1,0,1,14,1,0,1,0,0,0,147,0,147,0,147,0,147,0,147,0,147,0,147,0,147,0,147,0,0,0,1,0,1,14,1,0,1,0,0
0,0,0,0,0,0,0,0,0,0,0,141,1,1,1,1,1,1,1,1,1,1,1,1,1,1,1,1,1,140,0,0,0,0,0,0,0,0,0,0,0
0,0,0,0,0,0,0,0,0,0,0,0,1,0,0,0,0,0,0,0,142,0,0,0,0,15,105,0,1,0,0,0,0,0,0,0,0,0,0,0,0
0,0,0,0,0,0,0,0,0,0,0,141,1,0,0,0,0,0,0,0,0,0,0,0,0,0,0,0,1,140,0,0,0,0,0,0,0,0,0,0,0
0,0,0,0,0,0,0,0,0,0,0,0,1,186,185,0,0,0,0,0,0,0,0,0,0,0,0,185,1,0,0,0,0,0,0,0,0,0,0,0,0
0,0,0,0,0,0,0,0,0,0,141,1,1,1,1,140,163,0,0,0,0,0,0,0,163,141,1,1,1,1,140,0,0,0,0,0,0,0,0,0,0
0,0,0,0,0,0,0,0,0,0,0,1,185,0,0,0,0,163,0,0,0,0,0,163,0,0,186,186,186,1,0,0,0,0,0,0,0,0,0,0,0
0,0,0,0,0,0,0,0,0,0,141,1,0,0,0,0,0,147,0,0,0,0,0,147,0,0,0,0,186,1,140,0,0,0,0,0,0,0,0,0,0
0,0,0,0,0,0,0,0,0,0,0,1,0,0,0,0,0,1,185,0,0,0,185,1,186,0,0,0,186,1,0,0,0,0,0,0,0,0,0,0,0
0,0,0,0,0,0,0,0,0,0,141,1,0,0,0,0,0,1,1,1,1,1,1,1,186,0,0,0,186,1,140,0,0,0,0,0,0,0,0,0,0
0,0,0,0,0,0,0,0,0,0,0,1,185,0,0,0,185,1,139,142,139,142,139,1,186,186,186,186,186,1,0,0,0,0,0,0,0,0,0,0,0
0,0,0,0,0,0,0,0,0,0,141,1,1,1,1,1,1,1,0,0,0,0,0,1,1,1,1,1,1,1,140,0,0,0,0,0,0,0,0,0,0
0,0,0,0,0,0,0,0,0,0,0,139,0,139,0,139,0,139,0,0,0,0,0,139,0,139,0,139,0,139,0,0,0,0,0,0,0,0,0,0,0
0,0,0,0,0,0,0,0,0,0,0,0,0,0,0,0,0,0,0,0,0,0,0,0,0,0,0,0,0,0,0,0,0,0,0,0,0,0,0,0,0
0,0,1,0,1,78,1,0,1,0,0,0,0,0,0,0,0,0,0,0,0,0,0,0,0,0,0,0,0,0,0,0,1,0,1,78,1,0,1,0,0
0,0,0,0,0,0,227,0,0,0,0,0,0,0,0,0,0,0,0,0,0,0,0,0,0,0,0,0,0,0,0,0,0,0,227,0,0,0,0,0,0
0,0,1,0,0,0,0,0,1,0,0,0,0,0,0,0,0,0,0,0,0,0,0,0,0,0,0,0,0,0,0,0,1,0,0,0,0,0,1,0,0
0,0,0,0,0,0,0,0,29,0,0,0,0,0,0,0,0,0,0,0,0,0,0,0,0,0,0,0,0,0,0,0,27,0,0,0,0,0,0,0,0
0,0,1,0,0,0,0,0,1,0,0,0,0,0,0,0,0,0,0,0,0,0,0,0,0,0,0,0,0,0,0,0,1,0,0,0,0,0,1,0,0
0,0,0,0,0,0,0,0,0,0,0,0,0,0,0,0,0,0,0,0,0,0,0,0,0,0,0,0,0,0,0,0,0,0,0,0,0,0,0,0,0
0,0,1,0,1,0,1,0,1,0,0,0,0,0,0,0,0,0,0,0,0,0,0,0,0,0,0,0,0,0,0,0,1,0,1,0,1,0,1,0,0
0,0,0,0,0,0,0,0,0,0,0,0,0,0,0,0,0,0,0,0,0,0,0,0,0,0,0,0,0,0,0,0,0,0,0,0,0,0,0,0,0
0,0,0,0,0,0,0,0,0,0,0,0,0,0,0,0,0,0,0,0,0,0,0,0,0,0,0,0,0,0,0,0,0,0,0,0,0,0,0,0,0
:endlayer
layer: 15
0,0,0,0,0,0,0,0,0,0,0,0,0,0,0,0,0,0,0,0,0,0,0,0,0,0,0,0,0,0,0,0,0,0,0,0,0,0,0,0,0
0,0,0,0,0,0,0,0,0,0,0,0,0,0,0,0,0,0,0,0,0,0,0,0,0,0,0,0,0,0,0,0,0,0,0,0,0,0,0,0,0
0,0,1,147,1,147,1,147,1,0,0,0,0,0,0,0,0,0,0,0,0,0,0,0,0,0,0,0,0,0,0,0,1,147,1,147,1,147,1,0,0
0,0,141,0,0,142,0,0,140,0,0,0,0,0,0,0,0,0,0,0,0,0,0,0,0,0,0,0,0,0,0,0,141,0,0,142,0,0,140,0,0
0,0,1,0,0,0,0,0,1,0,0,0,0,0,0,0,0,0,0,0,0,0,0,0,0,0,0,0,0,0,0,0,1,0,0,0,0,0,1,0,0
0,0,141,137,0,0,0,138,140,0,0,0,0,0,0,0,0,0,0,0,0,0,0,0,0,0,0,0,0,0,0,0,141,137,0,0,0,138,140,0,0
0,0,1,0,0,0,0,0,1,0,0,0,0,0,0,0,0,0,0,0,0,0,0,0,0,0,0,0,0,0,0,0,1,0,0,0,0,0,1,0,0
0,0,141,0,0,146,208,0,140,0,0,0,0,0,0,0,0,0,0,0,0,0,0,0,0,0,0,0,0,0,0,0,141,0,208,146,0,0,140,0,0
0,0,1,139,1,139,1,139,1,0,0,178,178,178,178,178,178,178,178,178,178,178,178,178,178,178,178,178,178,178,0,0,1,139,1,139,1,139,1,0,0
0,0,0,0,0,0,0,0,0,0,0,178,1,1,1,1,1,1,1,1,1,1,1,1,1,1,1,1,1,178,0,0,0,0,0,0,0,0,0,0,0
0,0,0,0,0,0,0,0,0,0,0,178,1,7,7,7,7,7,7,7,7,7,105,0,0,0,15,7,1,178,0,0,0,0,0,0,0,0,0,0,0
0,0,0,0,0,0,0,0,0,0,0,178,1,7,6,6,6,6,6,6,6,6,6,7,7,7,7,7,1,178,0,0,0,0,0,0,0,0,0,0,0
0,0,0,0,0,0,0,0,0,0,178,178,1,7,7,7,7,7,7,7,7,7,7,7,7,7,7,7,1,178,178,0,0,0,0,0,0,0,0,0,0
0,0,0,0,0,0,0,0,0,0,178,1,1,1,1,1,1,7,7,6,147,6,7,7,1,1,1,1,1,1,178,0,0,0,0,0,0,0,0,0,0
0,0,0,0,0,0,0,0,0,0,178,1,239,239,239,239,239,1,7,141,175,140,7,1,239,239,239,239,239,1,178,0,0,0,0,0,0,0,0,0,0
0,0,0,0,0,0,0,0,0,0,178,1,239,6,147,6,239,1,7,6,139,6,7,1,239,6,147,6,239,1,178,0,0,0,0,0,0,0,0,0,0
0,0,0,0,0,0,0,0,0,0,178,1,239,141,175,140,239,1,7,7,7,7,7,1,239,141,175,140,239,1,178,0,0,0,0,0,0,0,0,0,0
0,0,0,0,0,0,0,0,0,0,178,1,239,6,139,6,239,1,1,1,1,1,1,1,239,6,139,6,239,1,178,0,0,0,0,0,0,0,0,0,0
0,0,0,0,0,0,0,0,0,0,178,1,239,239,239,239,239,1,5,178,178,178,5,1,239,239,239,239,239,1,178,0,0,0,0,0,0,0,0,0,0
0,0,0,0,0,0,0,0,0,0,178,1,1,1,1,1,1,1,178,0,0,0,178,1,1,1,1,1,1,1,178,0,0,0,0,0,0,0,0,0,0
0,0,0,0,0,0,0,0,0,0,178,178,178,178,178,178,178,178,178,0,0,0,178,178,178,178,178,178,178,178,178,0,0,0,0,0,0,0,0,0,0
0,0,0,0,0,0,0,0,0,0,0,0,0,0,0,0,0,0,0,0,0,0,0,0,0,0,0,0,0,0,0,0,0,0,0,0,0,0,0,0,0
0,0,1,147,1,147,1,147,1,0,0,0,0,0,0,0,0,0,0,0,0,0,0,0,0,0,0,0,0,0,0,0,1,147,1,147,1,147,1,0,0
0,0,141,0,0,142,227,0,140,0,0,0,0,0,0,0,0,0,0,0,0,0,0,0,0,0,0,0,0,0,0,0,141,0,227,142,0,0,140,0,0
0,0,1,0,0,0,0,0,1,0,0,0,0,0,0,0,0,0,0,0,0,0,0,0,0,0,0,0,0,0,0,0,1,0,0,0,0,0,1,0,0
0,0,141,137,0,0,0,138,140,0,0,0,0,0,0,0,0,0,0,0,0,0,0,0,0,0,0,0,0,0,0,0,141,137,0,0,0,138,140,0,0
0,0,1,0,0,0,0,0,1,0,0,0,0,0,0,0,0,0,0,0,0,0,0,0,0,0,0,0,0,0,0,0,1,0,0,0,0,0,1,0,0
0,0,141,0,0,146,0,0,140,0,0,0,0,0,0,0,0,0,0,0,0,0,0,0,0,0,0,0,0,0,0,0,141,0,0,146,0,0,140,0,0
0,0,1,139,1,139,1,139,1,0,0,0,0,0,0,0,0,0,0,0,0,0,0,0,0,0,0,0,0,0,0,0,1,139,1,139,1,139,1,0,0
0,0,0,0,0,0,0,0,0,0,0,0,0,0,0,0,0,0,0,0,0,0,0,0,0,0,0,0,0,0,0,0,0,0,0,0,0,0,0,0,0
0,0,0,0,0,0,0,0,0,0,0,0,0,0,0,0,0,0,0,0,0,0,0,0,0,0,0,0,0,0,0,0,0,0,0,0,0,0,0,0,0
:endlayer
layer: 16
0,0,0,0,0,0,0,0,0,0,0,0,0,0,0,0,0,0,0,0,0,0,0,0,0,0,0,0,0,0,0,0,0,0,0,0,0,0,0,0,0
0,0,159,0,159,0,159,0,159,0,0,0,0,0,0,0,0,0,0,0,0,0,0,0,0,0,0,0,0,0,0,0,159,0,159,0,159,0,159,0,0
0,148,5,5,5,5,5,5,5,105,0,0,0,0,0,0,0,0,0,0,0,0,0,0,0,0,0,0,0,0,0,148,5,5,5,5,5,5,5,105,0
0,0,5,0,0,0,0,0,5,0,0,0,0,0,0,0,0,0,0,0,0,0,0,0,0,0,0,0,0,0,0,0,5,0,0,0,0,0,5,0,0
0,148,5,0,0,0,0,0,5,105,0,0,0,0,0,0,0,0,0,0,0,0,0,0,0,0,0,0,0,0,0,148,5,0,0,0,0,0,5,105,0
0,0,5,0,0,0,0,0,5,0,0,0,0,0,0,0,0,0,0,0,0,0,0,0,0,0,0,0,0,0,0,0,5,0,0,0,0,0,5,0,0
0,148,5,0,0,0,0,0,5,105,0,0,0,0,0,0,0,0,0,0,0,0,0,0,0,0,0,0,0,0,0,148,5,0,0,0,0,0,5,105,0
0,0,5,0,0,0,208,0,5,0,0,0,0,0,0,0,0,0,0,0,0,0,0,0,0,0,0,0,0,0,0,0,5,0,208,0,0,0,5,0,0
0,148,5,5,5,5,5,5,5,105,0,0,0,159,0,159,0,159,0,159,0,159,0,159,0,159,0,159,0,0,0,148,5,5,5,5,5,5,5,105,0
0,0,174,0,174,0,174,0,174,0,0,0,7,7,7,7,7,7,7,7,7,7,7,7,7,7,7,7,7,0,0,0,174,0,174,0,174,0,174,0,0
0,0,0,0,0,0,0,0,0,0,0,148,7,4,4,4,4,4,4,4,4,4,4,105,0,0,0,15,7,105,0,0,0,0,0,0,0,0,0,0,0
0,0,0,0,0,0,0,0,0,0,0,0,7,4,4,4,4,4,4,4,4,4,4,1,1,1,1,1,7,0,0,0,0,0,0,0,0,0,0,0,0
0,0,0,0,0,0,0,0,0,0,0,148,7,4,4,4,4,4,4,4,3,3,3,1,1,1,1,1,7,105,0,0,0,0,0,0,0,0,0,0,0
0,0,0,0,0,0,0,0,0,0,0,7,7,7,7,7,7,7,4,4,3,4,4,7,7,7,7,7,7,7,0,0,0,0,0,0,0,0,0,0,0
0,0,0,0,0,0,0,0,0,0,148,7,1,1,1,1,1,7,3,3,3,3,3,7,1,1,1,1,1,7,105,0,0,0,0,0,0,0,0,0,0
0,0,0,0,0,0,0,0,0,0,0,7,1,1,1,1,1,7,3,3,3,3,3,7,1,1,1,1,1,7,0,0,0,0,0,0,0,0,0,0,0
0,0,0,0,0,0,0,0,0,0,148,7,1,1,1,1,1,7,4,4,4,4,4,7,1,1,1,1,1,7,105,0,0,0,0,0,0,0,0,0,0
0,0,0,0,0,0,0,0,0,0,0,7,1,1,1,1,1,7,7,7,7,7,7,7,1,1,1,1,1,7,0,0,0,0,0,0,0,0,0,0,0
0,0,0,0,0,0,0,0,0,0,148,7,1,1,1,1,1,7,5,174,0,174,5,7,1,1,1,1,1,7,105,0,0,0,0,0,0,0,0,0,0
0,0,0,0,0,0,0,0,0,0,0,7,7,7,7,7,7,7,105,0,0,0,148,7,7,7,7,7,7,7,0,0,0,0,0,0,0,0,0,0,0
0,0,0,0,0,0,0,0,0,0,0,0,174,0,174,0,174,0,0,0,0,0,0,0,174,0,174,0,174,0,0,0,0,0,0,0,0,0,0,0,0
0,0,159,0,159,0,159,0,159,0,0,0,0,0,0,0,0,0,0,0,0,0,0,0,0,0,0,0,0,0,0,0,159,0,159,0,159,0,159,0,0
0,148,5,5,5,5,5,5,5,105,0,0,0,0,0,0,0,0,0,0,0,0,0,0,0,0,0,0,0,0,0,148,5,5,5,5,5,5,5,105,0
0,0,5,0,0,0,227,0,5,0,0,0,0,0,0,0,0,0,0,0,0,0,0,0,0,0,0,0,0,0,0,0,5,0,227,0,0,0,5,0,0
0,148,5,0,0,0,0,0,5,105,0,0,0,0,0,0,0,0,0,0,0,0,0,0,0,0,0,0,0,0,0,148,5,0,0,0,0,0,5,105,0
0,0,5,0,0,0,0,0,5,0,0,0,0,0,0,0,0,0,0,0,0,0,0,0,0,0,0,0,0,0,0,0,5,0,0,0,0,0,5,0,0
0,148,5,0,0,0,0,0,5,105,0,0,0,0,0,0,0,0,0,0,0,0,0,0,0,0,0,0,0,0,0,148,5,0,0,0,0,0,5,105,0
0,0,5,0,0,0,0,0,5,0,0,0,0,0,0,0,0,0,0,0,0,0,0,0,0,0,0,0,0,0,0,0,5,0,0,0,0,0,5,0,0
0,148,5,5,5,5,5,5,5,105,0,0,0,0,0,0,0,0,0,0,0,0,0,0,0,0,0,0,0,0,0,148,5,5,5,5,5,5,5,105,0
0,0,174,0,174,0,174,0,174,0,0,0,0,0,0,0,0,0,0,0,0,0,0,0,0,0,0,0,0,0,0,0,174,0,174,0,174,0,174,0,0
0,0,0,0,0,0,0,0,0,0,0,0,0,0,0,0,0,0,0,0,0,0,0,0,0,0,0,0,0,0,0,0,0,0,0,0,0,0,0,0,0
:endlayer
layer: 17
0,0,0,0,0,0,0,0,0,0,0,0,0,0,0,0,0,0,0,0,0,0,0,0,0,0,0,0,0,0,0,0,0,0,0,0,0,0,0,0,0
0,0,176,176,176,176,176,176,176,0,0,0,0,0,0,0,0,0,0,0,0,0,0,0,0,0,0,0,0,0,0,0,176,176,176,176,176,176,176,0,0
0,176,1,1,1,1,1,1,1,176,0,0,0,0,0,0,0,0,0,0,0,0,0,0,0,0,0,0,0,0,0,176,1,1,1,1,1,1,1,176,0
0,176,1,1,1,1,1,1,1,176,0,0,0,0,0,0,0,0,0,0,0,0,0,0,0,0,0,0,0,0,0,176,1,1,1,1,1,1,1,176,0
0,176,1,1,1,1,1,1,1,176,0,0,0,0,0,0,0,0,0,0,0,0,0,0,0,0,0,0,0,0,0,176,1,1,1,1,1,1,1,176,0
0,176,1,1,1,1,1,1,1,176,0,0,0,0,0,0,0,0,0,0,0,0,0,0,0,0,0,0,0,0,0,176,1,1,1,1,1,1,1,176,0
0,176,1,1,1,1,1,1,1,176,0,0,0,0,0,0,0,0,0,0,0,0,0,0,0,0,0,0,0,0,0,176,1,1,1,1,1,1,1,176,0
0,176,1,1,1,1,208,1,1,176,0,0,0,0,0,0,0,0,0,0,0,0,0,0,0,0,0,0,0,0,0,176,1,1,208,1,1,1,1,176,0
0,176,1,1,1,1,1,1,1,176,0,0,176,176,176,176,176,176,176,176,176,176,176,176,176,176,176,176,176,0,0,176,1,1,1,1,1,1,1,176,0
0,0,176,176,176,176,176,176,176,0,0,176,5,5,5,5,5,5,5,5,5,5,5,5,5,5,5,5,5,176,0,0,176,176,176,176,176,176,176,0,0
0,0,0,0,0,0,0,0,0,0,0,176,5,0,0,0,0,0,0,0,0,0,0,185,0,0,0,0,5,176,0,0,0,0,0,0,0,0,0,0,0
0,0,0,0,0,0,0,0,0,0,0,176,5,0,0,0,0,240,0,0,241,0,0,185,185,185,185,0,5,176,0,0,0,0,0,0,0,0,0,0,0
0,0,0,0,0,0,0,0,0,0,0,176,5,0,0,0,0,0,0,0,0,0,0,0,0,0,0,0,5,176,0,0,0,0,0,0,0,0,0,0,0
0,0,0,0,0,0,0,0,0,0,176,5,5,5,5,5,5,5,12,0,0,0,12,5,5,5,5,5,5,5,176,0,0,0,0,0,0,0,0,0,0
0,0,0,0,0,0,0,0,0,0,176,5,0,0,0,0,0,0,0,0,0,0,0,0,0,0,0,0,0,5,176,0,0,0,0,0,0,0,0,0,0
0,0,0,0,0,0,0,0,0,0,176,5,0,0,0,0,0,0,0,0,0,0,0,0,0,0,0,0,0,5,176,0,0,0,0,0,0,0,0,0,0
0,0,0,0,0,0,0,0,0,0,176,5,0,0,242,0,0,5,12,0,0,0,12,5,0,0,243,0,0,5,176,0,0,0,0,0,0,0,0,0,0
0,0,0,0,0,0,0,0,0,0,176,5,0,0,0,0,0,5,5,5,5,5,5,5,0,0,0,0,0,5,176,0,0,0,0,0,0,0,0,0,0
0,0,0,0,0,0,0,0,0,0,176,5,0,0,208,0,0,5,176,176,176,176,176,5,0,0,208,0,0,5,176,0,0,0,0,0,0,0,0,0,0
0,0,0,0,0,0,0,0,0,0,176,5,5,5,5,5,5,5,176,0,0,0,176,5,5,5,5,5,5,5,176,0,0,0,0,0,0,0,0,0,0
0,0,0,0,0,0,0,0,0,0,0,176,176,176,176,176,176,176,0,0,0,0,0,176,176,176,176,176,176,176,0,0,0,0,0,0,0,0,0,0,0
0,0,176,176,176,176,176,176,176,0,0,0,0,0,0,0,0,0,0,0,0,0,0,0,0,0,0,0,0,0,0,0,176,176,176,176,176,176,176,0,0
0,176,1,1,1,1,1,1,1,176,0,0,0,0,0,0,0,0,0,0,0,0,0,0,0,0,0,0,0,0,0,176,1,1,1,1,1,1,1,176,0
0,176,1,1,1,1,227,1,1,176,0,0,0,0,0,0,0,0,0,0,0,0,0,0,0,0,0,0,0,0,0,176,1,1,227,1,1,1,1,176,0
0,176,1,1,1,1,1,1,1,176,0,0,0,0,0,0,0,0,0,0,0,0,0,0,0,0,0,0,0,0,0,176,1,1,1,1,1,1,1,176,0
0,176,1,1,1,1,1,1,1,176,0,0,0,0,0,0,0,0,0,0,0,0,0,0,0,0,0,0,0,0,0,176,1,1,1,1,1,1,1,176,0
0,176,1,1,1,1,1,1,1,176,0,0,0,0,0,0,0,0,0,0,0,0,0,0,0,0,0,0,0,0,0,176,1,1,1,1,1,1,1,176,0
0,176,1,1,1,1,1,1,1,176,0,0,0,0,0,0,0,0,0,0,0,0,0,0,0,0,0,0,0,0,0,176,1,1,1,1,1,1,1,176,0
0,176,1,1,1,1,1,1,1,176,0,0,0,0,0,0,0,0,0,0,0,0,0,0,0,0,0,0,0,0,0,176,1,1,1,1,1,1,1,176,0
0,0,176,176,176,176,176,176,176,0,0,0,0,0,0,0,0,0,0,0,0,0,0,0,0,0,0,0,0,0,0,0,176,176,176,176,176,176,176,0,0
0,0,0,0,0,0,0,0,0,0,0,0,0,0,0,0,0,0,0,0,0,0,0,0,0,0,0,0,0,0,0,0,0,0,0,0,0,0,0,0,0
:endlayer
layer: 18
0,0,0,0,0,0,0,0,0,0,0,0,0,0,0,0,0,0,0,0,0,0,0,0,0,0,0,0,0,0,0,0,0,0,0,0,0,0,0,0,0
0,0,0,0,0,0,0,0,0,0,0,0,0,0,0,0,0,0,0,0,0,0,0,0,0,0,0,0,0,0,0,0,0,0,0,0,0,0,0,0,0
0,0,5,29,0,176,0,27,5,0,0,0,0,0,0,0,0,0,0,0,0,0,0,0,0,0,0,0,0,0,0,0,5,29,0,176,0,27,5,0,0
0,0,14,12,0,0,0,12,14,0,0,0,0,0,0,0,0,0,0,0,0,0,0,0,0,0,0,0,0,0,0,0,14,0,0,0,0,0,14,0,0
0,0,0,0,0,0,244,0,0,0,0,0,0,0,0,0,0,0,0,0,0,0,0,0,0,0,0,0,0,0,0,0,0,0,245,0,0,0,0,0,0
0,0,176,0,0,199,0,0,176,0,0,0,0,0,0,0,0,0,0,0,0,0,0,0,0,0,0,0,0,0,0,0,176,0,0,199,0,0,176,0,0
0,0,0,0,246,0,0,0,0,0,0,0,0,0,0,0,0,0,0,0,0,0,0,0,0,0,0,0,0,0,0,0,0,0,0,0,247,0,0,0,0
0,0,78,12,248,0,0,12,78,0,0,0,0,0,0,0,0,0,0,0,0,0,0,0,0,0,0,0,0,0,0,0,78,249,0,0,0,0,78,0,0
0,0,5,29,0,176,0,27,5,0,0,0,0,0,0,0,0,0,0,0,0,0,0,0,0,0,0,0,0,0,0,0,5,29,0,176,0,27,5,0,0
0,0,0,0,0,0,0,0,0,0,0,0,8,84,8,84,8,84,8,84,8,84,8,84,8,84,8,84,8,0,0,0,0,0,0,0,0,0,0,0,0
0,0,0,0,0,0,0,0,0,0,0,0,15,0,0,0,0,0,0,142,0,0,0,0,0,0,0,0,13,0,0,0,0,0,0,0,0,0,0,0,0
0,0,0,0,0,0,0,0,0,0,0,0,8,0,0,0,0,0,0,0,0,0,0,0,0,0,0,0,8,0,0,0,0,0,0,0,0,0,0,0,0
0,0,0,0,0,0,0,0,0,0,0,0,15,0,0,0,0,0,0,0,0,0,0,0,0,0,0,0,13,0,0,0,0,0,0,0,0,0,0,0,0
0,0,0,0,0,0,0,0,0,0,0,1,0,0,1,0,0,1,12,0,0,0,12,1,0,0,1,0,0,1,0,0,0,0,0,0,0,0,0,0,0
0,0,0,0,0,0,0,0,0,0,0,0,0,0,0,0,0,0,0,0,0,0,0,0,0,0,0,0,0,0,0,0,0,0,0,0,0,0,0,0,0
0,0,0,0,0,0,0,0,0,0,0,0,0,0,0,0,0,0,0,0,0,0,0,0,0,0,0,0,0,0,0,0,0,0,0,0,0,0,0,0,0
0,0,0,0,0,0,0,0,0,0,0,1,0,0,0,0,0,1,12,0,146,0,12,1,0,0,0,0,0,1,0,0,0,0,0,0,0,0,0,0,0
0,0,0,0,0,0,0,0,0,0,0,0,0,0,0,0,0,8,11,8,11,8,11,8,0,0,0,0,0,0,0,0,0,0,0,0,0,0,0,0,0
0,0,0,0,0,0,0,0,0,0,0,0,0,0,208,0,0,178,0,0,0,0,0,178,0,0,208,0,0,0,0,0,0,0,0,0,0,0,0,0,0
0,0,0,0,0,0,0,0,0,0,0,1,0,0,1,0,0,1,0,0,0,0,0,1,0,0,1,0,0,1,0,0,0,0,0,0,0,0,0,0,0
0,0,0,0,0,0,0,0,0,0,0,0,0,0,0,0,0,0,0,0,0,0,0,0,0,0,0,0,0,0,0,0,0,0,0,0,0,0,0,0,0
0,0,0,0,0,0,0,0,0,0,0,0,0,0,0,0,0,0,0,0,0,0,0,0,0,0,0,0,0,0,0,0,0,0,0,0,0,0,0,0,0
0,0,5,29,0,176,0,27,5,0,0,0,0,0,0,0,0,0,0,0,0,0,0,0,0,0,0,0,0,0,0,0,5,29,0,176,0,27,5,0,0
0,0,14,0,0,0,0,250,14,0,0,0,0,0,0,0,0,0,0,0,0,0,0,0,0,0,0,0,0,0,0,0,14,12,0,0,251,12,14,0,0
0,0,0,0,252,0,0,0,0,0,0,0,0,0,0,0,0,0,0,0,0,0,0,0,0,0,0,0,0,0,0,0,0,0,0,0,253,0,0,0,0
0,0,176,0,0,199,0,0,176,0,0,0,0,0,0,0,0,0,0,0,0,0,0,0,0,0,0,0,0,0,0,0,176,0,0,199,0,0,176,0,0
0,0,0,0,0,0,254,0,0,0,0,0,0,0,0,0,0,0,0,0,0,0,0,0,0,0,0,0,0,0,0,0,0,0,255,0,0,0,0,0,0
0,0,78,0,0,0,0,0,78,0,0,0,0,0,0,0,0,0,0,0,0,0,0,0,0,0,0,0,0,0,0,0,78,12,0,0,0,12,78,0,0
0,0,5,29,0,176,0,27,5,0,0,0,0,0,0,0,0,0,0,0,0,0,0,0,0,0,0,0,0,0,0,0,5,29,0,176,0,27,5,0,0
0,0,0,0,0,0,0,0,0,0,0,0,0,0,0,0,0,0,0,0,0,0,0,0,0,0,0,0,0,0,0,0,0,0,0,0,0,0,0,0,0
0,0,0,0,0,0,0,0,0,0,0,0,0,0,0,0,0,0,0,0,0,0,0,0,0,0,0,0,0,0,0,0,0,0,0,0,0,0,0,0,0
:endlayer
layer: 19
0,0,0,0,0,0,0,0,0,0,0,0,0,0,0,0,0,0,0,0,0,0,0,0,0,0,0,0,0,0,0,0,0,0,0,0,0,0,0,0,0
0,0,0,0,0,0,0,0,0,0,0,0,0,0,0,0,0,0,0,0,0,0,0,0,0,0,0,0,0,0,0,0,0,0,0,0,0,0,0,0,0
0,0,176,0,0,0,0,0,176,0,0,0,0,0,0,0,0,0,0,0,0,0,0,0,0,0,0,0,0,0,0,0,176,0,0,0,0,0,176,0,0
0,0,0,12,0,0,0,12,0,0,0,0,0,0,0,0,0,0,0,0,0,0,0,0,0,0,0,0,0,0,0,0,0,0,0,0,0,0,0,0,0
0,0,0,0,0,0,0,0,0,0,0,0,0,0,0,0,0,0,0,0,0,0,0,0,0,0,0,0,0,0,0,0,0,0,0,0,0,0,0,0,0
0,0,0,0,0,0,0,0,0,0,0,0,0,0,0,0,0,0,0,0,0,0,0,0,0,0,0,0,0,0,0,0,0,0,0,0,0,0,0,0,0
0,0,0,0,0,0,0,0,0,0,0,0,0,0,0,0,0,0,0,0,0,0,0,0,0,0,0,0,0,0,0,0,0,0,0,0,0,0,0,0,0
0,0,0,12,0,0,0,12,0,0,0,0,0,0,0,0,0,0,0,0,0,0,0,0,0,0,0,0,0,0,0,0,0,0,0,0,0,0,0,0,0
0,0,176,0,0,0,0,0,176,0,0,0,0,0,0,0,0,0,0,0,0,0,0,0,0,0,0,0,0,0,0,0,176,0,0,0,0,0,176,0,0
0,0,0,0,0,0,0,0,0,0,0,0,178,0,178,0,178,0,178,0,178,0,178,0,178,0,178,0,178,0,0,0,0,0,0,0,0,0,0,0,0
0,0,0,0,0,0,0,0,0,0,0,0,0,0,0,0,0,0,0,0,0,0,0,0,0,0,0,0,0,0,0,0,0,0,0,0,0,0,0,0,0
0,0,0,0,0,0,0,0,0,0,0,0,178,0,0,0,0,0,0,0,0,0,0,0,0,0,0,0,178,0,0,0,0,0,0,0,0,0,0,0,0
0,0,0,0,0,0,0,0,0,0,0,0,0,0,146,0,0,146,0,0,0,0,0,146,0,0,146,0,0,0,0,0,0,0,0,0,0,0,0,0,0
0,0,0,0,0,0,0,0,0,0,0,1,0,0,1,0,0,1,12,0,0,0,12,1,0,0,1,0,0,1,0,0,0,0,0,0,0,0,0,0,0
0,0,0,0,0,0,0,0,0,0,0,0,0,0,0,0,0,0,0,0,0,0,0,0,0,0,0,0,0,0,0,0,0,0,0,0,0,0,0,0,0
0,0,0,0,0,0,0,0,0,0,0,0,0,0,0,0,0,0,0,0,0,0,0,0,0,0,0,0,0,0,0,0,0,0,0,0,0,0,0,0,0
0,0,0,0,0,0,0,0,0,0,0,1,0,0,0,0,0,1,12,0,0,0,12,1,0,0,0,0,0,1,0,0,0,0,0,0,0,0,0,0,0
0,0,0,0,0,0,0,0,0,0,0,0,0,0,0,0,0,178,0,178,0,178,0,178,0,0,0,0,0,0,0,0,0,0,0,0,0,0,0,0,0
0,0,0,0,0,0,0,0,0,0,0,0,0,0,208,0,0,0,0,0,0,0,0,0,0,0,208,0,0,0,0,0,0,0,0,0,0,0,0,0,0
0,0,0,0,0,0,0,0,0,0,0,1,0,0,1,0,0,1,0,0,0,0,0,1,0,0,1,0,0,1,0,0,0,0,0,0,0,0,0,0,0
0,0,0,0,0,0,0,0,0,0,0,0,0,0,0,0,0,0,0,0,0,0,0,0,0,0,0,0,0,0,0,0,0,0,0,0,0,0,0,0,0
0,0,0,0,0,0,0,0,0,0,0,0,0,0,0,0,0,0,0,0,0,0,0,0,0,0,0,0,0,0,0,0,0,0,0,0,0,0,0,0,0
0,0,176,0,0,0,0,0,176,0,0,0,0,0,0,0,0,0,0,0,0,0,0,0,0,0,0,0,0,0,0,0,176,0,0,0,0,0,176,0,0
0,0,0,0,0,0,0,0,0,0,0,0,0,0,0,0,0,0,0,0,0,0,0,0,0,0,0,0,0,0,0,0,0,12,0,0,0,12,0,0,0
0,0,0,0,0,0,0,0,0,0,0,0,0,0,0,0,0,0,0,0,0,0,0,0,0,0,0,0,0,0,0,0,0,0,0,0,0,0,0,0,0
0,0,0,0,0,0,0,0,0,0,0,0,0,0,0,0,0,0,0,0,0,0,0,0,0,0,0,0,0,0,0,0,0,0,0,0,0,0,0,0,0
0,0,0,0,0,0,0,0,0,0,0,0,0,0,0,0,0,0,0,0,0,0,0,0,0,0,0,0,0,0,0,0,0,0,0,0,0,0,0,0,0
0,0,0,0,0,0,0,0,0,0,0,0,0,0,0,0,0,0,0,0,0,0,0,0,0,0,0,0,0,0,0,0,0,12,0,0,0,12,0,0,0
0,0,176,0,0,0,0,0,176,0,0,0,0,0,0,0,0,0,0,0,0,0,0,0,0,0,0,0,0,0,0,0,176,0,0,0,0,0,176,0,0
0,0,0,0,0,0,0,0,0,0,0,0,0,0,0,0,0,0,0,0,0,0,0,0,0,0,0,0,0,0,0,0,0,0,0,0,0,0,0,0,0
0,0,0,0,0,0,0,0,0,0,0,0,0,0,0,0,0,0,0,0,0,0,0,0,0,0,0,0,0,0,0,0,0,0,0,0,0,0,0,0,0
:endlayer
layer: 20
0,0,0,0,0,0,0,0,0,0,0,0,0,0,0,0,0,0,0,0,0,0,0,0,0,0,0,0,0,0,0,0,0,0,0,0,0,0,0,0,0
0,0,0,0,0,0,0,0,0,0,0,0,0,0,0,0,0,0,0,0,0,0,0,0,0,0,0,0,0,0,0,0,0,0,0,0,0,0,0,0,0
0,0,0,0,0,0,0,0,0,0,0,0,0,0,0,0,0,0,0,0,0,0,0,0,0,0,0,0,0,0,0,0,0,0,0,0,0,0,0,0,0
0,0,0,12,0,0,0,12,0,0,0,0,0,0,0,0,0,0,0,0,0,0,0,0,0,0,0,0,0,0,0,0,0,0,0,0,0,0,0,0,0
0,0,0,0,0,0,0,0,0,0,0,0,0,0,0,0,0,0,0,0,0,0,0,0,0,0,0,0,0,0,0,0,0,0,0,0,0,0,0,0,0
0,0,0,0,0,0,0,0,0,0,0,0,0,0,0,0,0,0,0,0,0,0,0,0,0,0,0,0,0,0,0,0,0,0,0,0,0,0,0,0,0
0,0,0,0,0,0,0,0,0,0,0,0,0,0,0,0,0,0,0,0,0,0,0,0,0,0,0,0,0,0,0,0,0,0,0,0,0,0,0,0,0
0,0,0,12,0,0,0,12,0,0,0,0,0,0,0,0,0,0,0,0,0,0,0,0,0,0,0,0,0,0,0,0,0,0,0,0,0,0,0,0,0
0,0,0,0,0,0,0,0,0,0,0,0,0,0,0,0,0,0,0,0,0,0,0,0,0,0,0,0,0,0,0,0,0,0,0,0,0,0,0,0,0
0,0,0,0,0,0,0,0,0,0,0,0,0,0,0,0,0,0,0,0,0,0,0,0,0,0,0,0,0,0,0,0,0,0,0,0,0,0,0,0,0
0,0,0,0,0,0,0,0,0,0,0,0,0,0,0,0,0,0,0,0,0,0,0,0,0,0,0,0,0,0,0,0,0,0,0,0,0,0,0,0,0
0,0,0,0,0,0,0,0,0,0,0,0,0,0,0,0,0,0,0,0,0,0,0,0,0,0,0,0,0,0,0,0,0,0,0,0,0,0,0,0,0
0,0,0,0,0,0,0,0,0,0,0,0,0,0,0,0,0,0,0,0,0,0,0,0,0,0,0,0,0,0,0,0,0,0,0,0,0,0,0,0,0
0,0,0,0,0,0,0,0,0,0,0,8,105,148,8,105,148,8,256,256,256,256,256,8,105,148,8,105,148,8,0,0,0,0,0,0,0,0,0,0,0
0,0,0,0,0,0,0,0,0,0,0,174,0,0,142,0,0,174,180,257,180,257,180,174,0,0,142,0,0,174,0,0,0,0,0,0,0,0,0,0,0
0,0,0,0,0,0,0,0,0,0,0,159,0,0,0,0,0,159,180,257,180,257,180,159,0,0,0,0,0,159,0,0,0,0,0,0,0,0,0,0,0
0,0,0,0,0,0,0,0,0,0,0,8,137,0,0,0,138,8,256,256,256,256,256,8,137,0,0,0,138,8,0,0,0,0,0,0,0,0,0,0,0
0,0,0,0,0,0,0,0,0,0,0,174,0,0,0,0,0,174,0,0,0,0,0,174,0,0,0,0,0,174,0,0,0,0,0,0,0,0,0,0,0
0,0,0,0,0,0,0,0,0,0,0,159,0,0,208,0,0,159,0,0,0,0,0,159,0,0,208,0,0,159,0,0,0,0,0,0,0,0,0,0,0
0,0,0,0,0,0,0,0,0,0,0,8,105,148,8,105,148,8,0,0,0,0,0,8,105,148,8,105,148,8,0,0,0,0,0,0,0,0,0,0,0
0,0,0,0,0,0,0,0,0,0,0,0,0,0,0,0,0,0,0,0,0,0,0,0,0,0,0,0,0,0,0,0,0,0,0,0,0,0,0,0,0
0,0,0,0,0,0,0,0,0,0,0,0,0,0,0,0,0,0,0,0,0,0,0,0,0,0,0,0,0,0,0,0,0,0,0,0,0,0,0,0,0
0,0,0,0,0,0,0,0,0,0,0,0,0,0,0,0,0,0,0,0,0,0,0,0,0,0,0,0,0,0,0,0,0,0,0,0,0,0,0,0,0
0,0,0,0,0,0,0,0,0,0,0,0,0,0,0,0,0,0,0,0,0,0,0,0,0,0,0,0,0,0,0,0,0,12,0,0,0,12,0,0,0
0,0,0,0,0,0,0,0,0,0,0,0,0,0,0,0,0,0,0,0,0,0,0,0,0,0,0,0,0,0,0,0,0,0,0,0,0,0,0,0,0
0,0,0,0,0,0,0,0,0,0,0,0,0,0,0,0,0,0,0,0,0,0,0,0,0,0,0,0,0,0,0,0,0,0,0,0,0,0,0,0,0
0,0,0,0,0,0,0,0,0,0,0,0,0,0,0,0,0,0,0,0,0,0,0,0,0,0,0,0,0,0,0,0,0,0,0,0,0,0,0,0,0
0,0,0,0,0,0,0,0,0,0,0,0,0,0,0,0,0,0,0,0,0,0,0,0,0,0,0,0,0,0,0,0,0,12,0,0,0,12,0,0,0
0,0,0,0,0,0,0,0,0,0,0,0,0,0,0,0,0,0,0,0,0,0,0,0,0,0,0,0,0,0,0,0,0,0,0,0,0,0,0,0,0
0,0,0,0,0,0,0,0,0,0,0,0,0,0,0,0,0,0,0,0,0,0,0,0,0,0,0,0,0,0,0,0,0,0,0,0,0,0,0,0,0
0,0,0,0,0,0,0,0,0,0,0,0,0,0,0,0,0,0,0,0,0,0,0,0,0,0,0,0,0,0,0,0,0,0,0,0,0,0,0,0,0
:endlayer
layer: 21
0,0,0,0,0,0,0,0,0,0,0,0,0,0,0,0,0,0,0,0,0,0,0,0,0,0,0,0,0,0,0,0,0,0,0,0,0,0,0,0,0
0,0,0,0,0,0,0,0,0,0,0,0,0,0,0,0,0,0,0,0,0,0,0,0,0,0,0,0,0,0,0,0,0,0,0,0,0,0,0,0,0
0,0,0,0,0,0,0,0,0,0,0,0,0,0,0,0,0,0,0,0,0,0,0,0,0,0,0,0,0,0,0,0,0,0,0,0,0,0,0,0,0
0,0,0,256,256,256,256,256,0,0,0,0,0,0,0,0,0,0,0,0,0,0,0,0,0,0,0,0,0,0,0,0,0,0,0,0,0,0,0,0,0
0,0,0,256,257,180,257,256,0,0,0,0,0,0,0,0,0,0,0,0,0,0,0,0,0,0,0,0,0,0,0,0,0,0,0,0,0,0,0,0,0
0,0,0,256,257,180,257,256,0,0,0,0,0,0,0,0,0,0,0,0,0,0,0,0,0,0,0,0,0,0,0,0,0,0,0,0,0,0,0,0,0
0,0,0,256,257,180,257,256,0,0,0,0,0,0,0,0,0,0,0,0,0,0,0,0,0,0,0,0,0,0,0,0,0,0,0,0,0,0,0,0,0
0,0,0,256,256,256,256,256,0,0,0,0,0,0,0,0,0,0,0,0,0,0,0,0,0,0,0,0,0,0,0,0,0,0,0,0,0,0,0,0,0
0,0,0,0,0,0,0,0,0,0,0,0,0,0,0,0,0,0,0,0,0,0,0,0,0,0,0,0,0,0,0,0,0,0,0,0,0,0,0,0,0
0,0,0,0,0,0,0,0,0,0,0,0,0,0,0,0,0,0,0,0,0,0,0,0,0,0,0,0,0,0,0,0,0,0,0,0,0,0,0,0,0
0,0,0,0,0,0,0,0,0,0,0,0,0,0,0,0,0,0,0,0,0,0,0,0,0,0,0,0,0,0,0,0,0,0,0,0,0,0,0,0,0
0,0,0,0,0,0,0,0,0,0,0,0,0,0,0,0,0,0,0,0,0,0,0,0,0,0,0,0,0,0,0,0,0,0,0,0,0,0,0,0,0
0,0,0,0,0,0,0,0,0,0,0,0,0,0,0,0,0,0,0,0,0,0,0,0,0,0,0,0,0,0,0,0,0,0,0,0,0,0,0,0,0
0,0,0,0,0,0,0,0,0,0,0,7,7,7,7,7,7,7,0,0,0,0,0,7,7,7,7,7,7,7,0,0,0,0,0,0,0,0,0,0,0
0,0,0,0,0,0,0,0,0,0,0,7,1,1,1,1,1,7,0,0,0,0,0,7,1,1,1,1,1,7,0,0,0,0,0,0,0,0,0,0,0
0,0,0,0,0,0,0,0,0,0,0,7,1,1,1,1,1,7,0,0,0,0,0,7,1,1,1,1,1,7,0,0,0,0,0,0,0,0,0,0,0
0,0,0,0,0,0,0,0,0,0,0,7,1,1,1,1,1,7,0,0,0,0,0,7,1,1,1,1,1,7,0,0,0,0,0,0,0,0,0,0,0
0,0,0,0,0,0,0,0,0,0,0,7,1,1,1,1,1,7,0,0,0,0,0,7,1,1,1,1,1,7,0,0,0,0,0,0,0,0,0,0,0
0,0,0,0,0,0,0,0,0,0,0,7,1,1,208,1,1,7,0,0,0,0,0,7,1,1,208,1,1,7,0,0,0,0,0,0,0,0,0,0,0
0,0,0,0,0,0,0,0,0,0,0,7,7,7,7,7,7,7,0,0,0,0,0,7,7,7,7,7,7,7,0,0,0,0,0,0,0,0,0,0,0
0,0,0,0,0,0,0,0,0,0,0,0,0,0,0,0,0,0,0,0,0,0,0,0,0,0,0,0,0,0,0,0,0,0,0,0,0,0,0,0,0
0,0,0,0,0,0,0,0,0,0,0,0,0,0,0,0,0,0,0,0,0,0,0,0,0,0,0,0,0,0,0,0,0,0,0,0,0,0,0,0,0
0,0,0,0,0,0,0,0,0,0,0,0,0,0,0,0,0,0,0,0,0,0,0,0,0,0,0,0,0,0,0,0,0,0,0,0,0,0,0,0,0
0,0,0,0,0,0,0,0,0,0,0,0,0,0,0,0,0,0,0,0,0,0,0,0,0,0,0,0,0,0,0,0,0,256,256,256,256,256,0,0,0
0,0,0,0,0,0,0,0,0,0,0,0,0,0,0,0,0,0,0,0,0,0,0,0,0,0,0,0,0,0,0,0,0,256,180,180,180,256,0,0,0
0,0,0,0,0,0,0,0,0,0,0,0,0,0,0,0,0,0,0,0,0,0,0,0,0,0,0,0,0,0,0,0,0,256,257,257,257,256,0,0,0
0,0,0,0,0,0,0,0,0,0,0,0,0,0,0,0,0,0,0,0,0,0,0,0,0,0,0,0,0,0,0,0,0,256,180,180,180,256,0,0,0
0,0,0,0,0,0,0,0,0,0,0,0,0,0,0,0,0,0,0,0,0,0,0,0,0,0,0,0,0,0,0,0,0,256,256,256,256,256,0,0,0
0,0,0,0,0,0,0,0,0,0,0,0,0,0,0,0,0,0,0,0,0,0,0,0,0,0,0,0,0,0,0,0,0,0,0,0,0,0,0,0,0
0,0,0,0,0,0,0,0,0,0,0,0,0,0,0,0,0,0,0,0,0,0,0,0,0,0,0,0,0,0,0,0,0,0,0,0,0,0,0,0,0
0,0,0,0,0,0,0,0,0,0,0,0,0,0,0,0,0,0,0,0,0,0,0,0,0,0,0,0,0,0,0,0,0,0,0,0,0,0,0,0,0
:endlayer
layer: 22
0,0,0,0,0,0,0,0,0,0,0,0,0,0,0,0,0,0,0,0,0,0,0,0,0,0,0,0,0,0,0,0,0,0,0,0,0,0,0,0,0
0,0,0,0,0,0,0,0,0,0,0,0,0,0,0,0,0,0,0,0,0,0,0,0,0,0,0,0,0,0,0,0,0,0,0,0,0,0,0,0,0
0,0,0,0,0,0,0,0,0,0,0,0,0,0,0,0,0,0,0,0,0,0,0,0,0,0,0,0,0,0,0,0,0,0,0,0,0,0,0,0,0
0,0,0,0,0,0,0,0,0,0,0,0,0,0,0,0,0,0,0,0,0,0,0,0,0,0,0,0,0,0,0,0,0,0,0,0,0,0,0,0,0
0,0,0,0,0,0,0,0,0,0,0,0,0,0,0,0,0,0,0,0,0,0,0,0,0,0,0,0,0,0,0,0,0,0,0,0,0,0,0,0,0
0,0,0,0,0,0,0,0,0,0,0,0,0,0,0,0,0,0,0,0,0,0,0,0,0,0,0,0,0,0,0,0,0,0,0,0,0,0,0,0,0
0,0,0,0,0,0,0,0,0,0,0,0,0,0,0,0,0,0,0,0,0,0,0,0,0,0,0,0,0,0,0,0,0,0,0,0,0,0,0,0,0
0,0,0,0,0,0,0,0,0,0,0,0,0,0,0,0,0,0,0,0,0,0,0,0,0,0,0,0,0,0,0,0,0,0,0,0,0,0,0,0,0
0,0,0,0,0,0,0,0,0,0,0,0,0,0,0,0,0,0,0,0,0,0,0,0,0,0,0,0,0,0,0,0,0,0,0,0,0,0,0,0,0
0,0,0,0,0,0,0,0,0,0,0,0,0,0,0,0,0,0,0,0,0,0,0,0,0,0,0,0,0,0,0,0,0,0,0,0,0,0,0,0,0
0,0,0,0,0,0,0,0,0,0,0,0,0,0,0,0,0,0,0,0,0,0,0,0,0,0,0,0,0,0,0,0,0,0,0,0,0,0,0,0,0
0,0,0,0,0,0,0,0,0,0,0,0,0,0,0,0,0,0,0,0,0,0,0,0,0,0,0,0,0,0,0,0,0,0,0,0,0,0,0,0,0
0,0,0,0,0,0,0,0,0,0,0,0,0,0,0,0,0,0,0,0,0,0,0,0,0,0,0,0,0,0,0,0,0,0,0,0,0,0,0,0,0
0,0,0,0,0,0,0,0,0,0,0,176,0,8,147,8,0,176,0,0,0,0,0,176,0,8,147,8,0,176,0,0,0,0,0,0,0,0,0,0,0
0,0,0,0,0,0,0,0,0,0,0,0,163,258,258,258,163,0,0,0,0,0,0,0,163,258,258,258,163,0,0,0,0,0,0,0,0,0,0,0,0
0,0,0,0,0,0,0,0,0,0,0,8,258,0,259,0,258,8,0,0,0,0,0,8,258,0,0,0,258,8,0,0,0,0,0,0,0,0,0,0,0
0,0,0,0,0,0,0,0,0,0,0,141,258,0,0,0,258,140,0,0,0,0,0,141,258,0,0,0,258,140,0,0,0,0,0,0,0,0,0,0,0
0,0,0,0,0,0,0,0,0,0,0,8,258,0,0,0,258,8,0,0,0,0,0,8,258,0,0,0,258,8,0,0,0,0,0,0,0,0,0,0,0
0,0,0,0,0,0,0,0,0,0,0,0,163,258,208,258,163,0,0,0,0,0,0,0,163,258,208,258,163,0,0,0,0,0,0,0,0,0,0,0,0
0,0,0,0,0,0,0,0,0,0,0,176,0,8,139,8,0,176,0,0,0,0,0,176,0,8,139,8,0,176,0,0,0,0,0,0,0,0,0,0,0
0,0,0,0,0,0,0,0,0,0,0,0,0,0,0,0,0,0,0,0,0,0,0,0,0,0,0,0,0,0,0,0,0,0,0,0,0,0,0,0,0
0,0,0,0,0,0,0,0,0,0,0,0,0,0,0,0,0,0,0,0,0,0,0,0,0,0,0,0,0,0,0,0,0,0,0,0,0,0,0,0,0
0,0,0,0,0,0,0,0,0,0,0,0,0,0,0,0,0,0,0,0,0,0,0,0,0,0,0,0,0,0,0,0,0,0,0,0,0,0,0,0,0
0,0,0,0,0,0,0,0,0,0,0,0,0,0,0,0,0,0,0,0,0,0,0,0,0,0,0,0,0,0,0,0,0,0,0,0,0,0,0,0,0
0,0,0,0,0,0,0,0,0,0,0,0,0,0,0,0,0,0,0,0,0,0,0,0,0,0,0,0,0,0,0,0,0,0,0,0,0,0,0,0,0
0,0,0,0,0,0,0,0,0,0,0,0,0,0,0,0,0,0,0,0,0,0,0,0,0,0,0,0,0,0,0,0,0,0,0,0,0,0,0,0,0
0,0,0,0,0,0,0,0,0,0,0,0,0,0,0,0,0,0,0,0,0,0,0,0,0,0,0,0,0,0,0,0,0,0,0,0,0,0,0,0,0
0,0,0,0,0,0,0,0,0,0,0,0,0,0,0,0,0,0,0,0,0,0,0,0,0,0,0,0,0,0,0,0,0,0,0,0,0,0,0,0,0
0,0,0,0,0,0,0,0,0,0,0,0,0,0,0,0,0,0,0,0,0,0,0,0,0,0,0,0,0,0,0,0,0,0,0,0,0,0,0,0,0
0,0,0,0,0,0,0,0,0,0,0,0,0,0,0,0,0,0,0,0,0,0,0,0,0,0,0,0,0,0,0,0,0,0,0,0,0,0,0,0,0
0,0,0,0,0,0,0,0,0,0,0,0,0,0,0,0,0,0,0,0,0,0,0,0,0,0,0,0,0,0,0,0,0,0,0,0,0,0,0,0,0
:endlayer
layer: 23
0,0,0,0,0,0,0,0,0,0,0,0,0,0,0,0,0,0,0,0,0,0,0,0,0,0,0,0,0,0,0,0,0,0,0,0,0,0,0,0,0
0,0,0,0,0,0,0,0,0,0,0,0,0,0,0,0,0,0,0,0,0,0,0,0,0,0,0,0,0,0,0,0,0,0,0,0,0,0,0,0,0
0,0,0,0,0,0,0,0,0,0,0,0,0,0,0,0,0,0,0,0,0,0,0,0,0,0,0,0,0,0,0,0,0,0,0,0,0,0,0,0,0
0,0,0,0,0,0,0,0,0,0,0,0,0,0,0,0,0,0,0,0,0,0,0,0,0,0,0,0,0,0,0,0,0,0,0,0,0,0,0,0,0
0,0,0,0,0,0,0,0,0,0,0,0,0,0,0,0,0,0,0,0,0,0,0,0,0,0,0,0,0,0,0,0,0,0,0,0,0,0,0,0,0
0,0,0,0,0,0,0,0,0,0,0,0,0,0,0,0,0,0,0,0,0,0,0,0,0,0,0,0,0,0,0,0,0,0,0,0,0,0,0,0,0
0,0,0,0,0,0,0,0,0,0,0,0,0,0,0,0,0,0,0,0,0,0,0,0,0,0,0,0,0,0,0,0,0,0,0,0,0,0,0,0,0
0,0,0,0,0,0,0,0,0,0,0,0,0,0,0,0,0,0,0,0,0,0,0,0,0,0,0,0,0,0,0,0,0,0,0,0,0,0,0,0,0
0,0,0,0,0,0,0,0,0,0,0,0,0,0,0,0,0,0,0,0,0,0,0,0,0,0,0,0,0,0,0,0,0,0,0,0,0,0,0,0,0
0,0,0,0,0,0,0,0,0,0,0,0,0,0,0,0,0,0,0,0,0,0,0,0,0,0,0,0,0,0,0,0,0,0,0,0,0,0,0,0,0
0,0,0,0,0,0,0,0,0,0,0,0,0,0,0,0,0,0,0,0,0,0,0,0,0,0,0,0,0,0,0,0,0,0,0,0,0,0,0,0,0
0,0,0,0,0,0,0,0,0,0,0,0,0,0,0,0,0,0,0,0,0,0,0,0,0,0,0,0,0,0,0,0,0,0,0,0,0,0,0,0,0
0,0,0,0,0,0,0,0,0,0,0,0,0,0,0,0,0,0,0,0,0,0,0,0,0,0,0,0,0,0,0,0,0,0,0,0,0,0,0,0,0
0,0,0,0,0,0,0,0,0,0,0,0,258,258,258,258,258,0,0,0,0,0,0,0,258,258,258,258,258,0,0,0,0,0,0,0,0,0,0,0,0
0,0,0,0,0,0,0,0,0,0,0,258,258,185,0,185,258,258,0,0,0,0,0,258,258,185,0,185,258,258,0,0,0,0,0,0,0,0,0,0,0
0,0,0,0,0,0,0,0,0,0,0,258,185,0,260,0,185,258,0,0,0,0,0,258,185,0,0,0,185,258,0,0,0,0,0,0,0,0,0,0,0
0,0,0,0,0,0,0,0,0,0,0,258,0,0,0,0,0,258,0,0,0,0,0,258,0,0,0,0,0,258,0,0,0,0,0,0,0,0,0,0,0
0,0,0,0,0,0,0,0,0,0,0,258,185,0,0,0,185,258,0,0,0,0,0,258,185,0,0,0,185,258,0,0,0,0,0,0,0,0,0,0,0
0,0,0,0,0,0,0,0,0,0,0,258,258,185,208,185,258,258,0,0,0,0,0,258,258,185,208,185,258,258,0,0,0,0,0,0,0,0,0,0,0
0,0,0,0,0,0,0,0,0,0,0,0,258,258,258,258,258,0,0,0,0,0,0,0,258,258,258,258,258,0,0,0,0,0,0,0,0,0,0,0,0
0,0,0,0,0,0,0,0,0,0,0,0,0,0,0,0,0,0,0,0,0,0,0,0,0,0,0,0,0,0,0,0,0,0,0,0,0,0,0,0,0
0,0,0,0,0,0,0,0,0,0,0,0,0,0,0,0,0,0,0,0,0,0,0,0,0,0,0,0,0,0,0,0,0,0,0,0,0,0,0,0,0
0,0,0,0,0,0,0,0,0,0,0,0,0,0,0,0,0,0,0,0,0,0,0,0,0,0,0,0,0,0,0,0,0,0,0,0,0,0,0,0,0
0,0,0,0,0,0,0,0,0,0,0,0,0,0,0,0,0,0,0,0,0,0,0,0,0,0,0,0,0,0,0,0,0,0,0,0,0,0,0,0,0
0,0,0,0,0,0,0,0,0,0,0,0,0,0,0,0,0,0,0,0,0,0,0,0,0,0,0,0,0,0,0,0,0,0,0,0,0,0,0,0,0
0,0,0,0,0,0,0,0,0,0,0,0,0,0,0,0,0,0,0,0,0,0,0,0,0,0,0,0,0,0,0,0,0,0,0,0,0,0,0,0,0
0,0,0,0,0,0,0,0,0,0,0,0,0,0,0,0,0,0,0,0,0,0,0,0,0,0,0,0,0,0,0,0,0,0,0,0,0,0,0,0,0
0,0,0,0,0,0,0,0,0,0,0,0,0,0,0,0,0,0,0,0,0,0,0,0,0,0,0,0,0,0,0,0,0,0,0,0,0,0,0,0,0
0,0,0,0,0,0,0,0,0,0,0,0,0,0,0,0,0,0,0,0,0,0,0,0,0,0,0,0,0,0,0,0,0,0,0,0,0,0,0,0,0
0,0,0,0,0,0,0,0,0,0,0,0,0,0,0,0,0,0,0,0,0,0,0,0,0,0,0,0,0,0,0,0,0,0,0,0,0,0,0,0,0
0,0,0,0,0,0,0,0,0,0,0,0,0,0,0,0,0,0,0,0,0,0,0,0,0,0,0,0,0,0,0,0,0,0,0,0,0,0,0,0,0
:endlayer
layer: 24
0,0,0,0,0,0,0,0,0,0,0,0,0,0,0,0,0,0,0,0,0,0,0,0,0,0,0,0,0,0,0,0,0,0,0,0,0,0,0,0,0
0,0,0,0,0,0,0,0,0,0,0,0,0,0,0,0,0,0,0,0,0,0,0,0,0,0,0,0,0,0,0,0,0,0,0,0,0,0,0,0,0
0,0,0,0,0,0,0,0,0,0,0,0,0,0,0,0,0,0,0,0,0,0,0,0,0,0,0,0,0,0,0,0,0,0,0,0,0,0,0,0,0
0,0,0,0,0,0,0,0,0,0,0,0,0,0,0,0,0,0,0,0,0,0,0,0,0,0,0,0,0,0,0,0,0,0,0,0,0,0,0,0,0
0,0,0,0,0,0,0,0,0,0,0,0,0,0,0,0,0,0,0,0,0,0,0,0,0,0,0,0,0,0,0,0,0,0,0,0,0,0,0,0,0
0,0,0,0,0,0,0,0,0,0,0,0,0,0,0,0,0,0,0,0,0,0,0,0,0,0,0,0,0,0,0,0,0,0,0,0,0,0,0,0,0
0,0,0,0,0,0,0,0,0,0,0,0,0,0,0,0,0,0,0,0,0,0,0,0,0,0,0,0,0,0,0,0,0,0,0,0,0,0,0,0,0
0,0,0,0,0,0,0,0,0,0,0,0,0,0,0,0,0,0,0,0,0,0,0,0,0,0,0,0,0,0,0,0,0,0,0,0,0,0,0,0,0
0,0,0,0,0,0,0,0,0,0,0,0,0,0,0,0,0,0,0,0,0,0,0,0,0,0,0,0,0,0,0,0,0,0,0,0,0,0,0,0,0
0,0,0,0,0,0,0,0,0,0,0,0,0,0,0,0,0,0,0,0,0,0,0,0,0,0,0,0,0,0,0,0,0,0,0,0,0,0,0,0,0
0,0,0,0,0,0,0,0,0,0,0,0,0,0,0,0,0,0,0,0,0,0,0,0,0,0,0,0,0,0,0,0,0,0,0,0,0,0,0,0,0
0,0,0,0,0,0,0,0,0,0,0,0,0,0,0,0,0,0,0,0,0,0,0,0,0,0,0,0,0,0,0,0,0,0,0,0,0,0,0,0,0
0,0,0,0,0,0,0,0,0,0,0,0,0,0,0,0,0,0,0,0,0,0,0,0,0,0,0,0,0,0,0,0,0,0,0,0,0,0,0,0,0
0,0,0,0,0,0,0,0,0,0,0,0,258,258,258,258,258,0,0,0,0,0,0,0,258,258,258,258,258,0,0,0,0,0,0,0,0,0,0,0,0
0,0,0,0,0,0,0,0,0,0,0,258,258,185,139,185,258,258,0,0,0,0,0,258,258,185,139,185,258,258,0,0,0,0,0,0,0,0,0,0,0
0,0,0,0,0,0,0,0,0,0,0,258,185,0,0,0,185,258,0,0,0,0,0,258,185,0,0,0,185,258,0,0,0,0,0,0,0,0,0,0,0
0,0,0,0,0,0,0,0,0,0,0,258,140,0,0,0,141,258,0,0,0,0,0,258,140,0,0,0,141,258,0,0,0,0,0,0,0,0,0,0,0
0,0,0,0,0,0,0,0,0,0,0,258,185,0,0,0,185,258,0,0,0,0,0,258,185,0,0,0,185,258,0,0,0,0,0,0,0,0,0,0,0
0,0,0,0,0,0,0,0,0,0,0,258,258,185,147,185,258,258,0,0,0,0,0,258,258,185,147,185,258,258,0,0,0,0,0,0,0,0,0,0,0
0,0,0,0,0,0,0,0,0,0,0,0,258,258,258,258,258,0,0,0,0,0,0,0,258,258,258,258,258,0,0,0,0,0,0,0,0,0,0,0,0
0,0,0,0,0,0,0,0,0,0,0,0,0,0,0,0,0,0,0,0,0,0,0,0,0,0,0,0,0,0,0,0,0,0,0,0,0,0,0,0,0
0,0,0,0,0,0,0,0,0,0,0,0,0,0,0,0,0,0,0,0,0,0,0,0,0,0,0,0,0,0,0,0,0,0,0,0,0,0,0,0,0
0,0,0,0,0,0,0,0,0,0,0,0,0,0,0,0,0,0,0,0,0,0,0,0,0,0,0,0,0,0,0,0,0,0,0,0,0,0,0,0,0
0,0,0,0,0,0,0,0,0,0,0,0,0,0,0,0,0,0,0,0,0,0,0,0,0,0,0,0,0,0,0,0,0,0,0,0,0,0,0,0,0
0,0,0,0,0,0,0,0,0,0,0,0,0,0,0,0,0,0,0,0,0,0,0,0,0,0,0,0,0,0,0,0,0,0,0,0,0,0,0,0,0
0,0,0,0,0,0,0,0,0,0,0,0,0,0,0,0,0,0,0,0,0,0,0,0,0,0,0,0,0,0,0,0,0,0,0,0,0,0,0,0,0
0,0,0,0,0,0,0,0,0,0,0,0,0,0,0,0,0,0,0,0,0,0,0,0,0,0,0,0,0,0,0,0,0,0,0,0,0,0,0,0,0
0,0,0,0,0,0,0,0,0,0,0,0,0,0,0,0,0,0,0,0,0,0,0,0,0,0,0,0,0,0,0,0,0,0,0,0,0,0,0,0,0
0,0,0,0,0,0,0,0,0,0,0,0,0,0,0,0,0,0,0,0,0,0,0,0,0,0,0,0,0,0,0,0,0,0,0,0,0,0,0,0,0
0,0,0,0,0,0,0,0,0,0,0,0,0,0,0,0,0,0,0,0,0,0,0,0,0,0,0,0,0,0,0,0,0,0,0,0,0,0,0,0,0
0,0,0,0,0,0,0,0,0,0,0,0,0,0,0,0,0,0,0,0,0,0,0,0,0,0,0,0,0,0,0,0,0,0,0,0,0,0,0,0,0
:endlayer
layer: 25
0,0,0,0,0,0,0,0,0,0,0,0,0,0,0,0,0,0,0,0,0,0,0,0,0,0,0,0,0,0,0,0,0,0,0,0,0,0,0,0,0
0,0,0,0,0,0,0,0,0,0,0,0,0,0,0,0,0,0,0,0,0,0,0,0,0,0,0,0,0,0,0,0,0,0,0,0,0,0,0,0,0
0,0,0,0,0,0,0,0,0,0,0,0,0,0,0,0,0,0,0,0,0,0,0,0,0,0,0,0,0,0,0,0,0,0,0,0,0,0,0,0,0
0,0,0,0,0,0,0,0,0,0,0,0,0,0,0,0,0,0,0,0,0,0,0,0,0,0,0,0,0,0,0,0,0,0,0,0,0,0,0,0,0
0,0,0,0,0,0,0,0,0,0,0,0,0,0,0,0,0,0,0,0,0,0,0,0,0,0,0,0,0,0,0,0,0,0,0,0,0,0,0,0,0
0,0,0,0,0,0,0,0,0,0,0,0,0,0,0,0,0,0,0,0,0,0,0,0,0,0,0,0,0,0,0,0,0,0,0,0,0,0,0,0,0
0,0,0,0,0,0,0,0,0,0,0,0,0,0,0,0,0,0,0,0,0,0,0,0,0,0,0,0,0,0,0,0,0,0,0,0,0,0,0,0,0
0,0,0,0,0,0,0,0,0,0,0,0,0,0,0,0,0,0,0,0,0,0,0,0,0,0,0,0,0,0,0,0,0,0,0,0,0,0,0,0,0
0,0,0,0,0,0,0,0,0,0,0,0,0,0,0,0,0,0,0,0,0,0,0,0,0,0,0,0,0,0,0,0,0,0,0,0,0,0,0,0,0
0,0,0,0,0,0,0,0,0,0,0,0,0,0,0,0,0,0,0,0,0,0,0,0,0,0,0,0,0,0,0,0,0,0,0,0,0,0,0,0,0
0,0,0,0,0,0,0,0,0,0,0,0,0,0,0,0,0,0,0,0,0,0,0,0,0,0,0,0,0,0,0,0,0,0,0,0,0,0,0,0,0
0,0,0,0,0,0,0,0,0,0,0,0,0,0,0,0,0,0,0,0,0,0,0,0,0,0,0,0,0,0,0,0,0,0,0,0,0,0,0,0,0
0,0,0,0,0,0,0,0,0,0,0,0,0,0,0,0,0,0,0,0,0,0,0,0,0,0,0,0,0,0,0,0,0,0,0,0,0,0,0,0,0
0,0,0,0,0,0,0,0,0,0,0,0,27,258,258,258,29,0,0,0,0,0,0,0,27,258,258,258,29,0,0,0,0,0,0,0,0,0,0,0,0
0,0,0,0,0,0,0,0,0,0,0,78,258,139,175,139,258,78,0,0,0,0,0,78,258,139,175,139,258,78,0,0,0,0,0,0,0,0,0,0,0
0,0,0,0,0,0,0,0,0,0,0,258,140,163,0,163,141,258,0,0,0,0,0,258,140,163,0,163,141,258,0,0,0,0,0,0,0,0,0,0,0
0,0,0,0,0,0,0,0,0,0,0,258,175,0,0,0,175,258,0,0,0,0,0,258,175,0,0,0,175,258,0,0,0,0,0,0,0,0,0,0,0
0,0,0,0,0,0,0,0,0,0,0,258,140,163,0,163,141,258,0,0,0,0,0,258,140,163,0,163,141,258,0,0,0,0,0,0,0,0,0,0,0
0,0,0,0,0,0,0,0,0,0,0,14,258,147,175,147,258,14,0,0,0,0,0,14,258,147,175,147,258,14,0,0,0,0,0,0,0,0,0,0,0
0,0,0,0,0,0,0,0,0,0,0,0,27,258,258,258,29,0,0,0,0,0,0,0,27,258,258,258,29,0,0,0,0,0,0,0,0,0,0,0,0
0,0,0,0,0,0,0,0,0,0,0,0,0,0,0,0,0,0,0,0,0,0,0,0,0,0,0,0,0,0,0,0,0,0,0,0,0,0,0,0,0
0,0,0,0,0,0,0,0,0,0,0,0,0,0,0,0,0,0,0,0,0,0,0,0,0,0,0,0,0,0,0,0,0,0,0,0,0,0,0,0,0
0,0,0,0,0,0,0,0,0,0,0,0,0,0,0,0,0,0,0,0,0,0,0,0,0,0,0,0,0,0,0,0,0,0,0,0,0,0,0,0,0
0,0,0,0,0,0,0,0,0,0,0,0,0,0,0,0,0,0,0,0,0,0,0,0,0,0,0,0,0,0,0,0,0,0,0,0,0,0,0,0,0
0,0,0,0,0,0,0,0,0,0,0,0,0,0,0,0,0,0,0,0,0,0,0,0,0,0,0,0,0,0,0,0,0,0,0,0,0,0,0,0,0
0,0,0,0,0,0,0,0,0,0,0,0,0,0,0,0,0,0,0,0,0,0,0,0,0,0,0,0,0,0,0,0,0,0,0,0,0,0,0,0,0
0,0,0,0,0,0,0,0,0,0,0,0,0,0,0,0,0,0,0,0,0,0,0,0,0,0,0,0,0,0,0,0,0,0,0,0,0,0,0,0,0
0,0,0,0,0,0,0,0,0,0,0,0,0,0,0,0,0,0,0,0,0,0,0,0,0,0,0,0,0,0,0,0,0,0,0,0,0,0,0,0,0
0,0,0,0,0,0,0,0,0,0,0,0,0,0,0,0,0,0,0,0,0,0,0,0,0,0,0,0,0,0,0,0,0,0,0,0,0,0,0,0,0
0,0,0,0,0,0,0,0,0,0,0,0,0,0,0,0,0,0,0,0,0,0,0,0,0,0,0,0,0,0,0,0,0,0,0,0,0,0,0,0,0
0,0,0,0,0,0,0,0,0,0,0,0,0,0,0,0,0,0,0,0,0,0,0,0,0,0,0,0,0,0,0,0,0,0,0,0,0,0,0,0,0
:endlayer
layer: 26
0,0,0,0,0,0,0,0,0,0,0,0,0,0,0,0,0,0,0,0,0,0,0,0,0,0,0,0,0,0,0,0,0,0,0,0,0,0,0,0,0
0,0,0,0,0,0,0,0,0,0,0,0,0,0,0,0,0,0,0,0,0,0,0,0,0,0,0,0,0,0,0,0,0,0,0,0,0,0,0,0,0
0,0,0,0,0,0,0,0,0,0,0,0,0,0,0,0,0,0,0,0,0,0,0,0,0,0,0,0,0,0,0,0,0,0,0,0,0,0,0,0,0
0,0,0,0,0,0,0,0,0,0,0,0,0,0,0,0,0,0,0,0,0,0,0,0,0,0,0,0,0,0,0,0,0,0,0,0,0,0,0,0,0
0,0,0,0,0,0,0,0,0,0,0,0,0,0,0,0,0,0,0,0,0,0,0,0,0,0,0,0,0,0,0,0,0,0,0,0,0,0,0,0,0
0,0,0,0,0,0,0,0,0,0,0,0,0,0,0,0,0,0,0,0,0,0,0,0,0,0,0,0,0,0,0,0,0,0,0,0,0,0,0,0,0
0,0,0,0,0,0,0,0,0,0,0,0,0,0,0,0,0,0,0,0,0,0,0,0,0,0,0,0,0,0,0,0,0,0,0,0,0,0,0,0,0
0,0,0,0,0,0,0,0,0,0,0,0,0,0,0,0,0,0,0,0,0,0,0,0,0,0,0,0,0,0,0,0,0,0,0,0,0,0,0,0,0
0,0,0,0,0,0,0,0,0,0,0,0,0,0,0,0,0,0,0,0,0,0,0,0,0,0,0,0,0,0,0,0,0,0,0,0,0,0,0,0,0
0,0,0,0,0,0,0,0,0,0,0,0,0,0,0,0,0,0,0,0,0,0,0,0,0,0,0,0,0,0,0,0,0,0,0,0,0,0,0,0,0
0,0,0,0,0,0,0,0,0,0,0,0,0,0,0,0,0,0,0,0,0,0,0,0,0,0,0,0,0,0,0,0,0,0,0,0,0,0,0,0,0
0,0,0,0,0,0,0,0,0,0,0,0,0,0,0,0,0,0,0,0,0,0,0,0,0,0,0,0,0,0,0,0,0,0,0,0,0,0,0,0,0
0,0,0,0,0,0,0,0,0,0,0,0,0,0,0,0,0,0,0,0,0,0,0,0,0,0,0,0,0,0,0,0,0,0,0,0,0,0,0,0,0
0,0,0,0,0,0,0,0,0,0,0,0,0,0,176,0,0,0,0,0,0,0,0,0,0,0,176,0,0,0,0,0,0,0,0,0,0,0,0,0,0
0,0,0,0,0,0,0,0,0,0,0,0,176,258,258,258,176,0,0,0,0,0,0,0,176,258,258,258,176,0,0,0,0,0,0,0,0,0,0,0,0
0,0,0,0,0,0,0,0,0,0,0,0,258,1,185,1,258,0,0,0,0,0,0,0,258,1,185,1,258,0,0,0,0,0,0,0,0,0,0,0,0
0,0,0,0,0,0,0,0,0,0,0,176,258,185,0,185,258,176,0,0,0,0,0,176,258,185,0,185,258,176,0,0,0,0,0,0,0,0,0,0,0
0,0,0,0,0,0,0,0,0,0,0,0,258,1,185,1,258,0,0,0,0,0,0,0,258,1,185,1,258,0,0,0,0,0,0,0,0,0,0,0,0
0,0,0,0,0,0,0,0,0,0,0,0,176,258,258,258,176,0,0,0,0,0,0,0,176,258,258,258,176,0,0,0,0,0,0,0,0,0,0,0,0
0,0,0,0,0,0,0,0,0,0,0,0,0,0,176,0,0,0,0,0,0,0,0,0,0,0,176,0,0,0,0,0,0,0,0,0,0,0,0,0,0
0,0,0,0,0,0,0,0,0,0,0,0,0,0,0,0,0,0,0,0,0,0,0,0,0,0,0,0,0,0,0,0,0,0,0,0,0,0,0,0,0
0,0,0,0,0,0,0,0,0,0,0,0,0,0,0,0,0,0,0,0,0,0,0,0,0,0,0,0,0,0,0,0,0,0,0,0,0,0,0,0,0
0,0,0,0,0,0,0,0,0,0,0,0,0,0,0,0,0,0,0,0,0,0,0,0,0,0,0,0,0,0,0,0,0,0,0,0,0,0,0,0,0
0,0,0,0,0,0,0,0,0,0,0,0,0,0,0,0,0,0,0,0,0,0,0,0,0,0,0,0,0,0,0,0,0,0,0,0,0,0,0,0,0
0,0,0,0,0,0,0,0,0,0,0,0,0,0,0,0,0,0,0,0,0,0,0,0,0,0,0,0,0,0,0,0,0,0,0,0,0,0,0,0,0
0,0,0,0,0,0,0,0,0,0,0,0,0,0,0,0,0,0,0,0,0,0,0,0,0,0,0,0,0,0,0,0,0,0,0,0,0,0,0,0,0
0,0,0,0,0,0,0,0,0,0,0,0,0,0,0,0,0,0,0,0,0,0,0,0,0,0,0,0,0,0,0,0,0,0,0,0,0,0,0,0,0
0,0,0,0,0,0,0,0,0,0,0,0,0,0,0,0,0,0,0,0,0,0,0,0,0,0,0,0,0,0,0,0,0,0,0,0,0,0,0,0,0
0,0,0,0,0,0,0,0,0,0,0,0,0,0,0,0,0,0,0,0,0,0,0,0,0,0,0,0,0,0,0,0,0,0,0,0,0,0,0,0,0
0,0,0,0,0,0,0,0,0,0,0,0,0,0,0,0,0,0,0,0,0,0,0,0,0,0,0,0,0,0,0,0,0,0,0,0,0,0,0,0,0
0,0,0,0,0,0,0,0,0,0,0,0,0,0,0,0,0,0,0,0,0,0,0,0,0,0,0,0,0,0,0,0,0,0,0,0,0,0,0,0,0
:endlayer
layer: 27
0,0,0,0,0,0,0,0,0,0,0,0,0,0,0,0,0,0,0,0,0,0,0,0,0,0,0,0,0,0,0,0,0,0,0,0,0,0,0,0,0
0,0,0,0,0,0,0,0,0,0,0,0,0,0,0,0,0,0,0,0,0,0,0,0,0,0,0,0,0,0,0,0,0,0,0,0,0,0,0,0,0
0,0,0,0,0,0,0,0,0,0,0,0,0,0,0,0,0,0,0,0,0,0,0,0,0,0,0,0,0,0,0,0,0,0,0,0,0,0,0,0,0
0,0,0,0,0,0,0,0,0,0,0,0,0,0,0,0,0,0,0,0,0,0,0,0,0,0,0,0,0,0,0,0,0,0,0,0,0,0,0,0,0
0,0,0,0,0,0,0,0,0,0,0,0,0,0,0,0,0,0,0,0,0,0,0,0,0,0,0,0,0,0,0,0,0,0,0,0,0,0,0,0,0
0,0,0,0,0,0,0,0,0,0,0,0,0,0,0,0,0,0,0,0,0,0,0,0,0,0,0,0,0,0,0,0,0,0,0,0,0,0,0,0,0
0,0,0,0,0,0,0,0,0,0,0,0,0,0,0,0,0,0,0,0,0,0,0,0,0,0,0,0,0,0,0,0,0,0,0,0,0,0,0,0,0
0,0,0,0,0,0,0,0,0,0,0,0,0,0,0,0,0,0,0,0,0,0,0,0,0,0,0,0,0,0,0,0,0,0,0,0,0,0,0,0,0
0,0,0,0,0,0,0,0,0,0,0,0,0,0,0,0,0,0,0,0,0,0,0,0,0,0,0,0,0,0,0,0,0,0,0,0,0,0,0,0,0
0,0,0,0,0,0,0,0,0,0,0,0,0,0,0,0,0,0,0,0,0,0,0,0,0,0,0,0,0,0,0,0,0,0,0,0,0,0,0,0,0
0,0,0,0,0,0,0,0,0,0,0,0,0,0,0,0,0,0,0,0,0,0,0,0,0,0,0,0,0,0,0,0,0,0,0,0,0,0,0,0,0
0,0,0,0,0,0,0,0,0,0,0,0,0,0,0,0,0,0,0,0,0,0,0,0,0,0,0,0,0,0,0,0,0,0,0,0,0,0,0,0,0
0,0,0,0,0,0,0,0,0,0,0,0,0,0,0,0,0,0,0,0,0,0,0,0,0,0,0,0,0,0,0,0,0,0,0,0,0,0,0,0,0
0,0,0,0,0,0,0,0,0,0,0,0,0,0,0,0,0,0,0,0,0,0,0,0,0,0,0,0,0,0,0,0,0,0,0,0,0,0,0,0,0
0,0,0,0,0,0,0,0,0,0,0,0,0,185,176,185,0,0,0,0,0,0,0,0,0,185,176,185,0,0,0,0,0,0,0,0,0,0,0,0,0
0,0,0,0,0,0,0,0,0,0,0,0,185,1,0,1,185,0,0,0,0,0,0,0,185,1,0,1,185,0,0,0,0,0,0,0,0,0,0,0,0
0,0,0,0,0,0,0,0,0,0,0,0,176,0,0,0,176,0,0,0,0,0,0,0,176,0,0,0,176,0,0,0,0,0,0,0,0,0,0,0,0
0,0,0,0,0,0,0,0,0,0,0,0,185,1,0,1,185,0,0,0,0,0,0,0,185,1,0,1,185,0,0,0,0,0,0,0,0,0,0,0,0
0,0,0,0,0,0,0,0,0,0,0,0,0,185,176,185,0,0,0,0,0,0,0,0,0,185,176,185,0,0,0,0,0,0,0,0,0,0,0,0,0
0,0,0,0,0,0,0,0,0,0,0,0,0,0,0,0,0,0,0,0,0,0,0,0,0,0,0,0,0,0,0,0,0,0,0,0,0,0,0,0,0
0,0,0,0,0,0,0,0,0,0,0,0,0,0,0,0,0,0,0,0,0,0,0,0,0,0,0,0,0,0,0,0,0,0,0,0,0,0,0,0,0
0,0,0,0,0,0,0,0,0,0,0,0,0,0,0,0,0,0,0,0,0,0,0,0,0,0,0,0,0,0,0,0,0,0,0,0,0,0,0,0,0
0,0,0,0,0,0,0,0,0,0,0,0,0,0,0,0,0,0,0,0,0,0,0,0,0,0,0,0,0,0,0,0,0,0,0,0,0,0,0,0,0
0,0,0,0,0,0,0,0,0,0,0,0,0,0,0,0,0,0,0,0,0,0,0,0,0,0,0,0,0,0,0,0,0,0,0,0,0,0,0,0,0
0,0,0,0,0,0,0,0,0,0,0,0,0,0,0,0,0,0,0,0,0,0,0,0,0,0,0,0,0,0,0,0,0,0,0,0,0,0,0,0,0
0,0,0,0,0,0,0,0,0,0,0,0,0,0,0,0,0,0,0,0,0,0,0,0,0,0,0,0,0,0,0,0,0,0,0,0,0,0,0,0,0
0,0,0,0,0,0,0,0,0,0,0,0,0,0,0,0,0,0,0,0,0,0,0,0,0,0,0,0,0,0,0,0,0,0,0,0,0,0,0,0,0
0,0,0,0,0,0,0,0,0,0,0,0,0,0,0,0,0,0,0,0,0,0,0,0,0,0,0,0,0,0,0,0,0,0,0,0,0,0,0,0,0
0,0,0,0,0,0,0,0,0,0,0,0,0,0,0,0,0,0,0,0,0,0,0,0,0,0,0,0,0,0,0,0,0,0,0,0,0,0,0,0,0
0,0,0,0,0,0,0,0,0,0,0,0,0,0,0,0,0,0,0,0,0,0,0,0,0,0,0,0,0,0,0,0,0,0,0,0,0,0,0,0,0
0,0,0,0,0,0,0,0,0,0,0,0,0,0,0,0,0,0,0,0,0,0,0,0,0,0,0,0,0,0,0,0,0,0,0,0,0,0,0,0,0
:endlayer
layer: 28
0,0,0,0,0,0,0,0,0,0,0,0,0,0,0,0,0,0,0,0,0,0,0,0,0,0,0,0,0,0,0,0,0,0,0,0,0,0,0,0,0
0,0,0,0,0,0,0,0,0,0,0,0,0,0,0,0,0,0,0,0,0,0,0,0,0,0,0,0,0,0,0,0,0,0,0,0,0,0,0,0,0
0,0,0,0,0,0,0,0,0,0,0,0,0,0,0,0,0,0,0,0,0,0,0,0,0,0,0,0,0,0,0,0,0,0,0,0,0,0,0,0,0
0,0,0,0,0,0,0,0,0,0,0,0,0,0,0,0,0,0,0,0,0,0,0,0,0,0,0,0,0,0,0,0,0,0,0,0,0,0,0,0,0
0,0,0,0,0,0,0,0,0,0,0,0,0,0,0,0,0,0,0,0,0,0,0,0,0,0,0,0,0,0,0,0,0,0,0,0,0,0,0,0,0
0,0,0,0,0,0,0,0,0,0,0,0,0,0,0,0,0,0,0,0,0,0,0,0,0,0,0,0,0,0,0,0,0,0,0,0,0,0,0,0,0
0,0,0,0,0,0,0,0,0,0,0,0,0,0,0,0,0,0,0,0,0,0,0,0,0,0,0,0,0,0,0,0,0,0,0,0,0,0,0,0,0
0,0,0,0,0,0,0,0,0,0,0,0,0,0,0,0,0,0,0,0,0,0,0,0,0,0,0,0,0,0,0,0,0,0,0,0,0,0,0,0,0
0,0,0,0,0,0,0,0,0,0,0,0,0,0,0,0,0,0,0,0,0,0,0,0,0,0,0,0,0,0,0,0,0,0,0,0,0,0,0,0,0
0,0,0,0,0,0,0,0,0,0,0,0,0,0,0,0,0,0,0,0,0,0,0,0,0,0,0,0,0,0,0,0,0,0,0,0,0,0,0,0,0
0,0,0,0,0,0,0,0,0,0,0,0,0,0,0,0,0,0,0,0,0,0,0,0,0,0,0,0,0,0,0,0,0,0,0,0,0,0,0,0,0
0,0,0,0,0,0,0,0,0,0,0,0,0,0,0,0,0,0,0,0,0,0,0,0,0,0,0,0,0,0,0,0,0,0,0,0,0,0,0,0,0
0,0,0,0,0,0,0,0,0,0,0,0,0,0,0,0,0,0,0,0,0,0,0,0,0,0,0,0,0,0,0,0,0,0,0,0,0,0,0,0,0
0,0,0,0,0,0,0,0,0,0,0,0,0,0,0,0,0,0,0,0,0,0,0,0,0,0,0,0,0,0,0,0,0,0,0,0,0,0,0,0,0
0,0,0,0,0,0,0,0,0,0,0,0,0,185,0,185,0,0,0,0,0,0,0,0,0,185,0,185,0,0,0,0,0,0,0,0,0,0,0,0,0
0,0,0,0,0,0,0,0,0,0,0,0,185,1,0,1,185,0,0,0,0,0,0,0,185,1,0,1,185,0,0,0,0,0,0,0,0,0,0,0,0
0,0,0,0,0,0,0,0,0,0,0,0,0,0,0,0,0,0,0,0,0,0,0,0,0,0,0,0,0,0,0,0,0,0,0,0,0,0,0,0,0
0,0,0,0,0,0,0,0,0,0,0,0,185,1,0,1,185,0,0,0,0,0,0,0,185,1,0,1,185,0,0,0,0,0,0,0,0,0,0,0,0
0,0,0,0,0,0,0,0,0,0,0,0,0,185,0,185,0,0,0,0,0,0,0,0,0,185,0,185,0,0,0,0,0,0,0,0,0,0,0,0,0
0,0,0,0,0,0,0,0,0,0,0,0,0,0,0,0,0,0,0,0,0,0,0,0,0,0,0,0,0,0,0,0,0,0,0,0,0,0,0,0,0
0,0,0,0,0,0,0,0,0,0,0,0,0,0,0,0,0,0,0,0,0,0,0,0,0,0,0,0,0,0,0,0,0,0,0,0,0,0,0,0,0
0,0,0,0,0,0,0,0,0,0,0,0,0,0,0,0,0,0,0,0,0,0,0,0,0,0,0,0,0,0,0,0,0,0,0,0,0,0,0,0,0
0,0,0,0,0,0,0,0,0,0,0,0,0,0,0,0,0,0,0,0,0,0,0,0,0,0,0,0,0,0,0,0,0,0,0,0,0,0,0,0,0
0,0,0,0,0,0,0,0,0,0,0,0,0,0,0,0,0,0,0,0,0,0,0,0,0,0,0,0,0,0,0,0,0,0,0,0,0,0,0,0,0
0,0,0,0,0,0,0,0,0,0,0,0,0,0,0,0,0,0,0,0,0,0,0,0,0,0,0,0,0,0,0,0,0,0,0,0,0,0,0,0,0
0,0,0,0,0,0,0,0,0,0,0,0,0,0,0,0,0,0,0,0,0,0,0,0,0,0,0,0,0,0,0,0,0,0,0,0,0,0,0,0,0
0,0,0,0,0,0,0,0,0,0,0,0,0,0,0,0,0,0,0,0,0,0,0,0,0,0,0,0,0,0,0,0,0,0,0,0,0,0,0,0,0
0,0,0,0,0,0,0,0,0,0,0,0,0,0,0,0,0,0,0,0,0,0,0,0,0,0,0,0,0,0,0,0,0,0,0,0,0,0,0,0,0
0,0,0,0,0,0,0,0,0,0,0,0,0,0,0,0,0,0,0,0,0,0,0,0,0,0,0,0,0,0,0,0,0,0,0,0,0,0,0,0,0
0,0,0,0,0,0,0,0,0,0,0,0,0,0,0,0,0,0,0,0,0,0,0,0,0,0,0,0,0,0,0,0,0,0,0,0,0,0,0,0,0
0,0,0,0,0,0,0,0,0,0,0,0,0,0,0,0,0,0,0,0,0,0,0,0,0,0,0,0,0,0,0,0,0,0,0,0,0,0,0,0,0
:endlayer
layer: 29
0,0,0,0,0,0,0,0,0,0,0,0,0,0,0,0,0,0,0,0,0,0,0,0,0,0,0,0,0,0,0,0,0,0,0,0,0,0,0,0,0
0,0,0,0,0,0,0,0,0,0,0,0,0,0,0,0,0,0,0,0,0,0,0,0,0,0,0,0,0,0,0,0,0,0,0,0,0,0,0,0,0
0,0,0,0,0,0,0,0,0,0,0,0,0,0,0,0,0,0,0,0,0,0,0,0,0,0,0,0,0,0,0,0,0,0,0,0,0,0,0,0,0
0,0,0,0,0,0,0,0,0,0,0,0,0,0,0,0,0,0,0,0,0,0,0,0,0,0,0,0,0,0,0,0,0,0,0,0,0,0,0,0,0
0,0,0,0,0,0,0,0,0,0,0,0,0,0,0,0,0,0,0,0,0,0,0,0,0,0,0,0,0,0,0,0,0,0,0,0,0,0,0,0,0
0,0,0,0,0,0,0,0,0,0,0,0,0,0,0,0,0,0,0,0,0,0,0,0,0,0,0,0,0,0,0,0,0,0,0,0,0,0,0,0,0
0,0,0,0,0,0,0,0,0,0,0,0,0,0,0,0,0,0,0,0,0,0,0,0,0,0,0,0,0,0,0,0,0,0,0,0,0,0,0,0,0
0,0,0,0,0,0,0,0,0,0,0,0,0,0,0,0,0,0,0,0,0,0,0,0,0,0,0,0,0,0,0,0,0,0,0,0,0,0,0,0,0
0,0,0,0,0,0,0,0,0,0,0,0,0,0,0,0,0,0,0,0,0,0,0,0,0,0,0,0,0,0,0,0,0,0,0,0,0,0,0,0,0
0,0,0,0,0,0,0,0,0,0,0,0,0,0,0,0,0,0,0,0,0,0,0,0,0,0,0,0,0,0,0,0,0,0,0,0,0,0,0,0,0
0,0,0,0,0,0,0,0,0,0,0,0,0,0,0,0,0,0,0,0,0,0,0,0,0,0,0,0,0,0,0,0,0,0,0,0,0,0,0,0,0
0,0,0,0,0,0,0,0,0,0,0,0,0,0,0,0,0,0,0,0,0,0,0,0,0,0,0,0,0,0,0,0,0,0,0,0,0,0,0,0,0
0,0,0,0,0,0,0,0,0,0,0,0,0,0,0,0,0,0,0,0,0,0,0,0,0,0,0,0,0,0,0,0,0,0,0,0,0,0,0,0,0
0,0,0,0,0,0,0,0,0,0,0,0,0,0,0,0,0,0,0,0,0,0,0,0,0,0,0,0,0,0,0,0,0,0,0,0,0,0,0,0,0
0,0,0,0,0,0,0,0,0,0,0,0,0,141,258,140,0,0,0,0,0,0,0,0,0,141,258,140,0,0,0,0,0,0,0,0,0,0,0,0,0
0,0,0,0,0,0,0,0,0,0,0,0,147,8,139,8,147,0,0,0,0,0,0,0,147,8,139,8,147,0,0,0,0,0,0,0,0,0,0,0,0
0,0,0,0,0,0,0,0,0,0,0,0,258,140,175,141,258,0,0,0,0,0,0,0,258,140,175,141,258,0,0,0,0,0,0,0,0,0,0,0,0
0,0,0,0,0,0,0,0,0,0,0,0,139,8,147,8,139,0,0,0,0,0,0,0,139,8,147,8,139,0,0,0,0,0,0,0,0,0,0,0,0
0,0,0,0,0,0,0,0,0,0,0,0,0,141,258,140,0,0,0,0,0,0,0,0,0,141,258,140,0,0,0,0,0,0,0,0,0,0,0,0,0
0,0,0,0,0,0,0,0,0,0,0,0,0,0,0,0,0,0,0,0,0,0,0,0,0,0,0,0,0,0,0,0,0,0,0,0,0,0,0,0,0
0,0,0,0,0,0,0,0,0,0,0,0,0,0,0,0,0,0,0,0,0,0,0,0,0,0,0,0,0,0,0,0,0,0,0,0,0,0,0,0,0
0,0,0,0,0,0,0,0,0,0,0,0,0,0,0,0,0,0,0,0,0,0,0,0,0,0,0,0,0,0,0,0,0,0,0,0,0,0,0,0,0
0,0,0,0,0,0,0,0,0,0,0,0,0,0,0,0,0,0,0,0,0,0,0,0,0,0,0,0,0,0,0,0,0,0,0,0,0,0,0,0,0
0,0,0,0,0,0,0,0,0,0,0,0,0,0,0,0,0,0,0,0,0,0,0,0,0,0,0,0,0,0,0,0,0,0,0,0,0,0,0,0,0
0,0,0,0,0,0,0,0,0,0,0,0,0,0,0,0,0,0,0,0,0,0,0,0,0,0,0,0,0,0,0,0,0,0,0,0,0,0,0,0,0
0,0,0,0,0,0,0,0,0,0,0,0,0,0,0,0,0,0,0,0,0,0,0,0,0,0,0,0,0,0,0,0,0,0,0,0,0,0,0,0,0
0,0,0,0,0,0,0,0,0,0,0,0,0,0,0,0,0,0,0,0,0,0,0,0,0,0,0,0,0,0,0,0,0,0,0,0,0,0,0,0,0
0,0,0,0,0,0,0,0,0,0,0,0,0,0,0,0,0,0,0,0,0,0,0,0,0,0,0,0,0,0,0,0,0,0,0,0,0,0,0,0,0
0,0,0,0,0,0,0,0,0,0,0,0,0,0,0,0,0,0,0,0,0,0,0,0,0,0,0,0,0,0,0,0,0,0,0,0,0,0,0,0,0
0,0,0,0,0,0,0,0,0,0,0,0,0,0,0,0,0,0,0,0,0,0,0,0,0,0,0,0,0,0,0,0,0,0,0,0,0,0,0,0,0
0,0,0,0,0,0,0,0,0,0,0,0,0,0,0,0,0,0,0,0,0,0,0,0,0,0,0,0,0,0,0,0,0,0,0,0,0,0,0,0,0
:endlayer
layer: 30
0,0,0,0,0,0,0,0,0,0,0,0,0,0,0,0,0,0,0,0,0,0,0,0,0,0,0,0,0,0,0,0,0,0,0,0,0,0,0,0,0
0,0,0,0,0,0,0,0,0,0,0,0,0,0,0,0,0,0,0,0,0,0,0,0,0,0,0,0,0,0,0,0,0,0,0,0,0,0,0,0,0
0,0,0,0,0,0,0,0,0,0,0,0,0,0,0,0,0,0,0,0,0,0,0,0,0,0,0,0,0,0,0,0,0,0,0,0,0,0,0,0,0
0,0,0,0,0,0,0,0,0,0,0,0,0,0,0,0,0,0,0,0,0,0,0,0,0,0,0,0,0,0,0,0,0,0,0,0,0,0,0,0,0
0,0,0,0,0,0,0,0,0,0,0,0,0,0,0,0,0,0,0,0,0,0,0,0,0,0,0,0,0,0,0,0,0,0,0,0,0,0,0,0,0
0,0,0,0,0,0,0,0,0,0,0,0,0,0,0,0,0,0,0,0,0,0,0,0,0,0,0,0,0,0,0,0,0,0,0,0,0,0,0,0,0
0,0,0,0,0,0,0,0,0,0,0,0,0,0,0,0,0,0,0,0,0,0,0,0,0,0,0,0,0,0,0,0,0,0,0,0,0,0,0,0,0
0,0,0,0,0,0,0,0,0,0,0,0,0,0,0,0,0,0,0,0,0,0,0,0,0,0,0,0,0,0,0,0,0,0,0,0,0,0,0,0,0
0,0,0,0,0,0,0,0,0,0,0,0,0,0,0,0,0,0,0,0,0,0,0,0,0,0,0,0,0,0,0,0,0,0,0,0,0,0,0,0,0
0,0,0,0,0,0,0,0,0,0,0,0,0,0,0,0,0,0,0,0,0,0,0,0,0,0,0,0,0,0,0,0,0,0,0,0,0,0,0,0,0
0,0,0,0,0,0,0,0,0,0,0,0,0,0,0,0,0,0,0,0,0,0,0,0,0,0,0,0,0,0,0,0,0,0,0,0,0,0,0,0,0
0,0,0,0,0,0,0,0,0,0,0,0,0,0,0,0,0,0,0,0,0,0,0,0,0,0,0,0,0,0,0,0,0,0,0,0,0,0,0,0,0
0,0,0,0,0,0,0,0,0,0,0,0,0,0,0,0,0,0,0,0,0,0,0,0,0,0,0,0,0,0,0,0,0,0,0,0,0,0,0,0,0
0,0,0,0,0,0,0,0,0,0,0,0,0,0,0,0,0,0,0,0,0,0,0,0,0,0,0,0,0,0,0,0,0,0,0,0,0,0,0,0,0
0,0,0,0,0,0,0,0,0,0,0,0,0,258,258,258,0,0,0,0,0,0,0,0,0,258,258,258,0,0,0,0,0,0,0,0,0,0,0,0,0
0,0,0,0,0,0,0,0,0,0,0,0,258,258,258,258,258,0,0,0,0,0,0,0,258,258,258,258,258,0,0,0,0,0,0,0,0,0,0,0,0
0,0,0,0,0,0,0,0,0,0,0,0,258,258,258,258,258,0,0,0,0,0,0,0,258,258,258,258,258,0,0,0,0,0,0,0,0,0,0,0,0
0,0,0,0,0,0,0,0,0,0,0,0,258,258,258,258,258,0,0,0,0,0,0,0,258,258,258,258,258,0,0,0,0,0,0,0,0,0,0,0,0
0,0,0,0,0,0,0,0,0,0,0,0,0,258,258,258,0,0,0,0,0,0,0,0,0,258,258,258,0,0,0,0,0,0,0,0,0,0,0,0,0
0,0,0,0,0,0,0,0,0,0,0,0,0,0,0,0,0,0,0,0,0,0,0,0,0,0,0,0,0,0,0,0,0,0,0,0,0,0,0,0,0
0,0,0,0,0,0,0,0,0,0,0,0,0,0,0,0,0,0,0,0,0,0,0,0,0,0,0,0,0,0,0,0,0,0,0,0,0,0,0,0,0
0,0,0,0,0,0,0,0,0,0,0,0,0,0,0,0,0,0,0,0,0,0,0,0,0,0,0,0,0,0,0,0,0,0,0,0,0,0,0,0,0
0,0,0,0,0,0,0,0,0,0,0,0,0,0,0,0,0,0,0,0,0,0,0,0,0,0,0,0,0,0,0,0,0,0,0,0,0,0,0,0,0
0,0,0,0,0,0,0,0,0,0,0,0,0,0,0,0,0,0,0,0,0,0,0,0,0,0,0,0,0,0,0,0,0,0,0,0,0,0,0,0,0
0,0,0,0,0,0,0,0,0,0,0,0,0,0,0,0,0,0,0,0,0,0,0,0,0,0,0,0,0,0,0,0,0,0,0,0,0,0,0,0,0
0,0,0,0,0,0,0,0,0,0,0,0,0,0,0,0,0,0,0,0,0,0,0,0,0,0,0,0,0,0,0,0,0,0,0,0,0,0,0,0,0
0,0,0,0,0,0,0,0,0,0,0,0,0,0,0,0,0,0,0,0,0,0,0,0,0,0,0,0,0,0,0,0,0,0,0,0,0,0,0,0,0
0,0,0,0,0,0,0,0,0,0,0,0,0,0,0,0,0,0,0,0,0,0,0,0,0,0,0,0,0,0,0,0,0,0,0,0,0,0,0,0,0
0,0,0,0,0,0,0,0,0,0,0,0,0,0,0,0,0,0,0,0,0,0,0,0,0,0,0,0,0,0,0,0,0,0,0,0,0,0,0,0,0
0,0,0,0,0,0,0,0,0,0,0,0,0,0,0,0,0,0,0,0,0,0,0,0,0,0,0,0,0,0,0,0,0,0,0,0,0,0,0,0,0
0,0,0,0,0,0,0,0,0,0,0,0,0,0,0,0,0,0,0,0,0,0,0,0,0,0,0,0,0,0,0,0,0,0,0,0,0,0,0,0,0
:endlayer
layer: 31
0,0,0,0,0,0,0,0,0,0,0,0,0,0,0,0,0,0,0,0,0,0,0,0,0,0,0,0,0,0,0,0,0,0,0,0,0,0,0,0,0
0,0,0,0,0,0,0,0,0,0,0,0,0,0,0,0,0,0,0,0,0,0,0,0,0,0,0,0,0,0,0,0,0,0,0,0,0,0,0,0,0
0,0,0,0,0,0,0,0,0,0,0,0,0,0,0,0,0,0,0,0,0,0,0,0,0,0,0,0,0,0,0,0,0,0,0,0,0,0,0,0,0
0,0,0,0,0,0,0,0,0,0,0,0,0,0,0,0,0,0,0,0,0,0,0,0,0,0,0,0,0,0,0,0,0,0,0,0,0,0,0,0,0
0,0,0,0,0,0,0,0,0,0,0,0,0,0,0,0,0,0,0,0,0,0,0,0,0,0,0,0,0,0,0,0,0,0,0,0,0,0,0,0,0
0,0,0,0,0,0,0,0,0,0,0,0,0,0,0,0,0,0,0,0,0,0,0,0,0,0,0,0,0,0,0,0,0,0,0,0,0,0,0,0,0
0,0,0,0,0,0,0,0,0,0,0,0,0,0,0,0,0,0,0,0,0,0,0,0,0,0,0,0,0,0,0,0,0,0,0,0,0,0,0,0,0
0,0,0,0,0,0,0,0,0,0,0,0,0,0,0,0,0,0,0,0,0,0,0,0,0,0,0,0,0,0,0,0,0,0,0,0,0,0,0,0,0
0,0,0,0,0,0,0,0,0,0,0,0,0,0,0,0,0,0,0,0,0,0,0,0,0,0,0,0,0,0,0,0,0,0,0,0,0,0,0,0,0
0,0,0,0,0,0,0,0,0,0,0,0,0,0,0,0,0,0,0,0,0,0,0,0,0,0,0,0,0,0,0,0,0,0,0,0,0,0,0,0,0
0,0,0,0,0,0,0,0,0,0,0,0,0,0,0,0,0,0,0,0,0,0,0,0,0,0,0,0,0,0,0,0,0,0,0,0,0,0,0,0,0
0,0,0,0,0,0,0,0,0,0,0,0,0,0,0,0,0,0,0,0,0,0,0,0,0,0,0,0,0,0,0,0,0,0,0,0,0,0,0,0,0
0,0,0,0,0,0,0,0,0,0,0,0,0,0,0,0,0,0,0,0,0,0,0,0,0,0,0,0,0,0,0,0,0,0,0,0,0,0,0,0,0
0,0,0,0,0,0,0,0,0,0,0,0,0,0,0,0,0,0,0,0,0,0,0,0,0,0,0,0,0,0,0,0,0,0,0,0,0,0,0,0,0
0,0,0,0,0,0,0,0,0,0,0,0,0,27,258,29,0,0,0,0,0,0,0,0,0,27,258,29,0,0,0,0,0,0,0,0,0,0,0,0,0
0,0,0,0,0,0,0,0,0,0,0,0,78,258,258,258,78,0,0,0,0,0,0,0,78,258,258,258,78,0,0,0,0,0,0,0,0,0,0,0,0
0,0,0,0,0,0,0,0,0,0,0,0,258,258,258,258,258,0,0,0,0,0,0,0,258,258,258,258,258,0,0,0,0,0,0,0,0,0,0,0,0
0,0,0,0,0,0,0,0,0,0,0,0,14,258,258,258,14,0,0,0,0,0,0,0,14,258,258,258,14,0,0,0,0,0,0,0,0,0,0,0,0
0,0,0,0,0,0,0,0,0,0,0,0,0,27,258,29,0,0,0,0,0,0,0,0,0,27,258,29,0,0,0,0,0,0,0,0,0,0,0,0,0
0,0,0,0,0,0,0,0,0,0,0,0,0,0,0,0,0,0,0,0,0,0,0,0,0,0,0,0,0,0,0,0,0,0,0,0,0,0,0,0,0
0,0,0,0,0,0,0,0,0,0,0,0,0,0,0,0,0,0,0,0,0,0,0,0,0,0,0,0,0,0,0,0,0,0,0,0,0,0,0,0,0
0,0,0,0,0,0,0,0,0,0,0,0,0,0,0,0,0,0,0,0,0,0,0,0,0,0,0,0,0,0,0,0,0,0,0,0,0,0,0,0,0
0,0,0,0,0,0,0,0,0,0,0,0,0,0,0,0,0,0,0,0,0,0,0,0,0,0,0,0,0,0,0,0,0,0,0,0,0,0,0,0,0
0,0,0,0,0,0,0,0,0,0,0,0,0,0,0,0,0,0,0,0,0,0,0,0,0,0,0,0,0,0,0,0,0,0,0,0,0,0,0,0,0
0,0,0,0,0,0,0,0,0,0,0,0,0,0,0,0,0,0,0,0,0,0,0,0,0,0,0,0,0,0,0,0,0,0,0,0,0,0,0,0,0
0,0,0,0,0,0,0,0,0,0,0,0,0,0,0,0,0,0,0,0,0,0,0,0,0,0,0,0,0,0,0,0,0,0,0,0,0,0,0,0,0
0,0,0,0,0,0,0,0,0,0,0,0,0,0,0,0,0,0,0,0,0,0,0,0,0,0,0,0,0,0,0,0,0,0,0,0,0,0,0,0,0
0,0,0,0,0,0,0,0,0,0,0,0,0,0,0,0,0,0,0,0,0,0,0,0,0,0,0,0,0,0,0,0,0,0,0,0,0,0,0,0,0
0,0,0,0,0,0,0,0,0,0,0,0,0,0,0,0,0,0,0,0,0,0,0,0,0,0,0,0,0,0,0,0,0,0,0,0,0,0,0,0,0
0,0,0,0,0,0,0,0,0,0,0,0,0,0,0,0,0,0,0,0,0,0,0,0,0,0,0,0,0,0,0,0,0,0,0,0,0,0,0,0,0
0,0,0,0,0,0,0,0,0,0,0,0,0,0,0,0,0,0,0,0,0,0,0,0,0,0,0,0,0,0,0,0,0,0,0,0,0,0,0,0,0
:endlayer
layer: 32
0,0,0,0,0,0,0,0,0,0,0,0,0,0,0,0,0,0,0,0,0,0,0,0,0,0,0,0,0,0,0,0,0,0,0,0,0,0,0,0,0
0,0,0,0,0,0,0,0,0,0,0,0,0,0,0,0,0,0,0,0,0,0,0,0,0,0,0,0,0,0,0,0,0,0,0,0,0,0,0,0,0
0,0,0,0,0,0,0,0,0,0,0,0,0,0,0,0,0,0,0,0,0,0,0,0,0,0,0,0,0,0,0,0,0,0,0,0,0,0,0,0,0
0,0,0,0,0,0,0,0,0,0,0,0,0,0,0,0,0,0,0,0,0,0,0,0,0,0,0,0,0,0,0,0,0,0,0,0,0,0,0,0,0
0,0,0,0,0,0,0,0,0,0,0,0,0,0,0,0,0,0,0,0,0,0,0,0,0,0,0,0,0,0,0,0,0,0,0,0,0,0,0,0,0
0,0,0,0,0,0,0,0,0,0,0,0,0,0,0,0,0,0,0,0,0,0,0,0,0,0,0,0,0,0,0,0,0,0,0,0,0,0,0,0,0
0,0,0,0,0,0,0,0,0,0,0,0,0,0,0,0,0,0,0,0,0,0,0,0,0,0,0,0,0,0,0,0,0,0,0,0,0,0,0,0,0
0,0,0,0,0,0,0,0,0,0,0,0,0,0,0,0,0,0,0,0,0,0,0,0,0,0,0,0,0,0,0,0,0,0,0,0,0,0,0,0,0
0,0,0,0,0,0,0,0,0,0,0,0,0,0,0,0,0,0,0,0,0,0,0,0,0,0,0,0,0,0,0,0,0,0,0,0,0,0,0,0,0
0,0,0,0,0,0,0,0,0,0,0,0,0,0,0,0,0,0,0,0,0,0,0,0,0,0,0,0,0,0,0,0,0,0,0,0,0,0,0,0,0
0,0,0,0,0,0,0,0,0,0,0,0,0,0,0,0,0,0,0,0,0,0,0,0,0,0,0,0,0,0,0,0,0,0,0,0,0,0,0,0,0
0,0,0,0,0,0,0,0,0,0,0,0,0,0,0,0,0,0,0,0,0,0,0,0,0,0,0,0,0,0,0,0,0,0,0,0,0,0,0,0,0
0,0,0,0,0,0,0,0,0,0,0,0,0,0,0,0,0,0,0,0,0,0,0,0,0,0,0,0,0,0,0,0,0,0,0,0,0,0,0,0,0
0,0,0,0,0,0,0,0,0,0,0,0,0,0,0,0,0,0,0,0,0,0,0,0,0,0,0,0,0,0,0,0,0,0,0,0,0,0,0,0,0
0,0,0,0,0,0,0,0,0,0,0,0,0,0,0,0,0,0,0,0,0,0,0,0,0,0,0,0,0,0,0,0,0,0,0,0,0,0,0,0,0
0,0,0,0,0,0,0,0,0,0,0,0,0,176,258,176,0,0,0,0,0,0,0,0,0,176,258,176,0,0,0,0,0,0,0,0,0,0,0,0,0
0,0,0,0,0,0,0,0,0,0,0,0,0,258,258,258,0,0,0,0,0,0,0,0,0,258,258,258,0,0,0,0,0,0,0,0,0,0,0,0,0
0,0,0,0,0,0,0,0,0,0,0,0,0,176,258,176,0,0,0,0,0,0,0,0,0,176,258,176,0,0,0,0,0,0,0,0,0,0,0,0,0
0,0,0,0,0,0,0,0,0,0,0,0,0,0,0,0,0,0,0,0,0,0,0,0,0,0,0,0,0,0,0,0,0,0,0,0,0,0,0,0,0
0,0,0,0,0,0,0,0,0,0,0,0,0,0,0,0,0,0,0,0,0,0,0,0,0,0,0,0,0,0,0,0,0,0,0,0,0,0,0,0,0
0,0,0,0,0,0,0,0,0,0,0,0,0,0,0,0,0,0,0,0,0,0,0,0,0,0,0,0,0,0,0,0,0,0,0,0,0,0,0,0,0
0,0,0,0,0,0,0,0,0,0,0,0,0,0,0,0,0,0,0,0,0,0,0,0,0,0,0,0,0,0,0,0,0,0,0,0,0,0,0,0,0
0,0,0,0,0,0,0,0,0,0,0,0,0,0,0,0,0,0,0,0,0,0,0,0,0,0,0,0,0,0,0,0,0,0,0,0,0,0,0,0,0
0,0,0,0,0,0,0,0,0,0,0,0,0,0,0,0,0,0,0,0,0,0,0,0,0,0,0,0,0,0,0,0,0,0,0,0,0,0,0,0,0
0,0,0,0,0,0,0,0,0,0,0,0,0,0,0,0,0,0,0,0,0,0,0,0,0,0,0,0,0,0,0,0,0,0,0,0,0,0,0,0,0
0,0,0,0,0,0,0,0,0,0,0,0,0,0,0,0,0,0,0,0,0,0,0,0,0,0,0,0,0,0,0,0,0,0,0,0,0,0,0,0,0
0,0,0,0,0,0,0,0,0,0,0,0,0,0,0,0,0,0,0,0,0,0,0,0,0,0,0,0,0,0,0,0,0,0,0,0,0,0,0,0,0
0,0,0,0,0,0,0,0,0,0,0,0,0,0,0,0,0,0,0,0,0,0,0,0,0,0,0,0,0,0,0,0,0,0,0,0,0,0,0,0,0
0,0,0,0,0,0,0,0,0,0,0,0,0,0,0,0,0,0,0,0,0,0,0,0,0,0,0,0,0,0,0,0,0,0,0,0,0,0,0,0,0
0,0,0,0,0,0,0,0,0,0,0,0,0,0,0,0,0,0,0,0,0,0,0,0,0,0,0,0,0,0,0,0,0,0,0,0,0,0,0,0,0
0,0,0,0,0,0,0,0,0,0,0,0,0,0,0,0,0,0,0,0,0,0,0,0,0,0,0,0,0,0,0,0,0,0,0,0,0,0,0,0,0
:endlayer
layer: 33
0,0,0,0,0,0,0,0,0,0,0,0,0,0,0,0,0,0,0,0,0,0,0,0,0,0,0,0,0,0,0,0,0,0,0,0,0,0,0,0,0
0,0,0,0,0,0,0,0,0,0,0,0,0,0,0,0,0,0,0,0,0,0,0,0,0,0,0,0,0,0,0,0,0,0,0,0,0,0,0,0,0
0,0,0,0,0,0,0,0,0,0,0,0,0,0,0,0,0,0,0,0,0,0,0,0,0,0,0,0,0,0,0,0,0,0,0,0,0,0,0,0,0
0,0,0,0,0,0,0,0,0,0,0,0,0,0,0,0,0,0,0,0,0,0,0,0,0,0,0,0,0,0,0,0,0,0,0,0,0,0,0,0,0
0,0,0,0,0,0,0,0,0,0,0,0,0,0,0,0,0,0,0,0,0,0,0,0,0,0,0,0,0,0,0,0,0,0,0,0,0,0,0,0,0
0,0,0,0,0,0,0,0,0,0,0,0,0,0,0,0,0,0,0,0,0,0,0,0,0,0,0,0,0,0,0,0,0,0,0,0,0,0,0,0,0
0,0,0,0,0,0,0,0,0,0,0,0,0,0,0,0,0,0,0,0,0,0,0,0,0,0,0,0,0,0,0,0,0,0,0,0,0,0,0,0,0
0,0,0,0,0,0,0,0,0,0,0,0,0,0,0,0,0,0,0,0,0,0,0,0,0,0,0,0,0,0,0,0,0,0,0,0,0,0,0,0,0
0,0,0,0,0,0,0,0,0,0,0,0,0,0,0,0,0,0,0,0,0,0,0,0,0,0,0,0,0,0,0,0,0,0,0,0,0,0,0,0,0
0,0,0,0,0,0,0,0,0,0,0,0,0,0,0,0,0,0,0,0,0,0,0,0,0,0,0,0,0,0,0,0,0,0,0,0,0,0,0,0,0
0,0,0,0,0,0,0,0,0,0,0,0,0,0,0,0,0,0,0,0,0,0,0,0,0,0,0,0,0,0,0,0,0,0,0,0,0,0,0,0,0
0,0,0,0,0,0,0,0,0,0,0,0,0,0,0,0,0,0,0,0,0,0,0,0,0,0,0,0,0,0,0,0,0,0,0,0,0,0,0,0,0
0,0,0,0,0,0,0,0,0,0,0,0,0,0,0,0,0,0,0,0,0,0,0,0,0,0,0,0,0,0,0,0,0,0,0,0,0,0,0,0,0
0,0,0,0,0,0,0,0,0,0,0,0,0,0,0,0,0,0,0,0,0,0,0,0,0,0,0,0,0,0,0,0,0,0,0,0,0,0,0,0,0
0,0,0,0,0,0,0,0,0,0,0,0,0,0,0,0,0,0,0,0,0,0,0,0,0,0,0,0,0,0,0,0,0,0,0,0,0,0,0,0,0
0,0,0,0,0,0,0,0,0,0,0,0,0,0,0,0,0,0,0,0,0,0,0,0,0,0,0,0,0,0,0,0,0,0,0,0,0,0,0,0,0
0,0,0,0,0,0,0,0,0,0,0,0,0,0,185,0,0,0,0,0,0,0,0,0,0,0,185,0,0,0,0,0,0,0,0,0,0,0,0,0,0
0,0,0,0,0,0,0,0,0,0,0,0,0,0,0,0,0,0,0,0,0,0,0,0,0,0,0,0,0,0,0,0,0,0,0,0,0,0,0,0,0
0,0,0,0,0,0,0,0,0,0,0,0,0,0,0,0,0,0,0,0,0,0,0,0,0,0,0,0,0,0,0,0,0,0,0,0,0,0,0,0,0
0,0,0,0,0,0,0,0,0,0,0,0,0,0,0,0,0,0,0,0,0,0,0,0,0,0,0,0,0,0,0,0,0,0,0,0,0,0,0,0,0
0,0,0,0,0,0,0,0,0,0,0,0,0,0,0,0,0,0,0,0,0,0,0,0,0,0,0,0,0,0,0,0,0,0,0,0,0,0,0,0,0
0,0,0,0,0,0,0,0,0,0,0,0,0,0,0,0,0,0,0,0,0,0,0,0,0,0,0,0,0,0,0,0,0,0,0,0,0,0,0,0,0
0,0,0,0,0,0,0,0,0,0,0,0,0,0,0,0,0,0,0,0,0,0,0,0,0,0,0,0,0,0,0,0,0,0,0,0,0,0,0,0,0
0,0,0,0,0,0,0,0,0,0,0,0,0,0,0,0,0,0,0,0,0,0,0,0,0,0,0,0,0,0,0,0,0,0,0,0,0,0,0,0,0
0,0,0,0,0,0,0,0,0,0,0,0,0,0,0,0,0,0,0,0,0,0,0,0,0,0,0,0,0,0,0,0,0,0,0,0,0,0,0,0,0
0,0,0,0,0,0,0,0,0,0,0,0,0,0,0,0,0,0,0,0,0,0,0,0,0,0,0,0,0,0,0,0,0,0,0,0,0,0,0,0,0
0,0,0,0,0,0,0,0,0,0,0,0,0,0,0,0,0,0,0,0,0,0,0,0,0,0,0,0,0,0,0,0,0,0,0,0,0,0,0,0,0
0,0,0,0,0,0,0,0,0,0,0,0,0,0,0,0,0,0,0,0,0,0,0,0,0,0,0,0,0,0,0,0,0,0,0,0,0,0,0,0,0
0,0,0,0,0,0,0,0,0,0,0,0,0,0,0,0,0,0,0,0,0,0,0,0,0,0,0,0,0,0,0,0,0,0,0,0,0,0,0,0,0
0,0,0,0,0,0,0,0,0,0,0,0,0,0,0,0,0,0,0,0,0,0,0,0,0,0,0,0,0,0,0,0,0,0,0,0,0,0,0,0,0
0,0,0,0,0,0,0,0,0,0,0,0,0,0,0,0,0,0,0,0,0,0,0,0,0,0,0,0,0,0,0,0,0,0,0,0,0,0,0,0,0
:endlayer
layer: 34
0,0,0,0,0,0,0,0,0,0,0,0,0,0,0,0,0,0,0,0,0,0,0,0,0,0,0,0,0,0,0,0,0,0,0,0,0,0,0,0,0
0,0,0,0,0,0,0,0,0,0,0,0,0,0,0,0,0,0,0,0,0,0,0,0,0,0,0,0,0,0,0,0,0,0,0,0,0,0,0,0,0
0,0,0,0,0,0,0,0,0,0,0,0,0,0,0,0,0,0,0,0,0,0,0,0,0,0,0,0,0,0,0,0,0,0,0,0,0,0,0,0,0
0,0,0,0,0,0,0,0,0,0,0,0,0,0,0,0,0,0,0,0,0,0,0,0,0,0,0,0,0,0,0,0,0,0,0,0,0,0,0,0,0
0,0,0,0,0,0,0,0,0,0,0,0,0,0,0,0,0,0,0,0,0,0,0,0,0,0,0,0,0,0,0,0,0,0,0,0,0,0,0,0,0
0,0,0,0,0,0,0,0,0,0,0,0,0,0,0,0,0,0,0,0,0,0,0,0,0,0,0,0,0,0,0,0,0,0,0,0,0,0,0,0,0
0,0,0,0,0,0,0,0,0,0,0,0,0,0,0,0,0,0,0,0,0,0,0,0,0,0,0,0,0,0,0,0,0,0,0,0,0,0,0,0,0
0,0,0,0,0,0,0,0,0,0,0,0,0,0,0,0,0,0,0,0,0,0,0,0,0,0,0,0,0,0,0,0,0,0,0,0,0,0,0,0,0
0,0,0,0,0,0,0,0,0,0,0,0,0,0,0,0,0,0,0,0,0,0,0,0,0,0,0,0,0,0,0,0,0,0,0,0,0,0,0,0,0
0,0,0,0,0,0,0,0,0,0,0,0,0,0,0,0,0,0,0,0,0,0,0,0,0,0,0,0,0,0,0,0,0,0,0,0,0,0,0,0,0
0,0,0,0,0,0,0,0,0,0,0,0,0,0,0,0,0,0,0,0,0,0,0,0,0,0,0,0,0,0,0,0,0,0,0,0,0,0,0,0,0
0,0,0,0,0,0,0,0,0,0,0,0,0,0,0,0,0,0,0,0,0,0,0,0,0,0,0,0,0,0,0,0,0,0,0,0,0,0,0,0,0
0,0,0,0,0,0,0,0,0,0,0,0,0,0,0,180,0,0,0,0,0,0,0,0,0,0,0,0,0,0,0,0,0,0,0,0,0,0,0,0,0
0,0,0,0,0,0,0,0,0,0,0,0,0,0,0,180,0,0,0,0,0,0,0,0,0,0,0,180,0,0,0,0,0,0,0,0,0,0,0,0,0
0,0,0,0,0,0,0,0,0,0,0,0,0,0,180,0,0,0,0,0,0,0,0,0,0,0,0,180,0,0,0,0,0,0,0,0,0,0,0,0,0
0,0,0,0,0,0,0,0,0,0,0,0,0,0,180,0,0,0,0,0,0,0,0,0,0,0,180,0,0,0,0,0,0,0,0,0,0,0,0,0,0
0,0,0,0,0,0,0,0,0,0,0,0,0,0,185,0,0,0,0,0,0,0,0,0,0,0,185,0,0,0,0,0,0,0,0,0,0,0,0,0,0
0,0,0,0,0,0,0,0,0,0,0,0,0,0,0,0,0,0,0,0,0,0,0,0,0,0,0,0,0,0,0,0,0,0,0,0,0,0,0,0,0
0,0,0,0,0,0,0,0,0,0,0,0,0,0,0,0,0,0,0,0,0,0,0,0,0,0,0,0,0,0,0,0,0,0,0,0,0,0,0,0,0
0,0,0,0,0,0,0,0,0,0,0,0,0,0,0,0,0,0,0,0,0,0,0,0,0,0,0,0,0,0,0,0,0,0,0,0,0,0,0,0,0
0,0,0,0,0,0,0,0,0,0,0,0,0,0,0,0,0,0,0,0,0,0,0,0,0,0,0,0,0,0,0,0,0,0,0,0,0,0,0,0,0
0,0,0,0,0,0,0,0,0,0,0,0,0,0,0,0,0,0,0,0,0,0,0,0,0,0,0,0,0,0,0,0,0,0,0,0,0,0,0,0,0
0,0,0,0,0,0,0,0,0,0,0,0,0,0,0,0,0,0,0,0,0,0,0,0,0,0,0,0,0,0,0,0,0,0,0,0,0,0,0,0,0
0,0,0,0,0,0,0,0,0,0,0,0,0,0,0,0,0,0,0,0,0,0,0,0,0,0,0,0,0,0,0,0,0,0,0,0,0,0,0,0,0
0,0,0,0,0,0,0,0,0,0,0,0,0,0,0,0,0,0,0,0,0,0,0,0,0,0,0,0,0,0,0,0,0,0,0,0,0,0,0,0,0
0,0,0,0,0,0,0,0,0,0,0,0,0,0,0,0,0,0,0,0,0,0,0,0,0,0,0,0,0,0,0,0,0,0,0,0,0,0,0,0,0
0,0,0,0,0,0,0,0,0,0,0,0,0,0,0,0,0,0,0,0,0,0,0,0,0,0,0,0,0,0,0,0,0,0,0,0,0,0,0,0,0
0,0,0,0,0,0,0,0,0,0,0,0,0,0,0,0,0,0,0,0,0,0,0,0,0,0,0,0,0,0,0,0,0,0,0,0,0,0,0,0,0
0,0,0,0,0,0,0,0,0,0,0,0,0,0,0,0,0,0,0,0,0,0,0,0,0,0,0,0,0,0,0,0,0,0,0,0,0,0,0,0,0
0,0,0,0,0,0,0,0,0,0,0,0,0,0,0,0,0,0,0,0,0,0,0,0,0,0,0,0,0,0,0,0,0,0,0,0,0,0,0,0,0
0,0,0,0,0,0,0,0,0,0,0,0,0,0,0,0,0,0,0,0,0,0,0,0,0,0,0,0,0,0,0,0,0,0,0,0,0,0,0,0,0
:endlayer
layer: 35
0,0,0,0,0,0,0,0,0,0,0,0,0,0,0,0,0,0,0,0,0,0,0,0,0,0,0,0,0,0,0,0,0,0,0,0,0,0,0,0,0
0,0,0,0,0,0,0,0,0,0,0,0,0,0,0,0,0,0,0,0,0,0,0,0,0,0,0,0,0,0,0,0,0,0,0,0,0,0,0,0,0
0,0,0,0,0,0,0,0,0,0,0,0,0,0,0,0,0,0,0,0,0,0,0,0,0,0,0,0,0,0,0,0,0,0,0,0,0,0,0,0,0
0,0,0,0,0,0,0,0,0,0,0,0,0,0,0,0,0,0,0,0,0,0,0,0,0,0,0,0,0,0,0,0,0,0,0,0,0,0,0,0,0
0,0,0,0,0,0,0,0,0,0,0,0,0,0,0,0,0,0,0,0,0,0,0,0,0,0,0,0,0,0,0,0,0,0,0,0,0,0,0,0,0
0,0,0,0,0,0,0,0,0,0,0,0,0,0,0,0,0,0,0,0,0,0,0,0,0,0,0,0,0,0,0,0,0,0,0,0,0,0,0,0,0
0,0,0,0,0,0,0,0,0,0,0,0,0,0,0,0,0,0,0,0,0,0,0,0,0,0,0,0,0,0,0,0,0,0,0,0,0,0,0,0,0
0,0,0,0,0,0,0,0,0,0,0,0,0,0,0,0,0,0,0,0,0,0,0,0,0,0,0,0,0,0,0,0,0,0,0,0,0,0,0,0,0
0,0,0,0,0,0,0,0,0,0,0,0,0,0,0,0,0,0,0,0,0,0,0,0,0,0,0,0,0,0,0,0,0,0,0,0,0,0,0,0,0
0,0,0,0,0,0,0,0,0,0,0,0,0,0,0,0,0,0,0,0,0,0,0,0,0,0,0,0,0,0,0,0,0,0,0,0,0,0,0,0,0
0,0,0,0,0,0,0,0,0,0,0,0,0,0,0,0,0,0,0,0,0,0,0,0,0,0,0,0,0,0,0,0,0,0,0,0,0,0,0,0,0
0,0,0,0,0,0,0,0,0,0,0,0,0,0,0,0,0,0,0,0,0,0,0,0,0,0,0,0,0,0,0,0,0,0,0,0,0,0,0,0,0
0,0,0,0,0,0,0,0,0,0,0,0,0,0,0,0,0,0,0,0,0,0,0,0,0,0,0,180,0,0,0,0,0,0,0,0,0,0,0,0,0
0,0,0,0,0,0,0,0,0,0,0,0,0,0,0,180,0,0,0,0,0,0,0,0,0,0,0,180,0,0,0,0,0,0,0,0,0,0,0,0,0
0,0,0,0,0,0,0,0,0,0,0,0,0,0,0,180,0,0,0,0,0,0,0,0,0,0,180,0,0,0,0,0,0,0,0,0,0,0,0,0,0
0,0,0,0,0,0,0,0,0,0,0,0,0,0,180,0,0,0,0,0,0,0,0,0,0,0,180,0,0,0,0,0,0,0,0,0,0,0,0,0,0
0,0,0,0,0,0,0,0,0,0,0,0,0,0,185,0,0,0,0,0,0,0,0,0,0,0,185,0,0,0,0,0,0,0,0,0,0,0,0,0,0
0,0,0,0,0,0,0,0,0,0,0,0,0,0,0,0,0,0,0,0,0,0,0,0,0,0,0,0,0,0,0,0,0,0,0,0,0,0,0,0,0
0,0,0,0,0,0,0,0,0,0,0,0,0,0,0,0,0,0,0,0,0,0,0,0,0,0,0,0,0,0,0,0,0,0,0,0,0,0,0,0,0
0,0,0,0,0,0,0,0,0,0,0,0,0,0,0,0,0,0,0,0,0,0,0,0,0,0,0,0,0,0,0,0,0,0,0,0,0,0,0,0,0
0,0,0,0,0,0,0,0,0,0,0,0,0,0,0,0,0,0,0,0,0,0,0,0,0,0,0,0,0,0,0,0,0,0,0,0,0,0,0,0,0
0,0,0,0,0,0,0,0,0,0,0,0,0,0,0,0,0,0,0,0,0,0,0,0,0,0,0,0,0,0,0,0,0,0,0,0,0,0,0,0,0
0,0,0,0,0,0,0,0,0,0,0,0,0,0,0,0,0,0,0,0,0,0,0,0,0,0,0,0,0,0,0,0,0,0,0,0,0,0,0,0,0
0,0,0,0,0,0,0,0,0,0,0,0,0,0,0,0,0,0,0,0,0,0,0,0,0,0,0,0,0,0,0,0,0,0,0,0,0,0,0,0,0
0,0,0,0,0,0,0,0,0,0,0,0,0,0,0,0,0,0,0,0,0,0,0,0,0,0,0,0,0,0,0,0,0,0,0,0,0,0,0,0,0
0,0,0,0,0,0,0,0,0,0,0,0,0,0,0,0,0,0,0,0,0,0,0,0,0,0,0,0,0,0,0,0,0,0,0,0,0,0,0,0,0
0,0,0,0,0,0,0,0,0,0,0,0,0,0,0,0,0,0,0,0,0,0,0,0,0,0,0,0,0,0,0,0,0,0,0,0,0,0,0,0,0
0,0,0,0,0,0,0,0,0,0,0,0,0,0,0,0,0,0,0,0,0,0,0,0,0,0,0,0,0,0,0,0,0,0,0,0,0,0,0,0,0
0,0,0,0,0,0,0,0,0,0,0,0,0,0,0,0,0,0,0,0,0,0,0,0,0,0,0,0,0,0,0,0,0,0,0,0,0,0,0,0,0
0,0,0,0,0,0,0,0,0,0,0,0,0,0,0,0,0,0,0,0,0,0,0,0,0,0,0,0,0,0,0,0,0,0,0,0,0,0,0,0,0
0,0,0,0,0,0,0,0,0,0,0,0,0,0,0,0,0,0,0,0,0,0,0,0,0,0,0,0,0,0,0,0,0,0,0,0,0,0,0,0,0
:endlayer
layer: 36
0,0,0,0,0,0,0,0,0,0,0,0,0,0,0,0,0,0,0,0,0,0,0,0,0,0,0,0,0,0,0,0,0,0,0,0,0,0,0,0,0
0,0,0,0,0,0,0,0,0,0,0,0,0,0,0,0,0,0,0,0,0,0,0,0,0,0,0,0,0,0,0,0,0,0,0,0,0,0,0,0,0
0,0,0,0,0,0,0,0,0,0,0,0,0,0,0,0,0,0,0,0,0,0,0,0,0,0,0,0,0,0,0,0,0,0,0,0,0,0,0,0,0
0,0,0,0,0,0,0,0,0,0,0,0,0,0,0,0,0,0,0,0,0,0,0,0,0,0,0,0,0,0,0,0,0,0,0,0,0,0,0,0,0
0,0,0,0,0,0,0,0,0,0,0,0,0,0,0,0,0,0,0,0,0,0,0,0,0,0,0,0,0,0,0,0,0,0,0,0,0,0,0,0,0
0,0,0,0,0,0,0,0,0,0,0,0,0,0,0,0,0,0,0,0,0,0,0,0,0,0,0,0,0,0,0,0,0,0,0,0,0,0,0,0,0
0,0,0,0,0,0,0,0,0,0,0,0,0,0,0,0,0,0,0,0,0,0,0,0,0,0,0,0,0,0,0,0,0,0,0,0,0,0,0,0,0
0,0,0,0,0,0,0,0,0,0,0,0,0,0,0,0,0,0,0,0,0,0,0,0,0,0,0,0,0,0,0,0,0,0,0,0,0,0,0,0,0
0,0,0,0,0,0,0,0,0,0,0,0,0,0,0,0,0,0,0,0,0,0,0,0,0,0,0,0,0,0,0,0,0,0,0,0,0,0,0,0,0
0,0,0,0,0,0,0,0,0,0,0,0,0,0,0,0,0,0,0,0,0,0,0,0,0,0,0,0,0,0,0,0,0,0,0,0,0,0,0,0,0
0,0,0,0,0,0,0,0,0,0,0,0,0,0,0,0,0,0,0,0,0,0,0,0,0,0,0,0,0,0,0,0,0,0,0,0,0,0,0,0,0
0,0,0,0,0,0,0,0,0,0,0,0,0,0,0,0,0,0,0,0,0,0,0,0,0,0,0,0,0,0,0,0,0,0,0,0,0,0,0,0,0
0,0,0,0,0,0,0,0,0,0,0,0,0,0,0,0,0,0,0,0,0,0,0,0,0,0,0,0,0,0,0,0,0,0,0,0,0,0,0,0,0
0,0,0,0,0,0,0,0,0,0,0,0,0,0,0,0,0,0,0,0,0,0,0,0,0,0,0,0,0,0,0,0,0,0,0,0,0,0,0,0,0
0,0,0,0,0,0,0,0,0,0,0,0,0,0,0,0,0,0,0,0,0,0,0,0,0,0,0,0,0,0,0,0,0,0,0,0,0,0,0,0,0
0,0,0,0,0,0,0,0,0,0,0,0,0,0,0,0,0,0,0,0,0,0,0,0,0,0,0,0,0,0,0,0,0,0,0,0,0,0,0,0,0
0,0,0,0,0,0,0,0,0,0,0,0,0,0,199,0,0,0,0,0,0,0,0,0,0,0,199,0,0,0,0,0,0,0,0,0,0,0,0,0,0
0,0,0,0,0,0,0,0,0,0,0,0,0,0,0,0,0,0,0,0,0,0,0,0,0,0,0,0,0,0,0,0,0,0,0,0,0,0,0,0,0
0,0,0,0,0,0,0,0,0,0,0,0,0,0,0,0,0,0,0,0,0,0,0,0,0,0,0,0,0,0,0,0,0,0,0,0,0,0,0,0,0
0,0,0,0,0,0,0,0,0,0,0,0,0,0,0,0,0,0,0,0,0,0,0,0,0,0,0,0,0,0,0,0,0,0,0,0,0,0,0,0,0
0,0,0,0,0,0,0,0,0,0,0,0,0,0,0,0,0,0,0,0,0,0,0,0,0,0,0,0,0,0,0,0,0,0,0,0,0,0,0,0,0
0,0,0,0,0,0,0,0,0,0,0,0,0,0,0,0,0,0,0,0,0,0,0,0,0,0,0,0,0,0,0,0,0,0,0,0,0,0,0,0,0
0,0,0,0,0,0,0,0,0,0,0,0,0,0,0,0,0,0,0,0,0,0,0,0,0,0,0,0,0,0,0,0,0,0,0,0,0,0,0,0,0
0,0,0,0,0,0,0,0,0,0,0,0,0,0,0,0,0,0,0,0,0,0,0,0,0,0,0,0,0,0,0,0,0,0,0,0,0,0,0,0,0
0,0,0,0,0,0,0,0,0,0,0,0,0,0,0,0,0,0,0,0,0,0,0,0,0,0,0,0,0,0,0,0,0,0,0,0,0,0,0,0,0
