# Ancient Warfare Structure Template File
# Auto-generated structure template file. created on: 3/6/2024 at: 23:7:29
# Lines beginning with # denote comments

header:
version=2.11
name=SarkonidFarmMelon
mods=
size=29,16,27
offset=14,5,14
:endheader

#### VALIDATION ####
validation:
type=ground
structureAuthor=TheOddlySeagull
survival=false
worldGenEnabled=true
unique=false
preserveBlocks=false
preventNaturalHostileSpawns=true
selectionWeight=50
clusterValue=50
minDuplicateDistance=1000
dimensionWhiteList=true
dimensionList=0
biomeGroupList=sarkonid
biomeWhiteList=true
biomeList=environs:sandstone_ranges,nt:sahel,minecraft:desert,minecraft:mutated_desert,minecraft:desert_hills
leveling=10
fill=10
border=6
blockSwap=false
territoryName=sarkonid
biomeReplacement=minecraft:
minGenerationHeight=0
maxGenerationHeight=255
:endvalidation

#### LAYERS ####
layer: 0
1,1,1,1,1,1,1,1,1,1,1,1,1,1,1,1,1,1,1,1,1,1,1,1,1,1,1,1,1
1,1,1,1,1,1,1,1,1,1,1,1,1,1,1,1,1,1,1,1,1,1,1,1,1,1,1,1,1
1,1,1,1,1,1,1,1,1,1,1,1,1,1,1,1,1,1,1,1,1,1,1,1,1,1,1,1,1
1,1,1,1,1,1,1,1,1,1,1,1,1,1,1,1,1,1,1,1,1,1,1,1,1,1,1,1,1
1,1,1,1,1,1,1,1,1,1,1,1,1,1,1,1,1,1,1,1,1,1,1,1,1,1,1,1,1
1,1,1,1,1,1,1,1,1,1,1,1,1,1,1,1,1,1,1,1,1,1,1,1,1,1,1,1,1
1,1,1,1,1,1,1,1,1,1,1,1,1,1,1,1,1,1,1,1,1,1,1,1,1,1,1,1,1
1,1,1,1,1,1,1,1,1,1,1,1,1,1,1,1,1,1,1,1,1,1,1,1,1,1,1,1,1
1,1,1,1,1,1,1,1,1,1,1,1,1,1,1,1,1,1,1,1,1,1,1,1,1,1,1,1,1
1,1,1,1,1,1,1,1,1,1,1,1,1,1,1,1,1,1,1,1,1,1,1,1,1,1,1,1,1
1,1,1,1,1,1,1,1,1,1,1,1,1,1,1,1,1,1,1,1,1,1,1,1,1,1,1,1,1
1,1,1,1,1,1,1,1,1,1,1,1,1,1,1,1,1,1,1,1,1,1,1,1,1,1,1,1,1
1,1,1,1,1,1,1,1,1,1,1,1,1,1,1,1,1,1,1,1,1,1,1,1,1,1,1,1,1
1,1,1,1,1,1,1,1,1,1,1,1,1,1,1,1,1,1,1,1,1,1,1,1,1,1,1,1,1
1,1,1,1,1,1,1,1,1,1,1,1,1,1,1,1,1,1,1,1,1,1,1,1,1,1,1,1,1
1,1,1,1,1,1,1,1,1,1,1,1,1,1,1,1,1,1,1,1,1,1,1,1,1,1,1,1,1
1,1,1,1,1,1,1,1,1,1,1,1,1,1,1,1,1,1,1,1,1,1,1,1,1,1,1,1,1
1,1,1,1,1,1,1,1,1,1,1,1,1,1,1,1,1,1,1,1,1,1,1,1,1,1,1,1,1
1,1,1,1,1,1,1,1,1,1,1,1,1,1,1,1,1,1,1,1,1,1,1,1,1,1,1,1,1
1,1,1,1,1,1,1,1,1,1,1,1,1,1,1,1,1,1,1,1,1,1,1,1,1,1,1,1,1
1,1,1,1,1,1,1,1,1,1,1,1,1,1,1,1,1,1,1,1,1,1,1,1,1,1,1,1,1
1,1,1,1,1,1,1,1,1,1,1,1,1,1,1,1,1,1,1,1,1,1,1,1,1,1,1,1,1
1,1,1,1,1,1,1,1,1,1,1,1,1,1,1,1,1,1,1,1,1,1,1,1,1,1,1,1,1
1,1,1,1,1,1,1,1,1,1,1,1,1,1,1,1,1,1,1,1,1,1,1,1,1,1,1,1,1
1,1,1,1,1,1,1,1,1,1,1,1,1,1,1,1,1,1,1,1,1,1,1,1,1,1,1,1,1
1,1,1,1,1,1,1,1,1,1,1,1,1,1,1,1,1,1,1,1,1,1,1,1,1,1,1,1,1
1,1,1,1,1,1,1,1,1,1,1,1,1,1,1,1,1,1,1,1,1,1,1,1,1,1,1,1,1
:endlayer
layer: 1
1,1,1,1,1,1,1,1,1,1,1,1,1,1,1,1,1,1,1,1,1,1,1,1,1,1,1,1,1
1,1,1,1,1,1,1,1,1,1,1,1,1,1,1,1,1,1,1,1,1,1,1,1,1,1,1,1,1
1,1,1,1,1,1,1,1,1,1,1,1,1,1,1,1,1,1,1,1,1,1,1,1,1,1,1,1,1
1,1,1,1,1,1,1,1,1,1,1,1,1,1,1,1,1,1,1,1,1,1,1,1,1,1,1,1,1
1,1,1,1,1,1,1,1,1,1,1,2,1,1,1,1,1,1,1,1,1,1,1,1,1,1,1,1,1
1,1,1,1,1,1,1,1,1,1,1,1,1,1,1,1,1,1,1,1,1,1,1,1,1,1,1,1,1
1,1,1,1,1,1,1,1,1,1,1,1,1,1,1,1,1,1,1,1,1,1,1,1,1,1,1,1,1
1,1,1,1,1,1,1,1,1,1,1,1,1,1,1,1,1,1,1,1,1,1,1,1,1,1,1,1,1
1,1,1,1,1,1,1,1,1,1,1,1,1,1,1,1,1,1,1,1,1,1,1,1,1,1,1,1,1
1,1,1,1,1,1,1,1,1,1,1,1,1,1,1,1,1,1,1,1,1,1,1,1,1,1,1,1,1
1,1,1,1,1,1,1,1,1,1,1,1,1,1,1,1,1,1,1,1,1,1,1,1,1,1,1,1,1
1,1,1,1,1,1,1,1,1,1,1,1,1,1,1,1,1,1,1,1,1,1,1,1,1,1,1,1,1
1,1,1,1,1,1,1,1,1,1,1,1,1,1,1,1,1,1,1,1,1,1,1,1,1,1,1,1,1
1,1,1,1,1,1,1,1,1,1,1,1,1,1,1,1,1,1,1,1,1,1,1,1,1,1,1,1,1
1,1,1,1,1,1,1,1,1,1,1,1,1,1,1,1,1,1,1,1,1,1,1,1,1,1,1,1,1
1,1,1,1,1,1,1,1,1,1,1,1,1,1,1,1,1,1,1,1,1,1,1,1,1,1,1,1,1
1,1,1,1,1,1,1,1,1,1,1,1,1,1,1,1,1,1,1,1,1,1,1,1,1,1,1,1,1
1,1,1,1,1,1,1,1,1,1,1,1,1,1,1,1,1,1,1,1,1,1,1,1,1,1,1,1,1
1,1,1,1,1,1,1,1,1,1,1,1,1,1,1,1,1,1,1,1,1,1,1,1,1,1,1,1,1
1,1,1,1,1,1,1,1,1,1,1,1,1,1,1,1,1,1,1,1,1,1,1,1,1,1,1,1,1
1,1,1,1,1,1,1,1,1,1,1,1,1,1,1,1,1,1,1,1,1,1,1,1,1,1,1,1,1
1,1,1,1,1,1,1,1,1,1,1,1,1,1,1,1,1,1,1,1,1,1,1,1,1,1,1,1,1
1,1,1,1,1,1,1,1,1,1,1,1,1,1,1,1,1,1,1,1,1,1,1,1,1,1,1,1,1
1,1,1,1,1,1,1,1,1,1,1,1,1,1,1,1,1,1,1,1,1,1,1,1,1,1,1,1,1
1,1,1,1,1,1,1,1,1,1,1,1,1,1,1,1,1,1,1,1,1,1,1,1,1,1,1,1,1
1,1,1,1,1,1,1,1,1,1,1,1,1,1,1,1,1,1,1,1,1,1,1,1,1,1,1,1,1
1,1,1,1,1,1,1,1,1,1,1,1,1,1,1,1,1,1,1,1,1,1,1,1,1,1,1,1,1
:endlayer
layer: 2
1,1,1,1,1,1,1,1,1,1,1,1,1,1,1,1,1,1,1,1,1,1,1,1,1,1,1,1,1
1,1,1,1,1,1,1,1,1,1,1,1,1,1,1,1,1,1,1,1,1,1,1,1,1,1,1,1,1
1,1,1,1,1,1,1,1,1,1,1,1,1,1,1,1,1,1,1,1,1,1,1,1,1,1,1,1,1
1,1,1,1,1,1,1,1,1,1,1,2,2,1,1,1,1,1,1,1,1,1,1,1,1,1,1,1,1
1,1,1,1,1,1,1,1,1,1,1,2,2,1,1,1,1,1,1,1,1,1,1,1,1,1,1,1,1
1,1,1,1,1,1,1,1,1,1,1,1,1,1,1,1,1,1,1,1,1,1,1,1,1,1,1,1,1
1,1,1,1,1,1,1,1,1,1,1,1,1,1,1,1,1,1,1,1,1,1,1,1,1,1,1,1,1
1,1,1,1,1,1,1,1,1,1,1,1,1,1,1,1,1,1,1,1,1,1,1,1,1,1,1,1,1
1,1,1,1,1,1,1,1,1,1,1,1,1,1,1,1,1,1,1,1,1,1,1,1,1,1,1,1,1
1,1,1,1,1,1,1,1,1,1,1,1,1,1,1,1,1,1,1,1,1,1,1,1,1,1,1,1,1
1,1,1,1,1,1,1,1,1,1,1,1,1,1,1,1,1,1,1,1,1,1,1,1,1,1,1,1,1
1,1,1,1,1,1,1,1,1,1,1,1,1,1,1,1,1,1,1,1,1,1,1,1,1,1,1,1,1
1,1,1,1,1,1,1,1,1,1,1,1,1,1,1,1,1,1,1,1,1,1,1,1,1,1,1,1,1
1,1,1,1,1,1,1,1,1,1,1,1,1,1,1,1,1,1,1,1,1,1,1,1,1,1,1,1,1
1,1,1,1,1,1,1,1,1,1,1,1,1,1,1,1,1,1,1,1,1,1,1,1,1,1,1,1,1
1,1,1,1,1,1,1,1,1,1,1,1,1,1,1,1,1,1,1,1,1,1,1,1,1,1,1,1,1
1,1,1,1,1,1,1,1,1,1,1,1,1,1,1,1,1,1,1,1,1,1,1,1,1,1,1,1,1
1,1,1,1,1,1,1,1,1,1,1,1,1,1,1,1,1,1,1,1,1,1,1,1,1,1,1,1,1
1,1,1,1,1,1,1,1,1,1,1,1,1,1,1,1,1,1,1,1,1,1,1,1,1,1,1,1,1
1,1,1,1,1,1,1,1,1,1,1,1,1,1,1,1,1,1,1,1,1,1,1,1,1,1,1,1,1
1,1,1,1,1,1,1,1,1,1,1,1,1,1,1,1,1,1,1,1,1,1,1,1,1,1,1,1,1
1,1,1,1,1,1,1,1,1,1,1,1,1,1,1,1,1,1,1,1,1,1,1,1,1,1,1,1,1
1,1,1,1,1,1,1,1,1,1,1,1,1,1,1,1,1,1,1,1,1,1,1,1,1,1,1,1,1
1,1,1,1,1,1,1,1,1,1,1,1,1,1,1,1,1,1,1,1,1,1,1,1,1,1,1,1,1
1,1,1,1,1,1,1,1,1,1,1,1,1,1,1,1,1,1,1,1,1,1,1,1,1,1,1,1,1
1,1,1,1,1,1,1,1,1,1,1,1,1,1,1,1,1,1,1,1,1,1,1,1,1,1,1,1,1
1,1,1,1,1,1,1,1,1,1,1,1,1,1,1,1,1,1,1,1,1,1,1,1,1,1,1,1,1
:endlayer
layer: 3
3,3,3,3,3,3,3,3,3,3,3,3,3,3,3,3,3,3,3,3,3,3,3,3,3,3,3,3,3
3,3,3,3,3,3,3,3,3,3,3,3,3,3,3,3,3,3,3,3,3,3,3,3,3,3,3,3,3
3,3,1,1,1,1,1,1,1,1,1,1,1,1,1,1,1,1,1,1,1,1,1,1,3,3,3,3,3
3,3,1,3,3,1,3,3,1,3,1,2,2,1,3,1,3,3,3,3,3,3,3,1,3,3,3,3,3
3,3,1,3,3,1,3,3,1,3,1,2,2,1,3,1,3,3,3,3,3,3,3,1,1,1,1,3,3
3,3,1,3,3,1,3,3,1,3,1,1,1,1,3,1,3,3,3,3,3,3,3,3,3,3,1,3,3
3,3,3,3,3,3,3,3,3,3,3,3,3,3,3,1,3,3,3,3,3,3,3,3,3,3,1,3,3
3,3,3,3,3,3,3,3,3,3,3,3,3,3,3,1,3,3,3,3,3,3,3,3,3,3,1,3,3
3,3,3,3,3,3,3,3,3,3,3,3,3,3,3,1,1,1,1,1,3,3,3,3,3,3,1,3,3
3,3,3,3,3,3,3,3,3,3,3,3,3,3,3,3,3,3,3,1,3,3,3,3,3,3,1,3,3
3,3,1,1,1,1,1,1,1,1,1,3,3,3,3,3,3,3,3,1,3,3,3,3,3,3,1,3,3
3,3,1,3,3,3,3,3,3,3,1,3,3,3,3,3,3,3,3,1,1,1,1,1,1,1,1,3,3
3,3,1,3,3,3,3,3,3,3,1,3,3,3,3,3,3,3,3,3,3,3,3,3,3,3,3,3,3
3,3,1,3,3,3,3,3,3,3,1,3,3,3,3,3,3,3,3,3,3,3,3,3,3,3,3,3,3
3,3,1,3,3,3,3,3,3,3,1,3,3,3,3,3,3,3,3,3,3,3,3,3,3,3,3,3,3
3,3,1,3,3,3,3,3,3,3,1,3,3,3,3,3,3,3,3,3,3,3,3,3,3,3,3,3,3
3,3,1,3,3,3,3,3,3,3,1,3,3,3,3,1,1,1,1,1,1,1,1,1,1,1,1,3,3
3,3,1,3,3,3,3,3,3,3,1,3,3,3,3,1,3,3,3,3,3,3,3,3,3,3,1,3,3
3,3,1,3,3,3,3,3,3,3,1,3,3,3,3,1,3,3,3,3,3,3,3,3,3,3,1,3,3
3,3,1,3,3,3,3,3,3,3,1,3,3,3,3,1,3,3,3,3,3,3,3,3,3,3,1,3,3
3,3,1,3,3,3,3,3,3,3,1,3,3,3,3,1,3,3,3,3,3,3,3,3,3,3,1,3,3
3,3,1,3,3,3,3,3,3,3,1,3,3,3,3,1,3,3,3,3,3,3,3,3,3,3,1,3,3
3,3,1,3,3,3,3,3,3,3,1,3,3,3,3,1,3,3,3,3,3,3,3,3,3,3,1,3,3
3,3,1,3,3,3,3,3,3,3,1,3,3,3,3,1,3,3,3,3,3,3,3,3,3,3,1,3,3
3,3,1,1,1,1,1,1,1,1,1,3,3,3,3,1,1,1,1,1,1,1,1,1,1,1,1,3,3
3,3,3,3,3,3,3,3,3,3,3,3,3,3,3,3,3,3,3,3,3,3,3,3,3,3,3,3,3
3,3,3,3,3,3,3,3,3,3,3,3,3,3,3,3,3,3,3,3,3,3,3,3,3,3,3,3,3
:endlayer
layer: 4
3,3,3,3,3,3,3,3,3,3,3,3,3,3,3,3,3,3,3,3,3,3,3,1,3,3,3,1,3
3,3,3,3,3,3,3,3,3,3,3,3,3,3,3,3,3,3,3,3,3,1,3,3,1,3,1,3,3
3,3,1,1,1,1,1,1,1,1,1,1,1,1,1,1,1,1,1,1,1,1,1,1,1,1,3,3,3
3,3,1,1,4,4,3,4,1,3,1,2,2,1,1,1,1,1,1,1,1,1,1,1,1,1,3,1,3
3,3,1,3,1,1,3,4,1,1,1,2,2,1,3,1,1,1,1,1,1,1,1,1,1,1,1,3,3
3,3,1,4,1,3,4,1,1,1,1,1,1,1,3,1,1,1,1,1,1,1,1,1,1,1,1,3,1
1,3,3,3,1,1,1,1,3,1,3,1,3,3,3,1,1,1,1,1,1,1,1,1,1,1,1,3,3
3,3,1,1,3,3,1,3,1,3,3,3,3,1,1,1,1,1,1,1,1,1,1,1,1,1,1,3,3
1,3,1,1,1,3,1,1,1,3,3,3,3,1,1,1,1,1,1,1,1,1,1,1,1,1,1,3,3
1,3,1,1,1,1,3,3,1,3,3,3,1,1,3,1,1,3,1,1,1,1,1,1,1,1,1,3,3
3,3,1,1,1,1,1,1,1,1,1,1,1,3,3,1,1,3,1,1,1,1,1,1,1,1,1,3,3
3,3,1,3,3,3,3,3,3,3,1,1,3,1,1,1,3,1,1,1,1,1,1,1,1,1,1,3,3
3,3,1,3,3,3,3,3,3,3,1,3,1,1,1,3,1,3,3,1,1,1,1,1,3,3,1,3,1
3,3,1,3,3,3,3,3,3,3,1,3,3,1,3,3,1,1,1,3,3,1,3,1,3,1,3,1,1
3,3,1,3,3,3,3,3,3,3,1,3,3,3,1,1,1,1,1,1,1,1,3,3,3,3,3,3,1
3,3,1,3,3,3,3,3,3,3,1,1,1,3,3,1,1,3,3,1,1,1,3,1,1,3,3,3,3
3,3,1,3,3,3,3,3,3,3,1,3,3,1,3,1,1,1,1,1,1,1,1,1,1,1,1,3,3
3,3,1,3,3,3,3,3,3,3,1,3,1,3,1,1,3,3,3,3,3,3,3,3,3,3,1,3,3
3,3,1,3,3,3,3,3,3,3,1,1,1,3,1,1,3,3,3,3,3,3,3,3,3,3,1,3,3
3,3,1,3,3,3,3,3,3,3,1,1,1,1,3,1,3,3,3,3,3,3,3,3,3,3,1,3,3
3,3,1,3,3,3,3,3,3,3,1,1,3,1,3,1,3,3,3,3,3,3,3,3,3,3,1,1,1
3,3,1,3,3,3,3,3,3,3,1,3,1,3,1,1,3,3,3,3,3,3,3,3,3,3,1,3,1
3,3,1,3,3,3,3,3,3,3,1,1,1,1,3,1,3,3,3,3,3,3,3,3,3,3,1,3,3
3,3,1,3,3,3,3,3,3,3,1,3,1,1,1,1,3,3,3,3,3,3,3,3,3,3,1,3,3
3,3,1,1,1,1,1,1,1,1,1,3,1,1,3,1,1,1,1,1,1,1,1,1,1,1,1,3,3
3,3,3,3,3,3,3,3,3,3,3,1,3,3,3,3,3,3,3,3,3,3,3,3,3,3,3,3,3
3,3,3,3,3,1,1,1,3,3,3,1,3,1,1,3,3,3,3,3,3,3,3,3,3,3,3,3,3
:endlayer
layer: 5
0,0,0,0,0,0,0,0,0,0,0,0,0,0,0,0,0,0,0,0,0,0,0,0,0,0,0,0,0
0,0,0,0,0,0,0,0,0,0,0,0,0,0,0,0,0,0,0,0,0,0,0,0,0,10,0,0,0
0,0,1,1,1,1,1,1,1,1,1,1,1,1,1,1,1,1,1,1,1,1,1,1,0,0,0,0,0
0,0,1,0,0,1,0,0,1,41,37,0,0,37,36,1,23,30,28,25,25,24,22,1,0,0,8,0,0
0,0,1,47,0,1,0,43,1,0,37,0,0,37,0,1,19,0,29,26,26,0,0,1,18,1,1,0,0
0,0,1,44,44,1,44,44,1,42,1,37,37,1,0,1,33,31,0,0,0,0,0,0,0,11,1,0,0
0,0,0,0,0,0,0,0,0,0,0,0,0,0,0,1,33,31,0,0,19,23,23,19,0,11,1,1,0
0,0,0,0,0,0,0,0,0,0,0,0,0,0,0,1,24,0,0,0,19,23,23,19,0,11,1,5,0
0,0,0,0,0,0,0,0,0,0,0,0,0,0,0,1,1,1,1,1,19,23,23,19,0,12,1,6,0
0,0,0,0,46,0,0,0,0,0,0,0,0,0,0,0,0,0,0,27,0,0,0,20,0,13,1,1,0
0,0,1,1,1,45,45,45,1,1,1,0,0,0,0,0,0,0,0,27,0,0,0,0,0,14,1,1,0
0,0,1,16,17,16,1,16,17,16,1,0,0,0,0,0,34,0,0,1,1,1,21,21,1,1,1,7,0
0,0,1,16,17,16,1,16,17,16,1,0,0,38,0,0,0,0,0,0,0,0,0,0,0,0,0,0,0
0,0,1,16,17,16,1,16,17,16,1,0,0,0,0,0,0,0,0,0,0,0,0,0,0,0,0,0,0
0,0,1,16,17,16,1,16,17,16,1,0,0,0,0,0,0,32,0,0,0,0,0,0,0,15,0,0,0
0,0,1,16,17,16,2,16,17,16,1,0,0,0,0,0,0,0,0,0,0,0,0,0,0,0,0,0,0
0,0,1,16,17,16,1,16,17,16,1,0,0,0,0,1,1,1,1,1,1,1,1,1,1,1,1,0,0
0,0,1,16,17,16,1,16,17,16,1,0,0,0,0,1,16,16,16,16,16,16,16,16,16,16,1,0,0
0,0,1,16,17,16,1,16,17,16,1,0,0,0,0,1,17,17,17,17,17,17,17,17,17,17,1,0,0
0,0,1,16,17,16,2,16,17,16,1,0,0,0,0,35,16,16,16,16,16,16,16,16,16,16,9,0,0
0,0,1,16,17,16,1,16,17,16,1,0,0,39,0,35,1,1,2,1,1,1,1,2,1,1,9,0,0
0,0,1,16,17,16,1,16,17,16,1,0,0,0,0,35,16,16,16,16,16,16,16,16,16,16,9,0,0
0,0,1,16,17,16,1,16,17,16,1,0,0,0,0,1,17,17,17,17,17,17,17,17,17,17,1,0,0
0,0,1,16,17,16,1,16,17,16,1,40,0,0,0,1,16,16,16,16,16,16,16,16,16,16,1,0,0
0,0,1,1,1,7,7,7,1,1,1,0,0,0,0,1,1,1,1,1,1,1,1,1,1,1,1,0,0
0,0,0,0,0,0,0,0,0,0,0,0,0,0,0,0,0,0,0,0,0,0,0,0,0,0,0,0,0
0,0,0,0,0,0,0,0,0,0,0,0,0,0,0,0,0,0,0,0,0,0,0,0,0,0,0,0,0
:endlayer
layer: 6
0,0,0,0,0,0,0,0,0,0,0,0,0,0,0,0,0,0,0,0,0,0,0,0,0,0,0,0,0
0,0,0,0,0,0,0,0,0,0,0,0,0,0,0,0,0,0,0,0,0,0,0,0,0,0,0,0,0
0,0,1,1,1,1,1,1,1,1,1,1,1,1,1,1,49,1,1,1,49,1,1,1,0,0,0,0,0
0,0,1,0,0,1,0,0,1,0,0,0,0,0,0,49,0,0,0,0,0,53,0,49,0,0,0,0,0
0,0,1,0,0,1,0,0,1,0,0,0,0,0,0,1,0,0,0,0,0,0,0,1,52,1,1,0,0
0,0,1,0,0,1,0,0,1,0,49,0,0,49,0,49,0,0,0,0,0,0,0,0,0,48,1,0,0
0,0,0,0,0,0,0,0,0,0,0,0,0,0,0,1,0,0,0,0,0,0,0,0,0,0,1,1,0
0,0,0,0,0,0,0,0,0,0,0,0,0,0,0,49,53,0,0,0,0,0,0,0,0,0,1,0,0
0,0,0,0,0,0,0,0,0,0,0,0,0,0,0,1,49,1,49,1,0,0,0,0,0,0,1,0,0
0,0,0,0,0,0,0,0,0,0,0,0,0,0,0,0,0,0,0,52,0,0,0,0,0,0,1,1,0
0,0,37,0,37,0,0,0,37,0,37,0,0,0,0,0,0,0,0,54,0,0,0,0,0,0,1,7,0
0,0,0,0,51,50,0,50,51,0,0,0,0,0,0,0,34,0,0,1,49,1,52,54,1,49,1,0,0
0,0,0,0,51,50,0,0,51,50,0,0,0,0,0,0,0,0,0,0,0,0,0,0,0,0,0,0,0
0,0,37,0,51,50,0,0,51,50,37,0,0,0,0,0,0,0,0,0,0,0,0,0,0,0,0,0,0
0,0,0,50,51,0,53,0,51,50,0,0,0,0,0,0,0,0,0,0,0,0,0,0,0,0,0,0,0
0,0,0,0,51,50,55,0,51,50,0,0,0,0,0,0,0,0,0,0,0,0,0,0,0,0,0,0,0
0,0,37,50,51,0,53,50,51,0,37,0,0,0,0,37,0,0,37,0,0,0,0,37,0,0,37,0,0
0,0,0,0,51,50,0,50,51,0,0,0,0,0,0,0,0,50,0,50,50,50,50,50,0,50,0,0,0
0,0,37,50,51,0,53,50,51,0,37,0,0,0,0,37,51,51,51,51,51,51,51,51,51,51,37,0,0
0,0,0,0,51,50,55,0,51,50,0,0,0,0,0,0,50,0,50,0,0,0,0,0,50,0,0,0,0
0,0,0,0,51,50,53,0,51,50,0,0,0,0,0,0,0,53,55,53,0,0,53,55,53,0,0,0,0
0,0,37,50,51,0,0,50,51,0,37,0,0,0,0,0,50,0,0,0,0,0,50,0,50,0,0,0,0
0,0,0,50,51,0,0,0,51,50,0,0,0,0,0,37,51,51,51,51,51,51,51,51,51,51,37,0,0
0,0,0,0,51,50,0,50,51,0,0,0,0,0,0,0,0,50,50,50,50,50,0,50,0,50,0,0,0
0,0,37,0,37,0,0,0,37,0,37,0,0,0,0,37,0,0,37,0,0,0,0,37,0,0,37,0,0
0,0,0,0,0,0,0,0,0,0,0,0,0,0,0,0,0,0,0,0,0,0,0,0,0,0,0,0,0
0,0,0,0,0,0,0,0,0,0,0,0,0,0,0,0,0,0,0,0,0,0,0,0,0,0,0,0,0
:endlayer
layer: 7
0,0,0,0,0,0,0,0,0,0,0,0,0,0,0,0,0,0,0,0,0,0,0,0,0,0,0,0,0
0,0,0,0,0,0,0,0,0,0,0,0,0,0,0,0,0,0,0,0,0,0,0,57,0,0,0,0,0
0,0,1,1,1,1,1,1,1,49,1,1,1,1,49,1,49,1,1,1,49,1,49,1,0,0,0,0,0
0,0,1,0,0,1,0,0,1,0,0,0,0,0,0,49,0,0,0,0,0,0,0,49,0,0,0,0,0
0,0,1,0,0,1,0,0,1,0,0,0,0,0,0,1,0,0,0,0,0,0,0,1,1,1,1,0,0
0,0,1,0,0,1,0,0,1,0,49,0,0,49,0,49,0,0,0,0,0,0,0,0,0,0,1,0,0
0,0,0,0,0,0,0,0,0,0,0,0,0,0,0,1,0,0,0,0,0,0,0,0,0,0,1,1,0
0,0,0,0,0,0,0,0,0,0,0,0,0,0,0,49,0,0,0,0,0,0,0,0,0,0,1,56,0
0,0,0,0,0,0,0,0,0,0,0,0,0,0,0,1,49,1,49,1,0,0,0,0,0,0,1,56,0
0,0,0,0,0,0,0,0,0,0,0,0,0,0,0,0,0,0,0,1,0,0,0,0,0,0,1,7,0
0,0,0,0,0,0,0,0,0,0,0,0,0,0,0,0,0,0,0,1,0,0,0,0,0,0,1,0,0
0,0,0,0,0,0,0,0,0,0,0,0,0,0,0,0,34,0,0,1,49,1,1,1,1,49,1,0,0
0,0,0,0,0,0,0,0,0,0,0,0,0,0,0,0,0,0,0,0,0,0,0,0,0,0,0,0,0
0,0,0,0,0,0,0,0,0,0,0,0,0,0,0,0,0,0,0,0,0,0,0,0,0,0,0,0,0
0,0,0,0,0,0,0,0,0,0,0,0,0,0,0,0,0,0,0,0,0,0,0,0,0,0,0,0,0
0,0,0,0,0,0,0,0,0,0,0,0,0,0,0,0,0,0,0,0,0,0,0,0,0,0,0,0,0
0,0,0,0,0,0,0,0,0,0,0,0,0,0,0,0,0,0,0,0,0,0,0,0,0,0,0,0,0
0,0,0,0,0,0,0,0,0,0,0,0,0,0,0,0,0,0,0,0,0,0,0,0,0,0,0,0,0
0,0,0,0,0,0,0,0,0,0,0,0,0,0,0,0,0,0,0,0,0,0,0,0,0,0,0,0,0
0,0,0,0,0,0,0,0,0,0,0,0,0,0,0,0,0,0,0,0,0,0,0,0,0,0,0,0,0
0,0,0,0,0,0,0,0,0,0,0,0,0,0,0,0,0,0,0,0,0,0,0,0,0,0,0,0,0
0,0,0,0,0,0,0,0,0,0,0,0,0,0,0,0,0,0,0,0,0,0,0,0,0,0,0,0,0
0,0,0,0,0,0,0,0,0,0,0,0,0,0,0,0,0,0,0,0,0,0,0,0,0,0,0,0,0
0,0,0,0,0,0,0,0,0,0,0,0,0,0,0,0,0,0,0,0,0,0,0,0,0,0,0,0,0
0,0,0,0,0,0,0,0,0,0,0,0,0,0,0,0,0,0,0,0,0,0,0,0,0,0,0,0,0
0,0,0,0,0,0,0,0,0,0,0,0,0,0,0,0,0,0,0,0,0,0,0,0,0,0,0,0,0
0,0,0,0,0,0,0,0,0,0,0,0,0,0,0,0,0,0,0,0,0,0,0,0,0,0,0,0,0
:endlayer
layer: 8
0,0,0,0,0,0,0,0,0,0,0,0,0,0,0,0,0,0,0,0,0,0,0,0,0,0,0,0,0
0,0,57,0,0,0,0,0,0,0,57,0,0,0,0,0,0,0,0,0,0,0,0,0,0,0,0,0,0
0,0,61,61,61,61,61,61,61,61,61,61,61,61,61,1,1,1,1,1,1,1,1,1,0,0,0,0,0
0,0,61,37,37,61,37,37,61,0,37,62,62,37,0,1,0,0,0,59,0,0,0,1,0,0,0,0,0
0,0,61,37,37,61,37,37,61,0,37,62,62,37,0,1,0,0,0,0,0,0,60,1,1,1,1,58,0
0,0,61,49,49,61,49,49,61,0,37,37,37,37,0,1,58,0,0,0,0,0,0,59,0,0,1,0,0
0,0,59,0,0,59,0,0,59,0,0,0,0,0,0,1,0,0,0,0,0,0,0,0,0,60,1,1,0
0,0,0,0,0,0,0,0,0,0,0,0,0,0,0,1,0,0,0,57,0,0,0,0,0,0,1,1,0
0,0,0,0,0,0,0,0,0,0,0,0,0,0,60,1,1,1,1,1,58,0,0,0,0,0,1,7,0
0,0,0,0,0,0,0,0,0,0,0,0,0,0,0,59,0,0,0,1,0,0,0,0,0,60,1,0,0
0,0,0,0,0,0,0,0,0,0,0,0,0,0,0,0,0,0,0,1,0,57,0,0,57,0,1,0,0
0,0,0,0,0,0,0,0,0,0,0,0,0,0,0,0,0,0,60,1,1,1,1,1,1,1,1,0,0
0,0,0,0,0,0,0,0,0,0,0,0,0,0,0,0,34,0,0,59,0,0,0,0,0,0,59,0,0
0,0,0,0,0,0,0,0,0,0,0,0,0,0,0,0,0,0,0,0,0,0,0,0,0,0,0,0,0
0,0,0,0,0,0,0,0,0,0,0,0,0,0,0,0,0,0,0,0,0,0,0,0,0,0,0,0,0
0,0,0,0,0,0,0,0,0,0,0,0,0,0,0,0,0,0,0,0,0,0,0,0,0,0,0,0,0
0,0,0,0,0,0,0,0,0,0,0,0,0,0,0,0,0,0,0,0,0,0,0,0,0,0,0,0,0
0,0,0,0,0,0,0,0,0,0,0,0,0,0,0,0,0,0,0,0,0,0,0,0,0,0,0,0,0
0,0,0,0,0,0,0,0,0,0,0,0,0,0,0,0,0,0,0,0,0,0,0,0,0,0,0,0,0
0,0,0,0,0,0,0,0,0,0,0,0,0,0,0,0,0,0,0,0,0,0,0,0,0,0,0,0,0
0,0,0,0,0,0,0,0,0,0,0,0,0,0,0,0,0,0,0,0,0,0,0,0,0,0,0,0,0
0,0,0,0,0,0,0,0,0,0,0,0,0,0,0,0,0,0,0,0,0,0,0,0,0,0,0,0,0
0,0,0,0,0,0,0,0,0,0,0,0,0,0,0,0,0,0,0,0,0,0,0,0,0,0,0,0,0
0,0,0,0,0,0,0,0,0,0,0,0,0,0,0,0,0,0,0,0,0,0,0,0,0,0,0,0,0
0,0,0,0,0,0,0,0,0,0,0,0,0,0,0,0,0,0,0,0,0,0,0,0,0,0,0,0,0
0,0,0,0,0,0,0,0,0,0,0,0,0,0,0,0,0,0,0,0,0,0,0,0,0,0,0,0,0
0,0,0,0,0,0,0,0,0,0,0,0,0,0,0,0,0,0,0,0,0,0,0,0,0,0,0,0,0
:endlayer
layer: 9
0,0,0,0,0,0,0,0,0,0,0,0,0,0,0,0,0,0,0,0,0,0,0,0,0,0,0,0,0
0,0,0,0,0,0,0,0,0,0,0,0,0,0,0,62,64,62,62,62,62,62,64,62,0,0,0,0,0
0,0,1,55,55,55,55,55,55,55,55,55,55,55,67,63,63,63,63,63,63,63,63,63,62,0,0,0,0
0,0,0,0,0,0,0,0,0,0,0,0,0,0,66,63,1,1,1,1,1,1,1,63,62,64,62,0,0
0,0,0,0,0,0,0,0,0,0,0,0,0,0,62,63,1,1,1,1,1,1,1,63,63,63,63,0,0
0,0,55,0,0,55,0,0,55,0,0,0,0,0,62,63,1,1,1,1,1,1,1,1,1,1,63,0,0
0,0,0,0,0,0,0,0,0,0,0,0,0,0,62,63,1,1,1,1,1,1,1,1,1,1,63,1,0
0,0,0,0,0,0,0,0,0,0,0,0,0,0,66,63,1,1,1,1,1,1,1,1,1,1,63,7,0
0,0,0,0,0,0,0,0,0,0,0,0,0,0,62,63,63,63,63,63,1,1,1,1,1,1,63,0,0
0,0,0,0,0,0,0,0,0,0,0,0,0,0,0,62,65,62,62,63,1,1,1,1,1,1,63,0,0
0,0,0,0,0,0,0,0,0,0,0,0,0,0,0,0,0,0,66,63,1,1,1,1,1,1,63,0,0
0,0,0,0,0,0,0,0,0,0,0,0,0,0,0,0,0,0,62,63,63,63,63,63,63,63,63,0,0
0,0,0,0,0,0,0,0,0,0,0,0,0,0,0,0,34,0,0,62,65,62,0,0,62,65,62,0,0
0,0,0,0,0,0,0,0,0,0,0,0,0,0,0,0,0,0,0,0,0,0,0,0,0,0,0,0,0
0,0,0,0,0,0,0,0,0,0,0,0,0,0,0,0,0,0,0,0,0,0,0,0,0,0,0,0,0
0,0,0,0,0,0,0,0,0,0,0,0,0,0,0,0,0,0,0,0,0,0,0,0,0,0,0,0,0
0,0,0,0,0,0,0,0,0,0,0,0,0,0,0,0,0,0,0,0,0,0,0,0,0,0,0,0,0
0,0,0,0,0,0,0,0,0,0,0,0,0,0,0,0,0,0,0,0,0,0,0,0,0,0,0,0,0
0,0,0,0,0,0,0,0,0,0,0,0,0,0,0,0,0,0,0,0,0,0,0,0,0,0,0,0,0
0,0,0,0,0,0,0,0,0,0,0,0,0,0,0,0,0,0,0,0,0,0,0,0,0,0,0,0,0
0,0,0,0,0,0,0,0,0,0,0,0,0,0,0,0,0,0,0,0,0,0,0,0,0,0,0,0,0
0,0,0,0,0,0,0,0,0,0,0,0,0,0,0,0,0,0,0,0,0,0,0,0,0,0,0,0,0
0,0,0,0,0,0,0,0,0,0,0,0,0,0,0,0,0,0,0,0,0,0,0,0,0,0,0,0,0
0,0,0,0,0,0,0,0,0,0,0,0,0,0,0,0,0,0,0,0,0,0,0,0,0,0,0,0,0
0,0,0,0,0,0,0,0,0,0,0,0,0,0,0,0,0,0,0,0,0,0,0,0,0,0,0,0,0
0,0,0,0,0,0,0,0,0,0,0,0,0,0,0,0,0,0,0,0,0,0,0,0,0,0,0,0,0
0,0,0,0,0,0,0,0,0,0,0,0,0,0,0,0,0,0,0,0,0,0,0,0,0,0,0,0,0
:endlayer
layer: 10
0,0,0,0,0,0,0,0,0,0,0,0,0,0,0,0,0,0,0,0,0,0,0,0,0,0,0,0,0
0,0,0,0,0,0,0,0,0,0,0,0,0,0,0,0,0,0,0,0,0,0,0,0,0,0,0,0,0
0,0,0,0,0,0,0,0,0,0,0,0,0,0,0,1,55,55,55,55,55,55,55,1,0,0,0,0,0
0,0,0,0,0,0,0,0,0,0,0,0,0,0,0,55,49,0,0,0,71,0,49,55,0,0,0,0,0
0,0,0,0,0,0,0,0,0,0,0,0,0,0,0,55,0,72,23,23,72,0,0,1,55,55,1,0,0
0,0,0,0,0,0,0,0,0,0,0,0,0,0,0,55,73,72,23,23,72,69,0,0,0,0,55,0,0
0,0,0,0,0,0,0,0,0,0,0,0,0,0,0,55,0,72,23,23,72,0,0,0,0,0,55,0,0
0,0,0,0,0,0,0,0,0,0,0,0,0,0,0,55,49,0,0,0,0,0,49,0,0,68,55,0,0
0,0,0,0,0,0,0,0,0,0,0,0,0,0,0,1,55,55,55,1,0,0,0,0,0,0,55,0,0
0,0,0,0,0,0,0,0,0,0,0,0,0,0,0,0,0,0,0,55,0,0,0,0,0,0,55,0,0
0,0,0,0,0,0,0,0,0,0,0,0,0,0,0,0,0,0,0,55,0,70,0,0,0,0,55,0,0
0,0,0,0,0,0,0,0,0,0,0,0,0,0,0,0,0,0,0,1,55,55,55,55,55,55,1,0,0
0,0,0,0,0,0,0,0,0,0,0,0,0,0,0,0,34,0,0,0,0,0,37,37,0,0,0,0,0
0,0,0,0,0,0,0,0,0,0,0,0,0,0,0,0,0,0,0,0,0,0,0,0,0,0,0,0,0
0,0,0,0,0,0,0,0,0,0,0,0,0,0,0,0,0,0,0,0,0,0,0,0,0,0,0,0,0
0,0,0,0,0,0,0,0,0,0,0,0,0,0,0,0,0,0,0,0,0,0,0,0,0,0,0,0,0
0,0,0,0,0,0,0,0,0,0,0,0,0,0,0,0,0,0,0,0,0,0,0,0,0,0,0,0,0
0,0,0,0,0,0,0,0,0,0,0,0,0,0,0,0,0,0,0,0,0,0,0,0,0,0,0,0,0
0,0,0,0,0,0,0,0,0,0,0,0,0,0,0,0,0,0,0,0,0,0,0,0,0,0,0,0,0
0,0,0,0,0,0,0,0,0,0,0,0,0,0,0,0,0,0,0,0,0,0,0,0,0,0,0,0,0
0,0,0,0,0,0,0,0,0,0,0,0,0,0,0,0,0,0,0,0,0,0,0,0,0,0,0,0,0
0,0,0,0,0,0,0,0,0,0,0,0,0,0,0,0,0,0,0,0,0,0,0,0,0,0,0,0,0
0,0,0,0,0,0,0,0,0,0,0,0,0,0,0,0,0,0,0,0,0,0,0,0,0,0,0,0,0
0,0,0,0,0,0,0,0,0,0,0,0,0,0,0,0,0,0,0,0,0,0,0,0,0,0,0,0,0
0,0,0,0,0,0,0,0,0,0,0,0,0,0,0,0,0,0,0,0,0,0,0,0,0,0,0,0,0
0,0,0,0,0,0,0,0,0,0,0,0,0,0,0,0,0,0,0,0,0,0,0,0,0,0,0,0,0
0,0,0,0,0,0,0,0,0,0,0,0,0,0,0,0,0,0,0,0,0,0,0,0,0,0,0,0,0
:endlayer
layer: 11
0,0,0,0,0,0,0,0,0,0,0,0,0,0,0,0,0,0,0,0,0,0,0,0,0,0,0,0,0
0,0,0,0,0,0,0,0,0,0,0,0,0,0,0,0,0,0,0,0,0,0,0,0,0,0,0,0,0
0,0,0,0,0,0,0,0,0,0,0,0,0,0,0,53,0,0,0,0,0,0,0,53,0,0,0,0,0
0,0,0,0,0,0,0,0,0,0,0,0,0,0,0,0,49,0,0,0,0,0,49,0,0,0,0,0,0
0,0,0,0,0,0,0,0,0,0,0,0,0,0,0,0,0,0,0,0,0,0,0,53,0,0,53,0,0
0,0,0,0,0,0,0,0,0,0,0,0,0,0,0,0,0,0,0,0,0,0,0,0,0,0,0,0,0
0,0,0,0,0,0,0,0,0,0,0,0,0,0,0,0,0,0,0,0,0,0,0,0,0,0,0,0,0
0,0,0,0,0,0,0,0,0,0,0,0,0,0,0,0,49,0,0,0,0,0,49,0,0,0,0,0,0
0,0,0,0,0,0,0,0,0,0,0,0,0,0,0,53,0,0,0,53,0,0,0,0,0,0,0,0,0
0,0,0,0,0,0,0,0,0,0,0,0,0,0,0,0,0,0,0,0,0,0,0,0,0,0,0,0,0
0,0,0,0,0,0,0,0,0,0,0,0,0,0,0,0,0,0,0,0,0,0,0,0,0,0,0,0,0
0,0,0,0,0,0,0,0,0,0,0,0,0,0,0,0,0,0,0,53,0,0,0,0,0,0,53,0,0
0,0,0,0,0,0,0,0,0,0,0,0,0,0,0,34,0,0,0,0,0,0,0,0,0,0,0,0,0
0,0,0,0,0,0,0,0,0,0,0,0,0,0,0,0,0,0,0,0,0,0,0,0,0,0,0,0,0
0,0,0,0,0,0,0,0,0,0,0,0,0,0,0,0,0,0,0,0,0,0,0,0,0,0,0,0,0
0,0,0,0,0,0,0,0,0,0,0,0,0,0,0,0,0,0,0,0,0,0,0,0,0,0,0,0,0
0,0,0,0,0,0,0,0,0,0,0,0,0,0,0,0,0,0,0,0,0,0,0,0,0,0,0,0,0
0,0,0,0,0,0,0,0,0,0,0,0,0,0,0,0,0,0,0,0,0,0,0,0,0,0,0,0,0
0,0,0,0,0,0,0,0,0,0,0,0,0,0,0,0,0,0,0,0,0,0,0,0,0,0,0,0,0
0,0,0,0,0,0,0,0,0,0,0,0,0,0,0,0,0,0,0,0,0,0,0,0,0,0,0,0,0
0,0,0,0,0,0,0,0,0,0,0,0,0,0,0,0,0,0,0,0,0,0,0,0,0,0,0,0,0
0,0,0,0,0,0,0,0,0,0,0,0,0,0,0,0,0,0,0,0,0,0,0,0,0,0,0,0,0
0,0,0,0,0,0,0,0,0,0,0,0,0,0,0,0,0,0,0,0,0,0,0,0,0,0,0,0,0
0,0,0,0,0,0,0,0,0,0,0,0,0,0,0,0,0,0,0,0,0,0,0,0,0,0,0,0,0
0,0,0,0,0,0,0,0,0,0,0,0,0,0,0,0,0,0,0,0,0,0,0,0,0,0,0,0,0
0,0,0,0,0,0,0,0,0,0,0,0,0,0,0,0,0,0,0,0,0,0,0,0,0,0,0,0,0
0,0,0,0,0,0,0,0,0,0,0,0,0,0,0,0,0,0,0,0,0,0,0,0,0,0,0,0,0
:endlayer
layer: 12
0,0,0,0,0,0,0,0,0,0,0,0,0,0,0,0,0,0,0,0,0,0,0,0,0,0,0,0,0
0,0,0,0,0,0,0,0,0,0,0,0,0,0,0,0,0,0,0,0,0,0,0,0,0,0,0,0,0
0,0,0,0,0,0,0,0,0,0,0,0,0,0,0,0,0,0,0,0,0,0,0,0,0,0,0,0,0
0,0,0,0,0,0,0,0,0,0,0,0,0,0,0,0,49,0,0,0,0,0,49,0,0,0,0,0,0
0,0,0,0,0,0,0,0,0,0,0,0,0,0,0,0,0,0,0,0,0,0,0,0,0,0,0,0,0
0,0,0,0,0,0,0,0,0,0,0,0,0,0,0,0,0,0,0,0,0,0,0,0,0,0,0,0,0
0,0,0,0,0,0,0,0,0,0,0,0,0,0,0,0,0,0,0,0,0,0,0,0,0,0,0,0,0
0,0,0,0,0,0,0,0,0,0,0,0,0,0,0,0,49,0,0,0,0,0,49,0,0,0,0,0,0
0,0,0,0,0,0,0,0,0,0,0,0,0,0,0,0,0,0,0,0,0,0,0,0,0,0,0,0,0
0,0,0,0,0,0,0,0,0,0,0,0,0,0,0,0,0,0,0,0,0,0,0,0,0,0,0,0,0
0,0,0,0,0,0,0,0,0,0,0,0,0,0,0,0,0,0,0,0,0,0,0,0,0,0,0,0,0
0,0,0,0,0,0,0,0,0,0,0,0,0,0,0,0,0,0,0,0,0,0,0,0,0,0,0,0,0
0,0,0,0,0,0,0,0,0,0,0,0,0,0,0,34,0,0,0,0,0,0,0,0,0,0,0,0,0
0,0,0,0,0,0,0,0,0,0,0,0,0,0,0,0,0,0,0,0,0,0,0,0,0,0,0,0,0
0,0,0,0,0,0,0,0,0,0,0,0,0,0,0,0,0,0,0,0,0,0,0,0,0,0,0,0,0
0,0,0,0,0,0,0,0,0,0,0,0,0,0,0,0,0,0,0,0,0,0,0,0,0,0,0,0,0
0,0,0,0,0,0,0,0,0,0,0,0,0,0,0,0,0,0,0,0,0,0,0,0,0,0,0,0,0
0,0,0,0,0,0,0,0,0,0,0,0,0,0,0,0,0,0,0,0,0,0,0,0,0,0,0,0,0
0,0,0,0,0,0,0,0,0,0,0,0,0,0,0,0,0,0,0,0,0,0,0,0,0,0,0,0,0
0,0,0,0,0,0,0,0,0,0,0,0,0,0,0,0,0,0,0,0,0,0,0,0,0,0,0,0,0
0,0,0,0,0,0,0,0,0,0,0,0,0,0,0,0,0,0,0,0,0,0,0,0,0,0,0,0,0
0,0,0,0,0,0,0,0,0,0,0,0,0,0,0,0,0,0,0,0,0,0,0,0,0,0,0,0,0
0,0,0,0,0,0,0,0,0,0,0,0,0,0,0,0,0,0,0,0,0,0,0,0,0,0,0,0,0
0,0,0,0,0,0,0,0,0,0,0,0,0,0,0,0,0,0,0,0,0,0,0,0,0,0,0,0,0
0,0,0,0,0,0,0,0,0,0,0,0,0,0,0,0,0,0,0,0,0,0,0,0,0,0,0,0,0
0,0,0,0,0,0,0,0,0,0,0,0,0,0,0,0,0,0,0,0,0,0,0,0,0,0,0,0,0
0,0,0,0,0,0,0,0,0,0,0,0,0,0,0,0,0,0,0,0,0,0,0,0,0,0,0,0,0
:endlayer
layer: 13
0,0,0,0,0,0,0,0,0,0,0,0,0,0,0,0,0,0,0,0,0,0,0,0,0,0,0,0,0
0,0,0,0,0,0,0,0,0,0,0,0,0,0,0,0,0,0,0,0,0,0,0,0,0,0,0,0,0
0,0,0,0,0,0,0,0,0,0,0,0,0,0,0,0,0,0,0,0,0,0,0,0,0,0,0,0,0
0,0,0,0,0,0,0,0,0,0,0,0,0,0,0,0,74,74,74,74,74,74,74,0,0,0,0,0,0
0,0,0,0,0,0,0,0,0,0,0,0,0,0,0,0,74,75,76,75,76,75,74,0,0,0,0,0,0
0,0,0,0,0,0,0,0,0,0,0,0,0,0,0,0,74,75,76,75,76,75,74,0,0,0,0,0,0
0,0,0,0,0,0,0,0,0,0,0,0,0,0,0,0,74,75,76,75,76,75,74,0,0,0,0,0,0
0,0,0,0,0,0,0,0,0,0,0,0,0,0,0,0,74,74,74,74,74,74,74,0,0,0,0,0,0
0,0,0,0,0,0,0,0,0,0,0,0,0,0,0,77,0,0,0,0,0,0,0,0,0,0,0,0,0
0,0,0,0,0,0,0,0,0,0,0,0,78,0,0,77,0,0,78,0,0,0,0,0,0,0,0,0,0
0,0,0,0,0,0,0,0,0,0,0,0,0,78,0,0,0,78,0,0,0,0,0,0,0,0,0,0,0
0,0,0,0,0,0,0,0,0,0,0,0,0,0,0,0,0,0,0,0,0,0,0,0,0,0,0,0,0
0,0,0,0,0,0,0,0,0,0,0,77,78,0,0,34,0,0,78,77,0,0,0,0,0,0,0,0,0
0,0,0,0,0,0,0,0,0,0,0,0,0,0,0,0,0,0,0,0,0,0,0,0,0,0,0,0,0
0,0,0,0,0,0,0,0,0,0,0,0,0,78,0,0,0,78,0,0,0,0,0,0,0,0,0,0,0
0,0,0,0,0,0,0,0,0,0,0,0,78,0,0,77,0,0,78,0,0,0,0,0,0,0,0,0,0
0,0,0,0,0,0,0,0,0,0,0,0,0,0,0,77,0,0,0,0,0,0,0,0,0,0,0,0,0
0,0,0,0,0,0,0,0,0,0,0,0,0,0,0,0,0,0,0,0,0,0,0,0,0,0,0,0,0
0,0,0,0,0,0,0,0,0,0,0,0,0,0,0,0,0,0,0,0,0,0,0,0,0,0,0,0,0
0,0,0,0,0,0,0,0,0,0,0,0,0,0,0,0,0,0,0,0,0,0,0,0,0,0,0,0,0
0,0,0,0,0,0,0,0,0,0,0,0,0,0,0,0,0,0,0,0,0,0,0,0,0,0,0,0,0
0,0,0,0,0,0,0,0,0,0,0,0,0,0,0,0,0,0,0,0,0,0,0,0,0,0,0,0,0
0,0,0,0,0,0,0,0,0,0,0,0,0,0,0,0,0,0,0,0,0,0,0,0,0,0,0,0,0
0,0,0,0,0,0,0,0,0,0,0,0,0,0,0,0,0,0,0,0,0,0,0,0,0,0,0,0,0
0,0,0,0,0,0,0,0,0,0,0,0,0,0,0,0,0,0,0,0,0,0,0,0,0,0,0,0,0
0,0,0,0,0,0,0,0,0,0,0,0,0,0,0,0,0,0,0,0,0,0,0,0,0,0,0,0,0
0,0,0,0,0,0,0,0,0,0,0,0,0,0,0,0,0,0,0,0,0,0,0,0,0,0,0,0,0
:endlayer
layer: 14
0,0,0,0,0,0,0,0,0,0,0,0,0,0,0,0,0,0,0,0,0,0,0,0,0,0,0,0,0
0,0,0,0,0,0,0,0,0,0,0,0,0,0,0,0,0,0,0,0,0,0,0,0,0,0,0,0,0
0,0,0,0,0,0,0,0,0,0,0,0,0,0,0,0,0,0,0,0,0,0,0,0,0,0,0,0,0
0,0,0,0,0,0,0,0,0,0,0,0,0,0,0,0,0,0,0,0,0,0,0,0,0,0,0,0,0
0,0,0,0,0,0,0,0,0,0,0,0,0,0,0,0,0,0,0,0,0,0,0,0,0,0,0,0,0
0,0,0,0,0,0,0,0,0,0,0,0,0,0,0,0,0,0,0,0,0,0,0,0,0,0,0,0,0
0,0,0,0,0,0,0,0,0,0,0,0,0,0,0,0,0,0,0,0,0,0,0,0,0,0,0,0,0
0,0,0,0,0,0,0,0,0,0,0,0,0,0,0,0,0,0,0,0,0,0,0,0,0,0,0,0,0
0,0,0,0,0,0,0,0,0,0,0,0,0,0,0,0,0,0,0,0,0,0,0,0,0,0,0,0,0
0,0,0,0,0,0,0,0,0,0,0,0,0,0,0,77,0,0,0,0,0,0,0,0,0,0,0,0,0
0,0,0,0,0,0,0,0,0,0,0,0,0,78,0,78,0,78,0,0,0,0,0,0,0,0,0,0,0
0,0,0,0,0,0,0,0,0,0,0,0,0,0,78,78,78,0,0,0,0,0,0,0,0,0,0,0,0
0,0,0,0,0,0,0,0,0,0,0,0,78,78,78,78,78,78,78,0,0,0,0,0,0,0,0,0,0
0,0,0,0,0,0,0,0,0,0,0,0,0,0,78,77,78,0,0,0,0,0,0,0,0,0,0,0,0
0,0,0,0,0,0,0,0,0,0,0,0,0,78,0,77,0,78,0,0,0,0,0,0,0,0,0,0,0
0,0,0,0,0,0,0,0,0,0,0,0,0,0,0,77,0,0,0,0,0,0,0,0,0,0,0,0,0
0,0,0,0,0,0,0,0,0,0,0,0,0,0,0,0,0,0,0,0,0,0,0,0,0,0,0,0,0
0,0,0,0,0,0,0,0,0,0,0,0,0,0,0,0,0,0,0,0,0,0,0,0,0,0,0,0,0
0,0,0,0,0,0,0,0,0,0,0,0,0,0,0,0,0,0,0,0,0,0,0,0,0,0,0,0,0
0,0,0,0,0,0,0,0,0,0,0,0,0,0,0,0,0,0,0,0,0,0,0,0,0,0,0,0,0
0,0,0,0,0,0,0,0,0,0,0,0,0,0,0,0,0,0,0,0,0,0,0,0,0,0,0,0,0
0,0,0,0,0,0,0,0,0,0,0,0,0,0,0,0,0,0,0,0,0,0,0,0,0,0,0,0,0
0,0,0,0,0,0,0,0,0,0,0,0,0,0,0,0,0,0,0,0,0,0,0,0,0,0,0,0,0
0,0,0,0,0,0,0,0,0,0,0,0,0,0,0,0,0,0,0,0,0,0,0,0,0,0,0,0,0
0,0,0,0,0,0,0,0,0,0,0,0,0,0,0,0,0,0,0,0,0,0,0,0,0,0,0,0,0
0,0,0,0,0,0,0,0,0,0,0,0,0,0,0,0,0,0,0,0,0,0,0,0,0,0,0,0,0
0,0,0,0,0,0,0,0,0,0,0,0,0,0,0,0,0,0,0,0,0,0,0,0,0,0,0,0,0
:endlayer
layer: 15
0,0,0,0,0,0,0,0,0,0,0,0,0,0,0,0,0,0,0,0,0,0,0,0,0,0,0,0,0
0,0,0,0,0,0,0,0,0,0,0,0,0,0,0,0,0,0,0,0,0,0,0,0,0,0,0,0,0
0,0,0,0,0,0,0,0,0,0,0,0,0,0,0,0,0,0,0,0,0,0,0,0,0,0,0,0,0
0,0,0,0,0,0,0,0,0,0,0,0,0,0,0,0,0,0,0,0,0,0,0,0,0,0,0,0,0
0,0,0,0,0,0,0,0,0,0,0,0,0,0,0,0,0,0,0,0,0,0,0,0,0,0,0,0,0
0,0,0,0,0,0,0,0,0,0,0,0,0,0,0,0,0,0,0,0,0,0,0,0,0,0,0,0,0
0,0,0,0,0,0,0,0,0,0,0,0,0,0,0,0,0,0,0,0,0,0,0,0,0,0,0,0,0
0,0,0,0,0,0,0,0,0,0,0,0,0,0,0,0,0,0,0,0,0,0,0,0,0,0,0,0,0
0,0,0,0,0,0,0,0,0,0,0,0,0,0,0,0,0,0,0,0,0,0,0,0,0,0,0,0,0
0,0,0,0,0,0,0,0,0,0,0,0,0,0,0,0,0,0,0,0,0,0,0,0,0,0,0,0,0
0,0,0,0,0,0,0,0,0,0,0,0,0,0,0,0,0,0,0,0,0,0,0,0,0,0,0,0,0
0,0,0,0,0,0,0,0,0,0,0,0,0,0,0,0,0,0,0,0,0,0,0,0,0,0,0,0,0
0,0,0,0,0,0,0,0,0,0,0,0,0,0,0,77,0,0,0,0,0,0,0,0,0,0,0,0,0
0,0,0,0,0,0,0,0,0,0,0,0,0,0,0,0,0,0,0,0,0,0,0,0,0,0,0,0,0
0,0,0,0,0,0,0,0,0,0,0,0,0,0,0,0,0,0,0,0,0,0,0,0,0,0,0,0,0
0,0,0,0,0,0,0,0,0,0,0,0,0,0,0,0,0,0,0,0,0,0,0,0,0,0,0,0,0
0,0,0,0,0,0,0,0,0,0,0,0,0,0,0,0,0,0,0,0,0,0,0,0,0,0,0,0,0
0,0,0,0,0,0,0,0,0,0,0,0,0,0,0,0,0,0,0,0,0,0,0,0,0,0,0,0,0
0,0,0,0,0,0,0,0,0,0,0,0,0,0,0,0,0,0,0,0,0,0,0,0,0,0,0,0,0
0,0,0,0,0,0,0,0,0,0,0,0,0,0,0,0,0,0,0,0,0,0,0,0,0,0,0,0,0
0,0,0,0,0,0,0,0,0,0,0,0,0,0,0,0,0,0,0,0,0,0,0,0,0,0,0,0,0
0,0,0,0,0,0,0,0,0,0,0,0,0,0,0,0,0,0,0,0,0,0,0,0,0,0,0,0,0
0,0,0,0,0,0,0,0,0,0,0,0,0,0,0,0,0,0,0,0,0,0,0,0,0,0,0,0,0
0,0,0,0,0,0,0,0,0,0,0,0,0,0,0,0,0,0,0,0,0,0,0,0,0,0,0,0,0
0,0,0,0,0,0,0,0,0,0,0,0,0,0,0,0,0,0,0,0,0,0,0,0,0,0,0,0,0
0,0,0,0,0,0,0,0,0,0,0,0,0,0,0,0,0,0,0,0,0,0,0,0,0,0,0,0,0
0,0,0,0,0,0,0,0,0,0,0,0,0,0,0,0,0,0,0,0,0,0,0,0,0,0,0,0,0
:endlayer

#### RULES ####
rule:
plugin=vanillaBlocks
number=1
data:
JSON:{blockState:{blockName:"minecraft:sandstone",properties:{type:"sandstone"}}}
:enddata
:endrule

rule:
plugin=fluid
number=2
data:
JSON:{blockState:{blockName:"minecraft:water",properties:{level:"0"}}}
:enddata
:endrule

rule:
plugin=vanillaBlocks
number=3
data:
JSON:{blockState:{blockName:"minecraft:sand",properties:{variant:"sand"}}}
:enddata
:endrule

rule:
plugin=vanillaBlocks
number=4
data:
JSON:{blockState:{blockName:"minecraft:dirt",properties:{variant:"coarse_dirt",snowy:"false"}}}
:enddata
:endrule

rule:
plugin=blockTile
number=5
data:
JSON:{blockState:{blockName:"ancientwarfarestructure:advanced_loot_chest",properties:{facing:"east"}},teData:{lootSettings:{lootRolls:1,splashPotion:0b,hasMessage:0b,hasLoot:1b,lootTableName:"ancientwarfare:chests/village_farm_melon",spawnEntity:0b,entity:"minecraft:"},Items:[],id:"ancientwarfarestructure:advanced_loot_chest_tile",Lock:""}}
:enddata
:endrule

rule:
plugin=blockTile
number=6
data:
JSON:{blockState:{blockName:"ancientwarfarestructure:advanced_loot_chest",properties:{facing:"east"}},teData:{lootSettings:{lootRolls:1,splashPotion:0b,hasMessage:0b,hasLoot:1b,lootTableName:"ancientwarfare:chests/village_farm_melon",spawnEntity:0b,entity:"minecraft:"},Items:[],id:"ancientwarfarestructure:advanced_loot_chest_tile",Lock:""}}
:enddata
:endrule

rule:
plugin=vanillaBlocks
number=7
data:
JSON:{blockState:{blockName:"minecraft:sandstone_stairs",properties:{half:"bottom",shape:"straight",facing:"north"}}}
:enddata
:endrule

rule:
plugin=blockTile
number=8
data:
JSON:{blockState:{blockName:"ancientwarfarestructure:advanced_spawner",properties:{transparent:"true"}},teData:{id:"ancientwarfarestructure:advanced_spawner_tile",spawnerSettings:{minDelay:10,spawnDelay:6,lightSensitive:0b,spawnGroups:[{settingsList:[{remainingSpawnCount:1,hostile:1b,customTag:{ArmorDropChances:[0.085f,0.085f,0.085f,0.085f],hasCustomEquipment:0b,ArmorItems:[{},{},{},{}],skinSettings:{npcTypeName:"custom",skinTypeSelected:"default"},HandDropChances:[0.085f,0.085f],factionName:"sarkonid",HandItems:[{id:"ancientwarfarenpc:golden_spear",Count:1b,Damage:0s},{id:"ancientwarfarenpc:gold_shield",Count:1b,Damage:0s}]},maxToSpawn:1,entityId:"ancientwarfarenpc:faction.soldier",minToSpawn:1}],groupWeight:1}],playerRange:16,respondToRedstone:0b,inventory:{Size:9,Items:[]},spawnRange:0,transparent:1b,maxDelay:10,spawnYOffset:0,xpToDrop:0,mobRange:0,debugMode:0b,maxNearbyMonsters:0}}}
:enddata
:endrule

rule:
plugin=vanillaBlocks
number=9
data:
JSON:{blockState:{blockName:"minecraft:sandstone_stairs",properties:{half:"bottom",shape:"straight",facing:"west"}}}
:enddata
:endrule

rule:
plugin=blockTile
number=10
data:
JSON:{blockState:{blockName:"ancientwarfarestructure:advanced_spawner",properties:{transparent:"true"}},teData:{id:"ancientwarfarestructure:advanced_spawner_tile",spawnerSettings:{minDelay:10,spawnDelay:3,lightSensitive:0b,spawnGroups:[{settingsList:[{remainingSpawnCount:1,hostile:1b,customTag:{ArmorDropChances:[0.085f,0.085f,0.085f,0.085f],hasCustomEquipment:0b,ArmorItems:[{},{},{},{}],skinSettings:{npcTypeName:"custom",skinTypeSelected:"default"},HandDropChances:[0.085f,0.085f],factionName:"sarkonid",HandItems:[{id:"ancientwarfarenpc:golden_lance",Count:1b,Damage:0s},{}]},maxToSpawn:1,entityId:"ancientwarfarenpc:faction.cavalry",minToSpawn:1}],groupWeight:1}],playerRange:16,respondToRedstone:0b,inventory:{Size:9,Items:[]},spawnRange:0,transparent:1b,maxDelay:10,spawnYOffset:0,xpToDrop:0,mobRange:0,debugMode:0b,maxNearbyMonsters:0}}}
:enddata
:endrule

rule:
plugin=vanillaBlocks
number=11
data:
JSON:{blockState:{blockName:"minecraft:stone",properties:{variant:"smooth_andesite"}}}
:enddata
:endrule

rule:
plugin=inventory
number=12
data:
JSON:{blockState:{blockName:"minecraft:furnace",properties:{facing:"west"}},lootLevel:0,teData:{CookTime:0,BurnTime:0,Items:[],id:"minecraft:furnace",CookTimeTotal:0,Lock:""},inventoryData:{length:0,inventoryContents:[]},legacyFeatures:0b}
:enddata
:endrule

rule:
plugin=inventory
number=13
data:
JSON:{blockState:{blockName:"minecraft:furnace",properties:{facing:"west"}},lootLevel:0,teData:{CookTime:0,BurnTime:0,Items:[],id:"minecraft:furnace",CookTimeTotal:0,Lock:""},inventoryData:{length:0,inventoryContents:[]},legacyFeatures:0b}
:enddata
:endrule

rule:
plugin=inventory
number=14
data:
JSON:{blockState:{blockName:"minecraft:furnace",properties:{facing:"west"}},lootLevel:0,teData:{CookTime:0,BurnTime:0,Items:[],id:"minecraft:furnace",CookTimeTotal:0,Lock:""},inventoryData:{length:0,inventoryContents:[]},legacyFeatures:0b}
:enddata
:endrule

rule:
plugin=blockTile
number=15
data:
JSON:{blockState:{blockName:"ancientwarfarestructure:advanced_spawner",properties:{transparent:"true"}},teData:{id:"ancientwarfarestructure:advanced_spawner_tile",spawnerSettings:{minDelay:10,spawnDelay:7,lightSensitive:0b,spawnGroups:[{settingsList:[{remainingSpawnCount:1,hostile:1b,customTag:{ArmorDropChances:[0.085f,0.085f,0.085f,0.085f],hasCustomEquipment:0b,ArmorItems:[{},{},{},{}],skinSettings:{npcTypeName:"custom",skinTypeSelected:"default"},HandDropChances:[0.085f,0.085f],factionName:"sarkonid",HandItems:[{id:"ancientwarfarenpc:golden_spear",Count:1b,Damage:0s},{id:"ancientwarfarenpc:gold_shield",Count:1b,Damage:0s}]},maxToSpawn:1,entityId:"ancientwarfarenpc:faction.soldier",minToSpawn:1}],groupWeight:1}],playerRange:16,respondToRedstone:0b,inventory:{Size:9,Items:[]},spawnRange:0,transparent:1b,maxDelay:10,spawnYOffset:0,xpToDrop:0,mobRange:0,debugMode:0b,maxNearbyMonsters:0}}}
:enddata
:endrule

rule:
plugin=vanillaBlocks
number=16
data:
JSON:{blockState:{blockName:"minecraft:dirt",properties:{variant:"dirt",snowy:"false"}}}
:enddata
:endrule

rule:
plugin=vanillaBlocks
number=17
data:
JSON:{blockState:{blockName:"minecraft:farmland",properties:{moisture:"7"}}}
:enddata
:endrule

rule:
plugin=doors
number=18
data:
JSON:{blockState:{blockName:"minecraft:spruce_door",properties:{hinge:"left",half:"lower",powered:"false",facing:"south",open:"false"}}}
:enddata
:endrule

rule:
plugin=vanillaBlocks
number=19
data:
JSON:{blockState:{blockName:"ancientwarfarestructure:stool",properties:{variant:"oak"}}}
:enddata
:endrule

rule:
plugin=blockTile
number=20
data:
JSON:{blockState:{blockName:"ancientwarfarestructure:advanced_spawner",properties:{transparent:"true"}},teData:{id:"ancientwarfarestructure:advanced_spawner_tile",spawnerSettings:{minDelay:10,spawnDelay:2,lightSensitive:0b,spawnGroups:[{settingsList:[{remainingSpawnCount:1,hostile:1b,customTag:{ArmorDropChances:[0.085f,0.085f,0.085f,0.085f],hasCustomEquipment:0b,ArmorItems:[{},{},{},{}],skinSettings:{npcTypeName:"custom",skinTypeSelected:"default"},HandDropChances:[0.085f,0.085f],factionName:"sarkonid",HandItems:[{},{}]},maxToSpawn:1,entityId:"ancientwarfarenpc:faction.civilian.female",minToSpawn:1}],groupWeight:1}],playerRange:16,respondToRedstone:0b,inventory:{Size:9,Items:[]},spawnRange:0,transparent:1b,maxDelay:10,spawnYOffset:0,xpToDrop:0,mobRange:0,debugMode:0b,maxNearbyMonsters:0}}}
:enddata
:endrule

rule:
plugin=doors
number=21
data:
JSON:{blockState:{blockName:"minecraft:spruce_door",properties:{hinge:"left",half:"lower",powered:"false",facing:"north",open:"false"}}}
:enddata
:endrule

rule:
plugin=blockTile
number=22
data:
JSON:{blockState:{blockName:"ancientwarfarestructure:advanced_loot_chest",properties:{facing:"south"}},teData:{lootSettings:{lootRolls:1,splashPotion:0b,hasMessage:0b,hasLoot:1b,lootTableName:"ancientwarfare:chests/sarkonid",spawnEntity:0b,entity:"minecraft:"},Items:[],id:"ancientwarfarestructure:advanced_loot_chest_tile",Lock:""}}
:enddata
:endrule

rule:
plugin=vanillaBlocks
number=23
data:
JSON:{blockState:{blockName:"ancientwarfarestructure:table",properties:{leg_southwest:"true",leg_northwest:"true",variant:"oak",leg_northeast:"true",leg_southeast:"true"}}}
:enddata
:endrule

rule:
plugin=vanillaBlocks
number=24
data:
JSON:{blockState:{blockName:"minecraft:crafting_table"}}
:enddata
:endrule

rule:
plugin=bed
number=25
data:
JSON:{blockState:{blockName:"minecraft:bed",properties:{part:"head",facing:"north",occupied:"false"}},bedColor:13}
:enddata
:endrule

rule:
plugin=bed
number=26
data:
JSON:{blockState:{blockName:"minecraft:bed",properties:{part:"foot",facing:"north",occupied:"false"}},bedColor:13}
:enddata
:endrule

rule:
plugin=doors
number=27
data:
JSON:{blockState:{blockName:"minecraft:spruce_door",properties:{hinge:"left",half:"lower",powered:"false",facing:"east",open:"false"}}}
:enddata
:endrule

rule:
plugin=blockTile
number=28
data:
JSON:{blockState:{blockName:"ancientwarfarestructure:advanced_loot_chest",properties:{facing:"south"}},teData:{lootSettings:{lootRolls:1,splashPotion:0b,hasMessage:0b,hasLoot:1b,lootTableName:"ancientwarfare:chests/village_farm_melon",spawnEntity:0b,entity:"minecraft:"},Items:[],id:"ancientwarfarestructure:advanced_loot_chest_tile",Lock:""}}
:enddata
:endrule

rule:
plugin=blockTile
number=29
data:
JSON:{blockState:{blockName:"ancientwarfarestructure:advanced_spawner",properties:{transparent:"true"}},teData:{id:"ancientwarfarestructure:advanced_spawner_tile",spawnerSettings:{minDelay:10,spawnDelay:10,lightSensitive:0b,spawnGroups:[{settingsList:[{remainingSpawnCount:1,hostile:1b,customTag:{ArmorDropChances:[0.085f,0.085f,0.085f,0.085f],hasCustomEquipment:0b,ArmorItems:[{},{},{},{}],skinSettings:{npcTypeName:"custom",skinTypeSelected:"default"},HandDropChances:[0.085f,0.085f],factionName:"sarkonid",HandItems:[{},{}]},maxToSpawn:1,entityId:"ancientwarfarenpc:faction.civilian.male",minToSpawn:1}],groupWeight:1}],playerRange:16,respondToRedstone:0b,inventory:{Size:9,Items:[]},spawnRange:0,transparent:1b,maxDelay:10,spawnYOffset:0,xpToDrop:0,mobRange:0,debugMode:0b,maxNearbyMonsters:0}}}
:enddata
:endrule

rule:
plugin=blockTile
number=30
data:
JSON:{blockState:{blockName:"ancientwarfarestructure:advanced_loot_chest",properties:{facing:"south"}},teData:{lootSettings:{lootRolls:1,splashPotion:0b,hasMessage:0b,hasLoot:1b,lootTableName:"ancientwarfare:chests/village_farm_melon",spawnEntity:0b,entity:"minecraft:"},Items:[],id:"ancientwarfarestructure:advanced_loot_chest_tile",Lock:""}}
:enddata
:endrule

rule:
plugin=bed
number=31
data:
JSON:{blockState:{blockName:"minecraft:bed",properties:{part:"foot",facing:"west",occupied:"false"}},bedColor:13}
:enddata
:endrule

rule:
plugin=blockTile
number=32
data:
JSON:{blockState:{blockName:"ancientwarfarestructure:advanced_spawner",properties:{transparent:"true"}},teData:{id:"ancientwarfarestructure:advanced_spawner_tile",spawnerSettings:{minDelay:10,spawnDelay:4,lightSensitive:0b,spawnGroups:[{settingsList:[{remainingSpawnCount:1,hostile:1b,customTag:{ArmorDropChances:[0.085f,0.085f,0.085f,0.085f],hasCustomEquipment:0b,ArmorItems:[{},{},{},{}],skinSettings:{npcTypeName:"custom",skinTypeSelected:"default"},HandDropChances:[0.085f,0.085f],factionName:"sarkonid",HandItems:[{},{}]},maxToSpawn:1,entityId:"ancientwarfarenpc:faction.civilian.male",minToSpawn:1}],groupWeight:1}],playerRange:16,respondToRedstone:0b,inventory:{Size:9,Items:[]},spawnRange:0,transparent:1b,maxDelay:10,spawnYOffset:0,xpToDrop:0,mobRange:0,debugMode:0b,maxNearbyMonsters:0}}}
:enddata
:endrule

rule:
plugin=bed
number=33
data:
JSON:{blockState:{blockName:"minecraft:bed",properties:{part:"head",facing:"west",occupied:"false"}},bedColor:13}
:enddata
:endrule

rule:
plugin=vanillaBlocks
number=34
data:
JSON:{blockState:{blockName:"minecraft:log",properties:{variant:"jungle",axis:"y"}}}
:enddata
:endrule

rule:
plugin=vanillaBlocks
number=35
data:
JSON:{blockState:{blockName:"minecraft:sandstone_stairs",properties:{half:"bottom",shape:"straight",facing:"east"}}}
:enddata
:endrule

rule:
plugin=blockTile
number=36
data:
JSON:{blockState:{blockName:"ancientwarfarestructure:advanced_loot_chest",properties:{facing:"south"}},teData:{lootSettings:{lootRolls:1,splashPotion:0b,hasMessage:0b,hasLoot:1b,lootTableName:"ancientwarfare:chests/village_farm_melon",spawnEntity:0b,entity:"minecraft:"},Items:[],id:"ancientwarfarestructure:advanced_loot_chest_tile",Lock:""}}
:enddata
:endrule

rule:
plugin=vanillaBlocks
number=37
data:
JSON:{blockState:{blockName:"minecraft:stone_slab2",properties:{half:"bottom",variant:"red_sandstone"}}}
:enddata
:endrule

rule:
plugin=blockTile
number=38
data:
JSON:{blockState:{blockName:"ancientwarfarestructure:advanced_spawner",properties:{transparent:"true"}},teData:{id:"ancientwarfarestructure:advanced_spawner_tile",spawnerSettings:{minDelay:10,spawnDelay:4,lightSensitive:0b,spawnGroups:[{settingsList:[{remainingSpawnCount:1,hostile:1b,customTag:{ArmorDropChances:[0.085f,0.085f,0.085f,0.085f],hasCustomEquipment:0b,ArmorItems:[{},{},{},{}],skinSettings:{npcTypeName:"custom",skinTypeSelected:"default"},HandDropChances:[0.085f,0.085f],factionName:"sarkonid",HandItems:[{id:"ancientwarfarenpc:golden_lance",Count:1b,Damage:0s},{}]},maxToSpawn:1,entityId:"ancientwarfarenpc:faction.cavalry",minToSpawn:1}],groupWeight:1}],playerRange:16,respondToRedstone:0b,inventory:{Size:9,Items:[]},spawnRange:0,transparent:1b,maxDelay:10,spawnYOffset:0,xpToDrop:0,mobRange:0,debugMode:0b,maxNearbyMonsters:0}}}
:enddata
:endrule

rule:
plugin=blockTile
number=39
data:
JSON:{blockState:{blockName:"ancientwarfarestructure:advanced_spawner",properties:{transparent:"true"}},teData:{id:"ancientwarfarestructure:advanced_spawner_tile",spawnerSettings:{minDelay:10,spawnDelay:1,lightSensitive:0b,spawnGroups:[{settingsList:[{remainingSpawnCount:1,hostile:1b,customTag:{ArmorDropChances:[0.085f,0.085f,0.085f,0.085f],hasCustomEquipment:0b,ArmorItems:[{},{},{},{}],skinSettings:{npcTypeName:"custom",skinTypeSelected:"default"},HandDropChances:[0.085f,0.085f],factionName:"sarkonid",HandItems:[{id:"minecraft:bow",Count:1b,Damage:0s},{}]},maxToSpawn:1,entityId:"ancientwarfarenpc:faction.mounted_archer",minToSpawn:1}],groupWeight:1}],playerRange:32,respondToRedstone:0b,inventory:{Size:9,Items:[]},spawnRange:0,transparent:1b,maxDelay:10,spawnYOffset:0,xpToDrop:0,mobRange:0,debugMode:0b,maxNearbyMonsters:0}}}
:enddata
:endrule

rule:
plugin=blockTile
number=40
data:
JSON:{blockState:{blockName:"ancientwarfarestructure:advanced_spawner",properties:{transparent:"true"}},teData:{id:"ancientwarfarestructure:advanced_spawner_tile",spawnerSettings:{minDelay:10,spawnDelay:3,lightSensitive:0b,spawnGroups:[{settingsList:[{remainingSpawnCount:1,hostile:1b,customTag:{ArmorDropChances:[0.085f,0.085f,0.085f,0.085f],hasCustomEquipment:0b,ArmorItems:[{},{},{},{}],skinSettings:{npcTypeName:"custom",skinTypeSelected:"default"},HandDropChances:[0.085f,0.085f],factionName:"sarkonid",HandItems:[{id:"ancientwarfarenpc:golden_spear",Count:1b,Damage:0s},{id:"ancientwarfarenpc:gold_shield",Count:1b,Damage:0s}]},maxToSpawn:1,entityId:"ancientwarfarenpc:faction.soldier",minToSpawn:1}],groupWeight:1}],playerRange:16,respondToRedstone:0b,inventory:{Size:9,Items:[]},spawnRange:0,transparent:1b,maxDelay:10,spawnYOffset:0,xpToDrop:0,mobRange:0,debugMode:0b,maxNearbyMonsters:0}}}
:enddata
:endrule

rule:
plugin=blockTile
number=41
data:
JSON:{blockState:{blockName:"ancientwarfarestructure:advanced_loot_chest",properties:{facing:"south"}},teData:{lootSettings:{lootRolls:1,splashPotion:0b,hasMessage:0b,hasLoot:1b,lootTableName:"ancientwarfare:chests/village_farm_melon",spawnEntity:0b,entity:"minecraft:"},Items:[],id:"ancientwarfarestructure:advanced_loot_chest_tile",Lock:""}}
:enddata
:endrule

rule:
plugin=blockTile
number=42
data:
JSON:{blockState:{blockName:"ancientwarfarestructure:advanced_spawner",properties:{transparent:"true"}},teData:{id:"ancientwarfarestructure:advanced_spawner_tile",spawnerSettings:{minDelay:10,spawnDelay:9,lightSensitive:0b,spawnGroups:[{settingsList:[{remainingSpawnCount:1,hostile:1b,customTag:{ArmorDropChances:[0.085f,0.085f,0.085f,0.085f],hasCustomEquipment:0b,ArmorItems:[{},{},{},{}],skinSettings:{npcTypeName:"custom",skinTypeSelected:"default"},HandDropChances:[0.085f,0.085f],factionName:"sarkonid",HandItems:[{},{}]},maxToSpawn:1,entityId:"ancientwarfarenpc:faction.civilian.female",minToSpawn:1}],groupWeight:1}],playerRange:16,respondToRedstone:0b,inventory:{Size:9,Items:[]},spawnRange:0,transparent:1b,maxDelay:10,spawnYOffset:0,xpToDrop:0,mobRange:0,debugMode:0b,maxNearbyMonsters:0}}}
:enddata
:endrule

rule:
plugin=blockTile
number=43
data:
JSON:{blockState:{blockName:"ancientwarfarestructure:advanced_spawner",properties:{transparent:"true"}},teData:{id:"ancientwarfarestructure:advanced_spawner_tile",spawnerSettings:{minDelay:10,spawnDelay:9,lightSensitive:0b,spawnGroups:[{settingsList:[{remainingSpawnCount:1,hostile:0b,customTag:{ArmorDropChances:[0.085f,0.085f,0.085f,0.085f],ArmorItems:[{},{},{},{}],HandDropChances:[0.085f,0.085f],HandItems:[{},{}]},maxToSpawn:1,entityId:"minecraft:llama",minToSpawn:1}],groupWeight:1}],playerRange:16,respondToRedstone:0b,inventory:{Size:9,Items:[]},spawnRange:0,transparent:1b,maxDelay:10,spawnYOffset:0,xpToDrop:0,mobRange:0,debugMode:0b,maxNearbyMonsters:0}}}
:enddata
:endrule

rule:
plugin=vanillaBlocks
number=44
data:
JSON:{blockState:{blockName:"minecraft:birch_fence_gate",properties:{in_wall:"false",powered:"false",facing:"north",open:"false"}}}
:enddata
:endrule

rule:
plugin=vanillaBlocks
number=45
data:
JSON:{blockState:{blockName:"minecraft:sandstone_stairs",properties:{half:"bottom",shape:"straight",facing:"south"}}}
:enddata
:endrule

rule:
plugin=blockTile
number=46
data:
JSON:{blockState:{blockName:"ancientwarfarestructure:advanced_spawner",properties:{transparent:"true"}},teData:{id:"ancientwarfarestructure:advanced_spawner_tile",spawnerSettings:{minDelay:10,spawnDelay:4,lightSensitive:0b,spawnGroups:[{settingsList:[{remainingSpawnCount:1,hostile:1b,customTag:{ArmorDropChances:[0.085f,0.085f,0.085f,0.085f],hasCustomEquipment:0b,ArmorItems:[{},{},{},{}],skinSettings:{npcTypeName:"custom",skinTypeSelected:"default"},HandDropChances:[0.085f,0.085f],factionName:"sarkonid",HandItems:[{id:"ancientwarfarenpc:golden_spear",Count:1b,Damage:0s},{id:"ancientwarfarenpc:gold_shield",Count:1b,Damage:0s}]},maxToSpawn:1,entityId:"ancientwarfarenpc:faction.soldier",minToSpawn:1}],groupWeight:1}],playerRange:16,respondToRedstone:0b,inventory:{Size:9,Items:[]},spawnRange:0,transparent:1b,maxDelay:10,spawnYOffset:0,xpToDrop:0,mobRange:0,debugMode:0b,maxNearbyMonsters:0}}}
:enddata
:endrule

rule:
plugin=blockTile
number=47
data:
JSON:{blockState:{blockName:"ancientwarfarestructure:advanced_spawner",properties:{transparent:"true"}},teData:{id:"ancientwarfarestructure:advanced_spawner_tile",spawnerSettings:{minDelay:10,spawnDelay:1,lightSensitive:0b,spawnGroups:[{settingsList:[{remainingSpawnCount:1,hostile:0b,customTag:{ArmorDropChances:[0.085f,0.085f,0.085f,0.085f],ArmorItems:[{},{},{},{}],HandDropChances:[0.085f,0.085f],HandItems:[{},{}]},maxToSpawn:1,entityId:"minecraft:llama",minToSpawn:1}],groupWeight:1}],playerRange:16,respondToRedstone:0b,inventory:{Size:9,Items:[]},spawnRange:0,transparent:1b,maxDelay:10,spawnYOffset:0,xpToDrop:0,mobRange:0,debugMode:0b,maxNearbyMonsters:0}}}
:enddata
:endrule

rule:
plugin=blockTile
number=48
data:
JSON:{blockState:{blockName:"ancientwarfarestructure:advanced_loot_chest",properties:{facing:"west"}},teData:{lootSettings:{lootRolls:1,splashPotion:0b,hasMessage:0b,hasLoot:1b,lootTableName:"ancientwarfare:chests/sarkonid",spawnEntity:0b,entity:"minecraft:"},Items:[],id:"ancientwarfarestructure:advanced_loot_chest_tile",Lock:""}}
:enddata
:endrule

rule:
plugin=vanillaBlocks
number=49
data:
JSON:{blockState:{blockName:"minecraft:birch_fence",properties:{east:"false",south:"false",north:"false",west:"false"}}}
:enddata
:endrule

rule:
plugin=vanillaBlocks
number=50
data:
JSON:{blockState:{blockName:"minecraft:melon_block"}}
:enddata
:endrule

rule:
plugin=vanillaBlocks
number=51
data:
JSON:{blockState:{blockName:"minecraft:melon_stem",properties:{facing:"up",age:"7"}}}
:enddata
:endrule

rule:
plugin=doors
number=52
data:
JSON:{blockState:{blockName:"minecraft:spruce_door",properties:{hinge:"left",half:"upper",powered:"false",facing:"east",open:"false"}}}
:enddata
:endrule

rule:
plugin=vanillaBlocks
number=53
data:
JSON:{blockState:{blockName:"minecraft:torch",properties:{facing:"up"}}}
:enddata
:endrule

rule:
plugin=doors
number=54
data:
JSON:{blockState:{blockName:"minecraft:spruce_door",properties:{hinge:"right",half:"upper",powered:"false",facing:"east",open:"false"}}}
:enddata
:endrule

rule:
plugin=vanillaBlocks
number=55
data:
JSON:{blockState:{blockName:"minecraft:stone_slab",properties:{half:"bottom",variant:"sandstone"}}}
:enddata
:endrule

rule:
plugin=vanillaBlocks
number=56
data:
JSON:{blockState:{blockName:"minecraft:sandstone_stairs",properties:{half:"top",shape:"straight",facing:"west"}}}
:enddata
:endrule

rule:
plugin=vanillaBlocks
number=57
data:
JSON:{blockState:{blockName:"minecraft:torch",properties:{facing:"north"}}}
:enddata
:endrule

rule:
plugin=vanillaBlocks
number=58
data:
JSON:{blockState:{blockName:"minecraft:torch",properties:{facing:"east"}}}
:enddata
:endrule

rule:
plugin=vanillaBlocks
number=59
data:
JSON:{blockState:{blockName:"minecraft:torch",properties:{facing:"south"}}}
:enddata
:endrule

rule:
plugin=vanillaBlocks
number=60
data:
JSON:{blockState:{blockName:"minecraft:torch",properties:{facing:"west"}}}
:enddata
:endrule

rule:
plugin=vanillaBlocks
number=61
data:
JSON:{blockState:{blockName:"minecraft:stained_hardened_clay",properties:{color:"lime"}}}
:enddata
:endrule

rule:
plugin=vanillaBlocks
number=62
data:
JSON:{blockState:{blockName:"minecraft:stone_slab2",properties:{half:"top",variant:"red_sandstone"}}}
:enddata
:endrule

rule:
plugin=vanillaBlocks
number=63
data:
JSON:{blockState:{blockName:"minecraft:stained_hardened_clay",properties:{color:"green"}}}
:enddata
:endrule

rule:
plugin=vanillaBlocks
number=64
data:
JSON:{blockState:{blockName:"minecraft:red_sandstone_stairs",properties:{half:"top",shape:"straight",facing:"south"}}}
:enddata
:endrule

rule:
plugin=vanillaBlocks
number=65
data:
JSON:{blockState:{blockName:"minecraft:red_sandstone_stairs",properties:{half:"top",shape:"straight",facing:"north"}}}
:enddata
:endrule

rule:
plugin=vanillaBlocks
number=66
data:
JSON:{blockState:{blockName:"minecraft:red_sandstone_stairs",properties:{half:"top",shape:"straight",facing:"east"}}}
:enddata
:endrule

rule:
plugin=vanillaBlocks
number=67
data:
JSON:{blockState:{blockName:"minecraft:double_stone_slab",properties:{seamless:"false",variant:"sandstone"}}}
:enddata
:endrule

rule:
plugin=blockTile
number=68
data:
JSON:{blockState:{blockName:"ancientwarfarestructure:advanced_spawner",properties:{transparent:"true"}},teData:{id:"ancientwarfarestructure:advanced_spawner_tile",spawnerSettings:{minDelay:10,spawnDelay:3,lightSensitive:0b,spawnGroups:[{settingsList:[{remainingSpawnCount:1,hostile:1b,customTag:{ArmorDropChances:[0.085f,0.085f,0.085f,0.085f],hasCustomEquipment:0b,ArmorItems:[{},{},{},{}],skinSettings:{npcTypeName:"custom",skinTypeSelected:"default"},HandDropChances:[0.085f,0.085f],factionName:"sarkonid",HandItems:[{id:"minecraft:bow",Count:1b,Damage:0s},{}]},maxToSpawn:1,entityId:"ancientwarfarenpc:faction.archer",minToSpawn:1}],groupWeight:1}],playerRange:32,respondToRedstone:0b,inventory:{Size:9,Items:[]},spawnRange:0,transparent:1b,maxDelay:10,spawnYOffset:0,xpToDrop:0,mobRange:0,debugMode:0b,maxNearbyMonsters:0}}}
:enddata
:endrule

rule:
plugin=blockTile
number=69
data:
JSON:{blockState:{blockName:"ancientwarfarestructure:advanced_spawner",properties:{transparent:"true"}},teData:{id:"ancientwarfarestructure:advanced_spawner_tile",spawnerSettings:{minDelay:10,spawnDelay:9,lightSensitive:0b,spawnGroups:[{settingsList:[{remainingSpawnCount:1,hostile:1b,customTag:{ArmorDropChances:[0.085f,0.085f,0.085f,0.085f],hasCustomEquipment:0b,ArmorItems:[{},{},{},{}],skinSettings:{npcTypeName:"custom",skinTypeSelected:"default"},HandDropChances:[0.085f,0.085f],factionName:"sarkonid",HandItems:[{},{}]},maxToSpawn:1,entityId:"ancientwarfarenpc:faction.civilian.male",minToSpawn:1}],groupWeight:1}],playerRange:16,respondToRedstone:0b,inventory:{Size:9,Items:[]},spawnRange:0,transparent:1b,maxDelay:10,spawnYOffset:0,xpToDrop:0,mobRange:0,debugMode:0b,maxNearbyMonsters:0}}}
:enddata
:endrule

rule:
plugin=blockTile
number=70
data:
JSON:{blockState:{blockName:"ancientwarfarestructure:advanced_spawner",properties:{transparent:"true"}},teData:{id:"ancientwarfarestructure:advanced_spawner_tile",spawnerSettings:{minDelay:10,spawnDelay:2,lightSensitive:0b,spawnGroups:[{settingsList:[{remainingSpawnCount:1,hostile:1b,customTag:{ArmorDropChances:[0.085f,0.085f,0.085f,0.085f],hasCustomEquipment:0b,ArmorItems:[{},{},{},{}],skinSettings:{npcTypeName:"custom",skinTypeSelected:"default"},HandDropChances:[0.085f,0.085f],factionName:"sarkonid",HandItems:[{id:"minecraft:bow",Count:1b,Damage:0s},{}]},maxToSpawn:1,entityId:"ancientwarfarenpc:faction.archer",minToSpawn:1}],groupWeight:1}],playerRange:32,respondToRedstone:0b,inventory:{Size:9,Items:[]},spawnRange:0,transparent:1b,maxDelay:10,spawnYOffset:0,xpToDrop:0,mobRange:0,debugMode:0b,maxNearbyMonsters:0}}}
:enddata
:endrule

rule:
plugin=blockTile
number=71
data:
JSON:{blockState:{blockName:"ancientwarfarestructure:advanced_spawner",properties:{transparent:"true"}},teData:{id:"ancientwarfarestructure:advanced_spawner_tile",spawnerSettings:{minDelay:10,spawnDelay:5,lightSensitive:0b,spawnGroups:[{settingsList:[{remainingSpawnCount:1,hostile:1b,customTag:{ArmorDropChances:[0.085f,0.085f,0.085f,0.085f],hasCustomEquipment:0b,ArmorItems:[{},{},{},{}],skinSettings:{npcTypeName:"custom",skinTypeSelected:"default"},HandDropChances:[0.085f,0.085f],factionName:"sarkonid",HandItems:[{id:"minecraft:bow",Count:1b,Damage:0s},{}]},maxToSpawn:1,entityId:"ancientwarfarenpc:faction.archer",minToSpawn:1}],groupWeight:1}],playerRange:32,respondToRedstone:0b,inventory:{Size:9,Items:[]},spawnRange:0,transparent:1b,maxDelay:10,spawnYOffset:0,xpToDrop:0,mobRange:0,debugMode:0b,maxNearbyMonsters:0}}}
:enddata
:endrule

rule:
plugin=vanillaBlocks
number=72
data:
JSON:{blockState:{blockName:"ancientwarfarestructure:bench",properties:{legs:"none",variant:"oak",axis:"z"}}}
:enddata
:endrule

rule:
plugin=blockTile
number=73
data:
JSON:{blockState:{blockName:"ancientwarfarestructure:advanced_spawner",properties:{transparent:"true"}},teData:{id:"ancientwarfarestructure:advanced_spawner_tile",spawnerSettings:{minDelay:10,spawnDelay:3,lightSensitive:0b,spawnGroups:[{settingsList:[{remainingSpawnCount:1,hostile:1b,customTag:{ArmorDropChances:[0.085f,0.085f,0.085f,0.085f],hasCustomEquipment:0b,ArmorItems:[{},{},{},{}],skinSettings:{npcTypeName:"custom",skinTypeSelected:"default"},HandDropChances:[0.085f,0.085f],factionName:"sarkonid",HandItems:[{id:"minecraft:bow",Count:1b,Damage:0s},{}]},maxToSpawn:1,entityId:"ancientwarfarenpc:faction.archer",minToSpawn:1}],groupWeight:1}],playerRange:32,respondToRedstone:0b,inventory:{Size:9,Items:[]},spawnRange:0,transparent:1b,maxDelay:10,spawnYOffset:0,xpToDrop:0,mobRange:0,debugMode:0b,maxNearbyMonsters:0}}}
:enddata
:endrule

rule:
plugin=vanillaBlocks
number=74
data:
JSON:{blockState:{blockName:"minecraft:wooden_slab",properties:{half:"bottom",variant:"birch"}}}
:enddata
:endrule

rule:
plugin=vanillaBlocks
number=75
data:
JSON:{blockState:{blockName:"minecraft:wool",properties:{color:"red"}}}
:enddata
:endrule

rule:
plugin=vanillaBlocks
number=76
data:
JSON:{blockState:{blockName:"minecraft:wool",properties:{color:"green"}}}
:enddata
:endrule

rule:
plugin=vanillaBlocks
number=77
data:
JSON:{blockState:{blockName:"minecraft:leaves",properties:{check_decay:"false",decayable:"false",variant:"jungle"}}}
:enddata
:endrule

rule:
plugin=vanillaBlocks
number=78
data:
JSON:{blockState:{blockName:"minecraft:leaves",properties:{check_decay:"true",decayable:"false",variant:"jungle"}}}
:enddata
:endrule

#### ENTITIES ####
