# Ancient Warfare Structure Template File
# Auto-generated structure template file. created on: 12/11/2023 at: 23:58:0
# Lines beginning with # denote comments

header:
version=2.11
name=NoggVillageSmall
mods=
size=44,19,42
offset=27,5,24
:endheader

#### VALIDATION ####
validation:
type=ground
structureAuthor=TheOddlySeagull
survival=false
worldGenEnabled=true
unique=false
preserveBlocks=false
preventNaturalHostileSpawns=true
selectionWeight=30
clusterValue=30
minDuplicateDistance=1000
dimensionWhiteList=true
dimensionList=0
biomeGroupList=nogg
biomeWhiteList=true
biomeList=minecraft:birch_forest,minecraft:birch_forest_hills
leveling=50
fill=20
border=4
blockSwap=false
territoryName=nogg
biomeReplacement=minecraft:birch_forest
minGenerationHeight=0
maxGenerationHeight=0
:endvalidation

#### LAYERS ####
layer: 0
1,1,1,1,1,1,1,1,1,1,1,1,1,1,1,1,1,1,1,1,1,1,1,1,1,1,1,1,1,1,1,1,1,1,1,1,1,1,1,1,1,1,1,1
1,1,1,1,1,1,1,1,1,1,1,1,1,1,1,1,1,1,1,1,1,1,1,1,1,1,1,1,1,1,1,1,1,1,1,1,1,1,1,1,1,1,1,1
1,1,1,1,1,1,1,1,1,1,1,1,1,1,1,1,1,1,1,1,1,1,1,1,1,1,1,1,1,1,1,1,1,1,1,1,1,1,1,1,1,1,1,1
1,1,1,1,1,1,1,1,1,1,1,1,1,1,1,1,1,1,1,1,1,1,1,1,1,1,1,1,1,1,1,1,1,1,1,1,1,1,1,1,1,1,1,1
1,1,1,1,1,1,1,1,1,1,1,1,1,1,1,1,1,1,1,1,1,1,1,1,1,1,1,1,1,1,1,1,1,1,1,1,1,1,1,1,1,1,1,1
1,1,1,1,1,1,1,1,1,1,1,1,1,1,1,1,1,1,1,1,1,1,1,1,1,1,1,1,1,1,1,1,1,1,1,1,1,1,1,1,1,1,1,1
1,1,1,1,1,1,1,1,1,1,1,1,1,1,1,1,1,1,1,1,1,1,1,1,1,1,1,1,1,1,1,1,1,1,1,1,1,1,1,1,1,1,1,1
1,1,1,1,1,1,1,1,1,1,1,1,1,1,1,1,1,1,1,1,1,1,1,1,1,1,1,1,1,1,1,1,1,1,1,1,1,1,1,1,1,1,1,1
1,1,1,1,1,1,1,1,1,1,1,1,1,1,1,1,1,1,1,1,1,1,1,1,1,1,1,1,1,1,1,1,1,1,1,1,1,1,1,1,1,1,1,1
1,1,1,1,1,1,1,1,1,1,1,1,1,1,1,1,1,1,1,1,1,1,1,1,1,1,1,1,1,1,1,1,1,1,1,1,1,1,1,1,1,1,1,1
1,1,1,1,1,1,1,1,1,1,1,1,1,1,1,1,1,1,1,1,1,1,1,1,1,1,1,1,1,1,1,1,1,1,1,1,1,1,1,1,1,1,1,1
1,1,1,1,1,1,1,1,1,1,1,1,1,1,1,1,1,1,1,1,1,1,1,1,1,1,1,1,1,1,1,1,1,1,1,1,1,1,1,1,1,1,1,1
1,1,1,1,1,1,1,1,1,1,1,1,1,1,1,1,1,1,1,1,1,1,1,1,1,1,1,1,1,1,1,1,1,1,1,1,1,1,1,1,1,1,1,1
1,1,1,1,1,1,1,1,1,1,1,1,1,1,1,1,1,1,1,1,1,1,1,1,1,1,1,1,1,1,1,1,1,1,1,1,1,1,1,1,1,1,1,1
1,1,1,1,1,1,1,1,1,1,1,1,1,1,1,1,1,1,1,1,1,1,1,1,1,1,1,1,1,1,1,1,1,1,1,1,1,1,1,1,1,1,1,1
1,1,1,1,1,1,1,1,1,1,1,1,1,1,1,1,1,1,1,1,1,1,1,1,1,1,1,1,1,1,1,1,1,1,1,1,1,1,1,1,1,1,1,1
1,1,1,1,1,1,1,1,1,1,1,1,1,1,1,1,1,1,1,1,1,1,1,1,1,1,1,1,1,1,1,1,1,1,1,1,1,1,1,1,1,1,1,1
1,1,1,1,1,1,1,1,1,1,1,1,1,1,1,1,1,1,1,1,1,1,1,1,1,1,1,1,1,1,1,1,1,1,1,1,1,1,1,1,1,1,1,1
1,1,1,1,1,1,1,1,1,1,1,1,1,1,1,1,1,1,1,1,1,1,1,1,1,1,1,1,1,1,1,1,1,1,1,1,1,1,1,1,1,1,1,1
1,1,1,1,1,1,1,1,1,1,1,1,1,1,1,1,1,1,1,1,1,1,1,1,1,1,1,1,1,1,1,1,1,1,1,1,1,1,1,1,1,1,1,1
1,1,1,1,1,1,1,1,1,1,1,1,1,1,1,1,1,1,1,1,1,1,1,1,1,1,1,1,1,1,1,1,1,1,1,1,1,1,1,1,1,1,1,1
1,1,1,1,1,1,1,1,1,1,1,1,1,1,1,1,1,1,1,1,1,1,1,1,1,1,1,1,1,1,1,1,1,1,1,1,1,1,1,1,1,1,1,1
1,1,1,1,1,1,1,1,1,1,1,1,1,1,1,1,1,1,1,1,1,1,1,1,1,1,1,1,1,1,1,1,1,1,1,1,1,1,1,1,1,1,1,1
1,1,1,1,1,1,1,1,1,1,1,1,1,1,1,1,1,1,1,1,1,1,1,1,1,1,1,1,1,1,1,1,1,1,1,1,1,1,1,1,1,1,1,1
1,1,1,1,1,1,1,1,1,1,1,1,1,1,1,1,1,1,1,1,1,1,1,1,1,1,1,1,1,1,1,1,1,1,1,1,1,1,1,1,1,1,1,1
1,1,1,1,1,1,1,1,1,1,1,1,1,1,1,1,1,1,1,1,1,1,1,1,1,1,1,1,1,1,1,1,1,1,1,1,1,1,1,1,1,1,1,1
1,1,1,1,1,1,1,1,1,1,1,1,1,1,1,1,1,1,1,1,1,1,1,1,1,1,1,1,1,1,1,1,1,1,1,1,1,1,1,1,1,1,1,1
1,1,1,1,1,1,1,1,1,1,1,1,1,1,1,1,1,1,1,1,1,1,1,1,1,1,1,1,1,1,1,1,1,1,1,1,1,1,1,1,1,1,1,1
1,1,1,1,1,1,1,1,1,1,1,1,1,1,1,1,1,1,1,1,1,1,1,1,1,1,1,1,1,1,1,1,1,1,1,1,1,1,1,1,1,1,1,1
1,1,1,1,1,1,1,1,1,1,1,1,1,1,1,1,1,1,1,1,1,1,1,1,1,1,1,1,1,1,1,1,1,1,1,1,1,1,1,1,1,1,1,1
1,1,1,1,1,1,1,1,1,1,1,1,1,1,1,1,1,1,1,1,1,1,1,1,1,1,1,1,1,1,1,1,1,1,1,1,1,1,1,1,1,1,1,1
1,1,1,1,1,1,1,1,1,1,1,1,1,1,1,1,1,1,1,1,1,1,1,1,1,1,1,1,1,1,1,1,1,1,1,1,1,1,1,1,1,1,1,1
1,1,1,1,1,1,1,1,1,1,1,1,1,1,1,1,1,1,1,1,1,1,1,1,1,1,1,1,1,1,1,1,1,1,1,1,1,1,1,1,1,1,1,1
1,1,1,1,1,1,1,1,1,1,1,1,1,1,1,1,1,1,1,1,1,1,1,1,1,1,1,1,1,1,1,1,1,1,1,1,1,1,1,1,1,1,1,1
1,1,1,1,1,1,1,1,1,1,1,1,1,1,1,1,1,1,1,1,1,1,1,1,1,1,1,1,1,1,1,1,1,1,1,1,1,1,1,1,1,1,1,1
1,1,1,1,1,1,1,1,1,1,1,1,1,1,1,1,1,1,1,1,1,1,1,1,1,1,1,1,1,1,1,1,1,1,1,1,1,1,1,1,1,1,1,1
1,1,1,1,1,1,1,1,1,1,1,1,1,1,1,1,1,1,1,1,1,1,1,1,1,1,1,1,1,1,1,1,1,1,1,1,1,1,1,1,1,1,1,1
1,1,1,1,1,1,1,1,1,1,1,1,1,1,1,1,1,1,1,1,1,1,1,1,1,1,1,1,1,1,1,1,1,1,1,1,1,1,1,1,1,1,1,1
1,1,1,1,1,1,1,1,1,1,1,1,1,1,1,1,1,1,1,1,1,1,1,1,1,1,1,1,1,1,1,1,1,1,1,1,1,1,1,1,1,1,1,1
1,1,1,1,1,1,1,1,1,1,1,1,1,1,1,1,1,1,1,1,1,1,1,1,1,1,1,1,1,1,1,1,1,1,1,1,1,1,1,1,1,1,1,1
1,1,1,1,1,1,1,1,1,1,1,1,1,1,1,1,1,1,1,1,1,1,1,1,1,1,1,1,1,1,1,1,1,1,1,1,1,1,1,1,1,1,1,1
1,1,1,1,1,1,1,1,1,1,1,1,1,1,1,1,1,1,1,1,1,1,1,1,1,1,1,1,1,1,1,1,1,1,1,1,1,1,1,1,1,1,1,1
:endlayer
layer: 1
1,1,1,1,1,1,1,1,1,1,1,1,1,1,1,1,1,1,1,1,1,1,1,1,1,1,1,1,1,1,1,1,1,1,1,1,1,1,1,1,1,1,1,1
1,1,1,1,1,1,1,1,1,1,1,1,1,1,1,1,1,1,1,1,1,1,1,1,1,1,1,1,1,1,1,1,1,1,1,1,1,1,1,1,1,1,1,1
1,1,1,1,1,1,1,1,1,1,1,1,1,1,1,1,1,1,1,1,1,1,1,1,1,1,1,1,1,1,1,1,1,1,1,1,1,1,1,1,1,1,1,1
1,1,1,1,1,1,1,1,1,1,1,1,1,1,1,1,1,1,1,1,1,1,1,1,1,1,1,1,1,1,1,1,1,1,1,1,1,1,1,1,1,1,1,1
1,1,1,1,1,1,1,1,1,1,1,1,1,1,1,1,1,1,1,1,1,1,1,1,1,1,1,1,1,1,1,1,1,1,1,1,1,1,1,1,1,1,1,1
1,1,1,1,1,1,1,1,1,1,1,1,1,1,1,1,1,1,1,1,1,1,1,1,1,1,1,1,1,1,1,1,1,1,1,1,1,1,1,1,1,1,1,1
1,1,1,1,1,1,1,1,1,1,1,1,1,1,1,1,1,1,1,1,1,1,1,1,1,1,1,1,1,1,1,1,1,1,1,1,1,1,1,1,1,1,1,1
1,1,1,1,1,1,1,1,1,1,1,1,1,1,1,1,1,1,1,1,1,1,1,1,1,1,1,1,1,1,1,1,1,1,1,1,1,1,1,1,1,1,1,1
1,1,1,1,1,1,1,1,1,1,1,1,1,1,1,1,1,1,1,1,1,1,1,1,1,1,1,1,1,1,1,1,1,1,1,1,1,1,1,1,1,1,1,1
1,1,1,1,1,1,1,1,1,1,1,1,1,1,1,1,1,1,1,1,1,1,1,1,1,1,1,1,1,1,1,1,1,1,1,1,1,1,1,1,1,1,1,1
1,1,1,1,1,1,1,1,1,1,1,1,1,1,1,1,1,1,1,1,1,1,1,1,1,1,1,1,1,1,1,1,1,1,1,1,1,1,1,1,1,1,1,1
1,1,1,1,1,1,1,1,1,1,1,1,1,1,1,1,1,1,1,1,1,1,1,1,1,1,1,1,1,1,1,1,1,1,1,1,1,1,1,1,1,1,1,1
1,1,1,1,1,1,1,1,1,1,1,1,1,1,1,1,1,1,1,1,1,1,1,1,1,1,1,1,1,1,1,1,1,1,1,1,1,1,1,1,1,1,1,1
1,1,1,1,1,1,1,1,1,1,1,1,1,1,1,1,1,1,1,1,1,1,1,1,1,1,1,1,1,1,1,1,1,1,1,1,1,1,1,1,1,1,1,1
1,1,1,1,1,1,1,1,1,1,1,1,1,1,1,1,1,1,1,1,1,1,1,1,1,1,1,1,1,1,1,1,1,1,1,1,1,1,1,1,1,1,1,1
1,1,1,1,1,1,1,1,1,1,1,1,1,1,1,1,1,1,1,1,1,1,1,1,1,1,1,1,1,1,1,1,1,1,1,1,1,1,1,1,1,1,1,1
1,1,1,1,1,1,1,1,1,1,1,1,1,1,1,1,1,1,1,1,1,1,1,1,1,1,1,1,1,1,1,1,1,1,1,1,1,1,1,1,1,1,1,1
1,1,1,1,1,1,1,1,1,1,1,1,1,1,1,1,1,1,1,1,1,1,1,1,1,1,1,1,1,1,1,1,1,1,1,1,1,1,1,1,1,1,1,1
1,1,1,1,1,1,1,1,1,1,1,1,1,1,1,1,1,1,1,1,1,1,1,1,1,1,1,1,1,1,1,1,1,1,1,1,1,1,1,1,1,1,1,1
1,1,1,1,1,1,1,1,1,1,1,1,1,1,1,1,1,1,1,1,1,1,1,1,1,1,1,1,1,1,1,1,1,1,1,1,1,1,1,1,1,1,1,1
1,1,1,1,1,1,1,1,1,1,1,1,1,1,1,1,1,1,1,1,1,1,1,1,1,1,1,1,1,1,1,1,1,1,1,1,1,1,1,1,1,1,1,1
1,1,1,1,1,1,1,1,1,1,1,1,1,1,1,1,1,1,1,1,1,1,1,1,1,1,1,1,1,1,1,1,1,1,1,1,1,1,1,1,1,1,1,1
1,1,1,1,1,1,1,1,1,1,1,1,1,1,1,1,1,1,1,1,1,1,1,1,1,1,1,1,1,1,1,1,1,1,1,1,1,1,1,1,1,1,1,1
1,1,1,1,1,1,1,1,1,1,1,1,1,1,1,1,1,1,1,1,1,1,1,1,1,1,1,1,1,1,1,1,1,1,1,1,1,1,1,1,1,1,1,1
1,1,1,1,1,1,1,1,1,1,1,1,1,1,1,1,1,1,1,1,1,1,1,1,1,1,1,1,1,1,1,1,1,1,1,1,1,1,1,1,1,1,1,1
1,1,1,1,1,1,1,1,1,1,1,1,1,1,1,1,1,1,1,1,1,1,1,1,1,1,1,1,1,1,1,1,1,1,1,1,1,1,1,1,1,1,1,1
1,1,1,1,1,1,1,1,1,1,1,1,1,1,1,1,1,1,1,1,1,1,1,1,1,1,1,1,1,1,1,1,1,1,1,1,1,1,1,1,1,1,1,1
1,1,1,1,1,1,1,1,1,1,1,1,1,1,1,1,1,1,1,1,1,1,1,1,1,1,1,1,1,1,1,1,1,1,1,1,1,1,1,1,1,1,1,1
1,1,1,1,1,1,1,1,1,1,1,1,1,1,1,1,1,1,1,1,1,1,1,1,1,1,1,1,1,1,1,1,1,1,1,1,1,1,1,1,1,1,1,1
1,1,1,1,1,1,1,1,1,1,1,1,1,1,1,1,1,1,1,1,1,1,1,1,1,1,1,1,1,1,1,1,1,1,1,1,1,1,1,1,1,1,1,1
1,1,1,1,1,1,1,1,1,1,1,1,1,1,1,1,1,1,1,1,1,1,1,1,1,1,1,1,1,1,1,1,1,1,1,1,1,1,1,1,1,1,1,1
1,1,1,1,1,1,1,1,1,1,1,1,1,1,1,1,1,1,1,1,1,1,1,1,1,1,1,1,1,1,1,1,1,1,1,1,1,1,1,1,1,1,1,1
1,1,1,1,1,1,1,1,1,1,1,1,1,1,1,1,1,1,1,1,1,1,1,1,1,1,1,1,1,1,1,1,1,1,1,1,1,1,1,1,1,1,1,1
1,1,1,1,1,1,1,1,1,1,1,1,1,1,1,1,1,1,1,1,1,1,1,1,1,1,1,1,1,1,1,1,1,1,1,1,1,1,1,1,1,1,1,1
1,1,1,1,1,1,1,1,1,1,1,1,1,1,1,1,1,1,1,1,1,1,1,1,1,1,1,1,1,1,1,1,1,1,1,1,1,1,1,1,1,1,1,1
1,1,1,1,1,1,1,1,1,1,1,1,1,1,1,1,1,1,1,1,1,1,1,1,1,1,1,1,1,1,1,1,1,1,1,1,1,1,1,1,1,1,1,1
1,1,1,1,1,1,1,1,1,1,1,1,1,1,1,1,1,1,1,1,1,1,1,1,1,1,1,1,1,1,1,1,1,1,1,1,1,1,1,1,1,1,1,1
1,1,1,1,1,1,1,1,1,1,1,1,1,1,1,1,1,1,1,1,1,1,1,1,1,1,1,1,1,1,1,1,1,1,1,1,1,1,1,1,1,1,1,1
1,1,1,1,1,1,1,1,1,1,1,1,1,1,1,1,1,1,1,1,1,1,1,1,1,1,1,1,1,1,1,1,1,1,1,1,1,1,1,1,1,1,1,1
1,1,1,1,1,1,1,1,1,1,1,1,1,1,1,1,1,1,1,1,1,1,1,1,1,1,1,1,1,1,1,1,1,1,1,1,1,1,1,1,1,1,1,1
1,1,1,1,1,1,1,1,1,1,1,1,1,1,1,1,1,1,1,1,1,1,1,1,1,1,1,1,1,1,1,1,1,1,1,1,1,1,1,1,1,1,1,1
1,1,1,1,1,1,1,1,1,1,1,1,1,1,1,1,1,1,1,1,1,1,1,1,1,1,1,1,1,1,1,1,1,1,1,1,1,1,1,1,1,1,1,1
:endlayer
layer: 2
1,1,1,1,1,1,1,1,1,1,1,1,1,1,1,1,1,1,1,1,1,1,1,1,1,1,1,1,1,1,1,1,1,1,1,1,1,1,1,1,1,1,1,1
1,1,1,1,1,1,1,1,1,1,1,1,1,1,1,1,1,1,1,1,1,1,1,1,1,1,1,1,1,1,1,1,1,1,1,1,1,1,1,1,1,1,1,1
1,1,1,1,1,1,1,1,1,1,1,1,1,1,1,1,1,1,1,1,1,1,1,1,1,1,1,1,1,1,1,1,1,1,1,1,1,1,1,1,1,1,1,1
1,1,1,1,1,1,1,1,1,1,1,1,1,1,1,1,1,1,1,1,1,1,1,1,1,1,1,1,1,1,1,1,1,1,1,1,1,1,1,1,1,1,1,1
1,1,1,1,1,1,1,1,1,1,1,1,1,1,1,1,1,1,1,1,1,1,1,1,1,1,1,1,1,1,1,1,1,1,1,1,1,1,1,1,1,1,1,1
1,1,1,1,1,1,1,1,1,1,1,1,1,1,1,1,1,1,1,1,1,1,1,1,1,1,1,1,1,1,1,1,1,1,1,1,1,1,1,1,1,1,1,1
1,1,1,1,1,1,1,1,1,1,1,1,1,1,1,1,1,1,1,1,1,1,1,1,1,1,1,1,1,1,1,1,1,1,1,1,1,1,1,1,1,1,1,1
1,1,1,1,1,1,1,1,1,1,1,1,1,1,1,1,1,1,1,1,1,1,1,1,1,1,1,1,1,1,1,1,1,1,1,1,1,1,1,1,1,1,1,1
1,1,1,1,1,1,1,1,1,1,1,1,1,1,1,1,1,1,1,1,1,1,1,1,1,1,1,1,1,1,1,1,1,1,1,1,1,1,1,1,1,1,1,1
1,1,1,1,1,1,1,1,1,1,1,1,1,1,1,1,1,1,1,1,1,1,1,1,1,1,1,1,1,1,1,1,1,1,1,1,1,1,1,1,1,1,1,1
1,1,1,1,1,1,1,1,1,1,1,1,1,1,1,1,1,1,1,1,1,1,1,1,1,1,1,1,1,1,1,1,1,1,1,1,1,1,1,1,1,1,1,1
1,1,1,1,1,1,1,1,1,1,1,1,1,1,1,1,1,1,1,1,1,1,1,1,1,1,1,1,1,1,1,1,1,1,1,1,1,1,1,1,1,1,1,1
1,1,1,1,1,1,1,1,1,1,1,1,1,1,1,1,1,1,1,1,1,1,1,1,1,1,1,1,1,1,1,1,1,1,1,1,1,1,1,1,1,1,1,1
1,1,1,1,1,1,1,1,1,1,1,1,1,1,1,1,1,1,1,1,1,1,1,1,1,1,1,1,1,1,1,1,1,1,1,1,1,1,1,1,1,1,1,1
1,1,1,1,1,1,1,1,1,1,1,1,1,1,1,1,1,1,1,1,1,1,1,1,1,1,1,1,1,1,1,1,1,1,1,1,1,1,1,1,1,1,1,1
1,1,1,1,1,1,1,1,1,1,1,1,1,1,1,1,1,1,1,1,1,1,1,1,1,1,1,1,1,1,1,1,1,1,1,1,1,1,1,1,1,1,1,1
1,1,1,1,1,1,1,1,1,1,1,1,1,1,1,1,1,1,1,1,1,1,1,1,1,1,1,1,1,1,1,1,1,1,1,1,1,1,1,1,1,1,1,1
1,1,1,1,1,1,1,1,1,1,1,1,1,1,1,1,1,1,1,1,1,1,1,1,1,1,1,1,1,1,1,1,1,1,1,1,1,1,1,1,1,1,1,1
1,1,1,1,1,1,1,1,1,1,1,1,1,1,1,1,1,1,1,1,1,1,1,1,1,1,1,1,1,1,1,1,1,1,1,1,1,1,1,1,1,1,1,1
1,1,1,1,1,1,1,1,1,1,1,1,1,1,1,1,1,1,1,1,1,1,1,1,1,1,1,1,1,1,1,1,1,1,1,1,1,1,1,1,1,1,1,1
1,1,1,1,1,1,1,1,1,1,1,1,1,1,1,1,1,1,1,1,1,1,1,1,1,1,1,1,1,1,1,1,1,1,1,1,1,1,1,1,1,1,1,1
1,1,1,1,1,1,1,1,1,1,1,1,1,1,1,1,1,1,1,1,1,1,1,1,1,1,1,1,1,1,1,1,1,1,1,1,1,1,1,1,1,1,1,1
1,1,1,1,1,1,1,1,1,1,1,1,1,1,1,1,1,1,1,1,1,1,1,1,1,1,1,1,1,1,1,1,1,1,1,1,1,1,1,1,1,1,1,1
1,1,1,1,1,1,1,1,1,1,1,1,1,1,1,1,1,1,1,1,1,1,1,1,1,1,1,1,1,1,1,1,1,1,1,1,1,1,1,1,1,1,1,1
1,1,1,1,1,1,1,1,1,1,1,1,1,1,1,1,1,1,1,1,1,1,1,1,1,1,1,1,1,1,1,1,1,1,1,1,1,1,1,1,1,1,1,1
1,1,1,1,1,1,1,1,1,1,1,1,1,1,1,1,1,1,1,1,1,1,1,1,1,1,1,1,1,1,1,1,1,1,1,1,1,1,1,1,1,1,1,1
1,1,1,1,1,1,1,1,1,1,1,1,1,1,1,1,1,1,1,1,1,1,1,1,1,1,1,1,1,1,1,1,1,1,1,1,1,1,1,1,1,1,1,1
1,1,1,1,1,1,1,1,1,1,1,1,1,1,1,1,1,1,1,1,1,1,1,1,1,1,1,1,1,1,1,1,1,1,1,1,1,1,1,1,1,1,1,1
1,1,1,1,1,1,1,1,1,1,1,1,1,1,1,1,1,1,1,1,1,1,1,1,1,1,1,1,1,1,1,1,1,1,1,1,1,1,1,1,1,1,1,1
1,1,1,1,1,1,1,1,1,1,1,1,1,1,1,1,1,1,1,1,1,1,1,1,1,1,1,1,1,1,1,1,1,1,1,1,1,1,1,1,1,1,1,1
1,1,1,1,1,1,1,1,1,1,1,1,1,1,1,1,1,1,1,1,1,1,1,1,1,1,1,1,1,1,1,1,1,1,1,1,1,1,1,1,1,1,1,1
1,1,1,1,1,1,1,1,1,1,1,1,1,1,1,1,1,1,1,1,1,1,1,1,1,1,1,1,1,1,1,1,1,1,1,1,1,1,1,1,1,1,1,1
1,1,1,1,1,1,1,1,1,1,1,1,1,1,1,1,1,1,1,1,1,1,1,1,1,1,1,1,1,1,1,1,1,1,1,1,1,1,1,1,1,1,1,1
1,1,1,1,1,1,1,1,1,1,1,1,1,1,1,1,1,1,1,1,1,1,1,1,1,1,1,1,1,1,1,1,1,1,1,1,1,1,1,1,1,1,1,1
1,1,1,1,1,1,1,1,1,1,1,1,1,1,1,1,1,1,1,1,1,1,1,1,1,1,1,1,1,1,1,1,1,1,1,1,1,1,1,1,1,1,1,1
1,1,1,1,1,1,1,1,1,1,1,1,1,1,1,1,1,1,1,1,1,1,1,1,1,1,1,1,1,1,1,1,1,1,1,1,1,1,1,1,1,1,1,1
1,1,1,1,1,1,1,1,1,1,1,1,1,1,1,1,1,1,1,1,1,1,1,1,1,1,1,1,1,1,1,1,1,1,1,1,1,1,1,1,1,1,1,1
1,1,1,1,1,1,1,1,1,1,1,1,1,1,1,1,1,1,1,1,1,1,1,1,1,1,1,1,1,1,1,1,1,1,1,1,1,1,1,1,1,1,1,1
1,1,1,1,1,1,1,1,1,1,1,1,1,1,1,1,1,1,1,1,1,1,1,1,1,1,1,1,1,1,1,1,1,1,1,1,1,1,1,1,1,1,1,1
1,1,1,1,1,1,1,1,1,1,1,1,1,1,1,1,1,1,1,1,1,1,1,1,1,1,1,1,1,1,1,1,1,1,1,1,1,1,1,1,1,1,1,1
1,1,1,1,1,1,1,1,1,1,1,1,1,1,1,1,1,1,1,1,1,1,1,1,1,1,1,1,1,1,1,1,1,1,1,1,1,1,1,1,1,1,1,1
1,1,1,1,1,1,1,1,1,1,1,1,1,1,1,1,1,1,1,1,1,1,1,1,1,1,1,1,1,1,1,1,1,1,1,1,1,1,1,1,1,1,1,1
:endlayer
layer: 3
2,2,2,2,2,2,2,2,2,2,2,2,2,2,2,2,2,2,2,2,2,2,2,2,2,2,2,2,2,2,2,2,2,2,2,2,2,2,2,2,2,2,2,2
2,2,2,2,2,2,2,2,2,2,2,2,2,2,2,2,2,2,2,2,2,2,2,2,2,2,2,2,2,2,2,2,2,2,2,2,2,2,2,2,2,2,2,2
2,2,2,2,2,2,2,2,2,2,2,2,2,2,2,2,2,2,2,2,2,2,2,2,2,2,2,2,2,2,2,2,2,2,2,2,2,2,2,2,2,2,2,2
2,2,2,2,2,2,2,2,2,2,2,2,2,2,2,2,2,2,2,2,2,2,2,2,2,2,2,2,2,2,2,2,2,2,2,2,2,2,2,2,2,2,2,2
2,2,2,2,2,2,2,2,2,2,2,2,2,2,2,2,2,2,2,2,2,2,2,2,2,2,2,2,2,2,2,2,2,2,2,2,2,2,2,2,2,2,2,2
2,2,2,2,2,2,2,2,2,2,2,2,2,2,2,2,2,2,2,2,2,2,2,2,2,2,2,2,2,2,2,2,2,2,2,2,2,2,2,2,2,2,2,2
2,2,2,2,2,2,2,2,2,2,2,2,2,2,2,2,2,2,2,2,2,2,2,2,2,2,2,2,2,2,2,2,2,2,2,2,2,2,2,2,2,2,2,2
2,2,2,2,2,2,2,2,2,2,2,2,2,2,2,2,2,2,2,2,2,2,2,2,2,2,2,2,2,2,2,2,2,2,2,2,2,2,2,2,2,2,2,2
2,2,2,2,2,2,2,2,2,2,2,2,2,2,2,2,2,2,2,2,2,2,2,2,2,2,2,2,2,2,3,2,2,2,2,2,2,2,2,2,2,2,2,2
2,2,2,2,2,2,2,2,2,2,2,2,2,2,2,2,2,2,2,2,2,2,2,2,2,2,2,2,2,2,2,2,2,2,2,2,2,2,2,2,2,2,2,2
2,2,2,2,2,2,2,2,2,2,2,2,2,2,2,2,2,2,2,2,2,2,2,2,2,2,2,2,2,2,2,2,2,2,2,2,2,2,2,2,2,2,2,2
2,2,2,2,2,2,2,2,2,2,2,2,2,2,2,2,2,2,2,2,2,2,2,2,2,2,2,2,2,2,2,2,2,2,2,2,2,2,2,2,2,2,2,2
2,2,2,2,2,2,2,2,2,2,2,2,2,2,2,2,2,2,2,2,2,2,2,2,2,2,2,2,2,2,2,2,2,2,2,2,2,2,2,2,2,2,2,2
2,2,2,2,2,2,2,2,2,2,2,2,2,2,2,2,2,2,2,2,2,2,2,2,2,2,2,2,2,2,2,2,2,2,2,2,2,2,2,2,2,2,2,2
2,2,2,2,2,2,2,2,2,2,2,2,2,2,2,2,2,2,2,2,2,2,2,2,2,2,2,2,2,2,2,2,2,2,2,2,2,2,2,2,2,2,2,2
2,2,2,2,2,2,2,2,2,2,2,2,2,2,2,2,2,2,2,2,2,2,2,2,2,2,2,2,2,2,2,2,2,2,2,2,2,2,2,2,2,2,2,2
2,2,2,2,2,2,2,2,2,2,2,2,2,2,2,2,2,2,2,2,2,2,2,2,2,2,2,2,2,2,2,2,2,2,2,2,2,2,2,2,2,2,2,2
2,2,2,2,2,2,2,2,2,2,2,2,2,2,2,2,2,2,2,2,2,2,2,2,2,2,2,2,2,2,2,2,2,2,2,2,2,2,2,2,2,2,2,2
2,2,2,2,2,2,2,2,2,2,2,2,2,2,2,2,2,2,2,2,2,2,2,2,2,2,2,2,2,2,2,2,2,2,2,2,2,2,2,2,2,2,2,2
2,2,2,2,2,2,2,2,2,2,2,2,2,2,2,2,2,2,2,2,2,2,2,2,2,2,2,2,2,2,2,2,2,2,2,2,2,2,2,2,2,2,2,2
2,2,2,2,2,2,2,2,2,2,2,2,2,2,2,2,2,2,2,2,2,2,2,2,2,2,2,2,2,2,2,2,2,2,2,2,2,2,2,2,2,2,2,2
2,2,2,2,2,2,2,2,2,2,2,2,2,2,2,2,2,2,2,2,2,2,2,2,2,2,2,2,2,2,2,2,2,2,2,2,2,2,2,2,2,2,2,2
2,2,2,2,2,2,2,2,2,2,2,2,2,2,2,2,2,2,2,2,2,2,2,2,2,2,2,2,2,2,2,2,2,2,2,2,2,2,2,2,2,2,2,2
2,2,2,2,2,2,2,2,2,2,2,2,2,2,2,2,2,2,2,2,2,2,2,2,2,2,2,2,2,2,2,2,2,2,2,2,2,2,2,2,2,2,2,2
2,2,2,2,2,2,2,2,2,2,2,2,2,2,2,2,2,2,2,2,2,2,2,2,2,2,2,2,2,2,2,2,2,2,2,2,2,2,2,2,2,2,2,2
2,2,2,2,2,2,2,2,2,2,2,2,2,2,2,2,2,2,2,2,2,2,2,2,2,2,2,2,2,2,2,2,2,2,2,2,2,2,2,2,2,2,2,2
2,2,2,2,2,2,2,2,2,2,2,2,2,2,2,2,2,2,2,2,2,2,2,2,2,2,2,2,2,2,2,2,2,2,2,2,2,2,2,2,2,2,2,2
2,2,2,2,2,2,2,2,2,2,2,2,2,2,2,2,2,2,2,2,2,2,2,2,2,2,2,2,2,2,2,2,2,2,2,2,2,2,2,2,2,2,2,2
2,2,2,2,2,2,2,2,2,2,2,2,2,2,2,2,2,2,2,2,2,2,2,2,2,2,2,2,2,2,2,2,2,2,2,2,2,2,2,2,2,2,2,2
2,2,2,2,2,2,2,2,2,2,2,2,2,2,2,2,2,2,2,2,2,2,2,2,2,2,2,2,2,2,2,2,2,2,2,2,2,2,2,2,2,2,2,2
2,2,2,2,2,2,2,2,2,2,2,2,2,2,2,2,2,2,2,2,2,2,2,2,2,2,2,2,2,2,2,2,2,2,2,2,2,2,2,2,2,2,2,2
2,2,2,2,2,2,2,2,2,2,2,2,2,2,2,2,2,2,2,2,2,2,2,2,2,2,2,2,2,2,2,2,2,2,2,2,2,2,2,2,2,2,2,2
2,2,2,2,2,2,2,2,2,2,2,2,2,2,2,2,2,2,2,2,2,2,2,2,2,2,2,2,2,2,2,2,2,2,2,2,2,2,2,2,2,2,2,2
2,2,2,2,2,2,2,2,2,2,2,2,2,2,2,2,2,2,2,2,2,2,2,2,2,2,2,2,2,2,2,2,2,2,2,2,2,2,2,2,2,2,2,2
2,2,2,2,2,2,2,2,2,2,2,2,2,2,2,2,2,2,2,2,2,2,2,2,2,2,2,2,2,2,2,2,2,2,2,2,2,2,2,2,2,2,2,2
2,2,2,2,2,2,2,2,2,2,2,2,2,2,2,2,2,2,2,2,2,2,2,2,2,2,2,2,2,2,2,2,2,2,2,2,2,2,2,2,2,2,2,2
2,2,2,2,2,2,2,2,2,2,2,2,2,2,2,2,2,2,2,2,2,2,2,2,2,2,2,2,2,2,2,2,2,2,2,2,2,2,2,2,2,2,2,2
2,2,2,2,2,2,2,2,2,2,2,2,2,2,2,2,2,2,2,2,2,2,2,2,2,2,2,2,2,2,2,2,2,2,2,2,2,2,2,2,2,2,2,2
2,2,2,2,2,2,2,2,2,2,2,2,2,2,2,2,2,2,2,2,2,2,2,2,2,2,2,2,2,2,2,2,2,2,2,2,2,2,2,2,2,2,2,2
2,2,2,2,2,2,2,2,2,2,2,2,2,2,2,2,2,2,2,2,2,2,2,2,2,2,2,2,2,2,2,2,2,2,2,2,2,2,2,2,2,2,2,2
2,2,2,2,2,2,2,2,2,2,2,2,2,2,2,2,2,2,2,2,2,2,2,2,2,2,2,2,2,2,2,2,2,2,2,2,2,2,2,2,2,2,2,2
2,2,2,2,2,2,2,2,2,2,2,2,2,2,2,2,2,2,2,2,2,2,2,2,2,2,2,2,2,2,2,2,2,2,2,2,2,2,2,2,2,2,2,2
:endlayer
layer: 4
4,4,4,4,4,4,4,4,4,4,4,4,4,4,4,4,4,5,5,5,5,4,4,4,4,4,4,4,4,4,4,4,4,4,4,4,4,4,4,4,4,4,4,4
4,4,4,4,4,4,4,4,4,4,4,4,4,4,4,4,4,5,5,5,5,4,4,4,4,4,4,4,4,4,4,4,4,4,4,4,4,4,4,4,4,4,4,4
4,4,6,8,8,6,4,4,4,4,4,4,4,6,8,8,6,8,8,8,8,6,8,8,6,4,4,4,4,4,4,4,4,4,4,4,4,4,6,8,8,6,4,4
4,4,7,3,3,7,8,8,8,8,8,8,8,7,3,3,7,3,3,3,3,7,3,3,7,8,8,8,8,8,8,8,8,8,8,8,8,8,7,3,3,7,4,4
4,4,7,3,3,7,5,5,5,4,4,4,5,7,3,3,7,3,3,3,3,7,3,3,7,5,10,10,10,10,10,10,10,10,12,4,5,5,7,3,3,7,4,4
4,4,6,8,8,6,4,5,5,4,4,4,5,6,8,8,6,8,8,8,8,6,8,8,6,5,9,3,3,3,3,3,3,3,17,4,4,5,6,8,8,6,4,4
4,4,4,7,5,4,4,5,5,5,4,4,5,4,4,4,9,3,3,3,3,12,10,10,10,10,9,3,13,13,13,13,9,3,12,4,4,5,5,5,7,4,4,4
4,4,4,7,5,5,5,5,5,5,5,5,5,5,5,5,9,3,3,3,3,3,3,3,3,3,3,3,12,6,8,6,9,3,12,4,4,4,5,5,7,4,4,4
4,4,4,7,4,4,5,5,4,4,4,4,4,4,4,4,13,13,13,3,13,13,13,13,13,13,9,3,12,7,16,7,9,3,12,4,4,4,4,5,7,4,4,4
4,4,4,7,4,4,4,4,4,4,6,8,6,8,8,6,8,6,9,3,12,6,8,8,8,6,9,3,12,6,8,6,9,3,12,4,4,4,5,5,7,4,4,4
4,4,4,7,4,4,4,4,4,4,7,3,11,11,11,11,11,7,9,3,12,7,14,14,14,7,9,3,10,10,10,10,10,3,10,12,4,5,5,5,7,4,4,4
4,4,4,7,4,4,4,6,8,8,6,3,3,11,11,11,11,6,9,3,12,7,14,14,14,7,9,3,3,3,3,3,3,3,3,12,5,5,6,8,8,6,4,4
4,4,4,7,4,4,4,7,11,11,7,3,3,3,3,3,3,7,9,3,12,7,14,14,14,7,9,3,13,13,13,13,13,13,3,12,5,4,7,3,3,7,4,4
4,4,4,7,4,4,4,7,11,11,7,3,3,11,11,11,11,6,9,3,12,7,14,14,14,7,9,3,12,6,8,8,6,9,3,12,5,4,7,3,3,7,4,4
4,4,4,7,4,4,4,6,8,8,6,3,11,11,11,11,11,7,9,3,12,7,14,14,14,7,9,3,12,7,14,14,7,9,3,10,10,10,6,8,8,6,4,4
4,4,4,7,4,4,4,4,4,4,6,8,6,8,8,6,8,6,9,3,12,6,8,8,8,6,9,3,12,7,14,14,7,9,3,3,3,3,7,3,3,7,5,5
4,4,4,7,4,9,10,10,10,10,10,10,10,10,10,10,10,10,10,3,10,10,10,10,10,10,9,3,12,6,8,8,6,9,13,13,3,3,7,3,3,7,5,5
4,4,4,7,5,9,3,3,3,3,3,3,3,3,3,3,3,3,3,3,3,3,3,3,3,3,3,3,12,7,14,14,7,4,4,9,3,3,7,3,3,7,5,5
4,4,4,7,5,9,3,3,3,3,12,13,13,13,13,13,13,13,13,13,13,13,13,13,13,13,13,3,12,7,14,14,7,4,4,9,3,3,7,3,3,7,5,5
4,4,6,8,8,6,8,8,8,8,6,8,8,6,4,5,4,6,8,8,6,4,4,4,4,4,9,3,12,6,14,14,6,8,6,9,3,3,7,3,3,7,5,5
4,4,7,3,3,7,3,3,3,3,7,3,3,7,4,5,4,7,14,14,7,8,8,8,8,6,9,3,12,7,14,14,14,14,7,9,3,3,7,3,3,7,5,5
4,4,7,3,3,7,3,3,3,3,7,3,3,7,5,5,4,7,14,14,7,14,14,14,14,7,9,3,12,7,14,14,14,14,7,9,3,13,6,8,8,6,4,4
4,4,6,8,8,6,8,8,8,8,6,8,8,6,5,4,4,6,8,8,6,14,14,14,14,7,9,3,12,6,8,8,8,8,6,9,3,12,7,3,3,7,4,4
4,4,4,4,4,4,5,5,5,5,4,7,5,5,5,4,4,4,4,7,14,14,14,14,14,6,9,3,10,10,10,10,10,10,10,10,3,12,7,3,3,7,4,4
4,4,4,4,4,4,5,5,5,5,4,7,5,4,4,4,4,4,4,7,14,14,14,14,14,7,9,3,3,3,3,3,3,3,3,3,3,12,6,8,8,6,4,4
4,4,4,2,4,5,5,5,5,5,4,7,5,4,4,4,4,4,4,7,14,14,14,14,14,7,9,3,13,13,13,13,13,13,13,13,13,13,5,5,7,4,4,4
4,4,4,4,4,5,5,5,5,5,4,7,5,5,4,4,4,4,4,7,14,14,14,14,14,7,9,3,12,6,8,8,6,8,8,6,5,5,5,4,7,4,4,4
4,4,4,5,5,5,5,5,5,4,4,7,5,4,4,4,4,4,0,8,8,6,8,8,8,6,9,3,12,7,14,14,14,14,14,7,4,5,4,4,7,4,4,4
5,5,5,5,5,5,5,5,5,4,4,7,5,5,4,4,4,4,7,15,15,7,4,4,4,4,9,3,12,7,14,14,14,14,14,7,4,5,4,4,7,4,4,4
5,5,5,5,5,5,5,5,4,4,4,7,5,4,4,4,4,4,7,15,15,7,4,4,4,4,9,3,12,6,14,14,6,14,14,6,4,5,5,4,7,4,4,4
5,5,5,5,5,5,5,4,4,4,4,7,5,4,4,4,4,4,6,8,8,6,4,4,4,4,9,3,12,7,14,14,14,14,14,7,4,4,5,4,7,4,4,4
5,5,5,5,5,4,4,4,4,4,4,7,5,5,4,4,4,4,4,4,4,4,4,4,4,4,9,3,12,7,14,14,14,14,14,7,4,4,5,5,7,4,4,4
4,4,4,4,4,4,4,4,4,4,4,7,5,5,4,4,4,4,4,4,4,4,4,4,4,4,9,3,12,6,8,8,6,8,8,6,4,4,4,5,7,4,4,4
4,4,4,4,4,4,4,4,4,4,4,7,5,4,4,4,4,4,4,9,10,10,10,10,10,10,10,3,12,4,4,4,4,4,4,4,4,4,4,5,7,4,4,4
4,4,4,4,4,4,4,4,4,4,4,7,5,4,4,4,5,5,5,9,3,3,3,3,3,3,3,3,12,5,4,4,4,4,4,4,4,4,5,5,7,4,4,4
4,4,4,4,4,4,4,4,4,4,4,7,5,5,5,5,5,5,5,9,3,3,3,3,12,13,13,13,12,5,5,5,5,4,4,4,4,5,5,5,7,4,4,4
4,4,4,2,4,4,4,4,4,4,6,8,8,6,5,5,6,8,8,6,8,8,8,8,6,8,8,6,5,5,4,15,5,5,5,5,4,5,6,8,8,6,4,4
4,4,4,4,4,4,4,4,4,4,7,3,3,7,4,5,7,3,3,7,3,3,3,3,7,3,3,7,5,5,4,4,4,4,4,5,5,5,7,3,3,7,4,4
4,4,4,4,4,4,4,4,4,4,7,3,3,7,8,8,7,3,3,7,3,3,3,3,7,3,3,7,8,8,8,8,8,8,8,8,8,8,7,3,3,7,4,4
4,4,4,4,4,4,4,4,4,4,6,8,8,6,4,4,6,8,8,6,8,8,8,8,6,8,8,6,4,4,4,4,4,4,4,4,4,4,6,8,8,6,4,4
4,4,4,4,4,4,4,4,4,4,4,4,4,4,4,4,4,4,4,4,5,5,5,5,4,4,4,4,4,4,4,4,4,4,4,4,4,4,4,4,4,4,4,4
4,4,4,4,4,4,4,4,4,4,4,4,4,4,4,4,4,4,4,4,5,5,5,5,4,4,4,4,4,4,4,4,4,4,4,4,4,4,4,4,4,4,4,4
:endlayer
layer: 5
18,18,18,0,18,18,20,18,0,0,0,0,0,18,18,18,53,0,0,0,0,81,0,0,18,18,20,0,0,0,0,20,0,18,18,18,0,21,0,0,0,21,22,18
18,18,18,0,0,18,18,18,18,18,0,44,0,22,18,18,0,0,0,0,0,0,0,22,0,18,0,18,0,0,0,0,0,0,18,18,0,0,0,0,0,18,21,18
18,18,6,25,25,6,0,18,18,0,18,22,0,6,25,25,6,56,60,67,74,6,25,25,6,18,0,0,0,0,21,0,0,18,18,0,0,0,6,25,25,6,0,18
18,0,23,0,0,15,25,25,25,25,25,25,25,15,0,0,27,0,0,0,0,23,0,0,15,25,25,25,25,25,25,25,25,25,25,25,25,25,15,0,0,27,0,0
0,0,23,0,0,29,0,0,0,0,0,18,0,0,0,0,27,0,0,0,0,23,0,0,0,0,0,0,0,0,0,0,0,0,0,0,0,0,0,0,0,27,0,0
0,0,6,15,0,6,18,0,0,23,42,18,0,6,24,24,6,55,59,66,73,6,24,24,6,0,0,105,0,0,0,0,0,0,23,42,0,0,6,136,15,6,18,18
0,0,0,23,0,18,0,0,0,0,26,18,0,0,18,18,52,0,0,0,0,80,0,0,0,0,0,0,0,0,0,0,0,0,0,0,0,0,0,0,27,18,18,18
20,18,0,23,0,0,0,0,0,0,0,0,0,0,0,0,0,0,0,65,0,0,0,0,0,0,0,0,0,6,0,6,0,0,0,22,18,0,0,0,27,0,18,18
19,18,18,23,0,18,0,0,18,18,18,0,21,18,0,0,0,0,0,0,0,0,0,0,0,0,0,0,0,0,0,0,0,0,0,18,18,18,18,0,27,0,18,0
18,18,0,23,18,18,0,18,18,18,6,25,6,15,15,6,25,6,0,0,0,6,15,15,15,6,0,0,0,6,0,6,0,0,0,19,18,20,0,0,27,0,0,0
0,18,0,23,0,18,18,22,18,0,23,43,46,0,46,51,46,27,0,0,0,15,0,0,102,15,0,0,0,0,0,0,0,120,0,0,18,0,0,0,27,0,0,0
0,0,0,23,18,18,18,6,25,25,6,0,46,0,46,0,46,6,0,0,0,15,0,94,0,15,0,0,106,0,0,0,0,0,0,0,0,0,6,0,15,6,0,18
0,0,0,23,18,18,18,15,0,0,41,0,47,0,0,0,0,54,0,0,0,15,87,0,0,15,0,0,0,0,0,0,0,0,0,0,0,0,23,0,0,27,20,18
18,0,0,23,18,21,0,15,0,0,0,0,46,49,46,0,46,6,0,0,0,15,58,93,101,15,0,0,0,6,25,25,6,0,124,0,0,0,23,0,0,27,18,18
18,18,18,23,18,18,26,6,24,24,6,0,46,0,46,0,46,27,0,0,0,15,86,0,100,15,0,0,0,15,0,0,15,0,0,0,0,127,6,15,15,6,18,144
18,20,18,23,21,18,18,0,0,0,6,24,6,15,15,6,24,6,0,0,0,6,15,92,15,6,0,0,0,15,0,0,15,0,0,0,0,0,135,0,0,142,0,0
18,18,18,23,18,0,0,0,0,0,0,0,0,0,0,0,0,0,0,0,0,0,0,0,0,0,0,0,0,6,0,102,6,0,0,0,0,0,134,0,0,141,0,0
18,0,18,23,0,0,0,0,0,0,0,0,0,0,50,0,0,0,0,0,0,0,0,0,0,0,0,0,0,23,0,115,15,18,18,0,0,126,133,0,0,140,0,0
18,18,18,23,0,28,0,35,0,0,40,0,0,0,0,0,0,0,0,0,0,0,0,0,0,0,0,0,0,23,0,114,15,18,18,0,0,0,132,0,0,139,0,0
18,18,6,15,0,6,32,34,37,39,6,25,25,6,0,0,0,6,15,15,6,0,0,0,0,0,0,0,0,6,112,0,6,25,6,0,0,0,131,0,0,138,0,0
18,18,23,0,0,27,0,0,0,0,23,0,0,15,0,0,18,23,58,64,15,15,15,15,15,6,0,0,0,23,0,0,0,119,103,0,0,0,130,0,0,137,0,0
18,18,23,0,0,27,0,0,0,0,23,0,0,48,0,0,18,23,57,0,0,0,85,58,99,27,0,104,0,23,111,58,116,0,103,0,0,125,6,15,15,6,18,143
18,22,6,24,24,6,31,33,36,38,6,15,0,6,0,18,18,6,24,15,6,79,79,91,0,27,0,0,0,6,15,15,15,15,6,0,0,0,23,0,0,27,0,18
18,0,0,0,0,0,0,0,0,0,0,23,0,0,0,18,0,0,0,15,72,79,79,58,98,6,0,0,0,0,0,0,0,0,0,0,0,0,23,0,0,27,18,18
0,18,0,0,0,0,0,0,0,0,18,23,0,18,0,0,22,0,0,15,58,79,79,90,0,15,0,0,0,0,0,0,0,0,0,0,0,0,6,0,15,6,0,0
0,18,0,6,0,0,0,0,0,0,0,23,0,0,18,26,22,0,0,15,71,0,0,0,0,103,0,0,0,0,0,0,0,0,0,0,0,0,0,0,27,0,0,0
0,18,0,18,0,0,0,0,0,0,0,23,0,0,18,18,18,0,18,15,0,78,84,58,97,15,0,0,0,6,110,110,6,25,25,6,0,0,0,0,27,0,0,0
0,18,18,0,0,0,0,0,0,0,18,23,0,18,18,18,18,18,6,15,0,6,24,24,24,6,0,0,0,23,0,0,0,118,123,27,0,0,129,18,27,0,0,0
0,0,0,0,0,0,0,0,0,18,18,23,0,0,18,18,18,0,15,63,0,15,18,0,18,0,0,0,0,23,0,113,58,117,0,27,0,0,24,18,27,21,0,0
0,0,0,0,0,0,0,0,0,26,18,23,0,18,0,0,18,0,15,58,70,15,18,0,18,0,0,0,0,6,109,0,6,0,101,6,0,0,0,18,27,0,0,0
0,0,0,0,0,0,0,0,0,0,18,23,0,18,0,18,0,0,6,15,15,6,18,18,18,18,0,0,0,15,0,0,0,0,122,15,18,18,0,18,27,18,0,18
0,0,0,0,0,0,0,0,0,0,18,23,0,0,0,18,18,0,0,0,18,0,18,18,18,0,0,0,0,15,108,102,0,0,121,15,18,18,0,0,27,18,18,18
0,0,0,0,18,0,30,0,18,18,0,23,0,0,18,18,18,0,0,0,0,0,18,18,18,18,0,0,0,6,15,15,6,24,24,6,18,18,18,0,27,0,18,18
18,0,0,0,0,0,18,22,21,18,0,23,0,0,18,18,18,0,0,0,0,0,0,0,0,0,0,0,0,0,0,0,18,18,18,21,18,18,18,0,27,18,18,18
0,0,0,0,0,0,0,18,18,18,18,23,0,18,18,18,0,0,0,0,0,0,0,0,0,0,0,0,0,0,18,18,18,18,18,0,0,0,0,0,27,0,26,18
0,0,0,0,0,0,0,18,18,18,0,23,0,0,0,0,0,0,0,62,0,77,0,0,96,0,0,0,0,0,0,0,0,18,18,18,0,0,0,0,27,0,0,0
0,21,0,6,0,18,0,0,18,18,6,15,45,6,0,0,6,25,25,6,69,76,83,89,6,25,25,6,0,0,107,27,0,0,0,0,0,0,6,0,15,6,0,0
18,18,0,18,0,0,0,0,0,18,23,0,0,15,0,0,0,0,0,27,0,0,0,0,23,0,0,0,0,0,0,0,0,18,18,0,0,0,128,0,0,27,0,0
18,18,21,18,0,0,0,0,0,0,23,0,0,15,24,24,15,0,0,27,0,0,0,0,23,0,0,15,24,24,24,24,24,24,24,24,24,24,15,0,0,27,0,0
18,18,18,18,26,0,0,0,0,0,6,24,24,6,18,18,6,24,24,6,68,75,82,88,6,24,24,6,18,20,18,0,0,18,18,0,18,18,6,24,24,6,18,18
18,18,22,18,18,0,0,0,18,18,18,21,18,0,0,18,21,18,0,0,0,0,0,0,0,0,0,0,18,18,0,0,0,0,0,18,0,18,0,0,0,18,18,18
0,18,0,0,0,0,0,18,18,18,18,18,18,0,18,0,18,18,0,61,0,0,0,0,95,18,0,21,18,18,0,0,0,0,18,21,18,0,0,0,0,18,18,18
:endlayer
layer: 6
0,0,0,0,0,0,0,0,0,0,0,0,0,0,0,0,0,0,0,0,0,0,0,0,0,0,0,0,0,0,0,0,0,0,0,0,0,0,0,0,0,0,0,0
0,0,0,0,0,0,0,0,0,0,0,0,0,0,0,0,0,0,0,0,0,0,0,0,0,0,0,0,0,0,0,0,0,0,0,0,0,0,0,0,0,0,0,0
0,0,6,25,25,6,0,0,0,0,0,0,0,6,25,25,6,160,165,169,177,6,25,25,6,0,0,0,0,0,0,0,0,0,0,0,0,0,6,25,25,6,0,0
0,0,23,0,0,15,25,25,25,25,25,25,25,15,0,0,27,0,0,0,0,23,0,0,15,25,25,25,25,25,25,25,25,25,25,25,25,25,15,0,0,27,0,0
0,0,23,0,0,0,0,0,0,0,0,0,0,0,0,0,27,0,0,0,0,23,0,0,0,0,0,0,0,0,0,0,0,0,0,0,0,0,0,0,161,27,0,0
0,0,6,15,0,6,0,0,0,0,23,42,0,6,24,24,6,159,164,168,176,6,24,24,6,0,0,0,0,0,0,0,0,0,0,23,42,0,6,0,15,6,0,0
0,0,0,23,0,0,0,0,0,0,0,0,0,0,0,0,0,0,0,0,0,0,0,0,0,0,0,0,0,0,0,0,0,0,0,0,0,0,0,0,27,0,0,0
0,0,0,23,0,0,0,0,0,0,0,0,0,0,0,0,0,0,0,0,0,0,0,0,0,0,0,0,0,6,0,6,0,0,0,0,0,0,0,0,27,0,0,0
0,0,0,23,0,0,0,0,0,0,0,0,0,0,0,0,0,0,0,0,0,0,0,0,0,0,0,0,0,0,0,0,0,0,0,0,0,0,0,0,27,0,0,0
0,0,0,23,0,0,0,0,0,0,6,25,6,151,151,6,25,6,0,0,0,6,15,151,15,6,0,0,0,6,0,6,0,0,0,0,0,0,0,0,27,0,0,0
0,0,0,23,0,0,0,0,0,0,23,0,0,0,0,0,0,27,0,0,0,15,0,0,197,15,0,0,0,0,0,0,0,0,0,0,0,0,0,0,27,0,0,0
0,0,0,23,0,0,0,6,25,25,6,0,0,0,0,0,0,6,0,0,0,151,0,0,0,151,0,0,0,0,0,0,0,0,0,0,0,0,6,0,15,6,0,0
0,0,0,23,0,0,0,151,0,0,156,0,0,0,0,0,0,158,0,0,0,15,186,0,0,15,0,0,0,0,0,0,0,0,0,0,0,0,23,0,0,27,0,0
0,0,0,23,0,0,0,151,0,0,0,0,0,0,0,0,0,6,0,0,0,151,0,0,0,151,0,0,0,6,25,25,6,0,0,0,0,0,23,145,0,27,0,0
0,0,0,23,0,0,0,6,24,24,6,0,0,0,0,0,0,27,0,0,0,15,185,0,0,15,0,0,0,151,0,0,151,0,0,0,0,0,6,15,15,6,0,0
0,0,0,23,0,0,0,0,0,0,6,24,6,151,151,6,24,6,0,0,0,6,15,194,15,6,0,0,0,151,0,0,151,0,0,0,0,0,215,0,0,221,0,0
0,0,0,23,0,0,0,0,0,0,0,0,0,0,0,0,0,0,0,0,0,0,0,0,0,0,0,0,0,6,0,205,6,0,0,0,0,0,214,0,0,220,0,0
0,0,0,23,0,0,0,0,0,0,0,0,0,0,0,0,0,0,0,0,0,0,0,0,0,0,0,0,0,23,0,0,151,0,0,0,0,0,213,0,0,219,0,0
0,0,0,23,0,0,0,0,0,0,0,0,0,0,0,0,0,0,0,0,0,0,0,0,0,0,0,0,0,23,0,204,151,0,0,0,0,0,212,0,0,218,0,0
0,0,6,15,0,6,148,150,153,155,6,25,25,6,0,0,0,6,151,151,6,0,0,0,0,0,0,0,0,6,0,0,6,25,6,0,0,0,211,0,0,217,0,0
0,0,23,0,0,27,0,0,0,0,23,0,157,15,0,0,0,23,163,64,15,15,151,151,15,6,0,0,0,23,0,0,0,0,199,0,0,0,210,0,0,216,0,0
0,0,23,0,145,27,0,0,0,0,23,0,0,0,0,0,0,23,162,0,0,0,184,193,196,27,0,0,0,23,200,203,207,0,194,0,0,0,6,15,15,6,0,0
0,0,6,24,24,6,147,149,152,154,6,15,0,6,0,0,0,6,24,15,6,0,0,192,0,27,0,0,0,6,15,151,151,15,6,0,0,0,23,0,0,27,0,0
0,0,0,0,0,0,0,0,0,0,0,23,0,0,0,0,0,0,0,15,175,180,0,191,0,6,0,0,0,0,0,0,0,0,0,0,0,0,23,0,0,27,0,0
0,0,0,0,0,0,0,0,0,0,0,23,0,0,0,0,0,0,0,151,174,0,0,190,0,15,0,0,0,0,0,0,0,0,0,0,0,0,6,0,15,6,0,0
0,0,0,6,0,0,0,0,0,0,0,23,0,0,0,0,0,0,0,151,173,0,0,0,0,199,0,0,0,0,0,0,0,0,0,0,0,0,0,0,27,0,0,0
0,0,0,0,0,0,0,0,0,0,0,23,0,0,0,0,0,0,0,15,0,0,183,189,195,15,0,0,0,6,199,194,6,25,25,6,0,0,129,0,27,0,0,0
0,0,0,0,0,146,0,0,0,0,0,23,0,0,0,0,0,0,6,15,0,6,24,24,24,6,0,0,0,23,0,0,0,0,123,27,0,0,24,0,27,0,0,0
0,0,0,0,0,0,0,0,0,0,0,23,0,0,0,0,0,0,151,167,0,151,0,0,0,0,0,0,0,23,0,202,206,208,0,27,0,0,0,0,27,0,0,0
0,0,0,0,0,0,0,0,0,0,0,23,0,0,0,0,0,0,151,166,172,151,0,0,0,0,0,0,0,6,0,0,6,0,209,6,0,0,0,0,27,0,0,0
0,0,0,0,0,0,0,0,0,0,0,23,0,0,0,0,0,0,6,151,151,6,0,0,0,0,0,0,0,151,0,0,0,0,0,151,0,0,0,0,27,0,0,0
0,0,0,0,0,0,0,0,0,0,0,23,0,0,0,0,0,0,0,0,0,0,0,0,0,0,0,0,0,151,0,201,0,0,0,151,0,0,0,0,27,0,0,0
0,0,0,0,0,0,0,0,0,0,0,23,0,0,0,0,0,0,0,0,0,0,0,0,0,0,0,0,0,6,151,151,6,24,24,6,0,0,0,0,27,0,0,0
0,0,0,0,0,0,0,0,0,0,0,23,0,0,0,0,0,0,0,0,0,0,0,0,0,0,0,0,0,0,0,0,0,0,0,0,0,0,0,0,27,0,0,0
0,0,0,0,0,0,0,0,0,0,0,23,0,0,0,0,0,0,0,0,0,0,0,0,0,0,0,0,0,0,0,0,0,0,0,0,0,0,0,0,27,0,0,0
0,0,0,0,0,0,0,0,0,0,0,23,0,0,0,0,0,0,0,0,0,0,0,0,0,0,0,0,0,0,0,0,0,0,0,0,0,0,0,0,27,0,0,0
0,0,0,6,0,0,0,0,0,0,6,15,0,6,0,0,6,25,25,6,171,179,182,188,6,25,25,6,0,107,27,0,0,0,0,0,0,0,6,0,15,6,0,0
0,0,0,0,0,0,0,0,0,0,23,0,0,15,0,0,0,0,161,27,0,0,0,0,23,198,0,0,0,0,0,0,0,0,0,0,0,0,0,0,0,27,0,0
0,0,0,0,0,0,0,0,0,0,23,0,0,15,24,24,15,0,0,27,0,0,0,0,23,0,0,15,24,24,24,24,24,24,24,24,24,24,15,145,0,27,0,0
0,0,0,0,0,0,0,0,0,0,6,24,24,6,0,0,6,24,24,6,170,178,181,187,6,24,24,6,0,0,0,0,0,0,0,0,0,0,6,24,24,6,0,0
0,0,0,0,0,0,0,0,0,0,0,0,0,0,0,0,0,0,0,0,0,0,0,0,0,0,0,0,0,0,0,0,0,0,0,0,0,0,0,0,0,0,0,0
0,0,0,0,0,0,0,0,0,0,0,0,0,0,0,0,0,0,0,0,0,0,0,0,0,0,0,0,0,0,0,0,0,0,0,0,0,0,0,0,0,0,0,0
:endlayer
layer: 7
0,0,0,0,0,0,0,0,0,0,0,0,0,0,0,0,0,0,0,0,0,0,0,0,0,0,0,0,0,0,0,0,0,0,0,0,0,0,0,0,0,0,0,0
0,0,0,0,0,0,0,0,0,0,0,0,0,0,0,0,0,0,0,0,0,0,0,0,0,0,0,0,0,0,0,0,0,0,0,0,0,0,0,0,0,0,0,0
0,0,6,25,25,6,0,0,0,0,0,0,0,6,25,25,6,233,235,237,241,6,25,25,6,0,0,0,0,0,0,0,0,0,0,0,0,0,6,25,25,6,0,0
0,0,23,0,157,15,25,25,25,25,25,25,25,15,157,0,27,0,0,0,0,23,0,157,15,25,25,25,25,25,25,25,25,25,25,25,25,25,15,0,0,27,0,0
0,0,23,0,0,15,0,0,0,0,0,0,0,15,0,0,27,0,0,0,0,23,0,0,15,0,0,0,0,0,0,0,0,0,0,0,0,0,15,0,0,27,0,0
0,0,6,15,15,6,0,0,0,0,0,23,42,6,24,24,6,232,234,236,240,6,24,24,6,0,0,0,0,0,0,0,0,0,0,0,23,42,6,15,15,6,0,0
0,0,0,23,0,0,0,0,0,0,0,0,0,0,0,0,0,0,0,0,0,0,0,0,0,0,0,0,0,249,250,249,0,0,0,0,0,0,0,0,27,0,0,0
0,0,0,23,0,0,0,0,0,0,0,0,0,0,0,0,0,0,0,0,0,0,0,0,0,0,0,0,249,6,8,6,249,0,0,0,0,0,0,0,27,0,0,0
0,0,0,23,0,0,0,0,0,0,0,0,0,0,0,0,0,0,0,0,0,0,0,0,0,0,0,0,250,7,0,7,250,0,0,0,0,0,0,0,27,0,0,0
0,0,0,23,0,0,0,0,0,0,6,25,6,151,151,6,25,6,0,0,0,6,15,151,15,6,0,0,249,6,8,6,249,0,0,0,0,0,0,0,27,0,0,0
0,0,0,23,0,0,0,0,0,0,23,0,157,0,0,157,0,27,0,0,0,15,0,0,0,15,0,0,0,249,250,249,0,0,0,0,0,0,0,0,27,0,0,0
0,0,0,23,0,0,0,6,25,25,6,0,0,0,0,0,0,6,0,0,0,151,0,0,0,151,0,0,0,0,0,0,0,0,0,0,0,0,6,15,15,6,0,0
0,0,0,23,0,0,0,151,0,0,231,0,0,0,0,0,0,15,0,0,0,15,0,0,0,15,0,0,0,0,0,0,0,0,0,0,0,0,23,0,0,27,0,0
0,0,0,23,0,0,0,151,0,0,129,0,0,0,0,0,0,6,0,0,0,151,0,0,0,151,0,0,0,6,25,25,6,0,0,0,0,0,23,0,0,27,0,0
0,0,0,23,0,0,0,6,24,24,6,0,145,0,0,145,0,27,0,0,0,15,0,0,0,15,0,0,0,151,0,0,151,0,0,0,0,0,6,15,15,6,0,0
0,0,0,23,0,0,0,0,0,0,6,24,6,151,151,6,24,6,0,0,0,6,15,15,15,6,0,0,0,151,0,0,151,0,0,0,0,0,256,0,0,262,0,0
0,0,0,23,0,0,0,0,0,0,0,0,0,0,0,0,0,0,0,0,0,0,0,0,0,0,0,0,0,6,0,0,6,0,0,0,0,0,255,0,0,261,0,0
0,0,0,23,0,0,0,0,0,0,0,0,0,0,0,0,0,0,0,0,0,0,0,0,0,0,0,0,0,23,0,0,151,0,0,0,0,0,254,0,0,260,0,0
0,0,0,23,0,0,0,0,0,0,0,0,0,0,0,0,0,0,0,0,0,0,0,0,0,0,0,0,0,23,0,0,151,0,0,0,0,0,253,0,0,259,0,0
0,0,6,15,15,6,224,226,228,230,6,25,25,6,0,0,0,6,151,151,6,0,0,0,0,0,0,0,0,6,0,0,6,25,6,0,0,0,252,0,0,258,0,0
0,0,23,0,0,27,0,0,0,0,23,0,0,15,0,0,0,23,0,64,15,15,151,151,15,6,0,0,0,23,0,0,0,0,15,0,0,0,251,0,0,257,0,0
0,0,23,0,0,27,0,0,0,0,23,0,0,15,0,0,0,23,0,0,15,0,0,0,0,27,0,0,0,23,0,0,0,0,15,0,0,0,6,15,15,6,0,0
0,0,6,24,24,6,223,225,227,229,6,15,15,6,0,0,0,6,24,15,6,0,0,0,0,27,0,0,0,6,15,151,151,15,6,0,0,0,23,157,0,27,0,0
0,0,0,0,0,0,0,0,0,0,0,23,0,0,0,0,0,0,0,15,0,0,0,0,0,6,0,0,0,0,0,0,0,0,0,0,0,0,23,0,0,27,0,0
0,0,0,0,0,0,0,0,0,0,0,23,0,0,0,0,0,0,0,151,0,0,0,0,0,15,0,0,0,0,0,0,0,0,0,0,0,0,6,15,15,6,0,0
0,0,0,6,0,0,0,0,0,0,0,23,0,0,0,0,0,0,0,151,0,0,0,0,0,15,248,0,0,0,0,0,0,0,0,0,0,0,129,0,27,0,0,0
0,0,0,0,0,0,0,0,0,0,0,23,0,0,0,0,0,0,0,15,0,0,0,0,0,15,0,0,0,6,15,15,6,25,25,6,0,0,24,0,27,0,0,0
0,0,0,0,0,0,0,0,0,0,0,23,0,0,0,0,0,0,6,15,15,6,24,24,24,6,0,0,0,23,0,0,0,0,123,27,0,0,0,0,27,0,0,0
0,0,0,0,0,0,0,0,0,0,0,23,0,0,0,0,0,0,151,0,0,151,0,0,0,0,0,0,0,23,0,0,0,0,0,27,0,0,0,0,27,0,0,0
0,0,0,0,0,0,0,0,0,0,0,23,0,0,0,0,0,0,151,0,0,151,0,0,0,0,0,0,0,6,0,0,6,0,0,6,0,0,0,0,27,0,0,0
0,0,0,0,0,0,0,0,0,0,0,23,0,0,0,0,0,0,6,151,151,6,0,0,0,0,0,0,0,151,0,0,0,0,0,151,0,0,0,0,27,0,0,0
0,0,0,0,0,0,0,0,0,0,0,23,0,0,0,0,0,0,0,0,0,0,0,0,0,0,0,0,0,151,0,0,0,0,0,151,0,0,0,0,27,0,0,0
0,0,0,0,0,0,0,0,0,0,0,23,0,0,0,0,0,0,0,0,0,0,0,0,0,0,0,0,0,6,151,151,6,24,24,6,0,0,0,0,27,0,0,0
0,0,0,0,0,0,0,0,0,0,0,23,0,0,0,0,0,0,0,0,0,0,0,0,0,0,0,0,0,0,0,0,0,0,0,0,0,0,0,0,27,0,0,0
0,0,222,222,222,0,0,0,0,0,0,23,0,0,0,0,0,0,0,0,0,0,0,0,0,0,0,0,0,0,0,0,0,0,0,0,0,0,0,0,27,0,0,0
0,222,222,222,222,222,0,0,0,0,0,23,0,0,0,0,0,0,0,0,0,0,0,0,0,0,0,0,0,0,0,0,0,0,0,0,0,0,0,0,27,0,0,0
0,222,222,6,222,222,0,0,0,0,6,15,15,6,0,0,6,25,25,6,239,243,245,247,6,25,25,6,107,27,0,0,0,0,0,0,0,0,6,15,15,6,0,0
0,222,222,222,222,222,0,0,0,0,23,0,0,15,0,0,15,0,0,27,0,0,0,0,23,0,0,15,0,0,0,0,0,0,0,0,0,0,15,0,0,27,0,0
0,222,222,222,222,0,0,0,0,0,23,0,145,15,24,24,15,0,0,27,0,0,0,0,23,0,0,15,24,24,24,24,24,24,24,24,24,24,15,0,0,27,0,0
0,0,0,0,0,0,0,0,0,0,6,24,24,6,0,0,6,24,24,6,238,242,244,246,6,24,24,6,0,0,0,0,0,0,0,0,0,0,6,24,24,6,0,0
0,0,0,0,0,0,0,0,0,0,0,0,0,0,0,0,0,0,0,0,0,0,0,0,0,0,0,0,0,0,0,0,0,0,0,0,0,0,0,0,0,0,0,0
0,0,0,0,0,0,0,0,0,0,0,0,0,0,0,0,0,0,0,0,0,0,0,0,0,0,0,0,0,0,0,0,0,0,0,0,0,0,0,0,0,0,0,0
:endlayer
layer: 8
0,0,0,0,0,0,0,0,0,0,0,0,0,0,0,0,0,0,0,0,0,0,0,0,0,0,0,0,0,0,0,0,0,0,0,0,0,0,0,0,0,0,0,0
0,0,145,0,0,145,0,0,0,0,0,0,0,145,0,0,145,0,0,0,0,145,0,0,145,0,0,0,0,0,0,0,0,0,0,0,0,0,145,0,0,145,0,0
0,161,6,8,8,6,129,249,129,249,129,249,129,6,8,8,6,272,274,276,280,6,8,8,6,129,249,129,249,129,249,129,249,129,249,129,249,129,6,8,8,6,198,0
0,0,7,249,249,7,8,8,8,8,8,8,8,7,249,249,7,0,0,0,0,7,249,249,7,8,8,8,8,8,8,8,8,8,8,8,8,8,7,249,249,7,0,0
0,0,7,249,249,7,231,249,231,249,231,249,231,7,249,249,7,0,0,0,0,7,249,249,7,231,249,231,249,231,249,231,249,231,249,231,249,231,7,249,249,7,0,0
0,161,6,8,8,6,0,0,0,0,0,0,23,6,8,8,6,271,273,275,279,6,8,8,6,0,0,0,0,0,0,0,0,0,0,0,0,23,6,8,8,6,198,0
0,0,107,7,42,0,0,0,0,0,0,0,0,0,0,0,0,0,0,0,0,0,0,0,0,0,0,0,0,0,287,0,0,0,0,0,0,0,0,107,7,42,0,0
0,0,249,7,249,0,0,0,0,0,0,0,0,0,0,0,0,0,0,0,0,0,0,0,0,0,0,0,0,287,15,287,0,0,0,0,0,0,0,249,7,249,0,0
0,0,107,7,42,0,0,0,0,249,249,249,249,249,249,249,249,249,249,0,249,0,0,0,0,0,249,0,287,15,15,15,287,0,0,0,0,0,0,107,7,42,0,0
0,0,249,7,249,0,0,0,0,0,6,8,8,8,8,8,8,6,0,0,249,6,8,8,8,6,249,0,0,287,15,287,0,0,0,0,0,0,0,249,7,249,0,0
0,0,107,7,42,0,0,0,0,0,7,0,231,0,0,231,0,7,0,0,249,7,249,249,249,7,249,0,0,0,287,0,0,0,0,0,0,0,0,107,7,42,0,0
0,0,249,7,249,0,0,6,8,8,6,0,0,0,0,0,0,7,0,0,249,7,249,0,249,7,249,0,0,0,0,0,0,0,0,0,0,0,6,8,8,6,198,0
0,0,107,7,42,0,0,7,0,0,7,198,0,0,0,0,161,7,0,0,249,7,249,0,249,7,249,0,0,0,0,0,0,0,0,0,0,0,7,249,249,7,0,0
0,0,249,7,249,0,0,7,0,0,7,0,0,0,0,0,0,7,0,0,249,7,249,0,249,7,249,0,0,6,8,8,6,0,0,0,0,0,7,249,249,7,0,0
0,0,107,7,42,0,0,6,8,8,6,0,129,0,0,129,0,7,0,0,249,7,249,249,249,7,249,0,0,7,0,0,7,0,0,0,0,0,6,8,8,6,198,0
0,0,249,7,249,0,0,0,0,0,6,8,8,8,8,8,8,6,0,0,249,6,8,8,8,6,249,0,0,7,0,0,7,0,0,0,0,0,293,0,0,299,0,0
0,0,107,7,42,0,0,0,0,249,249,249,249,249,249,249,249,249,249,0,249,0,0,0,0,0,249,0,249,6,8,8,6,249,0,0,0,0,292,0,0,298,0,0
0,0,249,7,249,0,0,0,0,0,0,0,0,0,0,0,0,0,0,0,0,0,0,0,0,0,0,0,249,7,0,0,7,249,0,0,0,0,291,0,0,297,0,0
0,0,107,7,42,0,0,0,0,0,0,0,0,0,0,0,0,0,0,0,0,0,0,0,0,0,0,0,249,7,0,0,7,249,249,249,0,0,290,0,0,296,0,0
0,161,6,8,8,6,264,266,268,270,6,8,8,6,0,0,0,6,8,8,6,249,249,249,249,249,249,0,0,7,0,0,6,8,6,0,0,0,289,0,0,295,0,0
0,0,7,249,249,7,0,0,0,0,7,249,249,7,0,0,0,7,249,64,7,8,8,8,8,6,0,0,0,7,0,0,0,0,7,0,0,0,288,0,0,294,0,0
0,0,7,249,249,7,0,0,0,0,7,249,249,7,0,0,0,7,249,249,7,231,231,231,231,7,0,0,0,7,0,0,0,0,7,0,0,0,6,8,8,6,198,0
0,161,6,8,8,6,263,265,267,269,6,8,8,6,0,0,0,6,8,8,6,0,0,0,0,7,0,0,0,6,8,8,8,8,6,0,0,0,7,249,249,7,0,0
0,222,157,222,222,157,0,0,0,0,107,7,42,0,0,0,0,0,0,7,0,0,0,0,0,7,0,0,249,249,249,249,249,249,249,249,0,0,7,249,249,7,0,0
0,222,222,222,222,222,0,0,0,0,249,7,249,0,0,0,0,0,0,7,0,0,0,0,0,7,0,0,0,0,0,0,0,0,0,0,0,0,6,8,8,6,198,0
0,222,222,6,222,222,0,0,0,0,107,7,42,0,0,0,0,0,0,7,0,0,0,0,0,7,0,0,249,0,0,0,0,0,0,0,249,0,24,107,7,42,0,0
0,222,222,222,222,222,0,0,0,0,249,7,249,0,0,0,0,0,0,7,129,129,129,129,129,7,0,0,249,6,8,8,6,8,8,6,249,0,0,249,7,249,0,0
0,222,222,222,222,0,0,0,0,0,107,7,42,0,0,0,0,0,6,8,8,6,8,8,8,6,0,0,249,7,0,0,7,249,123,7,249,0,0,107,7,42,0,0
0,0,0,0,0,0,0,0,0,0,249,7,249,0,0,0,0,0,7,0,0,7,249,249,249,249,249,0,249,7,0,0,7,249,249,7,249,0,0,249,7,249,0,0
0,0,0,0,0,0,0,0,0,0,107,7,42,0,0,0,0,0,7,0,0,7,0,0,0,0,0,0,249,7,0,0,6,8,8,6,249,0,0,107,7,42,0,0
0,0,0,0,0,0,0,0,0,0,249,7,249,0,0,0,0,0,6,8,8,6,0,0,0,0,0,0,249,7,0,0,0,0,0,7,249,0,0,249,7,249,0,0
0,0,0,0,0,0,0,0,0,0,107,7,42,0,0,0,0,0,0,0,0,0,0,0,0,0,0,0,249,7,0,0,0,0,0,7,249,0,0,107,7,42,0,0
0,0,0,0,0,0,0,0,0,0,249,7,249,0,0,0,0,0,0,0,0,0,0,0,0,0,0,0,249,6,8,8,8,8,8,6,249,0,0,249,7,249,0,0
0,0,0,0,0,0,0,0,0,0,107,7,42,0,0,0,0,0,0,0,0,0,0,0,0,0,0,0,249,0,0,0,0,0,0,0,249,0,0,107,7,42,0,0
0,0,222,222,222,222,0,0,0,0,249,7,249,0,0,0,0,0,0,0,0,0,0,0,0,0,0,0,0,0,0,0,0,0,0,0,0,0,0,249,7,249,0,0
0,222,222,222,222,222,0,0,0,0,107,7,42,0,0,0,0,0,0,0,0,0,0,0,0,0,0,0,0,0,0,0,0,0,0,0,0,0,0,107,7,42,0,0
0,222,222,6,222,222,0,0,0,161,6,8,8,6,0,0,6,8,8,6,278,282,284,286,6,8,8,6,27,0,0,0,0,0,0,0,0,0,6,8,8,6,198,0
0,222,222,222,222,222,0,0,0,0,7,249,249,7,129,129,7,249,249,7,0,0,0,0,7,249,249,7,129,249,129,249,129,249,129,249,129,249,7,249,249,7,0,0
0,222,222,222,222,0,0,0,0,0,7,249,249,7,8,8,7,249,249,7,0,0,0,0,7,249,249,7,8,8,8,8,8,8,8,8,8,8,7,249,249,7,0,0
0,0,0,0,0,0,0,0,0,161,6,8,8,6,231,231,6,8,8,6,277,281,283,285,6,8,8,6,231,249,231,249,231,249,231,249,231,249,6,8,8,6,198,0
0,0,0,0,0,0,0,0,0,0,157,0,0,157,0,0,157,0,0,157,0,0,0,0,157,0,0,157,0,0,0,0,0,0,0,0,0,0,157,0,0,157,0,0
0,0,0,0,0,0,0,0,0,0,0,0,0,0,0,0,0,0,0,0,0,0,0,0,0,0,0,0,0,0,0,0,0,0,0,0,0,0,0,0,0,0,0,0
:endlayer
layer: 9
0,0,0,0,0,0,0,0,0,0,0,0,0,0,0,0,0,0,0,0,0,0,0,0,0,0,0,0,0,0,0,0,0,0,0,0,0,0,0,0,0,0,0,0
0,0,0,0,0,0,0,0,0,0,0,0,0,0,0,0,0,0,0,0,0,0,0,0,0,0,0,0,0,0,0,0,0,0,0,0,0,0,0,0,0,0,0,0
0,0,6,25,25,6,24,15,24,15,24,15,24,6,25,25,6,309,313,315,317,6,25,25,6,24,15,24,15,24,15,24,15,24,15,24,15,24,6,25,25,6,0,0
0,0,23,302,0,0,0,0,0,0,303,0,0,0,0,307,23,42,0,0,107,27,318,0,0,0,0,0,0,0,0,320,0,0,0,0,0,0,0,0,334,27,0,0
0,0,23,0,0,0,0,0,0,0,0,0,0,0,0,0,23,42,0,0,107,27,0,0,0,0,0,0,0,0,0,0,0,0,0,0,0,0,0,0,0,27,0,0
0,0,6,0,0,6,0,0,0,0,0,0,0,6,24,24,6,308,312,314,316,6,24,24,6,0,0,0,0,0,0,0,0,0,0,0,0,0,6,0,0,6,0,0
0,0,27,0,0,0,0,0,0,0,0,0,0,0,0,0,0,0,0,0,0,0,0,0,0,0,0,0,0,0,0,0,0,0,0,0,0,0,0,0,0,23,0,0
0,0,15,0,0,0,0,0,0,0,0,0,0,0,0,0,0,0,0,0,0,0,0,0,0,0,0,0,0,0,0,0,0,0,0,0,0,0,0,0,0,15,0,0
0,0,27,0,0,0,0,0,0,0,0,0,0,0,0,0,0,0,0,0,0,287,249,0,249,287,0,0,0,0,287,0,0,0,0,0,0,0,0,0,333,23,0,0
0,0,15,0,0,0,0,0,0,287,287,287,287,287,287,287,287,287,287,0,0,287,15,15,15,287,0,0,0,0,0,0,0,0,0,0,0,0,0,0,0,15,0,0
0,0,27,0,0,0,0,0,0,249,15,15,15,15,15,15,15,15,249,0,0,287,15,15,15,287,0,0,0,0,0,0,0,0,0,0,0,0,0,0,0,23,0,0
0,0,15,0,0,0,0,6,25,25,6,249,231,249,249,231,249,15,0,0,0,287,15,15,15,287,0,0,0,0,0,0,0,0,0,0,0,0,6,0,0,6,0,0
0,0,27,301,0,0,0,23,0,0,15,0,249,0,0,249,0,250,0,0,0,287,15,15,15,287,0,0,0,0,0,0,0,0,0,0,0,0,23,0,0,27,0,0
0,0,15,0,0,0,0,23,0,0,15,249,129,249,249,129,249,15,0,0,0,287,15,15,15,287,0,0,0,6,15,15,6,0,0,0,0,0,23,0,332,27,0,0
0,0,27,0,0,0,0,6,24,15,6,15,15,15,15,15,15,15,249,0,0,287,15,15,15,287,0,0,0,15,0,0,15,0,0,0,0,0,6,25,25,6,0,0
0,0,15,0,0,0,0,0,0,287,287,287,287,287,287,287,287,287,287,0,0,287,15,15,15,287,0,0,0,15,0,0,15,0,0,0,0,0,328,231,231,340,0,0
0,0,27,0,0,0,0,0,0,0,0,0,0,0,0,0,0,0,0,0,0,287,249,0,249,287,0,0,0,6,15,15,6,0,0,0,0,0,327,0,0,339,0,0
0,0,15,0,0,0,0,0,0,0,0,0,0,0,0,0,0,0,0,0,0,0,0,0,0,0,0,0,0,287,15,15,287,0,0,0,0,0,326,0,0,338,0,0
0,0,27,0,0,0,0,0,0,0,0,0,0,0,0,0,0,0,0,0,0,0,0,0,0,0,0,0,0,287,15,15,287,0,0,0,0,0,325,0,0,337,0,0
0,0,6,0,0,6,8,8,8,8,6,25,25,6,0,0,0,6,15,15,6,0,0,0,0,0,0,0,287,287,15,15,287,287,287,287,0,0,324,0,0,336,0,0
0,0,23,0,0,23,15,15,15,15,27,0,306,27,0,0,0,15,311,64,15,287,287,287,287,287,287,0,249,15,15,15,15,15,15,249,0,0,323,129,129,335,0,0
0,0,23,300,0,23,15,15,15,15,27,0,0,27,0,0,0,15,108,102,15,15,15,15,15,15,249,0,249,15,15,15,15,15,15,249,0,0,6,24,24,6,0,0
0,0,6,24,24,6,8,8,8,8,6,0,0,6,0,0,0,6,15,15,6,231,231,231,231,15,0,0,287,287,287,287,287,287,287,287,0,0,23,0,331,27,0,0
0,222,222,222,222,0,0,0,0,0,27,0,0,0,0,0,0,0,0,15,249,0,249,0,249,15,0,0,0,0,0,0,0,0,0,0,0,0,23,0,0,27,0,0
0,222,222,222,222,222,0,0,0,0,15,0,0,0,0,0,0,0,0,15,249,0,249,0,249,15,0,0,0,0,0,0,0,0,0,0,0,0,6,0,0,6,0,0
0,222,222,6,222,222,0,0,0,0,27,0,0,0,0,0,0,0,0,15,129,129,129,129,129,15,0,0,0,287,249,0,0,0,249,287,0,0,0,0,0,23,0,0
0,222,222,222,222,222,0,0,0,0,15,0,0,0,0,0,0,0,249,15,15,15,15,15,15,15,249,0,0,287,15,15,6,15,15,6,0,0,0,0,0,15,0,0
0,0,222,222,222,222,0,0,0,0,27,0,0,0,0,0,0,0,6,15,15,6,287,287,287,287,287,0,0,287,15,15,15,102,123,15,0,0,0,0,0,23,0,0
0,0,0,0,0,0,0,0,0,0,15,0,0,0,0,0,0,0,151,0,0,151,0,0,0,0,0,0,0,287,15,15,15,322,0,15,0,0,0,0,0,15,0,0
0,0,0,0,0,0,0,0,0,0,27,0,0,0,0,0,0,0,151,0,0,151,0,0,0,0,0,0,0,287,15,15,6,15,15,6,0,0,0,0,330,23,0,0
0,0,0,0,0,0,0,0,0,0,15,0,0,0,0,0,0,0,6,151,151,6,0,0,0,0,0,0,0,287,15,15,15,15,15,287,0,0,0,0,0,15,0,0
0,0,0,0,0,0,0,0,0,0,27,305,0,0,0,0,0,0,0,0,0,0,0,0,0,0,0,0,0,287,15,15,15,15,15,287,0,0,0,0,0,23,0,0
0,0,0,0,0,0,0,0,0,0,15,0,0,0,0,0,0,0,0,0,0,0,0,0,0,0,0,0,0,287,15,15,15,15,15,287,0,0,0,0,0,15,0,0
0,0,0,0,0,0,0,0,0,0,27,0,0,0,0,0,0,0,0,0,0,0,0,0,0,0,0,0,0,287,249,0,0,0,249,287,0,0,0,0,0,23,0,0
0,0,0,0,0,0,0,0,0,0,15,0,0,0,0,0,0,0,0,0,0,0,0,0,0,0,0,0,0,0,0,0,0,0,0,0,0,0,0,0,0,15,0,0
0,0,222,222,222,0,0,0,0,0,27,0,0,0,0,0,0,0,0,0,0,0,0,0,0,0,0,0,0,0,0,0,0,0,0,0,0,0,0,0,0,23,0,0
0,0,222,6,222,0,0,0,0,0,6,0,0,6,0,0,6,25,25,6,8,8,8,8,6,25,25,6,0,0,0,0,0,0,0,0,0,0,6,0,0,6,0,0
0,0,222,222,0,0,0,0,0,0,23,0,0,0,0,0,0,0,0,23,15,15,15,15,27,0,0,0,0,0,0,0,0,0,0,0,0,0,0,0,0,27,0,0
0,0,0,0,0,0,0,0,0,0,23,304,0,0,0,0,0,0,310,23,15,15,15,15,27,319,0,0,0,0,0,0,321,0,0,0,0,0,0,0,329,27,0,0
0,0,0,0,0,0,0,0,0,0,6,24,24,6,25,25,6,24,24,6,8,8,8,8,6,24,24,6,25,15,25,15,25,15,25,15,25,15,6,24,24,6,0,0
0,0,0,0,0,0,0,0,0,0,0,0,0,0,0,0,0,0,0,0,0,0,0,0,0,0,0,0,0,0,0,0,0,0,0,0,0,0,0,0,0,0,0,0
0,0,0,0,0,0,0,0,0,0,0,0,0,0,0,0,0,0,0,0,0,0,0,0,0,0,0,0,0,0,0,0,0,0,0,0,0,0,0,0,0,0,0,0
:endlayer
layer: 10
0,0,0,0,0,0,0,0,0,0,0,0,0,0,0,0,0,0,0,0,0,0,0,0,0,0,0,0,0,0,0,0,0,0,0,0,0,0,0,0,0,0,0,0
0,0,0,0,0,0,0,0,0,0,0,0,0,0,0,0,0,0,0,0,0,0,0,0,0,0,0,0,0,0,0,0,0,0,0,0,0,0,0,0,0,0,0,0
0,0,6,0,0,6,0,287,0,287,0,287,0,6,0,0,6,8,8,8,8,6,0,0,6,0,287,0,287,0,287,0,287,0,287,0,287,0,6,0,0,6,0,0
0,0,0,0,0,0,0,0,0,0,0,0,0,0,0,0,0,23,15,15,27,0,0,0,0,0,0,0,0,0,0,0,0,0,0,0,0,0,0,0,0,0,0,0
0,0,0,0,0,0,0,0,0,0,0,0,0,0,0,0,0,23,15,15,27,0,0,0,0,0,0,0,0,0,0,0,0,0,0,0,0,0,0,0,0,0,0,0
0,0,6,0,0,6,0,0,0,0,0,0,0,6,0,0,6,8,8,8,8,6,0,0,6,0,0,0,0,0,0,0,0,0,0,0,0,0,6,0,0,6,0,0
0,0,0,0,0,0,0,0,0,0,0,0,0,0,0,0,0,0,0,0,0,0,0,0,0,0,0,0,0,0,0,0,0,0,0,0,0,0,0,0,0,0,0,0
0,0,287,0,0,0,0,0,0,0,0,0,0,0,0,0,0,0,0,0,0,0,0,0,0,0,0,0,0,0,0,0,0,0,0,0,0,0,0,0,0,287,0,0
0,0,0,0,0,0,0,0,0,0,0,0,0,0,0,0,0,0,0,0,0,0,0,287,0,0,0,0,0,0,0,0,0,0,0,0,0,0,0,0,0,0,0,0
0,0,287,0,0,0,0,0,0,0,0,0,0,0,0,0,0,0,0,0,0,0,0,287,0,0,0,0,0,0,0,0,0,0,0,0,0,0,0,0,0,287,0,0
0,0,0,0,0,0,0,0,0,0,0,0,0,0,0,0,0,0,0,0,0,0,0,287,0,0,0,0,0,0,0,0,0,0,0,0,0,0,0,0,0,0,0,0
0,0,287,0,0,0,0,6,25,25,6,287,287,287,287,287,287,287,287,0,0,0,0,287,0,0,0,0,0,0,0,0,0,0,0,0,0,0,6,0,0,6,0,0
0,0,0,0,0,0,0,23,0,0,15,15,15,15,15,15,15,15,249,0,0,0,0,287,0,0,0,0,0,0,0,0,0,0,0,0,0,0,0,0,0,0,0,0
0,0,287,0,0,0,0,23,0,0,15,287,287,287,287,287,287,287,287,0,0,0,0,287,0,0,0,0,0,6,151,151,6,0,0,0,0,0,0,0,0,0,0,0
0,0,0,0,0,0,0,6,24,24,6,0,0,0,0,0,0,0,0,0,0,0,0,287,0,0,0,0,0,151,0,0,151,0,0,0,0,0,6,0,0,6,0,0
0,0,287,0,0,0,0,0,0,0,0,0,0,0,0,0,0,0,0,0,0,0,0,287,0,0,0,0,0,151,0,0,151,0,0,0,0,0,7,25,25,7,0,0
0,0,0,0,0,0,0,0,0,0,0,0,0,0,0,0,0,0,0,0,0,0,0,287,0,0,0,0,0,6,15,15,6,0,0,0,0,0,7,15,15,7,0,0
0,0,287,0,0,0,0,0,0,0,0,0,0,0,0,0,0,0,0,0,0,0,0,0,0,0,0,0,0,0,0,0,0,0,0,0,0,0,7,15,15,7,0,0
0,0,0,0,0,0,0,0,0,0,0,0,0,0,0,0,0,0,0,0,0,0,0,0,0,0,0,0,0,0,0,0,0,0,0,0,0,0,7,15,15,7,0,0
0,0,6,0,0,6,24,287,287,24,6,0,0,6,0,0,0,6,151,151,6,0,0,0,0,0,0,0,0,0,0,0,0,0,0,0,0,0,7,15,15,7,0,0
0,0,0,0,0,0,0,0,0,0,0,0,0,0,0,0,0,151,0,64,15,0,0,0,0,0,0,0,0,0,0,0,0,0,0,0,0,0,7,24,24,7,0,0
0,0,0,0,0,0,0,0,0,0,0,0,0,0,0,0,0,151,0,341,15,0,0,0,0,0,0,0,0,0,0,0,0,0,0,0,0,0,6,0,0,6,0,0
0,0,6,0,0,6,25,15,15,25,6,0,0,6,0,0,0,6,15,15,6,287,287,287,287,287,287,0,0,0,0,0,0,0,0,0,0,0,0,0,0,0,0,0
0,0,0,0,0,0,0,0,0,0,0,0,0,0,0,0,0,0,249,15,15,15,15,15,15,15,249,0,0,0,0,0,0,0,0,0,0,0,0,0,0,0,0,0
0,0,0,222,222,0,0,0,0,0,287,0,0,0,0,0,0,0,249,15,15,15,15,15,15,15,249,0,0,0,0,0,0,0,0,0,0,0,6,0,0,6,0,0
0,0,222,6,222,0,0,0,0,0,0,0,0,0,0,0,0,0,287,287,287,287,287,287,287,287,287,0,0,0,0,287,249,287,0,0,0,0,0,0,0,0,0,0
0,0,222,222,0,0,0,0,0,0,287,0,0,0,0,0,0,0,0,0,0,0,0,0,0,0,0,0,0,0,0,287,6,15,15,6,0,0,0,0,0,287,0,0
0,0,0,0,0,0,0,0,0,0,0,0,0,0,0,0,0,0,6,15,15,6,0,0,0,0,0,0,0,0,0,287,15,342,123,151,0,0,0,0,0,0,0,0
0,0,0,0,0,0,0,0,0,0,287,0,0,0,0,0,0,0,151,0,0,151,0,0,0,0,0,0,0,0,0,287,15,0,0,151,0,0,0,0,0,287,0,0
0,0,0,0,0,0,0,0,0,0,0,0,0,0,0,0,0,0,151,0,0,151,0,0,0,0,0,0,0,0,0,287,6,15,15,6,0,0,0,0,0,0,0,0
0,0,0,0,0,0,0,0,0,0,287,0,0,0,0,0,0,0,6,151,151,6,0,0,0,0,0,0,0,0,0,287,15,287,0,0,0,0,0,0,0,287,0,0
0,0,0,0,0,0,0,0,0,0,0,0,0,0,0,0,0,0,0,0,0,0,0,0,0,0,0,0,0,0,0,287,15,287,0,0,0,0,0,0,0,0,0,0
0,0,0,0,0,0,0,0,0,0,287,0,0,0,0,0,0,0,0,0,0,0,0,0,0,0,0,0,0,0,0,287,15,287,0,0,0,0,0,0,0,287,0,0
0,0,0,0,0,0,0,0,0,0,0,0,0,0,0,0,0,0,0,0,0,0,0,0,0,0,0,0,0,0,0,287,249,287,0,0,0,0,0,0,0,0,0,0
0,0,0,0,0,0,0,0,0,0,287,0,0,0,0,0,0,0,0,0,0,0,0,0,0,0,0,0,0,0,0,0,0,0,0,0,0,0,0,0,0,287,0,0
0,0,0,222,0,0,0,0,0,0,0,0,0,0,0,0,0,0,0,0,0,0,0,0,0,0,0,0,0,0,0,0,0,0,0,0,0,0,0,0,0,0,0,0
0,0,222,222,222,0,0,0,0,0,6,0,0,6,0,0,6,0,0,6,24,287,287,24,6,0,0,6,0,0,0,0,0,0,0,0,0,0,6,0,0,6,0,0
0,0,0,222,0,0,0,0,0,0,0,0,0,0,0,0,0,0,0,0,0,0,0,0,0,0,0,0,0,0,0,0,0,0,0,0,0,0,0,0,0,0,0,0
0,0,0,0,0,0,0,0,0,0,0,0,0,0,0,0,0,0,0,0,0,0,0,0,0,0,0,0,0,0,0,0,0,0,0,0,0,0,0,0,0,0,0,0
0,0,0,0,0,0,0,0,0,0,6,0,0,6,0,0,6,0,0,6,25,15,15,25,6,0,0,6,0,287,0,287,0,287,0,287,0,287,6,0,0,6,0,0
0,0,0,0,0,0,0,0,0,0,0,0,0,0,0,0,0,0,0,0,0,0,0,0,0,0,0,0,0,0,0,0,0,0,0,0,0,0,0,0,0,0,0,0
0,0,0,0,0,0,0,0,0,0,0,0,0,0,0,0,0,0,0,0,0,0,0,0,0,0,0,0,0,0,0,0,0,0,0,0,0,0,0,0,0,0,0,0
:endlayer
layer: 11
0,0,0,0,0,0,0,0,0,0,0,0,0,0,0,0,0,0,0,0,0,0,0,0,0,0,0,0,0,0,0,0,0,0,0,0,0,0,0,0,0,0,0,0
0,0,0,0,0,0,0,0,0,0,0,0,0,0,0,0,0,0,0,0,0,0,0,0,0,0,0,0,0,0,0,0,0,0,0,0,0,0,0,0,0,0,0,0
0,0,6,129,129,6,0,0,0,0,0,0,0,6,129,129,6,24,15,15,24,6,129,129,6,0,0,0,0,0,0,0,0,0,0,0,0,0,6,129,129,6,0,0
0,0,107,0,0,0,0,0,0,0,0,0,0,0,0,0,0,0,0,0,0,0,0,0,0,0,0,0,0,0,0,0,0,0,0,0,0,0,0,0,0,42,0,0
0,0,107,0,0,0,0,0,0,0,0,0,0,0,0,0,0,0,0,0,0,0,0,0,0,0,0,0,0,0,0,0,0,0,0,0,0,0,0,0,0,42,0,0
0,0,6,0,0,6,0,0,0,0,0,0,0,6,231,231,6,25,287,287,25,6,231,231,6,0,0,0,0,0,0,0,0,0,0,0,0,0,6,0,0,6,0,0
0,0,0,0,0,0,0,0,0,0,0,0,0,0,0,0,0,0,0,0,0,0,0,0,0,0,0,0,0,0,0,0,0,0,0,0,0,0,0,0,0,0,0,0
0,0,0,0,0,0,0,0,0,0,0,0,0,0,0,0,0,0,0,0,0,0,0,0,0,0,0,0,0,0,0,0,0,0,0,0,0,0,0,0,0,0,0,0
0,0,0,0,0,0,0,0,0,0,0,0,0,0,0,0,0,0,0,0,0,0,0,0,0,0,0,0,0,0,0,0,0,0,0,0,0,0,0,0,0,0,0,0
0,0,0,0,0,0,0,0,0,0,0,0,0,0,0,0,0,0,0,0,0,0,0,0,0,0,0,0,0,0,0,0,0,0,0,0,0,0,0,0,0,0,0,0
0,0,0,0,0,0,0,0,0,0,0,0,0,0,0,0,0,0,0,0,0,0,0,0,0,0,0,0,0,0,0,0,0,0,0,0,0,0,0,0,0,0,0,0
0,0,0,0,0,0,0,6,25,25,6,0,0,0,0,0,0,0,0,0,0,0,0,0,0,0,0,0,0,0,0,0,0,0,0,0,0,0,6,0,0,6,0,0
0,0,0,0,0,0,0,23,0,0,15,0,0,0,0,0,0,0,0,0,0,0,0,0,0,0,0,0,0,0,0,0,0,0,0,0,0,0,107,0,0,42,0,0
0,0,0,0,0,0,0,23,0,0,15,0,0,0,0,0,0,0,0,0,0,0,0,0,0,0,0,0,0,6,151,151,6,0,0,0,0,0,107,0,0,42,0,0
0,0,0,0,0,0,0,6,24,24,6,0,0,0,0,0,0,0,0,0,0,0,0,0,0,0,0,0,0,151,0,0,151,0,0,0,0,0,6,0,0,6,0,0
0,0,0,0,0,0,0,0,0,0,0,0,0,0,0,0,0,0,0,0,0,0,0,0,0,0,0,0,0,151,0,0,151,0,0,0,0,0,27,0,0,23,0,0
0,0,0,0,0,0,0,0,0,0,0,0,0,0,0,0,0,0,0,0,0,0,0,0,0,0,0,0,0,6,15,15,6,0,0,0,0,0,287,0,0,15,0,0
0,0,0,0,0,0,0,0,0,0,0,0,0,0,0,0,0,0,0,0,0,0,0,0,0,0,0,0,0,0,0,0,0,0,0,0,0,0,287,0,343,23,0,0
0,0,0,0,0,0,0,0,0,0,0,0,0,0,0,0,0,0,0,0,0,0,0,0,0,0,0,0,0,0,0,0,0,0,0,0,0,0,287,0,0,23,0,0
0,0,6,0,0,6,0,0,0,0,6,129,129,6,0,0,0,6,151,151,6,0,0,0,0,0,0,0,0,0,0,0,0,0,0,0,0,0,287,0,0,15,0,0
0,0,107,0,0,0,0,0,0,0,0,0,0,42,0,0,0,151,0,64,15,0,0,0,0,0,0,0,0,0,0,0,0,0,0,0,0,0,27,0,0,23,0,0
0,0,107,0,0,0,0,0,0,0,0,0,0,42,0,0,0,151,0,0,15,0,0,0,0,0,0,0,0,0,0,0,0,0,0,0,0,0,6,0,0,6,0,0
0,0,6,231,231,6,0,287,287,0,6,0,0,6,0,0,0,6,15,15,6,0,0,0,0,0,0,0,0,0,0,0,0,0,0,0,0,0,107,0,0,42,0,0
0,0,0,0,0,0,0,0,0,0,0,0,0,0,0,0,0,0,0,0,0,0,0,0,0,0,0,0,0,0,0,0,0,0,0,0,0,0,107,0,0,42,0,0
0,0,0,222,0,0,0,0,0,0,0,0,0,0,0,0,0,0,0,0,0,0,0,0,0,0,0,0,0,0,0,0,0,0,0,0,0,0,6,0,0,6,0,0
0,0,222,222,222,0,0,0,0,0,0,0,0,0,0,0,0,0,0,0,0,0,0,0,0,0,0,0,0,0,0,0,0,0,0,0,0,0,0,0,0,0,0,0
0,0,0,222,0,0,0,0,0,0,0,0,0,0,0,0,0,0,249,0,0,249,0,0,0,0,0,0,0,0,0,0,6,15,15,6,0,0,0,0,0,0,0,0
0,0,0,0,0,0,0,0,0,0,0,0,0,0,0,0,0,249,6,8,8,6,249,0,0,0,0,0,0,0,0,0,15,0,123,151,0,0,0,0,0,0,0,0
0,0,0,0,0,0,0,0,0,0,0,0,0,0,0,0,0,0,7,0,0,7,0,0,0,0,0,0,0,0,0,0,15,0,0,151,0,0,0,0,0,0,0,0
0,0,0,0,0,0,0,0,0,0,0,0,0,0,0,0,0,0,7,0,0,7,0,0,0,0,0,0,0,0,0,0,6,15,15,6,0,0,0,0,0,0,0,0
0,0,0,0,0,0,0,0,0,0,0,0,0,0,0,0,0,249,6,8,8,6,249,0,0,0,0,0,0,0,0,0,0,0,0,0,0,0,0,0,0,0,0,0
0,0,0,0,0,0,0,0,0,0,0,0,0,0,0,0,0,0,249,0,0,249,0,0,0,0,0,0,0,0,0,0,0,0,0,0,0,0,0,0,0,0,0,0
0,0,0,0,0,0,0,0,0,0,0,0,0,0,0,0,0,0,0,0,0,0,0,0,0,0,0,0,0,0,0,0,0,0,0,0,0,0,0,0,0,0,0,0
0,0,0,0,0,0,0,0,0,0,0,0,0,0,0,0,0,0,0,0,0,0,0,0,0,0,0,0,0,0,0,0,0,0,0,0,0,0,0,0,0,0,0,0
0,0,0,0,0,0,0,0,0,0,0,0,0,0,0,0,0,0,0,0,0,0,0,0,0,0,0,0,0,0,0,0,0,0,0,0,0,0,0,0,0,0,0,0
0,0,0,0,0,0,0,0,0,0,0,0,0,0,0,0,0,0,0,0,0,0,0,0,0,0,0,0,0,0,0,0,0,0,0,0,0,0,0,0,0,0,0,0
0,0,0,0,0,0,0,0,0,0,6,0,0,6,0,0,6,129,129,6,0,0,0,0,6,129,129,6,0,0,0,0,0,0,0,0,0,0,6,0,0,6,0,0
0,0,0,0,0,0,0,0,0,0,107,0,0,0,0,0,0,0,0,0,0,0,0,0,0,0,0,0,0,0,0,0,0,0,0,0,0,0,0,0,0,42,0,0
0,0,0,0,0,0,0,0,0,0,107,0,0,0,0,0,0,0,0,0,0,0,0,0,0,0,0,0,0,0,0,0,0,0,0,0,0,0,0,0,0,42,0,0
0,0,0,0,0,0,0,0,0,0,6,231,231,6,0,0,6,231,231,6,0,287,287,0,6,231,231,6,0,0,0,0,0,0,0,0,0,0,6,231,231,6,0,0
0,0,0,0,0,0,0,0,0,0,0,0,0,0,0,0,0,0,0,0,0,0,0,0,0,0,0,0,0,0,0,0,0,0,0,0,0,0,0,0,0,0,0,0
0,0,0,0,0,0,0,0,0,0,0,0,0,0,0,0,0,0,0,0,0,0,0,0,0,0,0,0,0,0,0,0,0,0,0,0,0,0,0,0,0,0,0,0
:endlayer
layer: 12
0,0,0,0,0,0,0,0,0,0,0,0,0,0,0,0,0,0,0,0,0,0,0,0,0,0,0,0,0,0,0,0,0,0,0,0,0,0,0,0,0,0,0,0
0,0,249,0,0,249,0,0,0,0,0,0,0,0,0,0,0,0,0,0,0,0,0,0,0,0,0,0,0,0,0,0,0,0,0,0,0,0,249,0,0,249,0,0
0,249,6,8,8,6,249,0,0,0,0,0,0,6,8,8,6,0,287,287,0,6,8,8,6,0,0,0,0,0,0,0,0,0,0,0,0,249,6,8,8,6,249,0
0,0,7,0,0,7,0,0,0,0,0,0,0,7,0,0,0,0,0,0,0,0,0,0,7,0,0,0,0,0,0,0,0,0,0,0,0,0,7,0,0,7,0,0
0,0,7,0,0,7,0,0,0,0,0,0,0,7,0,0,0,0,0,0,0,0,0,0,7,0,0,0,0,0,0,0,0,0,0,0,0,0,7,0,0,7,0,0
0,249,6,8,8,6,249,0,0,0,0,0,0,6,8,8,6,0,0,0,0,6,8,8,6,0,0,0,0,0,0,0,0,0,0,0,0,249,6,8,8,6,249,0
0,0,249,0,0,249,0,0,0,0,0,0,0,0,0,0,0,0,0,0,0,0,0,0,0,0,0,0,0,0,0,0,0,0,0,0,0,0,249,0,0,249,0,0
0,0,0,0,0,0,0,0,0,0,0,0,0,0,0,0,0,0,0,0,0,0,0,0,0,0,0,0,0,0,0,0,0,0,0,0,0,0,0,0,0,0,0,0
0,0,0,0,0,0,0,0,0,0,0,0,0,0,0,0,0,0,0,0,0,0,0,0,0,0,0,0,0,0,0,0,0,0,0,0,0,0,0,0,0,0,0,0
0,0,0,0,0,0,0,0,0,0,0,0,0,0,0,0,0,0,0,0,0,0,0,0,0,0,0,0,0,0,0,0,0,0,0,0,0,0,0,0,0,0,0,0
0,0,0,0,0,0,0,0,0,0,0,0,0,0,0,0,0,0,0,0,0,0,0,0,0,0,0,0,0,0,0,0,0,0,0,0,0,0,0,0,0,0,0,0
0,0,0,0,0,0,0,6,8,8,6,0,0,0,0,0,0,0,0,0,0,0,0,0,0,0,0,0,0,0,0,0,0,0,0,0,0,0,6,8,8,6,0,0
0,0,0,0,0,0,0,7,0,0,7,0,0,0,0,0,0,0,0,0,0,0,0,0,0,0,0,0,0,0,0,0,0,0,0,0,0,0,7,0,0,7,0,0
0,0,0,0,0,0,0,7,0,0,7,0,0,0,0,0,0,0,0,0,0,0,0,0,0,0,0,0,0,6,8,8,6,0,0,0,0,0,7,0,0,7,0,0
0,0,0,0,0,0,0,6,8,8,6,0,0,0,0,0,0,0,0,0,0,0,0,0,0,0,0,0,0,7,0,0,7,0,0,0,0,0,6,0,0,6,0,0
0,0,0,0,0,0,0,0,0,0,0,0,0,0,0,0,0,0,0,0,0,0,0,0,0,0,0,0,0,7,0,0,7,0,0,0,0,0,0,0,0,0,0,0
0,0,0,0,0,0,0,0,0,0,0,0,0,0,0,0,0,0,0,0,0,0,0,0,0,0,0,0,0,6,8,8,6,0,0,0,0,0,0,0,0,287,0,0
0,0,0,0,0,0,0,0,0,0,0,0,0,0,0,0,0,0,0,0,0,0,0,0,0,0,0,0,0,0,0,0,0,0,0,0,0,0,0,0,0,0,0,0
0,0,0,0,0,0,0,0,0,0,0,0,0,0,0,0,0,249,0,0,249,0,0,0,0,0,0,0,0,0,0,0,0,0,0,0,0,0,0,0,0,0,0,0
0,0,6,8,8,6,0,0,0,0,6,8,8,6,0,0,249,6,8,8,6,249,0,0,0,0,0,0,0,0,0,0,0,0,0,0,0,0,0,0,0,287,0,0
0,0,7,0,0,0,0,0,0,0,0,0,0,7,0,0,0,7,0,64,7,0,0,0,0,0,0,0,0,0,0,0,0,0,0,0,0,0,0,0,0,0,0,0
0,0,7,0,0,0,0,0,0,0,0,0,0,7,0,0,0,7,0,0,7,0,0,0,0,0,0,0,0,0,0,0,0,0,0,0,0,0,6,0,0,6,0,0
0,0,6,8,8,6,0,0,0,0,6,8,8,6,0,0,249,6,8,8,6,249,0,0,0,0,0,0,0,0,0,0,0,0,0,0,0,0,7,0,0,7,0,0
0,0,0,0,0,0,0,0,0,0,0,0,0,0,0,0,0,249,0,0,249,0,0,0,0,0,0,0,0,0,0,0,0,0,0,0,0,0,7,0,0,7,0,0
0,0,0,0,0,0,0,0,0,0,0,0,0,0,0,0,0,0,0,0,0,0,0,0,0,0,0,0,0,0,0,0,0,0,0,0,0,0,6,8,8,6,0,0
0,0,0,0,0,0,0,0,0,0,0,0,0,0,0,0,0,0,0,0,0,0,0,0,0,0,0,0,0,0,0,0,249,0,0,249,0,0,0,0,0,0,0,0
0,0,0,0,0,0,0,0,0,0,0,0,0,0,0,0,0,0,0,287,287,0,0,0,0,0,0,0,0,0,0,249,6,8,8,6,249,0,0,0,0,0,0,0
0,0,0,0,0,0,0,0,0,0,0,0,0,0,0,0,0,0,287,15,15,287,0,0,0,0,0,0,0,0,0,0,7,0,0,7,0,0,0,0,0,0,0,0
0,0,0,0,0,0,0,0,0,0,0,0,0,0,0,0,0,287,15,15,15,15,287,0,0,0,0,0,0,0,0,0,7,0,0,7,0,0,0,0,0,0,0,0
0,0,0,0,0,0,0,0,0,0,0,0,0,0,0,0,0,287,15,15,15,15,287,0,0,0,0,0,0,0,0,249,6,8,8,6,249,0,0,0,0,0,0,0
0,0,0,0,0,0,0,0,0,0,0,0,0,0,0,0,0,0,287,15,15,287,0,0,0,0,0,0,0,0,0,0,249,0,0,249,0,0,0,0,0,0,0,0
0,0,0,0,0,0,0,0,0,0,0,0,0,0,0,0,0,0,0,287,287,0,0,0,0,0,0,0,0,0,0,0,0,0,0,0,0,0,0,0,0,0,0,0
0,0,0,0,0,0,0,0,0,0,0,0,0,0,0,0,0,0,0,0,0,0,0,0,0,0,0,0,0,0,0,0,0,0,0,0,0,0,0,0,0,0,0,0
0,0,0,0,0,0,0,0,0,0,0,0,0,0,0,0,0,0,0,0,0,0,0,0,0,0,0,0,0,0,0,0,0,0,0,0,0,0,0,0,0,0,0,0
0,0,0,0,0,0,0,0,0,0,0,0,0,0,0,0,0,0,0,0,0,0,0,0,0,0,0,0,0,0,0,0,0,0,0,0,0,0,0,0,0,0,0,0
0,0,0,0,0,0,0,0,0,0,249,0,0,249,0,0,0,0,0,0,0,0,0,0,0,0,0,0,0,0,0,0,0,0,0,0,0,0,249,0,0,249,0,0
0,0,0,0,0,0,0,0,0,249,6,8,8,6,249,0,6,8,8,6,0,0,0,0,6,8,8,6,0,0,0,0,0,0,0,0,0,249,6,8,8,6,249,0
0,0,0,0,0,0,0,0,0,0,7,0,0,7,0,0,7,0,0,0,0,0,0,0,0,0,0,7,0,0,0,0,0,0,0,0,0,0,7,0,0,7,0,0
0,0,0,0,0,0,0,0,0,0,7,0,0,7,0,0,7,0,0,0,0,0,0,0,0,0,0,7,0,0,0,0,0,0,0,0,0,0,7,0,0,7,0,0
0,0,0,0,0,0,0,0,0,249,6,8,8,6,249,0,6,8,8,6,0,0,0,0,6,8,8,6,0,0,0,0,0,0,0,0,0,249,6,8,8,6,249,0
0,0,0,0,0,0,0,0,0,0,249,0,0,249,0,0,0,0,0,0,0,0,0,0,0,0,0,0,0,0,0,0,0,0,0,0,0,0,249,0,0,249,0,0
0,0,0,0,0,0,0,0,0,0,0,0,0,0,0,0,0,0,0,0,0,0,0,0,0,0,0,0,0,0,0,0,0,0,0,0,0,0,0,0,0,0,0,0
:endlayer
layer: 13
0,0,0,0,0,0,0,0,0,0,0,0,0,0,0,0,0,0,0,0,0,0,0,0,0,0,0,0,0,0,0,0,0,0,0,0,0,0,0,0,0,0,0,0
0,0,0,287,287,0,0,0,0,0,0,0,0,0,0,0,0,0,0,0,0,0,0,0,0,0,0,0,0,0,0,0,0,0,0,0,0,0,0,287,287,0,0,0
0,0,287,15,15,287,0,0,0,0,0,0,0,6,15,15,6,0,0,0,0,6,15,15,6,0,0,0,0,0,0,0,0,0,0,0,0,0,287,15,15,287,0,0
0,287,15,15,15,15,287,0,0,0,0,0,0,15,0,0,0,0,0,0,0,0,0,0,15,0,0,0,0,0,0,0,0,0,0,0,0,287,15,15,15,15,287,0
0,287,15,15,15,15,287,0,0,0,0,0,0,15,0,0,0,0,0,0,0,0,0,0,15,0,0,0,0,0,0,0,0,0,0,0,0,287,15,15,15,15,287,0
0,0,287,15,15,287,0,0,0,0,0,0,0,6,15,15,6,0,0,0,0,6,15,15,6,0,0,0,0,0,0,0,0,0,0,0,0,0,287,15,15,287,0,0
0,0,0,287,287,0,0,0,0,0,0,0,0,0,0,0,0,0,0,0,0,0,0,0,0,0,0,0,0,0,0,0,0,0,0,0,0,0,0,287,287,0,0,0
0,0,0,0,0,0,0,0,0,0,0,0,0,0,0,0,0,0,0,0,0,0,0,0,0,0,0,0,0,0,0,0,0,0,0,0,0,0,0,0,0,0,0,0
0,0,0,0,0,0,0,0,0,0,0,0,0,0,0,0,0,0,0,0,0,0,0,0,0,0,0,0,0,0,0,0,0,0,0,0,0,0,0,0,0,0,0,0
0,0,0,0,0,0,0,0,0,0,0,0,0,0,0,0,0,0,0,0,0,0,0,0,0,0,0,0,0,0,0,0,0,0,0,0,0,0,0,0,0,0,0,0
0,0,0,0,0,0,0,0,0,0,0,0,0,0,0,0,0,0,0,0,0,0,0,0,0,0,0,0,0,0,0,0,0,0,0,0,0,0,0,0,0,0,0,0
0,0,0,0,0,0,0,6,15,15,6,0,0,0,0,0,0,0,0,0,0,0,0,0,0,0,0,0,0,0,0,0,0,0,0,0,0,0,6,15,15,6,0,0
0,0,0,0,0,0,0,15,0,0,15,0,0,0,0,0,0,0,0,0,0,0,0,0,0,0,0,0,0,0,0,0,0,0,0,0,0,0,15,0,0,15,0,0
0,0,0,0,0,0,0,15,0,0,15,0,0,0,0,0,0,0,0,0,0,0,0,0,0,0,0,0,0,6,151,151,6,0,0,0,0,0,15,0,0,15,0,0
0,0,0,0,0,0,0,6,15,15,6,0,0,0,0,0,0,0,0,0,0,0,0,0,0,0,0,0,0,151,0,0,151,0,0,0,0,0,6,0,0,6,0,0
0,0,0,0,0,0,0,0,0,0,0,0,0,0,0,0,0,0,0,0,0,0,0,0,0,0,0,0,0,151,0,0,151,0,0,0,0,0,0,0,0,0,0,0
0,0,0,0,0,0,0,0,0,0,0,0,0,0,0,0,0,0,0,0,0,0,0,0,0,0,0,0,0,6,151,151,6,0,0,0,0,0,0,0,0,0,0,0
0,0,0,0,0,0,0,0,0,0,0,0,0,0,0,0,0,0,0,0,0,0,0,0,0,0,0,0,0,0,0,0,0,0,0,0,0,0,0,0,0,0,0,0
0,0,249,0,0,249,0,0,0,0,249,0,0,249,0,0,0,0,287,287,0,0,0,0,0,0,0,0,0,0,0,0,0,0,0,0,0,0,0,0,0,0,0,0
0,249,6,15,15,6,249,0,0,249,6,15,15,6,249,0,0,287,15,15,287,0,0,0,0,0,0,0,0,0,0,0,0,0,0,0,0,0,0,0,0,0,0,0
0,0,15,0,0,7,0,0,0,0,7,0,0,15,0,0,287,15,15,15,15,287,0,0,0,0,0,0,0,0,0,0,0,0,0,0,0,0,0,0,0,0,0,0
0,0,15,0,0,7,0,0,0,0,7,0,0,15,0,0,287,15,15,15,15,287,0,0,0,0,0,0,0,0,0,0,0,0,0,0,0,0,6,0,0,6,0,0
0,249,6,15,15,6,249,0,0,249,6,15,15,6,249,0,0,287,15,15,287,0,0,0,0,0,0,0,0,0,0,0,0,0,0,0,0,0,15,0,0,15,0,0
0,0,249,0,0,249,0,0,0,0,249,0,0,249,0,0,0,0,287,287,0,0,0,0,0,0,0,0,0,0,0,0,0,0,0,0,0,0,15,0,0,15,0,0
0,0,0,0,0,0,0,0,0,0,0,0,0,0,0,0,0,0,0,0,0,0,0,0,0,0,0,0,0,0,0,0,0,0,0,0,0,0,6,15,15,6,0,0
0,0,0,0,0,0,0,0,0,0,0,0,0,0,0,0,0,0,0,0,0,0,0,0,0,0,0,0,0,0,0,0,0,287,287,0,0,0,0,0,0,0,0,0
0,0,0,0,0,0,0,0,0,0,0,0,0,0,0,0,0,0,0,0,0,0,0,0,0,0,0,0,0,0,0,0,287,15,15,287,0,0,0,0,0,0,0,0
0,0,0,0,0,0,0,0,0,0,0,0,0,0,0,0,0,0,0,0,0,0,0,0,0,0,0,0,0,0,0,287,15,15,15,15,287,0,0,0,0,0,0,0
0,0,0,0,0,0,0,0,0,0,0,0,0,0,0,0,0,0,0,287,287,0,0,0,0,0,0,0,0,0,0,287,15,15,15,15,287,0,0,0,0,0,0,0
0,0,0,0,0,0,0,0,0,0,0,0,0,0,0,0,0,0,0,287,287,0,0,0,0,0,0,0,0,0,0,0,287,15,15,287,0,0,0,0,0,0,0,0
0,0,0,0,0,0,0,0,0,0,0,0,0,0,0,0,0,0,0,0,0,0,0,0,0,0,0,0,0,0,0,0,0,287,287,0,0,0,0,0,0,0,0,0
0,0,0,0,0,0,0,0,0,0,0,0,0,0,0,0,0,0,0,0,0,0,0,0,0,0,0,0,0,0,0,0,0,0,0,0,0,0,0,0,0,0,0,0
0,0,0,0,0,0,0,0,0,0,0,0,0,0,0,0,0,0,0,0,0,0,0,0,0,0,0,0,0,0,0,0,0,0,0,0,0,0,0,0,0,0,0,0
0,0,0,0,0,0,0,0,0,0,0,0,0,0,0,0,0,0,0,0,0,0,0,0,0,0,0,0,0,0,0,0,0,0,0,0,0,0,0,0,0,0,0,0
0,0,0,0,0,0,0,0,0,0,0,0,0,0,0,0,0,0,0,0,0,0,0,0,0,0,0,0,0,0,0,0,0,0,0,0,0,0,0,0,0,0,0,0
0,0,0,0,0,0,0,0,0,0,0,287,287,0,0,0,249,0,0,249,0,0,0,0,249,0,0,249,0,0,0,0,0,0,0,0,0,0,0,287,287,0,0,0
0,0,0,0,0,0,0,0,0,0,287,15,15,287,0,249,6,15,15,6,249,0,0,249,6,15,15,6,249,0,0,0,0,0,0,0,0,0,287,15,15,287,0,0
0,0,0,0,0,0,0,0,0,287,15,15,15,15,287,0,15,0,0,7,0,0,0,0,7,0,0,15,0,0,0,0,0,0,0,0,0,287,15,15,15,15,287,0
0,0,0,0,0,0,0,0,0,287,15,15,15,15,287,0,15,0,0,7,0,0,0,0,7,0,0,15,0,0,0,0,0,0,0,0,0,287,15,15,15,15,287,0
0,0,0,0,0,0,0,0,0,0,287,15,15,287,0,249,6,15,15,6,249,0,0,249,6,15,15,6,249,0,0,0,0,0,0,0,0,0,287,15,15,287,0,0
0,0,0,0,0,0,0,0,0,0,0,287,287,0,0,0,249,0,0,249,0,0,0,0,249,0,0,249,0,0,0,0,0,0,0,0,0,0,0,287,287,0,0,0
0,0,0,0,0,0,0,0,0,0,0,0,0,0,0,0,0,0,0,0,0,0,0,0,0,0,0,0,0,0,0,0,0,0,0,0,0,0,0,0,0,0,0,0
:endlayer
layer: 14
0,0,0,0,0,0,0,0,0,0,0,0,0,0,0,0,0,0,0,0,0,0,0,0,0,0,0,0,0,0,0,0,0,0,0,0,0,0,0,0,0,0,0,0
0,0,0,0,0,0,0,0,0,0,0,0,0,249,0,0,249,0,0,0,0,249,0,0,249,0,0,0,0,0,0,0,0,0,0,0,0,0,0,0,0,0,0,0
0,0,0,0,0,0,0,0,0,0,0,0,249,6,8,8,6,249,0,0,249,6,8,8,6,249,0,0,0,0,0,0,0,0,0,0,0,0,0,0,0,0,0,0
0,0,0,287,287,0,0,0,0,0,0,0,0,7,0,0,7,0,0,0,0,7,0,0,7,0,0,0,0,0,0,0,0,0,0,0,0,0,0,287,287,0,0,0
0,0,0,287,287,0,0,0,0,0,0,0,0,7,0,0,7,0,0,0,0,7,0,0,7,0,0,0,0,0,0,0,0,0,0,0,0,0,0,287,287,0,0,0
0,0,0,0,0,0,0,0,0,0,0,0,249,6,8,8,6,249,0,0,249,6,8,8,6,249,0,0,0,0,0,0,0,0,0,0,0,0,0,0,0,0,0,0
0,0,0,0,0,0,0,0,0,0,0,0,0,249,0,0,249,0,0,0,0,249,0,0,249,0,0,0,0,0,0,0,0,0,0,0,0,0,0,0,0,0,0,0
0,0,0,0,0,0,0,0,0,0,0,0,0,0,0,0,0,0,0,0,0,0,0,0,0,0,0,0,0,0,0,0,0,0,0,0,0,0,0,0,0,0,0,0
0,0,0,0,0,0,0,0,0,0,0,0,0,0,0,0,0,0,0,0,0,0,0,0,0,0,0,0,0,0,0,0,0,0,0,0,0,0,0,0,0,0,0,0
0,0,0,0,0,0,0,0,0,0,0,0,0,0,0,0,0,0,0,0,0,0,0,0,0,0,0,0,0,0,0,0,0,0,0,0,0,0,0,0,0,0,0,0
0,0,0,0,0,0,0,0,0,0,0,0,0,0,0,0,0,0,0,0,0,0,0,0,0,0,0,0,0,0,0,0,0,0,0,0,0,0,249,0,0,249,0,0
0,0,0,0,0,0,0,6,250,250,6,0,0,0,0,0,0,0,0,0,0,0,0,0,0,0,0,0,0,0,0,0,0,0,0,0,0,249,6,8,8,6,249,0
0,0,0,0,0,0,0,250,0,0,250,0,0,0,0,0,0,0,0,0,0,0,0,0,0,0,0,0,0,249,0,0,249,0,0,0,0,0,7,0,0,7,0,0
0,0,0,0,0,0,0,250,0,0,250,0,0,0,0,0,0,0,0,0,0,0,0,0,0,0,0,0,249,6,8,8,6,249,0,0,0,0,7,0,0,7,0,0
0,0,0,0,0,0,0,6,250,250,6,0,0,0,0,0,0,0,0,0,0,0,0,0,0,0,0,0,0,7,0,0,7,0,0,0,0,249,6,8,8,6,249,0
0,0,0,0,0,0,0,0,0,0,0,0,0,0,0,0,0,0,0,0,0,0,0,0,0,0,0,0,0,7,0,0,7,0,0,0,0,0,249,0,0,249,0,0
0,0,0,0,0,0,0,0,0,0,0,0,0,0,0,0,0,0,0,0,0,0,0,0,0,0,0,0,249,6,8,8,6,249,0,0,0,0,0,0,0,0,0,0
0,0,0,0,0,0,0,0,0,0,0,0,0,0,0,0,0,0,0,0,0,0,0,0,0,0,0,0,0,249,0,0,249,0,0,0,0,0,0,0,0,0,0,0
0,0,0,287,287,0,0,0,0,0,0,287,287,0,0,0,0,0,0,0,0,0,0,0,0,0,0,0,0,0,0,0,0,0,0,0,0,0,0,0,0,0,0,0
0,0,287,15,15,287,0,0,0,0,287,15,15,287,0,0,0,0,0,0,0,0,0,0,0,0,0,0,0,0,0,0,0,0,0,0,0,0,0,0,0,0,0,0
0,287,15,15,15,15,287,0,0,287,15,15,15,15,287,0,0,0,287,287,0,0,0,0,0,0,0,0,0,0,0,0,0,0,0,0,0,0,249,0,0,249,0,0
0,287,15,15,15,15,287,0,0,287,15,15,15,15,287,0,0,0,287,287,0,0,0,0,0,0,0,0,0,0,0,0,0,0,0,0,0,249,6,8,8,6,249,0
0,0,287,15,15,287,0,0,0,0,287,15,15,287,0,0,0,0,0,0,0,0,0,0,0,0,0,0,0,0,0,0,0,0,0,0,0,0,7,0,0,7,0,0
0,0,0,287,287,0,0,0,0,0,0,287,287,0,0,0,0,0,0,0,0,0,0,0,0,0,0,0,0,0,0,0,0,0,0,0,0,0,7,0,0,7,0,0
0,0,0,0,0,0,0,0,0,0,0,0,0,0,0,0,0,0,0,0,0,0,0,0,0,0,0,0,0,0,0,0,0,0,0,0,0,249,6,8,8,6,249,0
0,0,0,0,0,0,0,0,0,0,0,0,0,0,0,0,0,0,0,0,0,0,0,0,0,0,0,0,0,0,0,0,0,0,0,0,0,0,249,0,0,249,0,0
0,0,0,0,0,0,0,0,0,0,0,0,0,0,0,0,0,0,0,0,0,0,0,0,0,0,0,0,0,0,0,0,0,0,0,0,0,0,0,0,0,0,0,0
0,0,0,0,0,0,0,0,0,0,0,0,0,0,0,0,0,0,0,0,0,0,0,0,0,0,0,0,0,0,0,0,0,287,287,0,0,0,0,0,0,0,0,0
0,0,0,0,0,0,0,0,0,0,0,0,0,0,0,0,0,0,0,0,0,0,0,0,0,0,0,0,0,0,0,0,0,287,287,0,0,0,0,0,0,0,0,0
0,0,0,0,0,0,0,0,0,0,0,0,0,0,0,0,0,0,0,0,0,0,0,0,0,0,0,0,0,0,0,0,0,0,0,0,0,0,0,0,0,0,0,0
0,0,0,0,0,0,0,0,0,0,0,0,0,0,0,0,0,0,0,0,0,0,0,0,0,0,0,0,0,0,0,0,0,0,0,0,0,0,0,0,0,0,0,0
0,0,0,0,0,0,0,0,0,0,0,0,0,0,0,0,0,0,0,0,0,0,0,0,0,0,0,0,0,0,0,0,0,0,0,0,0,0,0,0,0,0,0,0
0,0,0,0,0,0,0,0,0,0,0,0,0,0,0,0,0,0,0,0,0,0,0,0,0,0,0,0,0,0,0,0,0,0,0,0,0,0,0,0,0,0,0,0
0,0,0,0,0,0,0,0,0,0,0,0,0,0,0,0,0,0,0,0,0,0,0,0,0,0,0,0,0,0,0,0,0,0,0,0,0,0,0,0,0,0,0,0
0,0,0,0,0,0,0,0,0,0,0,0,0,0,0,0,0,0,0,0,0,0,0,0,0,0,0,0,0,0,0,0,0,0,0,0,0,0,0,0,0,0,0,0
0,0,0,0,0,0,0,0,0,0,0,0,0,0,0,0,0,287,287,0,0,0,0,0,0,287,287,0,0,0,0,0,0,0,0,0,0,0,0,0,0,0,0,0
0,0,0,0,0,0,0,0,0,0,0,0,0,0,0,0,287,15,15,287,0,0,0,0,287,15,15,287,0,0,0,0,0,0,0,0,0,0,0,0,0,0,0,0
0,0,0,0,0,0,0,0,0,0,0,287,287,0,0,287,15,15,15,15,287,0,0,287,15,15,15,15,287,0,0,0,0,0,0,0,0,0,0,287,287,0,0,0
0,0,0,0,0,0,0,0,0,0,0,287,287,0,0,287,15,15,15,15,287,0,0,287,15,15,15,15,287,0,0,0,0,0,0,0,0,0,0,287,287,0,0,0
0,0,0,0,0,0,0,0,0,0,0,0,0,0,0,0,287,15,15,287,0,0,0,0,287,15,15,287,0,0,0,0,0,0,0,0,0,0,0,0,0,0,0,0
0,0,0,0,0,0,0,0,0,0,0,0,0,0,0,0,0,287,287,0,0,0,0,0,0,287,287,0,0,0,0,0,0,0,0,0,0,0,0,0,0,0,0,0
0,0,0,0,0,0,0,0,0,0,0,0,0,0,0,0,0,0,0,0,0,0,0,0,0,0,0,0,0,0,0,0,0,0,0,0,0,0,0,0,0,0,0,0
:endlayer
layer: 15
0,0,0,0,0,0,0,0,0,0,0,0,0,0,0,0,0,0,0,0,0,0,0,0,0,0,0,0,0,0,0,0,0,0,0,0,0,0,0,0,0,0,0,0
0,0,0,0,0,0,0,0,0,0,0,0,0,0,287,287,0,0,0,0,0,0,287,287,0,0,0,0,0,0,0,0,0,0,0,0,0,0,0,0,0,0,0,0
0,0,0,0,0,0,0,0,0,0,0,0,0,287,15,15,287,0,0,0,0,287,15,15,287,0,0,0,0,0,0,0,0,0,0,0,0,0,0,0,0,0,0,0
0,0,0,0,0,0,0,0,0,0,0,0,287,15,15,15,15,287,0,0,287,15,15,15,15,287,0,0,0,0,0,0,0,0,0,0,0,0,0,0,0,0,0,0
0,0,0,0,0,0,0,0,0,0,0,0,287,15,15,15,15,287,0,0,287,15,15,15,15,287,0,0,0,0,0,0,0,0,0,0,0,0,0,0,0,0,0,0
0,0,0,0,0,0,0,0,0,0,0,0,0,287,15,15,287,0,0,0,0,287,15,15,287,0,0,0,0,0,0,0,0,0,0,0,0,0,0,0,0,0,0,0
0,0,0,0,0,0,0,0,0,0,0,0,0,0,287,287,0,0,0,0,0,0,287,287,0,0,0,0,0,0,0,0,0,0,0,0,0,0,0,0,0,0,0,0
0,0,0,0,0,0,0,0,0,0,0,0,0,0,0,0,0,0,0,0,0,0,0,0,0,0,0,0,0,0,0,0,0,0,0,0,0,0,0,0,0,0,0,0
0,0,0,0,0,0,0,0,0,0,0,0,0,0,0,0,0,0,0,0,0,0,0,0,0,0,0,0,0,0,0,0,0,0,0,0,0,0,0,0,0,0,0,0
0,0,0,0,0,0,0,0,0,0,0,0,0,0,0,0,0,0,0,0,0,0,0,0,0,0,0,0,0,0,0,0,0,0,0,0,0,0,0,0,0,0,0,0
0,0,0,0,0,0,0,0,0,0,0,0,0,0,0,0,0,0,0,0,0,0,0,0,0,0,0,0,0,0,0,0,0,0,0,0,0,0,0,287,287,0,0,0
0,0,0,0,0,0,0,6,250,250,6,0,0,0,0,0,0,0,0,0,0,0,0,0,0,0,0,0,0,0,0,0,0,0,0,0,0,0,287,15,15,287,0,0
0,0,0,0,0,0,0,250,0,0,250,0,0,0,0,0,0,0,0,0,0,0,0,0,0,0,0,0,0,0,287,287,0,0,0,0,0,287,15,15,15,15,287,0
0,0,0,0,0,0,0,250,0,0,250,0,0,0,0,0,0,0,0,0,0,0,0,0,0,0,0,0,0,287,15,15,287,0,0,0,0,287,15,15,15,15,287,0
0,0,0,0,0,0,0,6,250,250,6,0,0,0,0,0,0,0,0,0,0,0,0,0,0,0,0,0,287,15,15,15,15,287,0,0,0,0,287,15,15,287,0,0
0,0,0,0,0,0,0,0,0,0,0,0,0,0,0,0,0,0,0,0,0,0,0,0,0,0,0,0,287,15,15,15,15,287,0,0,0,0,0,287,287,0,0,0
0,0,0,0,0,0,0,0,0,0,0,0,0,0,0,0,0,0,0,0,0,0,0,0,0,0,0,0,0,287,15,15,287,0,0,0,0,0,0,0,0,0,0,0
0,0,0,0,0,0,0,0,0,0,0,0,0,0,0,0,0,0,0,0,0,0,0,0,0,0,0,0,0,0,287,287,0,0,0,0,0,0,0,0,0,0,0,0
0,0,0,0,0,0,0,0,0,0,0,0,0,0,0,0,0,0,0,0,0,0,0,0,0,0,0,0,0,0,0,0,0,0,0,0,0,0,0,0,0,0,0,0
0,0,0,0,0,0,0,0,0,0,0,0,0,0,0,0,0,0,0,0,0,0,0,0,0,0,0,0,0,0,0,0,0,0,0,0,0,0,0,0,0,0,0,0
0,0,0,287,287,0,0,0,0,0,0,287,287,0,0,0,0,0,0,0,0,0,0,0,0,0,0,0,0,0,0,0,0,0,0,0,0,0,0,287,287,0,0,0
0,0,0,287,287,0,0,0,0,0,0,287,287,0,0,0,0,0,0,0,0,0,0,0,0,0,0,0,0,0,0,0,0,0,0,0,0,0,287,15,15,287,0,0
0,0,0,0,0,0,0,0,0,0,0,0,0,0,0,0,0,0,0,0,0,0,0,0,0,0,0,0,0,0,0,0,0,0,0,0,0,287,15,15,15,15,287,0
0,0,0,0,0,0,0,0,0,0,0,0,0,0,0,0,0,0,0,0,0,0,0,0,0,0,0,0,0,0,0,0,0,0,0,0,0,287,15,15,15,15,287,0
0,0,0,0,0,0,0,0,0,0,0,0,0,0,0,0,0,0,0,0,0,0,0,0,0,0,0,0,0,0,0,0,0,0,0,0,0,0,287,15,15,287,0,0
0,0,0,0,0,0,0,0,0,0,0,0,0,0,0,0,0,0,0,0,0,0,0,0,0,0,0,0,0,0,0,0,0,0,0,0,0,0,0,287,287,0,0,0
0,0,0,0,0,0,0,0,0,0,0,0,0,0,0,0,0,0,0,0,0,0,0,0,0,0,0,0,0,0,0,0,0,0,0,0,0,0,0,0,0,0,0,0
0,0,0,0,0,0,0,0,0,0,0,0,0,0,0,0,0,0,0,0,0,0,0,0,0,0,0,0,0,0,0,0,0,0,0,0,0,0,0,0,0,0,0,0
0,0,0,0,0,0,0,0,0,0,0,0,0,0,0,0,0,0,0,0,0,0,0,0,0,0,0,0,0,0,0,0,0,0,0,0,0,0,0,0,0,0,0,0
0,0,0,0,0,0,0,0,0,0,0,0,0,0,0,0,0,0,0,0,0,0,0,0,0,0,0,0,0,0,0,0,0,0,0,0,0,0,0,0,0,0,0,0
0,0,0,0,0,0,0,0,0,0,0,0,0,0,0,0,0,0,0,0,0,0,0,0,0,0,0,0,0,0,0,0,0,0,0,0,0,0,0,0,0,0,0,0
0,0,0,0,0,0,0,0,0,0,0,0,0,0,0,0,0,0,0,0,0,0,0,0,0,0,0,0,0,0,0,0,0,0,0,0,0,0,0,0,0,0,0,0
0,0,0,0,0,0,0,0,0,0,0,0,0,0,0,0,0,0,0,0,0,0,0,0,0,0,0,0,0,0,0,0,0,0,0,0,0,0,0,0,0,0,0,0
0,0,0,0,0,0,0,0,0,0,0,0,0,0,0,0,0,0,0,0,0,0,0,0,0,0,0,0,0,0,0,0,0,0,0,0,0,0,0,0,0,0,0,0
0,0,0,0,0,0,0,0,0,0,0,0,0,0,0,0,0,0,0,0,0,0,0,0,0,0,0,0,0,0,0,0,0,0,0,0,0,0,0,0,0,0,0,0
0,0,0,0,0,0,0,0,0,0,0,0,0,0,0,0,0,0,0,0,0,0,0,0,0,0,0,0,0,0,0,0,0,0,0,0,0,0,0,0,0,0,0,0
0,0,0,0,0,0,0,0,0,0,0,0,0,0,0,0,0,0,0,0,0,0,0,0,0,0,0,0,0,0,0,0,0,0,0,0,0,0,0,0,0,0,0,0
0,0,0,0,0,0,0,0,0,0,0,0,0,0,0,0,0,287,287,0,0,0,0,0,0,287,287,0,0,0,0,0,0,0,0,0,0,0,0,0,0,0,0,0
0,0,0,0,0,0,0,0,0,0,0,0,0,0,0,0,0,287,287,0,0,0,0,0,0,287,287,0,0,0,0,0,0,0,0,0,0,0,0,0,0,0,0,0
0,0,0,0,0,0,0,0,0,0,0,0,0,0,0,0,0,0,0,0,0,0,0,0,0,0,0,0,0,0,0,0,0,0,0,0,0,0,0,0,0,0,0,0
0,0,0,0,0,0,0,0,0,0,0,0,0,0,0,0,0,0,0,0,0,0,0,0,0,0,0,0,0,0,0,0,0,0,0,0,0,0,0,0,0,0,0,0
0,0,0,0,0,0,0,0,0,0,0,0,0,0,0,0,0,0,0,0,0,0,0,0,0,0,0,0,0,0,0,0,0,0,0,0,0,0,0,0,0,0,0,0
:endlayer
layer: 16
0,0,0,0,0,0,0,0,0,0,0,0,0,0,0,0,0,0,0,0,0,0,0,0,0,0,0,0,0,0,0,0,0,0,0,0,0,0,0,0,0,0,0,0
0,0,0,0,0,0,0,0,0,0,0,0,0,0,0,0,0,0,0,0,0,0,0,0,0,0,0,0,0,0,0,0,0,0,0,0,0,0,0,0,0,0,0,0
0,0,0,0,0,0,0,0,0,0,0,0,0,0,0,0,0,0,0,0,0,0,0,0,0,0,0,0,0,0,0,0,0,0,0,0,0,0,0,0,0,0,0,0
0,0,0,0,0,0,0,0,0,0,0,0,0,0,287,287,0,0,0,0,0,0,287,287,0,0,0,0,0,0,0,0,0,0,0,0,0,0,0,0,0,0,0,0
0,0,0,0,0,0,0,0,0,0,0,0,0,0,287,287,0,0,0,0,0,0,287,287,0,0,0,0,0,0,0,0,0,0,0,0,0,0,0,0,0,0,0,0
0,0,0,0,0,0,0,0,0,0,0,0,0,0,0,0,0,0,0,0,0,0,0,0,0,0,0,0,0,0,0,0,0,0,0,0,0,0,0,0,0,0,0,0
0,0,0,0,0,0,0,0,0,0,0,0,0,0,0,0,0,0,0,0,0,0,0,0,0,0,0,0,0,0,0,0,0,0,0,0,0,0,0,0,0,0,0,0
0,0,0,0,0,0,0,0,0,0,0,0,0,0,0,0,0,0,0,0,0,0,0,0,0,0,0,0,0,0,0,0,0,0,0,0,0,0,0,0,0,0,0,0
0,0,0,0,0,0,0,0,0,0,0,0,0,0,0,0,0,0,0,0,0,0,0,0,0,0,0,0,0,0,0,0,0,0,0,0,0,0,0,0,0,0,0,0
0,0,0,0,0,0,0,0,0,0,0,0,0,0,0,0,0,0,0,0,0,0,0,0,0,0,0,0,0,0,0,0,0,0,0,0,0,0,0,0,0,0,0,0
0,0,0,0,0,0,0,249,0,0,249,0,0,0,0,0,0,0,0,0,0,0,0,0,0,0,0,0,0,0,0,0,0,0,0,0,0,0,0,0,0,0,0,0
0,0,0,0,0,0,249,6,8,8,6,249,0,0,0,0,0,0,0,0,0,0,0,0,0,0,0,0,0,0,0,0,0,0,0,0,0,0,0,0,0,0,0,0
0,0,0,0,0,0,0,7,0,0,7,0,0,0,0,0,0,0,0,0,0,0,0,0,0,0,0,0,0,0,0,0,0,0,0,0,0,0,0,287,287,0,0,0
0,0,0,0,0,0,0,7,0,0,7,0,0,0,0,0,0,0,0,0,0,0,0,0,0,0,0,0,0,0,0,0,0,0,0,0,0,0,0,287,287,0,0,0
0,0,0,0,0,0,249,6,8,8,6,249,0,0,0,0,0,0,0,0,0,0,0,0,0,0,0,0,0,0,287,287,0,0,0,0,0,0,0,0,0,0,0,0
0,0,0,0,0,0,0,249,0,0,249,0,0,0,0,0,0,0,0,0,0,0,0,0,0,0,0,0,0,0,287,287,0,0,0,0,0,0,0,0,0,0,0,0
0,0,0,0,0,0,0,0,0,0,0,0,0,0,0,0,0,0,0,0,0,0,0,0,0,0,0,0,0,0,0,0,0,0,0,0,0,0,0,0,0,0,0,0
0,0,0,0,0,0,0,0,0,0,0,0,0,0,0,0,0,0,0,0,0,0,0,0,0,0,0,0,0,0,0,0,0,0,0,0,0,0,0,0,0,0,0,0
0,0,0,0,0,0,0,0,0,0,0,0,0,0,0,0,0,0,0,0,0,0,0,0,0,0,0,0,0,0,0,0,0,0,0,0,0,0,0,0,0,0,0,0
0,0,0,0,0,0,0,0,0,0,0,0,0,0,0,0,0,0,0,0,0,0,0,0,0,0,0,0,0,0,0,0,0,0,0,0,0,0,0,0,0,0,0,0
0,0,0,0,0,0,0,0,0,0,0,0,0,0,0,0,0,0,0,0,0,0,0,0,0,0,0,0,0,0,0,0,0,0,0,0,0,0,0,0,0,0,0,0
0,0,0,0,0,0,0,0,0,0,0,0,0,0,0,0,0,0,0,0,0,0,0,0,0,0,0,0,0,0,0,0,0,0,0,0,0,0,0,0,0,0,0,0
0,0,0,0,0,0,0,0,0,0,0,0,0,0,0,0,0,0,0,0,0,0,0,0,0,0,0,0,0,0,0,0,0,0,0,0,0,0,0,287,287,0,0,0
0,0,0,0,0,0,0,0,0,0,0,0,0,0,0,0,0,0,0,0,0,0,0,0,0,0,0,0,0,0,0,0,0,0,0,0,0,0,0,287,287,0,0,0
0,0,0,0,0,0,0,0,0,0,0,0,0,0,0,0,0,0,0,0,0,0,0,0,0,0,0,0,0,0,0,0,0,0,0,0,0,0,0,0,0,0,0,0
0,0,0,0,0,0,0,0,0,0,0,0,0,0,0,0,0,0,0,0,0,0,0,0,0,0,0,0,0,0,0,0,0,0,0,0,0,0,0,0,0,0,0,0
0,0,0,0,0,0,0,0,0,0,0,0,0,0,0,0,0,0,0,0,0,0,0,0,0,0,0,0,0,0,0,0,0,0,0,0,0,0,0,0,0,0,0,0
0,0,0,0,0,0,0,0,0,0,0,0,0,0,0,0,0,0,0,0,0,0,0,0,0,0,0,0,0,0,0,0,0,0,0,0,0,0,0,0,0,0,0,0
0,0,0,0,0,0,0,0,0,0,0,0,0,0,0,0,0,0,0,0,0,0,0,0,0,0,0,0,0,0,0,0,0,0,0,0,0,0,0,0,0,0,0,0
0,0,0,0,0,0,0,0,0,0,0,0,0,0,0,0,0,0,0,0,0,0,0,0,0,0,0,0,0,0,0,0,0,0,0,0,0,0,0,0,0,0,0,0
0,0,0,0,0,0,0,0,0,0,0,0,0,0,0,0,0,0,0,0,0,0,0,0,0,0,0,0,0,0,0,0,0,0,0,0,0,0,0,0,0,0,0,0
0,0,0,0,0,0,0,0,0,0,0,0,0,0,0,0,0,0,0,0,0,0,0,0,0,0,0,0,0,0,0,0,0,0,0,0,0,0,0,0,0,0,0,0
0,0,0,0,0,0,0,0,0,0,0,0,0,0,0,0,0,0,0,0,0,0,0,0,0,0,0,0,0,0,0,0,0,0,0,0,0,0,0,0,0,0,0,0
0,0,0,0,0,0,0,0,0,0,0,0,0,0,0,0,0,0,0,0,0,0,0,0,0,0,0,0,0,0,0,0,0,0,0,0,0,0,0,0,0,0,0,0
0,0,0,0,0,0,0,0,0,0,0,0,0,0,0,0,0,0,0,0,0,0,0,0,0,0,0,0,0,0,0,0,0,0,0,0,0,0,0,0,0,0,0,0
0,0,0,0,0,0,0,0,0,0,0,0,0,0,0,0,0,0,0,0,0,0,0,0,0,0,0,0,0,0,0,0,0,0,0,0,0,0,0,0,0,0,0,0
0,0,0,0,0,0,0,0,0,0,0,0,0,0,0,0,0,0,0,0,0,0,0,0,0,0,0,0,0,0,0,0,0,0,0,0,0,0,0,0,0,0,0,0
0,0,0,0,0,0,0,0,0,0,0,0,0,0,0,0,0,0,0,0,0,0,0,0,0,0,0,0,0,0,0,0,0,0,0,0,0,0,0,0,0,0,0,0
0,0,0,0,0,0,0,0,0,0,0,0,0,0,0,0,0,0,0,0,0,0,0,0,0,0,0,0,0,0,0,0,0,0,0,0,0,0,0,0,0,0,0,0
0,0,0,0,0,0,0,0,0,0,0,0,0,0,0,0,0,0,0,0,0,0,0,0,0,0,0,0,0,0,0,0,0,0,0,0,0,0,0,0,0,0,0,0
0,0,0,0,0,0,0,0,0,0,0,0,0,0,0,0,0,0,0,0,0,0,0,0,0,0,0,0,0,0,0,0,0,0,0,0,0,0,0,0,0,0,0,0
0,0,0,0,0,0,0,0,0,0,0,0,0,0,0,0,0,0,0,0,0,0,0,0,0,0,0,0,0,0,0,0,0,0,0,0,0,0,0,0,0,0,0,0
:endlayer
layer: 17
0,0,0,0,0,0,0,0,0,0,0,0,0,0,0,0,0,0,0,0,0,0,0,0,0,0,0,0,0,0,0,0,0,0,0,0,0,0,0,0,0,0,0,0
0,0,0,0,0,0,0,0,0,0,0,0,0,0,0,0,0,0,0,0,0,0,0,0,0,0,0,0,0,0,0,0,0,0,0,0,0,0,0,0,0,0,0,0
0,0,0,0,0,0,0,0,0,0,0,0,0,0,0,0,0,0,0,0,0,0,0,0,0,0,0,0,0,0,0,0,0,0,0,0,0,0,0,0,0,0,0,0
0,0,0,0,0,0,0,0,0,0,0,0,0,0,0,0,0,0,0,0,0,0,0,0,0,0,0,0,0,0,0,0,0,0,0,0,0,0,0,0,0,0,0,0
0,0,0,0,0,0,0,0,0,0,0,0,0,0,0,0,0,0,0,0,0,0,0,0,0,0,0,0,0,0,0,0,0,0,0,0,0,0,0,0,0,0,0,0
0,0,0,0,0,0,0,0,0,0,0,0,0,0,0,0,0,0,0,0,0,0,0,0,0,0,0,0,0,0,0,0,0,0,0,0,0,0,0,0,0,0,0,0
0,0,0,0,0,0,0,0,0,0,0,0,0,0,0,0,0,0,0,0,0,0,0,0,0,0,0,0,0,0,0,0,0,0,0,0,0,0,0,0,0,0,0,0
0,0,0,0,0,0,0,0,0,0,0,0,0,0,0,0,0,0,0,0,0,0,0,0,0,0,0,0,0,0,0,0,0,0,0,0,0,0,0,0,0,0,0,0
0,0,0,0,0,0,0,0,0,0,0,0,0,0,0,0,0,0,0,0,0,0,0,0,0,0,0,0,0,0,0,0,0,0,0,0,0,0,0,0,0,0,0,0
0,0,0,0,0,0,0,0,0,0,0,0,0,0,0,0,0,0,0,0,0,0,0,0,0,0,0,0,0,0,0,0,0,0,0,0,0,0,0,0,0,0,0,0
0,0,0,0,0,0,0,0,287,287,0,0,0,0,0,0,0,0,0,0,0,0,0,0,0,0,0,0,0,0,0,0,0,0,0,0,0,0,0,0,0,0,0,0
0,0,0,0,0,0,0,287,15,15,287,0,0,0,0,0,0,0,0,0,0,0,0,0,0,0,0,0,0,0,0,0,0,0,0,0,0,0,0,0,0,0,0,0
0,0,0,0,0,0,287,15,15,15,15,287,0,0,0,0,0,0,0,0,0,0,0,0,0,0,0,0,0,0,0,0,0,0,0,0,0,0,0,0,0,0,0,0
0,0,0,0,0,0,287,15,15,15,15,287,0,0,0,0,0,0,0,0,0,0,0,0,0,0,0,0,0,0,0,0,0,0,0,0,0,0,0,0,0,0,0,0
0,0,0,0,0,0,0,287,15,15,287,0,0,0,0,0,0,0,0,0,0,0,0,0,0,0,0,0,0,0,0,0,0,0,0,0,0,0,0,0,0,0,0,0
0,0,0,0,0,0,0,0,287,287,0,0,0,0,0,0,0,0,0,0,0,0,0,0,0,0,0,0,0,0,0,0,0,0,0,0,0,0,0,0,0,0,0,0
0,0,0,0,0,0,0,0,0,0,0,0,0,0,0,0,0,0,0,0,0,0,0,0,0,0,0,0,0,0,0,0,0,0,0,0,0,0,0,0,0,0,0,0
0,0,0,0,0,0,0,0,0,0,0,0,0,0,0,0,0,0,0,0,0,0,0,0,0,0,0,0,0,0,0,0,0,0,0,0,0,0,0,0,0,0,0,0
0,0,0,0,0,0,0,0,0,0,0,0,0,0,0,0,0,0,0,0,0,0,0,0,0,0,0,0,0,0,0,0,0,0,0,0,0,0,0,0,0,0,0,0
0,0,0,0,0,0,0,0,0,0,0,0,0,0,0,0,0,0,0,0,0,0,0,0,0,0,0,0,0,0,0,0,0,0,0,0,0,0,0,0,0,0,0,0
0,0,0,0,0,0,0,0,0,0,0,0,0,0,0,0,0,0,0,0,0,0,0,0,0,0,0,0,0,0,0,0,0,0,0,0,0,0,0,0,0,0,0,0
0,0,0,0,0,0,0,0,0,0,0,0,0,0,0,0,0,0,0,0,0,0,0,0,0,0,0,0,0,0,0,0,0,0,0,0,0,0,0,0,0,0,0,0
0,0,0,0,0,0,0,0,0,0,0,0,0,0,0,0,0,0,0,0,0,0,0,0,0,0,0,0,0,0,0,0,0,0,0,0,0,0,0,0,0,0,0,0
0,0,0,0,0,0,0,0,0,0,0,0,0,0,0,0,0,0,0,0,0,0,0,0,0,0,0,0,0,0,0,0,0,0,0,0,0,0,0,0,0,0,0,0
0,0,0,0,0,0,0,0,0,0,0,0,0,0,0,0,0,0,0,0,0,0,0,0,0,0,0,0,0,0,0,0,0,0,0,0,0,0,0,0,0,0,0,0
0,0,0,0,0,0,0,0,0,0,0,0,0,0,0,0,0,0,0,0,0,0,0,0,0,0,0,0,0,0,0,0,0,0,0,0,0,0,0,0,0,0,0,0
0,0,0,0,0,0,0,0,0,0,0,0,0,0,0,0,0,0,0,0,0,0,0,0,0,0,0,0,0,0,0,0,0,0,0,0,0,0,0,0,0,0,0,0
0,0,0,0,0,0,0,0,0,0,0,0,0,0,0,0,0,0,0,0,0,0,0,0,0,0,0,0,0,0,0,0,0,0,0,0,0,0,0,0,0,0,0,0
0,0,0,0,0,0,0,0,0,0,0,0,0,0,0,0,0,0,0,0,0,0,0,0,0,0,0,0,0,0,0,0,0,0,0,0,0,0,0,0,0,0,0,0
0,0,0,0,0,0,0,0,0,0,0,0,0,0,0,0,0,0,0,0,0,0,0,0,0,0,0,0,0,0,0,0,0,0,0,0,0,0,0,0,0,0,0,0
0,0,0,0,0,0,0,0,0,0,0,0,0,0,0,0,0,0,0,0,0,0,0,0,0,0,0,0,0,0,0,0,0,0,0,0,0,0,0,0,0,0,0,0
0,0,0,0,0,0,0,0,0,0,0,0,0,0,0,0,0,0,0,0,0,0,0,0,0,0,0,0,0,0,0,0,0,0,0,0,0,0,0,0,0,0,0,0
0,0,0,0,0,0,0,0,0,0,0,0,0,0,0,0,0,0,0,0,0,0,0,0,0,0,0,0,0,0,0,0,0,0,0,0,0,0,0,0,0,0,0,0
0,0,0,0,0,0,0,0,0,0,0,0,0,0,0,0,0,0,0,0,0,0,0,0,0,0,0,0,0,0,0,0,0,0,0,0,0,0,0,0,0,0,0,0
0,0,0,0,0,0,0,0,0,0,0,0,0,0,0,0,0,0,0,0,0,0,0,0,0,0,0,0,0,0,0,0,0,0,0,0,0,0,0,0,0,0,0,0
0,0,0,0,0,0,0,0,0,0,0,0,0,0,0,0,0,0,0,0,0,0,0,0,0,0,0,0,0,0,0,0,0,0,0,0,0,0,0,0,0,0,0,0
0,0,0,0,0,0,0,0,0,0,0,0,0,0,0,0,0,0,0,0,0,0,0,0,0,0,0,0,0,0,0,0,0,0,0,0,0,0,0,0,0,0,0,0
0,0,0,0,0,0,0,0,0,0,0,0,0,0,0,0,0,0,0,0,0,0,0,0,0,0,0,0,0,0,0,0,0,0,0,0,0,0,0,0,0,0,0,0
0,0,0,0,0,0,0,0,0,0,0,0,0,0,0,0,0,0,0,0,0,0,0,0,0,0,0,0,0,0,0,0,0,0,0,0,0,0,0,0,0,0,0,0
0,0,0,0,0,0,0,0,0,0,0,0,0,0,0,0,0,0,0,0,0,0,0,0,0,0,0,0,0,0,0,0,0,0,0,0,0,0,0,0,0,0,0,0
0,0,0,0,0,0,0,0,0,0,0,0,0,0,0,0,0,0,0,0,0,0,0,0,0,0,0,0,0,0,0,0,0,0,0,0,0,0,0,0,0,0,0,0
0,0,0,0,0,0,0,0,0,0,0,0,0,0,0,0,0,0,0,0,0,0,0,0,0,0,0,0,0,0,0,0,0,0,0,0,0,0,0,0,0,0,0,0
:endlayer
layer: 18
0,0,0,0,0,0,0,0,0,0,0,0,0,0,0,0,0,0,0,0,0,0,0,0,0,0,0,0,0,0,0,0,0,0,0,0,0,0,0,0,0,0,0,0
0,0,0,0,0,0,0,0,0,0,0,0,0,0,0,0,0,0,0,0,0,0,0,0,0,0,0,0,0,0,0,0,0,0,0,0,0,0,0,0,0,0,0,0
0,0,0,0,0,0,0,0,0,0,0,0,0,0,0,0,0,0,0,0,0,0,0,0,0,0,0,0,0,0,0,0,0,0,0,0,0,0,0,0,0,0,0,0
0,0,0,0,0,0,0,0,0,0,0,0,0,0,0,0,0,0,0,0,0,0,0,0,0,0,0,0,0,0,0,0,0,0,0,0,0,0,0,0,0,0,0,0
0,0,0,0,0,0,0,0,0,0,0,0,0,0,0,0,0,0,0,0,0,0,0,0,0,0,0,0,0,0,0,0,0,0,0,0,0,0,0,0,0,0,0,0
0,0,0,0,0,0,0,0,0,0,0,0,0,0,0,0,0,0,0,0,0,0,0,0,0,0,0,0,0,0,0,0,0,0,0,0,0,0,0,0,0,0,0,0
0,0,0,0,0,0,0,0,0,0,0,0,0,0,0,0,0,0,0,0,0,0,0,0,0,0,0,0,0,0,0,0,0,0,0,0,0,0,0,0,0,0,0,0
0,0,0,0,0,0,0,0,0,0,0,0,0,0,0,0,0,0,0,0,0,0,0,0,0,0,0,0,0,0,0,0,0,0,0,0,0,0,0,0,0,0,0,0
0,0,0,0,0,0,0,0,0,0,0,0,0,0,0,0,0,0,0,0,0,0,0,0,0,0,0,0,0,0,0,0,0,0,0,0,0,0,0,0,0,0,0,0
0,0,0,0,0,0,0,0,0,0,0,0,0,0,0,0,0,0,0,0,0,0,0,0,0,0,0,0,0,0,0,0,0,0,0,0,0,0,0,0,0,0,0,0
0,0,0,0,0,0,0,0,0,0,0,0,0,0,0,0,0,0,0,0,0,0,0,0,0,0,0,0,0,0,0,0,0,0,0,0,0,0,0,0,0,0,0,0
0,0,0,0,0,0,0,0,0,0,0,0,0,0,0,0,0,0,0,0,0,0,0,0,0,0,0,0,0,0,0,0,0,0,0,0,0,0,0,0,0,0,0,0
0,0,0,0,0,0,0,0,287,287,0,0,0,0,0,0,0,0,0,0,0,0,0,0,0,0,0,0,0,0,0,0,0,0,0,0,0,0,0,0,0,0,0,0
0,0,0,0,0,0,0,0,287,287,0,0,0,0,0,0,0,0,0,0,0,0,0,0,0,0,0,0,0,0,0,0,0,0,0,0,0,0,0,0,0,0,0,0
0,0,0,0,0,0,0,0,0,0,0,0,0,0,0,0,0,0,0,0,0,0,0,0,0,0,0,0,0,0,0,0,0,0,0,0,0,0,0,0,0,0,0,0
0,0,0,0,0,0,0,0,0,0,0,0,0,0,0,0,0,0,0,0,0,0,0,0,0,0,0,0,0,0,0,0,0,0,0,0,0,0,0,0,0,0,0,0
0,0,0,0,0,0,0,0,0,0,0,0,0,0,0,0,0,0,0,0,0,0,0,0,0,0,0,0,0,0,0,0,0,0,0,0,0,0,0,0,0,0,0,0
0,0,0,0,0,0,0,0,0,0,0,0,0,0,0,0,0,0,0,0,0,0,0,0,0,0,0,0,0,0,0,0,0,0,0,0,0,0,0,0,0,0,0,0
0,0,0,0,0,0,0,0,0,0,0,0,0,0,0,0,0,0,0,0,0,0,0,0,0,0,0,0,0,0,0,0,0,0,0,0,0,0,0,0,0,0,0,0
0,0,0,0,0,0,0,0,0,0,0,0,0,0,0,0,0,0,0,0,0,0,0,0,0,0,0,0,0,0,0,0,0,0,0,0,0,0,0,0,0,0,0,0
0,0,0,0,0,0,0,0,0,0,0,0,0,0,0,0,0,0,0,0,0,0,0,0,0,0,0,0,0,0,0,0,0,0,0,0,0,0,0,0,0,0,0,0
0,0,0,0,0,0,0,0,0,0,0,0,0,0,0,0,0,0,0,0,0,0,0,0,0,0,0,0,0,0,0,0,0,0,0,0,0,0,0,0,0,0,0,0
0,0,0,0,0,0,0,0,0,0,0,0,0,0,0,0,0,0,0,0,0,0,0,0,0,0,0,0,0,0,0,0,0,0,0,0,0,0,0,0,0,0,0,0
0,0,0,0,0,0,0,0,0,0,0,0,0,0,0,0,0,0,0,0,0,0,0,0,0,0,0,0,0,0,0,0,0,0,0,0,0,0,0,0,0,0,0,0
0,0,0,0,0,0,0,0,0,0,0,0,0,0,0,0,0,0,0,0,0,0,0,0,0,0,0,0,0,0,0,0,0,0,0,0,0,0,0,0,0,0,0,0
0,0,0,0,0,0,0,0,0,0,0,0,0,0,0,0,0,0,0,0,0,0,0,0,0,0,0,0,0,0,0,0,0,0,0,0,0,0,0,0,0,0,0,0
0,0,0,0,0,0,0,0,0,0,0,0,0,0,0,0,0,0,0,0,0,0,0,0,0,0,0,0,0,0,0,0,0,0,0,0,0,0,0,0,0,0,0,0
0,0,0,0,0,0,0,0,0,0,0,0,0,0,0,0,0,0,0,0,0,0,0,0,0,0,0,0,0,0,0,0,0,0,0,0,0,0,0,0,0,0,0,0
0,0,0,0,0,0,0,0,0,0,0,0,0,0,0,0,0,0,0,0,0,0,0,0,0,0,0,0,0,0,0,0,0,0,0,0,0,0,0,0,0,0,0,0
0,0,0,0,0,0,0,0,0,0,0,0,0,0,0,0,0,0,0,0,0,0,0,0,0,0,0,0,0,0,0,0,0,0,0,0,0,0,0,0,0,0,0,0
0,0,0,0,0,0,0,0,0,0,0,0,0,0,0,0,0,0,0,0,0,0,0,0,0,0,0,0,0,0,0,0,0,0,0,0,0,0,0,0,0,0,0,0
0,0,0,0,0,0,0,0,0,0,0,0,0,0,0,0,0,0,0,0,0,0,0,0,0,0,0,0,0,0,0,0,0,0,0,0,0,0,0,0,0,0,0,0
0,0,0,0,0,0,0,0,0,0,0,0,0,0,0,0,0,0,0,0,0,0,0,0,0,0,0,0,0,0,0,0,0,0,0,0,0,0,0,0,0,0,0,0
0,0,0,0,0,0,0,0,0,0,0,0,0,0,0,0,0,0,0,0,0,0,0,0,0,0,0,0,0,0,0,0,0,0,0,0,0,0,0,0,0,0,0,0
0,0,0,0,0,0,0,0,0,0,0,0,0,0,0,0,0,0,0,0,0,0,0,0,0,0,0,0,0,0,0,0,0,0,0,0,0,0,0,0,0,0,0,0
0,0,0,0,0,0,0,0,0,0,0,0,0,0,0,0,0,0,0,0,0,0,0,0,0,0,0,0,0,0,0,0,0,0,0,0,0,0,0,0,0,0,0,0
0,0,0,0,0,0,0,0,0,0,0,0,0,0,0,0,0,0,0,0,0,0,0,0,0,0,0,0,0,0,0,0,0,0,0,0,0,0,0,0,0,0,0,0
0,0,0,0,0,0,0,0,0,0,0,0,0,0,0,0,0,0,0,0,0,0,0,0,0,0,0,0,0,0,0,0,0,0,0,0,0,0,0,0,0,0,0,0
0,0,0,0,0,0,0,0,0,0,0,0,0,0,0,0,0,0,0,0,0,0,0,0,0,0,0,0,0,0,0,0,0,0,0,0,0,0,0,0,0,0,0,0
0,0,0,0,0,0,0,0,0,0,0,0,0,0,0,0,0,0,0,0,0,0,0,0,0,0,0,0,0,0,0,0,0,0,0,0,0,0,0,0,0,0,0,0
0,0,0,0,0,0,0,0,0,0,0,0,0,0,0,0,0,0,0,0,0,0,0,0,0,0,0,0,0,0,0,0,0,0,0,0,0,0,0,0,0,0,0,0
0,0,0,0,0,0,0,0,0,0,0,0,0,0,0,0,0,0,0,0,0,0,0,0,0,0,0,0,0,0,0,0,0,0,0,0,0,0,0,0,0,0,0,0
:endlayer

#### RULES ####
rule:
plugin=vanillaBlocks
number=1
data:
JSON:{blockState:{blockName:"minecraft:stone",properties:{variant:"stone"}}}
:enddata
:endrule

rule:
plugin=vanillaBlocks
number=2
data:
JSON:{blockState:{blockName:"minecraft:dirt",properties:{variant:"dirt",snowy:"false"}}}
:enddata
:endrule

rule:
plugin=vanillaBlocks
number=3
data:
JSON:{blockState:{blockName:"minecraft:stone",properties:{variant:"smooth_andesite"}}}
:enddata
:endrule

rule:
plugin=vanillaBlocks
number=4
data:
JSON:{blockState:{blockName:"minecraft:grass",properties:{snowy:"false"}}}
:enddata
:endrule

rule:
plugin=vanillaBlocks
number=5
data:
JSON:{blockState:{blockName:"minecraft:grass_path"}}
:enddata
:endrule

rule:
plugin=vanillaBlocks
number=6
data:
JSON:{blockState:{blockName:"minecraft:log",properties:{variant:"birch",axis:"y"}}}
:enddata
:endrule

rule:
plugin=vanillaBlocks
number=7
data:
JSON:{blockState:{blockName:"minecraft:log",properties:{variant:"birch",axis:"z"}}}
:enddata
:endrule

rule:
plugin=vanillaBlocks
number=8
data:
JSON:{blockState:{blockName:"minecraft:log",properties:{variant:"birch",axis:"x"}}}
:enddata
:endrule

rule:
plugin=vanillaBlocks
number=9
data:
JSON:{blockState:{blockName:"minecraft:stone_brick_stairs",properties:{half:"bottom",shape:"straight",facing:"west"}}}
:enddata
:endrule

rule:
plugin=vanillaBlocks
number=10
data:
JSON:{blockState:{blockName:"minecraft:stone_brick_stairs",properties:{half:"bottom",shape:"straight",facing:"north"}}}
:enddata
:endrule

rule:
plugin=vanillaBlocks
number=11
data:
JSON:{blockState:{blockName:"minecraft:stone",properties:{variant:"andesite"}}}
:enddata
:endrule

rule:
plugin=vanillaBlocks
number=12
data:
JSON:{blockState:{blockName:"minecraft:stone_brick_stairs",properties:{half:"bottom",shape:"straight",facing:"east"}}}
:enddata
:endrule

rule:
plugin=vanillaBlocks
number=13
data:
JSON:{blockState:{blockName:"minecraft:stone_brick_stairs",properties:{half:"bottom",shape:"straight",facing:"south"}}}
:enddata
:endrule

rule:
plugin=vanillaBlocks
number=14
data:
JSON:{blockState:{blockName:"minecraft:planks",properties:{variant:"oak"}}}
:enddata
:endrule

rule:
plugin=vanillaBlocks
number=15
data:
JSON:{blockState:{blockName:"minecraft:planks",properties:{variant:"birch"}}}
:enddata
:endrule

rule:
plugin=fluid
number=16
data:
JSON:{blockState:{blockName:"minecraft:water",properties:{level:"0"}}}
:enddata
:endrule

rule:
plugin=vanillaBlocks
number=17
data:
JSON:{blockState:{blockName:"minecraft:stonebrick",properties:{variant:"stonebrick"}}}
:enddata
:endrule

rule:
plugin=vanillaBlocks
number=18
data:
JSON:{blockState:{blockName:"minecraft:tallgrass",properties:{type:"tall_grass"}}}
:enddata
:endrule

rule:
plugin=vanillaBlocks
number=19
data:
JSON:{blockState:{blockName:"minecraft:red_flower",properties:{type:"pink_tulip"}}}
:enddata
:endrule

rule:
plugin=vanillaBlocks
number=20
data:
JSON:{blockState:{blockName:"minecraft:red_flower",properties:{type:"houstonia"}}}
:enddata
:endrule

rule:
plugin=vanillaBlocks
number=21
data:
JSON:{blockState:{blockName:"minecraft:yellow_flower",properties:{type:"dandelion"}}}
:enddata
:endrule

rule:
plugin=vanillaBlocks
number=22
data:
JSON:{blockState:{blockName:"minecraft:red_flower",properties:{type:"oxeye_daisy"}}}
:enddata
:endrule

rule:
plugin=vanillaBlocks
number=23
data:
JSON:{blockState:{blockName:"minecraft:birch_stairs",properties:{half:"bottom",shape:"straight",facing:"east"}}}
:enddata
:endrule

rule:
plugin=vanillaBlocks
number=24
data:
JSON:{blockState:{blockName:"minecraft:birch_stairs",properties:{half:"bottom",shape:"straight",facing:"north"}}}
:enddata
:endrule

rule:
plugin=vanillaBlocks
number=25
data:
JSON:{blockState:{blockName:"minecraft:birch_stairs",properties:{half:"bottom",shape:"straight",facing:"south"}}}
:enddata
:endrule

rule:
plugin=vanillaBlocks
number=26
data:
JSON:{blockState:{blockName:"minecraft:red_flower",properties:{type:"poppy"}}}
:enddata
:endrule

rule:
plugin=vanillaBlocks
number=27
data:
JSON:{blockState:{blockName:"minecraft:birch_stairs",properties:{half:"bottom",shape:"straight",facing:"west"}}}
:enddata
:endrule

rule:
plugin=blockTile
number=28
data:
JSON:{blockState:{blockName:"ancientwarfarestructure:advanced_spawner",properties:{transparent:"true"}},teData:{id:"ancientwarfarestructure:advanced_spawner_tile",spawnerSettings:{minDelay:10,spawnDelay:5,lightSensitive:0b,spawnGroups:[{settingsList:[{remainingSpawnCount:1,hostile:1b,customTag:{ArmorDropChances:[0.085f,0.085f,0.085f,0.085f],hasCustomEquipment:0b,ArmorItems:[{},{},{},{}],skinSettings:{npcTypeName:"custom",skinTypeSelected:"default"},HandDropChances:[0.085f,0.085f],factionName:"nogg",HandItems:[{id:"ancientwarfarenpc:iron_halberd",Count:1b,Damage:0s},{}]},maxToSpawn:1,entityId:"ancientwarfarenpc:faction.soldier",minToSpawn:1}],groupWeight:1}],playerRange:16,respondToRedstone:0b,inventory:{Size:9,Items:[]},spawnRange:0,transparent:1b,maxDelay:10,spawnYOffset:0,xpToDrop:0,mobRange:0,debugMode:0b,maxNearbyMonsters:0}}}
:enddata
:endrule

rule:
plugin=blockTile
number=29
data:
JSON:{blockState:{blockName:"ancientwarfarestructure:advanced_spawner",properties:{transparent:"true"}},teData:{id:"ancientwarfarestructure:advanced_spawner_tile",spawnerSettings:{minDelay:10,spawnDelay:7,lightSensitive:0b,spawnGroups:[{settingsList:[{remainingSpawnCount:1,hostile:1b,customTag:{ArmorDropChances:[0.085f,0.085f,0.085f,0.085f],hasCustomEquipment:0b,ArmorItems:[{},{},{},{}],skinSettings:{npcTypeName:"custom",skinTypeSelected:"default"},HandDropChances:[0.085f,0.085f],factionName:"nogg",HandItems:[{id:"ancientwarfarenpc:iron_halberd",Count:1b,Damage:0s},{}]},maxToSpawn:1,entityId:"ancientwarfarenpc:faction.soldier",minToSpawn:1}],groupWeight:1}],playerRange:16,respondToRedstone:0b,inventory:{Size:9,Items:[]},spawnRange:0,transparent:1b,maxDelay:10,spawnYOffset:0,xpToDrop:0,mobRange:0,debugMode:0b,maxNearbyMonsters:0}}}
:enddata
:endrule

rule:
plugin=blockTile
number=30
data:
JSON:{blockState:{blockName:"ancientwarfarestructure:advanced_spawner",properties:{transparent:"true"}},teData:{id:"ancientwarfarestructure:advanced_spawner_tile",spawnerSettings:{minDelay:10,spawnDelay:2,lightSensitive:0b,spawnGroups:[{settingsList:[{remainingSpawnCount:1,hostile:1b,customTag:{ArmorDropChances:[0.085f,0.085f,0.085f,0.085f],hasCustomEquipment:0b,ArmorItems:[{},{},{},{}],skinSettings:{npcTypeName:"custom",skinTypeSelected:"default"},HandDropChances:[0.085f,0.085f],factionName:"nogg",HandItems:[{id:"ancientwarfarenpc:iron_lance",Count:1b,Damage:0s},{id:"ancientwarfarenpc:shield_round_5",Count:1b,Damage:0s}]},maxToSpawn:1,entityId:"ancientwarfarenpc:faction.cavalry",minToSpawn:1}],groupWeight:1}],playerRange:16,respondToRedstone:0b,inventory:{Size:9,Items:[]},spawnRange:0,transparent:1b,maxDelay:10,spawnYOffset:0,xpToDrop:0,mobRange:0,debugMode:0b,maxNearbyMonsters:0}}}
:enddata
:endrule

rule:
plugin=blockTile
number=31
data:
JSON:{blockState:{blockName:"ancientwarfarestructure:gate_proxy"},teData:{lsb:-8375260661482592323L,id:"ancientwarfarestructure:gate_proxy_tile",msb:2602369046489484036L,render:1b}}
:enddata
:endrule

rule:
plugin=blockTile
number=32
data:
JSON:{blockState:{blockName:"ancientwarfarestructure:gate_proxy"},teData:{lsb:-4897676931410721565L,id:"ancientwarfarestructure:gate_proxy_tile",msb:1993465321214987127L,render:1b}}
:enddata
:endrule

rule:
plugin=blockTile
number=33
data:
JSON:{blockState:{blockName:"ancientwarfarestructure:gate_proxy"},teData:{lsb:-8375260661482592323L,id:"ancientwarfarestructure:gate_proxy_tile",msb:2602369046489484036L,render:1b}}
:enddata
:endrule

rule:
plugin=blockTile
number=34
data:
JSON:{blockState:{blockName:"ancientwarfarestructure:gate_proxy"},teData:{lsb:-4897676931410721565L,id:"ancientwarfarestructure:gate_proxy_tile",msb:1993465321214987127L,render:1b}}
:enddata
:endrule

rule:
plugin=blockTile
number=35
data:
JSON:{blockState:{blockName:"ancientwarfarestructure:advanced_spawner",properties:{transparent:"true"}},teData:{id:"ancientwarfarestructure:advanced_spawner_tile",spawnerSettings:{minDelay:10,spawnDelay:6,lightSensitive:0b,spawnGroups:[{settingsList:[{remainingSpawnCount:1,hostile:1b,customTag:{ArmorDropChances:[0.085f,0.085f,0.085f,0.085f],hasCustomEquipment:0b,ArmorItems:[{},{},{},{}],skinSettings:{npcTypeName:"custom",skinTypeSelected:"default"},HandDropChances:[0.085f,0.085f],factionName:"nogg",HandItems:[{id:"minecraft:bow",Count:1b,Damage:0s},{}]},maxToSpawn:1,entityId:"ancientwarfarenpc:faction.archer",minToSpawn:1}],groupWeight:1}],playerRange:16,respondToRedstone:0b,inventory:{Size:9,Items:[]},spawnRange:0,transparent:1b,maxDelay:10,spawnYOffset:0,xpToDrop:0,mobRange:0,debugMode:0b,maxNearbyMonsters:0}}}
:enddata
:endrule

rule:
plugin=blockTile
number=36
data:
JSON:{blockState:{blockName:"ancientwarfarestructure:gate_proxy"},teData:{lsb:-8375260661482592323L,id:"ancientwarfarestructure:gate_proxy_tile",msb:2602369046489484036L,render:1b}}
:enddata
:endrule

rule:
plugin=blockTile
number=37
data:
JSON:{blockState:{blockName:"ancientwarfarestructure:gate_proxy"},teData:{lsb:-4897676931410721565L,id:"ancientwarfarestructure:gate_proxy_tile",msb:1993465321214987127L,render:1b}}
:enddata
:endrule

rule:
plugin=blockTile
number=38
data:
JSON:{blockState:{blockName:"ancientwarfarestructure:gate_proxy"},teData:{lsb:-8375260661482592323L,id:"ancientwarfarestructure:gate_proxy_tile",msb:2602369046489484036L,render:1b}}
:enddata
:endrule

rule:
plugin=blockTile
number=39
data:
JSON:{blockState:{blockName:"ancientwarfarestructure:gate_proxy"},teData:{lsb:-4897676931410721565L,id:"ancientwarfarestructure:gate_proxy_tile",msb:1993465321214987127L,render:1b}}
:enddata
:endrule

rule:
plugin=blockTile
number=40
data:
JSON:{blockState:{blockName:"ancientwarfarestructure:advanced_spawner",properties:{transparent:"true"}},teData:{id:"ancientwarfarestructure:advanced_spawner_tile",spawnerSettings:{minDelay:10,spawnDelay:1,lightSensitive:0b,spawnGroups:[{settingsList:[{remainingSpawnCount:1,hostile:1b,customTag:{ArmorDropChances:[0.085f,0.085f,0.085f,0.085f],hasCustomEquipment:0b,ArmorItems:[{},{},{},{}],skinSettings:{npcTypeName:"custom",skinTypeSelected:"default"},HandDropChances:[0.085f,0.085f],factionName:"nogg",HandItems:[{id:"ancientwarfarenpc:iron_halberd",Count:1b,Damage:0s},{}]},maxToSpawn:1,entityId:"ancientwarfarenpc:faction.soldier",minToSpawn:1}],groupWeight:1}],playerRange:16,respondToRedstone:0b,inventory:{Size:9,Items:[]},spawnRange:0,transparent:1b,maxDelay:10,spawnYOffset:0,xpToDrop:0,mobRange:0,debugMode:0b,maxNearbyMonsters:0}}}
:enddata
:endrule

rule:
plugin=blockTile
number=41
data:
JSON:{blockState:{blockName:"ancientwarfarestructure:altar_short_cloth"},teData:{customColor:1b,color:2263842,dyeColor:0,customData:"nogg",id:"ancientwarfarestructure:colored_tile",unlocalizedNamePart:"faction"}}
:enddata
:endrule

rule:
plugin=vanillaBlocks
number=42
data:
JSON:{blockState:{blockName:"minecraft:birch_stairs",properties:{half:"top",shape:"straight",facing:"west"}}}
:enddata
:endrule

rule:
plugin=flag
number=43
data:
JSON:{blockState:{blockName:"ancientwarfarestructure:protection_flag",properties:{rotation:"14"}},teData:{name:"nogg",id:"ancientwarfarestructure:protection_flag_tile"}}
:enddata
:endrule

rule:
plugin=vanillaBlocks
number=44
data:
JSON:{blockState:{blockName:"minecraft:red_flower",properties:{type:"red_tulip"}}}
:enddata
:endrule

rule:
plugin=blockTile
number=45
data:
JSON:{blockState:{blockName:"ancientwarfarestructure:advanced_spawner",properties:{transparent:"true"}},teData:{id:"ancientwarfarestructure:advanced_spawner_tile",spawnerSettings:{minDelay:10,spawnDelay:6,lightSensitive:0b,spawnGroups:[{settingsList:[{remainingSpawnCount:1,hostile:1b,customTag:{ArmorDropChances:[0.085f,0.085f,0.085f,0.085f],hasCustomEquipment:0b,ArmorItems:[{},{},{},{}],skinSettings:{npcTypeName:"custom",skinTypeSelected:"default"},HandDropChances:[0.085f,0.085f],factionName:"nogg",HandItems:[{id:"ancientwarfarenpc:iron_halberd",Count:1b,Damage:0s},{}]},maxToSpawn:1,entityId:"ancientwarfarenpc:faction.soldier",minToSpawn:1}],groupWeight:1}],playerRange:16,respondToRedstone:0b,inventory:{Size:9,Items:[]},spawnRange:0,transparent:1b,maxDelay:10,spawnYOffset:0,xpToDrop:0,mobRange:0,debugMode:0b,maxNearbyMonsters:0}}}
:enddata
:endrule

rule:
plugin=vanillaBlocks
number=46
data:
JSON:{blockState:{blockName:"ancientwarfarestructure:bench",properties:{legs:"none",variant:"oak",axis:"z"}}}
:enddata
:endrule

rule:
plugin=blockTile
number=47
data:
JSON:{blockState:{blockName:"ancientwarfarestructure:advanced_spawner",properties:{transparent:"true"}},teData:{id:"ancientwarfarestructure:advanced_spawner_tile",spawnerSettings:{minDelay:10,spawnDelay:9,lightSensitive:0b,spawnGroups:[{settingsList:[{remainingSpawnCount:1,hostile:1b,customTag:{ArmorDropChances:[0.085f,0.085f,0.085f,0.085f],hasCustomEquipment:0b,ArmorItems:[{},{},{},{}],skinSettings:{npcTypeName:"custom",skinTypeSelected:"default"},HandDropChances:[0.085f,0.085f],factionName:"nogg",HandItems:[{id:"minecraft:book",Count:1b,Damage:0s},{}]},maxToSpawn:1,entityId:"ancientwarfarenpc:faction.priest",minToSpawn:1}],groupWeight:1}],playerRange:16,respondToRedstone:0b,inventory:{Size:9,Items:[]},spawnRange:0,transparent:1b,maxDelay:10,spawnYOffset:0,xpToDrop:0,mobRange:0,debugMode:0b,maxNearbyMonsters:0}}}
:enddata
:endrule

rule:
plugin=blockTile
number=48
data:
JSON:{blockState:{blockName:"ancientwarfarestructure:advanced_spawner",properties:{transparent:"true"}},teData:{id:"ancientwarfarestructure:advanced_spawner_tile",spawnerSettings:{minDelay:10,spawnDelay:2,lightSensitive:0b,spawnGroups:[{settingsList:[{remainingSpawnCount:1,hostile:1b,customTag:{ArmorDropChances:[0.085f,0.085f,0.085f,0.085f],hasCustomEquipment:0b,ArmorItems:[{},{},{},{}],skinSettings:{npcTypeName:"custom",skinTypeSelected:"default"},HandDropChances:[0.085f,0.085f],factionName:"nogg",HandItems:[{id:"ancientwarfarenpc:iron_halberd",Count:1b,Damage:0s},{}]},maxToSpawn:1,entityId:"ancientwarfarenpc:faction.soldier",minToSpawn:1}],groupWeight:1}],playerRange:16,respondToRedstone:0b,inventory:{Size:9,Items:[]},spawnRange:0,transparent:1b,maxDelay:10,spawnYOffset:0,xpToDrop:0,mobRange:0,debugMode:0b,maxNearbyMonsters:0}}}
:enddata
:endrule

rule:
plugin=blockTile
number=49
data:
JSON:{blockState:{blockName:"ancientwarfarestructure:advanced_spawner",properties:{transparent:"true"}},teData:{id:"ancientwarfarestructure:advanced_spawner_tile",spawnerSettings:{minDelay:10,spawnDelay:6,lightSensitive:0b,spawnGroups:[{settingsList:[{remainingSpawnCount:1,hostile:1b,customTag:{ArmorDropChances:[0.085f,0.085f,0.085f,0.085f],hasCustomEquipment:0b,ArmorItems:[{},{},{},{}],skinSettings:{npcTypeName:"custom",skinTypeSelected:"default"},HandDropChances:[0.085f,0.085f],factionName:"nogg",HandItems:[{},{}]},maxToSpawn:1,entityId:"ancientwarfarenpc:faction.civilian.female",minToSpawn:1}],groupWeight:1}],playerRange:16,respondToRedstone:0b,inventory:{Size:9,Items:[]},spawnRange:0,transparent:1b,maxDelay:10,spawnYOffset:0,xpToDrop:0,mobRange:0,debugMode:0b,maxNearbyMonsters:0}}}
:enddata
:endrule

rule:
plugin=blockTile
number=50
data:
JSON:{blockState:{blockName:"ancientwarfarestructure:advanced_spawner",properties:{transparent:"true"}},teData:{id:"ancientwarfarestructure:advanced_spawner_tile",spawnerSettings:{minDelay:10,spawnDelay:9,lightSensitive:0b,spawnGroups:[{settingsList:[{remainingSpawnCount:1,hostile:1b,customTag:{ArmorDropChances:[0.085f,0.085f,0.085f,0.085f],hasCustomEquipment:0b,ArmorItems:[{},{},{},{}],skinSettings:{npcTypeName:"custom",skinTypeSelected:"default"},HandDropChances:[0.085f,0.085f],factionName:"nogg",HandItems:[{},{}]},maxToSpawn:1,entityId:"ancientwarfarenpc:faction.civilian.female",minToSpawn:1}],groupWeight:1}],playerRange:16,respondToRedstone:0b,inventory:{Size:9,Items:[]},spawnRange:0,transparent:1b,maxDelay:10,spawnYOffset:0,xpToDrop:0,mobRange:0,debugMode:0b,maxNearbyMonsters:0}}}
:enddata
:endrule

rule:
plugin=blockTile
number=51
data:
JSON:{blockState:{blockName:"ancientwarfarestructure:advanced_spawner",properties:{transparent:"true"}},teData:{id:"ancientwarfarestructure:advanced_spawner_tile",spawnerSettings:{minDelay:10,spawnDelay:3,lightSensitive:0b,spawnGroups:[{settingsList:[{remainingSpawnCount:1,hostile:1b,customTag:{ArmorDropChances:[0.085f,0.085f,0.085f,0.085f],hasCustomEquipment:0b,ArmorItems:[{},{},{},{}],skinSettings:{npcTypeName:"custom",skinTypeSelected:"default"},HandDropChances:[0.085f,0.085f],factionName:"nogg",HandItems:[{},{}]},maxToSpawn:1,entityId:"ancientwarfarenpc:faction.civilian.male",minToSpawn:1}],groupWeight:1}],playerRange:16,respondToRedstone:0b,inventory:{Size:9,Items:[]},spawnRange:0,transparent:1b,maxDelay:10,spawnYOffset:0,xpToDrop:0,mobRange:0,debugMode:0b,maxNearbyMonsters:0}}}
:enddata
:endrule

rule:
plugin=blockTile
number=52
data:
JSON:{blockState:{blockName:"ancientwarfarestructure:advanced_spawner",properties:{transparent:"true"}},teData:{id:"ancientwarfarestructure:advanced_spawner_tile",spawnerSettings:{minDelay:10,spawnDelay:4,lightSensitive:0b,spawnGroups:[{settingsList:[{remainingSpawnCount:1,hostile:1b,customTag:{ArmorDropChances:[0.085f,0.085f,0.085f,0.085f],hasCustomEquipment:0b,ArmorItems:[{},{},{},{}],skinSettings:{npcTypeName:"custom",skinTypeSelected:"default"},HandDropChances:[0.085f,0.085f],factionName:"nogg",HandItems:[{id:"ancientwarfarenpc:iron_halberd",Count:1b,Damage:0s},{}]},maxToSpawn:1,entityId:"ancientwarfarenpc:faction.soldier",minToSpawn:1}],groupWeight:1}],playerRange:16,respondToRedstone:0b,inventory:{Size:9,Items:[]},spawnRange:0,transparent:1b,maxDelay:10,spawnYOffset:0,xpToDrop:0,mobRange:0,debugMode:0b,maxNearbyMonsters:0}}}
:enddata
:endrule

rule:
plugin=blockTile
number=53
data:
JSON:{blockState:{blockName:"ancientwarfarestructure:advanced_spawner",properties:{transparent:"true"}},teData:{id:"ancientwarfarestructure:advanced_spawner_tile",spawnerSettings:{minDelay:10,spawnDelay:4,lightSensitive:0b,spawnGroups:[{settingsList:[{remainingSpawnCount:1,hostile:1b,customTag:{ArmorDropChances:[0.085f,0.085f,0.085f,0.085f],hasCustomEquipment:0b,ArmorItems:[{},{},{},{}],skinSettings:{npcTypeName:"custom",skinTypeSelected:"default"},HandDropChances:[0.085f,0.085f],factionName:"nogg",HandItems:[{id:"ancientwarfarenpc:iron_lance",Count:1b,Damage:0s},{id:"ancientwarfarenpc:shield_round_5",Count:1b,Damage:0s}]},maxToSpawn:1,entityId:"ancientwarfarenpc:faction.cavalry",minToSpawn:1}],groupWeight:1}],playerRange:16,respondToRedstone:0b,inventory:{Size:9,Items:[]},spawnRange:0,transparent:1b,maxDelay:10,spawnYOffset:0,xpToDrop:0,mobRange:0,debugMode:0b,maxNearbyMonsters:0}}}
:enddata
:endrule

rule:
plugin=doors
number=54
data:
JSON:{blockState:{blockName:"minecraft:spruce_door",properties:{hinge:"left",half:"lower",powered:"false",facing:"west",open:"false"}}}
:enddata
:endrule

rule:
plugin=blockTile
number=55
data:
JSON:{blockState:{blockName:"ancientwarfarestructure:gate_proxy"},teData:{lsb:-8733431657411238274L,id:"ancientwarfarestructure:gate_proxy_tile",msb:6507551214884897674L,render:1b}}
:enddata
:endrule

rule:
plugin=blockTile
number=56
data:
JSON:{blockState:{blockName:"ancientwarfarestructure:gate_proxy"},teData:{lsb:-6975057207272915622L,id:"ancientwarfarestructure:gate_proxy_tile",msb:-6646095098529823748L,render:1b}}
:enddata
:endrule

rule:
plugin=blockTile
number=57
data:
JSON:{blockState:{blockName:"ancientwarfarestructure:chair",properties:{visible:"true",variant:"spruce",facing:"west"}},facing:"north",teData:{facing:"east",id:"ancientwarfarestructure:chair_tile"}}
:enddata
:endrule

rule:
plugin=vanillaBlocks
number=58
data:
JSON:{blockState:{blockName:"ancientwarfarestructure:table",properties:{leg_southwest:"true",leg_northwest:"true",variant:"spruce",leg_northeast:"true",leg_southeast:"true"}}}
:enddata
:endrule

rule:
plugin=blockTile
number=59
data:
JSON:{blockState:{blockName:"ancientwarfarestructure:gate_proxy"},teData:{lsb:-8733431657411238274L,id:"ancientwarfarestructure:gate_proxy_tile",msb:6507551214884897674L,render:1b}}
:enddata
:endrule

rule:
plugin=blockTile
number=60
data:
JSON:{blockState:{blockName:"ancientwarfarestructure:gate_proxy"},teData:{lsb:-6975057207272915622L,id:"ancientwarfarestructure:gate_proxy_tile",msb:-6646095098529823748L,render:1b}}
:enddata
:endrule

rule:
plugin=blockTile
number=61
data:
JSON:{blockState:{blockName:"ancientwarfarestructure:advanced_spawner",properties:{transparent:"true"}},teData:{id:"ancientwarfarestructure:advanced_spawner_tile",spawnerSettings:{minDelay:10,spawnDelay:5,lightSensitive:0b,spawnGroups:[{settingsList:[{remainingSpawnCount:1,hostile:1b,customTag:{ArmorDropChances:[0.085f,0.085f,0.085f,0.085f],hasCustomEquipment:0b,ArmorItems:[{},{},{},{}],skinSettings:{npcTypeName:"custom",skinTypeSelected:"default"},HandDropChances:[0.085f,0.085f],factionName:"nogg",HandItems:[{id:"ancientwarfarenpc:iron_lance",Count:1b,Damage:0s},{id:"ancientwarfarenpc:shield_round_5",Count:1b,Damage:0s}]},maxToSpawn:1,entityId:"ancientwarfarenpc:faction.cavalry",minToSpawn:1}],groupWeight:1}],playerRange:16,respondToRedstone:0b,inventory:{Size:9,Items:[]},spawnRange:0,transparent:1b,maxDelay:10,spawnYOffset:0,xpToDrop:0,mobRange:0,debugMode:0b,maxNearbyMonsters:0}}}
:enddata
:endrule

rule:
plugin=blockTile
number=62
data:
JSON:{blockState:{blockName:"ancientwarfarestructure:advanced_spawner",properties:{transparent:"true"}},teData:{id:"ancientwarfarestructure:advanced_spawner_tile",spawnerSettings:{minDelay:10,spawnDelay:7,lightSensitive:0b,spawnGroups:[{settingsList:[{remainingSpawnCount:1,hostile:1b,customTag:{ArmorDropChances:[0.085f,0.085f,0.085f,0.085f],hasCustomEquipment:0b,ArmorItems:[{},{},{},{}],skinSettings:{npcTypeName:"custom",skinTypeSelected:"default"},HandDropChances:[0.085f,0.085f],factionName:"nogg",HandItems:[{id:"ancientwarfarenpc:iron_halberd",Count:1b,Damage:0s},{}]},maxToSpawn:1,entityId:"ancientwarfarenpc:faction.soldier",minToSpawn:1}],groupWeight:1}],playerRange:16,respondToRedstone:0b,inventory:{Size:9,Items:[]},spawnRange:0,transparent:1b,maxDelay:10,spawnYOffset:0,xpToDrop:0,mobRange:0,debugMode:0b,maxNearbyMonsters:0}}}
:enddata
:endrule

rule:
plugin=blockTile
number=63
data:
JSON:{blockState:{blockName:"ancientwarfarestructure:chair",properties:{visible:"true",variant:"spruce",facing:"west"}},facing:"south",teData:{facing:"west",id:"ancientwarfarestructure:chair_tile"}}
:enddata
:endrule

rule:
plugin=vanillaBlocks
number=64
data:
JSON:{blockState:{blockName:"minecraft:ladder",properties:{facing:"west"}}}
:enddata
:endrule

rule:
plugin=blockTile
number=65
data:
