# Ancient Warfare Structure Template File
# Auto-generated structure template file. created on: 2/24/2024 at: 12:3:4
# Lines beginning with # denote comments

header:
version=2.11
name=EmpireLeviathanSeaSovereignShipOfTheLine
mods=
size=25,66,79
offset=12,7,63
:endheader

#### VALIDATION ####
validation:
type=water
structureAuthor=TheOddlySeagull
survival=false
worldGenEnabled=true
unique=false
preserveBlocks=false
preventNaturalHostileSpawns=true
selectionWeight=5
clusterValue=60
minDuplicateDistance=20000
dimensionWhiteList=true
dimensionList=0
biomeGroupList=
biomeWhiteList=true
biomeList=minecraft:deep_ocean
leveling=0
fill=0
border=0
blockSwap=false
territoryName=empirefleet
biomeReplacement=minecraft:
:endvalidation

#### LAYERS ####
layer: 0
1,1,1,1,1,1,1,1,1,1,1,1,1,1,1,1,1,1,1,1,1,1,1,1,1
1,1,1,1,1,1,1,1,1,1,1,1,1,1,1,1,1,1,1,1,1,1,1,1,1
1,1,1,1,1,1,1,1,1,1,1,1,1,1,1,1,1,1,1,1,1,1,1,1,1
1,1,1,1,1,1,1,1,1,1,1,1,1,1,1,1,1,1,1,1,1,1,1,1,1
1,1,1,1,1,1,1,1,1,1,1,1,1,1,1,1,1,1,1,1,1,1,1,1,1
1,1,1,1,1,1,1,1,1,1,1,1,1,1,1,1,1,1,1,1,1,1,1,1,1
1,1,1,1,1,1,1,1,1,1,1,1,1,1,1,1,1,1,1,1,1,1,1,1,1
1,1,1,1,1,1,1,1,1,1,1,1,1,1,1,1,1,1,1,1,1,1,1,1,1
1,1,1,1,1,1,1,1,1,1,1,1,1,1,1,1,1,1,1,1,1,1,1,1,1
1,1,1,1,1,1,1,1,1,1,1,1,1,1,1,1,1,1,1,1,1,1,1,1,1
1,1,1,1,1,1,1,1,1,1,1,1,1,1,1,1,1,1,1,1,1,1,1,1,1
1,1,1,1,1,1,1,1,1,1,1,1,1,1,1,1,1,1,1,1,1,1,1,1,1
1,1,1,1,1,1,1,1,1,1,1,1,1,1,1,1,1,1,1,1,1,1,1,1,1
1,1,1,1,1,1,1,1,1,1,1,1,1,1,1,1,1,1,1,1,1,1,1,1,1
1,1,1,1,1,1,1,1,1,1,1,1,1,1,1,1,1,1,1,1,1,1,1,1,1
1,1,1,1,1,1,1,1,1,1,1,1,1,1,1,1,1,1,1,1,1,1,1,1,1
1,1,1,1,1,1,1,1,1,1,1,1,1,1,1,1,1,1,1,1,1,1,1,1,1
1,1,1,1,1,1,1,1,1,1,1,1,1,1,1,1,1,1,1,1,1,1,1,1,1
1,1,1,1,1,1,1,1,1,1,1,1,1,1,1,1,1,1,1,1,1,1,1,1,1
1,1,1,1,1,1,1,1,1,1,1,1,1,1,1,1,1,1,1,1,1,1,1,1,1
1,1,1,1,1,1,1,1,1,1,1,1,1,1,1,1,1,1,1,1,1,1,1,1,1
1,1,1,1,1,1,1,1,1,1,1,1,1,1,1,1,1,1,1,1,1,1,1,1,1
1,1,1,1,1,1,1,1,1,1,1,1,1,1,1,1,1,1,1,1,1,1,1,1,1
1,1,1,1,1,1,1,1,1,1,1,1,1,1,1,1,1,1,1,1,1,1,1,1,1
1,1,1,1,1,1,1,1,1,1,1,1,1,1,1,1,1,1,1,1,1,1,1,1,1
1,1,1,1,1,1,1,1,1,1,1,1,1,1,1,1,1,1,1,1,1,1,1,1,1
1,1,1,1,1,1,1,1,1,1,1,1,1,1,1,1,1,1,1,1,1,1,1,1,1
1,1,1,1,1,1,1,1,1,1,1,1,1,1,1,1,1,1,1,1,1,1,1,1,1
1,1,1,1,1,1,1,1,1,1,1,1,1,1,1,1,1,1,1,1,1,1,1,1,1
1,1,1,1,1,1,1,1,1,1,1,1,1,1,1,1,1,1,1,1,1,1,1,1,1
1,1,1,1,1,1,1,1,1,1,1,1,1,1,1,1,1,1,1,1,1,1,1,1,1
1,1,1,1,1,1,1,1,1,1,1,1,1,1,1,1,1,1,1,1,1,1,1,1,1
1,1,1,1,1,1,1,1,1,1,1,1,1,1,1,1,1,1,1,1,1,1,1,1,1
1,1,1,1,1,1,1,1,1,1,1,1,1,1,1,1,1,1,1,1,1,1,1,1,1
1,1,1,1,1,1,1,1,1,1,1,1,1,1,1,1,1,1,1,1,1,1,1,1,1
1,1,1,1,1,1,1,1,1,1,1,1,1,1,1,1,1,1,1,1,1,1,1,1,1
1,1,1,1,1,1,1,1,1,1,1,1,1,1,1,1,1,1,1,1,1,1,1,1,1
1,1,1,1,1,1,1,1,1,1,1,1,1,1,1,1,1,1,1,1,1,1,1,1,1
1,1,1,1,1,1,1,1,1,1,1,1,1,1,1,1,1,1,1,1,1,1,1,1,1
1,1,1,1,1,1,1,1,1,1,1,1,1,1,1,1,1,1,1,1,1,1,1,1,1
1,1,1,1,1,1,1,1,1,1,1,1,1,1,1,1,1,1,1,1,1,1,1,1,1
1,1,1,1,1,1,1,1,1,1,1,1,1,1,1,1,1,1,1,1,1,1,1,1,1
1,1,1,1,1,1,1,1,1,1,1,1,1,1,1,1,1,1,1,1,1,1,1,1,1
1,1,1,1,1,1,1,1,1,1,1,1,1,1,1,1,1,1,1,1,1,1,1,1,1
1,1,1,1,1,1,1,1,1,1,1,1,1,1,1,1,1,1,1,1,1,1,1,1,1
1,1,1,1,1,1,1,1,1,1,1,1,1,1,1,1,1,1,1,1,1,1,1,1,1
1,1,1,1,1,1,1,1,1,1,1,1,1,1,1,1,1,1,1,1,1,1,1,1,1
1,1,1,1,1,1,1,1,1,1,1,1,1,1,1,1,1,1,1,1,1,1,1,1,1
1,1,1,1,1,1,1,1,1,1,1,1,1,1,1,1,1,1,1,1,1,1,1,1,1
1,1,1,1,1,1,1,1,1,1,1,1,1,1,1,1,1,1,1,1,1,1,1,1,1
1,1,1,1,1,1,1,1,1,1,1,1,1,1,1,1,1,1,1,1,1,1,1,1,1
1,1,1,1,1,1,1,1,1,1,1,1,1,1,1,1,1,1,1,1,1,1,1,1,1
1,1,1,1,1,1,1,1,1,1,1,1,1,1,1,1,1,1,1,1,1,1,1,1,1
1,1,1,1,1,1,1,1,1,1,1,1,1,1,1,1,1,1,1,1,1,1,1,1,1
1,1,1,1,1,1,1,1,1,1,1,1,1,1,1,1,1,1,1,1,1,1,1,1,1
1,1,1,1,1,1,1,1,1,1,1,1,1,1,1,1,1,1,1,1,1,1,1,1,1
1,1,1,1,1,1,1,1,1,1,1,1,1,1,1,1,1,1,1,1,1,1,1,1,1
1,1,1,1,1,1,1,1,1,1,1,1,1,1,1,1,1,1,1,1,1,1,1,1,1
1,1,1,1,1,1,1,1,1,1,1,1,1,1,1,1,1,1,1,1,1,1,1,1,1
1,1,1,1,1,1,1,1,1,1,1,1,1,1,1,1,1,1,1,1,1,1,1,1,1
1,1,1,1,1,1,1,1,1,1,1,1,1,1,1,1,1,1,1,1,1,1,1,1,1
1,1,1,1,1,1,1,1,1,1,1,1,1,1,1,1,1,1,1,1,1,1,1,1,1
1,1,1,1,1,1,1,1,1,1,1,1,1,1,1,1,1,1,1,1,1,1,1,1,1
1,1,1,1,1,1,1,1,1,1,1,1,1,1,1,1,1,1,1,1,1,1,1,1,1
1,1,1,1,1,1,1,1,1,1,1,1,1,1,1,1,1,1,1,1,1,1,1,1,1
1,1,1,1,1,1,1,1,1,1,1,1,1,1,1,1,1,1,1,1,1,1,1,1,1
1,1,1,1,1,1,1,1,1,1,1,1,1,1,1,1,1,1,1,1,1,1,1,1,1
1,1,1,1,1,1,1,1,1,1,1,1,1,1,1,1,1,1,1,1,1,1,1,1,1
1,1,1,1,1,1,1,1,1,1,1,1,1,1,1,1,1,1,1,1,1,1,1,1,1
1,1,1,1,1,1,1,1,1,1,1,1,1,1,1,1,1,1,1,1,1,1,1,1,1
1,1,1,1,1,1,1,1,1,1,1,1,1,1,1,1,1,1,1,1,1,1,1,1,1
1,1,1,1,1,1,1,1,1,1,1,1,1,1,1,1,1,1,1,1,1,1,1,1,1
1,1,1,1,1,1,1,1,1,1,1,1,1,1,1,1,1,1,1,1,1,1,1,1,1
1,1,1,1,1,1,1,1,1,1,1,1,1,1,1,1,1,1,1,1,1,1,1,1,1
1,1,1,1,1,1,1,1,1,1,1,1,1,1,1,1,1,1,1,1,1,1,1,1,1
1,1,1,1,1,1,1,1,1,1,1,1,1,1,1,1,1,1,1,1,1,1,1,1,1
1,1,1,1,1,1,1,1,1,1,1,1,1,1,1,1,1,1,1,1,1,1,1,1,1
1,1,1,1,1,1,1,1,1,1,1,1,1,1,1,1,1,1,1,1,1,1,1,1,1
1,1,1,1,1,1,1,1,1,1,1,1,1,1,1,1,1,1,1,1,1,1,1,1,1
:endlayer
layer: 1
1,1,1,1,1,1,1,1,1,1,1,1,1,1,1,1,1,1,1,1,1,1,1,1,1
1,1,1,1,1,1,1,1,1,1,1,1,1,1,1,1,1,1,1,1,1,1,1,1,1
1,1,1,1,1,1,1,1,1,1,1,1,1,1,1,1,1,1,1,1,1,1,1,1,1
1,1,1,1,1,1,1,1,1,1,1,1,1,1,1,1,1,1,1,1,1,1,1,1,1
1,1,1,1,1,1,1,1,1,1,1,1,1,1,1,1,1,1,1,1,1,1,1,1,1
1,1,1,1,1,1,1,1,1,1,1,1,1,1,1,1,1,1,1,1,1,1,1,1,1
1,1,1,1,1,1,1,1,1,1,1,1,1,1,1,1,1,1,1,1,1,1,1,1,1
1,1,1,1,1,1,1,1,1,1,1,1,1,1,1,1,1,1,1,1,1,1,1,1,1
1,1,1,1,1,1,1,1,1,1,1,1,1,1,1,1,1,1,1,1,1,1,1,1,1
1,1,1,1,1,1,1,1,1,1,1,1,1,1,1,1,1,1,1,1,1,1,1,1,1
1,1,1,1,1,1,1,1,1,1,1,1,1,1,1,1,1,1,1,1,1,1,1,1,1
1,1,1,1,1,1,1,1,1,1,1,1,1,1,1,1,1,1,1,1,1,1,1,1,1
1,1,1,1,1,1,1,1,1,1,1,1,1,1,1,1,1,1,1,1,1,1,1,1,1
1,1,1,1,1,1,1,1,1,1,1,1,1,1,1,1,1,1,1,1,1,1,1,1,1
1,1,1,1,1,1,1,1,1,1,1,1,1,1,1,1,1,1,1,1,1,1,1,1,1
1,1,1,1,1,1,1,1,1,1,1,1,1,1,1,1,1,1,1,1,1,1,1,1,1
1,1,1,1,1,1,1,1,1,1,1,1,1,1,1,1,1,1,1,1,1,1,1,1,1
1,1,1,1,1,1,1,1,1,1,1,1,1,1,1,1,1,1,1,1,1,1,1,1,1
1,1,1,1,1,1,1,1,1,1,1,1,1,1,1,1,1,1,1,1,1,1,1,1,1
1,1,1,1,1,1,1,1,1,1,1,1,1,1,1,1,1,1,1,1,1,1,1,1,1
1,1,1,1,1,1,1,1,1,1,1,1,1,1,1,1,1,1,1,1,1,1,1,1,1
1,1,1,1,1,1,1,1,1,1,1,1,1,1,1,1,1,1,1,1,1,1,1,1,1
1,1,1,1,1,1,1,1,1,1,1,1,1,1,1,1,1,1,1,1,1,1,1,1,1
1,1,1,1,1,1,1,1,1,1,1,1,1,1,1,1,1,1,1,1,1,1,1,1,1
1,1,1,1,1,1,1,1,1,1,1,1,1,1,1,1,1,1,1,1,1,1,1,1,1
1,1,1,1,1,1,1,1,1,1,1,1,1,1,1,1,1,1,1,1,1,1,1,1,1
1,1,1,1,1,1,1,1,1,1,1,1,1,1,1,1,1,1,1,1,1,1,1,1,1
1,1,1,1,1,1,1,1,1,1,1,1,1,1,1,1,1,1,1,1,1,1,1,1,1
1,1,1,1,1,1,1,1,1,1,1,1,1,1,1,1,1,1,1,1,1,1,1,1,1
1,1,1,1,1,1,1,1,1,1,1,1,1,1,1,1,1,1,1,1,1,1,1,1,1
1,1,1,1,1,1,1,1,1,1,1,1,1,1,1,1,1,1,1,1,1,1,1,1,1
1,1,1,1,1,1,1,1,1,1,1,1,1,1,1,1,1,1,1,1,1,1,1,1,1
1,1,1,1,1,1,1,1,1,1,1,1,1,1,1,1,1,1,1,1,1,1,1,1,1
1,1,1,1,1,1,1,1,1,1,1,1,1,1,1,1,1,1,1,1,1,1,1,1,1
1,1,1,1,1,1,1,1,1,1,1,1,1,1,1,1,1,1,1,1,1,1,1,1,1
1,1,1,1,1,1,1,1,1,1,1,1,1,1,1,1,1,1,1,1,1,1,1,1,1
1,1,1,1,1,1,1,1,1,1,1,1,1,1,1,1,1,1,1,1,1,1,1,1,1
1,1,1,1,1,1,1,1,1,1,1,1,1,1,1,1,1,1,1,1,1,1,1,1,1
1,1,1,1,1,1,1,1,1,1,1,1,1,1,1,1,1,1,1,1,1,1,1,1,1
1,1,1,1,1,1,1,1,1,1,1,1,1,1,1,1,1,1,1,1,1,1,1,1,1
1,1,1,1,1,1,1,1,1,1,1,1,1,1,1,1,1,1,1,1,1,1,1,1,1
1,1,1,1,1,1,1,1,1,1,1,1,1,1,1,1,1,1,1,1,1,1,1,1,1
1,1,1,1,1,1,1,1,1,1,1,1,1,1,1,1,1,1,1,1,1,1,1,1,1
1,1,1,1,1,1,1,1,1,1,1,1,1,1,1,1,1,1,1,1,1,1,1,1,1
1,1,1,1,1,1,1,1,1,1,1,1,1,1,1,1,1,1,1,1,1,1,1,1,1
1,1,1,1,1,1,1,1,1,1,1,1,1,1,1,1,1,1,1,1,1,1,1,1,1
1,1,1,1,1,1,1,1,1,1,1,1,1,1,1,1,1,1,1,1,1,1,1,1,1
1,1,1,1,1,1,1,1,1,1,1,1,1,1,1,1,1,1,1,1,1,1,1,1,1
1,1,1,1,1,1,1,1,1,1,1,1,1,1,1,1,1,1,1,1,1,1,1,1,1
1,1,1,1,1,1,1,1,1,1,1,1,1,1,1,1,1,1,1,1,1,1,1,1,1
1,1,1,1,1,1,1,1,1,1,1,1,1,1,1,1,1,1,1,1,1,1,1,1,1
1,1,1,1,1,1,1,1,1,1,1,1,1,1,1,1,1,1,1,1,1,1,1,1,1
1,1,1,1,1,1,1,1,1,1,1,1,1,1,1,1,1,1,1,1,1,1,1,1,1
1,1,1,1,1,1,1,1,1,1,1,1,1,1,1,1,1,1,1,1,1,1,1,1,1
1,1,1,1,1,1,1,1,1,1,1,1,1,1,1,1,1,1,1,1,1,1,1,1,1
1,1,1,1,1,1,1,1,1,1,1,1,1,1,1,1,1,1,1,1,1,1,1,1,1
1,1,1,1,1,1,1,1,1,1,1,1,1,1,1,1,1,1,1,1,1,1,1,1,1
1,1,1,1,1,1,1,1,1,1,1,1,1,1,1,1,1,1,1,1,1,1,1,1,1
1,1,1,1,1,1,1,1,1,1,1,1,1,1,1,1,1,1,1,1,1,1,1,1,1
1,1,1,1,1,1,1,1,1,1,1,1,1,1,1,1,1,1,1,1,1,1,1,1,1
1,1,1,1,1,1,1,1,1,1,1,1,1,1,1,1,1,1,1,1,1,1,1,1,1
1,1,1,1,1,1,1,1,1,1,1,1,1,1,1,1,1,1,1,1,1,1,1,1,1
1,1,1,1,1,1,1,1,1,1,1,1,1,1,1,1,1,1,1,1,1,1,1,1,1
1,1,1,1,1,1,1,1,1,1,1,1,1,1,1,1,1,1,1,1,1,1,1,1,1
1,1,1,1,1,1,1,1,1,1,1,1,1,1,1,1,1,1,1,1,1,1,1,1,1
1,1,1,1,1,1,1,1,1,1,1,1,1,1,1,1,1,1,1,1,1,1,1,1,1
1,1,1,1,1,1,1,1,1,1,1,1,1,1,1,1,1,1,1,1,1,1,1,1,1
1,1,1,1,1,1,1,1,1,1,1,1,1,1,1,1,1,1,1,1,1,1,1,1,1
1,1,1,1,1,1,1,1,1,1,1,1,1,1,1,1,1,1,1,1,1,1,1,1,1
1,1,1,1,1,1,1,1,1,1,1,1,1,1,1,1,1,1,1,1,1,1,1,1,1
1,1,1,1,1,1,1,1,1,1,1,1,1,1,1,1,1,1,1,1,1,1,1,1,1
1,1,1,1,1,1,1,1,1,1,1,1,1,1,1,1,1,1,1,1,1,1,1,1,1
1,1,1,1,1,1,1,1,1,1,1,1,1,1,1,1,1,1,1,1,1,1,1,1,1
1,1,1,1,1,1,1,1,1,1,1,1,1,1,1,1,1,1,1,1,1,1,1,1,1
1,1,1,1,1,1,1,1,1,1,1,1,1,1,1,1,1,1,1,1,1,1,1,1,1
1,1,1,1,1,1,1,1,1,1,1,1,1,1,1,1,1,1,1,1,1,1,1,1,1
1,1,1,1,1,1,1,1,1,1,1,1,1,1,1,1,1,1,1,1,1,1,1,1,1
1,1,1,1,1,1,1,1,1,1,1,1,1,1,1,1,1,1,1,1,1,1,1,1,1
1,1,1,1,1,1,1,1,1,1,1,1,1,1,1,1,1,1,1,1,1,1,1,1,1
:endlayer
layer: 2
1,1,1,1,1,1,1,1,1,1,1,1,1,1,1,1,1,1,1,1,1,1,1,1,1
1,1,1,1,1,1,1,1,1,1,1,1,1,1,1,1,1,1,1,1,1,1,1,1,1
1,1,1,1,1,1,1,1,1,1,1,1,1,1,1,1,1,1,1,1,1,1,1,1,1
1,1,1,1,1,1,1,1,1,1,1,1,1,1,1,1,1,1,1,1,1,1,1,1,1
1,1,1,1,1,1,1,1,1,1,1,1,1,1,1,1,1,1,1,1,1,1,1,1,1
1,1,1,1,1,1,1,1,1,1,1,1,1,1,1,1,1,1,1,1,1,1,1,1,1
1,1,1,1,1,1,1,1,1,1,1,1,1,1,1,1,1,1,1,1,1,1,1,1,1
1,1,1,1,1,1,1,1,1,1,1,1,1,1,1,1,1,1,1,1,1,1,1,1,1
1,1,1,1,1,1,1,1,1,1,1,1,1,1,1,1,1,1,1,1,1,1,1,1,1
1,1,1,1,1,1,1,1,1,1,1,1,1,1,1,1,1,1,1,1,1,1,1,1,1
1,1,1,1,1,1,1,1,1,1,1,1,1,1,1,1,1,1,1,1,1,1,1,1,1
1,1,1,1,1,1,1,1,1,1,1,1,1,1,1,1,1,1,1,1,1,1,1,1,1
1,1,1,1,1,1,1,1,1,1,1,1,1,1,1,1,1,1,1,1,1,1,1,1,1
1,1,1,1,1,1,1,1,1,1,1,1,1,1,1,1,1,1,1,1,1,1,1,1,1
1,1,1,1,1,1,1,1,1,1,1,1,1,1,1,1,1,1,1,1,1,1,1,1,1
1,1,1,1,1,1,1,1,1,1,1,1,1,1,1,1,1,1,1,1,1,1,1,1,1
1,1,1,1,1,1,1,1,1,1,1,1,1,1,1,1,1,1,1,1,1,1,1,1,1
1,1,1,1,1,1,1,1,1,1,1,1,1,1,1,1,1,1,1,1,1,1,1,1,1
1,1,1,1,1,1,1,1,1,1,1,1,1,1,1,1,1,1,1,1,1,1,1,1,1
1,1,1,1,1,1,1,1,1,1,1,1,1,1,1,1,1,1,1,1,1,1,1,1,1
1,1,1,1,1,1,1,1,1,1,1,1,1,1,1,1,1,1,1,1,1,1,1,1,1
1,1,1,1,1,1,1,1,1,1,1,1,1,1,1,1,1,1,1,1,1,1,1,1,1
1,1,1,1,1,1,1,1,1,1,1,1,1,1,1,1,1,1,1,1,1,1,1,1,1
1,1,1,1,1,1,1,1,1,1,1,1,1,1,1,1,1,1,1,1,1,1,1,1,1
1,1,1,1,1,1,1,1,1,1,1,1,1,1,1,1,1,1,1,1,1,1,1,1,1
1,1,1,1,1,1,1,1,1,1,1,1,1,1,1,1,1,1,1,1,1,1,1,1,1
1,1,1,1,1,1,1,1,1,1,1,1,1,1,1,1,1,1,1,1,1,1,1,1,1
1,1,1,1,1,1,1,1,1,1,1,1,1,1,1,1,1,1,1,1,1,1,1,1,1
1,1,1,1,1,1,1,1,1,1,1,1,1,1,1,1,1,1,1,1,1,1,1,1,1
1,1,1,1,1,1,1,1,1,1,1,1,1,1,1,1,1,1,1,1,1,1,1,1,1
1,1,1,1,1,1,1,1,1,1,1,1,1,1,1,1,1,1,1,1,1,1,1,1,1
1,1,1,1,1,1,1,1,1,1,1,1,1,1,1,1,1,1,1,1,1,1,1,1,1
1,1,1,1,1,1,1,1,1,1,1,1,1,1,1,1,1,1,1,1,1,1,1,1,1
1,1,1,1,1,1,1,1,1,1,1,1,1,1,1,1,1,1,1,1,1,1,1,1,1
1,1,1,1,1,1,1,1,1,1,1,1,1,1,1,1,1,1,1,1,1,1,1,1,1
1,1,1,1,1,1,1,1,1,1,1,1,1,1,1,1,1,1,1,1,1,1,1,1,1
1,1,1,1,1,1,1,1,1,1,1,1,1,1,1,1,1,1,1,1,1,1,1,1,1
1,1,1,1,1,1,1,1,1,1,1,1,1,1,1,1,1,1,1,1,1,1,1,1,1
1,1,1,1,1,1,1,1,1,1,1,1,1,1,1,1,1,1,1,1,1,1,1,1,1
1,1,1,1,1,1,1,1,1,1,1,1,1,1,1,1,1,1,1,1,1,1,1,1,1
1,1,1,1,1,1,1,1,1,1,1,1,1,1,1,1,1,1,1,1,1,1,1,1,1
1,1,1,1,1,1,1,1,1,1,1,1,1,1,1,1,1,1,1,1,1,1,1,1,1
1,1,1,1,1,1,1,1,1,1,1,1,1,1,1,1,1,1,1,1,1,1,1,1,1
1,1,1,1,1,1,1,1,1,1,1,1,1,1,1,1,1,1,1,1,1,1,1,1,1
1,1,1,1,1,1,1,1,1,1,1,1,1,1,1,1,1,1,1,1,1,1,1,1,1
1,1,1,1,1,1,1,1,1,1,1,1,1,1,1,1,1,1,1,1,1,1,1,1,1
1,1,1,1,1,1,1,1,1,1,1,1,1,1,1,1,1,1,1,1,1,1,1,1,1
1,1,1,1,1,1,1,1,1,1,1,1,1,1,1,1,1,1,1,1,1,1,1,1,1
1,1,1,1,1,1,1,1,1,1,1,1,1,1,1,1,1,1,1,1,1,1,1,1,1
1,1,1,1,1,1,1,1,1,1,1,1,1,1,1,1,1,1,1,1,1,1,1,1,1
1,1,1,1,1,1,1,1,1,1,1,1,1,1,1,1,1,1,1,1,1,1,1,1,1
1,1,1,1,1,1,1,1,1,1,1,1,1,1,1,1,1,1,1,1,1,1,1,1,1
1,1,1,1,1,1,1,1,1,1,1,1,1,1,1,1,1,1,1,1,1,1,1,1,1
1,1,1,1,1,1,1,1,1,1,1,1,1,1,1,1,1,1,1,1,1,1,1,1,1
1,1,1,1,1,1,1,1,1,1,1,1,1,1,1,1,1,1,1,1,1,1,1,1,1
1,1,1,1,1,1,1,1,1,1,1,1,1,1,1,1,1,1,1,1,1,1,1,1,1
1,1,1,1,1,1,1,1,1,1,1,1,1,1,1,1,1,1,1,1,1,1,1,1,1
1,1,1,1,1,1,1,1,1,1,1,1,1,1,1,1,1,1,1,1,1,1,1,1,1
1,1,1,1,1,1,1,1,1,1,1,1,1,1,1,1,1,1,1,1,1,1,1,1,1
1,1,1,1,1,1,1,1,1,1,1,1,1,1,1,1,1,1,1,1,1,1,1,1,1
1,1,1,1,1,1,1,1,1,1,1,1,1,1,1,1,1,1,1,1,1,1,1,1,1
1,1,1,1,1,1,1,1,1,1,1,1,1,1,1,1,1,1,1,1,1,1,1,1,1
1,1,1,1,1,1,1,1,1,1,1,1,1,1,1,1,1,1,1,1,1,1,1,1,1
1,1,1,1,1,1,1,1,1,1,1,1,1,1,1,1,1,1,1,1,1,1,1,1,1
1,1,1,1,1,1,1,1,1,1,1,1,1,1,1,1,1,1,1,1,1,1,1,1,1
1,1,1,1,1,1,1,1,1,1,1,1,1,1,1,1,1,1,1,1,1,1,1,1,1
1,1,1,1,1,1,1,1,1,1,1,1,1,1,1,1,1,1,1,1,1,1,1,1,1
1,1,1,1,1,1,1,1,1,1,1,1,1,1,1,1,1,1,1,1,1,1,1,1,1
1,1,1,1,1,1,1,1,1,1,1,1,1,1,1,1,1,1,1,1,1,1,1,1,1
1,1,1,1,1,1,1,1,1,1,1,1,1,1,1,1,1,1,1,1,1,1,1,1,1
1,1,1,1,1,1,1,1,1,1,1,1,1,1,1,1,1,1,1,1,1,1,1,1,1
1,1,1,1,1,1,1,1,1,1,1,1,1,1,1,1,1,1,1,1,1,1,1,1,1
1,1,1,1,1,1,1,1,1,1,1,1,1,1,1,1,1,1,1,1,1,1,1,1,1
1,1,1,1,1,1,1,1,1,1,1,1,1,1,1,1,1,1,1,1,1,1,1,1,1
1,1,1,1,1,1,1,1,1,1,1,1,1,1,1,1,1,1,1,1,1,1,1,1,1
1,1,1,1,1,1,1,1,1,1,1,1,1,1,1,1,1,1,1,1,1,1,1,1,1
1,1,1,1,1,1,1,1,1,1,1,1,1,1,1,1,1,1,1,1,1,1,1,1,1
1,1,1,1,1,1,1,1,1,1,1,1,1,1,1,1,1,1,1,1,1,1,1,1,1
1,1,1,1,1,1,1,1,1,1,1,1,1,1,1,1,1,1,1,1,1,1,1,1,1
:endlayer
layer: 3
1,1,1,1,1,1,1,1,1,1,1,1,1,1,1,1,1,1,1,1,1,1,1,1,1
1,1,1,1,1,1,1,1,1,1,1,1,1,1,1,1,1,1,1,1,1,1,1,1,1
1,1,1,1,1,1,1,1,1,1,1,1,1,1,1,1,1,1,1,1,1,1,1,1,1
1,1,1,1,1,1,1,1,1,1,1,1,1,1,1,1,1,1,1,1,1,1,1,1,1
1,1,1,1,1,1,1,1,1,1,1,1,1,1,1,1,1,1,1,1,1,1,1,1,1
1,1,1,1,1,1,1,1,1,1,1,1,1,1,1,1,1,1,1,1,1,1,1,1,1
1,1,1,1,1,1,1,1,1,1,1,1,1,1,1,1,1,1,1,1,1,1,1,1,1
1,1,1,1,1,1,1,1,1,1,1,1,1,1,1,1,1,1,1,1,1,1,1,1,1
1,1,1,1,1,1,1,1,1,1,1,1,1,1,1,1,1,1,1,1,1,1,1,1,1
1,1,1,1,1,1,1,1,1,1,1,1,1,1,1,1,1,1,1,1,1,1,1,1,1
1,1,1,1,1,1,1,1,1,1,1,1,1,1,1,1,1,1,1,1,1,1,1,1,1
1,1,1,1,1,1,1,1,1,1,1,1,1,1,1,1,1,1,1,1,1,1,1,1,1
1,1,1,1,1,1,1,1,1,1,1,1,1,1,1,1,1,1,1,1,1,1,1,1,1
1,1,1,1,1,1,1,1,1,1,1,1,1,1,1,1,1,1,1,1,1,1,1,1,1
1,1,1,1,1,1,1,1,1,1,1,1,1,1,1,1,1,1,1,1,1,1,1,1,1
1,1,1,1,1,1,1,1,1,1,1,1,1,1,1,1,1,1,1,1,1,1,1,1,1
1,1,1,1,1,1,1,1,1,1,1,1,1,1,1,1,1,1,1,1,1,1,1,1,1
1,1,1,1,1,1,1,1,1,1,1,1,1,1,1,1,1,1,1,1,1,1,1,1,1
1,1,1,1,1,1,1,1,1,1,1,2,2,2,1,1,1,1,1,1,1,1,1,1,1
1,1,1,1,1,1,1,1,1,1,2,2,2,2,2,1,1,1,1,1,1,1,1,1,1
1,1,1,1,1,1,1,1,1,1,2,2,2,2,2,1,1,1,1,1,1,1,1,1,1
1,1,1,1,1,1,1,1,1,1,2,2,2,2,2,1,1,1,1,1,1,1,1,1,1
1,1,1,1,1,1,1,1,1,1,2,2,2,2,2,1,1,1,1,1,1,1,1,1,1
1,1,1,1,1,1,1,1,1,1,2,2,2,2,2,1,1,1,1,1,1,1,1,1,1
1,1,1,1,1,1,1,1,1,1,2,2,2,2,2,1,1,1,1,1,1,1,1,1,1
1,1,1,1,1,1,1,1,1,1,2,2,2,2,2,1,1,1,1,1,1,1,1,1,1
1,1,1,1,1,1,1,1,1,1,2,2,2,2,2,1,1,1,1,1,1,1,1,1,1
1,1,1,1,1,1,1,1,1,1,2,2,2,2,2,1,1,1,1,1,1,1,1,1,1
1,1,1,1,1,1,1,1,1,1,2,2,2,2,2,1,1,1,1,1,1,1,1,1,1
1,1,1,1,1,1,1,1,1,1,2,2,2,2,2,1,1,1,1,1,1,1,1,1,1
1,1,1,1,1,1,1,1,1,1,2,2,2,2,2,1,1,1,1,1,1,1,1,1,1
1,1,1,1,1,1,1,1,1,1,2,2,2,2,2,1,1,1,1,1,1,1,1,1,1
1,1,1,1,1,1,1,1,1,1,2,2,2,2,2,1,1,1,1,1,1,1,1,1,1
1,1,1,1,1,1,1,1,1,1,2,2,2,2,2,1,1,1,1,1,1,1,1,1,1
1,1,1,1,1,1,1,1,1,1,2,2,2,2,2,1,1,1,1,1,1,1,1,1,1
1,1,1,1,1,1,1,1,1,1,2,2,2,2,2,1,1,1,1,1,1,1,1,1,1
1,1,1,1,1,1,1,1,1,1,2,2,2,2,2,1,1,1,1,1,1,1,1,1,1
1,1,1,1,1,1,1,1,1,1,2,2,2,2,2,1,1,1,1,1,1,1,1,1,1
1,1,1,1,1,1,1,1,1,1,2,2,2,2,2,1,1,1,1,1,1,1,1,1,1
1,1,1,1,1,1,1,1,1,1,2,2,2,2,2,1,1,1,1,1,1,1,1,1,1
1,1,1,1,1,1,1,1,1,1,2,2,2,2,2,1,1,1,1,1,1,1,1,1,1
1,1,1,1,1,1,1,1,1,1,2,2,2,2,2,1,1,1,1,1,1,1,1,1,1
1,1,1,1,1,1,1,1,1,1,2,2,2,2,2,1,1,1,1,1,1,1,1,1,1
1,1,1,1,1,1,1,1,1,1,2,2,2,2,2,1,1,1,1,1,1,1,1,1,1
1,1,1,1,1,1,1,1,1,1,2,2,2,2,2,1,1,1,1,1,1,1,1,1,1
1,1,1,1,1,1,1,1,1,1,2,2,2,2,2,1,1,1,1,1,1,1,1,1,1
1,1,1,1,1,1,1,1,1,1,2,2,2,2,2,1,1,1,1,1,1,1,1,1,1
1,1,1,1,1,1,1,1,1,1,2,2,2,2,2,1,1,1,1,1,1,1,1,1,1
1,1,1,1,1,1,1,1,1,1,2,2,2,2,2,1,1,1,1,1,1,1,1,1,1
1,1,1,1,1,1,1,1,1,1,2,2,2,2,2,1,1,1,1,1,1,1,1,1,1
1,1,1,1,1,1,1,1,1,1,2,2,2,2,2,1,1,1,1,1,1,1,1,1,1
1,1,1,1,1,1,1,1,1,1,2,2,2,2,2,1,1,1,1,1,1,1,1,1,1
1,1,1,1,1,1,1,1,1,1,1,2,2,2,1,1,1,1,1,1,1,1,1,1,1
1,1,1,1,1,1,1,1,1,1,1,2,2,2,1,1,1,1,1,1,1,1,1,1,1
1,1,1,1,1,1,1,1,1,1,1,1,2,1,1,1,1,1,1,1,1,1,1,1,1
1,1,1,1,1,1,1,1,1,1,1,1,2,1,1,1,1,1,1,1,1,1,1,1,1
1,1,1,1,1,1,1,1,1,1,1,1,1,1,1,1,1,1,1,1,1,1,1,1,1
1,1,1,1,1,1,1,1,1,1,1,1,1,1,1,1,1,1,1,1,1,1,1,1,1
1,1,1,1,1,1,1,1,1,1,1,1,1,1,1,1,1,1,1,1,1,1,1,1,1
1,1,1,1,1,1,1,1,1,1,1,1,1,1,1,1,1,1,1,1,1,1,1,1,1
1,1,1,1,1,1,1,1,1,1,1,1,1,1,1,1,1,1,1,1,1,1,1,1,1
1,1,1,1,1,1,1,1,1,1,1,1,1,1,1,1,1,1,1,1,1,1,1,1,1
1,1,1,1,1,1,1,1,1,1,1,1,1,1,1,1,1,1,1,1,1,1,1,1,1
1,1,1,1,1,1,1,1,1,1,1,1,1,1,1,1,1,1,1,1,1,1,1,1,1
1,1,1,1,1,1,1,1,1,1,1,1,1,1,1,1,1,1,1,1,1,1,1,1,1
1,1,1,1,1,1,1,1,1,1,1,1,1,1,1,1,1,1,1,1,1,1,1,1,1
1,1,1,1,1,1,1,1,1,1,1,1,1,1,1,1,1,1,1,1,1,1,1,1,1
1,1,1,1,1,1,1,1,1,1,1,1,1,1,1,1,1,1,1,1,1,1,1,1,1
1,1,1,1,1,1,1,1,1,1,1,1,1,1,1,1,1,1,1,1,1,1,1,1,1
1,1,1,1,1,1,1,1,1,1,1,1,1,1,1,1,1,1,1,1,1,1,1,1,1
1,1,1,1,1,1,1,1,1,1,1,1,1,1,1,1,1,1,1,1,1,1,1,1,1
1,1,1,1,1,1,1,1,1,1,1,1,1,1,1,1,1,1,1,1,1,1,1,1,1
1,1,1,1,1,1,1,1,1,1,1,1,1,1,1,1,1,1,1,1,1,1,1,1,1
1,1,1,1,1,1,1,1,1,1,1,1,1,1,1,1,1,1,1,1,1,1,1,1,1
1,1,1,1,1,1,1,1,1,1,1,1,1,1,1,1,1,1,1,1,1,1,1,1,1
1,1,1,1,1,1,1,1,1,1,1,1,1,1,1,1,1,1,1,1,1,1,1,1,1
1,1,1,1,1,1,1,1,1,1,1,1,1,1,1,1,1,1,1,1,1,1,1,1,1
1,1,1,1,1,1,1,1,1,1,1,1,1,1,1,1,1,1,1,1,1,1,1,1,1
1,1,1,1,1,1,1,1,1,1,1,1,1,1,1,1,1,1,1,1,1,1,1,1,1
:endlayer
layer: 4
1,1,1,1,1,1,1,1,1,1,1,1,1,1,1,1,1,1,1,1,1,1,1,1,1
1,1,1,1,1,1,1,1,1,1,1,1,1,1,1,1,1,1,1,1,1,1,1,1,1
1,1,1,1,1,1,1,1,1,1,1,1,1,1,1,1,1,1,1,1,1,1,1,1,1
1,1,1,1,1,1,1,1,1,1,1,1,1,1,1,1,1,1,1,1,1,1,1,1,1
1,1,1,1,1,1,1,1,1,1,1,1,1,1,1,1,1,1,1,1,1,1,1,1,1
1,1,1,1,1,1,1,1,1,1,1,1,1,1,1,1,1,1,1,1,1,1,1,1,1
1,1,1,1,1,1,1,1,1,1,1,1,1,1,1,1,1,1,1,1,1,1,1,1,1
1,1,1,1,1,1,1,1,1,1,1,1,1,1,1,1,1,1,1,1,1,1,1,1,1
1,1,1,1,1,1,1,1,1,1,1,1,1,1,1,1,1,1,1,1,1,1,1,1,1
1,1,1,1,1,1,1,1,1,1,1,1,1,1,1,1,1,1,1,1,1,1,1,1,1
1,1,1,1,1,1,1,1,1,1,1,1,1,1,1,1,1,1,1,1,1,1,1,1,1
1,1,1,1,1,1,1,1,1,1,1,1,1,1,1,1,1,1,1,1,1,1,1,1,1
1,1,1,1,1,1,1,1,1,1,1,1,1,1,1,1,1,1,1,1,1,1,1,1,1
1,1,1,1,1,1,1,1,1,1,1,1,1,1,1,1,1,1,1,1,1,1,1,1,1
1,1,1,1,1,1,1,1,1,1,1,1,1,1,1,1,1,1,1,1,1,1,1,1,1
1,1,1,1,1,1,1,1,1,1,1,1,1,1,1,1,1,1,1,1,1,1,1,1,1
1,1,1,1,1,1,1,1,1,1,1,1,1,1,1,1,1,1,1,1,1,1,1,1,1
1,1,1,1,1,1,1,1,1,1,2,2,2,2,2,1,1,1,1,1,1,1,1,1,1
1,1,1,1,1,1,1,1,1,2,2,40,2,2,2,2,1,1,1,1,1,1,1,1,1
1,1,1,1,1,1,1,1,1,2,54,0,2,2,2,2,1,1,1,1,1,1,1,1,1
1,1,1,1,1,1,1,1,1,2,55,33,2,2,2,2,1,1,1,1,1,1,1,1,1
1,1,1,1,1,1,1,1,1,2,2,2,31,2,2,2,1,1,1,1,1,1,1,1,1
1,1,1,1,1,1,1,1,1,2,56,41,22,20,3,2,1,1,1,1,1,1,1,1,1
1,1,1,1,1,1,1,1,1,2,57,42,0,21,4,2,1,1,1,1,1,1,1,1,1
1,1,1,1,1,1,1,1,1,2,58,0,0,22,5,2,1,1,1,1,1,1,1,1,1
1,1,1,1,1,1,1,1,1,2,59,43,0,23,6,2,1,1,1,1,1,1,1,1,1
1,1,1,1,1,1,1,1,1,2,60,44,32,22,7,2,1,1,1,1,1,1,1,1,1
1,1,1,1,1,1,1,1,1,2,58,22,0,0,5,2,1,1,1,1,1,1,1,1,1
1,1,1,1,1,1,1,1,1,2,61,22,0,24,8,2,1,1,1,1,1,1,1,1,1
1,1,1,1,1,1,1,1,1,2,62,0,0,0,9,2,1,1,1,1,1,1,1,1,1
1,1,1,1,1,1,1,1,1,2,58,45,33,22,5,2,1,1,1,1,1,1,1,1,1
1,1,1,1,1,1,1,1,1,2,2,2,31,2,2,2,1,1,1,1,1,1,1,1,1
1,1,1,1,1,1,1,1,1,2,63,46,34,0,0,2,1,1,1,1,1,1,1,1,1
1,1,1,1,1,1,1,1,1,2,64,0,10,25,0,2,1,1,1,1,1,1,1,1,1
1,1,1,1,1,1,1,1,1,2,65,0,10,10,10,2,1,1,1,1,1,1,1,1,1
1,1,1,1,1,1,1,1,1,2,66,0,34,0,0,2,1,1,1,1,1,1,1,1,1
1,1,1,1,1,1,1,1,1,2,67,47,10,26,0,2,1,1,1,1,1,1,1,1,1
1,1,1,1,1,1,1,1,1,2,67,0,10,10,10,2,1,1,1,1,1,1,1,1,1
1,1,1,1,1,1,1,1,1,2,66,0,34,0,11,2,1,1,1,1,1,1,1,1,1
1,1,1,1,1,1,1,1,1,2,0,0,10,10,10,2,1,1,1,1,1,1,1,1,1
1,1,1,1,1,1,1,1,1,2,68,0,33,27,12,2,1,1,1,1,1,1,1,1,1
1,1,1,1,1,1,1,1,1,2,2,30,31,2,2,2,1,1,1,1,1,1,1,1,1
1,1,1,1,1,1,1,1,1,2,22,0,0,28,13,2,1,1,1,1,1,1,1,1,1
1,1,1,1,1,1,1,1,1,2,69,22,0,29,14,2,1,1,1,1,1,1,1,1,1
1,1,1,1,1,1,1,1,1,2,70,48,0,0,15,2,1,1,1,1,1,1,1,1,1
1,1,1,1,1,1,1,1,1,2,71,49,35,0,16,2,1,1,1,1,1,1,1,1,1
1,1,1,1,1,1,1,1,1,2,72,50,0,0,17,2,1,1,1,1,1,1,1,1,1
1,1,1,1,1,1,1,1,1,2,73,51,36,0,18,2,1,1,1,1,1,1,1,1,1
1,1,1,1,1,1,1,1,1,2,2,2,31,30,2,2,1,1,1,1,1,1,1,1,1
1,1,1,1,1,1,1,1,1,2,74,0,37,0,19,2,1,1,1,1,1,1,1,1,1
1,1,1,1,1,1,1,1,1,2,2,0,33,0,2,2,1,1,1,1,1,1,1,1,1
1,1,1,1,1,1,1,1,1,1,2,52,31,0,2,1,1,1,1,1,1,1,1,1,1
1,1,1,1,1,1,1,1,1,1,2,53,0,0,2,1,1,1,1,1,1,1,1,1,1
1,1,1,1,1,1,1,1,1,1,2,2,38,2,2,1,1,1,1,1,1,1,1,1,1
1,1,1,1,1,1,1,1,1,1,1,2,39,2,1,1,1,1,1,1,1,1,1,1,1
1,1,1,1,1,1,1,1,1,1,1,2,2,2,1,1,1,1,1,1,1,1,1,1,1
1,1,1,1,1,1,1,1,1,1,1,1,2,1,1,1,1,1,1,1,1,1,1,1,1
1,1,1,1,1,1,1,1,1,1,1,1,2,1,1,1,1,1,1,1,1,1,1,1,1
1,1,1,1,1,1,1,1,1,1,1,1,2,1,1,1,1,1,1,1,1,1,1,1,1
1,1,1,1,1,1,1,1,1,1,1,1,1,1,1,1,1,1,1,1,1,1,1,1,1
1,1,1,1,1,1,1,1,1,1,1,1,1,1,1,1,1,1,1,1,1,1,1,1,1
1,1,1,1,1,1,1,1,1,1,1,1,1,1,1,1,1,1,1,1,1,1,1,1,1
1,1,1,1,1,1,1,1,1,1,1,1,1,1,1,1,1,1,1,1,1,1,1,1,1
1,1,1,1,1,1,1,1,1,1,1,1,1,1,1,1,1,1,1,1,1,1,1,1,1
1,1,1,1,1,1,1,1,1,1,1,1,1,1,1,1,1,1,1,1,1,1,1,1,1
1,1,1,1,1,1,1,1,1,1,1,1,1,1,1,1,1,1,1,1,1,1,1,1,1
1,1,1,1,1,1,1,1,1,1,1,1,1,1,1,1,1,1,1,1,1,1,1,1,1
1,1,1,1,1,1,1,1,1,1,1,1,1,1,1,1,1,1,1,1,1,1,1,1,1
1,1,1,1,1,1,1,1,1,1,1,1,1,1,1,1,1,1,1,1,1,1,1,1,1
1,1,1,1,1,1,1,1,1,1,1,1,1,1,1,1,1,1,1,1,1,1,1,1,1
1,1,1,1,1,1,1,1,1,1,1,1,1,1,1,1,1,1,1,1,1,1,1,1,1
1,1,1,1,1,1,1,1,1,1,1,1,1,1,1,1,1,1,1,1,1,1,1,1,1
1,1,1,1,1,1,1,1,1,1,1,1,1,1,1,1,1,1,1,1,1,1,1,1,1
1,1,1,1,1,1,1,1,1,1,1,1,1,1,1,1,1,1,1,1,1,1,1,1,1
1,1,1,1,1,1,1,1,1,1,1,1,1,1,1,1,1,1,1,1,1,1,1,1,1
1,1,1,1,1,1,1,1,1,1,1,1,1,1,1,1,1,1,1,1,1,1,1,1,1
1,1,1,1,1,1,1,1,1,1,1,1,1,1,1,1,1,1,1,1,1,1,1,1,1
1,1,1,1,1,1,1,1,1,1,1,1,1,1,1,1,1,1,1,1,1,1,1,1,1
1,1,1,1,1,1,1,1,1,1,1,1,1,1,1,1,1,1,1,1,1,1,1,1,1
:endlayer
layer: 5
1,1,1,1,1,1,1,1,1,1,1,1,1,1,1,1,1,1,1,1,1,1,1,1,1
1,1,1,1,1,1,1,1,1,1,1,1,1,1,1,1,1,1,1,1,1,1,1,1,1
1,1,1,1,1,1,1,1,1,1,1,1,1,1,1,1,1,1,1,1,1,1,1,1,1
1,1,1,1,1,1,1,1,1,1,1,1,1,1,1,1,1,1,1,1,1,1,1,1,1
1,1,1,1,1,1,1,1,1,1,1,1,1,1,1,1,1,1,1,1,1,1,1,1,1
1,1,1,1,1,1,1,1,1,1,1,1,1,1,1,1,1,1,1,1,1,1,1,1,1
1,1,1,1,1,1,1,1,1,1,1,1,1,1,1,1,1,1,1,1,1,1,1,1,1
1,1,1,1,1,1,1,1,1,1,1,1,1,1,1,1,1,1,1,1,1,1,1,1,1
1,1,1,1,1,1,1,1,1,1,1,1,1,1,1,1,1,1,1,1,1,1,1,1,1
1,1,1,1,1,1,1,1,1,1,1,1,1,1,1,1,1,1,1,1,1,1,1,1,1
1,1,1,1,1,1,1,1,1,1,1,1,1,1,1,1,1,1,1,1,1,1,1,1,1
1,1,1,1,1,1,1,1,1,1,1,1,1,1,1,1,1,1,1,1,1,1,1,1,1
1,1,1,1,1,1,1,1,1,1,1,1,1,1,1,1,1,1,1,1,1,1,1,1,1
1,1,1,1,1,1,1,1,1,1,1,1,1,1,1,1,1,1,1,1,1,1,1,1,1
1,1,1,1,1,1,1,1,1,1,1,1,1,1,1,1,1,1,1,1,1,1,1,1,1
1,1,1,1,1,1,1,1,1,1,1,1,2,1,1,1,1,1,1,1,1,1,1,1,1
1,1,1,1,1,1,1,1,1,2,2,2,2,2,2,2,1,1,1,1,1,1,1,1,1
1,1,1,1,1,1,1,1,2,2,117,113,2,10,96,2,2,1,1,1,1,1,1,1,1
1,1,1,1,1,1,1,1,2,121,32,0,2,104,97,75,2,1,1,1,1,1,1,1,1
1,1,1,1,1,1,1,1,2,122,0,0,2,105,98,0,2,1,1,1,1,1,1,1,1
1,1,1,1,1,1,1,1,2,123,0,33,2,106,58,76,2,1,1,1,1,1,1,1,1
1,1,1,1,1,1,1,1,2,2,2,2,31,2,2,2,2,1,1,1,1,1,1,1,1
1,1,1,1,1,1,1,1,2,124,0,0,111,0,0,77,2,1,1,1,1,1,1,1,1
1,1,1,1,1,1,1,1,2,125,0,0,0,0,0,78,2,1,1,1,1,1,1,1,1
1,1,1,1,1,1,1,1,2,126,0,0,0,0,0,79,2,1,1,1,1,1,1,1,1
1,1,1,1,1,1,1,1,2,127,0,0,0,0,0,80,2,1,1,1,1,1,1,1,1
1,1,1,1,1,1,1,1,2,128,0,0,0,0,0,81,2,1,1,1,1,1,1,1,1
1,1,1,1,1,1,1,1,2,129,0,0,0,0,0,82,2,1,1,1,1,1,1,1,1
1,1,1,1,1,1,1,1,2,130,0,0,0,0,0,83,2,1,1,1,1,1,1,1,1
1,1,1,1,1,1,1,1,2,131,0,0,0,0,0,84,2,1,1,1,1,1,1,1,1
1,1,1,1,1,1,1,1,2,132,22,107,33,107,0,85,2,1,1,1,1,1,1,1,1
1,1,1,1,1,1,1,1,2,2,2,2,31,2,2,2,2,1,1,1,1,1,1,1,1
1,1,1,1,1,1,1,1,2,63,65,0,0,0,0,64,2,1,1,1,1,1,1,1,1
1,1,1,1,1,1,1,1,2,133,0,0,0,0,0,86,2,1,1,1,1,1,1,1,1
1,1,1,1,1,1,1,1,2,134,0,0,10,32,10,10,2,1,1,1,1,1,1,1,1
1,1,1,1,1,1,1,1,2,135,0,0,0,0,0,87,2,1,1,1,1,1,1,1,1
1,1,1,1,1,1,1,1,2,136,0,0,0,0,0,65,2,1,1,1,1,1,1,1,1
1,1,1,1,1,1,1,1,2,137,0,0,10,32,10,10,2,1,1,1,1,1,1,1,1
1,1,1,1,1,1,1,1,2,135,0,0,0,0,0,88,2,1,1,1,1,1,1,1,1
1,1,1,1,1,1,1,1,2,138,0,0,10,32,10,10,2,1,1,1,1,1,1,1,1
1,1,1,1,1,1,1,1,2,139,0,0,33,0,0,89,2,1,1,1,1,1,1,1,1
1,1,1,1,1,1,1,1,2,2,2,114,31,2,2,2,2,1,1,1,1,1,1,1,1
1,1,1,1,1,1,1,1,2,140,0,0,111,0,0,90,2,1,1,1,1,1,1,1,1
1,1,1,1,1,1,1,1,2,141,0,0,0,0,0,91,2,1,1,1,1,1,1,1,1
1,1,1,1,1,1,1,1,2,142,0,0,0,0,99,92,2,1,1,1,1,1,1,1,1
1,1,1,1,1,1,1,1,2,143,0,0,0,0,0,93,2,1,1,1,1,1,1,1,1
1,1,1,1,1,1,1,1,2,144,0,0,0,0,0,94,2,1,1,1,1,1,1,1,1
1,1,1,1,1,1,1,1,2,145,0,0,107,0,100,95,2,1,1,1,1,1,1,1,1
1,1,1,1,1,1,1,1,2,2,2,2,31,108,2,2,2,1,1,1,1,1,1,1,1
1,1,1,1,1,1,1,1,2,2,118,0,111,0,101,2,2,1,1,1,1,1,1,1,1
1,1,1,1,1,1,1,1,1,2,2,0,33,0,2,2,1,1,1,1,1,1,1,1,1
1,1,1,1,1,1,1,1,1,2,119,0,31,0,102,2,1,1,1,1,1,1,1,1,1
1,1,1,1,1,1,1,1,1,2,120,0,111,0,103,2,1,1,1,1,1,1,1,1,1
1,1,1,1,1,1,1,1,1,2,2,115,0,109,2,2,1,1,1,1,1,1,1,1,1
1,1,1,1,1,1,1,1,1,1,2,116,0,110,2,1,1,1,1,1,1,1,1,1,1
1,1,1,1,1,1,1,1,1,1,2,2,112,2,2,1,1,1,1,1,1,1,1,1,1
1,1,1,1,1,1,1,1,1,1,1,2,2,2,1,1,1,1,1,1,1,1,1,1,1
1,1,1,1,1,1,1,1,1,1,1,2,2,2,1,1,1,1,1,1,1,1,1,1,1
1,1,1,1,1,1,1,1,1,1,1,1,2,1,1,1,1,1,1,1,1,1,1,1,1
1,1,1,1,1,1,1,1,1,1,1,1,2,1,1,1,1,1,1,1,1,1,1,1,1
1,1,1,1,1,1,1,1,1,1,1,1,2,1,1,1,1,1,1,1,1,1,1,1,1
1,1,1,1,1,1,1,1,1,1,1,1,1,1,1,1,1,1,1,1,1,1,1,1,1
1,1,1,1,1,1,1,1,1,1,1,1,1,1,1,1,1,1,1,1,1,1,1,1,1
1,1,1,1,1,1,1,1,1,1,1,1,1,1,1,1,1,1,1,1,1,1,1,1,1
1,1,1,1,1,1,1,1,1,1,1,1,1,1,1,1,1,1,1,1,1,1,1,1,1
1,1,1,1,1,1,1,1,1,1,1,1,1,1,1,1,1,1,1,1,1,1,1,1,1
1,1,1,1,1,1,1,1,1,1,1,1,1,1,1,1,1,1,1,1,1,1,1,1,1
1,1,1,1,1,1,1,1,1,1,1,1,1,1,1,1,1,1,1,1,1,1,1,1,1
1,1,1,1,1,1,1,1,1,1,1,1,1,1,1,1,1,1,1,1,1,1,1,1,1
1,1,1,1,1,1,1,1,1,1,1,1,1,1,1,1,1,1,1,1,1,1,1,1,1
1,1,1,1,1,1,1,1,1,1,1,1,1,1,1,1,1,1,1,1,1,1,1,1,1
1,1,1,1,1,1,1,1,1,1,1,1,1,1,1,1,1,1,1,1,1,1,1,1,1
1,1,1,1,1,1,1,1,1,1,1,1,1,1,1,1,1,1,1,1,1,1,1,1,1
1,1,1,1,1,1,1,1,1,1,1,1,1,1,1,1,1,1,1,1,1,1,1,1,1
1,1,1,1,1,1,1,1,1,1,1,1,1,1,1,1,1,1,1,1,1,1,1,1,1
1,1,1,1,1,1,1,1,1,1,1,1,1,1,1,1,1,1,1,1,1,1,1,1,1
1,1,1,1,1,1,1,1,1,1,1,1,1,1,1,1,1,1,1,1,1,1,1,1,1
1,1,1,1,1,1,1,1,1,1,1,1,1,1,1,1,1,1,1,1,1,1,1,1,1
1,1,1,1,1,1,1,1,1,1,1,1,1,1,1,1,1,1,1,1,1,1,1,1,1
:endlayer
layer: 6
1,1,1,1,1,1,1,1,1,1,1,1,1,1,1,1,1,1,1,1,1,1,1,1,1
1,1,1,1,1,1,1,1,1,1,1,1,1,1,1,1,1,1,1,1,1,1,1,1,1
1,1,1,1,1,1,1,1,1,1,1,1,1,1,1,1,1,1,1,1,1,1,1,1,1
1,1,1,1,1,1,1,1,1,1,1,1,1,1,1,1,1,1,1,1,1,1,1,1,1
1,1,1,1,1,1,1,1,1,1,1,1,1,1,1,1,1,1,1,1,1,1,1,1,1
1,1,1,1,1,1,1,1,1,1,1,1,1,1,1,1,1,1,1,1,1,1,1,1,1
1,1,1,1,1,1,1,1,1,1,1,1,1,1,1,1,1,1,1,1,1,1,1,1,1
1,1,1,1,1,1,1,1,1,1,1,1,1,1,1,1,1,1,1,1,1,1,1,1,1
1,1,1,1,1,1,1,1,1,1,1,1,1,1,1,1,1,1,1,1,1,1,1,1,1
1,1,1,1,1,1,1,1,1,1,1,1,1,1,1,1,1,1,1,1,1,1,1,1,1
1,1,1,1,1,1,1,1,1,1,1,1,1,1,1,1,1,1,1,1,1,1,1,1,1
1,1,1,1,1,1,1,1,1,1,1,1,1,1,1,1,1,1,1,1,1,1,1,1,1
1,1,1,1,1,1,1,1,1,1,1,1,1,1,1,1,1,1,1,1,1,1,1,1,1
1,1,1,1,1,1,1,1,1,1,1,1,1,1,1,1,1,1,1,1,1,1,1,1,1
1,1,1,1,1,1,1,1,1,1,1,2,2,2,1,1,1,1,1,1,1,1,1,1,1
1,1,1,1,1,1,1,1,2,2,2,2,2,2,2,2,2,1,1,1,1,1,1,1,1
1,1,1,1,1,1,1,2,2,157,157,157,2,155,153,75,75,2,1,1,1,1,1,1,1
1,1,1,1,1,1,1,2,157,157,157,157,2,10,154,0,146,2,1,1,1,1,1,1,1
1,1,1,1,1,1,1,2,157,157,157,157,2,156,0,0,147,2,1,1,1,1,1,1,1
1,1,1,1,1,1,1,2,157,157,157,157,2,106,0,0,148,2,1,1,1,1,1,1,1
1,1,1,1,1,1,1,2,157,157,157,33,2,58,0,0,149,2,1,1,1,1,1,1,1
1,1,1,1,1,1,1,2,2,2,2,2,31,2,2,2,2,2,1,1,1,1,1,1,1
1,1,1,1,1,1,1,2,150,151,151,151,151,151,151,151,150,2,1,1,1,1,1,1,1
1,1,1,1,1,1,1,2,150,151,151,151,151,151,151,151,150,2,1,1,1,1,1,1,1
1,1,1,1,1,1,1,2,150,151,151,151,151,151,151,151,150,2,1,1,1,1,1,1,1
1,1,1,1,1,1,1,2,150,151,151,151,151,151,151,151,150,2,1,1,1,1,1,1,1
1,1,1,1,1,1,1,2,150,151,151,151,151,151,151,151,150,2,1,1,1,1,1,1,1
1,1,1,1,1,1,1,2,150,151,151,151,151,151,151,151,150,2,1,1,1,1,1,1,1
1,1,1,1,1,1,1,2,150,151,151,151,151,151,151,151,150,2,1,1,1,1,1,1,1
1,1,1,1,1,1,1,2,150,151,151,151,151,151,151,151,150,2,1,1,1,1,1,1,1
1,1,1,1,1,1,1,2,150,151,151,151,33,151,151,151,150,2,1,1,1,1,1,1,1
1,1,1,1,1,1,1,2,150,150,150,150,31,150,150,150,150,2,1,1,1,1,1,1,1
1,1,1,1,1,1,1,2,150,151,151,151,151,151,151,151,150,2,1,1,1,1,1,1,1
1,1,1,1,1,1,1,2,150,151,151,151,151,151,151,151,150,2,1,1,1,1,1,1,1
1,1,1,1,1,1,1,2,150,151,151,151,152,151,151,152,150,2,1,1,1,1,1,1,1
1,1,1,1,1,1,1,2,150,151,151,151,151,151,151,151,150,2,1,1,1,1,1,1,1
1,1,1,1,1,1,1,2,150,151,151,151,151,151,151,151,150,2,1,1,1,1,1,1,1
1,1,1,1,1,1,1,2,150,151,151,151,152,151,151,152,150,2,1,1,1,1,1,1,1
1,1,1,1,1,1,1,2,150,151,151,151,151,151,151,151,150,2,1,1,1,1,1,1,1
1,1,1,1,1,1,1,2,150,151,151,151,152,151,151,152,150,2,1,1,1,1,1,1,1
1,1,1,1,1,1,1,2,150,151,151,151,33,151,151,151,150,2,1,1,1,1,1,1,1
1,1,1,1,1,1,1,2,150,150,150,150,31,150,150,150,150,2,1,1,1,1,1,1,1
1,1,1,1,1,1,1,2,150,151,151,151,151,151,151,151,150,2,1,1,1,1,1,1,1
1,1,1,1,1,1,1,2,150,151,151,151,151,151,151,151,150,2,1,1,1,1,1,1,1
1,1,1,1,1,1,1,2,150,151,151,151,151,151,151,151,150,2,1,1,1,1,1,1,1
1,1,1,1,1,1,1,2,150,151,151,151,151,151,151,151,150,2,1,1,1,1,1,1,1
1,1,1,1,1,1,1,2,150,151,151,151,151,151,151,151,150,2,1,1,1,1,1,1,1
1,1,1,1,1,1,1,2,150,151,151,151,151,151,151,151,150,2,1,1,1,1,1,1,1
1,1,1,1,1,1,1,2,2,2,2,2,31,2,2,2,2,2,1,1,1,1,1,1,1
1,1,1,1,1,1,1,1,2,150,151,151,151,151,151,150,2,1,1,1,1,1,1,1,1
1,1,1,1,1,1,1,1,2,150,150,151,33,151,150,150,2,1,1,1,1,1,1,1,1
1,1,1,1,1,1,1,1,2,150,151,151,31,151,151,150,2,1,1,1,1,1,1,1,1
1,1,1,1,1,1,1,1,2,150,151,151,151,151,151,150,2,1,1,1,1,1,1,1,1
1,1,1,1,1,1,1,1,2,150,150,151,151,151,150,150,2,1,1,1,1,1,1,1,1
1,1,1,1,1,1,1,1,1,2,150,151,151,151,150,2,1,1,1,1,1,1,1,1,1
1,1,1,1,1,1,1,1,1,2,150,150,151,150,150,2,1,1,1,1,1,1,1,1,1
1,1,1,1,1,1,1,1,1,1,2,2,150,2,2,1,1,1,1,1,1,1,1,1,1
1,1,1,1,1,1,1,1,1,1,2,2,2,2,2,1,1,1,1,1,1,1,1,1,1
1,1,1,1,1,1,1,1,1,1,1,2,2,2,1,1,1,1,1,1,1,1,1,1,1
1,1,1,1,1,1,1,1,1,1,1,2,2,2,1,1,1,1,1,1,1,1,1,1,1
1,1,1,1,1,1,1,1,1,1,1,2,2,2,1,1,1,1,1,1,1,1,1,1,1
1,1,1,1,1,1,1,1,1,1,1,1,2,1,1,1,1,1,1,1,1,1,1,1,1
1,1,1,1,1,1,1,1,1,1,1,1,2,1,1,1,1,1,1,1,1,1,1,1,1
1,1,1,1,1,1,1,1,1,1,1,1,1,1,1,1,1,1,1,1,1,1,1,1,1
1,1,1,1,1,1,1,1,1,1,1,1,1,1,1,1,1,1,1,1,1,1,1,1,1
1,1,1,1,1,1,1,1,1,1,1,1,1,1,1,1,1,1,1,1,1,1,1,1,1
1,1,1,1,1,1,1,1,1,1,1,1,1,1,1,1,1,1,1,1,1,1,1,1,1
1,1,1,1,1,1,1,1,1,1,1,1,1,1,1,1,1,1,1,1,1,1,1,1,1
1,1,1,1,1,1,1,1,1,1,1,1,1,1,1,1,1,1,1,1,1,1,1,1,1
1,1,1,1,1,1,1,1,1,1,1,1,1,1,1,1,1,1,1,1,1,1,1,1,1
1,1,1,1,1,1,1,1,1,1,1,1,1,1,1,1,1,1,1,1,1,1,1,1,1
1,1,1,1,1,1,1,1,1,1,1,1,1,1,1,1,1,1,1,1,1,1,1,1,1
1,1,1,1,1,1,1,1,1,1,1,1,1,1,1,1,1,1,1,1,1,1,1,1,1
1,1,1,1,1,1,1,1,1,1,1,1,1,1,1,1,1,1,1,1,1,1,1,1,1
1,1,1,1,1,1,1,1,1,1,1,1,1,1,1,1,1,1,1,1,1,1,1,1,1
1,1,1,1,1,1,1,1,1,1,1,1,1,1,1,1,1,1,1,1,1,1,1,1,1
1,1,1,1,1,1,1,1,1,1,1,1,1,1,1,1,1,1,1,1,1,1,1,1,1
1,1,1,1,1,1,1,1,1,1,1,1,1,1,1,1,1,1,1,1,1,1,1,1,1
1,1,1,1,1,1,1,1,1,1,1,1,1,1,1,1,1,1,1,1,1,1,1,1,1
:endlayer
layer: 7
0,0,0,0,0,0,0,0,0,0,0,0,0,0,0,0,0,0,0,0,0,0,0,0,0
0,0,0,0,0,0,0,0,0,0,0,0,0,0,0,0,0,0,0,0,0,0,0,0,0
0,0,0,0,0,0,0,0,0,0,0,0,0,0,0,0,0,0,0,0,0,0,0,0,0
0,0,0,0,0,0,0,0,0,0,0,0,0,0,0,0,0,0,0,0,0,0,0,0,0
0,0,0,0,0,0,0,0,0,0,0,0,0,0,0,0,0,0,0,0,0,0,0,0,0
0,0,0,0,0,0,0,0,0,0,0,0,0,0,0,0,0,0,0,0,0,0,0,0,0
0,0,0,0,0,0,0,0,0,0,0,0,0,0,0,0,0,0,0,0,0,0,0,0,0
0,0,0,0,0,0,0,0,0,0,0,0,0,0,0,0,0,0,0,0,0,0,0,0,0
0,0,0,0,0,0,0,0,0,0,0,0,0,0,0,0,0,0,0,0,0,0,0,0,0
0,0,0,0,0,0,0,0,0,0,0,0,0,0,0,0,0,0,0,0,0,0,0,0,0
0,0,0,0,0,0,0,0,0,0,0,0,0,0,0,0,0,0,0,0,0,0,0,0,0
0,0,0,0,0,0,0,0,0,0,0,0,0,0,0,0,0,0,0,0,0,0,0,0,0
0,0,0,0,0,0,0,0,0,0,0,0,0,0,0,0,0,0,0,0,0,0,0,0,0
0,0,0,0,0,0,0,0,0,250,2,2,2,2,2,159,0,0,0,0,0,0,0,0,0
0,0,0,0,0,0,0,250,2,2,2,233,2,75,75,2,2,159,0,0,0,0,0,0,0
0,0,0,0,0,0,0,2,2,251,233,233,2,214,199,189,10,2,0,0,0,0,0,0,0
0,0,0,0,0,0,158,2,111,0,0,234,2,215,0,190,177,2,158,0,0,0,0,0,0
0,0,0,0,0,0,250,0,258,0,0,235,2,10,0,0,0,160,159,0,0,0,0,0,0
0,0,0,0,0,0,250,0,0,0,246,236,2,106,0,0,0,161,159,0,0,0,0,0,0
0,0,0,0,0,0,250,0,259,0,0,0,2,216,0,0,0,162,159,0,0,0,0,0,0
0,0,0,0,0,0,250,0,0,0,0,33,2,0,0,107,178,163,159,0,0,0,0,0,0
0,0,0,0,0,0,250,2,2,30,30,2,31,2,2,2,2,2,159,0,0,0,0,0,0
0,0,0,0,0,0,250,266,260,0,0,237,227,2,200,191,179,164,159,0,0,0,0,0,0
0,0,0,0,0,0,250,267,261,206,0,0,0,30,0,192,0,165,159,0,0,0,0,0,0
0,0,0,0,0,0,250,268,0,0,0,238,0,30,0,0,0,165,159,0,0,0,0,0,0
0,0,0,0,0,0,250,267,261,206,193,182,171,2,22,0,0,166,159,0,0,0,0,0,0
0,0,0,0,0,0,250,269,262,0,0,0,22,2,201,0,180,167,159,0,0,0,0,0,0
0,0,0,0,0,0,250,267,261,206,193,182,171,2,2,0,2,2,159,0,0,0,0,0,0
0,0,0,0,0,0,250,270,0,0,0,239,228,2,202,0,0,168,159,0,0,0,0,0,0
0,0,0,0,0,0,250,267,261,206,193,182,171,2,203,0,0,169,159,0,0,0,0,0,0
0,0,0,0,0,0,250,202,263,0,0,0,33,2,204,0,181,170,159,0,0,0,0,0,0
0,0,0,0,0,0,250,2,2,0,0,2,31,2,2,2,2,2,159,0,0,0,0,0,0
0,0,0,0,0,0,250,252,252,252,0,0,10,217,205,10,0,22,159,0,0,0,0,0,0
0,0,0,0,0,0,250,253,253,253,0,0,5,218,0,193,182,171,159,0,0,0,0,0,0
0,0,0,0,0,0,250,252,252,252,247,0,0,219,0,194,0,172,159,0,0,0,0,0,0
0,0,0,0,0,0,250,252,252,252,0,193,182,171,206,193,182,171,159,0,0,0,0,0,0
0,0,0,0,0,0,250,253,253,253,248,0,0,0,0,195,0,173,159,0,0,0,0,0,0
0,0,0,0,0,0,250,252,252,252,0,193,182,171,206,193,182,171,159,0,0,0,0,0,0
0,0,0,0,0,0,250,252,252,252,249,240,0,0,0,0,183,22,159,0,0,0,0,0,0
0,0,0,0,0,0,250,253,253,253,0,193,182,171,206,193,182,171,159,0,0,0,0,0,0
0,0,0,0,0,0,250,252,252,252,0,0,33,0,207,0,0,174,159,0,0,0,0,0,0
0,0,0,0,0,0,250,2,2,2,2,2,31,0,2,2,2,2,159,0,0,0,0,0,0
0,0,0,0,0,0,250,271,0,0,208,230,208,0,208,0,0,175,159,0,0,0,0,0,0
0,0,0,0,0,0,250,267,261,206,209,0,209,0,209,193,182,171,159,0,0,0,0,0,0
0,0,0,0,0,0,250,272,0,254,210,0,210,0,210,0,184,176,159,0,0,0,0,0,0
0,0,0,0,0,0,250,267,261,206,211,241,211,0,211,193,182,171,159,0,0,0,0,0,0
0,0,0,0,0,0,250,135,0,0,212,0,212,0,212,0,0,22,159,0,0,0,0,0,0
0,0,0,0,0,0,158,2,264,206,213,22,213,220,213,193,185,2,158,0,0,0,0,0,0
0,0,0,0,0,0,0,2,2,2,2,2,31,2,2,2,2,2,0,0,0,0,0,0,0
0,0,0,0,0,0,0,2,265,255,0,242,229,221,58,0,186,2,0,0,0,0,0,0,0
0,0,0,0,0,0,0,2,265,255,0,0,33,0,0,0,187,2,0,0,0,0,0,0,0
0,0,0,0,0,0,0,158,257,256,0,0,31,222,0,196,188,158,0,0,0,0,0,0,0
0,0,0,0,0,0,0,158,257,197,0,0,0,0,0,197,188,158,0,0,0,0,0,0,0
0,0,0,0,0,0,0,0,257,198,0,243,0,0,0,198,188,0,0,0,0,0,0,0,0
0,0,0,0,0,0,0,0,2,257,165,202,165,0,197,188,2,0,0,0,0,0,0,0,0
0,0,0,0,0,0,0,0,2,257,165,202,165,223,198,188,2,0,0,0,0,0,0,0,0
0,0,0,0,0,0,0,0,158,2,2,2,2,2,2,2,158,0,0,0,0,0,0,0,0
0,0,0,0,0,0,0,0,0,2,2,244,230,224,2,2,0,0,0,0,0,0,0,0,0
0,0,0,0,0,0,0,0,0,158,2,245,0,225,2,158,0,0,0,0,0,0,0,0,0
0,0,0,0,0,0,0,0,0,0,2,2,231,2,2,0,0,0,0,0,0,0,0,0,0
0,0,0,0,0,0,0,0,0,0,158,2,232,2,158,0,0,0,0,0,0,0,0,0,0
0,0,0,0,0,0,0,0,0,0,0,2,2,2,0,0,0,0,0,0,0,0,0,0,0
0,0,0,0,0,0,0,0,0,0,0,226,2,226,0,0,0,0,0,0,0,0,0,0,0
0,0,0,0,0,0,0,0,0,0,0,0,226,0,0,0,0,0,0,0,0,0,0,0,0
0,0,0,0,0,0,0,0,0,0,0,0,0,0,0,0,0,0,0,0,0,0,0,0,0
0,0,0,0,0,0,0,0,0,0,0,0,0,0,0,0,0,0,0,0,0,0,0,0,0
0,0,0,0,0,0,0,0,0,0,0,0,0,0,0,0,0,0,0,0,0,0,0,0,0
0,0,0,0,0,0,0,0,0,0,0,0,0,0,0,0,0,0,0,0,0,0,0,0,0
0,0,0,0,0,0,0,0,0,0,0,0,0,0,0,0,0,0,0,0,0,0,0,0,0
0,0,0,0,0,0,0,0,0,0,0,0,0,0,0,0,0,0,0,0,0,0,0,0,0
0,0,0,0,0,0,0,0,0,0,0,0,0,0,0,0,0,0,0,0,0,0,0,0,0
0,0,0,0,0,0,0,0,0,0,0,0,0,0,0,0,0,0,0,0,0,0,0,0,0
0,0,0,0,0,0,0,0,0,0,0,0,0,0,0,0,0,0,0,0,0,0,0,0,0
0,0,0,0,0,0,0,0,0,0,0,0,0,0,0,0,0,0,0,0,0,0,0,0,0
0,0,0,0,0,0,0,0,0,0,0,0,0,0,0,0,0,0,0,0,0,0,0,0,0
0,0,0,0,0,0,0,0,0,0,0,0,0,0,0,0,0,0,0,0,0,0,0,0,0
0,0,0,0,0,0,0,0,0,0,0,0,0,0,0,0,0,0,0,0,0,0,0,0,0
0,0,0,0,0,0,0,0,0,0,0,0,0,0,0,0,0,0,0,0,0,0,0,0,0
0,0,0,0,0,0,0,0,0,0,0,0,0,0,0,0,0,0,0,0,0,0,0,0,0
:endlayer
layer: 8
0,0,0,0,0,0,0,0,0,0,0,0,0,0,0,0,0,0,0,0,0,0,0,0,0
0,0,0,0,0,0,0,0,0,0,0,0,0,0,0,0,0,0,0,0,0,0,0,0,0
0,0,0,0,0,0,0,0,0,0,0,0,0,0,0,0,0,0,0,0,0,0,0,0,0
0,0,0,0,0,0,0,0,0,0,0,0,0,0,0,0,0,0,0,0,0,0,0,0,0
0,0,0,0,0,0,0,0,0,0,0,0,0,0,0,0,0,0,0,0,0,0,0,0,0
0,0,0,0,0,0,0,0,0,0,0,0,0,0,0,0,0,0,0,0,0,0,0,0,0
0,0,0,0,0,0,0,0,0,0,0,0,0,0,0,0,0,0,0,0,0,0,0,0,0
0,0,0,0,0,0,0,0,0,0,0,0,0,0,0,0,0,0,0,0,0,0,0,0,0
0,0,0,0,0,0,0,0,0,0,0,0,0,0,0,0,0,0,0,0,0,0,0,0,0
0,0,0,0,0,0,0,0,0,0,0,0,0,0,0,0,0,0,0,0,0,0,0,0,0
0,0,0,0,0,0,0,0,0,0,0,0,0,0,0,0,0,0,0,0,0,0,0,0,0
0,0,0,0,0,0,0,0,0,0,0,0,158,0,0,0,0,0,0,0,0,0,0,0,0
0,0,0,0,0,0,0,0,250,2,2,2,2,2,2,2,159,0,0,0,0,0,0,0,0
0,0,0,0,0,0,273,2,2,2,233,233,2,293,286,2,2,2,273,0,0,0,0,0,0
0,0,0,0,0,0,274,2,307,233,233,0,2,10,287,285,283,2,274,0,0,0,0,0,0
0,0,0,0,0,0,274,308,0,0,0,0,2,294,0,0,10,277,274,0,0,0,0,0,0
0,0,0,0,0,0,274,309,0,0,0,0,2,295,0,0,0,278,274,0,0,0,0,0,0
0,0,0,0,0,0,274,135,0,0,0,177,2,106,0,0,0,279,274,0,0,0,0,0,0
0,0,0,0,0,0,275,0,0,0,0,0,2,216,0,0,0,280,275,0,0,0,0,0,0
0,0,0,0,0,0,274,135,0,0,0,177,2,0,0,0,0,281,274,0,0,0,0,0,0
0,0,0,0,0,0,275,0,107,0,0,33,2,0,0,0,0,0,275,0,0,0,0,0,0
0,0,0,0,0,0,274,2,2,108,114,2,31,2,2,2,2,2,274,0,0,0,0,0,0
0,0,0,0,0,0,275,0,111,0,0,301,299,274,0,0,0,0,275,0,0,0,0,0,0
0,0,0,0,0,0,274,267,261,206,0,0,0,108,0,0,0,177,274,0,0,0,0,0,0
0,0,0,0,0,0,275,282,0,0,0,0,0,114,0,0,0,0,275,0,0,0,0,0,0
0,0,0,0,0,0,274,267,261,206,193,182,171,274,288,0,0,177,274,0,0,0,0,0,0
0,0,0,0,0,0,275,0,0,0,0,0,177,274,289,0,0,0,275,0,0,0,0,0,0
0,0,0,0,0,0,274,267,261,206,193,182,171,274,274,0,274,274,274,0,0,0,0,0,0
0,0,0,0,0,0,275,0,0,0,0,0,177,274,282,0,0,0,275,0,0,0,0,0,0
0,0,0,0,0,0,274,267,261,206,193,182,171,274,0,0,0,0,274,0,0,0,0,0,0
0,0,0,0,0,0,275,0,0,0,0,0,33,274,0,0,107,0,275,0,0,0,0,0,0
0,0,0,0,0,0,274,274,274,0,0,274,31,274,274,274,274,274,274,0,0,0,0,0,0
0,0,0,0,0,0,275,0,111,0,0,111,10,296,290,10,111,0,275,0,0,0,0,0,0
0,0,0,0,0,0,274,135,0,0,0,0,0,5,218,193,182,171,274,0,0,0,0,0,0
0,0,0,0,0,0,275,0,0,0,0,0,0,0,0,0,0,0,275,0,0,0,0,0,0
0,0,0,0,0,0,274,135,0,0,0,193,182,171,206,193,182,171,274,0,0,0,0,0,0
0,0,0,0,0,0,275,0,0,0,0,0,0,0,0,0,0,0,275,0,0,0,0,0,0
0,0,0,0,0,0,274,135,0,0,0,193,182,171,206,193,182,171,274,0,0,0,0,0,0
0,0,0,0,0,0,275,0,0,0,0,0,0,0,0,0,0,282,275,0,0,0,0,0,0
0,0,0,0,0,0,274,135,0,306,0,193,182,171,206,193,182,171,274,0,0,0,0,0,0
0,0,0,0,0,0,275,0,0,0,107,0,33,0,107,0,0,0,275,0,0,0,0,0,0
0,0,0,0,0,0,274,274,274,274,274,274,31,0,274,274,274,274,274,0,0,0,0,0,0
0,0,0,0,0,0,275,0,0,111,208,230,208,0,208,111,0,0,275,0,0,0,0,0,0
0,0,0,0,0,0,274,267,261,206,209,0,209,0,209,193,182,171,274,0,0,0,0,0,0
0,0,0,0,0,0,275,0,0,0,210,0,210,0,210,0,0,0,275,0,0,0,0,0,0
0,0,0,0,0,0,274,267,261,206,211,0,211,0,211,193,182,171,274,0,0,0,0,0,0
0,0,0,0,0,0,275,0,0,0,212,0,212,0,212,0,0,282,275,0,0,0,0,0,0
0,0,0,0,0,0,274,267,261,206,213,107,213,107,213,193,182,171,274,0,0,0,0,0,0
0,0,0,0,0,0,274,274,274,274,274,274,31,274,274,274,274,274,274,0,0,0,0,0,0
0,0,0,0,0,0,276,274,135,0,0,0,152,58,0,0,177,274,276,0,0,0,0,0,0
0,0,0,0,0,0,0,275,0,0,0,0,33,0,0,0,0,275,0,0,0,0,0,0,0
0,0,0,0,0,0,0,274,135,0,0,0,31,0,0,0,177,274,0,0,0,0,0,0,0
0,0,0,0,0,0,0,275,0,0,0,0,111,0,0,0,0,275,0,0,0,0,0,0,0
0,0,0,0,0,0,0,274,135,0,0,0,0,0,0,0,177,274,0,0,0,0,0,0,0
0,0,0,0,0,0,0,276,274,135,0,0,0,0,0,177,274,276,0,0,0,0,0,0,0
0,0,0,0,0,0,0,0,275,0,0,0,0,0,0,0,275,0,0,0,0,0,0,0,0
0,0,0,0,0,0,0,0,274,274,274,274,274,274,274,274,274,0,0,0,0,0,0,0,0
0,0,0,0,0,0,0,0,284,274,304,111,230,111,291,274,284,0,0,0,0,0,0,0,0
0,0,0,0,0,0,0,0,0,274,305,0,0,0,292,274,0,0,0,0,0,0,0,0,0
0,0,0,0,0,0,0,0,0,284,274,302,0,297,274,284,0,0,0,0,0,0,0,0,0
0,0,0,0,0,0,0,0,0,0,274,303,0,298,274,0,0,0,0,0,0,0,0,0,0
0,0,0,0,0,0,0,0,0,0,284,274,300,274,284,0,0,0,0,0,0,0,0,0,0
0,0,0,0,0,0,0,0,0,0,0,274,274,274,0,0,0,0,0,0,0,0,0,0,0
0,0,0,0,0,0,0,0,0,0,0,0,274,0,0,0,0,0,0,0,0,0,0,0,0
0,0,0,0,0,0,0,0,0,0,0,0,0,0,0,0,0,0,0,0,0,0,0,0,0
0,0,0,0,0,0,0,0,0,0,0,0,0,0,0,0,0,0,0,0,0,0,0,0,0
0,0,0,0,0,0,0,0,0,0,0,0,0,0,0,0,0,0,0,0,0,0,0,0,0
0,0,0,0,0,0,0,0,0,0,0,0,0,0,0,0,0,0,0,0,0,0,0,0,0
0,0,0,0,0,0,0,0,0,0,0,0,0,0,0,0,0,0,0,0,0,0,0,0,0
0,0,0,0,0,0,0,0,0,0,0,0,0,0,0,0,0,0,0,0,0,0,0,0,0
0,0,0,0,0,0,0,0,0,0,0,0,0,0,0,0,0,0,0,0,0,0,0,0,0
0,0,0,0,0,0,0,0,0,0,0,0,0,0,0,0,0,0,0,0,0,0,0,0,0
0,0,0,0,0,0,0,0,0,0,0,0,0,0,0,0,0,0,0,0,0,0,0,0,0
0,0,0,0,0,0,0,0,0,0,0,0,0,0,0,0,0,0,0,0,0,0,0,0,0
0,0,0,0,0,0,0,0,0,0,0,0,0,0,0,0,0,0,0,0,0,0,0,0,0
0,0,0,0,0,0,0,0,0,0,0,0,0,0,0,0,0,0,0,0,0,0,0,0,0
0,0,0,0,0,0,0,0,0,0,0,0,0,0,0,0,0,0,0,0,0,0,0,0,0
0,0,0,0,0,0,0,0,0,0,0,0,0,0,0,0,0,0,0,0,0,0,0,0,0
0,0,0,0,0,0,0,0,0,0,0,0,0,0,0,0,0,0,0,0,0,0,0,0,0
:endlayer
layer: 9
0,0,0,0,0,0,0,0,0,0,0,0,0,0,0,0,0,0,0,0,0,0,0,0,0
0,0,0,0,0,0,0,0,0,0,0,0,0,0,0,0,0,0,0,0,0,0,0,0,0
0,0,0,0,0,0,0,0,0,0,0,0,0,0,0,0,0,0,0,0,0,0,0,0,0
0,0,0,0,0,0,0,0,0,0,0,0,0,0,0,0,0,0,0,0,0,0,0,0,0
0,0,0,0,0,0,0,0,0,0,0,0,0,0,0,0,0,0,0,0,0,0,0,0,0
0,0,0,0,0,0,0,0,0,0,0,0,0,0,0,0,0,0,0,0,0,0,0,0,0
0,0,0,0,0,0,0,0,0,0,0,0,0,0,0,0,0,0,0,0,0,0,0,0,0
0,0,0,0,0,0,0,0,0,0,0,0,0,0,0,0,0,0,0,0,0,0,0,0,0
0,0,0,0,0,0,0,0,0,0,0,0,0,0,0,0,0,0,0,0,0,0,0,0,0
0,0,0,0,0,0,0,0,0,0,0,0,0,0,0,0,0,0,0,0,0,0,0,0,0
0,0,0,0,0,0,0,0,0,0,0,0,0,0,0,0,0,0,0,0,0,0,0,0,0
0,0,0,0,0,0,0,0,0,158,2,2,2,2,2,158,0,0,0,0,0,0,0,0,0
0,0,0,0,0,0,0,250,2,2,2,2,311,2,2,2,2,159,0,0,0,0,0,0,0
0,0,0,0,0,0,2,2,150,150,151,151,311,151,151,150,150,2,2,0,0,0,0,0,0
0,0,0,0,0,0,2,150,151,151,151,151,311,218,151,151,151,150,2,0,0,0,0,0,0
0,0,0,0,0,0,2,151,151,151,151,151,311,218,151,151,150,151,2,0,0,0,0,0,0
0,0,0,0,0,0,2,151,151,151,151,151,311,106,151,151,151,151,2,0,0,0,0,0,0
0,0,0,0,0,0,2,151,151,151,151,151,311,216,151,151,151,151,2,0,0,0,0,0,0
0,0,0,0,0,0,2,151,151,151,151,151,311,0,151,151,151,151,2,0,0,0,0,0,0
0,0,0,0,0,0,2,151,151,151,151,151,311,0,151,151,151,151,2,0,0,0,0,0,0
0,0,0,0,0,0,2,151,151,151,151,151,311,0,151,151,151,151,2,0,0,0,0,0,0
0,0,0,0,0,0,2,150,150,150,150,150,31,150,150,150,150,150,2,0,0,0,0,0,0
0,0,0,0,0,0,2,151,151,151,151,151,151,150,151,151,151,151,2,0,0,0,0,0,0
0,0,0,0,0,0,2,151,151,151,151,151,151,150,151,151,151,151,2,0,0,0,0,0,0
0,0,0,0,0,0,2,151,151,151,151,151,151,150,151,151,151,151,2,0,0,0,0,0,0
0,0,0,0,0,0,2,151,151,151,151,151,151,150,151,151,151,151,2,0,0,0,0,0,0
0,0,0,0,0,0,2,151,151,151,151,151,151,150,151,151,151,151,2,0,0,0,0,0,0
0,0,0,0,0,0,2,151,151,151,151,151,151,150,150,150,150,150,2,0,0,0,0,0,0
0,0,0,0,0,0,2,151,151,151,151,151,151,150,151,151,151,151,2,0,0,0,0,0,0
0,0,0,0,0,0,2,151,151,151,151,151,151,150,151,151,151,151,2,0,0,0,0,0,0
0,0,0,0,0,0,2,151,151,151,151,151,151,150,151,151,151,151,2,0,0,0,0,0,0
0,0,0,0,0,0,2,150,150,150,150,150,31,150,150,150,150,150,2,0,0,0,0,0,0
0,0,0,0,0,0,2,151,151,151,151,151,310,310,310,310,310,310,2,0,0,0,0,0,0
0,0,0,0,0,0,2,151,151,151,151,0,0,0,5,218,151,151,2,0,0,0,0,0,0
0,0,0,0,0,0,2,151,151,151,151,151,151,151,151,151,151,151,2,0,0,0,0,0,0
0,0,0,0,0,0,2,151,151,151,151,151,151,151,151,151,151,151,2,0,0,0,0,0,0
0,0,0,0,0,0,2,151,151,151,151,151,151,151,151,151,151,151,2,0,0,0,0,0,0
0,0,0,0,0,0,2,151,151,151,151,151,151,151,151,151,151,151,2,0,0,0,0,0,0
0,0,0,0,0,0,2,151,151,151,151,151,151,151,151,151,151,151,2,0,0,0,0,0,0
0,0,0,0,0,0,2,151,151,151,151,151,151,151,151,151,151,151,2,0,0,0,0,0,0
0,0,0,0,0,0,2,151,151,151,151,151,33,151,151,151,151,151,2,0,0,0,0,0,0
0,0,0,0,0,0,2,150,150,150,150,150,31,150,150,150,150,150,2,0,0,0,0,0,0
0,0,0,0,0,0,2,151,151,151,151,151,151,151,151,151,151,151,2,0,0,0,0,0,0
0,0,0,0,0,0,2,151,151,151,151,151,151,151,151,151,151,151,2,0,0,0,0,0,0
0,0,0,0,0,0,2,151,151,151,151,151,151,151,151,151,151,151,2,0,0,0,0,0,0
0,0,0,0,0,0,2,151,151,151,151,151,151,151,151,151,151,151,2,0,0,0,0,0,0
0,0,0,0,0,0,2,151,151,151,151,151,151,151,151,151,151,151,2,0,0,0,0,0,0
0,0,0,0,0,0,2,151,151,151,151,151,151,151,151,151,151,151,2,0,0,0,0,0,0
0,0,0,0,0,0,2,2,2,2,2,2,31,2,2,2,2,2,2,0,0,0,0,0,0
0,0,0,0,0,0,2,2,151,151,151,152,58,0,0,0,0,2,2,0,0,0,0,0,0
0,0,0,0,0,0,2,2,151,151,151,151,151,151,151,151,151,2,2,0,0,0,0,0,0
0,0,0,0,0,0,158,2,151,151,151,151,31,151,151,151,151,2,158,0,0,0,0,0,0
0,0,0,0,0,0,0,2,151,151,151,151,151,151,151,151,151,2,0,0,0,0,0,0,0
0,0,0,0,0,0,0,2,151,151,151,151,151,151,151,151,151,2,0,0,0,0,0,0,0
0,0,0,0,0,0,0,2,2,151,151,151,151,151,151,151,2,2,0,0,0,0,0,0,0
0,0,0,0,0,0,0,226,2,151,151,151,151,151,151,151,2,226,0,0,0,0,0,0,0
0,0,0,0,0,0,0,0,2,2,2,2,2,2,2,2,2,0,0,0,0,0,0,0,0
0,0,0,0,0,0,0,0,2,2,151,151,230,151,151,2,2,0,0,0,0,0,0,0,0
0,0,0,0,0,0,0,0,226,2,151,151,151,151,151,2,226,0,0,0,0,0,0,0,0
0,0,0,0,0,0,0,0,0,2,2,151,151,151,2,2,0,0,0,0,0,0,0,0,0
0,0,0,0,0,0,0,0,0,226,2,151,151,151,2,226,0,0,0,0,0,0,0,0,0
0,0,0,0,0,0,0,0,0,0,2,2,151,2,2,0,0,0,0,0,0,0,0,0,0
0,0,0,0,0,0,0,0,0,0,226,2,2,2,226,0,0,0,0,0,0,0,0,0,0
0,0,0,0,0,0,0,0,0,0,0,226,2,226,0,0,0,0,0,0,0,0,0,0,0
0,0,0,0,0,0,0,0,0,0,0,0,226,0,0,0,0,0,0,0,0,0,0,0,0
0,0,0,0,0,0,0,0,0,0,0,0,0,0,0,0,0,0,0,0,0,0,0,0,0
0,0,0,0,0,0,0,0,0,0,0,0,0,0,0,0,0,0,0,0,0,0,0,0,0
0,0,0,0,0,0,0,0,0,0,0,0,0,0,0,0,0,0,0,0,0,0,0,0,0
0,0,0,0,0,0,0,0,0,0,0,0,0,0,0,0,0,0,0,0,0,0,0,0,0
0,0,0,0,0,0,0,0,0,0,0,0,0,0,0,0,0,0,0,0,0,0,0,0,0
0,0,0,0,0,0,0,0,0,0,0,0,0,0,0,0,0,0,0,0,0,0,0,0,0
0,0,0,0,0,0,0,0,0,0,0,0,0,0,0,0,0,0,0,0,0,0,0,0,0
0,0,0,0,0,0,0,0,0,0,0,0,0,0,0,0,0,0,0,0,0,0,0,0,0
0,0,0,0,0,0,0,0,0,0,0,0,0,0,0,0,0,0,0,0,0,0,0,0,0
0,0,0,0,0,0,0,0,0,0,0,0,0,0,0,0,0,0,0,0,0,0,0,0,0
0,0,0,0,0,0,0,0,0,0,0,0,0,0,0,0,0,0,0,0,0,0,0,0,0
0,0,0,0,0,0,0,0,0,0,0,0,0,0,0,0,0,0,0,0,0,0,0,0,0
0,0,0,0,0,0,0,0,0,0,0,0,0,0,0,0,0,0,0,0,0,0,0,0,0
0,0,0,0,0,0,0,0,0,0,0,0,0,0,0,0,0,0,0,0,0,0,0,0,0
:endlayer
layer: 10
0,0,0,0,0,0,0,0,0,0,0,0,0,0,0,0,0,0,0,0,0,0,0,0,0
0,0,0,0,0,0,0,0,0,0,0,0,0,0,0,0,0,0,0,0,0,0,0,0,0
0,0,0,0,0,0,0,0,0,0,0,0,0,0,0,0,0,0,0,0,0,0,0,0,0
0,0,0,0,0,0,0,0,0,0,0,0,0,0,0,0,0,0,0,0,0,0,0,0,0
0,0,0,0,0,0,0,0,0,0,0,0,0,0,0,0,0,0,0,0,0,0,0,0,0
0,0,0,0,0,0,0,0,0,0,0,0,0,0,0,0,0,0,0,0,0,0,0,0,0
0,0,0,0,0,0,0,0,0,0,0,0,0,0,0,0,0,0,0,0,0,0,0,0,0
0,0,0,0,0,0,0,0,0,0,0,0,0,0,0,0,0,0,0,0,0,0,0,0,0
0,0,0,0,0,0,0,0,0,0,0,0,0,0,0,0,0,0,0,0,0,0,0,0,0
0,0,0,0,0,0,0,0,0,0,0,0,0,0,0,0,0,0,0,0,0,0,0,0,0
0,0,0,0,0,0,0,0,0,0,158,349,349,349,158,0,0,0,0,0,0,0,0,0,0
0,0,0,0,0,0,0,158,2,2,2,2,31,2,2,2,2,158,0,0,0,0,0,0,0
0,0,0,0,0,0,250,2,202,0,0,367,2,67,340,332,323,2,159,0,0,0,0,0,0
0,0,0,0,0,158,2,399,0,0,0,368,2,350,341,333,0,10,2,158,0,0,0,0,0
0,0,0,0,0,250,22,0,0,0,0,0,2,351,0,0,0,0,67,159,0,0,0,0,0
0,0,0,0,0,250,2,2,2,2,30,2,2,10,0,67,67,0,67,159,0,0,0,0,0
0,0,0,0,0,250,406,211,211,0,0,233,2,0,0,251,67,0,67,159,0,0,0,0,0
0,0,0,0,0,250,193,400,393,206,379,233,2,0,0,251,67,0,67,159,0,0,0,0,0
0,0,0,0,0,250,0,210,210,0,0,233,2,0,0,67,67,0,67,159,0,0,0,0,0
0,0,0,0,0,250,251,401,0,0,380,369,2,0,0,0,0,0,67,159,0,0,0,0,0
0,0,0,0,0,250,2,2,30,30,2,2,2,349,2,0,324,0,2,159,0,0,0,0,0
0,0,0,0,0,250,407,0,0,0,381,370,31,312,312,312,0,312,312,159,0,0,0,0,0
0,0,0,0,0,250,408,0,394,0,10,10,2,202,202,202,0,202,202,159,0,0,0,0,0
0,0,0,0,0,250,67,0,0,0,381,370,2,312,312,312,0,312,312,159,0,0,0,0,0
0,0,0,0,0,250,67,402,0,0,10,10,2,352,0,0,325,312,312,159,0,0,0,0,0
0,0,0,0,0,250,67,0,395,0,381,370,2,312,312,312,0,202,202,159,0,0,0,0,0
0,0,0,0,0,250,67,0,0,0,10,10,2,202,202,202,326,312,312,159,0,0,0,0,0
0,0,0,0,0,250,67,0,0,0,381,370,2,312,312,312,0,312,312,159,0,0,0,0,0
0,0,0,0,0,250,67,0,0,0,10,10,2,353,0,0,0,202,202,159,0,0,0,0,0
0,0,0,0,0,250,67,0,396,0,381,370,2,312,312,312,0,312,312,159,0,0,0,0,0
0,0,0,0,0,250,409,0,0,386,10,10,2,202,202,202,0,0,0,159,0,0,0,0,0
0,0,0,0,0,250,410,0,0,0,381,370,31,312,312,312,0,318,313,159,0,0,0,0,0
0,0,0,0,0,250,2,0,0,2,2,2,2,2,2,334,0,0,2,159,0,0,0,0,0
0,0,0,0,0,250,22,0,0,387,10,0,0,0,0,0,0,0,314,159,0,0,0,0,0
0,0,0,0,0,250,267,261,0,0,31,371,361,354,31,335,0,182,171,159,0,0,0,0,0
0,0,0,0,0,250,22,0,0,388,382,106,106,106,342,336,0,0,315,159,0,0,0,0,0
0,0,0,0,0,250,267,261,0,0,31,216,216,216,31,0,0,182,171,159,0,0,0,0,0
0,0,0,0,0,250,411,0,0,0,0,0,362,0,0,0,0,0,316,159,0,0,0,0,0
0,0,0,0,0,250,267,261,0,0,383,0,0,0,343,0,0,182,171,159,0,0,0,0,0
0,0,0,0,0,250,22,0,0,0,0,0,0,0,0,0,0,0,317,159,0,0,0,0,0
0,0,0,0,0,250,267,261,0,0,31,0,33,0,31,0,0,182,171,159,0,0,0,0,0
0,0,0,0,0,250,412,0,0,0,0,372,31,355,10,0,327,0,22,159,0,0,0,0,0
0,0,0,0,0,250,2,0,397,0,0,2,2,2,2,2,2,2,2,159,0,0,0,0,0
0,0,0,0,0,250,413,0,0,0,0,319,0,0,319,0,0,319,0,159,0,0,0,0,0
0,0,0,0,0,250,157,0,0,0,384,0,0,0,0,0,0,0,0,159,0,0,0,0,0
0,0,0,0,0,250,157,0,0,0,0,373,0,356,344,0,0,320,0,159,0,0,0,0,0
0,0,0,0,0,250,157,0,0,0,0,374,0,0,0,0,328,0,0,159,0,0,0,0,0
0,0,0,0,0,250,413,403,0,0,0,202,202,202,345,337,329,0,0,159,0,0,0,0,0
0,0,0,0,0,250,2,2,0,389,0,2,31,2,2,2,2,2,2,159,0,0,0,0,0
0,0,0,0,0,158,2,251,0,0,0,0,0,0,0,0,0,321,2,158,0,0,0,0,0
0,0,0,0,0,0,2,404,312,312,0,0,10,10,10,10,10,10,2,0,0,0,0,0,0
0,0,0,0,0,0,2,405,202,202,0,0,31,203,202,203,0,322,2,0,0,0,0,0,0
0,0,0,0,0,0,2,2,312,312,0,0,0,0,346,0,330,22,2,0,0,0,0,0,0
0,0,0,0,0,0,226,2,10,0,0,375,331,331,331,331,331,2,226,0,0,0,0,0,0
0,0,0,0,0,0,0,2,398,0,0,0,31,0,0,0,66,2,0,0,0,0,0,0,0
0,0,0,0,0,0,0,2,2,390,0,0,363,0,0,251,2,2,0,0,0,0,0,0,0
0,0,0,0,0,0,0,226,2,2,30,2,2,2,2,2,2,226,0,0,0,0,0,0,0
0,0,0,0,0,0,0,0,2,391,0,0,230,357,347,338,2,0,0,0,0,0,0,0,0
0,0,0,0,0,0,0,0,2,392,0,0,0,0,0,339,2,0,0,0,0,0,0,0,0
0,0,0,0,0,0,0,0,226,2,385,376,364,358,348,2,226,0,0,0,0,0,0,0,0
0,0,0,0,0,0,0,0,0,2,2,377,365,359,2,2,0,0,0,0,0,0,0,0,0
0,0,0,0,0,0,0,0,0,226,2,378,0,360,2,226,0,0,0,0,0,0,0,0,0
0,0,0,0,0,0,0,0,0,0,2,2,366,2,2,0,0,0,0,0,0,0,0,0,0
0,0,0,0,0,0,0,0,0,0,0,2,2,2,0,0,0,0,0,0,0,0,0,0,0
0,0,0,0,0,0,0,0,0,0,0,0,2,0,0,0,0,0,0,0,0,0,0,0,0
0,0,0,0,0,0,0,0,0,0,0,0,0,0,0,0,0,0,0,0,0,0,0,0,0
0,0,0,0,0,0,0,0,0,0,0,0,0,0,0,0,0,0,0,0,0,0,0,0,0
0,0,0,0,0,0,0,0,0,0,0,0,0,0,0,0,0,0,0,0,0,0,0,0,0
0,0,0,0,0,0,0,0,0,0,0,0,0,0,0,0,0,0,0,0,0,0,0,0,0
0,0,0,0,0,0,0,0,0,0,0,0,0,0,0,0,0,0,0,0,0,0,0,0,0
0,0,0,0,0,0,0,0,0,0,0,0,0,0,0,0,0,0,0,0,0,0,0,0,0
0,0,0,0,0,0,0,0,0,0,0,0,0,0,0,0,0,0,0,0,0,0,0,0,0
0,0,0,0,0,0,0,0,0,0,0,0,0,0,0,0,0,0,0,0,0,0,0,0,0
0,0,0,0,0,0,0,0,0,0,0,0,0,0,0,0,0,0,0,0,0,0,0,0,0
0,0,0,0,0,0,0,0,0,0,0,0,0,0,0,0,0,0,0,0,0,0,0,0,0
0,0,0,0,0,0,0,0,0,0,0,0,0,0,0,0,0,0,0,0,0,0,0,0,0
0,0,0,0,0,0,0,0,0,0,0,0,0,0,0,0,0,0,0,0,0,0,0,0,0
0,0,0,0,0,0,0,0,0,0,0,0,0,0,0,0,0,0,0,0,0,0,0,0,0
0,0,0,0,0,0,0,0,0,0,0,0,0,0,0,0,0,0,0,0,0,0,0,0,0
:endlayer
layer: 11
0,0,0,0,0,0,0,0,0,0,0,0,0,0,0,0,0,0,0,0,0,0,0,0,0
0,0,0,0,0,0,0,0,0,0,0,0,0,0,0,0,0,0,0,0,0,0,0,0,0
0,0,0,0,0,0,0,0,0,0,0,0,0,0,0,0,0,0,0,0,0,0,0,0,0
0,0,0,0,0,0,0,0,0,0,0,0,0,0,0,0,0,0,0,0,0,0,0,0,0
0,0,0,0,0,0,0,0,0,0,0,0,0,0,0,0,0,0,0,0,0,0,0,0,0
0,0,0,0,0,0,0,0,0,0,0,0,0,0,0,0,0,0,0,0,0,0,0,0,0
0,0,0,0,0,0,0,0,0,0,0,0,0,0,0,0,0,0,0,0,0,0,0,0,0
0,0,0,0,0,0,0,0,0,0,0,0,0,0,0,0,0,0,0,0,0,0,0,0,0
0,0,0,0,0,0,0,0,0,0,0,0,0,0,0,0,0,0,0,0,0,0,0,0,0
0,0,0,0,0,0,0,0,0,0,0,0,0,0,0,0,0,0,0,0,0,0,0,0,0
0,0,0,0,0,0,0,0,2,2,2,2,2,2,2,2,2,0,0,0,0,0,0,0,0
0,0,0,0,0,0,2,2,282,10,455,449,31,436,432,427,423,2,2,0,0,0,0,0,0
0,0,0,0,0,2,462,461,0,0,0,0,2,10,433,32,424,422,2,2,0,0,0,0,0
0,0,0,0,0,2,463,0,0,0,0,0,2,437,0,0,0,10,415,2,0,0,0,0,0
0,0,0,0,0,275,0,0,0,0,0,0,2,438,0,0,0,0,0,275,0,0,0,0,0
0,0,0,0,0,2,2,2,2,2,108,2,2,10,0,428,0,0,416,2,0,0,0,0,0
0,0,0,0,0,275,0,0,0,0,0,450,2,0,0,0,0,0,417,275,0,0,0,0,0
0,0,0,0,0,2,0,0,0,0,0,0,2,0,0,0,0,0,418,2,0,0,0,0,0
0,0,0,0,0,275,0,0,0,0,0,0,2,0,0,0,425,0,419,275,0,0,0,0,0
0,0,0,0,0,2,0,0,0,0,0,0,2,0,0,0,0,0,420,2,0,0,0,0,0
0,0,0,0,0,414,414,414,108,114,414,414,414,414,414,0,0,0,414,414,0,0,0,0,0
0,0,0,0,0,275,0,0,0,0,0,0,31,0,0,0,0,0,0,275,0,0,0,0,0
0,0,0,0,0,414,0,0,0,0,10,10,414,0,0,429,0,0,0,414,0,0,0,0,0
0,0,0,0,0,275,0,0,0,0,0,0,414,0,0,0,0,0,0,275,0,0,0,0,0
0,0,0,0,0,414,464,0,0,0,10,10,414,439,0,0,0,0,0,414,0,0,0,0,0
0,0,0,0,0,275,0,0,0,0,0,0,414,0,0,0,0,0,0,275,0,0,0,0,0
0,0,0,0,0,414,0,0,0,0,10,10,414,0,0,0,0,0,0,414,0,0,0,0,0
0,0,0,0,0,275,0,0,0,0,0,0,414,0,0,0,0,0,0,275,0,0,0,0,0
0,0,0,0,0,414,465,0,0,0,10,10,414,440,0,0,0,0,0,414,0,0,0,0,0
0,0,0,0,0,275,466,0,0,0,0,0,414,0,0,0,0,0,0,275,0,0,0,0,0
0,0,0,0,0,414,0,0,0,0,10,10,414,0,0,0,0,0,0,414,0,0,0,0,0
0,0,0,0,0,275,0,0,0,0,0,0,31,0,0,0,0,0,0,275,0,0,0,0,0
0,0,0,0,0,414,414,0,0,414,414,414,414,414,414,0,0,0,414,414,0,0,0,0,0
0,0,0,0,0,275,0,0,0,0,10,0,0,0,0,0,0,0,0,275,0,0,0,0,0
0,0,0,0,0,414,135,0,0,0,31,106,106,106,31,0,0,0,177,414,0,0,0,0,0
0,0,0,0,0,275,0,0,0,0,456,216,216,216,434,0,0,0,0,275,0,0,0,0,0
0,0,0,0,0,414,135,0,0,0,31,0,0,0,31,0,0,0,177,414,0,0,0,0,0
0,0,0,0,0,275,0,0,0,0,0,0,0,0,0,0,0,0,0,275,0,0,0,0,0
0,0,0,0,0,414,135,0,0,0,0,0,0,0,0,0,0,0,177,414,0,0,0,0,0
0,0,0,0,0,275,0,0,0,0,0,0,0,0,0,0,0,0,0,275,0,0,0,0,0
0,0,0,0,0,414,135,0,0,0,31,0,33,0,31,0,0,0,177,414,0,0,0,0,0
0,0,0,0,0,275,0,0,0,0,0,451,31,441,10,0,0,0,0,275,0,0,0,0,0
0,0,0,0,0,414,414,0,0,0,0,414,414,414,414,414,414,414,414,414,0,0,0,0,0
0,0,0,0,0,275,0,0,0,0,442,65,445,442,65,421,426,65,421,275,0,0,0,0,0
0,0,0,0,0,414,0,0,0,0,0,0,0,0,0,0,0,0,0,414,0,0,0,0,0
0,0,0,0,0,275,0,0,0,0,0,0,0,0,0,0,0,0,0,275,0,0,0,0,0
0,0,0,0,0,414,0,0,0,0,0,0,0,0,0,0,0,0,0,414,0,0,0,0,0
0,0,0,0,0,2,467,0,0,0,0,452,446,0,0,0,0,0,0,2,0,0,0,0,0
0,0,0,0,0,2,2,2,0,0,0,2,31,2,2,10,2,2,2,2,0,0,0,0,0
0,0,0,0,0,2,2,0,0,0,0,0,0,0,111,0,111,0,2,2,0,0,0,0,0
0,0,0,0,0,2,2,135,0,0,0,0,0,0,0,0,0,0,2,2,0,0,0,0,0
0,0,0,0,0,226,2,0,0,0,0,177,31,0,0,0,0,0,2,226,0,0,0,0,0
0,0,0,0,0,0,2,2,135,0,0,0,0,0,0,0,0,10,2,0,0,0,0,0,0
0,0,0,0,0,0,2,2,10,0,0,0,331,331,331,331,331,2,2,0,0,0,0,0,0
0,0,0,0,0,0,226,2,460,0,0,442,31,0,0,0,0,2,226,0,0,0,0,0,0
0,0,0,0,0,0,0,2,2,107,0,0,447,0,107,0,2,2,0,0,0,0,0,0,0
0,0,0,0,0,0,0,2,2,2,108,2,2,2,2,2,2,2,0,0,0,0,0,0,0
0,0,0,0,0,0,0,226,2,458,0,111,230,111,0,430,2,226,0,0,0,0,0,0,0
0,0,0,0,0,0,0,0,2,459,0,0,0,0,0,431,2,0,0,0,0,0,0,0,0
0,0,0,0,0,0,0,0,2,2,457,0,0,0,435,2,2,0,0,0,0,0,0,0,0
0,0,0,0,0,0,0,0,226,2,2,453,0,443,2,2,226,0,0,0,0,0,0,0,0
0,0,0,0,0,0,0,0,0,2,2,454,0,444,2,2,0,0,0,0,0,0,0,0,0
0,0,0,0,0,0,0,0,0,276,2,2,448,2,2,276,0,0,0,0,0,0,0,0,0
0,0,0,0,0,0,0,0,0,0,226,2,2,2,226,0,0,0,0,0,0,0,0,0,0
0,0,0,0,0,0,0,0,0,0,0,226,274,226,0,0,0,0,0,0,0,0,0,0,0
0,0,0,0,0,0,0,0,0,0,0,0,284,0,0,0,0,0,0,0,0,0,0,0,0
0,0,0,0,0,0,0,0,0,0,0,0,0,0,0,0,0,0,0,0,0,0,0,0,0
0,0,0,0,0,0,0,0,0,0,0,0,0,0,0,0,0,0,0,0,0,0,0,0,0
0,0,0,0,0,0,0,0,0,0,0,0,0,0,0,0,0,0,0,0,0,0,0,0,0
0,0,0,0,0,0,0,0,0,0,0,0,0,0,0,0,0,0,0,0,0,0,0,0,0
0,0,0,0,0,0,0,0,0,0,0,0,0,0,0,0,0,0,0,0,0,0,0,0,0
0,0,0,0,0,0,0,0,0,0,0,0,0,0,0,0,0,0,0,0,0,0,0,0,0
0,0,0,0,0,0,0,0,0,0,0,0,0,0,0,0,0,0,0,0,0,0,0,0,0
0,0,0,0,0,0,0,0,0,0,0,0,0,0,0,0,0,0,0,0,0,0,0,0,0
0,0,0,0,0,0,0,0,0,0,0,0,0,0,0,0,0,0,0,0,0,0,0,0,0
0,0,0,0,0,0,0,0,0,0,0,0,0,0,0,0,0,0,0,0,0,0,0,0,0
0,0,0,0,0,0,0,0,0,0,0,0,0,0,0,0,0,0,0,0,0,0,0,0,0
0,0,0,0,0,0,0,0,0,0,0,0,0,0,0,0,0,0,0,0,0,0,0,0,0
0,0,0,0,0,0,0,0,0,0,0,0,0,0,0,0,0,0,0,0,0,0,0,0,0
:endlayer
layer: 12
0,0,0,0,0,0,0,0,0,0,0,0,0,0,0,0,0,0,0,0,0,0,0,0,0
0,0,0,0,0,0,0,0,0,0,0,0,0,0,0,0,0,0,0,0,0,0,0,0,0
0,0,0,0,0,0,0,0,0,0,0,0,0,0,0,0,0,0,0,0,0,0,0,0,0
0,0,0,0,0,0,0,0,0,0,0,0,0,0,0,0,0,0,0,0,0,0,0,0,0
0,0,0,0,0,0,0,0,0,0,0,0,0,0,0,0,0,0,0,0,0,0,0,0,0
0,0,0,0,0,0,0,0,0,0,0,0,0,0,0,0,0,0,0,0,0,0,0,0,0
0,0,0,0,0,0,0,0,0,0,0,0,0,0,0,0,0,0,0,0,0,0,0,0,0
0,0,0,0,0,0,0,0,0,0,0,0,0,0,0,0,0,0,0,0,0,0,0,0,0
0,0,0,0,0,0,0,0,0,0,0,0,0,0,0,0,0,0,0,0,0,0,0,0,0
0,0,0,0,0,0,0,0,0,0,276,274,274,274,276,0,0,0,0,0,0,0,0,0,0
0,0,0,0,0,0,0,276,274,274,274,274,274,274,274,274,274,276,0,0,0,0,0,0,0
0,0,0,0,0,273,2,2,482,10,0,0,31,158,158,158,158,2,2,273,0,0,0,0,0
0,0,0,0,0,2,462,0,0,0,0,0,2,10,0,0,0,158,2,2,0,0,0,0,0
0,0,0,0,0,2,0,0,0,0,0,177,2,479,0,0,0,10,158,2,0,0,0,0,0
0,0,0,0,276,2,0,0,107,0,0,0,2,480,0,0,0,0,0,2,276,0,0,0,0
0,0,0,0,276,2,2,2,2,2,2,2,2,10,0,0,0,0,177,2,276,0,0,0,0
0,0,0,0,0,2,0,0,111,0,0,0,2,0,0,0,0,0,0,2,0,0,0,0,0
0,0,0,0,0,2,135,0,0,0,0,177,2,135,0,0,0,0,177,2,0,0,0,0,0
0,0,0,0,0,2,0,0,0,0,0,0,2,0,0,0,0,0,0,2,0,0,0,0,0
0,0,0,0,0,2,0,0,0,107,0,0,2,0,107,0,0,0,107,2,0,0,0,0,0
0,0,0,0,0,414,414,414,414,414,414,414,414,414,414,158,158,158,414,414,0,0,0,0,0
0,0,0,0,0,275,0,111,0,0,111,177,31,135,0,0,0,0,0,275,0,0,0,0,0
0,0,0,0,0,414,135,0,0,0,0,0,414,0,0,0,0,0,177,414,0,0,0,0,0
0,0,0,0,0,275,0,0,0,0,0,177,414,135,0,0,0,0,0,275,0,0,0,0,0
0,0,0,0,0,414,135,0,0,0,0,0,414,0,0,0,0,0,177,414,0,0,0,0,0
0,0,0,0,0,275,0,0,0,0,0,177,414,135,0,0,0,0,0,275,0,0,0,0,0
0,0,0,0,0,414,135,0,0,0,0,0,414,0,0,0,0,0,177,414,0,0,0,0,0
0,0,0,0,0,275,0,0,0,0,0,177,414,135,0,0,0,0,0,275,0,0,0,0,0
0,0,0,0,0,414,135,0,0,0,0,0,414,0,0,0,0,0,177,414,0,0,0,0,0
0,0,0,0,0,275,0,0,0,0,0,177,414,135,0,0,0,0,0,275,0,0,0,0,0
0,0,0,0,0,414,135,0,0,0,0,0,414,0,0,0,0,0,177,414,0,0,0,0,0
0,0,0,0,0,275,0,0,0,0,0,177,31,135,0,0,0,0,0,275,0,0,0,0,0
0,0,0,0,0,414,414,158,158,414,414,414,414,414,414,158,158,158,414,414,0,0,0,0,0
0,0,0,0,0,275,0,0,0,0,10,106,106,106,0,0,0,0,0,275,0,0,0,0,0
0,0,0,0,0,414,476,486,483,468,31,216,216,216,31,476,473,469,468,414,0,0,0,0,0
0,0,0,0,0,275,0,0,0,0,158,0,0,0,158,0,0,0,0,275,0,0,0,0,0
0,0,0,0,0,414,476,487,484,468,31,135,0,177,31,476,474,470,468,414,0,0,0,0,0
0,0,0,0,0,275,0,0,0,0,158,0,0,0,158,0,0,0,0,275,0,0,0,0,0
0,0,0,0,0,414,0,0,0,0,158,0,0,0,158,0,0,0,0,414,0,0,0,0,0
0,0,0,0,0,275,0,0,0,0,158,0,0,0,158,0,0,0,0,275,0,0,0,0,0
0,0,0,0,0,414,476,488,485,468,31,135,33,177,31,476,475,471,468,414,0,0,0,0,0
0,0,0,0,0,275,0,0,0,0,0,158,31,158,10,0,0,0,0,275,0,0,0,0,0
0,0,0,0,0,414,414,159,158,158,250,414,414,414,414,414,414,414,414,414,0,0,0,0,0
0,0,0,0,0,275,0,0,0,0,0,481,111,0,478,0,111,472,0,275,0,0,0,0,0
0,0,0,0,0,414,135,0,0,0,0,0,0,0,0,0,0,0,177,414,0,0,0,0,0
0,0,0,0,0,275,0,0,0,0,0,0,0,0,0,0,0,0,0,275,0,0,0,0,0
0,0,0,0,0,414,135,0,0,0,0,0,0,0,0,0,0,0,177,414,0,0,0,0,0
0,0,0,0,0,2,0,107,0,0,0,107,0,107,0,107,0,107,0,2,0,0,0,0,0
0,0,0,0,0,2,2,2,158,158,158,2,31,2,2,2,2,2,2,2,0,0,0,0,0
0,0,0,0,0,2,150,151,151,151,151,151,311,151,151,151,151,151,150,2,0,0,0,0,0
0,0,0,0,0,2,150,151,151,151,151,151,311,151,151,151,151,151,150,2,0,0,0,0,0
0,0,0,0,0,2,150,151,151,151,151,151,31,151,151,151,151,151,150,2,0,0,0,0,0
0,0,0,0,0,226,2,150,151,151,151,151,311,151,151,151,151,150,2,226,0,0,0,0,0
0,0,0,0,0,158,2,150,218,151,151,151,311,150,150,150,150,150,2,158,0,0,0,0,0
0,0,0,0,0,250,2,150,218,151,151,151,311,151,151,151,151,150,2,159,0,0,0,0,0
0,0,0,0,0,0,226,2,150,151,151,151,311,151,151,151,150,2,226,0,0,0,0,0,0
0,0,0,0,0,0,158,2,150,150,150,150,311,150,150,150,150,2,158,0,0,0,0,0,0
0,0,0,0,0,0,250,2,150,218,151,151,311,151,151,152,150,2,159,0,0,0,0,0,0
0,0,0,0,0,0,0,226,2,218,151,151,311,151,151,152,2,226,0,0,0,0,0,0,0
0,0,0,0,0,0,0,158,2,150,106,151,311,151,106,150,2,158,0,0,0,0,0,0,0
0,0,0,0,0,0,0,250,2,2,2,218,310,152,2,2,2,159,0,0,0,0,0,0,0
0,0,0,0,0,0,0,0,226,311,2,218,151,152,2,311,226,0,0,0,0,0,0,0,0
0,0,0,0,0,0,0,0,0,311,2,2,106,2,2,311,0,0,0,0,0,0,0,0,0
0,0,0,0,0,0,0,0,0,477,274,2,2,2,274,477,0,0,0,0,0,0,0,0,0
0,0,0,0,0,0,0,0,0,0,284,274,2,274,284,0,0,0,0,0,0,0,0,0,0
0,0,0,0,0,0,0,0,0,0,0,274,2,274,0,0,0,0,0,0,0,0,0,0,0
0,0,0,0,0,0,0,0,0,0,0,276,274,276,0,0,0,0,0,0,0,0,0,0,0
0,0,0,0,0,0,0,0,0,0,0,0,274,0,0,0,0,0,0,0,0,0,0,0,0
0,0,0,0,0,0,0,0,0,0,0,0,276,0,0,0,0,0,0,0,0,0,0,0,0
0,0,0,0,0,0,0,0,0,0,0,0,276,0,0,0,0,0,0,0,0,0,0,0,0
0,0,0,0,0,0,0,0,0,0,0,0,0,0,0,0,0,0,0,0,0,0,0,0,0
0,0,0,0,0,0,0,0,0,0,0,0,0,0,0,0,0,0,0,0,0,0,0,0,0
0,0,0,0,0,0,0,0,0,0,0,0,0,0,0,0,0,0,0,0,0,0,0,0,0
0,0,0,0,0,0,0,0,0,0,0,0,0,0,0,0,0,0,0,0,0,0,0,0,0
0,0,0,0,0,0,0,0,0,0,0,0,0,0,0,0,0,0,0,0,0,0,0,0,0
0,0,0,0,0,0,0,0,0,0,0,0,0,0,0,0,0,0,0,0,0,0,0,0,0
0,0,0,0,0,0,0,0,0,0,0,0,0,0,0,0,0,0,0,0,0,0,0,0,0
0,0,0,0,0,0,0,0,0,0,0,0,0,0,0,0,0,0,0,0,0,0,0,0,0
0,0,0,0,0,0,0,0,0,0,0,0,0,0,0,0,0,0,0,0,0,0,0,0,0
:endlayer
layer: 13
0,0,0,0,0,0,0,0,0,0,0,0,0,0,0,0,0,0,0,0,0,0,0,0,0
0,0,0,0,0,0,0,0,0,0,0,0,0,0,0,0,0,0,0,0,0,0,0,0,0
0,0,0,0,0,0,0,0,0,0,0,0,0,0,0,0,0,0,0,0,0,0,0,0,0
0,0,0,0,0,0,0,0,0,0,0,0,0,0,0,0,0,0,0,0,0,0,0,0,0
0,0,0,0,0,0,0,0,0,0,0,0,0,0,0,0,0,0,0,0,0,0,0,0,0
0,0,0,0,0,0,0,0,0,0,0,0,0,0,0,0,0,0,0,0,0,0,0,0,0
0,0,0,0,0,0,0,0,0,0,0,0,0,0,0,0,0,0,0,0,0,0,0,0,0
0,0,0,0,0,0,0,0,0,0,0,0,0,0,0,0,0,0,0,0,0,0,0,0,0
0,0,0,0,0,0,0,0,0,158,349,158,349,158,349,158,0,0,0,0,0,0,0,0,0
0,0,0,0,0,0,0,0,525,274,274,274,274,274,274,274,489,0,0,0,0,0,0,0,0
0,0,0,0,0,525,274,274,274,150,150,150,2,150,150,150,274,274,274,489,0,0,0,0,0
0,0,0,0,273,274,150,150,150,150,150,150,31,150,150,150,150,150,150,274,273,0,0,0,0
0,0,0,0,274,150,150,150,150,150,150,150,150,150,150,150,150,150,150,150,274,0,0,0,0
0,0,0,0,274,150,150,150,150,150,150,150,150,151,150,150,150,150,150,150,274,0,0,0,0
0,0,0,0,274,150,150,150,150,150,150,150,150,151,150,150,150,150,150,150,274,0,0,0,0
0,0,0,0,274,150,150,150,150,150,150,150,150,150,150,150,150,150,150,150,274,0,0,0,0
0,0,0,0,274,150,150,150,150,150,150,150,150,150,150,150,150,150,150,150,274,0,0,0,0
0,0,0,0,274,150,150,150,150,150,150,150,150,150,150,150,150,150,150,150,274,0,0,0,0
0,0,0,0,284,2,150,150,150,150,150,150,150,150,150,150,150,150,150,2,284,0,0,0,0
0,0,0,0,158,2,150,150,150,150,150,150,150,150,150,150,150,150,150,2,158,0,0,0,0
0,0,0,0,250,2,150,150,150,150,150,150,150,150,150,150,150,150,150,2,159,0,0,0,0
0,0,0,0,158,2,150,150,150,150,150,150,31,150,150,150,150,150,150,2,158,0,0,0,0
0,0,0,0,250,2,150,150,150,150,150,150,150,150,150,150,150,150,150,2,159,0,0,0,0
0,0,0,0,158,2,150,150,150,150,150,150,150,150,150,150,150,150,150,2,158,0,0,0,0
0,0,0,0,250,2,150,150,150,497,497,497,150,497,497,497,150,150,150,2,159,0,0,0,0
0,0,0,0,158,2,150,150,150,506,506,498,150,506,498,498,150,150,150,2,158,0,0,0,0
0,0,0,0,250,2,150,150,150,506,506,498,150,506,498,498,150,150,150,2,159,0,0,0,0
0,0,0,0,158,2,150,150,150,506,506,498,150,506,498,498,150,150,150,2,158,0,0,0,0
0,0,0,0,250,2,150,150,150,506,506,498,150,506,498,498,150,150,150,2,159,0,0,0,0
0,0,0,0,158,2,150,150,150,499,499,499,150,499,499,499,150,150,150,2,158,0,0,0,0
0,0,0,0,250,2,150,150,150,150,150,150,150,150,150,150,150,150,150,2,159,0,0,0,0
0,0,0,0,158,2,150,150,150,150,150,150,31,150,150,150,150,150,150,2,158,0,0,0,0
0,0,0,0,250,2,150,150,150,150,503,503,503,503,503,150,150,150,150,2,159,0,0,0,0
0,0,0,0,158,2,150,150,150,150,311,216,216,216,311,150,150,150,150,2,158,0,0,0,0
0,0,0,0,250,2,150,150,150,150,311,0,512,0,311,150,150,150,150,2,159,0,0,0,0
0,0,0,0,158,2,150,150,150,150,311,0,0,0,311,150,150,150,150,2,158,0,0,0,0
0,0,0,0,250,2,150,150,150,150,311,499,499,499,311,150,150,150,150,2,159,0,0,0,0
0,0,0,0,158,2,150,150,150,150,311,499,499,499,311,150,150,150,150,2,158,0,0,0,0
0,0,0,0,250,2,150,150,150,150,311,499,499,499,311,150,150,150,150,2,159,0,0,0,0
0,0,0,0,158,2,150,150,150,150,503,503,503,503,503,150,150,150,150,2,158,0,0,0,0
0,0,0,0,250,2,150,150,150,150,150,150,150,150,150,150,150,150,150,2,159,0,0,0,0
0,0,0,0,158,2,150,150,150,150,150,150,31,150,150,150,150,150,150,2,158,0,0,0,0
0,0,0,0,250,2,150,150,150,150,150,150,150,150,150,150,150,150,150,2,159,0,0,0,0
0,0,0,0,158,2,150,150,150,150,150,150,150,150,150,150,150,150,150,2,158,0,0,0,0
0,0,0,0,250,2,150,150,150,150,150,150,150,150,150,150,150,150,150,2,159,0,0,0,0
0,0,0,0,158,2,150,150,150,150,150,150,150,150,150,150,150,150,150,2,158,0,0,0,0
0,0,0,0,250,2,150,150,150,150,150,150,150,150,150,150,150,150,150,2,159,0,0,0,0
0,0,0,0,158,2,150,150,150,150,150,150,150,150,150,150,150,150,150,2,158,0,0,0,0
0,0,0,0,250,274,537,531,274,274,150,150,150,150,150,150,274,494,492,274,159,0,0,0,0
0,0,0,0,0,274,538,532,526,520,462,462,274,274,274,274,274,0,0,274,0,0,0,0,0
0,0,0,0,0,530,539,0,0,0,0,0,274,507,477,500,0,0,0,490,0,0,0,0,0
0,0,0,0,0,274,540,533,0,521,253,253,31,508,0,0,0,0,493,274,0,0,0,0,0
0,0,0,0,0,491,274,534,514,514,514,514,0,0,0,0,491,491,274,491,0,0,0,0,0
0,0,0,0,0,0,530,535,514,515,515,514,513,0,0,0,181,170,490,0,0,0,0,0,0
0,0,0,0,0,491,274,536,514,514,514,514,0,0,504,0,181,170,274,491,0,0,0,0,0
0,0,0,0,0,0,491,274,527,522,516,0,31,509,0,0,491,274,491,0,0,0,0,0,0
0,0,0,0,0,0,0,530,528,0,517,0,274,510,0,0,495,490,0,0,0,0,0,0,0
0,0,0,0,0,0,491,274,529,0,0,0,274,0,0,501,496,274,491,0,0,0,0,0,0
0,0,0,0,0,0,0,491,274,523,518,0,274,0,0,502,274,491,0,0,0,0,0,0,0
0,0,0,0,0,0,0,0,530,524,519,511,31,511,505,67,490,0,0,0,0,0,0,0,0
0,0,0,0,0,0,0,491,274,274,274,274,311,274,274,274,274,491,0,0,0,0,0,0,0
0,0,0,0,0,0,0,0,491,477,2,150,311,150,2,477,491,0,0,0,0,0,0,0,0
0,0,0,0,0,0,0,0,0,491,2,150,150,150,2,491,0,0,0,0,0,0,0,0,0
0,0,0,0,0,0,0,0,0,319,2,2,150,2,2,319,0,0,0,0,0,0,0,0,0
0,0,0,0,0,0,0,0,0,319,2,2,2,2,2,319,0,0,0,0,0,0,0,0,0
0,0,0,0,0,0,0,0,319,319,477,414,2,414,477,319,319,0,0,0,0,0,0,0,0
0,0,0,0,0,0,0,0,319,319,0,414,2,414,0,319,319,0,0,0,0,0,0,0,0
0,0,0,0,0,0,0,0,0,0,0,477,414,477,0,0,0,0,0,0,0,0,0,0,0
0,0,0,0,0,0,0,0,0,0,0,0,414,0,0,0,0,0,0,0,0,0,0,0,0
0,0,0,0,0,0,0,0,0,0,0,0,414,0,0,0,0,0,0,0,0,0,0,0,0
0,0,0,0,0,0,0,0,0,0,0,0,477,0,0,0,0,0,0,0,0,0,0,0,0
0,0,0,0,0,0,0,0,0,0,0,0,0,0,0,0,0,0,0,0,0,0,0,0,0
0,0,0,0,0,0,0,0,0,0,0,0,0,0,0,0,0,0,0,0,0,0,0,0,0
0,0,0,0,0,0,0,0,0,0,0,0,0,0,0,0,0,0,0,0,0,0,0,0,0
0,0,0,0,0,0,0,0,0,0,0,0,0,0,0,0,0,0,0,0,0,0,0,0,0
0,0,0,0,0,0,0,0,0,0,0,0,0,0,0,0,0,0,0,0,0,0,0,0,0
0,0,0,0,0,0,0,0,0,0,0,0,0,0,0,0,0,0,0,0,0,0,0,0,0
0,0,0,0,0,0,0,0,0,0,0,0,0,0,0,0,0,0,0,0,0,0,0,0,0
0,0,0,0,0,0,0,0,0,0,0,0,0,0,0,0,0,0,0,0,0,0,0,0,0
:endlayer
layer: 14
0,0,0,0,0,0,0,0,0,0,0,0,0,0,0,0,0,0,0,0,0,0,0,0,0
0,0,0,0,0,0,0,0,0,0,0,0,0,0,0,0,0,0,0,0,0,0,0,0,0
0,0,0,0,0,0,0,0,0,0,0,0,0,0,0,0,0,0,0,0,0,0,0,0,0
0,0,0,0,0,0,0,0,0,0,0,0,0,0,0,0,0,0,0,0,0,0,0,0,0
0,0,0,0,0,0,0,0,0,0,0,0,0,0,0,0,0,0,0,0,0,0,0,0,0
0,0,0,0,0,0,0,0,0,0,0,0,0,0,0,0,0,0,0,0,0,0,0,0,0
0,0,0,0,0,0,0,0,0,0,0,0,0,0,0,0,0,0,0,0,0,0,0,0,0
0,0,0,0,0,0,0,0,0,0,0,0,0,0,0,0,0,0,0,0,0,0,0,0,0
0,0,0,0,0,0,0,0,0,0,491,0,491,0,491,0,0,0,0,0,0,0,0,0,0
0,0,0,0,0,0,0,0,274,511,274,511,274,511,274,511,274,0,0,0,0,0,0,0,0
0,0,0,0,0,274,511,274,22,0,0,0,274,582,0,0,561,274,511,274,0,0,0,0,0
0,0,0,0,274,22,367,274,618,0,181,170,31,0,575,0,0,0,0,541,274,0,0,0,0
0,0,0,0,530,0,368,274,619,0,181,170,462,583,575,66,0,0,0,542,490,0,0,0,0
0,0,0,0,274,0,0,274,274,562,274,462,462,462,274,274,562,274,274,274,274,0,0,0,0
0,0,0,0,530,635,0,562,0,0,0,0,0,0,576,515,515,515,515,543,490,0,0,0,0
0,0,0,0,274,274,274,274,620,0,602,0,0,0,577,515,514,514,515,0,274,0,0,0,0
0,0,0,0,530,367,0,0,2,0,0,575,575,575,0,515,514,514,515,544,490,0,0,0,0
0,0,0,0,274,368,0,0,562,0,603,575,575,575,578,515,515,515,515,545,274,0,0,0,0
0,0,0,0,274,2,0,0,2,0,604,0,0,0,579,567,2,555,0,2,274,0,0,0,0
0,0,0,0,274,2,630,625,2,0,0,0,0,0,0,0,2,556,549,2,274,0,0,0,0
0,0,0,0,530,2,2,2,2,274,274,274,274,562,562,274,2,2,2,2,490,0,0,0,0
0,0,0,0,491,274,216,216,274,610,605,0,31,0,580,568,274,216,216,274,491,0,0,0,0
0,0,0,0,530,274,0,0,477,0,0,0,0,0,0,0,477,0,0,274,490,0,0,0,0
0,0,0,0,491,274,0,0,621,0,0,0,588,0,0,0,563,0,0,274,491,0,0,0,0
0,0,0,0,530,274,135,0,0,0,0,0,0,0,0,0,0,0,177,274,490,0,0,0,0
0,0,0,0,491,491,491,0,0,0,0,0,0,0,0,0,0,0,491,491,491,0,0,0,0
0,0,0,0,530,274,631,32,622,0,0,0,589,0,0,0,564,32,550,274,490,0,0,0,0
0,0,0,0,491,491,491,0,0,0,0,0,0,0,0,0,0,0,491,491,491,0,0,0,0
0,0,0,0,530,0,0,0,0,0,0,0,590,0,0,0,0,0,0,0,490,0,0,0,0
0,0,0,0,491,636,0,0,0,0,0,0,591,0,0,0,0,0,0,546,491,0,0,0,0
0,0,0,0,530,0,0,0,623,0,0,0,33,0,0,0,565,0,0,0,490,0,0,0,0
0,0,0,0,491,491,491,0,0,0,0,596,31,584,0,0,0,0,491,491,491,0,0,0,0
0,0,0,0,530,274,632,32,0,0,0,0,0,0,0,0,0,32,551,274,490,0,0,0,0
0,0,0,0,491,274,491,0,0,611,0,0,0,0,0,569,0,0,491,274,491,0,0,0,0
0,0,0,0,530,274,135,626,0,0,0,0,0,0,0,0,0,557,177,274,490,0,0,0,0
0,0,0,0,491,477,0,0,0,612,0,0,0,0,0,570,0,0,0,477,491,0,0,0,0
0,0,0,0,530,0,0,627,0,0,606,0,0,0,581,0,0,558,0,0,490,0,0,0,0
0,0,0,0,491,491,491,0,0,0,0,0,0,0,0,0,0,0,491,491,491,0,0,0,0
0,0,0,0,530,274,633,32,0,613,0,0,0,0,0,571,0,32,552,274,490,0,0,0,0
0,0,0,0,491,491,491,0,0,0,0,0,0,0,0,0,0,0,491,491,491,0,0,0,0
0,0,0,0,530,0,0,0,0,0,0,0,33,0,0,0,0,0,0,0,490,0,0,0,0
0,0,0,0,491,637,0,628,560,614,0,560,31,560,0,572,560,559,0,547,491,0,0,0,0
0,0,0,0,530,0,0,560,274,562,562,274,274,274,562,562,274,560,0,0,490,0,0,0,0
0,0,0,0,491,0,0,0,530,615,0,0,592,0,0,0,490,0,0,0,491,0,0,0,0
0,0,0,0,530,638,0,0,274,312,312,312,312,0,0,165,274,0,0,548,490,0,0,0,0
0,0,0,0,491,491,0,0,530,0,607,597,0,0,0,165,490,0,0,491,491,0,0,0,0
0,0,0,0,530,274,634,0,274,616,608,598,593,585,0,573,274,0,553,274,490,0,0,0,0
0,0,0,0,491,414,554,554,274,0,0,599,0,0,0,165,274,554,554,414,491,0,0,0,0
0,0,0,0,530,414,310,310,274,617,609,600,594,586,0,165,274,310,310,414,490,0,0,0,0
0,0,0,0,0,414,0,0,284,284,462,462,274,274,562,274,274,0,0,414,0,0,0,0,0
0,0,0,0,0,275,0,0,0,0,0,0,274,560,0,560,0,0,0,275,0,0,0,0,0
0,0,0,0,0,414,0,0,0,0,0,0,31,0,0,0,0,0,0,414,0,0,0,0,0
0,0,0,0,0,0,414,0,0,0,0,0,0,0,0,0,0,0,414,0,0,0,0,0,0
0,0,0,0,0,0,275,0,0,0,0,0,0,0,0,0,0,0,275,0,0,0,0,0,0
0,0,0,0,0,0,414,629,0,0,0,0,0,0,0,0,0,0,414,0,0,0,0,0,0
0,0,0,0,0,0,0,414,0,0,0,0,31,0,0,0,0,414,0,0,0,0,0,0,0
0,0,0,0,0,0,0,275,0,0,0,0,414,0,0,0,0,275,0,0,0,0,0,0,0
0,0,0,0,0,0,0,414,624,0,0,0,414,0,0,0,0,414,0,0,0,0,0,0,0
0,0,0,0,0,0,0,0,414,0,0,0,414,0,0,0,414,0,0,0,0,0,0,0,0
0,0,0,0,0,0,0,0,275,0,0,0,31,0,0,0,275,0,0,0,0,0,0,0,0
0,0,0,0,0,0,0,0,414,275,414,562,414,562,414,275,414,0,0,0,0,0,0,0,0
0,0,0,0,0,0,0,0,0,0,560,0,595,0,560,0,0,0,0,0,0,0,0,0,0
0,0,0,0,0,0,0,0,0,0,560,0,311,0,560,0,0,0,0,0,0,0,0,0,0
0,0,0,0,0,0,0,0,0,0,560,601,311,587,560,0,0,0,0,0,0,0,0,0,0
0,0,0,0,0,0,0,0,0,0,560,560,151,560,560,0,0,0,0,0,0,0,0,0,0
0,0,0,0,0,0,0,0,0,0,0,477,274,477,0,0,0,0,0,0,0,0,0,0,0
0,0,0,0,0,0,0,0,319,0,0,0,477,0,0,0,319,0,0,0,0,0,0,0,0
0,0,0,0,0,0,0,0,319,0,0,0,491,0,0,0,319,0,0,0,0,0,0,0,0
0,0,0,0,0,0,0,0,319,0,0,0,491,0,0,0,319,0,0,0,0,0,0,0,0
0,0,0,0,0,0,0,0,319,0,0,0,0,0,0,0,319,0,0,0,0,0,0,0,0
0,0,0,0,0,0,0,0,566,566,566,566,566,566,566,566,566,0,0,0,0,0,0,0,0
0,0,0,0,0,0,0,0,0,0,574,574,574,574,574,0,0,0,0,0,0,0,0,0,0
0,0,0,0,0,0,0,0,0,574,574,574,574,574,574,574,0,0,0,0,0,0,0,0,0
0,0,0,0,0,0,0,0,0,0,0,574,574,574,0,0,0,0,0,0,0,0,0,0,0
0,0,0,0,0,0,0,0,0,0,0,0,0,0,0,0,0,0,0,0,0,0,0,0,0
0,0,0,0,0,0,0,0,0,0,0,0,0,0,0,0,0,0,0,0,0,0,0,0,0
0,0,0,0,0,0,0,0,0,0,0,0,0,0,0,0,0,0,0,0,0,0,0,0,0
0,0,0,0,0,0,0,0,0,0,0,0,0,0,0,0,0,0,0,0,0,0,0,0,0
0,0,0,0,0,0,0,0,0,0,0,0,0,0,0,0,0,0,0,0,0,0,0,0,0
:endlayer
layer: 15
0,0,0,0,0,0,0,0,0,0,0,0,0,0,0,0,0,0,0,0,0,0,0,0,0
0,0,0,0,0,0,0,0,0,0,0,0,0,0,0,0,0,0,0,0,0,0,0,0,0
0,0,0,0,0,0,0,0,0,0,0,0,0,0,0,0,0,0,0,0,0,0,0,0,0
0,0,0,0,0,0,0,0,0,0,0,0,0,0,0,0,0,0,0,0,0,0,0,0,0
0,0,0,0,0,0,0,0,0,0,0,0,0,0,0,0,0,0,0,0,0,0,0,0,0
0,0,0,0,0,0,0,0,0,0,0,0,0,0,0,0,0,0,0,0,0,0,0,0,0
0,0,0,0,0,0,0,0,0,0,0,0,0,0,0,0,0,0,0,0,0,0,0,0,0
0,0,0,0,0,0,0,0,0,0,0,0,0,0,0,0,0,0,0,0,0,0,0,0,0
0,0,0,0,0,0,0,0,0,0,0,0,0,0,0,0,0,0,0,0,0,0,0,0,0
0,0,0,0,0,0,0,0,414,275,414,275,414,275,414,275,414,0,0,0,0,0,0,0,0
0,0,0,0,0,414,275,414,0,0,0,0,414,0,0,0,643,414,275,414,0,0,0,0,0
0,0,0,0,414,0,0,414,0,0,0,0,31,0,0,0,0,0,0,0,414,0,0,0,0
0,0,0,0,275,0,0,414,0,0,0,0,462,0,0,0,0,0,0,0,275,0,0,0,0
0,0,0,0,414,0,0,414,414,644,414,462,462,462,414,414,644,414,414,414,414,0,0,0,0
0,0,0,0,275,0,0,645,0,0,0,0,0,0,0,0,0,0,0,0,275,0,0,0,0
0,0,0,0,414,414,414,414,0,0,0,0,0,0,0,0,0,0,0,0,414,0,0,0,0
0,0,0,0,275,0,0,0,2,0,0,0,0,0,0,0,0,0,0,0,275,0,0,0,0
0,0,0,0,414,107,0,0,644,0,0,0,0,0,0,0,0,0,0,0,414,0,0,0,0
0,0,0,0,414,2,0,0,2,0,0,0,0,0,0,0,2,0,0,2,414,0,0,0,0
0,0,0,0,477,2,106,106,2,0,0,0,0,0,0,0,2,106,106,2,477,0,0,0,0
0,0,0,0,0,2,216,216,2,414,275,275,414,645,644,414,2,216,216,2,0,0,0,0,0
0,0,0,0,0,477,0,0,477,0,0,0,31,0,0,0,477,0,0,477,0,0,0,0,0
0,0,0,0,0,511,0,0,0,0,0,0,0,0,0,0,0,0,0,511,0,0,0,0,0
0,0,0,0,0,319,0,0,0,0,0,0,0,0,0,0,0,0,0,319,0,0,0,0,0
0,0,0,0,0,319,0,0,0,0,0,0,0,0,0,0,0,0,0,319,0,0,0,0,0
0,0,0,0,0,0,0,0,0,0,0,0,0,0,0,0,0,0,0,0,0,0,0,0,0
0,0,0,0,0,0,0,0,0,0,0,0,0,0,0,0,0,0,0,0,0,0,0,0,0
0,0,0,0,0,0,653,0,0,0,0,0,0,0,0,0,0,0,640,0,0,0,0,0,0
0,0,0,0,0,0,0,0,0,0,0,0,0,0,0,0,0,0,0,0,0,0,0,0,0
0,0,0,0,0,0,0,0,0,0,0,0,0,0,0,0,0,0,0,0,0,0,0,0,0
0,0,0,0,0,0,0,0,0,0,0,0,33,0,0,0,0,0,0,0,0,0,0,0,0
0,0,0,0,0,0,654,0,0,0,0,0,31,0,0,0,0,0,641,0,0,0,0,0,0
0,0,0,0,0,0,0,0,0,0,0,0,0,0,0,0,0,0,0,0,0,0,0,0,0
0,0,0,0,0,511,0,0,0,0,0,0,0,0,0,0,0,0,0,511,0,0,0,0,0
0,0,0,0,0,319,0,0,0,0,0,0,0,0,0,0,0,0,0,319,0,0,0,0,0
0,0,0,0,0,319,0,0,0,0,0,0,0,0,0,0,0,0,0,319,0,0,0,0,0
0,0,0,0,0,0,0,0,0,0,0,0,0,0,0,0,0,0,0,0,0,0,0,0,0
0,0,0,0,0,0,655,0,0,0,0,0,0,0,0,0,0,0,642,0,0,0,0,0,0
0,0,0,0,0,0,0,0,0,0,0,0,0,0,0,0,0,0,0,0,0,0,0,0,0
0,0,0,0,0,0,0,0,0,0,0,0,0,0,0,0,0,0,0,0,0,0,0,0,0
0,0,0,0,0,0,0,0,0,0,0,0,33,0,0,0,0,0,0,0,0,0,0,0,0
0,0,0,0,0,0,0,0,560,0,0,560,31,560,0,0,560,0,0,0,0,0,0,0,0
0,0,0,0,0,0,0,560,414,644,645,414,414,414,644,645,414,560,0,0,0,0,0,0,0
0,0,0,0,0,0,0,0,275,0,0,0,0,0,0,0,275,0,0,0,0,0,0,0,0
0,0,0,0,0,0,0,0,414,0,0,0,0,0,0,0,414,0,0,0,0,0,0,0,0
0,0,0,0,0,656,0,0,275,0,0,0,0,0,0,0,275,0,0,639,0,0,0,0,0
0,0,0,0,0,32,0,0,414,650,0,0,647,0,0,646,414,0,0,32,0,0,0,0,0
0,0,0,0,0,511,0,0,414,0,0,0,0,0,0,0,414,0,0,511,0,0,0,0,0
0,0,0,0,0,414,554,554,414,651,0,0,648,0,0,0,414,554,554,414,0,0,0,0,0
0,0,0,0,0,414,310,310,414,414,462,462,414,414,645,414,414,310,310,414,0,0,0,0,0
0,0,0,0,0,275,0,0,0,0,0,0,414,560,0,560,111,0,0,275,0,0,0,0,0
0,0,0,0,0,414,0,0,0,0,0,177,31,135,0,0,0,0,0,414,0,0,0,0,0
0,0,0,0,0,0,414,135,0,0,0,0,276,0,0,0,0,177,414,0,0,0,0,0,0
0,0,0,0,0,0,275,0,0,0,0,0,276,0,0,0,0,0,275,0,0,0,0,0,0
0,0,0,0,0,0,414,0,0,0,0,0,276,0,0,0,0,0,414,0,0,0,0,0,0
0,0,0,0,0,0,0,414,135,0,0,177,31,135,0,0,177,414,0,0,0,0,0,0,0
0,0,0,0,0,0,0,275,0,0,0,0,414,0,0,0,0,275,0,0,0,0,0,0,0
0,0,0,0,0,0,0,414,652,0,0,0,414,0,0,0,0,414,0,0,0,0,0,0,0
0,0,0,0,0,0,0,0,414,0,0,0,414,0,0,177,414,0,0,0,0,0,0,0,0
0,0,0,0,0,0,0,0,275,0,0,177,31,135,0,0,275,0,0,0,0,0,0,0,0
0,0,0,0,0,0,0,0,414,275,414,644,414,645,414,275,414,0,0,0,0,0,0,0,0
0,0,0,0,0,0,0,0,276,0,111,0,111,0,111,0,276,0,0,0,0,0,0,0,0
0,0,0,0,0,0,0,0,276,0,0,0,649,0,0,0,276,0,0,0,0,0,0,0,0
0,0,0,0,0,0,0,0,0,276,32,0,595,0,32,276,0,0,0,0,0,0,0,0,0
0,0,0,0,0,0,0,0,0,0,276,0,311,0,276,0,0,0,0,0,0,0,0,0,0
0,0,0,0,0,0,0,0,0,0,0,276,311,276,0,0,0,0,0,0,0,0,0,0,0
0,0,0,0,0,0,0,0,0,0,0,276,151,276,0,0,0,0,0,0,0,0,0,0,0
0,0,0,0,0,0,0,0,0,0,0,0,0,0,0,0,0,0,0,0,0,0,0,0,0
0,0,0,0,0,0,0,0,0,0,0,0,0,0,0,0,0,0,0,0,0,0,0,0,0
0,0,0,0,0,0,0,0,319,0,0,0,0,0,0,0,319,0,0,0,0,0,0,0,0
0,0,0,0,0,0,0,319,319,0,0,0,0,0,0,0,319,319,0,0,0,0,0,0,0
0,0,0,0,0,0,0,566,574,574,0,0,0,0,0,574,574,566,0,0,0,0,0,0,0
0,0,0,0,0,0,0,566,574,319,0,0,0,0,0,319,574,566,0,0,0,0,0,0,0
0,0,0,0,0,0,0,0,0,574,574,0,0,0,574,574,0,0,0,0,0,0,0,0,0
0,0,0,0,0,0,0,0,0,574,574,574,574,574,574,574,0,0,0,0,0,0,0,0,0
0,0,0,0,0,0,0,0,0,0,0,574,574,574,0,0,0,0,0,0,0,0,0,0,0
0,0,0,0,0,0,0,0,0,0,0,0,0,0,0,0,0,0,0,0,0,0,0,0,0
0,0,0,0,0,0,0,0,0,0,0,0,0,0,0,0,0,0,0,0,0,0,0,0,0
0,0,0,0,0,0,0,0,0,0,0,0,0,0,0,0,0,0,0,0,0,0,0,0,0
:endlayer
layer: 16
0,0,0,0,0,0,0,0,0,0,0,0,0,0,0,0,0,0,0,0,0,0,0,0,0
0,0,0,0,0,0,0,0,0,0,0,0,0,0,0,0,0,0,0,0,0,0,0,0,0
0,0,0,0,0,0,0,0,0,0,0,0,0,0,0,0,0,0,0,0,0,0,0,0,0
0,0,0,0,0,0,0,0,0,0,0,0,0,0,0,0,0,0,0,0,0,0,0,0,0
0,0,0,0,0,0,0,0,0,0,0,0,0,0,0,0,0,0,0,0,0,0,0,0,0
0,0,0,0,0,0,0,0,0,0,0,0,0,0,0,0,0,0,0,0,0,0,0,0,0
0,0,0,0,0,0,0,0,0,0,0,0,0,0,0,0,0,0,0,0,0,0,0,0,0
0,0,0,0,0,0,0,0,0,0,0,0,0,0,0,0,0,0,0,0,0,0,0,0,0
0,0,0,0,0,0,0,0,0,0,0,0,0,0,0,0,0,0,0,0,0,0,0,0,0
0,0,0,0,0,0,0,0,414,275,414,275,414,275,414,275,414,0,0,0,0,0,0,0,0
0,0,0,0,0,414,275,414,0,0,111,0,414,0,111,0,0,414,275,414,0,0,0,0,0
0,0,0,0,414,0,0,414,135,0,0,0,31,0,0,0,0,0,0,177,414,0,0,0,0
0,0,0,0,275,0,177,414,0,107,0,0,462,0,107,0,0,0,107,0,275,0,0,0,0
0,0,0,0,414,135,0,414,414,414,414,462,462,462,414,414,414,414,414,414,414,0,0,0,0
0,0,0,0,275,0,0,414,0,0,111,0,0,0,111,0,0,0,111,0,275,0,0,0,0
0,0,0,0,414,414,414,414,135,0,0,0,0,0,0,0,0,0,0,177,414,0,0,0,0
0,0,0,0,275,0,111,0,2,0,0,0,0,0,0,0,0,0,0,0,275,0,0,0,0
0,0,0,0,414,349,0,0,2,135,0,0,0,0,0,0,107,0,0,349,414,0,0,0,0
0,0,0,0,477,2,106,106,2,159,0,0,0,0,0,250,2,106,106,2,477,0,0,0,0
0,0,0,0,0,2,216,216,2,159,0,0,107,0,0,250,2,216,216,2,0,0,0,0,0
0,0,0,0,0,477,0,0,477,414,275,275,414,657,657,414,477,0,0,477,0,0,0,0,0
0,0,0,0,0,0,0,0,0,111,0,0,31,0,0,111,0,0,0,0,0,0,0,0,0
0,0,0,0,0,0,0,0,0,0,0,0,111,0,0,0,0,0,0,0,0,0,0,0,0
0,0,0,0,0,0,0,0,0,0,0,0,0,0,0,0,0,0,0,0,0,0,0,0,0
0,0,0,0,0,319,0,0,0,0,0,0,0,0,0,0,0,0,0,319,0,0,0,0,0
0,0,0,0,0,319,0,0,0,0,0,0,0,0,0,0,0,0,0,319,0,0,0,0,0
0,0,0,0,0,0,0,0,0,0,0,0,0,0,0,0,0,0,0,0,0,0,0,0,0
0,0,0,0,0,0,0,0,0,0,0,0,0,0,0,0,0,0,0,0,0,0,0,0,0
0,0,0,0,0,0,0,0,0,0,0,0,0,0,0,0,0,0,0,0,0,0,0,0,0
0,0,0,0,0,0,0,0,0,0,0,0,0,0,0,0,0,0,0,0,0,0,0,0,0
0,0,0,0,0,0,0,0,0,0,0,0,33,0,0,0,0,0,0,0,0,0,0,0,0
0,0,0,0,0,0,0,0,0,0,0,0,31,0,0,0,0,0,0,0,0,0,0,0,0
0,0,0,0,0,0,0,0,0,0,0,0,0,0,0,0,0,0,0,0,0,0,0,0,0
0,0,0,0,0,0,0,0,0,0,0,0,0,0,0,0,0,0,0,0,0,0,0,0,0
0,0,0,0,0,0,0,0,0,0,0,0,0,0,0,0,0,0,0,0,0,0,0,0,0
0,0,0,0,0,319,0,0,0,0,0,0,0,0,0,0,0,0,0,319,0,0,0,0,0
0,0,0,0,0,319,0,0,0,0,0,0,0,0,0,0,0,0,0,319,0,0,0,0,0
0,0,0,0,0,0,0,0,0,0,0,0,0,0,0,0,0,0,0,0,0,0,0,0,0
0,0,0,0,0,0,0,0,0,0,0,0,0,0,0,0,0,0,0,0,0,0,0,0,0
0,0,0,0,0,0,0,0,0,0,0,0,0,0,0,0,0,0,0,0,0,0,0,0,0
0,0,0,0,0,0,0,0,0,0,0,0,33,0,0,0,0,0,0,0,0,0,0,0,0
0,0,0,0,0,0,0,0,560,0,0,560,31,560,0,0,560,0,0,0,0,0,0,0,0
0,0,0,0,0,0,0,560,414,657,657,414,414,414,657,657,414,560,0,0,0,0,0,0,0
0,0,0,0,0,0,0,0,275,0,0,111,0,111,0,0,275,0,0,0,0,0,0,0,0
0,0,0,0,0,0,0,0,414,135,0,0,0,0,0,177,414,0,0,0,0,0,0,0,0
0,0,0,0,0,0,0,0,275,0,0,0,0,0,0,0,275,0,0,0,0,0,0,0,0
0,0,0,0,0,0,0,0,414,135,0,0,0,0,0,0,414,0,0,0,0,0,0,0,0
0,0,0,0,0,0,0,0,414,0,0,0,0,0,0,177,414,0,0,0,0,0,0,0,0
0,0,0,0,0,511,0,0,414,0,0,0,0,107,0,0,414,0,0,511,0,0,0,0,0
0,0,0,0,250,274,554,554,274,274,462,462,274,274,274,274,274,554,554,274,159,0,0,0,0
0,0,0,0,158,274,150,150,150,150,150,150,150,150,150,150,150,150,150,274,158,0,0,0,0
0,0,0,0,250,274,150,150,150,150,150,150,31,150,150,150,150,150,150,274,159,0,0,0,0
0,0,0,0,0,250,274,150,150,150,150,150,150,150,150,150,150,150,274,159,0,0,0,0,0
0,0,0,0,0,158,274,150,150,150,150,150,150,150,150,150,150,150,274,158,0,0,0,0,0
0,0,0,0,0,250,274,150,150,150,506,498,150,506,498,150,150,150,274,159,0,0,0,0,0
0,0,0,0,0,0,250,274,150,150,506,498,150,506,498,150,150,274,159,0,0,0,0,0,0
0,0,0,0,0,0,158,274,150,150,506,498,150,506,498,150,150,274,158,0,0,0,0,0,0
0,0,0,0,0,0,250,274,150,150,150,150,150,150,150,150,150,274,159,0,0,0,0,0,0
0,0,0,0,0,0,0,250,274,150,150,150,150,150,150,150,274,159,0,0,0,0,0,0,0
0,0,0,0,0,0,0,158,274,150,150,150,150,150,150,150,274,158,0,0,0,0,0,0,0
0,0,0,0,0,0,0,250,274,274,274,274,274,274,274,274,274,159,0,0,0,0,0,0,0
0,0,0,0,0,0,0,0,226,158,226,158,226,158,226,158,226,0,0,0,0,0,0,0,0
0,0,0,0,0,0,0,0,0,0,0,0,0,0,0,0,0,0,0,0,0,0,0,0,0
0,0,0,0,0,0,0,0,0,659,0,0,0,0,0,658,0,0,0,0,0,0,0,0,0
0,0,0,0,0,0,0,0,0,0,0,0,0,0,0,0,0,0,0,0,0,0,0,0,0
0,0,0,0,0,0,0,0,0,0,0,0,595,0,0,0,0,0,0,0,0,0,0,0,0
0,0,0,0,0,0,0,0,0,0,0,177,311,135,0,0,0,0,0,0,0,0,0,0,0
0,0,0,0,0,0,0,0,0,0,0,0,311,0,0,0,0,0,0,0,0,0,0,0,0
0,0,0,0,0,0,0,0,0,0,0,0,151,0,0,0,0,0,0,0,0,0,0,0,0
0,0,0,0,0,0,0,0,0,0,0,0,0,0,0,0,0,0,0,0,0,0,0,0,0
0,0,0,0,0,0,0,0,0,0,0,0,0,0,0,0,0,0,0,0,0,0,0,0,0
0,0,0,0,0,0,0,0,0,0,0,0,0,0,0,0,0,0,0,0,0,0,0,0,0
0,0,0,0,0,0,0,319,0,0,0,0,0,0,0,0,0,319,0,0,0,0,0,0,0
0,0,0,0,0,0,0,566,574,0,0,0,0,0,0,0,574,566,0,0,0,0,0,0,0
0,0,0,0,0,0,0,566,574,319,0,0,0,0,0,319,574,566,0,0,0,0,0,0,0
0,0,0,0,0,0,0,0,0,574,574,0,0,0,574,574,0,0,0,0,0,0,0,0,0
0,0,0,0,0,0,0,0,0,0,0,574,574,574,0,0,0,0,0,0,0,0,0,0,0
0,0,0,0,0,0,0,0,0,0,0,0,0,0,0,0,0,0,0,0,0,0,0,0,0
0,0,0,0,0,0,0,0,0,0,0,0,0,0,0,0,0,0,0,0,0,0,0,0,0
:endlayer
layer: 17
0,0,0,0,0,0,0,0,0,0,0,0,0,0,0,0,0,0,0,0,0,0,0,0,0
0,0,0,0,0,0,0,0,0,0,0,0,0,0,0,0,0,0,0,0,0,0,0,0,0
0,0,0,0,0,0,0,0,0,0,0,0,0,0,0,0,0,0,0,0,0,0,0,0,0
0,0,0,0,0,0,0,0,0,0,0,0,0,0,0,0,0,0,0,0,0,0,0,0,0
0,0,0,0,0,0,0,0,0,0,0,0,0,0,0,0,0,0,0,0,0,0,0,0,0
0,0,0,0,0,0,0,0,0,0,0,0,0,0,0,0,0,0,0,0,0,0,0,0,0
0,0,0,0,0,0,0,0,0,0,0,0,0,0,0,0,0,0,0,0,0,0,0,0,0
0,0,0,0,0,0,0,0,0,0,0,0,0,0,0,0,0,0,0,0,0,0,0,0,0
0,0,0,0,0,0,0,0,0,0,0,0,151,0,0,0,0,0,0,0,0,0,0,0,0
0,0,0,0,0,0,0,0,274,273,274,273,311,273,274,273,274,0,0,0,0,0,0,0,0
0,0,0,0,0,274,273,274,274,150,150,150,311,150,150,150,274,274,273,274,0,0,0,0,0
0,0,0,0,274,274,150,150,150,150,150,150,31,150,150,150,150,150,150,274,274,0,0,0,0
0,0,0,0,525,150,150,150,150,150,150,150,150,150,150,150,150,150,150,150,489,0,0,0,0
0,0,0,0,274,150,150,150,150,150,150,150,150,150,150,150,150,150,150,150,274,0,0,0,0
0,0,0,0,525,150,150,150,150,150,150,150,150,150,150,150,150,150,150,150,489,0,0,0,0
0,0,0,0,274,150,150,150,150,150,150,150,150,150,150,150,150,150,150,150,274,0,0,0,0
0,0,0,0,525,150,150,150,150,150,150,150,150,150,150,150,150,150,150,150,489,0,0,0,0
0,0,0,0,477,2,150,150,150,150,150,150,150,150,150,150,150,150,150,2,477,0,0,0,0
0,0,0,0,0,2,216,216,2,2,150,150,150,150,150,2,2,216,216,2,0,0,0,0,0
0,0,0,0,0,477,0,0,477,2,150,150,150,150,150,2,477,0,0,477,0,0,0,0,0
0,0,0,0,0,0,0,0,0,2,274,274,274,274,274,2,0,0,0,0,0,0,0,0,0
0,0,0,0,0,0,0,0,0,226,158,158,31,158,158,226,0,0,0,0,0,0,0,0,0
0,0,0,0,0,0,0,0,0,0,0,0,0,0,0,0,0,0,0,0,0,0,0,0,0
0,0,0,0,0,0,0,0,0,0,0,0,0,0,0,0,0,0,0,0,0,0,0,0,0
0,0,0,0,0,0,0,0,0,0,0,0,0,0,0,0,0,0,0,0,0,0,0,0,0
0,0,0,0,0,319,0,0,0,0,0,0,0,0,0,0,0,0,0,319,0,0,0,0,0
0,0,0,0,0,319,0,0,0,0,0,0,0,0,0,0,0,0,0,319,0,0,0,0,0
0,0,0,0,0,0,0,0,0,0,0,0,0,0,0,0,0,0,0,0,0,0,0,0,0
0,0,0,0,0,0,0,0,0,0,0,0,0,0,0,0,0,0,0,0,0,0,0,0,0
0,0,0,0,0,0,0,0,0,0,0,0,0,0,0,0,0,0,0,0,0,0,0,0,0
0,0,0,0,0,0,0,0,0,0,0,0,33,0,0,0,0,0,0,0,0,0,0,0,0
0,0,0,0,0,0,0,0,0,0,0,0,31,0,0,0,0,0,0,0,0,0,0,0,0
0,0,0,0,0,0,0,0,0,0,0,0,0,0,0,0,0,0,0,0,0,0,0,0,0
0,0,0,0,0,0,0,0,0,0,0,0,0,0,0,0,0,0,0,0,0,0,0,0,0
0,0,0,0,0,0,0,0,0,0,0,0,0,0,0,0,0,0,0,0,0,0,0,0,0
0,0,0,0,0,0,0,0,0,0,0,0,0,0,0,0,0,0,0,0,0,0,0,0,0
0,0,0,0,0,319,0,0,0,0,0,0,0,0,0,0,0,0,0,319,0,0,0,0,0
0,0,0,0,0,319,0,0,0,0,0,0,0,0,0,0,0,0,0,319,0,0,0,0,0
0,0,0,0,0,0,0,0,0,0,0,0,0,0,0,0,0,0,0,0,0,0,0,0,0
0,0,0,0,0,0,0,0,0,0,0,0,0,0,0,0,0,0,0,0,0,0,0,0,0
0,0,0,0,0,0,0,0,0,0,0,0,33,0,0,0,0,0,0,0,0,0,0,0,0
0,0,0,0,0,0,0,0,273,276,276,273,31,273,276,276,273,0,0,0,0,0,0,0,0
0,0,0,0,0,0,0,525,274,274,274,274,274,274,274,274,274,489,0,0,0,0,0,0,0
0,0,0,0,0,0,0,276,525,150,150,150,150,150,150,150,489,276,0,0,0,0,0,0,0
0,0,0,0,0,0,0,525,274,150,150,150,150,150,150,150,274,489,0,0,0,0,0,0,0
0,0,0,0,0,0,0,276,525,150,506,498,150,506,498,150,489,276,0,0,0,0,0,0,0
0,0,0,0,0,0,0,525,274,150,506,498,150,506,498,150,274,489,0,0,0,0,0,0,0
0,0,0,0,0,0,0,0,274,150,150,150,150,150,150,150,274,0,0,0,0,0,0,0,0
0,0,0,0,0,0,0,0,274,150,150,150,150,150,150,150,274,0,0,0,0,0,0,0,0
0,0,0,0,511,491,0,0,274,216,216,216,150,216,216,216,274,0,0,491,511,0,0,0,0
0,0,0,0,274,274,678,0,675,0,0,595,150,595,0,0,662,0,660,274,274,0,0,0,0
0,0,0,0,477,274,491,0,0,672,0,671,31,667,0,664,0,0,491,274,477,0,0,0,0
0,0,0,0,0,319,0,677,0,0,0,0,0,0,0,0,0,661,0,319,0,0,0,0,0
0,0,0,0,0,319,0,0,0,0,0,0,668,0,0,0,0,0,0,319,0,0,0,0,0
0,0,0,0,0,477,511,0,0,0,0,0,0,0,0,0,0,0,511,477,0,0,0,0,0
0,0,0,0,0,0,319,0,0,673,0,0,0,0,0,665,0,0,319,0,0,0,0,0,0
0,0,0,0,0,0,319,32,0,0,0,0,0,0,0,0,0,32,319,0,0,0,0,0,0
0,0,0,0,0,0,477,511,491,674,0,0,669,0,0,666,491,511,477,0,0,0,0,0,0
0,0,0,0,0,0,0,274,676,491,0,0,0,0,0,491,663,274,0,0,0,0,0,0,0
0,0,0,0,0,0,0,274,274,491,0,0,0,0,0,491,274,274,0,0,0,0,0,0,0
0,0,0,0,0,0,0,477,274,491,0,0,107,0,0,491,274,477,0,0,0,0,0,0,0
0,0,0,0,0,0,0,0,530,319,319,319,274,319,319,319,490,0,0,0,0,0,0,0,0
0,0,0,0,0,0,0,0,0,0,0,0,0,0,0,0,0,0,0,0,0,0,0,0,0
0,0,0,0,0,0,0,0,0,0,0,0,0,0,0,0,0,0,0,0,0,0,0,0,0
0,0,0,0,0,0,0,0,0,0,0,0,0,0,0,0,0,0,0,0,0,0,0,0,0
0,0,0,0,0,0,0,0,0,0,0,0,0,0,0,0,0,0,0,0,0,0,0,0,0
0,0,0,0,0,0,0,0,0,0,0,0,670,0,0,0,0,0,0,0,0,0,0,0,0
0,0,0,0,0,0,0,0,0,0,0,0,595,0,0,0,0,0,0,0,0,0,0,0,0
0,0,0,0,0,0,0,0,0,0,0,0,311,0,0,0,0,0,0,0,0,0,0,0,0
0,0,0,0,0,0,0,0,0,0,0,0,311,0,0,0,0,0,0,0,0,0,0,0,0
0,0,0,0,0,0,0,0,0,0,0,0,151,0,0,0,0,0,0,0,0,0,0,0,0
0,0,0,0,0,0,0,0,0,0,0,0,0,0,0,0,0,0,0,0,0,0,0,0,0
0,0,0,0,0,0,0,0,0,0,0,0,0,0,0,0,0,0,0,0,0,0,0,0,0
0,0,0,0,0,0,0,0,0,0,0,0,0,0,0,0,0,0,0,0,0,0,0,0,0
0,0,0,0,0,0,0,319,0,0,0,0,0,0,0,0,0,319,0,0,0,0,0,0,0
0,0,0,0,0,0,0,566,574,319,0,0,0,0,0,319,574,566,0,0,0,0,0,0,0
0,0,0,0,0,0,0,0,0,574,574,574,574,574,574,574,0,0,0,0,0,0,0,0,0
0,0,0,0,0,0,0,0,0,0,0,0,0,0,0,0,0,0,0,0,0,0,0,0,0
0,0,0,0,0,0,0,0,0,0,0,0,0,0,0,0,0,0,0,0,0,0,0,0,0
:endlayer
layer: 18
0,0,0,0,0,0,0,0,0,0,0,0,0,0,0,0,0,0,0,0,0,0,0,0,0
0,0,0,0,0,0,0,0,0,0,0,0,0,0,0,0,0,0,0,0,0,0,0,0,0
0,0,0,0,0,0,0,0,0,0,0,0,0,0,0,0,0,0,0,0,0,0,0,0,0
0,0,0,0,0,0,0,0,0,0,0,0,0,0,0,0,0,0,0,0,0,0,0,0,0
0,0,0,0,0,0,0,0,0,0,0,0,0,0,0,0,0,0,0,0,0,0,0,0,0
0,0,0,0,0,0,0,0,0,0,0,0,0,0,0,0,0,0,0,0,0,0,0,0,0
0,0,0,0,0,0,0,0,0,0,0,0,151,0,0,0,0,0,0,0,0,0,0,0,0
0,0,0,0,0,0,0,0,0,0,0,0,311,0,0,0,0,0,0,0,0,0,0,0,0
0,0,0,0,0,0,0,0,0,0,0,0,311,0,0,0,0,0,0,0,0,0,0,0,0
0,0,0,0,0,0,0,0,274,319,319,319,274,319,319,319,274,0,0,0,0,0,0,0,0
0,0,0,0,0,319,274,319,319,717,0,0,702,0,0,692,319,319,274,319,0,0,0,0,0
0,0,0,0,274,319,477,0,720,0,0,710,31,698,0,0,686,0,477,319,274,0,0,0,0
0,0,0,0,319,730,727,0,0,0,0,711,703,699,0,0,0,0,681,679,319,0,0,0,0
0,0,0,0,274,490,728,0,0,0,0,0,0,0,0,0,0,0,682,530,274,0,0,0,0
0,0,0,0,319,0,0,0,721,0,0,491,491,491,0,0,687,0,0,0,319,0,0,0,0
0,0,0,0,319,731,0,0,0,0,491,274,274,274,491,0,0,0,0,680,319,0,0,0,0
0,0,0,0,319,274,0,0,0,0,274,274,704,274,274,0,0,0,0,274,319,0,0,0,0
0,0,0,0,0,274,0,0,722,0,714,274,705,274,695,0,688,0,0,274,0,0,0,0,0
0,0,0,0,0,274,0,0,274,319,491,274,274,274,491,319,274,0,0,274,0,0,0,0,0
0,0,0,0,0,0,0,0,723,319,491,274,31,274,491,319,689,0,0,0,0,0,0,0,0
0,0,0,0,0,0,0,0,0,319,491,274,274,274,491,319,0,0,0,0,0,0,0,0,0
0,0,0,0,0,0,0,0,0,274,319,319,31,319,319,274,0,0,0,0,0,0,0,0,0
0,0,0,0,0,0,0,0,0,0,0,0,284,0,0,0,0,0,0,0,0,0,0,0,0
0,0,0,0,0,0,0,0,0,0,0,0,0,0,0,0,0,0,0,0,0,0,0,0,0
0,0,0,0,0,0,0,0,0,0,0,0,0,0,0,0,0,0,0,0,0,0,0,0,0
0,0,0,0,0,0,0,0,0,0,0,0,0,0,0,0,0,0,0,0,0,0,0,0,0
0,0,0,0,0,319,319,0,0,0,0,0,0,0,0,0,0,0,319,319,0,0,0,0,0
0,0,0,0,0,319,319,0,0,0,0,0,0,0,0,0,0,0,319,319,0,0,0,0,0
0,0,0,0,0,319,319,0,0,0,0,0,0,0,0,0,0,0,319,319,0,0,0,0,0
0,0,0,0,0,0,0,0,0,0,0,0,0,0,0,0,0,0,0,0,0,0,0,0,0
0,0,0,0,0,0,0,0,0,0,0,0,33,0,0,0,0,0,0,0,0,0,0,0,0
0,0,0,0,0,0,0,0,0,0,0,0,31,0,0,0,0,0,0,0,0,0,0,0,0
0,0,0,0,0,0,0,0,0,0,0,0,0,0,0,0,0,0,0,0,0,0,0,0,0
0,0,0,0,0,0,0,0,0,0,0,0,0,0,0,0,0,0,0,0,0,0,0,0,0
0,0,0,0,0,0,0,0,0,0,0,0,0,0,0,0,0,0,0,0,0,0,0,0,0
0,0,0,0,0,0,0,0,0,0,0,0,0,0,0,0,0,0,0,0,0,0,0,0,0
0,0,0,0,0,0,0,0,0,0,0,0,0,0,0,0,0,0,0,0,0,0,0,0,0
0,0,0,0,0,319,319,0,0,0,0,0,0,0,0,0,0,0,319,319,0,0,0,0,0
0,0,0,0,0,319,319,0,0,0,0,0,0,0,0,0,0,0,319,319,0,0,0,0,0
0,0,0,0,0,0,0,0,0,0,0,0,0,0,0,0,0,0,0,0,0,0,0,0,0
0,0,0,0,0,0,0,0,0,0,0,0,33,0,0,0,0,0,0,0,0,0,0,0,0
0,0,0,0,0,0,0,0,188,319,319,319,31,319,319,319,257,0,0,0,0,0,0,0,0
0,0,0,0,0,0,0,684,2,718,715,0,706,0,696,693,2,684,0,0,0,0,0,0,0
0,0,0,0,0,0,0,319,491,491,0,0,0,0,0,491,491,319,0,0,0,0,0,0,0
0,0,0,0,0,0,0,319,32,0,0,0,707,0,0,0,32,319,0,0,0,0,0,0,0
0,0,0,0,0,0,0,319,724,0,0,0,0,0,0,0,690,319,0,0,0,0,0,0,0
0,0,0,0,0,0,0,75,684,0,0,0,0,0,0,0,684,75,0,0,0,0,0,0,0
0,0,0,0,0,0,0,0,319,0,0,712,708,700,0,0,319,0,0,0,0,0,0,0,0
0,0,0,0,0,0,0,0,274,719,716,713,709,701,697,694,274,0,0,0,0,0,0,0,0
0,0,0,0,0,0,0,0,477,0,0,0,0,0,0,0,477,0,0,0,0,0,0,0,0
0,0,0,0,0,0,0,0,0,0,0,0,33,0,0,0,0,0,0,0,0,0,0,0,0
0,0,0,0,0,32,729,0,0,0,0,0,31,0,0,0,0,0,683,32,0,0,0,0,0
0,0,0,0,0,0,0,0,0,0,0,0,0,0,0,0,0,0,0,0,0,0,0,0,0
0,0,0,0,0,0,0,0,0,0,0,0,0,0,0,0,0,0,0,0,0,0,0,0,0
0,0,0,0,0,0,0,0,0,0,0,0,0,0,0,0,0,0,0,0,0,0,0,0,0
0,0,0,0,0,0,0,0,0,0,0,0,0,0,0,0,0,0,0,0,0,0,0,0,0
0,0,0,0,0,0,0,0,0,0,0,0,0,0,0,0,0,0,0,0,0,0,0,0,0
0,0,0,0,0,0,0,0,0,0,0,0,0,0,0,0,0,0,0,0,0,0,0,0,0
0,0,0,0,0,0,0,726,0,0,0,0,0,0,0,0,0,685,0,0,0,0,0,0,0
0,0,0,0,0,0,0,0,725,0,0,0,0,0,0,0,691,0,0,0,0,0,0,0,0
0,0,0,0,0,0,0,0,319,0,0,0,0,0,0,0,319,0,0,0,0,0,0,0,0
0,0,0,0,0,0,0,0,0,0,32,0,319,0,32,0,0,0,0,0,0,0,0,0,0
0,0,0,0,0,0,0,0,0,0,0,0,0,0,0,0,0,0,0,0,0,0,0,0,0
0,0,0,0,0,0,0,0,0,0,0,0,0,0,0,0,0,0,0,0,0,0,0,0,0
0,0,0,0,0,0,0,0,0,0,0,0,0,0,0,0,0,0,0,0,0,0,0,0,0
0,0,0,0,0,0,0,0,0,0,0,0,0,0,0,0,0,0,0,0,0,0,0,0,0
0,0,0,0,0,0,0,0,0,0,0,0,0,0,0,0,0,0,0,0,0,0,0,0,0
0,0,0,0,0,0,0,0,0,0,0,0,0,0,0,0,0,0,0,0,0,0,0,0,0
0,0,0,0,0,0,0,0,0,0,0,0,0,0,0,0,0,0,0,0,0,0,0,0,0
0,0,0,0,0,0,0,0,0,0,0,0,595,0,0,0,0,0,0,0,0,0,0,0,0
0,0,0,0,0,0,0,0,0,0,0,0,311,0,0,0,0,0,0,0,0,0,0,0,0
0,0,0,0,0,0,0,0,0,0,0,177,311,135,0,0,0,0,0,0,0,0,0,0,0
0,0,0,0,0,0,0,0,0,0,0,0,151,0,0,0,0,0,0,0,0,0,0,0,0
0,0,0,0,0,0,0,0,0,0,0,0,0,0,0,0,0,0,0,0,0,0,0,0,0
0,0,0,0,0,0,0,0,0,0,0,0,0,0,0,0,0,0,0,0,0,0,0,0,0
0,0,0,0,0,0,0,0,0,0,0,0,0,0,0,0,0,0,0,0,0,0,0,0,0
0,0,0,0,0,0,0,566,574,574,319,0,0,0,319,574,574,566,0,0,0,0,0,0,0
0,0,0,0,0,0,0,0,0,0,574,574,574,574,574,0,0,0,0,0,0,0,0,0,0
0,0,0,0,0,0,0,0,0,0,0,0,0,0,0,0,0,0,0,0,0,0,0,0,0
:endlayer
layer: 19
0,0,0,0,0,0,0,0,0,0,0,0,0,0,0,0,0,0,0,0,0,0,0,0,0
0,0,0,0,0,0,0,0,0,0,0,0,0,0,0,0,0,0,0,0,0,0,0,0,0
0,0,0,0,0,0,0,0,0,0,0,0,0,0,0,0,0,0,0,0,0,0,0,0,0
0,0,0,0,0,0,0,0,0,0,0,0,0,0,0,0,0,0,0,0,0,0,0,0,0
0,0,0,0,0,0,0,0,0,0,0,0,151,0,0,0,0,0,0,0,0,0,0,0,0
0,0,0,0,0,0,0,0,0,0,0,0,311,0,0,0,0,0,0,0,0,0,0,0,0
0,0,0,0,0,0,0,0,0,0,0,0,311,0,0,0,0,0,0,0,0,0,0,0,0
0,0,0,0,0,0,0,0,0,0,0,0,595,0,0,0,0,0,0,0,0,0,0,0,0
0,0,0,0,0,0,0,0,0,0,0,0,0,0,0,0,0,0,0,0,0,0,0,0,0
0,0,0,0,0,0,0,0,319,0,32,0,319,0,32,0,319,0,0,0,0,0,0,0,0
0,0,0,0,0,0,0,0,0,0,0,0,0,0,0,0,0,0,0,0,0,0,0,0,0
0,0,0,0,32,0,0,0,0,0,0,0,31,0,0,0,0,0,0,0,32,0,0,0,0
0,0,0,0,0,0,0,0,0,0,0,0,0,0,0,0,0,0,0,0,0,0,0,0,0
0,0,0,0,0,0,0,0,0,0,0,0,0,0,0,0,0,0,0,0,0,0,0,0,0
0,0,0,0,0,0,0,0,0,0,0,0,0,0,0,0,0,0,0,0,0,0,0,0,0
0,0,0,0,0,0,0,0,0,0,738,0,282,0,734,0,0,0,0,0,0,0,0,0,0
0,0,0,0,0,32,0,0,0,0,0,737,514,736,0,0,0,0,0,32,0,0,0,0,0
0,0,0,0,0,511,0,0,0,0,0,0,514,0,0,0,0,0,0,511,0,0,0,0,0
0,0,0,0,0,319,0,0,32,0,0,0,211,0,0,0,32,0,0,319,0,0,0,0,0
0,0,0,0,0,319,0,0,0,0,739,560,31,560,735,0,0,0,0,319,0,0,0,0,0
0,0,0,0,0,0,0,0,0,0,0,0,33,0,0,0,0,0,0,0,0,0,0,0,0
0,0,0,0,0,0,0,0,0,319,0,319,31,319,0,319,0,0,0,0,0,0,0,0,0
0,0,0,0,0,0,0,0,0,0,0,0,274,0,0,0,0,0,0,0,0,0,0,0,0
0,0,0,0,0,0,0,0,0,0,0,0,0,0,0,0,0,0,0,0,0,0,0,0,0
0,0,0,0,0,0,0,0,0,0,0,0,0,0,0,0,0,0,0,0,0,0,0,0,0
0,0,0,0,0,0,0,0,0,0,0,0,0,0,0,0,0,0,0,0,0,0,0,0,0
0,0,0,0,0,0,0,0,0,0,0,0,0,0,0,0,0,0,0,0,0,0,0,0,0
0,0,0,0,0,0,0,0,0,0,0,0,0,0,0,0,0,0,0,0,0,0,0,0,0
0,0,0,0,0,0,319,0,0,0,0,0,0,0,0,0,0,0,319,0,0,0,0,0,0
0,0,0,0,0,0,319,0,0,0,0,0,0,0,0,0,0,0,319,0,0,0,0,0,0
0,0,0,0,0,0,0,0,0,0,0,0,33,0,0,0,0,0,0,0,0,0,0,0,0
0,0,0,0,0,0,0,0,0,0,0,0,31,0,0,0,0,0,0,0,0,0,0,0,0
0,0,0,0,0,0,0,0,0,0,0,0,0,0,0,0,0,0,0,0,0,0,0,0,0
0,0,0,0,0,0,0,0,0,0,0,0,0,0,0,0,0,0,0,0,0,0,0,0,0
0,0,0,0,0,0,0,0,0,0,0,0,0,0,0,0,0,0,0,0,0,0,0,0,0
0,0,0,0,0,0,0,0,0,0,0,0,0,0,0,0,0,0,0,0,0,0,0,0,0
0,0,0,0,0,0,0,0,0,0,0,0,0,0,0,0,0,0,0,0,0,0,0,0,0
0,0,0,0,0,0,0,0,0,0,0,0,0,0,0,0,0,0,0,0,0,0,0,0,0
0,0,0,0,0,0,319,0,0,0,0,0,0,0,0,0,0,0,319,0,0,0,0,0,0
0,0,0,0,0,0,319,0,0,0,0,0,0,0,0,0,0,0,319,0,0,0,0,0,0
0,0,0,0,0,0,0,0,0,0,0,0,33,0,0,0,0,0,0,0,0,0,0,0,0
0,0,0,0,0,0,0,0,0,0,0,0,31,0,0,0,0,0,0,0,0,0,0,0,0
0,0,0,0,0,0,0,0,0,0,0,0,0,0,0,0,0,0,0,0,0,0,0,0,0
0,0,0,0,0,0,0,0,740,0,0,0,0,0,0,0,733,0,0,0,0,0,0,0,0
0,0,0,0,0,0,0,0,0,0,0,0,0,0,0,0,0,0,0,0,0,0,0,0,0
0,0,0,0,0,0,0,0,0,0,0,0,0,0,0,0,0,0,0,0,0,0,0,0,0
0,0,0,0,0,0,0,741,0,0,0,0,0,0,0,0,0,732,0,0,0,0,0,0,0
0,0,0,0,0,0,0,0,0,0,0,0,0,0,0,0,0,0,0,0,0,0,0,0,0
0,0,0,0,0,0,0,0,511,0,0,0,0,0,0,0,511,0,0,0,0,0,0,0,0
0,0,0,0,0,0,0,0,319,0,0,0,0,0,0,0,319,0,0,0,0,0,0,0,0
0,0,0,0,0,0,0,0,319,0,0,0,33,0,0,0,319,0,0,0,0,0,0,0,0
0,0,0,0,0,0,0,0,319,0,0,177,31,135,0,0,319,0,0,0,0,0,0,0,0
0,0,0,0,0,0,0,0,0,0,0,0,111,0,0,0,0,0,0,0,0,0,0,0,0
0,0,0,0,0,0,0,0,0,0,0,0,0,0,0,0,0,0,0,0,0,0,0,0,0
0,0,0,0,0,0,0,0,0,0,0,0,0,0,0,0,0,0,0,0,0,0,0,0,0
0,0,0,0,0,0,0,0,0,0,0,0,0,0,0,0,0,0,0,0,0,0,0,0,0
0,0,0,0,0,0,0,0,0,0,0,0,0,0,0,0,0,0,0,0,0,0,0,0,0
0,0,0,0,0,0,0,0,0,0,0,0,0,0,0,0,0,0,0,0,0,0,0,0,0
0,0,0,0,0,0,0,0,0,0,0,0,0,0,0,0,0,0,0,0,0,0,0,0,0
0,0,0,0,0,0,0,0,0,0,0,0,0,0,0,0,0,0,0,0,0,0,0,0,0
0,0,0,0,0,0,0,0,32,0,0,0,0,0,0,0,32,0,0,0,0,0,0,0,0
0,0,0,0,0,0,0,0,0,0,0,0,32,0,0,0,0,0,0,0,0,0,0,0,0
0,0,0,0,0,0,0,0,0,0,0,0,0,0,0,0,0,0,0,0,0,0,0,0,0
0,0,0,0,0,0,0,0,0,0,0,0,0,0,0,0,0,0,0,0,0,0,0,0,0
0,0,0,0,0,0,0,0,0,0,0,0,0,0,0,0,0,0,0,0,0,0,0,0,0
0,0,0,0,0,0,0,0,0,0,0,0,0,0,0,0,0,0,0,0,0,0,0,0,0
0,0,0,0,0,0,0,0,0,0,0,0,0,0,0,0,0,0,0,0,0,0,0,0,0
0,0,0,0,0,0,0,0,0,0,0,0,0,0,0,0,0,0,0,0,0,0,0,0,0
0,0,0,0,0,0,0,0,0,0,0,0,0,0,0,0,0,0,0,0,0,0,0,0,0
0,0,0,0,0,0,0,0,0,0,0,0,0,0,0,0,0,0,0,0,0,0,0,0,0
0,0,0,0,0,0,0,0,0,0,0,0,273,0,0,0,0,0,0,0,0,0,0,0,0
0,0,0,0,0,0,0,0,0,0,0,0,311,0,0,0,0,0,0,0,0,0,0,0,0
0,0,0,0,0,0,0,0,0,0,0,0,311,0,0,0,0,0,0,0,0,0,0,0,0
0,0,0,0,0,0,0,0,0,0,0,0,311,0,0,0,0,0,0,0,0,0,0,0,0
0,0,0,0,0,0,0,0,0,0,0,0,151,0,0,0,0,0,0,0,0,0,0,0,0
0,0,0,0,0,0,0,0,0,0,0,0,0,0,0,0,0,0,0,0,0,0,0,0,0
0,0,0,0,0,0,0,319,0,0,0,0,0,0,0,0,0,319,0,0,0,0,0,0,0
0,0,0,0,0,0,0,566,566,566,566,566,566,566,566,566,566,566,0,0,0,0,0,0,0
0,0,0,0,0,0,0,0,0,0,0,0,0,0,0,0,0,0,0,0,0,0,0,0,0
:endlayer
layer: 20
0,0,0,0,0,0,0,0,0,0,0,0,0,0,0,0,0,0,0,0,0,0,0,0,0
0,0,0,0,0,0,0,0,0,0,0,0,0,0,0,0,0,0,0,0,0,0,0,0,0
0,0,0,0,0,0,0,0,0,0,0,0,0,0,0,0,0,0,0,0,0,0,0,0,0
0,0,0,0,0,0,0,0,0,0,0,0,0,0,0,0,0,0,0,0,0,0,0,0,0
0,0,0,0,0,0,0,0,0,0,0,0,319,0,0,0,0,0,0,0,0,0,0,0,0
0,0,0,0,0,0,0,0,0,0,0,0,319,0,0,0,0,0,0,0,0,0,0,0,0
0,0,0,0,0,0,0,0,0,0,0,0,0,0,0,0,0,0,0,0,0,0,0,0,0
0,0,0,0,0,0,0,0,0,0,0,0,0,0,0,0,0,0,0,0,0,0,0,0,0
0,0,0,0,0,0,0,0,0,0,0,0,0,0,0,0,0,0,0,0,0,0,0,0,0
0,0,0,0,0,0,0,0,32,0,0,0,319,0,0,0,32,0,0,0,0,0,0,0,0
0,0,0,0,0,0,0,0,0,0,0,0,0,0,0,0,0,0,0,0,0,0,0,0,0
0,0,0,0,0,0,0,0,0,0,0,0,31,0,0,0,0,0,0,0,0,0,0,0,0
0,0,0,0,0,0,0,0,0,0,0,0,0,0,0,0,0,0,0,0,0,0,0,0,0
0,0,0,0,0,0,0,0,0,0,0,0,0,0,0,0,0,0,0,0,0,0,0,0,0
0,0,0,0,0,0,0,0,0,0,0,0,0,0,0,0,0,0,0,0,0,0,0,0,0
0,0,0,0,0,0,0,0,0,0,0,0,0,0,0,0,0,0,0,0,0,0,0,0,0
0,0,0,0,0,743,0,0,0,0,0,0,0,0,0,0,0,0,0,742,0,0,0,0,0
0,0,0,0,0,0,0,0,0,0,0,0,0,0,0,0,0,0,0,0,0,0,0,0,0
0,0,0,0,0,0,0,0,0,0,0,0,0,0,0,0,0,0,0,0,0,0,0,0,0
0,0,0,0,0,319,319,0,0,0,0,0,491,0,0,0,0,0,319,319,0,0,0,0,0
0,0,0,0,0,319,319,0,0,0,0,0,33,0,0,0,0,0,319,319,0,0,0,0,0
0,0,0,0,0,0,0,0,0,32,0,0,31,0,0,32,0,0,0,0,0,0,0,0,0
0,0,0,0,0,0,0,0,0,0,0,0,319,0,0,0,0,0,0,0,0,0,0,0,0
0,0,0,0,0,0,0,0,0,0,0,0,0,0,0,0,0,0,0,0,0,0,0,0,0
0,0,0,0,0,0,0,0,0,0,0,0,0,0,0,0,0,0,0,0,0,0,0,0,0
0,0,0,0,0,0,0,0,0,0,0,0,0,0,0,0,0,0,0,0,0,0,0,0,0
0,0,0,0,0,0,0,0,0,0,0,0,0,0,0,0,0,0,0,0,0,0,0,0,0
0,0,0,0,0,0,0,0,0,0,0,0,0,0,0,0,0,0,0,0,0,0,0,0,0
0,0,0,0,0,0,0,0,0,0,0,0,0,0,0,0,0,0,0,0,0,0,0,0,0
0,0,0,0,0,0,319,0,0,0,0,0,0,0,0,0,0,0,319,0,0,0,0,0,0
0,0,0,0,0,0,319,0,0,0,0,0,33,0,0,0,0,0,319,0,0,0,0,0,0
0,0,0,0,0,0,0,0,0,0,0,0,31,0,0,0,0,0,0,0,0,0,0,0,0
0,0,0,0,0,0,0,0,0,0,0,0,0,0,0,0,0,0,0,0,0,0,0,0,0
0,0,0,0,0,0,0,0,0,0,0,0,0,0,0,0,0,0,0,0,0,0,0,0,0
0,0,0,0,0,0,0,0,0,0,0,0,0,0,0,0,0,0,0,0,0,0,0,0,0
0,0,0,0,0,0,0,0,0,0,0,0,0,0,0,0,0,0,0,0,0,0,0,0,0
0,0,0,0,0,0,0,0,0,0,0,0,0,0,0,0,0,0,0,0,0,0,0,0,0
0,0,0,0,0,0,0,0,0,0,0,0,0,0,0,0,0,0,0,0,0,0,0,0,0
0,0,0,0,0,0,0,0,0,0,0,0,0,0,0,0,0,0,0,0,0,0,0,0,0
0,0,0,0,0,0,319,0,0,0,0,0,0,0,0,0,0,0,319,0,0,0,0,0,0
0,0,0,0,0,0,319,0,0,0,0,0,33,0,0,0,0,0,319,0,0,0,0,0,0
0,0,0,0,0,0,0,0,0,0,0,0,31,0,0,0,0,0,0,0,0,0,0,0,0
0,0,0,0,0,0,0,0,0,0,0,0,0,0,0,0,0,0,0,0,0,0,0,0,0
0,0,0,0,0,0,0,0,0,0,0,0,0,0,0,0,0,0,0,0,0,0,0,0,0
0,0,0,0,0,0,0,0,0,0,0,0,0,0,0,0,0,0,0,0,0,0,0,0,0
0,0,0,0,0,0,0,0,0,0,0,0,0,0,0,0,0,0,0,0,0,0,0,0,0
0,0,0,0,0,0,0,0,0,0,0,0,0,0,0,0,0,0,0,0,0,0,0,0,0
0,0,0,0,0,0,0,0,0,0,0,0,0,0,0,0,0,0,0,0,0,0,0,0,0
0,0,0,0,0,0,0,0,0,0,0,0,0,0,0,0,0,0,0,0,0,0,0,0,0
0,0,0,0,0,0,0,0,0,0,0,0,0,0,0,0,0,0,0,0,0,0,0,0,0
0,0,0,0,0,0,0,0,0,0,0,0,33,0,0,0,0,0,0,0,0,0,0,0,0
0,0,0,0,0,0,0,319,319,0,0,0,31,0,0,0,319,319,0,0,0,0,0,0,0
0,0,0,0,0,0,0,319,0,0,0,0,0,0,0,0,0,319,0,0,0,0,0,0,0
0,0,0,0,0,0,0,319,566,566,566,566,566,566,566,566,566,319,0,0,0,0,0,0,0
0,0,0,0,0,0,0,0,0,0,0,0,0,0,0,0,0,0,0,0,0,0,0,0,0
0,0,0,0,0,0,0,0,0,0,0,0,0,0,0,0,0,0,0,0,0,0,0,0,0
0,0,0,0,0,0,0,0,0,0,0,0,0,0,0,0,0,0,0,0,0,0,0,0,0
0,0,0,0,0,0,0,0,0,0,0,0,0,0,0,0,0,0,0,0,0,0,0,0,0
0,0,0,0,0,0,0,0,0,0,0,0,0,0,0,0,0,0,0,0,0,0,0,0,0
0,0,0,0,0,0,0,0,0,0,0,0,0,0,0,0,0,0,0,0,0,0,0,0,0
0,0,0,0,0,0,0,0,0,0,0,0,0,0,0,0,0,0,0,0,0,0,0,0,0
0,0,0,0,0,0,0,0,0,0,0,0,0,0,0,0,0,0,0,0,0,0,0,0,0
0,0,0,0,0,0,0,0,0,0,0,0,0,0,0,0,0,0,0,0,0,0,0,0,0
0,0,0,0,0,0,0,0,0,0,0,0,0,0,0,0,0,0,0,0,0,0,0,0,0
0,0,0,0,0,0,0,0,0,0,0,0,0,0,0,0,0,0,0,0,0,0,0,0,0
0,0,0,0,0,0,0,0,0,0,0,0,0,0,0,0,0,0,0,0,0,0,0,0,0
0,0,0,0,0,0,0,0,0,0,0,0,0,0,0,0,0,0,0,0,0,0,0,0,0
0,0,0,0,0,0,0,0,0,0,0,0,0,0,0,0,0,0,0,0,0,0,0,0,0
0,0,0,0,0,0,0,0,0,0,0,0,0,0,0,0,0,0,0,0,0,0,0,0,0
0,0,0,0,0,0,0,0,0,0,0,0,319,0,0,0,0,0,0,0,0,0,0,0,0
0,0,0,0,0,0,0,0,0,0,0,0,319,0,0,0,0,0,0,0,0,0,0,0,0
0,0,0,0,0,0,0,0,0,0,0,0,274,0,0,0,0,0,0,0,0,0,0,0,0
0,0,0,0,0,0,0,0,0,0,0,0,477,0,0,0,0,0,0,0,0,0,0,0,0
0,0,0,0,0,0,0,0,0,0,0,0,595,0,0,0,0,0,0,0,0,0,0,0,0
0,0,0,0,0,0,0,0,0,0,0,0,311,0,0,0,0,0,0,0,0,0,0,0,0
0,0,0,0,0,0,0,0,107,0,0,0,311,0,0,0,107,0,0,0,0,0,0,0,0
0,0,0,0,0,0,152,503,503,503,503,503,503,503,503,503,503,503,218,0,0,0,0,0,0
0,0,0,0,0,0,0,0,0,0,0,0,319,0,0,0,0,0,0,0,0,0,0,0,0
0,0,0,0,0,0,0,0,0,0,0,0,0,0,0,0,0,0,0,0,0,0,0,0,0
:endlayer
layer: 21
0,0,0,0,0,0,0,0,0,0,0,0,0,0,0,0,0,0,0,0,0,0,0,0,0
0,0,0,0,0,0,0,0,0,0,0,0,0,0,0,0,0,0,0,0,0,0,0,0,0
0,0,0,0,0,0,0,0,0,0,0,0,0,0,0,0,0,0,0,0,0,0,0,0,0
0,0,0,0,0,0,0,0,0,0,0,0,0,0,0,0,0,0,0,0,0,0,0,0,0
0,0,0,0,0,0,0,0,0,0,0,0,319,0,0,0,0,0,0,0,0,0,0,0,0
0,0,0,0,0,0,0,0,0,0,0,0,32,0,0,0,0,0,0,0,0,0,0,0,0
0,0,0,0,0,0,0,0,0,0,0,0,0,0,0,0,0,0,0,0,0,0,0,0,0
0,0,0,0,0,0,0,0,0,0,0,0,0,0,0,0,0,0,0,0,0,0,0,0,0
0,0,0,0,0,0,0,0,0,0,0,0,0,0,0,0,0,0,0,0,0,0,0,0,0
0,0,0,0,0,0,0,0,0,0,0,0,32,0,0,0,0,0,0,0,0,0,0,0,0
0,0,0,0,0,0,0,0,0,0,0,0,107,0,0,0,0,0,0,0,0,0,0,0,0
0,0,0,0,0,0,0,0,0,0,0,177,31,135,0,0,0,0,0,0,0,0,0,0,0
0,0,0,0,0,0,0,0,0,0,0,0,111,0,0,0,0,0,0,0,0,0,0,0,0
0,0,0,0,0,0,0,0,0,0,0,0,0,0,0,0,0,0,0,0,0,0,0,0,0
0,0,0,0,0,0,0,0,0,0,0,0,0,0,0,0,0,0,0,0,0,0,0,0,0
0,0,0,0,0,0,0,0,0,0,0,0,0,0,0,0,0,0,0,0,0,0,0,0,0
0,0,0,0,0,0,0,0,0,0,0,0,0,0,0,0,0,0,0,0,0,0,0,0,0
0,0,0,0,0,0,0,0,0,0,0,0,0,0,0,0,0,0,0,0,0,0,0,0,0
0,0,0,0,0,0,0,0,0,0,0,0,0,0,0,0,0,0,0,0,0,0,0,0,0
0,0,0,0,0,0,0,0,0,0,0,0,0,0,0,0,0,0,0,0,0,0,0,0,0
0,0,0,0,0,0,319,0,0,0,0,0,33,0,0,0,0,0,319,0,0,0,0,0,0
0,0,0,0,0,0,319,0,0,0,0,177,31,319,0,0,0,0,319,0,0,0,0,0,0
0,0,0,0,0,0,319,0,0,0,0,0,319,319,0,0,0,0,319,0,0,0,0,0,0
0,0,0,0,0,0,0,0,0,0,0,0,0,0,0,0,0,0,0,0,0,0,0,0,0
0,0,0,0,0,0,0,0,0,0,0,0,0,0,0,0,0,0,0,0,0,0,0,0,0
0,0,0,0,0,0,0,0,0,0,0,0,0,0,0,0,0,0,0,0,0,0,0,0,0
0,0,0,0,0,0,0,0,0,0,0,0,0,0,0,0,0,0,0,0,0,0,0,0,0
0,0,0,0,0,0,0,0,0,0,0,0,0,0,0,0,0,0,0,0,0,0,0,0,0
0,0,0,0,0,0,0,0,0,0,0,0,0,0,0,0,0,0,0,0,0,0,0,0,0
0,0,0,0,0,0,0,0,0,0,0,0,0,0,0,0,0,0,0,0,0,0,0,0,0
0,0,0,0,0,0,319,0,0,0,0,0,33,0,0,0,0,0,319,0,0,0,0,0,0
0,0,0,0,0,0,319,0,0,0,0,177,31,135,0,0,0,0,319,0,0,0,0,0,0
0,0,0,0,0,0,319,0,0,0,0,0,111,0,0,0,0,0,319,0,0,0,0,0,0
0,0,0,0,0,0,0,0,0,0,0,0,0,0,0,0,0,0,0,0,0,0,0,0,0
0,0,0,0,0,0,0,0,0,0,0,0,0,0,0,0,0,0,0,0,0,0,0,0,0
0,0,0,0,0,0,0,0,0,0,0,0,0,0,0,0,0,0,0,0,0,0,0,0,0
0,0,0,0,0,0,0,0,0,0,0,0,0,0,0,0,0,0,0,0,0,0,0,0,0
0,0,0,0,0,0,0,0,0,0,0,0,0,0,0,0,0,0,0,0,0,0,0,0,0
0,0,0,0,0,0,0,0,0,0,0,0,0,0,0,0,0,0,0,0,0,0,0,0,0
0,0,0,0,0,0,0,0,0,0,0,0,0,0,0,0,0,0,0,0,0,0,0,0,0
0,0,0,0,0,0,319,0,0,0,0,0,33,0,0,0,0,0,319,0,0,0,0,0,0
0,0,0,0,0,0,319,0,0,0,0,177,31,135,0,0,0,0,319,0,0,0,0,0,0
0,0,0,0,0,0,319,0,0,0,0,0,111,0,0,0,0,0,319,0,0,0,0,0,0
0,0,0,0,0,0,0,0,0,0,0,0,0,0,0,0,0,0,0,0,0,0,0,0,0
0,0,0,0,0,0,0,0,0,0,0,0,0,0,0,0,0,0,0,0,0,0,0,0,0
0,0,0,0,0,0,0,0,0,0,0,0,0,0,0,0,0,0,0,0,0,0,0,0,0
0,0,0,0,0,0,0,0,0,0,0,0,0,0,0,0,0,0,0,0,0,0,0,0,0
0,0,0,0,0,0,0,0,0,0,0,0,0,0,0,0,0,0,0,0,0,0,0,0,0
0,0,0,0,0,0,0,0,0,0,0,0,0,0,0,0,0,0,0,0,0,0,0,0,0
0,0,0,0,0,0,0,0,0,0,0,0,0,0,0,0,0,0,0,0,0,0,0,0,0
0,0,0,0,0,0,0,0,0,0,0,0,33,0,0,0,0,0,0,0,0,0,0,0,0
0,0,0,0,0,0,0,0,0,0,0,0,31,0,0,0,0,0,0,0,0,0,0,0,0
0,0,0,0,0,0,0,0,0,0,0,0,0,0,0,0,0,0,0,0,0,0,0,0,0
0,0,0,0,0,0,0,566,574,574,574,574,574,574,574,574,574,566,0,0,0,0,0,0,0
0,0,0,0,0,0,0,0,0,0,0,0,0,0,0,0,0,0,0,0,0,0,0,0,0
0,0,0,0,0,0,0,0,0,0,0,0,0,0,0,0,0,0,0,0,0,0,0,0,0
0,0,0,0,0,0,0,0,0,0,0,0,0,0,0,0,0,0,0,0,0,0,0,0,0
0,0,0,0,0,0,0,0,0,0,0,0,0,0,0,0,0,0,0,0,0,0,0,0,0
0,0,0,0,0,0,0,0,0,0,0,0,0,0,0,0,0,0,0,0,0,0,0,0,0
0,0,0,0,0,0,0,0,0,0,0,0,0,0,0,0,0,0,0,0,0,0,0,0,0
0,0,0,0,0,0,0,0,0,0,0,0,0,0,0,0,0,0,0,0,0,0,0,0,0
0,0,0,0,0,0,0,0,0,0,0,0,0,0,0,0,0,0,0,0,0,0,0,0,0
0,0,0,0,0,0,0,0,0,0,0,0,0,0,0,0,0,0,0,0,0,0,0,0,0
0,0,0,0,0,0,0,0,0,0,0,0,0,0,0,0,0,0,0,0,0,0,0,0,0
0,0,0,0,0,0,0,0,0,0,0,0,0,0,0,0,0,0,0,0,0,0,0,0,0
0,0,0,0,0,0,0,0,0,0,0,0,0,0,0,0,0,0,0,0,0,0,0,0,0
0,0,0,0,0,0,0,0,0,0,0,0,0,0,0,0,0,0,0,0,0,0,0,0,0
0,0,0,0,0,0,0,0,0,0,0,0,0,0,0,0,0,0,0,0,0,0,0,0,0
0,0,0,0,0,0,0,0,0,0,0,0,319,0,0,0,0,0,0,0,0,0,0,0,0
0,0,0,0,0,0,0,0,0,0,0,0,319,0,0,0,0,0,0,0,0,0,0,0,0
0,0,0,0,0,0,0,0,0,0,0,0,491,0,0,0,0,0,0,0,0,0,0,0,0
0,0,0,0,0,0,0,0,0,0,0,0,491,0,0,0,0,0,0,0,0,0,0,0,0
0,0,0,0,0,0,0,0,0,0,0,0,0,0,0,0,0,0,0,0,0,0,0,0,0
0,0,0,0,0,0,0,0,0,0,0,0,0,0,0,0,0,0,0,0,0,0,0,0,0
0,0,0,0,0,0,0,0,0,0,0,0,0,0,0,0,0,0,0,0,0,0,0,0,0
0,0,0,0,0,0,0,0,0,0,0,0,595,0,0,0,0,0,0,0,0,0,0,0,0
0,0,0,0,0,0,0,0,595,319,319,319,311,319,319,319,595,0,0,0,0,0,0,0,0
0,0,0,0,0,0,0,0,0,0,0,0,216,0,0,0,0,0,0,0,0,0,0,0,0
0,0,0,0,0,0,0,0,0,0,0,0,0,0,0,0,0,0,0,0,0,0,0,0,0
:endlayer
layer: 22
0,0,0,0,0,0,0,0,0,0,0,0,0,0,0,0,0,0,0,0,0,0,0,0,0
0,0,0,0,0,0,0,0,0,0,0,0,0,0,0,0,0,0,0,0,0,0,0,0,0
0,0,0,0,0,0,0,0,0,0,0,0,0,0,0,0,0,0,0,0,0,0,0,0,0
0,0,0,0,0,0,0,0,0,0,0,0,0,319,0,0,0,0,0,0,0,0,0,0,0
0,0,0,0,0,0,0,0,0,0,0,0,319,319,0,0,0,0,0,0,0,0,0,0,0
0,0,0,0,0,0,0,0,0,0,0,0,0,0,0,0,0,0,0,0,0,0,0,0,0
0,0,0,0,0,0,0,0,0,0,0,0,0,0,0,0,0,0,0,0,0,0,0,0,0
0,0,0,0,0,0,0,0,0,0,0,0,0,0,0,0,0,0,0,0,0,0,0,0,0
0,0,0,0,0,0,0,0,0,0,0,0,0,0,0,0,0,0,0,0,0,0,0,0,0
0,0,0,0,0,0,0,0,0,0,0,0,0,0,0,0,0,0,0,0,0,0,0,0,0
0,0,0,0,0,0,0,0,0,0,0,0,0,0,0,0,0,0,0,0,0,0,0,0,0
0,0,0,0,0,0,0,0,0,0,0,0,31,0,0,0,0,0,0,0,0,0,0,0,0
0,0,0,0,0,0,0,0,0,0,0,0,0,0,0,0,0,0,0,0,0,0,0,0,0
0,0,0,0,0,0,0,0,0,0,0,0,0,0,0,0,0,0,0,0,0,0,0,0,0
0,0,0,0,0,0,0,0,0,0,0,0,0,0,0,0,0,0,0,0,0,0,0,0,0
0,0,0,0,0,0,0,0,0,0,0,0,0,0,0,0,0,0,0,0,0,0,0,0,0
0,0,0,0,0,0,0,0,0,0,0,0,0,0,0,0,0,0,0,0,0,0,0,0,0
0,0,0,0,0,0,0,0,0,0,0,0,0,0,0,0,0,0,0,0,0,0,0,0,0
0,0,0,0,0,0,0,0,0,0,0,0,0,0,0,0,0,0,0,0,0,0,0,0,0
0,0,0,0,0,0,0,0,0,0,0,0,0,0,0,0,0,0,0,0,0,0,0,0,0
0,0,0,0,0,0,0,0,0,0,0,0,33,0,0,0,0,0,0,0,0,0,0,0,0
0,0,0,0,0,0,319,0,0,0,0,0,31,319,0,0,0,0,319,0,0,0,0,0,0
0,0,0,0,0,0,566,319,0,0,0,0,0,0,0,0,0,319,566,0,0,0,0,0,0
0,0,0,0,0,0,0,566,566,566,566,566,566,566,566,566,566,566,0,0,0,0,0,0,0
0,0,0,0,0,0,0,0,0,0,0,0,0,0,0,0,0,0,0,0,0,0,0,0,0
0,0,0,0,0,0,0,0,0,0,0,0,0,0,0,0,0,0,0,0,0,0,0,0,0
0,0,0,0,0,0,0,0,0,0,0,0,0,0,0,0,0,0,0,0,0,0,0,0,0
0,0,0,0,0,0,0,0,0,0,0,0,0,0,0,0,0,0,0,0,0,0,0,0,0
0,0,0,0,0,0,0,0,0,0,0,0,0,0,0,0,0,0,0,0,0,0,0,0,0
0,0,0,0,0,0,0,0,0,0,0,0,0,0,0,0,0,0,0,0,0,0,0,0,0
0,0,0,0,0,0,0,0,0,0,0,0,33,0,0,0,0,0,0,0,0,0,0,0,0
