# Ancient Warfare Structure Template File
# Auto-generated structure template file. created on: 5/27/2021 at: 22:23:15
# Lines beginning with # denote comments

header:
version=2.11
name=SurvivalBuildTowerKeepA
mods=
size=27,33,30
offset=26,5,29
:endheader

#### VALIDATION ####
validation:
type=ground
structureAuthor=Loki61089
survival=true
worldGenEnabled=false
unique=false
preserveBlocks=true
preventNaturalHostileSpawns=false
selectionWeight=1
clusterValue=1
minDuplicateDistance=1
dimensionWhiteList=true
dimensionList=
biomeGroupList=
biomeWhiteList=true
biomeList=
leveling=0
fill=0
border=0
blockSwap=false
territoryName=
biomeReplacement=minecraft:
minGenerationHeight=0
maxGenerationHeight=255
:endvalidation

#### LAYERS ####
layer: 0
1,1,1,1,1,1,1,1,1,1,1,1,1,1,1,1,1,1,1,1,1,1,1,1,1,1,1
1,1,1,1,1,1,1,1,1,1,1,1,1,1,1,1,1,1,1,1,1,1,1,1,1,1,1
1,1,1,1,1,1,1,1,2,2,2,2,2,2,2,2,2,2,2,2,2,2,2,2,1,1,1
1,1,1,1,1,1,1,1,2,2,2,2,2,2,2,2,2,2,2,2,2,2,2,2,1,1,1
1,1,1,1,1,1,1,1,2,2,2,2,2,2,2,2,2,2,2,2,2,2,2,2,1,1,1
1,1,1,1,1,1,1,1,2,2,2,2,2,2,2,2,2,2,2,2,2,2,2,2,1,1,1
1,1,1,1,1,1,1,1,2,2,2,2,2,2,2,2,2,2,2,2,2,2,2,2,1,1,1
1,1,2,2,2,2,2,2,2,2,2,2,2,2,2,2,2,2,2,2,2,2,2,2,1,1,1
1,1,2,2,2,2,2,2,2,2,2,2,2,2,2,2,2,2,2,2,2,2,2,2,1,1,1
1,1,2,2,2,2,2,2,2,2,2,2,2,2,2,2,2,2,2,2,2,2,2,2,1,1,1
1,1,2,2,2,2,2,2,2,2,2,2,2,2,2,2,2,2,2,2,2,2,2,2,1,1,1
1,1,2,2,2,2,2,2,2,2,2,2,2,2,2,2,2,2,2,2,2,2,2,2,1,1,1
1,1,2,2,2,2,2,2,2,2,2,2,2,2,2,2,2,2,2,2,2,2,2,2,1,1,1
1,1,2,2,2,2,2,2,2,2,2,2,2,2,2,2,2,2,2,2,2,2,2,2,1,1,1
1,1,2,2,2,2,2,2,2,2,2,2,2,2,2,2,2,2,2,2,2,2,2,2,1,1,1
1,1,2,2,2,2,2,2,2,2,2,2,2,2,2,2,2,2,2,2,2,2,2,2,1,1,1
1,1,1,1,1,1,1,1,2,2,2,2,2,2,2,2,2,2,2,2,2,2,2,2,1,1,1
1,1,1,1,1,1,1,1,2,2,2,2,2,2,2,2,2,2,2,2,2,2,2,2,1,1,1
1,1,1,1,1,1,1,1,2,2,2,2,2,2,2,2,2,2,2,2,2,2,2,2,1,1,1
1,1,1,1,1,1,1,1,2,2,2,2,2,2,2,2,2,2,2,2,2,2,2,2,1,1,1
1,1,1,1,1,1,1,1,2,2,2,2,2,2,2,2,2,2,2,2,2,2,2,2,1,1,1
1,1,1,1,1,1,1,1,2,2,2,2,2,2,2,2,2,2,2,2,2,2,2,2,1,1,1
1,1,1,2,2,2,2,2,2,2,2,2,2,2,2,2,2,2,2,2,2,2,2,2,1,1,1
1,1,1,2,2,2,2,2,2,2,2,2,2,1,1,1,1,1,1,1,1,1,1,1,1,1,1
1,1,1,2,2,2,2,2,2,2,2,2,2,1,1,1,1,1,1,1,1,1,1,1,1,1,1
1,1,1,2,2,2,2,2,2,2,2,2,2,1,1,1,1,1,1,1,1,1,1,1,1,1,1
1,1,1,2,2,2,2,2,2,2,2,2,2,1,1,1,1,1,1,1,1,1,1,1,1,1,1
1,1,1,2,2,2,2,2,2,2,2,2,2,1,1,1,1,1,1,1,1,1,1,1,1,1,1
1,1,1,1,1,1,1,1,1,1,1,1,1,1,1,1,1,1,1,1,1,1,1,1,1,1,1
1,1,1,1,1,1,1,1,1,1,1,1,1,1,1,1,1,1,1,1,1,1,1,1,1,1,1
:endlayer
layer: 1
1,1,1,1,1,1,1,1,1,1,1,1,1,1,1,1,1,1,1,1,1,1,1,1,1,1,1
1,1,1,1,1,1,1,1,1,1,1,1,1,1,1,1,1,1,1,1,1,1,1,1,1,1,1
1,1,1,1,1,1,1,1,2,2,2,2,2,2,2,2,2,2,2,2,2,2,2,2,1,1,1
1,1,1,1,1,1,1,1,2,2,2,2,2,2,2,2,2,2,2,2,2,2,2,2,1,1,1
1,1,1,1,1,1,1,1,2,2,2,2,2,2,2,2,2,2,2,2,2,2,2,2,1,1,1
1,1,1,1,1,1,1,1,2,2,2,2,2,2,2,2,2,2,2,2,2,2,2,2,1,1,1
1,1,1,1,1,1,1,1,2,2,2,2,2,2,2,2,2,2,2,2,2,2,2,2,1,1,1
1,1,2,2,2,2,2,2,2,2,2,2,2,2,2,2,2,2,2,2,2,2,2,2,1,1,1
1,1,2,2,2,2,2,2,2,2,2,2,2,2,2,2,2,2,2,2,2,2,2,2,1,1,1
1,1,2,2,2,2,2,2,2,2,2,2,2,2,2,2,2,2,2,2,2,2,2,2,1,1,1
1,1,2,2,2,2,2,2,2,2,2,2,2,2,2,2,2,2,2,2,2,2,2,2,1,1,1
1,1,2,2,2,2,2,2,2,2,2,2,2,2,2,2,2,2,2,2,2,2,2,2,1,1,1
1,1,2,2,2,2,2,2,2,2,2,2,2,2,2,2,2,2,2,2,2,2,2,2,1,1,1
1,1,2,2,2,2,2,2,2,2,2,2,2,2,2,2,2,2,2,2,2,2,2,2,1,1,1
1,1,2,2,2,2,2,2,2,2,2,2,2,2,2,2,2,2,2,2,2,2,2,2,1,1,1
1,1,2,2,2,2,2,2,2,2,2,2,2,2,2,2,2,2,2,2,2,2,2,2,1,1,1
1,1,1,1,1,1,1,1,2,2,2,2,2,2,2,2,2,2,2,2,2,2,2,2,1,1,1
1,1,1,1,1,1,1,1,2,2,2,2,2,2,2,2,2,2,2,2,2,2,2,2,1,1,1
1,1,1,1,1,1,1,1,2,2,2,2,2,2,2,2,2,2,2,2,2,2,2,2,1,1,1
1,1,1,1,1,1,1,1,2,2,2,2,2,2,2,2,2,2,2,2,2,2,2,2,1,1,1
1,1,1,1,1,1,1,1,2,2,2,2,2,2,2,2,2,2,2,2,2,2,2,2,1,1,1
1,1,1,1,1,1,1,1,2,2,2,2,2,2,2,2,2,2,2,2,2,2,2,2,1,1,1
1,1,1,2,2,2,2,2,2,2,2,2,2,2,2,2,2,2,2,2,2,2,2,2,1,1,1
1,1,1,2,2,2,2,2,2,2,2,2,2,1,1,1,1,1,1,1,1,1,1,1,1,1,1
1,1,1,2,2,2,2,2,2,2,2,2,2,1,1,1,1,1,1,1,1,1,1,1,1,1,1
1,1,1,2,2,2,2,2,2,2,2,2,2,1,1,1,1,1,1,1,1,1,1,1,1,1,1
1,1,1,2,2,2,2,2,2,2,2,2,2,1,1,1,1,1,1,1,1,1,1,1,1,1,1
1,1,1,2,2,2,2,2,2,2,2,2,2,1,1,1,1,1,1,1,1,1,1,1,1,1,1
1,1,1,1,1,1,1,1,1,1,1,1,1,1,1,1,1,1,1,1,1,1,1,1,1,1,1
1,1,1,1,1,1,1,1,1,1,1,1,1,1,1,1,1,1,1,1,1,1,1,1,1,1,1
:endlayer
layer: 2
1,1,1,1,1,1,1,1,1,1,1,1,1,1,1,1,1,1,1,1,1,1,1,1,1,1,1
1,1,1,1,1,1,1,1,1,1,1,1,1,1,1,1,1,1,1,1,1,1,1,1,1,1,1
1,1,1,1,1,1,1,1,2,2,2,2,2,2,2,2,2,2,2,2,2,2,2,2,1,1,1
1,1,1,1,1,1,1,1,2,2,2,2,2,2,2,2,2,2,2,2,2,2,2,2,1,1,1
1,1,1,1,1,1,1,1,2,2,2,2,2,2,2,2,2,2,2,2,2,2,2,2,1,1,1
1,1,1,1,1,1,1,1,2,2,2,2,2,2,2,2,2,2,2,2,2,2,2,2,1,1,1
1,1,1,1,1,1,1,1,2,2,2,2,2,2,2,2,2,2,2,2,2,2,2,2,1,1,1
1,1,2,2,2,2,2,2,2,2,2,2,2,2,2,2,2,2,2,2,2,2,2,2,1,1,1
1,1,2,2,2,2,2,2,2,2,2,2,2,2,2,2,2,2,2,2,2,2,2,2,1,1,1
1,1,2,2,2,2,2,2,2,2,2,2,2,2,2,2,2,2,2,2,2,2,2,2,1,1,1
1,1,2,2,2,2,2,2,2,2,2,2,2,2,2,2,2,2,2,2,2,2,2,2,1,1,1
1,1,2,2,2,2,2,2,2,2,2,2,2,2,2,2,2,2,2,2,2,2,2,2,1,1,1
1,1,2,2,2,2,2,2,2,2,2,2,2,2,2,2,2,2,2,2,2,2,2,2,1,1,1
1,1,2,2,2,2,2,2,2,2,2,2,2,2,2,2,2,2,2,2,2,2,2,2,1,1,1
1,1,2,2,2,2,2,2,2,2,2,2,2,2,2,2,2,2,2,2,2,2,2,2,1,1,1
1,1,2,2,2,2,2,2,2,2,2,2,2,2,2,2,2,2,2,2,2,2,2,2,1,1,1
1,1,1,1,1,1,1,1,2,2,2,2,2,2,2,2,2,2,2,2,2,2,2,2,1,1,1
1,1,1,1,1,1,1,1,2,2,2,2,2,2,2,2,2,2,2,2,2,2,2,2,1,1,1
1,1,1,1,1,1,1,1,2,2,2,2,2,2,2,2,2,2,2,2,2,2,2,2,1,1,1
1,1,1,1,1,1,1,1,2,2,2,2,2,2,2,2,2,2,2,2,2,2,2,2,1,1,1
1,1,1,1,1,1,1,1,2,2,2,2,2,2,2,2,2,2,2,2,2,2,2,2,1,1,1
1,1,1,1,1,1,1,1,2,2,2,2,2,2,2,2,2,2,2,2,2,2,2,2,1,1,1
1,1,1,2,2,2,2,2,2,2,2,2,2,2,2,2,2,2,2,2,2,2,2,2,1,1,1
1,1,1,2,2,2,2,2,2,2,2,2,2,1,1,1,1,1,1,1,1,1,1,1,1,1,1
1,1,1,2,2,2,2,2,2,2,2,2,2,1,1,1,1,1,1,1,1,1,1,1,1,1,1
1,1,1,2,2,2,2,2,2,2,2,2,2,1,1,1,1,1,1,1,1,1,1,1,1,1,1
1,1,1,2,2,2,2,2,2,2,2,2,2,1,1,1,1,1,1,1,1,1,1,1,1,1,1
1,1,1,2,2,2,2,2,2,2,2,2,2,1,1,1,1,1,1,1,1,1,1,1,1,1,1
1,1,1,1,1,1,1,1,1,1,1,1,1,1,1,1,1,1,1,1,1,1,1,1,1,1,1
1,1,1,1,1,1,1,1,1,1,1,1,1,1,1,1,1,1,1,1,1,1,1,1,1,1,1
:endlayer
layer: 3
1,1,1,1,1,1,1,1,1,1,1,1,1,1,1,1,1,1,1,1,1,1,1,1,1,1,1
1,1,1,1,1,1,1,1,1,1,1,1,1,1,1,1,1,1,1,1,1,1,1,1,1,1,1
1,1,1,1,1,1,1,1,2,2,2,2,2,2,2,2,2,2,2,2,2,2,2,2,1,1,1
1,1,1,1,1,1,1,1,2,2,2,2,2,2,2,2,2,2,2,2,2,2,2,2,1,1,1
1,1,1,1,1,1,1,1,2,2,2,2,2,2,2,2,2,2,2,2,2,2,2,2,1,1,1
1,1,1,1,1,1,1,1,2,2,2,2,2,2,2,2,2,2,2,2,2,2,2,2,1,1,1
1,1,1,1,1,1,1,1,2,2,2,2,2,2,2,2,2,2,2,2,2,2,2,2,1,1,1
1,1,2,2,2,2,2,2,2,2,2,2,2,2,2,2,2,2,2,2,2,2,2,2,1,1,1
1,1,2,2,2,2,2,2,2,2,2,2,2,2,2,2,2,2,2,2,2,2,2,2,1,1,1
1,1,2,2,2,2,2,2,2,2,2,2,2,2,2,2,2,2,2,2,2,2,2,2,1,1,1
1,1,2,2,2,2,2,2,2,2,2,2,2,2,2,2,2,2,2,2,2,2,2,2,1,1,1
1,1,2,2,2,2,2,2,2,2,2,2,2,2,2,2,2,2,2,2,2,2,2,2,1,1,1
1,1,2,2,2,2,2,2,2,2,2,2,2,2,2,2,2,2,2,2,2,2,2,2,1,1,1
1,1,2,2,2,2,2,2,2,2,2,2,2,2,2,2,2,2,2,2,2,2,2,2,1,1,1
1,1,2,2,2,2,2,2,2,2,2,2,2,2,2,2,2,2,2,2,2,2,2,2,1,1,1
1,1,2,2,2,2,2,2,2,2,2,2,2,2,2,2,2,2,2,2,2,2,2,2,1,1,1
1,1,1,1,1,1,1,1,2,2,2,2,2,2,2,2,2,2,2,2,2,2,2,2,1,1,1
1,1,1,1,1,1,1,1,2,2,2,2,2,2,2,2,2,2,2,2,2,2,2,2,1,1,1
1,1,1,1,1,1,1,1,2,2,2,2,2,2,2,2,2,2,2,2,2,2,2,2,1,1,1
1,1,1,1,1,1,1,1,2,2,2,2,2,2,2,2,2,2,2,2,2,2,2,2,1,1,1
1,1,1,1,1,1,1,1,2,2,2,2,2,2,2,2,2,2,2,2,2,2,2,2,1,1,1
1,1,1,1,1,1,1,1,2,2,2,2,2,2,2,2,2,2,2,2,2,2,2,2,1,1,1
1,1,1,2,2,2,2,2,2,2,2,2,2,2,2,2,2,2,2,2,2,2,2,2,1,1,1
1,1,1,2,2,2,2,2,2,2,2,2,2,1,1,1,1,1,1,1,1,1,1,1,1,1,1
1,1,1,2,2,2,2,2,2,2,2,2,2,1,1,1,1,1,1,1,1,1,1,1,1,1,1
1,1,1,2,2,2,2,2,2,2,2,2,2,1,1,1,1,1,1,1,1,1,1,1,1,1,1
1,1,1,2,2,2,2,2,2,2,2,2,2,1,1,1,1,1,1,1,1,1,1,1,1,1,1
1,1,1,2,2,2,2,2,2,2,2,2,2,1,1,1,1,1,1,1,1,1,1,1,1,1,1
1,1,1,1,1,1,1,1,1,1,1,1,1,1,1,1,1,1,1,1,1,1,1,1,1,1,1
1,1,1,1,1,1,1,1,1,1,1,1,1,1,1,1,1,1,1,1,1,1,1,1,1,1,1
:endlayer
layer: 4
3,3,3,3,3,3,3,3,3,3,3,3,3,3,3,3,3,3,3,3,3,3,3,3,3,3,3
3,3,3,3,3,3,3,3,3,3,3,3,3,3,3,3,3,3,3,3,3,3,3,3,3,3,3
3,3,3,3,3,3,3,3,2,2,2,2,2,2,2,2,2,2,2,2,2,2,2,2,3,3,3
3,3,3,3,3,3,3,3,2,2,2,2,2,2,2,2,2,2,2,2,2,2,2,2,3,3,3
3,3,3,3,3,3,3,3,2,2,2,2,2,2,2,2,2,2,2,2,2,2,2,2,3,3,3
3,3,3,3,3,3,3,3,2,2,2,2,2,2,2,2,2,2,2,2,2,2,2,2,3,3,3
3,3,3,3,3,3,3,3,2,2,2,2,2,2,2,2,2,2,2,2,2,2,2,2,3,3,3
3,3,2,2,2,2,2,2,2,2,2,2,2,2,2,2,2,2,2,2,2,2,2,2,3,3,3
3,3,2,2,2,2,2,2,2,2,2,2,2,2,2,2,2,2,2,2,2,2,2,2,3,3,3
3,3,2,2,2,2,2,2,2,2,2,2,2,2,2,2,2,2,2,2,2,2,2,2,3,3,3
3,3,2,2,2,2,2,2,2,2,2,2,2,2,2,2,2,2,2,2,2,2,2,2,3,3,3
3,3,2,2,2,2,2,2,2,2,2,2,2,2,2,2,2,2,2,2,2,2,2,2,3,3,3
3,3,2,2,2,2,2,2,2,2,2,2,2,2,2,2,2,2,2,2,2,2,2,2,3,3,3
3,3,2,2,2,2,2,2,2,2,2,2,2,2,2,2,2,2,2,2,2,2,2,2,3,3,3
3,3,2,2,2,2,2,2,2,2,2,2,2,2,2,2,2,2,2,2,2,2,2,2,3,3,3
3,3,2,2,2,2,2,2,2,2,2,2,2,2,2,2,2,2,2,2,2,2,2,2,3,3,3
3,3,3,3,3,3,3,3,2,2,2,2,2,2,2,2,2,2,2,2,2,2,2,2,3,3,3
3,3,3,3,3,3,3,3,2,2,2,2,2,2,2,2,2,2,2,2,2,2,2,2,3,3,3
3,3,3,3,3,3,3,3,2,2,2,2,2,2,2,2,2,2,2,2,2,2,2,2,3,3,3
3,3,3,3,3,3,3,3,2,2,2,2,2,2,2,2,2,2,2,2,2,2,2,2,3,3,3
3,3,3,3,3,3,3,3,2,2,2,2,2,2,2,2,2,2,2,2,2,2,2,2,3,3,3
3,3,3,3,3,3,3,3,2,2,2,2,2,2,2,2,2,2,2,2,2,2,2,2,3,3,3
3,3,3,2,2,2,2,2,2,2,2,2,2,2,2,2,2,2,2,2,2,2,2,2,3,3,3
3,3,3,2,2,2,2,2,2,2,2,2,2,3,3,3,3,3,3,3,3,3,3,3,3,3,3
3,3,3,2,2,2,2,2,2,2,2,2,2,3,3,3,3,3,3,3,3,3,3,3,3,3,3
3,3,3,2,2,2,2,2,2,2,2,2,2,3,3,3,3,3,3,3,3,3,3,3,3,3,3
3,3,3,2,2,2,2,2,2,2,2,2,2,3,3,3,3,3,3,3,3,3,3,3,3,3,3
3,3,3,2,2,2,2,2,2,2,2,2,2,3,3,3,3,3,3,3,3,3,3,3,3,3,3
3,3,3,3,3,3,3,3,3,3,3,3,3,3,3,3,3,3,3,3,3,3,3,3,3,3,3
3,3,3,3,3,3,3,3,3,3,3,3,3,3,3,3,3,3,3,3,3,3,3,3,3,3,3
:endlayer
layer: 5
0,0,0,0,0,0,0,0,0,0,0,0,0,0,0,0,0,0,0,0,0,0,0,0,0,0,0
0,0,0,0,0,0,0,0,0,0,0,0,0,0,0,0,0,0,0,0,0,0,0,0,0,0,0
0,0,0,0,0,0,0,0,4,5,5,5,5,5,5,5,5,5,5,5,5,5,5,4,0,0,0
0,0,0,0,0,0,0,0,5,5,5,5,5,5,5,5,5,5,5,5,5,5,5,5,0,0,0
0,0,0,0,0,0,0,0,5,5,6,6,6,6,6,6,6,6,6,6,6,6,5,5,0,0,0
0,0,0,0,0,0,0,0,5,5,6,6,6,6,6,6,6,6,6,6,6,6,5,5,0,0,0
0,0,0,0,0,0,0,0,5,5,6,6,6,6,6,6,6,6,6,6,6,6,5,5,0,0,0
0,0,4,5,5,5,5,5,5,5,6,6,6,6,6,6,6,6,6,6,6,6,5,5,0,0,0
0,0,5,5,5,5,5,5,5,5,5,5,5,5,5,5,6,5,5,5,5,5,5,4,0,0,0
0,0,5,5,6,6,6,6,6,5,6,6,6,6,6,6,6,6,6,6,6,6,5,5,0,0,0
0,0,5,5,6,6,6,6,6,5,6,6,6,6,6,6,6,6,6,6,6,6,5,5,0,0,0
0,0,5,5,6,6,6,6,6,6,6,6,6,6,6,6,6,6,6,6,6,6,5,5,0,0,0
0,0,5,5,6,6,6,6,6,5,6,6,6,6,6,6,6,6,6,6,6,6,5,5,0,0,0
0,0,5,5,6,6,6,6,6,5,6,6,6,6,6,6,6,6,6,6,6,6,5,5,0,0,0
0,0,5,5,5,5,5,5,5,5,6,6,6,6,6,6,6,6,6,6,6,6,5,5,0,0,0
0,0,4,5,5,5,5,5,5,5,6,6,6,6,6,6,6,6,6,6,6,6,5,5,0,0,0
0,0,0,0,0,0,0,0,5,5,6,6,6,6,6,6,6,6,6,6,6,6,5,5,0,0,0
0,0,0,0,0,0,0,0,5,5,6,6,6,6,6,6,6,6,6,6,6,6,5,4,0,0,0
0,0,0,0,0,0,0,0,5,5,6,6,6,6,6,6,6,6,6,6,6,6,5,5,0,0,0
0,0,0,0,0,0,0,0,5,5,6,6,6,6,6,6,6,6,6,6,6,6,5,5,0,0,0
0,0,0,0,0,0,0,0,5,5,6,6,6,6,6,6,6,6,6,6,6,6,5,5,0,0,0
0,0,0,0,0,0,0,0,5,5,5,5,5,5,5,5,5,5,5,5,5,5,5,5,0,0,0
0,0,0,4,5,5,5,5,4,5,5,5,5,5,5,5,5,5,4,5,5,5,5,4,0,0,0
0,0,0,5,2,2,2,2,5,2,2,2,7,0,0,0,0,0,0,0,0,0,0,0,0,0,0
0,0,0,5,2,2,2,2,5,2,2,2,7,0,0,0,0,0,0,0,0,0,0,0,0,0,0
0,0,0,5,2,2,2,2,5,2,2,2,7,0,0,0,0,0,0,0,0,0,0,0,0,0,0
0,0,0,5,2,2,2,2,5,2,2,2,7,0,0,0,0,0,0,0,0,0,0,0,0,0,0
0,0,0,4,5,5,5,5,4,5,5,5,5,0,0,0,0,0,0,0,0,0,0,0,0,0,0
0,0,0,0,0,0,0,0,0,0,0,0,0,0,0,0,0,0,0,0,0,0,0,0,0,0,0
0,0,0,0,0,0,0,0,0,0,0,0,0,0,0,0,0,0,0,0,0,0,0,0,0,0,0
:endlayer
layer: 6
0,0,0,0,0,0,0,0,0,0,0,0,0,0,0,0,0,0,0,0,0,0,0,0,0,0,0
0,0,0,0,0,0,0,0,0,0,0,0,0,0,0,0,0,0,0,0,0,0,0,0,0,0,0
0,0,0,0,0,0,0,0,4,4,5,5,5,5,5,5,5,8,8,5,5,5,4,4,0,0,0
0,0,0,0,0,0,0,0,4,5,4,5,5,5,5,5,5,0,0,5,5,4,5,4,0,0,0
0,0,0,0,0,0,0,0,5,4,0,0,0,0,0,0,0,0,0,0,0,0,4,5,0,0,0
0,0,0,0,0,0,0,0,5,5,0,0,0,0,0,0,0,0,0,0,0,0,5,5,0,0,0
0,0,0,0,0,0,0,0,5,5,0,0,0,0,0,0,0,0,0,0,0,0,5,5,0,0,0
0,0,4,4,5,5,5,5,5,4,0,0,0,0,0,0,0,0,0,0,0,0,4,4,0,0,0
0,0,4,5,4,5,5,5,4,5,4,5,5,5,5,5,0,5,5,5,5,4,5,4,0,0,0
0,0,5,4,0,0,0,0,0,4,0,0,0,0,0,0,0,0,0,0,0,0,4,4,0,0,0
0,0,5,5,0,0,0,0,0,5,0,0,0,0,0,0,0,0,0,0,0,0,5,5,0,0,0
0,0,5,5,0,0,0,0,0,0,0,0,9,0,0,0,0,0,0,9,0,0,5,5,0,0,0
0,0,5,5,0,0,0,0,0,5,0,0,0,0,0,0,0,0,0,0,0,0,5,5,0,0,0
0,0,5,4,0,0,0,0,0,4,0,0,0,0,0,0,0,0,0,0,0,0,5,5,0,0,0
0,0,4,5,4,5,5,5,4,4,0,0,0,0,0,9,0,0,0,9,0,0,0,10,0,0,0
0,0,4,4,5,5,5,5,5,4,0,0,0,0,0,0,0,0,0,0,0,0,0,10,0,0,0
0,0,0,0,0,0,0,0,5,5,0,0,0,0,0,0,0,0,0,0,0,0,4,4,0,0,0
0,0,0,0,0,0,0,0,5,5,0,0,0,0,0,0,0,0,4,4,5,4,4,4,0,0,0
0,0,0,0,0,0,0,0,11,0,0,0,9,0,0,9,0,0,0,0,11,12,4,4,0,0,0
0,0,0,0,0,0,0,0,11,0,0,0,0,0,0,0,0,0,5,0,4,0,5,5,0,0,0
0,0,0,0,0,0,0,0,5,4,0,0,0,0,0,0,0,0,4,0,0,0,4,5,0,0,0
0,0,0,0,0,0,0,0,4,5,4,5,5,0,0,5,5,4,4,4,5,4,5,4,0,0,0
0,0,0,4,4,5,5,4,4,4,5,5,5,13,13,5,5,4,4,4,5,5,4,4,0,0,0
0,0,0,4,2,2,2,2,4,2,2,7,0,0,0,0,0,0,0,0,0,0,0,0,0,0,0
0,0,0,5,2,2,2,2,5,2,2,7,0,0,0,0,0,0,0,0,0,0,0,0,0,0,0
0,0,0,5,2,2,2,2,5,2,2,7,0,0,0,0,0,0,0,0,0,0,0,0,0,0,0
0,0,0,4,2,2,2,2,4,2,2,7,0,0,0,0,0,0,0,0,0,0,0,0,0,0,0
0,0,0,4,4,5,5,4,4,4,5,5,10,0,0,0,0,0,0,0,0,0,0,0,0,0,0
0,0,0,0,0,0,0,0,0,0,0,0,0,0,0,0,0,0,0,0,0,0,0,0,0,0,0
0,0,0,0,0,0,0,0,0,0,0,0,0,0,0,0,0,0,0,0,0,0,0,0,0,0,0
:endlayer
layer: 7
0,0,0,0,0,0,0,0,0,0,0,0,0,0,0,0,0,0,0,0,0,0,0,0,0,0,0
0,0,0,0,0,0,0,0,0,0,0,0,0,0,0,0,0,0,0,0,0,0,0,0,0,0,0
0,0,0,0,0,0,0,0,4,5,5,5,5,5,5,5,5,0,0,5,5,5,5,4,0,0,0
0,0,0,0,0,0,0,0,5,5,5,5,5,5,5,5,5,0,0,5,5,5,5,5,0,0,0
0,0,0,0,0,0,0,0,5,5,0,0,0,0,0,0,14,0,0,0,0,0,5,5,0,0,0
0,0,0,0,0,0,0,0,5,5,0,0,0,0,0,0,0,0,0,0,0,0,5,5,0,0,0
0,0,0,0,0,0,0,0,5,5,0,0,0,0,0,0,0,0,0,0,0,0,5,5,0,0,0
0,0,4,5,5,5,5,5,5,5,0,0,15,0,0,0,0,0,0,15,0,0,5,5,0,0,0
0,0,5,5,5,5,5,5,5,5,5,5,5,5,5,5,0,5,5,5,5,5,5,4,0,0,0
0,0,5,5,0,0,14,0,0,5,0,0,0,0,0,0,0,0,0,0,0,0,5,5,0,0,0
0,0,5,5,0,0,0,0,0,5,0,0,0,0,0,0,0,0,0,0,0,0,5,5,0,0,0
0,0,5,5,0,0,0,0,0,0,0,0,0,0,0,0,0,0,0,0,0,0,5,5,0,0,0
0,0,5,5,0,0,0,0,0,5,0,0,0,0,0,0,0,0,0,0,0,0,5,5,0,0,0
0,0,5,5,0,0,15,0,0,5,0,0,0,0,0,0,0,0,0,0,0,0,5,5,0,0,0
0,0,5,5,5,5,5,5,5,4,0,0,0,0,0,0,0,0,0,0,0,0,0,0,0,0,0
0,0,4,5,5,5,5,5,5,5,0,0,0,0,0,0,0,0,0,0,0,0,0,0,0,0,0
0,0,0,0,0,0,0,0,5,5,0,0,0,0,0,0,0,0,0,0,0,0,5,5,0,0,0
0,0,0,0,0,0,0,0,5,5,0,0,0,0,0,0,0,0,4,5,5,5,4,4,0,0,0
0,0,0,0,0,0,0,0,0,0,0,0,0,0,0,0,0,0,0,0,0,0,5,5,0,0,0
0,0,0,0,0,0,0,0,0,0,0,0,0,0,0,0,0,0,5,0,4,8,5,5,0,0,0
0,0,0,0,0,0,0,0,5,5,0,0,0,0,0,0,0,0,5,15,0,12,5,5,0,0,0
0,0,0,0,0,0,0,0,5,5,5,5,5,0,0,5,5,5,4,5,5,5,5,5,0,0,0
0,0,0,4,5,5,5,5,4,5,5,5,5,0,0,5,5,5,4,5,5,5,5,4,0,0,0
0,0,0,5,2,2,2,2,5,2,7,0,0,0,0,0,0,0,0,0,0,0,0,0,0,0,0
0,0,0,5,2,2,2,2,5,2,7,0,0,0,0,0,0,0,0,0,0,0,0,0,0,0,0
0,0,0,5,2,2,2,2,5,2,7,0,0,0,0,0,0,0,0,0,0,0,0,0,0,0,0
0,0,0,5,2,2,2,2,5,2,7,0,0,0,0,0,0,0,0,0,0,0,0,0,0,0,0
0,0,0,4,5,5,5,5,4,5,5,10,0,0,0,0,0,0,0,0,0,0,0,0,0,0,0
0,0,0,0,0,0,0,0,0,0,0,0,0,0,0,0,0,0,0,0,0,0,0,0,0,0,0
0,0,0,0,0,0,0,0,0,0,0,0,0,0,0,0,0,0,0,0,0,0,0,0,0,0,0
:endlayer
layer: 8
0,0,0,0,0,0,0,0,0,0,0,0,0,0,0,0,0,0,0,0,0,0,0,0,0,0,0
0,0,0,0,0,0,0,0,0,0,0,0,0,0,0,0,0,0,0,0,0,0,0,0,0,0,0
0,0,0,0,0,0,0,0,4,4,5,5,5,5,5,5,5,16,16,5,5,5,4,4,0,0,0
0,0,0,0,0,0,0,0,4,5,4,5,5,5,5,5,5,17,17,5,5,4,5,4,0,0,0
0,0,0,0,0,0,0,0,5,4,0,0,0,0,0,0,0,0,0,0,0,0,4,5,0,0,0
0,0,0,0,0,0,0,0,5,5,0,0,0,0,0,0,0,0,0,0,0,0,5,5,0,0,0
0,0,0,0,0,0,0,0,5,5,0,0,0,0,0,0,0,0,0,0,0,0,5,5,0,0,0
0,0,4,4,5,5,5,5,5,4,0,0,0,0,0,0,0,0,0,0,0,0,4,4,0,0,0
0,0,4,5,4,5,5,5,4,5,4,5,5,5,5,5,5,5,5,5,5,4,5,4,0,0,0
0,0,5,4,0,0,0,0,0,4,0,0,0,0,0,0,0,0,0,0,0,0,4,4,0,0,0
0,0,5,5,0,0,0,0,0,5,0,0,0,0,0,0,0,0,0,0,0,0,5,5,0,0,0
0,0,5,5,0,0,0,0,0,5,0,0,0,0,0,0,0,0,0,0,0,0,5,5,0,0,0
0,0,5,5,0,0,0,0,0,5,0,0,0,0,0,0,0,0,0,0,0,0,5,5,0,0,0
0,0,5,4,0,0,0,0,0,4,0,0,0,0,0,0,0,0,0,0,0,0,5,5,0,0,0
0,0,4,5,4,5,5,5,4,4,0,0,0,0,0,0,0,0,0,0,0,0,18,19,0,0,0
0,0,4,4,5,5,5,5,5,4,0,0,0,0,0,0,0,0,0,0,0,0,18,19,0,0,0
0,0,0,0,0,0,0,0,5,5,0,0,0,0,0,0,0,0,0,0,0,0,4,4,0,0,0
0,0,0,0,0,0,0,0,5,5,0,0,0,0,0,0,0,0,4,4,5,4,4,4,0,0,0
0,0,0,0,0,0,0,0,18,19,0,0,0,0,0,0,0,0,4,0,0,0,4,4,0,0,0
0,0,0,0,0,0,0,0,18,19,0,0,0,0,0,0,0,0,5,0,4,0,5,5,0,0,0
0,0,0,0,0,0,0,0,5,4,0,0,0,0,0,0,0,0,4,12,10,0,4,5,0,0,0
0,0,0,0,0,0,0,0,4,5,4,5,5,16,16,5,5,4,4,4,5,4,5,4,0,0,0
0,0,0,4,4,5,5,4,4,4,5,5,5,17,17,5,5,4,4,4,5,5,4,4,0,0,0
0,0,0,4,2,2,2,2,4,7,0,0,0,0,0,0,0,0,0,0,0,0,0,0,0,0,0
0,0,0,5,2,2,2,2,5,7,0,0,0,0,0,0,0,0,0,0,0,0,0,0,0,0,0
0,0,0,5,2,2,2,2,5,7,0,0,0,0,0,0,0,0,0,0,0,0,0,0,0,0,0
0,0,0,4,2,2,2,2,4,7,0,0,0,0,0,0,0,0,0,0,0,0,0,0,0,0,0
0,0,0,4,4,5,5,4,4,4,10,0,0,0,0,0,0,0,0,0,0,0,0,0,0,0,0
0,0,0,0,0,0,0,0,0,0,0,0,0,0,0,0,0,0,0,0,0,0,0,0,0,0,0
0,0,0,0,0,0,0,0,0,0,0,0,0,0,0,0,0,0,0,0,0,0,0,0,0,0,0
:endlayer
layer: 9
0,0,0,0,0,0,0,0,0,0,0,0,0,0,0,0,0,0,0,0,0,0,0,0,0,0,0
0,0,0,0,0,0,0,0,0,0,0,0,0,0,0,0,0,0,0,0,0,0,0,0,0,0,0
0,0,0,0,0,0,0,0,4,5,5,5,5,5,5,5,5,5,5,5,5,5,5,4,0,0,0
0,0,0,0,0,0,0,0,5,5,5,5,5,5,5,5,5,5,5,5,5,5,5,5,0,0,0
0,0,0,0,0,0,0,0,5,5,0,0,0,0,0,0,0,0,0,0,0,0,5,5,0,0,0
0,0,0,0,0,0,0,0,5,5,0,0,0,0,0,0,0,0,0,0,0,0,5,5,0,0,0
0,0,0,0,0,0,0,0,5,5,0,0,0,0,0,0,0,0,0,0,0,0,5,5,0,0,0
0,0,4,5,5,5,5,5,5,5,0,0,0,0,0,0,0,0,0,0,0,0,5,5,0,0,0
0,0,5,5,5,5,5,5,5,5,5,5,5,5,5,5,5,5,5,5,5,5,5,4,0,0,0
0,0,5,5,0,0,0,0,0,5,0,0,0,0,0,0,0,0,0,0,0,0,5,5,0,0,0
0,0,5,5,0,0,0,0,0,5,0,0,0,0,0,0,0,0,0,0,0,0,5,5,0,0,0
0,0,5,5,0,0,0,0,0,5,0,0,0,0,0,0,0,0,0,0,0,0,5,5,0,0,0
0,0,5,5,0,0,0,0,0,5,0,0,0,0,0,0,0,0,0,0,0,0,5,5,0,0,0
0,0,5,5,0,0,0,0,0,5,0,0,0,0,0,0,0,0,0,0,0,0,5,5,0,0,0
0,0,5,5,5,5,5,5,5,4,0,0,0,0,0,0,0,0,0,0,0,0,5,5,0,0,0
0,0,4,5,5,5,5,5,5,5,0,0,0,0,0,0,0,0,0,0,0,0,5,5,0,0,0
0,0,0,18,17,17,17,17,5,5,0,0,0,0,0,0,0,0,0,0,0,0,5,5,0,0,0
0,0,0,0,0,0,0,0,5,5,0,0,0,0,0,0,0,0,4,5,5,5,4,4,0,0,0
0,0,0,0,0,0,0,0,5,5,0,0,0,0,0,0,0,0,5,12,0,14,5,5,0,0,0
0,0,0,0,0,0,0,0,5,5,0,0,0,0,0,0,0,0,5,13,4,0,5,5,0,0,0
0,0,0,0,0,0,0,0,5,5,0,0,0,0,0,0,0,0,5,0,0,0,5,5,0,0,0
0,0,0,18,16,16,16,16,5,5,5,5,5,5,5,5,5,5,4,5,5,5,5,5,0,0,0
0,0,0,5,2,2,2,2,4,5,5,5,5,5,5,5,5,5,4,5,5,5,5,4,0,0,0
0,0,0,4,2,2,2,2,7,0,0,0,0,0,0,0,0,0,0,0,0,0,0,0,0,0,0
0,0,0,5,2,2,2,2,7,0,0,0,0,0,0,0,0,0,0,0,0,0,0,0,0,0,0
0,0,0,5,2,2,2,2,7,0,0,0,0,0,0,0,0,0,0,0,0,0,0,0,0,0,0
0,0,0,5,2,2,2,2,7,0,0,0,0,0,0,0,0,0,0,0,0,0,0,0,0,0,0
0,0,0,4,5,5,5,5,4,10,0,0,0,0,0,0,0,0,0,0,0,0,0,0,0,0,0
0,0,0,0,0,0,0,0,0,0,0,0,0,0,0,0,0,0,0,0,0,0,0,0,0,0,0
0,0,0,0,0,0,0,0,0,0,0,0,0,0,0,0,0,0,0,0,0,0,0,0,0,0,0
:endlayer
layer: 10
0,0,0,0,0,0,0,0,0,0,0,0,0,0,0,0,0,0,0,0,0,0,0,0,0,0,0
0,0,0,0,0,0,0,0,0,0,0,0,0,0,0,0,0,0,0,0,0,0,0,0,0,0,0
0,0,0,0,0,0,0,0,4,4,5,5,5,5,5,5,5,5,5,5,5,5,4,4,0,0,0
0,0,0,0,0,0,0,0,4,5,4,5,5,5,5,5,5,5,5,5,5,4,5,4,0,0,0
0,0,0,0,0,0,0,0,5,4,20,20,20,20,20,20,20,20,20,20,20,20,4,5,0,0,0
0,0,0,0,0,0,0,0,5,5,20,20,20,20,20,20,20,20,20,20,20,20,5,5,0,0,0
0,0,0,0,0,0,0,0,5,5,20,20,20,20,20,20,20,20,20,20,20,20,5,5,0,0,0
0,0,4,4,5,5,5,5,5,4,20,20,20,20,20,20,20,20,20,20,20,20,4,4,0,0,0
0,0,4,5,4,5,5,5,4,5,4,5,5,5,5,5,5,5,5,5,5,4,5,4,0,0,0
0,0,5,4,20,20,20,20,20,4,20,20,20,20,20,20,20,20,20,20,20,20,4,4,0,0,0
0,0,5,5,20,20,20,20,20,5,20,20,20,20,20,20,20,20,20,20,20,20,5,5,0,0,0
0,0,5,5,20,20,20,20,20,5,20,20,20,20,20,20,20,20,20,20,20,20,5,5,0,0,0
0,0,5,5,20,20,20,20,20,5,20,20,20,20,20,20,20,20,20,20,20,20,5,5,0,0,0
0,0,5,4,20,20,20,20,20,4,20,20,20,20,20,20,20,20,20,20,20,20,5,5,0,0,0
0,0,4,5,5,5,5,5,4,4,20,20,20,20,20,20,20,20,20,20,20,20,5,5,0,0,0
0,0,4,4,5,5,5,5,5,4,20,20,20,20,20,20,20,20,20,20,20,20,5,5,0,0,0
0,0,0,5,20,20,20,20,5,5,20,20,20,20,20,20,20,20,20,20,20,20,4,4,0,0,0
0,0,0,0,20,20,20,20,5,5,20,20,20,20,20,20,20,20,4,4,5,4,4,4,0,0,0
0,0,0,0,20,20,20,20,5,5,20,20,20,20,20,20,20,20,4,0,11,12,4,4,0,0,0
0,0,0,0,20,20,20,20,5,5,20,20,20,20,20,20,20,20,5,0,4,0,5,5,0,0,0
0,0,0,0,20,20,20,20,5,4,20,20,20,20,20,20,20,20,4,0,0,0,4,5,0,0,0
0,0,0,5,20,20,20,20,4,5,4,5,5,5,5,5,5,4,4,4,5,4,5,4,0,0,0
0,0,0,4,21,21,21,21,4,4,5,5,5,5,5,5,5,4,4,4,5,5,4,4,0,0,0
0,0,0,0,0,0,0,0,0,0,0,0,0,0,0,0,0,0,0,0,0,0,0,0,0,0,0
0,0,0,0,0,0,0,0,0,0,0,0,0,0,0,0,0,0,0,0,0,0,0,0,0,0,0
0,0,0,0,0,0,0,0,0,0,0,0,0,0,0,0,0,0,0,0,0,0,0,0,0,0,0
0,0,0,0,0,0,0,0,0,0,0,0,0,0,0,0,0,0,0,0,0,0,0,0,0,0,0
0,0,0,4,0,0,0,0,4,0,0,0,0,0,0,0,0,0,0,0,0,0,0,0,0,0,0
0,0,0,0,0,0,0,0,0,0,0,0,0,0,0,0,0,0,0,0,0,0,0,0,0,0,0
0,0,0,0,0,0,0,0,0,0,0,0,0,0,0,0,0,0,0,0,0,0,0,0,0,0,0
:endlayer
layer: 11
0,0,0,0,0,0,0,0,0,0,0,0,0,0,0,0,0,0,0,0,0,0,0,0,0,0,0
0,0,0,0,0,0,0,0,0,0,0,0,0,0,0,0,0,0,0,0,0,0,0,0,0,0,0
0,0,0,0,0,0,0,0,4,5,5,5,8,8,5,5,5,5,8,8,5,5,5,4,0,0,0
0,0,0,0,0,0,0,0,5,5,5,5,0,0,5,5,5,5,0,0,5,5,5,5,0,0,0
0,0,0,0,0,0,0,0,5,5,0,0,0,0,0,0,0,0,0,0,0,0,5,5,0,0,0
0,0,0,0,0,0,0,0,5,5,0,0,9,0,0,0,0,0,0,9,0,0,5,5,0,0,0
0,0,0,0,0,0,0,0,5,5,0,0,0,0,0,0,0,0,0,0,0,0,5,5,0,0,0
0,0,4,5,5,5,8,5,5,5,0,0,0,0,0,0,0,0,0,0,0,0,5,5,0,0,0
0,0,5,5,5,5,0,5,5,5,5,5,5,5,5,5,0,5,5,5,5,5,5,4,0,0,0
0,0,5,5,0,0,0,0,0,5,0,0,0,0,0,0,0,0,0,0,0,0,0,10,0,0,0
0,0,5,5,0,0,0,0,0,5,0,0,0,0,0,0,0,0,0,0,0,0,0,10,0,0,0
0,0,11,0,0,0,0,0,0,0,0,0,9,0,0,0,0,0,0,9,0,0,4,5,0,0,0
0,0,5,5,0,0,0,0,0,5,0,0,0,0,0,0,0,0,0,0,0,0,9,5,0,0,0
0,0,5,5,0,0,0,0,5,5,0,0,0,0,0,0,0,0,0,0,0,0,9,5,0,0,0
0,0,5,4,0,0,0,0,5,4,0,0,0,0,0,9,0,0,0,9,0,0,4,5,0,0,0
0,0,4,5,0,0,0,0,5,5,0,0,0,0,0,0,0,0,0,0,0,0,0,10,0,0,0
0,0,0,5,0,0,0,0,5,5,0,0,0,0,0,0,0,0,0,0,0,0,0,10,0,0,0
0,0,0,0,0,0,0,0,5,5,0,0,0,0,0,0,0,0,4,5,5,0,4,4,0,0,0
0,0,0,0,0,0,0,0,5,5,0,0,9,0,0,9,0,0,5,0,0,0,5,5,0,0,0
0,0,0,0,0,0,0,0,5,5,0,0,0,0,0,0,0,0,5,0,4,8,5,5,0,0,0
0,0,0,0,0,0,0,0,5,5,0,0,0,0,0,0,0,0,5,15,0,12,5,5,0,0,0
0,0,0,0,0,0,0,0,5,5,5,5,5,0,0,5,5,5,4,5,5,5,5,5,0,0,0
0,0,0,9,0,0,0,0,4,5,5,5,5,13,13,5,5,5,4,5,5,5,5,4,0,0,0
0,0,0,0,0,0,0,0,0,0,0,0,0,0,0,0,0,0,0,0,0,0,0,0,0,0,0
0,0,0,0,0,0,0,0,0,0,0,0,0,0,0,0,0,0,0,0,0,0,0,0,0,0,0
0,0,0,0,0,0,0,0,0,0,0,0,0,0,0,0,0,0,0,0,0,0,0,0,0,0,0
0,0,0,0,0,0,0,0,0,0,0,0,0,0,0,0,0,0,0,0,0,0,0,0,0,0,0
0,0,0,9,0,0,0,0,9,0,0,0,0,0,0,0,0,0,0,0,0,0,0,0,0,0,0
0,0,0,0,0,0,0,0,0,0,0,0,0,0,0,0,0,0,0,0,0,0,0,0,0,0,0
0,0,0,0,0,0,0,0,0,0,0,0,0,0,0,0,0,0,0,0,0,0,0,0,0,0,0
:endlayer
layer: 12
0,0,0,0,0,0,0,0,0,0,0,0,0,0,0,0,0,0,0,0,0,0,0,0,0,0,0
0,0,0,0,0,0,0,0,0,0,0,0,0,0,0,0,0,0,0,0,0,0,0,0,0,0,0
0,0,0,0,0,0,0,0,4,4,5,5,0,0,5,5,5,5,0,0,5,5,4,4,0,0,0
0,0,0,0,0,0,0,0,4,5,4,5,0,0,5,5,5,5,0,0,5,4,5,4,0,0,0
0,0,0,0,0,0,0,0,5,4,0,0,0,0,0,0,0,0,0,0,0,0,4,5,0,0,0
0,0,0,0,0,0,0,0,5,5,0,0,0,0,0,0,0,0,0,0,0,0,5,5,0,0,0
0,0,0,0,0,0,0,0,5,5,0,0,0,0,0,0,0,0,0,0,0,0,5,5,0,0,0
0,0,4,4,5,5,0,5,5,4,0,0,0,0,0,0,0,0,0,0,0,0,4,4,0,0,0
0,0,4,5,4,5,0,5,4,5,4,5,5,5,5,5,0,5,5,5,5,4,5,4,0,0,0
0,0,5,4,0,0,0,14,0,4,0,0,0,0,0,0,0,0,0,0,0,0,0,0,0,0,0
0,0,5,5,22,0,0,0,0,5,0,0,0,0,0,0,0,0,0,0,0,0,0,0,0,0,0
0,0,0,0,0,0,0,0,0,0,0,0,0,0,0,0,0,0,0,0,0,0,4,5,0,0,0
0,0,5,5,0,0,0,0,0,5,0,0,0,0,0,0,0,0,0,0,0,0,0,23,0,0,0
0,0,5,4,0,0,0,0,5,4,0,0,0,0,0,0,0,0,0,0,0,0,0,23,0,0,0
0,0,4,4,0,0,0,0,4,4,0,0,0,0,0,0,0,0,0,0,0,0,4,5,0,0,0
0,0,4,4,22,0,0,24,5,4,0,0,0,0,0,0,0,0,0,0,0,0,0,0,0,0,0
0,0,0,0,0,0,0,0,5,5,0,0,0,0,0,0,0,0,0,0,0,0,0,0,0,0,0
0,0,0,0,0,0,0,0,5,5,0,0,0,0,0,0,0,0,4,4,5,0,4,4,0,0,0
0,0,0,0,0,0,0,0,5,5,0,0,0,0,0,0,0,0,4,0,0,0,4,4,0,0,0
0,0,0,0,0,0,0,0,5,5,0,0,0,0,0,0,0,0,5,0,4,0,5,5,0,0,0
0,0,0,0,0,0,0,0,5,4,0,0,0,0,0,0,0,0,4,12,10,0,4,5,0,0,0
0,0,0,0,0,0,0,0,4,5,4,5,5,0,0,5,5,4,4,4,5,4,5,4,0,0,0
0,0,0,0,0,0,0,0,4,4,5,5,5,0,0,5,5,4,4,4,5,5,4,4,0,0,0
0,0,0,0,0,0,0,0,0,0,0,0,0,0,0,0,0,0,0,0,0,0,0,0,0,0,0
0,0,0,0,0,0,0,0,0,0,0,0,0,0,0,0,0,0,0,0,0,0,0,0,0,0,0
0,0,0,0,0,0,0,0,0,0,0,0,0,0,0,0,0,0,0,0,0,0,0,0,0,0,0
0,0,0,0,0,0,0,0,0,0,0,0,0,0,0,0,0,0,0,0,0,0,0,0,0,0,0
0,0,0,0,0,0,0,0,0,0,0,0,0,0,0,0,0,0,0,0,0,0,0,0,0,0,0
0,0,0,0,0,0,0,0,0,0,0,0,0,0,0,0,0,0,0,0,0,0,0,0,0,0,0
0,0,0,0,0,0,0,0,0,0,0,0,0,0,0,0,0,0,0,0,0,0,0,0,0,0,0
:endlayer
layer: 13
0,0,0,0,0,0,0,0,0,0,0,0,0,0,0,0,0,0,0,0,0,0,0,0,0,0,0
0,0,0,0,0,0,0,0,0,0,0,0,0,0,0,0,0,0,0,0,0,0,0,0,0,0,0
0,0,0,0,0,0,0,0,4,5,5,5,16,16,5,5,5,5,16,16,5,5,5,4,0,0,0
0,0,0,0,0,0,0,0,5,5,5,5,17,17,5,5,5,5,17,17,5,5,5,5,0,0,0
0,0,0,0,0,0,0,0,5,5,0,0,0,0,0,0,0,0,0,0,0,0,5,5,0,0,0
0,0,0,0,0,0,0,0,5,5,0,0,0,0,0,0,0,0,0,0,0,0,5,5,0,0,0
0,0,0,0,0,0,0,0,5,5,0,0,0,0,0,0,0,0,0,0,0,0,5,5,0,0,0
0,0,4,5,5,5,16,5,5,5,0,0,0,0,0,0,0,0,0,0,0,0,5,5,0,0,0
0,0,5,5,5,5,17,5,5,5,5,5,5,5,5,5,5,5,5,5,5,5,5,4,0,0,0
0,0,5,5,0,0,0,0,0,5,0,0,0,0,0,0,0,0,0,0,0,0,18,19,0,0,0
0,0,5,5,0,0,0,0,0,5,0,0,0,0,0,0,0,0,0,0,0,0,18,19,0,0,0
0,0,18,19,0,0,0,0,0,5,0,0,0,0,0,0,0,0,0,0,0,0,4,5,0,0,0
0,0,5,5,0,0,0,0,0,5,0,0,0,0,0,0,0,0,0,0,0,0,4,5,0,0,0
0,0,5,5,0,0,0,0,5,5,0,0,0,0,0,0,0,0,0,0,0,0,4,5,0,0,0
0,0,5,4,0,0,0,0,5,4,0,0,0,0,0,0,0,0,0,0,0,0,4,5,0,0,0
0,0,4,5,0,0,0,0,5,5,0,0,0,0,0,0,0,0,0,0,0,0,18,19,0,0,0
0,0,0,0,0,0,0,0,5,5,0,0,0,0,0,0,0,0,0,0,0,0,18,19,0,0,0
0,0,0,0,0,0,0,0,5,5,0,0,0,0,0,0,0,0,4,5,5,5,4,4,0,0,0
0,0,0,0,0,0,0,0,5,5,0,0,0,0,0,0,0,0,5,12,0,0,5,5,0,0,0
0,0,0,0,0,0,0,0,5,5,0,0,0,0,0,0,0,0,5,13,4,0,5,5,0,0,0
0,0,0,0,0,0,0,0,5,5,0,0,0,0,0,0,0,0,5,0,0,0,5,5,0,0,0
0,0,0,0,0,0,0,0,5,5,5,5,5,16,16,5,5,5,4,5,5,5,5,5,0,0,0
0,0,0,0,0,0,0,0,4,5,5,5,5,17,17,5,5,5,4,5,5,5,5,4,0,0,0
0,0,0,0,0,0,0,0,0,0,0,0,0,0,0,0,0,0,0,0,0,0,0,0,0,0,0
0,0,0,0,0,0,0,0,0,0,0,0,0,0,0,0,0,0,0,0,0,0,0,0,0,0,0
0,0,0,0,0,0,0,0,0,0,0,0,0,0,0,0,0,0,0,0,0,0,0,0,0,0,0
0,0,0,0,0,0,0,0,0,0,0,0,0,0,0,0,0,0,0,0,0,0,0,0,0,0,0
0,0,0,0,0,0,0,0,0,0,0,0,0,0,0,0,0,0,0,0,0,0,0,0,0,0,0
0,0,0,0,0,0,0,0,0,0,0,0,0,0,0,0,0,0,0,0,0,0,0,0,0,0,0
0,0,0,0,0,0,0,0,0,0,0,0,0,0,0,0,0,0,0,0,0,0,0,0,0,0,0
:endlayer
layer: 14
0,0,0,0,0,0,0,0,0,0,0,0,0,0,0,0,0,0,0,0,0,0,0,0,0,0,0
0,0,0,0,0,0,0,0,0,0,0,0,0,0,0,0,0,0,0,0,0,0,0,0,0,0,0
0,0,0,0,0,0,0,0,4,4,5,5,5,5,5,5,5,5,5,5,5,5,4,4,0,0,0
0,0,0,0,0,0,0,0,4,5,4,5,5,5,5,5,5,5,5,5,5,4,5,4,0,0,0
0,0,0,0,0,0,0,0,5,4,0,0,0,0,0,0,0,0,0,0,0,0,4,5,0,0,0
0,0,0,0,0,0,0,0,5,5,0,0,0,0,0,0,0,0,0,0,0,0,5,5,0,0,0
0,0,0,0,0,0,0,0,5,5,0,0,0,0,0,0,0,0,0,0,0,0,5,5,0,0,0
0,0,4,4,5,5,5,5,5,4,0,0,0,0,0,0,0,0,0,0,0,0,4,4,0,0,0
0,0,4,5,4,5,5,5,4,5,4,5,5,5,5,5,5,5,5,5,5,4,5,4,0,0,0
0,0,5,4,0,0,0,0,0,4,0,0,0,0,0,0,0,0,0,0,0,0,4,4,0,0,0
0,0,5,5,0,0,0,0,0,5,0,0,0,0,0,0,0,0,0,0,0,0,5,5,0,0,0
0,0,5,5,0,0,0,0,0,5,0,0,0,0,0,0,0,0,0,0,0,0,5,5,0,0,0
0,0,5,5,0,0,0,0,0,5,0,0,0,0,0,0,0,0,0,0,0,0,5,5,0,0,0
0,0,5,4,0,0,0,0,5,4,0,0,0,0,0,0,0,0,0,0,0,0,5,5,0,0,0
0,0,4,4,0,0,0,0,4,4,0,0,0,0,0,0,0,0,0,0,0,0,5,5,0,0,0
0,0,4,4,0,0,0,0,5,4,0,0,0,0,0,0,0,0,0,0,0,0,5,5,0,0,0
0,0,0,0,0,0,0,0,5,5,0,0,0,0,0,0,0,0,0,0,0,0,4,4,0,0,0
0,0,0,0,0,0,0,0,5,5,0,0,0,0,0,0,0,0,4,4,5,4,4,4,0,0,0
0,0,0,0,0,0,0,0,5,5,0,0,0,0,0,0,0,0,4,0,11,12,4,4,0,0,0
0,0,0,0,0,0,0,0,5,5,0,0,0,0,0,0,0,0,5,0,4,0,5,5,0,0,0
0,0,0,0,0,0,0,0,5,4,0,0,0,0,0,0,0,0,4,0,0,15,4,5,0,0,0
0,0,0,0,0,0,0,0,4,5,4,5,5,5,5,5,5,4,4,4,5,4,5,4,0,0,0
0,0,0,0,0,0,0,0,4,4,5,5,5,5,5,5,5,4,4,4,5,5,4,4,0,0,0
0,0,0,0,0,0,0,0,0,0,0,0,0,0,0,0,0,0,0,0,0,0,0,0,0,0,0
0,0,0,0,0,0,0,0,0,0,0,0,0,0,0,0,0,0,0,0,0,0,0,0,0,0,0
0,0,0,0,0,0,0,0,0,0,0,0,0,0,0,0,0,0,0,0,0,0,0,0,0,0,0
0,0,0,0,0,0,0,0,0,0,0,0,0,0,0,0,0,0,0,0,0,0,0,0,0,0,0
0,0,0,0,0,0,0,0,0,0,0,0,0,0,0,0,0,0,0,0,0,0,0,0,0,0,0
0,0,0,0,0,0,0,0,0,0,0,0,0,0,0,0,0,0,0,0,0,0,0,0,0,0,0
0,0,0,0,0,0,0,0,0,0,0,0,0,0,0,0,0,0,0,0,0,0,0,0,0,0,0
:endlayer
layer: 15
0,0,0,0,0,0,0,0,0,0,0,0,0,0,0,0,0,0,0,0,0,0,0,0,0,0,0
0,0,0,0,0,0,0,0,0,0,0,0,0,0,0,0,0,0,0,0,0,0,0,0,0,0,0
0,0,0,0,0,0,0,0,4,5,5,5,5,5,5,5,5,5,5,5,5,5,5,4,0,0,0
0,0,0,0,0,0,0,0,5,5,5,5,5,5,5,5,5,5,5,5,5,5,5,5,0,0,0
0,0,0,0,0,0,0,0,5,5,20,20,20,20,20,20,20,20,20,20,20,20,5,5,0,0,0
0,0,0,0,0,0,0,0,5,5,20,20,20,20,20,20,20,20,20,20,20,20,5,5,0,0,0
0,0,0,0,0,0,0,0,5,5,20,20,20,20,20,20,20,20,20,20,20,20,5,5,0,0,0
0,0,4,5,5,5,5,5,5,5,20,20,20,20,20,20,20,20,20,20,20,20,5,5,0,0,0
0,0,5,5,5,5,5,5,5,5,5,5,5,5,5,5,5,5,5,5,5,5,5,4,0,0,0
0,0,5,5,20,20,20,20,20,5,20,20,20,20,20,20,20,20,20,20,20,20,5,5,0,0,0
0,0,5,5,20,20,20,20,20,5,20,20,20,20,20,20,20,20,20,20,20,20,5,5,0,0,0
0,0,5,5,20,20,20,20,20,5,20,20,20,20,20,20,20,20,20,20,20,20,5,5,0,0,0
0,0,5,5,20,20,20,20,20,5,20,20,20,20,20,20,20,20,20,20,20,20,5,5,0,0,0
0,0,5,5,25,25,25,25,25,5,20,20,20,20,20,20,20,20,20,20,20,20,5,5,0,0,0
0,0,5,5,5,5,5,5,5,4,20,20,20,20,20,20,20,20,20,20,20,20,5,5,0,0,0
0,0,4,5,5,5,5,5,5,5,20,20,20,20,20,20,20,20,20,20,20,20,5,5,0,0,0
0,0,0,0,0,0,0,0,5,5,20,20,20,20,20,20,20,20,20,20,20,20,5,5,0,0,0
0,0,0,0,0,0,0,0,5,5,20,20,20,20,20,20,20,20,4,5,5,5,4,4,0,0,0
0,0,0,0,0,0,0,0,5,5,20,20,20,20,20,20,20,20,5,0,0,0,5,5,0,0,0
0,0,0,0,0,0,0,0,5,5,20,20,20,20,20,20,20,20,5,0,4,8,5,5,0,0,0
0,0,0,0,0,0,0,0,5,5,20,20,20,20,20,20,20,20,5,0,0,12,5,5,0,0,0
0,0,0,0,0,0,0,0,5,5,5,5,5,5,5,5,5,5,4,5,5,5,5,5,0,0,0
0,0,0,0,0,0,0,0,4,5,5,5,5,5,5,5,5,5,4,5,5,5,5,4,0,0,0
0,0,0,0,0,0,0,0,0,0,0,0,0,0,0,0,0,0,0,0,0,0,0,0,0,0,0
0,0,0,0,0,0,0,0,0,0,0,0,0,0,0,0,0,0,0,0,0,0,0,0,0,0,0
0,0,0,0,0,0,0,0,0,0,0,0,0,0,0,0,0,0,0,0,0,0,0,0,0,0,0
0,0,0,0,0,0,0,0,0,0,0,0,0,0,0,0,0,0,0,0,0,0,0,0,0,0,0
0,0,0,0,0,0,0,0,0,0,0,0,0,0,0,0,0,0,0,0,0,0,0,0,0,0,0
0,0,0,0,0,0,0,0,0,0,0,0,0,0,0,0,0,0,0,0,0,0,0,0,0,0,0
0,0,0,0,0,0,0,0,0,0,0,0,0,0,0,0,0,0,0,0,0,0,0,0,0,0,0
:endlayer
layer: 16
0,0,0,0,0,0,0,0,0,0,0,0,0,0,0,0,0,0,0,0,0,0,0,0,0,0,0
0,0,0,0,0,0,0,0,0,0,0,0,0,0,0,0,0,0,0,0,0,0,0,0,0,0,0
0,0,0,0,0,0,0,0,4,4,5,5,8,8,5,5,5,5,8,8,5,5,4,4,0,0,0
0,0,0,0,0,0,0,0,4,5,4,5,0,0,5,5,5,5,0,0,5,4,5,4,0,0,0
0,0,0,0,0,0,0,0,5,4,0,0,0,0,0,0,0,0,0,0,0,0,4,5,0,0,0
0,0,0,0,0,0,0,0,5,5,0,0,0,0,0,0,0,0,0,0,0,0,5,5,0,0,0
0,0,0,0,0,0,0,0,5,5,0,0,9,0,0,0,0,0,0,9,0,0,5,5,0,0,0
0,0,4,4,5,5,5,5,5,4,0,0,0,0,0,0,0,0,0,0,0,0,4,4,0,0,0
0,0,4,5,4,5,5,5,4,5,4,5,5,5,5,5,0,5,5,5,5,4,5,4,0,0,0
0,0,5,4,0,0,0,0,0,4,0,0,0,0,0,0,0,0,0,0,0,0,0,10,0,0,0
0,0,26,0,0,0,0,0,0,5,0,0,0,0,0,0,0,0,0,0,0,0,0,10,0,0,0
0,0,27,0,0,0,9,0,0,0,0,0,9,0,0,0,0,0,0,9,0,0,5,5,0,0,0
0,0,26,0,0,0,0,0,0,5,0,0,0,0,0,0,0,0,0,0,0,0,9,5,0,0,0
0,0,5,4,0,0,0,0,0,4,0,0,0,0,0,0,0,0,0,0,0,0,9,5,0,0,0
0,0,4,5,4,5,5,5,4,4,0,0,0,0,0,9,0,0,0,9,0,0,5,5,0,0,0
0,0,4,4,5,5,5,5,5,4,0,0,0,0,0,0,0,0,0,0,0,0,0,10,0,0,0
0,0,0,0,0,0,0,0,5,5,0,0,0,0,0,0,0,0,0,0,0,0,0,10,0,0,0
0,0,0,0,0,0,0,0,5,5,0,0,0,0,0,0,0,0,4,4,5,4,4,4,0,0,0
0,0,0,0,0,0,0,0,5,5,0,0,9,0,0,9,0,0,4,0,0,0,4,4,0,0,0
0,0,0,0,0,0,0,0,5,5,0,0,0,0,0,0,0,0,5,0,4,0,5,5,0,0,0
0,0,0,0,0,0,0,0,5,4,0,0,0,0,0,0,0,0,11,12,10,0,4,5,0,0,0
0,0,0,0,0,0,0,0,4,5,4,0,0,5,5,0,0,4,4,4,5,4,5,4,0,0,0
0,0,0,0,0,0,0,0,4,4,5,13,13,5,5,13,13,4,4,4,5,5,4,4,0,0,0
0,0,0,0,0,0,0,0,0,0,0,0,0,0,0,0,0,0,0,0,0,0,0,0,0,0,0
0,0,0,0,0,0,0,0,0,0,0,0,0,0,0,0,0,0,0,0,0,0,0,0,0,0,0
0,0,0,0,0,0,0,0,0,0,0,0,0,0,0,0,0,0,0,0,0,0,0,0,0,0,0
0,0,0,0,0,0,0,0,0,0,0,0,0,0,0,0,0,0,0,0,0,0,0,0,0,0,0
0,0,0,0,0,0,0,0,0,0,0,0,0,0,0,0,0,0,0,0,0,0,0,0,0,0,0
0,0,0,0,0,0,0,0,0,0,0,0,0,0,0,0,0,0,0,0,0,0,0,0,0,0,0
0,0,0,0,0,0,0,0,0,0,0,0,0,0,0,0,0,0,0,0,0,0,0,0,0,0,0
:endlayer
layer: 17
0,0,0,0,0,0,0,0,0,0,0,0,0,0,0,0,0,0,0,0,0,0,0,0,0,0,0
0,0,0,0,0,0,0,0,0,0,0,0,0,0,0,0,0,0,0,0,0,0,0,0,0,0,0
0,0,0,0,0,0,0,0,4,5,5,5,0,0,5,5,5,5,0,0,5,5,5,4,0,0,0
0,0,0,0,0,0,0,0,5,5,5,5,0,0,5,5,5,5,0,0,5,5,5,5,0,0,0
0,0,0,0,0,0,0,0,5,5,0,0,0,0,0,0,0,0,0,0,0,0,5,5,0,0,0
0,0,0,0,0,0,0,0,5,5,0,0,0,0,0,0,0,0,0,0,0,0,5,5,0,0,0
0,0,0,0,0,0,0,0,5,5,0,0,0,0,0,0,0,0,0,0,0,0,5,5,0,0,0
0,0,4,5,5,5,5,5,5,5,0,0,0,0,0,0,0,0,0,0,0,0,5,5,0,0,0
0,0,5,5,5,5,5,5,5,5,5,5,5,5,5,5,0,5,5,5,5,5,5,4,0,0,0
0,0,5,5,0,0,0,0,0,5,0,0,0,0,0,0,0,0,0,0,0,0,0,0,0,0,0
0,0,27,0,0,0,0,0,0,5,0,0,0,0,0,0,0,0,0,0,0,0,0,0,0,0,0
0,0,26,0,0,0,0,0,0,0,0,0,0,0,0,0,0,0,0,0,0,0,5,5,0,0,0
0,0,27,0,0,0,0,0,0,5,0,0,0,0,0,0,0,0,0,0,0,0,0,23,0,0,0
0,0,5,5,0,0,0,0,0,5,0,0,0,0,0,0,0,0,0,0,0,0,0,23,0,0,0
0,0,5,5,5,5,5,5,5,4,0,0,0,0,0,0,0,0,0,0,0,0,5,5,0,0,0
0,0,4,5,5,5,5,5,5,5,0,0,0,0,0,0,0,0,0,0,0,0,0,0,0,0,0
0,0,0,0,0,0,0,0,5,5,0,0,0,0,0,0,0,0,0,0,0,0,0,0,0,0,0
0,0,0,0,0,0,0,0,5,5,0,0,0,0,0,0,0,0,4,5,5,5,4,4,0,0,0
0,0,0,0,0,0,0,0,5,5,0,0,0,0,0,0,0,0,5,12,0,24,5,5,0,0,0
0,0,0,0,0,0,0,0,5,5,0,0,0,0,0,0,0,0,5,13,4,0,5,5,0,0,0
0,0,0,0,0,0,0,0,5,5,0,0,0,0,0,0,0,0,0,0,0,0,5,5,0,0,0
0,0,0,0,0,0,0,0,5,5,5,0,0,5,5,0,0,5,4,5,5,5,5,5,0,0,0
0,0,0,0,0,0,0,0,4,5,5,0,0,5,5,0,0,5,4,5,5,5,5,4,0,0,0
0,0,0,0,0,0,0,0,0,0,0,0,0,0,0,0,0,0,0,0,0,0,0,0,0,0,0
0,0,0,0,0,0,0,0,0,0,0,0,0,0,0,0,0,0,0,0,0,0,0,0,0,0,0
0,0,0,0,0,0,0,0,0,0,0,0,0,0,0,0,0,0,0,0,0,0,0,0,0,0,0
0,0,0,0,0,0,0,0,0,0,0,0,0,0,0,0,0,0,0,0,0,0,0,0,0,0,0
0,0,0,0,0,0,0,0,0,0,0,0,0,0,0,0,0,0,0,0,0,0,0,0,0,0,0
0,0,0,0,0,0,0,0,0,0,0,0,0,0,0,0,0,0,0,0,0,0,0,0,0,0,0
0,0,0,0,0,0,0,0,0,0,0,0,0,0,0,0,0,0,0,0,0,0,0,0,0,0,0
:endlayer
layer: 18
0,0,0,0,0,0,0,0,0,0,0,0,0,0,0,0,0,0,0,0,0,0,0,0,0,0,0
0,0,0,0,0,0,0,0,0,0,0,0,0,0,0,0,0,0,0,0,0,0,0,0,0,0,0
0,0,0,0,0,0,0,0,4,4,5,5,16,16,5,5,5,5,16,16,5,5,4,4,0,0,0
0,0,0,0,0,0,0,0,4,5,4,5,17,17,5,5,5,5,17,17,5,4,5,4,0,0,0
0,0,0,0,0,0,0,0,5,4,0,0,0,0,0,0,0,0,0,0,0,0,4,5,0,0,0
0,0,0,0,0,0,0,0,5,5,0,0,0,0,0,0,0,0,0,0,0,0,5,5,0,0,0
0,0,0,0,0,0,0,0,5,5,0,0,0,0,0,0,0,0,0,0,0,0,5,5,0,0,0
0,0,4,4,5,5,5,5,5,4,0,0,0,0,0,0,0,0,0,0,0,0,4,4,0,0,0
0,0,4,5,4,5,5,5,4,5,4,5,5,5,5,5,5,5,5,5,5,4,5,4,0,0,0
0,0,5,4,0,0,0,0,0,4,0,0,0,0,0,0,0,0,0,0,0,0,18,19,0,0,0
0,0,27,0,0,0,0,0,0,5,0,0,0,0,0,0,0,0,0,0,0,0,18,19,0,0,0
0,0,26,0,0,0,0,0,0,5,0,0,0,0,0,0,0,0,0,0,0,0,5,5,0,0,0
0,0,27,0,0,0,0,0,0,5,0,0,0,0,0,0,0,0,0,0,0,0,5,5,0,0,0
0,0,5,4,0,0,0,0,0,4,0,0,0,0,0,0,0,0,0,0,0,0,5,5,0,0,0
0,0,4,5,4,5,5,5,4,4,0,0,0,0,0,0,0,0,0,0,0,0,5,5,0,0,0
0,0,4,4,5,5,5,5,5,4,0,0,0,0,0,0,0,0,0,0,0,0,18,19,0,0,0
0,0,0,0,0,0,0,0,5,5,0,0,0,0,0,0,0,0,0,0,0,0,18,19,0,0,0
0,0,0,0,0,0,0,0,5,5,0,0,0,0,0,0,0,0,4,4,5,4,4,4,0,0,0
0,0,0,0,0,0,0,0,5,5,0,0,0,0,0,0,0,0,4,0,11,12,4,4,0,0,0
0,0,0,0,0,0,0,0,5,5,0,0,0,0,0,0,0,0,5,0,4,0,5,5,0,0,0
0,0,0,0,0,0,0,0,5,4,0,0,0,0,0,0,0,0,0,0,0,0,4,5,0,0,0
0,0,0,0,0,0,0,0,4,5,4,16,16,5,5,16,16,4,4,4,5,4,5,4,0,0,0
0,0,0,0,0,0,0,0,4,4,5,17,17,5,5,17,17,4,4,4,5,5,4,4,0,0,0
0,0,0,0,0,0,0,0,0,0,0,0,0,0,0,0,0,0,0,0,0,0,0,0,0,0,0
0,0,0,0,0,0,0,0,0,0,0,0,0,0,0,0,0,0,0,0,0,0,0,0,0,0,0
0,0,0,0,0,0,0,0,0,0,0,0,0,0,0,0,0,0,0,0,0,0,0,0,0,0,0
0,0,0,0,0,0,0,0,0,0,0,0,0,0,0,0,0,0,0,0,0,0,0,0,0,0,0
0,0,0,0,0,0,0,0,0,0,0,0,0,0,0,0,0,0,0,0,0,0,0,0,0,0,0
0,0,0,0,0,0,0,0,0,0,0,0,0,0,0,0,0,0,0,0,0,0,0,0,0,0,0
0,0,0,0,0,0,0,0,0,0,0,0,0,0,0,0,0,0,0,0,0,0,0,0,0,0,0
:endlayer
layer: 19
0,0,0,0,0,0,0,0,0,0,0,0,0,0,0,0,0,0,0,0,0,0,0,0,0,0,0
0,0,0,0,0,0,0,0,0,0,0,0,0,0,0,0,0,0,0,0,0,0,0,0,0,0,0
0,0,0,0,0,0,0,0,4,5,5,5,5,5,5,5,5,5,5,5,5,5,5,4,0,0,0
0,0,0,0,0,0,0,0,5,5,5,5,5,5,5,5,5,5,5,5,5,5,5,5,0,0,0
0,0,0,0,0,0,0,0,5,5,0,0,0,0,0,0,0,0,0,0,0,0,5,5,0,0,0
0,0,0,0,0,0,0,0,5,5,0,0,0,0,0,0,0,0,0,0,0,0,5,5,0,0,0
0,0,0,0,0,0,0,0,5,5,0,0,0,0,0,0,0,0,0,0,0,0,5,5,0,0,0
0,0,4,5,5,5,5,5,5,5,0,0,0,0,0,0,0,0,0,0,0,0,5,5,0,0,0
0,0,5,5,5,5,5,5,5,5,5,5,5,5,5,5,5,5,5,5,5,5,5,4,0,0,0
0,0,5,5,0,0,0,0,0,5,0,0,0,0,0,0,0,0,0,0,0,0,5,5,0,0,0
0,0,5,17,0,0,0,0,0,5,0,0,0,0,0,0,0,0,0,0,0,0,5,5,0,0,0
0,0,27,0,0,0,0,0,0,5,0,0,0,0,0,0,0,0,0,0,0,0,5,5,0,0,0
0,0,5,16,0,0,0,0,0,5,0,0,0,0,0,0,0,0,0,0,0,0,5,5,0,0,0
0,0,5,5,0,0,0,0,0,5,0,0,0,0,0,0,0,0,0,0,0,0,5,5,0,0,0
0,0,5,5,5,5,5,5,5,4,0,0,0,0,0,0,0,0,0,0,0,0,5,5,0,0,0
0,0,4,5,5,5,5,5,5,5,0,0,0,0,0,0,0,0,0,0,0,0,5,5,0,0,0
0,0,0,0,0,0,0,0,5,5,0,0,0,0,0,0,0,0,0,0,0,0,5,5,0,0,0
0,0,0,0,0,0,0,0,5,5,0,0,0,0,0,0,0,0,4,5,5,5,4,4,0,0,0
0,0,0,0,0,0,0,0,5,5,0,0,0,0,0,0,0,0,5,0,0,0,5,5,0,0,0
0,0,0,0,0,0,0,0,5,5,0,0,0,0,0,0,0,0,5,0,4,8,5,5,0,0,0
0,0,0,0,0,0,0,0,5,5,0,0,0,0,0,0,0,0,5,0,0,12,5,5,0,0,0
0,0,0,0,0,0,0,0,5,5,5,5,5,5,5,5,5,5,4,5,5,5,5,5,0,0,0
0,0,0,0,0,0,0,0,4,5,5,5,5,5,5,5,5,5,4,5,5,5,5,4,0,0,0
0,0,0,0,0,0,0,0,0,0,0,0,0,0,0,0,0,0,0,0,0,0,0,0,0,0,0
0,0,0,0,0,0,0,0,0,0,0,0,0,0,0,0,0,0,0,0,0,0,0,0,0,0,0
0,0,0,0,0,0,0,0,0,0,0,0,0,0,0,0,0,0,0,0,0,0,0,0,0,0,0
0,0,0,0,0,0,0,0,0,0,0,0,0,0,0,0,0,0,0,0,0,0,0,0,0,0,0
0,0,0,0,0,0,0,0,0,0,0,0,0,0,0,0,0,0,0,0,0,0,0,0,0,0,0
0,0,0,0,0,0,0,0,0,0,0,0,0,0,0,0,0,0,0,0,0,0,0,0,0,0,0
0,0,0,0,0,0,0,0,0,0,0,0,0,0,0,0,0,0,0,0,0,0,0,0,0,0,0
:endlayer
layer: 20
0,0,0,0,0,0,0,0,0,0,0,0,0,0,0,0,0,0,0,0,0,0,0,0,0,0,0
0,0,0,0,0,0,0,0,0,0,0,0,0,0,0,0,0,0,0,0,0,0,0,0,0,0,0
0,0,0,0,0,0,0,0,4,4,5,5,5,5,5,5,5,5,5,5,5,5,4,4,0,0,0
0,0,0,0,0,0,0,0,4,5,4,5,5,5,5,5,5,5,5,5,5,4,5,4,0,0,0
0,0,0,0,0,0,0,0,5,4,20,20,20,20,20,20,20,20,20,20,20,20,4,5,0,0,0
0,0,0,0,0,0,0,0,5,5,20,20,20,20,20,20,20,20,20,20,20,20,5,5,0,0,0
0,0,0,0,0,0,0,0,5,5,20,20,20,20,20,20,20,20,20,20,20,20,5,5,0,0,0
0,0,4,4,5,5,5,5,5,4,20,20,20,20,20,20,20,20,20,20,20,20,4,4,0,0,0
0,0,4,5,4,5,5,5,4,5,4,5,5,5,5,5,5,5,5,5,5,4,5,4,0,0,0
0,0,5,4,20,20,20,20,20,4,20,20,20,20,20,20,20,20,20,20,20,20,4,4,0,0,0
0,0,5,5,20,20,20,20,20,5,20,20,20,20,20,20,20,20,20,20,20,20,5,5,0,0,0
0,0,5,5,20,20,20,20,20,5,20,20,20,20,20,20,20,20,20,20,20,20,5,5,0,0,0
0,0,5,5,20,20,20,20,20,5,20,20,20,20,20,20,20,20,20,20,20,20,5,5,0,0,0
0,0,5,4,20,20,20,20,20,4,20,20,20,20,20,20,20,20,20,20,20,20,5,5,0,0,0
0,0,4,5,4,5,5,5,4,4,20,20,20,20,20,20,20,20,20,20,20,20,5,5,0,0,0
0,0,4,4,5,5,5,5,5,4,20,20,20,20,20,20,20,20,20,20,20,20,5,5,0,0,0
0,0,0,0,0,0,0,0,5,5,20,20,20,20,20,20,20,20,20,20,20,20,4,4,0,0,0
0,0,0,0,0,0,0,0,5,5,20,20,20,20,20,20,20,20,4,4,5,4,4,4,0,0,0
0,0,0,0,0,0,0,0,5,5,20,20,20,20,20,20,20,20,4,14,0,0,4,4,0,0,0
0,0,0,0,0,0,0,0,5,5,20,20,20,20,20,20,20,20,5,0,4,0,5,5,0,0,0
0,0,0,0,0,0,0,0,5,4,20,20,20,20,20,20,20,20,4,12,10,0,4,5,0,0,0
0,0,0,0,0,0,0,0,4,5,4,5,5,5,5,5,5,4,4,4,5,4,5,4,0,0,0
0,0,0,0,0,0,0,0,4,4,5,5,5,5,5,5,5,4,4,4,5,5,4,4,0,0,0
0,0,0,0,0,0,0,0,0,0,0,0,0,0,0,0,0,0,0,0,0,0,0,0,0,0,0
0,0,0,0,0,0,0,0,0,0,0,0,0,0,0,0,0,0,0,0,0,0,0,0,0,0,0
0,0,0,0,0,0,0,0,0,0,0,0,0,0,0,0,0,0,0,0,0,0,0,0,0,0,0
0,0,0,0,0,0,0,0,0,0,0,0,0,0,0,0,0,0,0,0,0,0,0,0,0,0,0
0,0,0,0,0,0,0,0,0,0,0,0,0,0,0,0,0,0,0,0,0,0,0,0,0,0,0
0,0,0,0,0,0,0,0,0,0,0,0,0,0,0,0,0,0,0,0,0,0,0,0,0,0,0
0,0,0,0,0,0,0,0,0,0,0,0,0,0,0,0,0,0,0,0,0,0,0,0,0,0,0
:endlayer
layer: 21
0,0,0,0,0,0,0,0,0,0,0,0,0,0,0,0,0,0,0,0,0,0,0,0,0,0,0
0,0,0,0,0,0,0,0,0,0,0,0,0,0,0,0,0,0,0,0,0,0,0,0,0,0,0
0,0,0,0,0,0,0,0,4,5,5,5,8,8,5,5,5,5,8,8,5,5,5,4,0,0,0
0,0,0,0,0,0,0,0,5,5,5,5,0,0,5,5,5,5,0,0,5,5,5,5,0,0,0
0,0,0,0,0,0,0,0,5,5,0,0,0,0,0,0,0,0,0,0,0,0,5,5,0,0,0
0,0,0,0,0,0,0,0,5,5,0,0,0,9,0,0,0,0,0,0,0,0,5,5,0,0,0
0,0,0,0,0,0,0,0,5,5,0,0,0,0,0,0,0,0,9,0,0,0,5,5,0,0,0
0,0,4,5,5,8,5,8,5,5,0,0,0,0,0,0,0,0,0,0,0,0,5,5,0,0,0
0,0,5,5,5,0,5,0,5,5,5,5,5,5,5,5,0,5,5,5,5,5,5,4,0,0,0
0,0,5,5,0,0,0,0,0,5,0,0,0,0,0,0,0,28,0,0,0,0,5,5,0,0,0
0,0,11,0,0,0,0,0,0,5,0,0,0,0,0,0,0,28,0,0,0,0,0,10,0,0,0
0,0,5,5,0,0,9,0,0,0,0,0,9,0,0,0,0,28,0,9,0,0,5,5,0,0,0
0,0,11,0,0,0,0,0,0,5,0,0,0,0,0,0,0,28,0,0,0,0,9,5,0,0,0
0,0,5,5,0,0,0,0,0,5,0,0,0,0,0,0,0,0,0,0,0,0,9,5,0,0,0
0,0,5,5,5,0,5,0,5,4,0,0,0,0,0,9,0,0,0,9,0,0,5,5,0,0,0
0,0,4,5,5,13,5,13,5,5,0,0,0,0,0,0,0,28,0,0,0,0,0,10,0,0,0
0,0,0,0,0,0,0,0,11,0,0,0,0,0,0,0,0,28,0,0,0,0,5,5,0,0,0
0,0,0,0,0,0,0,0,11,0,0,0,0,0,0,0,0,28,4,5,5,5,5,4,0,0,0
0,0,0,0,0,0,0,0,5,5,0,0,9,0,0,9,0,0,5,12,0,0,5,5,0,0,0
0,0,0,0,0,0,0,0,5,5,0,0,0,0,0,0,0,0,5,13,4,0,5,5,0,0,0
0,0,0,0,0,0,0,0,5,5,0,0,0,0,0,0,0,0,0,0,0,0,5,5,0,0,0
0,0,0,0,0,0,0,0,5,5,5,0,0,5,5,0,0,5,5,5,5,5,5,5,0,0,0
0,0,0,0,0,0,0,0,4,5,5,13,13,5,5,13,13,5,4,5,5,5,5,4,0,0,0
0,0,0,0,0,0,0,0,0,0,0,0,0,0,0,0,0,0,0,0,0,0,0,0,0,0,0
0,0,0,0,0,0,0,0,0,0,0,0,0,0,0,0,0,0,0,0,0,0,0,0,0,0,0
0,0,0,0,0,0,0,0,0,0,0,0,0,0,0,0,0,0,0,0,0,0,0,0,0,0,0
0,0,0,0,0,0,0,0,0,0,0,0,0,0,0,0,0,0,0,0,0,0,0,0,0,0,0
0,0,0,0,0,0,0,0,0,0,0,0,0,0,0,0,0,0,0,0,0,0,0,0,0,0,0
0,0,0,0,0,0,0,0,0,0,0,0,0,0,0,0,0,0,0,0,0,0,0,0,0,0,0
0,0,0,0,0,0,0,0,0,0,0,0,0,0,0,0,0,0,0,0,0,0,0,0,0,0,0
:endlayer
layer: 22
0,0,0,0,0,0,0,0,0,0,0,0,0,0,0,0,0,0,0,0,0,0,0,0,0,0,0
0,0,0,0,0,0,0,0,0,0,0,0,0,0,0,0,0,0,0,0,0,0,0,0,0,0,0
0,0,0,0,0,0,0,0,4,4,5,5,0,0,5,5,5,5,0,0,5,5,4,4,0,0,0
0,0,0,0,0,0,0,0,4,5,4,5,0,0,5,5,5,5,0,0,5,4,5,4,0,0,0
0,0,0,0,0,0,0,0,5,4,0,0,0,0,0,0,0,0,0,0,0,0,4,5,0,0,0
0,0,0,0,0,0,0,0,5,5,0,0,0,0,0,0,0,0,0,0,0,0,5,5,0,0,0
0,0,0,0,0,0,0,0,5,5,0,0,0,0,0,0,0,0,0,0,0,0,5,5,0,0,0
0,0,4,4,5,0,5,0,5,4,0,0,0,0,0,0,0,0,0,0,0,0,4,4,0,0,0
0,0,4,5,4,0,5,0,4,5,4,5,5,5,5,5,0,5,5,5,5,4,5,4,0,0,0
0,0,5,4,0,0,0,0,0,4,0,0,0,0,0,0,0,28,0,0,0,0,4,4,0,0,0
0,0,0,0,0,0,0,0,0,5,0,0,0,0,0,0,0,28,0,0,0,0,0,0,0,0,0
0,0,5,5,0,0,0,0,0,0,0,0,0,0,0,0,0,28,0,0,0,0,5,5,0,0,0
0,0,0,0,0,0,0,0,0,5,0,0,0,0,0,0,0,28,0,0,0,0,0,12,0,0,0
0,0,5,4,0,0,0,0,0,4,0,0,0,0,0,0,0,0,0,0,0,0,0,12,0,0,0
0,0,4,5,4,0,5,0,4,4,0,0,0,0,0,0,0,0,0,0,0,0,5,5,0,0,0
0,0,4,4,5,0,5,0,5,4,0,0,0,0,0,0,0,28,0,0,0,0,0,0,0,0,0
0,0,0,0,0,0,0,0,0,0,0,0,0,0,0,0,0,28,0,0,0,0,4,4,0,0,0
0,0,0,0,0,0,0,0,0,0,0,0,0,0,0,0,0,28,4,4,5,5,5,4,0,0,0
0,0,0,0,0,0,0,0,5,5,0,0,0,0,0,0,0,0,4,0,11,12,4,4,0,0,0
0,0,0,0,0,0,0,0,5,5,0,0,0,0,0,0,0,0,5,0,4,0,5,5,0,0,0
0,0,0,0,0,0,0,0,5,4,0,0,0,0,0,0,0,0,0,0,0,0,4,5,0,0,0
0,0,0,0,0,0,0,0,4,5,4,0,0,5,5,0,0,4,4,4,5,4,5,4,0,0,0
0,0,0,0,0,0,0,0,4,4,5,0,0,5,5,0,0,4,4,4,5,5,4,4,0,0,0
0,0,0,0,0,0,0,0,0,0,0,0,0,0,0,0,0,0,0,0,0,0,0,0,0,0,0
0,0,0,0,0,0,0,0,0,0,0,0,0,0,0,0,0,0,0,0,0,0,0,0,0,0,0
0,0,0,0,0,0,0,0,0,0,0,0,0,0,0,0,0,0,0,0,0,0,0,0,0,0,0
0,0,0,0,0,0,0,0,0,0,0,0,0,0,0,0,0,0,0,0,0,0,0,0,0,0,0
0,0,0,0,0,0,0,0,0,0,0,0,0,0,0,0,0,0,0,0,0,0,0,0,0,0,0
0,0,0,0,0,0,0,0,0,0,0,0,0,0,0,0,0,0,0,0,0,0,0,0,0,0,0
0,0,0,0,0,0,0,0,0,0,0,0,0,0,0,0,0,0,0,0,0,0,0,0,0,0,0
:endlayer
layer: 23
0,0,0,0,0,0,0,0,0,0,0,0,0,0,0,0,0,0,0,0,0,0,0,0,0,0,0
0,0,0,0,0,0,0,0,0,0,0,0,0,0,0,0,0,0,0,0,0,0,0,0,0,0,0
0,0,0,0,0,0,0,0,4,5,5,5,16,16,5,5,5,5,16,16,5,5,5,4,0,0,0
0,0,0,0,0,0,0,0,5,5,5,5,17,17,5,5,5,5,17,17,5,5,5,5,0,0,0
0,0,0,0,0,0,0,0,5,5,0,0,0,0,0,0,0,0,0,0,0,0,5,5,0,0,0
0,0,0,0,0,0,0,0,5,5,0,0,0,0,0,0,0,0,0,0,0,0,5,5,0,0,0
0,0,0,0,0,0,0,0,5,5,0,0,0,0,0,0,0,0,0,0,0,0,5,5,0,0,0
0,0,4,5,5,16,5,16,5,5,0,0,0,0,0,0,0,0,0,0,0,0,5,5,0,0,0
0,0,5,5,5,17,5,17,5,5,5,5,5,5,5,5,5,5,5,5,5,5,5,4,0,0,0
0,0,5,5,0,0,0,0,0,5,0,0,0,0,0,0,0,28,0,0,0,0,5,5,0,0,0
0,0,18,19,0,0,0,0,0,5,0,0,0,0,0,0,0,28,0,0,0,0,0,19,0,0,0
0,0,5,5,0,0,0,0,0,5,0,0,0,0,0,0,0,28,0,0,0,0,5,5,0,0,0
0,0,18,19,0,0,0,0,0,5,0,0,0,0,0,0,0,28,0,0,0,0,5,5,0,0,0
0,0,5,5,0,0,0,0,0,5,0,0,0,0,0,0,0,28,0,0,0,0,5,5,0,0,0
0,0,5,5,5,16,5,16,5,4,0,0,0,0,0,0,0,28,0,0,0,0,5,5,0,0,0
0,0,4,5,5,17,5,17,5,5,0,0,0,0,0,0,0,28,0,0,0,0,0,19,0,0,0
0,0,0,0,0,0,0,0,18,19,0,0,0,0,0,0,0,28,0,0,0,0,5,5,0,0,0
0,0,0,0,0,0,0,0,18,19,0,0,0,0,0,0,0,28,4,5,5,5,5,4,0,0,0
0,0,0,0,0,0,0,0,5,5,0,0,0,0,0,0,0,0,5,0,0,0,5,5,0,0,0
0,0,0,0,0,0,0,0,5,5,0,0,0,0,0,0,0,0,5,0,4,8,5,5,0,0,0
0,0,0,0,0,0,0,0,5,5,0,0,0,0,0,0,0,0,5,22,0,12,5,5,0,0,0
0,0,0,0,0,0,0,0,5,5,5,16,16,5,5,16,16,5,5,5,5,5,5,5,0,0,0
0,0,0,0,0,0,0,0,4,5,5,17,17,5,5,17,17,5,4,5,5,5,5,4,0,0,0
0,0,0,0,0,0,0,0,0,0,0,0,0,0,0,0,0,0,0,0,0,0,0,0,0,0,0
0,0,0,0,0,0,0,0,0,0,0,0,0,0,0,0,0,0,0,0,0,0,0,0,0,0,0
0,0,0,0,0,0,0,0,0,0,0,0,0,0,0,0,0,0,0,0,0,0,0,0,0,0,0
0,0,0,0,0,0,0,0,0,0,0,0,0,0,0,0,0,0,0,0,0,0,0,0,0,0,0
0,0,0,0,0,0,0,0,0,0,0,0,0,0,0,0,0,0,0,0,0,0,0,0,0,0,0
0,0,0,0,0,0,0,0,0,0,0,0,0,0,0,0,0,0,0,0,0,0,0,0,0,0,0
0,0,0,0,0,0,0,0,0,0,0,0,0,0,0,0,0,0,0,0,0,0,0,0,0,0,0
:endlayer
layer: 24
0,0,0,0,0,0,0,0,0,0,0,0,0,0,0,0,0,0,0,0,0,0,0,0,0,0,0
0,0,0,0,0,0,0,0,0,0,0,0,0,0,0,0,0,0,0,0,0,0,0,0,0,0,0
0,0,0,0,0,0,0,0,4,4,5,5,5,5,5,5,5,5,5,5,5,5,4,4,0,0,0
0,0,0,0,0,0,0,0,4,5,4,5,5,5,5,5,5,5,5,5,5,4,5,4,0,0,0
0,0,0,0,0,0,0,0,5,4,0,0,0,0,0,0,0,0,0,0,0,0,4,5,0,0,0
0,0,0,0,0,0,0,0,5,5,0,0,0,0,0,0,0,0,0,0,0,0,5,5,0,0,0
0,0,0,0,0,0,0,0,5,5,0,0,0,0,0,0,0,0,0,0,0,0,5,5,0,0,0
0,0,4,4,5,5,5,5,5,4,0,0,0,0,0,0,0,0,0,0,0,0,4,4,0,0,0
0,0,4,5,4,5,5,5,4,5,4,5,5,5,5,5,5,5,5,5,5,4,5,4,0,0,0
0,0,5,4,0,0,0,0,0,4,0,0,0,0,0,0,0,28,0,0,0,0,4,4,0,0,0
0,0,5,5,0,0,0,0,0,5,0,0,0,0,0,0,0,28,0,0,0,0,5,5,0,0,0
0,0,5,5,0,0,0,0,0,5,0,0,0,0,0,0,0,28,0,0,0,0,5,5,0,0,0
0,0,5,5,0,0,0,0,0,5,0,0,0,0,0,0,0,28,0,0,0,0,5,5,0,0,0
0,0,5,4,0,0,0,0,0,4,0,0,0,0,0,0,0,28,0,0,0,0,5,5,0,0,0
0,0,4,5,4,5,5,5,4,4,0,0,0,0,0,0,0,28,0,0,0,0,5,5,0,0,0
0,0,4,4,5,5,5,5,5,4,0,0,0,0,0,0,0,28,0,0,0,0,5,5,0,0,0
0,0,0,0,0,0,0,0,5,5,0,0,0,0,0,0,0,28,0,0,0,0,4,4,0,0,0
0,0,0,0,0,0,0,0,5,5,0,0,0,0,0,0,0,28,4,4,5,5,5,4,0,0,0
0,0,0,0,0,0,0,0,5,5,0,0,0,0,0,0,0,0,4,0,0,0,4,4,0,0,0
0,0,0,0,0,0,0,0,5,5,0,0,0,0,0,0,0,0,5,0,4,0,5,5,0,0,0
0,0,0,0,0,0,0,0,5,4,0,0,0,0,0,0,0,0,4,12,10,0,4,5,0,0,0
0,0,0,0,0,0,0,0,4,5,4,5,5,5,5,5,5,4,4,4,5,4,5,4,0,0,0
0,0,0,0,0,0,0,0,4,4,5,5,5,5,5,5,5,4,4,4,5,5,4,4,0,0,0
0,0,0,0,0,0,0,0,0,0,0,0,0,0,0,0,0,0,0,0,0,0,0,0,0,0,0
0,0,0,0,0,0,0,0,0,0,0,0,0,0,0,0,0,0,0,0,0,0,0,0,0,0,0
0,0,0,0,0,0,0,0,0,0,0,0,0,0,0,0,0,0,0,0,0,0,0,0,0,0,0
0,0,0,0,0,0,0,0,0,0,0,0,0,0,0,0,0,0,0,0,0,0,0,0,0,0,0
0,0,0,0,0,0,0,0,0,0,0,0,0,0,0,0,0,0,0,0,0,0,0,0,0,0,0
0,0,0,0,0,0,0,0,0,0,0,0,0,0,0,0,0,0,0,0,0,0,0,0,0,0,0
0,0,0,0,0,0,0,0,0,0,0,0,0,0,0,0,0,0,0,0,0,0,0,0,0,0,0
:endlayer
layer: 25
0,0,0,0,0,0,0,0,0,0,0,0,0,0,0,0,0,0,0,0,0,0,0,0,0,0,0
0,0,0,0,0,0,0,0,0,0,0,0,0,0,0,0,0,0,0,0,0,0,0,0,0,0,0
0,0,0,0,0,0,0,0,4,5,5,5,5,5,5,5,5,5,5,5,5,5,5,4,0,0,0
0,0,0,0,0,0,0,0,5,5,5,5,5,5,5,5,5,5,5,5,5,5,5,5,0,0,0
0,0,0,0,0,0,0,0,5,5,20,20,20,20,20,20,20,20,20,20,20,20,5,5,0,0,0
0,0,0,0,0,0,0,0,5,5,20,20,20,20,20,20,20,20,20,20,20,20,5,5,0,0,0
0,0,0,0,0,0,0,0,5,5,20,20,20,20,20,20,20,20,20,20,20,20,5,5,0,0,0
0,0,4,5,5,5,5,5,5,5,20,20,20,20,20,20,20,20,20,20,20,20,5,5,0,0,0
0,0,5,28,28,28,28,28,5,5,5,5,5,5,5,5,5,5,5,5,5,5,5,4,0,0,0
0,0,5,28,20,20,20,20,20,5,20,20,20,20,20,20,20,20,20,20,20,20,5,5,0,0,0
0,0,5,28,20,20,20,20,20,5,20,20,20,20,20,20,20,20,20,20,20,20,5,5,0,0,0
0,0,5,28,20,20,20,20,20,5,20,20,20,20,20,20,20,20,20,20,20,20,5,5,16,0,0
0,0,5,28,20,20,20,20,20,5,20,20,20,20,20,20,20,20,20,20,20,20,5,5,19,0,0
0,0,5,28,20,20,20,20,20,5,20,20,20,20,20,20,20,20,20,20,20,20,5,5,19,0,0
0,0,5,28,28,28,28,28,5,4,20,20,20,20,20,20,20,20,20,20,20,20,5,5,17,0,0
0,0,4,5,5,5,5,5,5,5,20,20,20,20,20,20,20,20,20,20,20,20,5,5,0,0,0
0,0,0,0,0,0,0,0,5,28,20,20,20,20,20,20,20,20,20,20,20,20,5,5,0,0,0
0,0,0,0,0,0,0,0,5,28,20,20,20,20,20,20,20,20,4,5,5,5,5,4,0,0,0
0,0,0,0,0,0,0,0,5,28,20,20,20,20,20,20,20,20,5,12,0,0,5,5,0,0,0
0,0,0,0,0,0,0,0,5,28,20,20,20,20,20,20,20,20,5,13,4,0,5,5,0,0,0
0,0,0,0,0,0,0,0,5,28,20,20,20,20,20,20,20,20,5,0,0,0,5,5,0,0,0
0,0,0,0,0,0,0,0,5,28,28,28,28,28,28,28,28,28,5,5,5,5,5,5,0,0,0
0,0,0,0,0,0,0,0,4,5,5,5,5,5,5,5,5,5,4,5,5,5,5,4,0,0,0
0,0,0,0,0,0,0,0,0,0,0,0,0,0,0,0,0,0,0,0,0,0,0,0,0,0,0
0,0,0,0,0,0,0,0,0,0,0,0,0,0,0,0,0,0,0,0,0,0,0,0,0,0,0
0,0,0,0,0,0,0,0,0,0,0,0,0,0,0,0,0,0,0,0,0,0,0,0,0,0,0
0,0,0,0,0,0,0,0,0,0,0,0,0,0,0,0,0,0,0,0,0,0,0,0,0,0,0
0,0,0,0,0,0,0,0,0,0,0,0,0,0,0,0,0,0,0,0,0,0,0,0,0,0,0
0,0,0,0,0,0,0,0,0,0,0,0,0,0,0,0,0,0,0,0,0,0,0,0,0,0,0
0,0,0,0,0,0,0,0,0,0,0,0,0,0,0,0,0,0,0,0,0,0,0,0,0,0,0
:endlayer
layer: 26
0,0,0,0,0,0,0,0,0,0,0,0,0,0,0,0,0,0,0,0,0,0,0,0,0,0,0
0,0,0,0,0,0,0,0,0,0,0,0,0,0,0,0,0,0,0,0,0,0,0,0,0,0,0
0,0,0,0,0,0,0,0,4,4,5,5,8,8,5,5,5,5,8,8,5,5,4,4,0,0,0
0,0,0,0,0,0,0,0,4,5,4,5,0,0,5,5,5,5,0,0,5,4,5,4,0,0,0
0,0,0,0,0,0,0,0,5,4,0,0,0,0,0,0,0,0,0,0,0,0,4,5,0,0,0
0,0,0,0,0,0,0,0,5,5,0,0,0,9,0,0,0,0,0,0,0,0,5,5,0,0,0
0,0,0,0,0,0,0,0,5,5,0,0,0,0,0,0,0,0,9,0,0,0,5,5,0,0,0
0,0,4,4,8,5,8,5,5,4,0,0,0,0,0,0,0,0,0,0,0,0,4,4,0,0,0
0,0,4,0,0,0,0,0,4,5,4,5,5,5,5,5,0,5,5,5,5,4,5,4,0,0,0
0,0,11,0,0,0,0,0,0,4,0,0,0,0,0,0,0,0,0,0,0,0,0,10,0,0,0
0,0,5,0,0,0,0,0,0,5,0,0,0,0,0,0,0,0,0,0,0,0,0,10,0,0,0
0,0,5,0,0,0,9,0,0,5,0,0,9,0,0,0,0,0,0,9,0,0,5,5,29,0,0
0,0,5,0,0,0,0,0,0,5,28,28,28,0,0,28,28,28,28,0,0,0,0,0,29,0,0
0,0,11,0,0,0,0,0,0,0,0,0,0,0,0,0,0,0,28,0,0,0,0,0,29,0,0
0,0,4,0,0,0,0,0,4,4,0,0,0,0,0,9,0,0,28,9,0,0,5,5,29,0,0
0,0,4,4,13,5,13,5,5,4,0,0,0,0,0,0,0,0,28,0,0,0,0,10,0,0,0
0,0,0,0,0,0,0,0,11,0,0,0,0,0,0,0,0,0,28,0,0,0,0,10,0,0,0
0,0,0,0,0,0,0,0,5,0,0,0,0,0,0,0,0,0,4,0,5,5,5,4,0,0,0
0,0,0,0,0,0,0,0,11,0,0,0,9,0,0,9,0,0,4,0,11,12,4,4,0,0,0
0,0,0,0,0,0,0,0,5,0,0,0,0,0,0,0,0,0,5,0,4,0,5,5,0,0,0
0,0,0,0,0,0,0,0,11,0,0,0,0,0,0,0,0,0,4,0,0,15,4,5,0,0,0
0,0,0,0,0,0,0,0,4,0,0,0,0,0,0,0,0,0,4,4,5,4,5,4,0,0,0
0,0,0,0,0,0,0,0,4,4,13,5,13,5,5,13,5,13,4,4,5,5,4,4,0,0,0
0,0,0,0,0,0,0,0,0,0,0,0,0,0,0,0,0,0,0,0,0,0,0,0,0,0,0
0,0,0,0,0,0,0,0,0,0,0,0,0,0,0,0,0,0,0,0,0,0,0,0,0,0,0
0,0,0,0,0,0,0,0,0,0,0,0,0,0,0,0,0,0,0,0,0,0,0,0,0,0,0
0,0,0,0,0,0,0,0,0,0,0,0,0,0,0,0,0,0,0,0,0,0,0,0,0,0,0
0,0,0,0,0,0,0,0,0,0,0,0,0,0,0,0,0,0,0,0,0,0,0,0,0,0,0
0,0,0,0,0,0,0,0,0,0,0,0,0,0,0,0,0,0,0,0,0,0,0,0,0,0,0
0,0,0,0,0,0,0,0,0,0,0,0,0,0,0,0,0,0,0,0,0,0,0,0,0,0,0
:endlayer
layer: 27
0,0,0,0,0,0,0,0,0,0,0,0,0,0,0,0,0,0,0,0,0,0,0,0,0,0,0
0,0,0,0,0,0,0,0,0,0,0,0,0,0,0,0,0,0,0,0,0,0,0,0,0,0,0
0,0,0,0,0,0,0,0,4,5,5,5,0,0,5,5,5,5,0,0,5,5,5,4,0,0,0
0,0,0,0,0,0,0,0,5,5,5,5,0,0,5,5,5,5,0,0,5,5,5,5,0,0,0
0,0,0,0,0,0,0,0,5,5,0,0,0,0,0,0,0,0,0,0,0,0,5,5,0,0,0
0,0,0,0,0,0,0,0,5,5,0,0,0,0,0,0,0,0,0,0,0,0,5,5,0,0,0
0,0,0,0,0,0,0,0,5,5,0,0,0,0,0,0,0,0,0,0,0,0,5,5,0,0,0
0,0,4,5,0,5,0,5,5,5,0,0,0,0,0,0,0,0,0,0,0,0,5,5,0,0,0
0,0,5,0,0,0,0,0,5,5,5,5,5,5,5,5,0,5,5,5,5,5,5,4,0,0,0
0,0,0,0,0,0,0,0,0,5,0,0,0,0,0,0,0,0,0,0,0,0,0,0,0,0,0
0,0,5,0,0,0,0,0,0,5,0,0,0,0,0,0,0,0,0,0,0,0,0,0,0,0,0
0,0,5,0,0,0,0,0,0,5,0,0,0,0,0,0,0,0,0,0,0,0,5,5,0,0,0
0,0,5,0,0,0,0,0,0,5,28,28,28,0,0,28,28,28,28,0,0,0,0,0,0,0,0
0,0,0,0,0,0,0,0,0,0,0,0,0,0,0,0,0,0,28,0,0,0,0,0,0,0,0
0,0,5,0,0,0,0,0,5,4,0,0,0,0,0,0,0,0,28,0,0,0,5,5,0,0,0
0,0,4,5,0,5,0,5,5,5,0,0,0,0,0,0,0,0,28,0,0,0,0,0,0,0,0
0,0,0,0,0,0,0,0,0,0,0,0,0,0,0,0,0,0,28,0,0,0,0,0,0,0,0
0,0,0,0,0,0,0,0,5,0,0,0,0,0,0,0,0,0,4,0,5,5,5,4,0,0,0
0,0,0,0,0,0,0,0,0,0,0,0,0,0,0,0,0,0,5,0,0,0,5,5,0,0,0
0,0,0,0,0,0,0,0,5,0,0,0,0,0,0,0,0,0,5,0,4,8,5,5,0,0,0
0,0,0,0,0,0,0,0,0,0,0,0,0,0,0,0,0,0,5,0,0,12,5,5,0,0,0
0,0,0,0,0,0,0,0,5,0,0,0,0,0,0,0,0,0,5,5,5,5,5,5,0,0,0
0,0,0,0,0,0,0,0,4,5,0,5,0,5,5,0,5,0,4,5,5,5,5,4,0,0,0
0,0,0,0,0,0,0,0,0,0,0,0,0,0,0,0,0,0,0,0,0,0,0,0,0,0,0
0,0,0,0,0,0,0,0,0,0,0,0,0,0,0,0,0,0,0,0,0,0,0,0,0,0,0
0,0,0,0,0,0,0,0,0,0,0,0,0,0,0,0,0,0,0,0,0,0,0,0,0,0,0
0,0,0,0,0,0,0,0,0,0,0,0,0,0,0,0,0,0,0,0,0,0,0,0,0,0,0
0,0,0,0,0,0,0,0,0,0,0,0,0,0,0,0,0,0,0,0,0,0,0,0,0,0,0
0,0,0,0,0,0,0,0,0,0,0,0,0,0,0,0,0,0,0,0,0,0,0,0,0,0,0
0,0,0,0,0,0,0,0,0,0,0,0,0,0,0,0,0,0,0,0,0,0,0,0,0,0,0
:endlayer
layer: 28
0,0,0,0,0,0,0,0,0,0,0,0,0,0,0,0,0,0,0,0,0,0,0,0,0,0,0
0,0,0,0,0,0,0,0,0,0,0,0,0,0,0,0,0,0,0,0,0,0,0,0,0,0,0
0,0,0,0,0,0,0,0,4,4,5,5,16,16,5,5,5,5,16,16,5,5,4,4,0,0,0
0,0,0,0,0,0,0,0,4,5,4,5,17,17,5,5,5,5,17,17,5,4,5,4,0,0,0
0,0,0,0,0,0,0,0,5,4,0,0,0,0,0,0,0,0,0,0,0,0,4,5,0,0,0
0,0,0,0,0,0,0,0,5,5,0,0,0,0,0,0,0,0,0,0,0,0,5,5,0,0,0
0,0,0,0,0,0,0,0,5,5,0,0,0,0,0,0,0,0,0,0,0,0,5,5,0,0,0
0,0,4,4,0,5,0,5,5,4,0,0,0,0,0,0,0,0,0,0,0,0,4,4,0,0,0
0,0,4,0,0,0,0,0,4,5,4,5,5,5,5,5,5,5,5,5,5,4,5,4,0,0,0
0,0,0,0,0,0,0,0,0,4,0,0,0,0,0,0,0,0,0,0,0,0,18,19,0,0,0
0,0,5,0,0,0,0,0,0,5,0,0,0,0,0,0,0,0,0,0,0,0,18,19,0,0,0
0,0,5,0,0,0,0,0,0,5,0,0,0,0,0,0,0,0,0,0,0,0,5,5,0,0,0
0,0,5,0,0,0,0,0,0,5,28,28,28,28,28,28,28,28,28,0,0,0,5,19,0,0,0
0,0,0,0,0,0,0,0,0,4,0,0,0,0,0,0,0,0,28,0,0,0,5,19,0,0,0
0,0,4,0,0,0,0,0,4,4,0,0,0,0,0,0,0,0,28,0,0,0,5,5,0,0,0
0,0,4,4,0,5,0,5,5,4,0,0,0,0,0,0,0,0,28,0,0,0,18,19,0,0,0
0,0,0,0,0,0,0,0,0,0,0,0,0,0,0,0,0,0,28,0,0,0,18,19,0,0,0
0,0,0,0,0,0,0,0,5,0,0,0,0,0,0,0,0,0,4,4,5,5,4,4,0,0,0
0,0,0,0,0,0,0,0,0,0,0,0,0,0,0,0,0,0,4,0,0,0,4,4,0,0,0
0,0,0,0,0,0,0,0,5,0,0,0,0,0,0,0,0,0,5,0,4,0,5,5,0,0,0
0,0,0,0,0,0,0,0,0,0,0,0,0,0,0,0,0,0,4,12,10,0,4,5,0,0,0
0,0,0,0,0,0,0,0,4,0,0,0,0,0,0,0,0,0,4,4,5,4,5,4,0,0,0
0,0,0,0,0,0,0,0,4,4,0,5,0,5,5,0,5,0,4,4,5,5,4,4,0,0,0
0,0,0,0,0,0,0,0,0,0,0,0,0,0,0,0,0,0,0,0,0,0,0,0,0,0,0
0,0,0,0,0,0,0,0,0,0,0,0,0,0,0,0,0,0,0,0,0,0,0,0,0,0,0
0,0,0,0,0,0,0,0,0,0,0,0,0,0,0,0,0,0,0,0,0,0,0,0,0,0,0
0,0,0,0,0,0,0,0,0,0,0,0,0,0,0,0,0,0,0,0,0,0,0,0,0,0,0
0,0,0,0,0,0,0,0,0,0,0,0,0,0,0,0,0,0,0,0,0,0,0,0,0,0,0
0,0,0,0,0,0,0,0,0,0,0,0,0,0,0,0,0,0,0,0,0,0,0,0,0,0,0
0,0,0,0,0,0,0,0,0,0,0,0,0,0,0,0,0,0,0,0,0,0,0,0,0,0,0
:endlayer
layer: 29
0,0,0,0,0,0,0,0,0,0,0,0,0,0,0,0,0,0,0,0,0,0,0,0,0,0,0
0,0,0,0,0,0,0,0,0,0,0,0,0,0,0,0,0,0,0,0,0,0,0,0,0,0,0
0,0,0,0,0,0,0,0,4,5,5,5,5,5,5,5,5,5,5,5,5,5,5,4,0,0,0
0,0,0,0,0,0,0,0,5,5,5,5,5,5,5,5,5,5,5,5,5,5,5,5,0,0,0
0,0,0,0,0,0,0,0,5,5,0,0,0,0,0,0,0,0,0,0,0,0,5,5,0,0,0
0,0,0,0,0,0,0,0,5,5,0,0,0,0,0,0,0,0,0,0,0,0,5,5,0,0,0
0,0,0,0,0,0,0,0,5,5,0,0,0,0,0,0,0,0,0,0,0,0,5,5,0,0,0
0,0,4,5,16,5,16,5,5,5,0,0,0,0,0,0,0,0,0,0,0,0,5,5,0,0,0
0,0,5,0,0,0,0,0,5,5,5,5,5,5,5,5,5,5,5,5,5,5,5,4,0,0,0
0,0,18,0,0,0,0,0,0,5,0,0,0,0,0,0,0,0,0,0,0,0,5,5,0,0,0
0,0,5,0,0,0,0,0,0,5,0,0,0,0,0,0,0,0,0,0,0,0,5,5,0,0,0
0,0,5,0,0,0,0,0,0,5,0,0,0,0,0,0,0,0,0,0,0,0,5,5,0,0,0
0,0,5,0,0,0,0,0,0,5,28,28,28,28,28,28,28,28,28,0,0,0,5,5,0,0,0
0,0,18,0,0,0,0,0,0,5,0,0,0,0,0,0,0,0,28,0,0,0,5,5,0,0,0
0,0,5,0,0,0,0,0,5,4,0,0,0,0,0,0,0,0,28,0,0,0,5,5,0,0,0
0,0,4,5,17,5,17,17,5,5,0,0,0,0,0,0,0,0,28,0,0,0,5,5,0,0,0
0,0,0,0,0,0,0,0,18,0,0,0,0,0,0,0,0,0,28,0,0,0,5,5,0,0,0
0,0,0,0,0,0,0,0,5,0,0,0,0,0,0,0,0,0,4,5,5,5,5,4,0,0,0
0,0,0,0,0,0,0,0,18,0,0,0,0,0,0,0,0,0,5,12,0,24,5,5,0,0,0
0,0,0,0,0,0,0,0,5,0,0,0,0,0,0,0,0,0,5,13,4,0,5,5,0,0,0
0,0,0,0,0,0,0,0,18,0,0,0,0,0,0,0,0,0,5,0,0,0,5,5,0,0,0
0,0,0,0,0,0,0,0,5,0,0,0,0,0,0,0,0,0,5,5,5,5,5,5,0,0,0
0,0,0,0,0,0,0,0,4,5,17,5,17,5,5,17,5,17,4,5,5,5,5,4,0,0,0
0,0,0,0,0,0,0,0,0,0,0,0,0,0,0,0,0,0,0,0,0,0,0,0,0,0,0
0,0,0,0,0,0,0,0,0,0,0,0,0,0,0,0,0,0,0,0,0,0,0,0,0,0,0
0,0,0,0,0,0,0,0,0,0,0,0,0,0,0,0,0,0,0,0,0,0,0,0,0,0,0
0,0,0,0,0,0,0,0,0,0,0,0,0,0,0,0,0,0,0,0,0,0,0,0,0,0,0
0,0,0,0,0,0,0,0,0,0,0,0,0,0,0,0,0,0,0,0,0,0,0,0,0,0,0
0,0,0,0,0,0,0,0,0,0,0,0,0,0,0,0,0,0,0,0,0,0,0,0,0,0,0
0,0,0,0,0,0,0,0,0,0,0,0,0,0,0,0,0,0,0,0,0,0,0,0,0,0,0
:endlayer
layer: 30
0,0,0,0,0,0,0,0,0,0,0,0,0,0,0,0,0,0,0,0,0,0,0,0,0,0,0
0,0,0,0,0,0,0,16,16,16,16,16,16,16,16,16,16,16,16,16,16,16,16,16,19,0,0
0,0,0,0,0,0,0,18,28,28,28,28,28,28,28,28,28,28,28,28,28,28,28,28,19,0,0
0,0,0,0,0,0,0,18,28,28,28,28,28,28,28,28,28,28,28,28,28,28,28,28,19,0,0
0,0,0,0,0,0,0,18,28,28,28,28,28,28,28,28,28,28,28,28,28,28,28,28,19,0,0
0,0,0,0,0,0,0,18,28,28,28,28,28,28,28,28,28,28,28,28,28,28,28,28,19,0,0
0,16,16,16,16,16,16,16,28,28,28,28,28,28,28,28,28,28,28,28,28,28,28,28,19,0,0
0,18,28,28,28,28,28,28,28,28,28,28,28,28,28,28,28,28,28,28,28,28,28,28,19,0,0
0,18,28,28,28,28,28,28,28,28,28,28,28,28,28,28,28,28,28,28,28,28,28,28,19,0,0
0,18,28,28,28,28,28,28,28,28,28,28,28,28,28,28,28,28,28,28,28,28,28,28,19,0,0
0,18,28,28,28,28,28,28,28,28,28,28,28,28,28,28,28,28,28,28,28,28,28,28,19,0,0
0,18,28,28,28,28,28,28,28,28,28,28,28,28,28,28,28,28,28,28,28,28,28,28,19,0,0
0,18,28,28,28,28,28,28,28,28,28,28,28,28,28,28,28,28,28,28,28,28,28,28,19,0,0
0,18,28,28,28,28,28,28,28,28,28,28,28,28,28,28,28,28,28,28,28,28,28,28,19,0,0
0,18,28,28,28,28,28,28,28,28,28,28,28,28,28,28,28,28,28,28,28,28,28,28,19,0,0
0,18,28,28,28,28,28,28,28,28,28,28,28,28,28,28,28,28,28,28,28,28,28,28,19,0,0
0,18,17,17,17,17,17,18,28,28,28,28,28,28,28,28,28,28,28,28,28,28,28,28,19,0,0
0,0,0,0,0,0,0,18,28,28,28,28,28,28,28,28,28,28,28,28,28,28,28,28,19,0,0
0,0,0,0,0,0,0,18,28,28,28,28,28,28,28,28,28,28,28,0,11,20,28,28,19,0,0
0,0,0,0,0,0,0,18,28,28,28,28,28,28,28,28,28,28,28,0,4,20,28,28,19,0,0
0,0,0,0,0,0,0,18,28,28,28,28,28,28,28,28,28,28,28,0,0,0,28,28,19,0,0
0,0,0,0,0,0,0,18,28,28,28,28,28,28,28,28,28,28,28,28,28,28,28,28,19,0,0
0,0,0,0,0,0,0,18,28,28,28,28,28,28,28,28,28,28,28,28,28,28,28,28,19,0,0
0,0,0,0,0,0,0,18,17,17,17,17,17,17,17,17,17,17,17,17,17,17,17,17,17,0,0
0,0,0,0,0,0,0,0,0,0,0,0,0,0,0,0,0,0,0,0,0,0,0,0,0,0,0
0,0,0,0,0,0,0,0,0,0,0,0,0,0,0,0,0,0,0,0,0,0,0,0,0,0,0
0,0,0,0,0,0,0,0,0,0,0,0,0,0,0,0,0,0,0,0,0,0,0,0,0,0,0
0,0,0,0,0,0,0,0,0,0,0,0,0,0,0,0,0,0,0,0,0,0,0,0,0,0,0
0,0,0,0,0,0,0,0,0,0,0,0,0,0,0,0,0,0,0,0,0,0,0,0,0,0,0
0,0,0,0,0,0,0,0,0,0,0,0,0,0,0,0,0,0,0,0,0,0,0,0,0,0,0
:endlayer
layer: 31
0,0,0,0,0,0,0,0,0,0,0,0,0,0,0,0,0,0,0,0,0,0,0,0,0,0,0
0,0,0,0,0,0,0,5,13,5,13,5,13,5,13,5,5,13,5,13,5,13,5,13,5,0,0
0,0,0,0,0,0,0,10,0,0,0,0,0,0,0,0,0,0,0,0,0,0,0,0,11,0,0
0,0,0,0,0,0,0,5,0,9,0,0,0,0,0,0,0,0,0,0,0,0,9,0,5,0,0
0,0,0,0,0,0,0,10,0,0,0,0,0,0,0,0,9,0,0,0,0,0,0,0,11,0,0
0,0,0,0,0,0,0,10,0,0,0,0,0,0,0,0,0,0,0,0,0,0,0,0,5,0,0
0,5,13,5,13,5,13,5,0,0,0,0,0,0,0,0,0,0,0,0,0,0,0,0,11,0,0
0,10,0,0,0,0,0,0,0,0,0,0,0,0,0,0,0,0,0,0,0,0,0,0,5,0,0
0,5,0,9,0,0,0,0,0,9,0,0,0,0,0,0,0,0,0,0,0,0,0,0,11,0,0
0,10,0,0,0,0,0,0,0,0,0,0,0,0,0,0,0,0,0,0,0,0,0,0,5,0,0
0,5,0,0,0,0,0,0,0,0,0,0,0,0,0,0,0,0,0,0,0,0,9,0,11,0,0
0,10,0,0,0,0,0,0,0,0,0,0,0,0,0,9,0,0,0,0,0,0,0,0,5,0,0
0,5,0,0,0,0,0,0,0,0,0,0,0,0,0,0,0,0,0,0,0,0,0,0,11,0,0
0,10,0,0,0,0,0,0,0,0,0,0,0,0,0,0,0,0,0,0,0,0,0,0,5,0,0
0,5,0,9,0,0,0,0,0,9,0,0,0,0,0,0,0,0,0,0,0,0,0,0,11,0,0
0,10,0,0,0,0,0,0,0,0,0,0,0,0,0,0,0,0,0,0,0,0,0,0,5,0,0
0,5,8,5,8,5,8,5,0,0,0,0,0,0,0,0,0,0,0,0,0,0,0,0,11,0,0
0,0,0,0,0,0,0,10,0,0,0,0,0,0,0,0,0,0,9,0,0,0,9,0,5,0,0
0,0,0,0,0,0,0,5,0,0,0,0,0,0,0,0,0,0,0,0,0,0,0,0,11,0,0
0,0,0,0,0,0,0,10,0,0,0,0,0,0,0,0,0,0,0,0,4,0,0,0,5,0,0
0,0,0,0,0,0,0,10,0,0,0,0,0,0,0,0,0,0,0,0,0,0,0,0,11,0,0
0,0,0,0,0,0,0,5,0,9,0,0,0,0,0,0,0,0,9,0,0,0,9,0,5,0,0
0,0,0,0,0,0,0,10,0,0,0,0,0,0,0,0,0,0,0,0,0,0,0,0,11,0,0
0,0,0,0,0,0,0,5,8,5,8,5,8,5,8,5,5,8,5,8,5,8,5,8,5,0,0
0,0,0,0,0,0,0,0,0,0,0,0,0,0,0,0,0,0,0,0,0,0,0,0,0,0,0
0,0,0,0,0,0,0,0,0,0,0,0,0,0,0,0,0,0,0,0,0,0,0,0,0,0,0
0,0,0,0,0,0,0,0,0,0,0,0,0,0,0,0,0,0,0,0,0,0,0,0,0,0,0
0,0,0,0,0,0,0,0,0,0,0,0,0,0,0,0,0,0,0,0,0,0,0,0,0,0,0
0,0,0,0,0,0,0,0,0,0,0,0,0,0,0,0,0,0,0,0,0,0,0,0,0,0,0
0,0,0,0,0,0,0,0,0,0,0,0,0,0,0,0,0,0,0,0,0,0,0,0,0,0,0
:endlayer
layer: 32
0,0,0,0,0,0,0,0,0,0,0,0,0,0,0,0,0,0,0,0,0,0,0,0,0,0,0
0,0,0,0,0,0,0,23,0,23,0,23,0,23,0,23,23,0,23,0,23,0,23,0,23,0,0
0,0,0,0,0,0,0,0,0,0,0,0,0,0,0,0,0,0,0,0,0,0,0,0,0,0,0
0,0,0,0,0,0,0,23,0,0,0,0,0,0,0,0,0,0,0,0,0,0,0,0,23,0,0
0,0,0,0,0,0,0,0,0,0,0,0,0,0,0,0,0,0,0,0,0,0,0,0,0,0,0
0,0,0,0,0,0,0,0,0,0,0,0,0,0,0,0,0,0,0,0,0,0,0,0,23,0,0
0,23,0,23,0,23,0,23,0,0,0,0,0,0,0,0,0,0,0,0,0,0,0,0,0,0,0
0,0,0,0,0,0,0,0,0,0,0,0,0,0,0,0,0,0,0,0,0,0,0,0,23,0,0
0,23,0,0,0,0,0,0,0,0,0,0,0,0,0,0,0,0,0,0,0,0,0,0,0,0,0
0,0,0,0,0,0,0,0,0,0,0,0,0,0,0,0,0,0,0,0,0,0,0,0,23,0,0
0,23,0,0,0,0,0,0,0,0,0,0,0,0,0,0,0,0,0,0,0,0,0,0,0,0,0
0,0,0,0,0,0,0,0,0,0,0,0,0,0,0,0,0,0,0,0,0,0,0,0,23,0,0
0,23,0,0,0,0,0,0,0,0,0,0,0,0,0,0,0,0,0,0,0,0,0,0,0,0,0
0,0,0,0,0,0,0,0,0,0,0,0,0,0,0,0,0,0,0,0,0,0,0,0,23,0,0
0,23,0,0,0,0,0,0,0,0,0,0,0,0,0,0,0,0,0,0,0,0,0,0,0,0,0
0,0,0,0,0,0,0,0,0,0,0,0,0,0,0,0,0,0,0,0,0,0,0,0,23,0,0
0,23,0,23,0,23,0,23,0,0,0,0,0,0,0,0,0,0,0,0,0,0,0,0,0,0,0
0,0,0,0,0,0,0,0,0,0,0,0,0,0,0,0,0,0,0,0,0,0,0,0,23,0,0
0,0,0,0,0,0,0,23,0,0,0,0,0,0,0,0,0,0,0,0,0,0,0,0,0,0,0
0,0,0,0,0,0,0,0,0,0,0,0,0,0,0,0,0,0,0,0,0,0,0,0,23,0,0
0,0,0,0,0,0,0,0,0,0,0,0,0,0,0,0,0,0,0,0,0,0,0,0,0,0,0
0,0,0,0,0,0,0,23,0,0,0,0,0,0,0,0,0,0,0,0,0,0,0,0,23,0,0
0,0,0,0,0,0,0,0,0,0,0,0,0,0,0,0,0,0,0,0,0,0,0,0,0,0,0
0,0,0,0,0,0,0,23,0,23,0,23,0,23,0,23,23,0,23,0,23,0,23,0,23,0,0
0,0,0,0,0,0,0,0,0,0,0,0,0,0,0,0,0,0,0,0,0,0,0,0,0,0,0
0,0,0,0,0,0,0,0,0,0,0,0,0,0,0,0,0,0,0,0,0,0,0,0,0,0,0
0,0,0,0,0,0,0,0,0,0,0,0,0,0,0,0,0,0,0,0,0,0,0,0,0,0,0
0,0,0,0,0,0,0,0,0,0,0,0,0,0,0,0,0,0,0,0,0,0,0,0,0,0,0
0,0,0,0,0,0,0,0,0,0,0,0,0,0,0,0,0,0,0,0,0,0,0,0,0,0,0
0,0,0,0,0,0,0,0,0,0,0,0,0,0,0,0,0,0,0,0,0,0,0,0,0,0,0
:endlayer

#### RULES ####
rule:
plugin=vanillaBlocks
number=1
data:
JSON:{blockState:{blockName:"minecraft:dirt",properties:{variant:"dirt",snowy:"false"}}}
:enddata
:endrule

rule:
plugin=vanillaBlocks
number=2
data:
JSON:{blockState:{blockName:"minecraft:cobblestone"}}
:enddata
:endrule

rule:
plugin=vanillaBlocks
number=3
data:
JSON:{blockState:{blockName:"minecraft:grass",properties:{snowy:"false"}}}
:enddata
:endrule

rule:
plugin=vanillaBlocks
number=4
data:
JSON:{blockState:{blockName:"minecraft:stone",properties:{variant:"smooth_andesite"}}}
:enddata
:endrule

rule:
plugin=vanillaBlocks
number=5
data:
JSON:{blockState:{blockName:"minecraft:stonebrick",properties:{variant:"stonebrick"}}}
:enddata
:endrule

rule:
plugin=vanillaBlocks
number=6
data:
JSON:{blockState:{blockName:"minecraft:dirt",properties:{variant:"coarse_dirt",snowy:"false"}}}
:enddata
:endrule

rule:
plugin=vanillaBlocks
number=7
data:
JSON:{blockState:{blockName:"minecraft:stone_stairs",properties:{half:"bottom",shape:"straight",facing:"west"}}}
:enddata
:endrule

rule:
plugin=vanillaBlocks
number=8
data:
JSON:{blockState:{blockName:"minecraft:stone_brick_stairs",properties:{half:"bottom",shape:"straight",facing:"south"}}}
:enddata
:endrule

rule:
plugin=vanillaBlocks
number=9
data:
JSON:{blockState:{blockName:"minecraft:torch",properties:{facing:"up"}}}
:enddata
:endrule

rule:
plugin=vanillaBlocks
number=10
data:
JSON:{blockState:{blockName:"minecraft:stone_brick_stairs",properties:{half:"bottom",shape:"straight",facing:"west"}}}
:enddata
:endrule

rule:
plugin=vanillaBlocks
number=11
data:
JSON:{blockState:{blockName:"minecraft:stone_brick_stairs",properties:{half:"bottom",shape:"straight",facing:"east"}}}
:enddata
:endrule

rule:
plugin=vanillaBlocks
number=12
data:
JSON:{blockState:{blockName:"minecraft:stone_slab",properties:{half:"top",variant:"stone_brick"}}}
:enddata
:endrule

rule:
plugin=vanillaBlocks
number=13
data:
JSON:{blockState:{blockName:"minecraft:stone_brick_stairs",properties:{half:"bottom",shape:"straight",facing:"north"}}}
:enddata
:endrule

rule:
plugin=vanillaBlocks
number=14
data:
JSON:{blockState:{blockName:"minecraft:torch",properties:{facing:"south"}}}
:enddata
:endrule

rule:
plugin=vanillaBlocks
number=15
data:
JSON:{blockState:{blockName:"minecraft:torch",properties:{facing:"north"}}}
:enddata
:endrule

rule:
plugin=vanillaBlocks
number=16
data:
JSON:{blockState:{blockName:"minecraft:stone_brick_stairs",properties:{half:"top",shape:"straight",facing:"south"}}}
:enddata
:endrule

rule:
plugin=vanillaBlocks
number=17
data:
JSON:{blockState:{blockName:"minecraft:stone_brick_stairs",properties:{half:"top",shape:"straight",facing:"north"}}}
:enddata
:endrule

rule:
plugin=vanillaBlocks
number=18
data:
JSON:{blockState:{blockName:"minecraft:stone_brick_stairs",properties:{half:"top",shape:"straight",facing:"east"}}}
:enddata
:endrule

rule:
plugin=vanillaBlocks
number=19
data:
JSON:{blockState:{blockName:"minecraft:stone_brick_stairs",properties:{half:"top",shape:"straight",facing:"west"}}}
:enddata
:endrule

rule:
plugin=vanillaBlocks
number=20
data:
JSON:{blockState:{blockName:"minecraft:wooden_slab",properties:{half:"top",variant:"oak"}}}
:enddata
:endrule

rule:
plugin=vanillaBlocks
number=21
data:
JSON:{blockState:{blockName:"minecraft:stone_stairs",properties:{half:"bottom",shape:"straight",facing:"north"}}}
:enddata
:endrule

rule:
plugin=vanillaBlocks
number=22
data:
JSON:{blockState:{blockName:"minecraft:torch",properties:{facing:"east"}}}
:enddata
:endrule

rule:
plugin=vanillaBlocks
number=23
data:
JSON:{blockState:{blockName:"minecraft:stone_slab",properties:{half:"bottom",variant:"stone_brick"}}}
:enddata
:endrule

rule:
plugin=vanillaBlocks
number=24
data:
JSON:{blockState:{blockName:"minecraft:torch",properties:{facing:"west"}}}
:enddata
:endrule

rule:
plugin=vanillaBlocks
number=25
data:
JSON:{blockState:{blockName:"minecraft:double_wooden_slab",properties:{variant:"oak"}}}
:enddata
:endrule

rule:
plugin=vanillaBlocks
number=26
data:
JSON:{blockState:{blockName:"minecraft:stained_glass_pane",properties:{east:"false",color:"red",south:"false",north:"false",west:"false"}}}
:enddata
:endrule

rule:
plugin=vanillaBlocks
number=27
data:
JSON:{blockState:{blockName:"minecraft:stained_glass_pane",properties:{east:"false",color:"blue",south:"false",north:"false",west:"false"}}}
:enddata
:endrule

rule:
plugin=vanillaBlocks
number=28
data:
JSON:{blockState:{blockName:"minecraft:planks",properties:{variant:"oak"}}}
:enddata
:endrule

rule:
plugin=vanillaBlocks
number=29
data:
JSON:{blockState:{blockName:"minecraft:birch_fence",properties:{east:"false",south:"false",north:"false",west:"false"}}}
:enddata
:endrule

#### ENTITIES ####
