# Ancient Warfare Structure Template File
# Auto-generated structure template file. created on: 5/27/2021 at: 22:21:36
# Lines beginning with # denote comments

header:
version=2.11
name=SurvivalBuildWatchtowerB
mods=
size=13,35,13
offset=12,1,12
:endheader

#### VALIDATION ####
validation:
type=ground
structureAuthor=Loki61089
survival=true
worldGenEnabled=false
unique=false
preserveBlocks=true
preventNaturalHostileSpawns=false
selectionWeight=1
clusterValue=1
minDuplicateDistance=1
dimensionWhiteList=true
dimensionList=
biomeGroupList=
biomeWhiteList=true
biomeList=
leveling=0
fill=0
border=0
blockSwap=false
territoryName=
biomeReplacement=minecraft:
minGenerationHeight=0
maxGenerationHeight=255
:endvalidation

#### LAYERS ####
layer: 0
1,1,1,1,1,1,1,1,1,1,1,1,1
1,1,1,1,1,1,1,1,1,1,1,1,1
1,1,1,1,2,2,2,2,2,2,2,1,1
1,1,1,1,2,3,3,3,3,3,2,1,1
1,1,1,1,2,3,3,3,3,3,2,1,1
1,1,1,1,2,3,3,3,3,3,2,1,1
1,1,4,4,2,3,3,3,3,3,2,1,1
1,1,4,4,2,3,3,3,3,3,2,1,1
1,1,4,4,2,2,2,2,2,1,2,1,1
1,1,4,4,4,4,4,4,1,1,1,1,1
1,1,4,4,4,4,4,4,4,1,1,1,1
1,1,1,1,1,1,1,1,1,1,1,1,1
1,1,1,1,1,1,1,1,1,1,1,1,1
:endlayer
layer: 1
0,0,0,0,0,0,0,0,0,0,0,0,0
0,0,0,0,0,0,0,0,0,0,0,0,0
0,0,0,0,5,5,2,2,2,2,5,0,0
0,0,0,0,2,0,0,0,0,0,5,0,0
0,0,0,0,2,0,0,0,0,0,2,0,0
0,0,0,0,2,0,0,0,0,0,2,0,0
0,0,2,2,2,0,0,0,0,0,2,0,0
0,0,2,3,5,0,0,0,0,0,2,0,0
0,0,2,3,5,2,2,2,2,6,5,0,0
0,0,2,3,3,3,3,3,7,0,0,0,0
0,0,2,2,2,2,2,2,2,0,0,0,0
0,0,0,0,0,0,0,0,0,0,0,0,0
0,0,0,0,0,0,0,0,0,0,0,0,0
:endlayer
layer: 2
0,0,0,0,0,0,0,0,0,0,0,0,0
0,0,0,0,8,0,0,0,0,0,8,0,0
0,0,0,9,5,2,2,2,2,5,5,10,0
0,0,0,0,5,0,0,11,0,0,2,0,0
0,0,0,0,2,0,0,0,0,0,2,0,0
0,0,8,0,2,0,0,0,0,0,2,0,0
0,0,2,2,2,0,0,0,0,0,2,0,0
0,0,2,3,2,0,0,8,0,0,5,0,0
0,0,2,3,5,5,2,2,2,12,5,10,0
0,0,2,3,3,3,3,7,0,0,11,0,0
0,0,2,2,2,2,2,2,13,0,0,0,0
0,0,0,0,0,0,0,0,0,0,0,0,0
0,0,0,0,0,0,0,0,0,0,0,0,0
:endlayer
layer: 3
0,0,0,0,0,0,0,0,0,0,0,0,0
0,0,0,0,0,0,0,0,0,0,0,0,0
0,0,0,0,5,5,2,14,2,2,5,0,0
0,0,0,0,2,0,0,0,0,0,5,0,0
0,0,0,0,2,0,0,0,0,0,2,0,0
0,0,0,0,14,0,0,0,0,0,14,0,0
0,0,2,2,2,0,0,0,0,0,2,0,0
0,0,2,3,5,0,0,0,0,0,2,0,0
0,0,2,3,5,2,2,14,2,5,5,0,0
0,0,2,3,3,3,7,0,0,0,0,0,0
0,0,2,2,2,2,2,13,0,0,0,0,0
0,0,0,0,0,0,0,0,0,0,0,0,0
0,0,0,0,0,0,0,0,0,0,0,0,0
:endlayer
layer: 4
0,0,0,0,0,0,0,0,0,0,0,0,0
0,0,0,0,0,0,0,0,0,0,0,0,0
0,0,0,0,5,2,2,2,2,5,5,0,0
0,0,0,0,5,15,15,15,15,15,2,0,0
0,0,0,0,2,15,15,15,15,15,2,0,0
0,0,0,0,2,15,15,15,15,15,2,0,0
0,0,2,2,2,15,15,15,15,15,2,0,0
0,0,2,3,5,15,15,15,15,15,5,0,0
0,0,2,3,5,5,2,2,2,2,5,0,0
0,0,2,3,3,7,0,0,0,0,0,0,0
0,0,2,2,2,2,13,0,0,0,0,0,0
0,0,0,0,0,0,0,0,0,0,0,0,0
0,0,0,0,0,0,0,0,0,0,0,0,0
:endlayer
layer: 5
0,0,0,0,0,0,0,0,0,0,0,0,0
0,0,0,0,0,0,0,0,0,0,0,0,0
0,0,0,0,5,5,2,16,2,2,5,0,0
0,0,0,0,2,0,0,0,0,0,5,0,0
0,0,0,0,2,0,0,0,0,0,2,0,0
0,0,0,0,17,0,0,0,0,0,13,0,0
0,0,18,18,2,0,2,2,2,0,2,0,0
0,0,18,0,19,0,17,20,0,0,2,0,0
0,0,18,0,5,2,2,2,2,5,5,0,0
0,0,18,0,0,0,0,0,0,0,0,0,0
0,0,18,18,18,18,0,0,0,0,0,0,0
0,0,0,0,0,0,0,0,0,0,0,0,0
0,0,0,0,0,0,0,0,0,0,0,0,0
:endlayer
layer: 6
0,0,0,0,0,0,0,0,0,0,0,0,0
0,0,0,0,0,0,0,0,0,0,0,0,0
0,0,0,0,5,2,2,0,2,5,5,0,0
0,0,0,0,5,0,0,0,0,0,2,0,0
0,0,0,0,2,0,0,0,0,0,2,0,0
0,0,0,0,0,0,0,0,0,0,0,0,0
0,0,0,0,2,0,2,2,2,0,2,0,0
0,0,0,0,21,0,0,17,20,0,5,0,0
0,0,0,0,5,5,2,2,2,2,5,0,0
0,0,0,0,0,0,0,0,0,0,0,0,0
0,0,0,0,0,0,0,0,0,0,0,0,0
0,0,0,0,0,0,0,0,0,0,0,0,0
0,0,0,0,0,0,0,0,0,0,0,0,0
:endlayer
layer: 7
0,0,0,0,0,0,0,0,0,0,0,0,0
0,0,0,0,0,0,0,0,0,0,0,0,0
0,0,0,0,5,5,2,22,2,2,5,0,0
0,0,0,0,2,0,0,0,0,0,5,0,0
0,0,0,0,2,0,0,0,0,0,2,0,0
0,0,0,0,23,0,0,8,0,0,20,0,0
0,0,0,0,2,0,2,2,2,22,2,0,0
0,0,0,0,5,0,0,0,17,24,2,0,0
0,0,0,0,5,2,2,2,2,5,5,0,0
0,0,0,0,0,0,0,0,0,0,0,0,0
0,0,0,0,0,0,0,0,0,0,0,0,0
0,0,0,0,0,0,0,0,0,0,0,0,0
0,0,0,0,0,0,0,0,0,0,0,0,0
:endlayer
layer: 8
0,0,0,0,0,0,0,0,0,0,0,0,0
0,0,0,0,0,0,0,0,0,0,0,0,0
0,0,0,0,5,2,2,2,2,5,5,0,0
0,0,0,0,5,15,15,15,15,15,2,0,0
0,0,0,0,2,15,15,15,15,15,2,0,0
0,0,0,0,2,15,15,15,15,15,2,0,0
0,0,0,0,2,15,2,2,2,25,2,0,0
0,0,0,0,2,0,0,0,0,0,5,0,0
0,0,0,0,5,5,2,2,2,2,5,0,0
0,0,0,0,0,0,0,0,0,0,0,0,0
0,0,0,0,0,0,0,0,0,0,0,0,0
0,0,0,0,0,0,0,0,0,0,0,0,0
0,0,0,0,0,0,0,0,0,0,0,0,0
:endlayer
layer: 9
0,0,0,0,0,0,0,0,0,0,0,0,0
0,0,0,0,0,0,0,0,0,0,0,0,0
0,0,0,0,5,5,2,16,2,2,5,0,0
0,0,0,0,2,0,0,0,0,0,5,0,0
0,0,0,0,2,0,0,0,0,0,2,0,0
0,0,0,0,17,0,0,0,0,0,13,0,0
0,0,0,0,2,16,2,2,2,0,2,0,0
0,0,0,0,5,24,0,11,0,0,2,0,0
0,0,0,0,5,2,2,2,2,5,5,0,0
0,0,0,0,0,0,0,0,0,0,0,0,0
0,0,0,0,0,0,0,0,0,0,0,0,0
0,0,0,0,0,0,0,0,0,0,0,0,0
0,0,0,0,0,0,0,0,0,0,0,0,0
:endlayer
layer: 10
0,0,0,0,0,0,0,0,0,0,0,0,0
0,0,0,0,0,0,0,0,0,0,0,0,0
0,0,0,0,5,2,2,0,2,5,5,0,0
0,0,0,0,5,0,0,0,0,0,2,0,0
0,0,0,0,2,0,0,0,0,0,2,0,0
0,0,0,0,0,0,0,0,0,0,0,0,0
0,0,0,0,2,0,2,2,2,0,2,0,0
0,0,0,0,2,0,17,24,0,0,5,0,0
0,0,0,0,5,5,2,2,2,2,5,0,0
0,0,0,0,0,0,0,0,0,0,0,0,0
0,0,0,0,0,0,0,0,0,0,0,0,0
0,0,0,0,0,0,0,0,0,0,0,0,0
0,0,0,0,0,0,0,0,0,0,0,0,0
:endlayer
layer: 11
0,0,0,0,0,0,0,0,0,0,0,0,0
0,0,0,0,0,0,0,0,0,0,0,0,0
0,0,0,0,5,5,2,22,2,2,5,0,0
0,0,0,0,2,0,0,0,0,0,5,0,0
0,0,0,0,2,0,0,0,0,0,2,0,0
0,0,0,0,23,0,0,8,0,0,20,0,0
0,0,0,0,2,0,2,2,2,0,2,0,0
0,0,0,0,5,0,0,0,17,24,2,0,0
0,0,0,0,5,2,2,2,2,5,5,0,0
0,0,0,0,0,0,0,0,0,0,0,0,0
0,0,0,0,0,0,0,0,0,0,0,0,0
0,0,0,0,0,0,0,0,0,0,0,0,0
0,0,0,0,0,0,0,0,0,0,0,0,0
:endlayer
layer: 12
0,0,0,0,0,0,0,0,0,0,0,0,0
0,0,0,0,0,0,0,0,0,0,0,0,0
0,0,0,0,5,2,2,2,2,5,5,0,0
0,0,0,0,5,15,15,15,15,15,2,0,0
0,0,0,0,2,15,15,15,15,15,2,0,0
0,0,0,0,2,15,15,15,15,15,2,0,0
0,0,0,0,2,15,2,2,2,25,2,0,0
0,0,0,0,2,0,0,0,0,0,5,0,0
0,0,0,0,5,5,2,2,2,2,5,0,0
0,0,0,0,0,0,0,0,0,0,0,0,0
0,0,0,0,0,0,0,0,0,0,0,0,0
0,0,0,0,0,0,0,0,0,0,0,0,0
0,0,0,0,0,0,0,0,0,0,0,0,0
:endlayer
layer: 13
0,0,0,0,0,0,0,0,0,0,0,0,0
0,0,0,0,0,0,0,0,0,0,0,0,0
0,0,0,0,5,5,2,16,2,2,5,0,0
0,0,0,0,2,0,0,0,0,0,5,0,0
0,0,0,0,2,0,0,0,0,0,2,0,0
0,0,0,0,17,0,0,0,0,0,13,0,0
0,0,0,0,2,16,2,2,2,0,2,0,0
0,0,0,0,5,24,0,11,0,0,2,0,0
0,0,0,0,5,2,2,2,2,5,5,0,0
0,0,0,0,0,0,0,0,0,0,0,0,0
0,0,0,0,0,0,0,0,0,0,0,0,0
0,0,0,0,0,0,0,0,0,0,0,0,0
0,0,0,0,0,0,0,0,0,0,0,0,0
:endlayer
layer: 14
0,0,0,0,0,0,0,0,0,0,0,0,0
0,0,0,0,0,0,0,0,0,0,0,0,0
0,0,0,0,5,2,2,0,2,5,5,0,0
0,0,0,0,5,0,0,0,0,0,2,0,0
0,0,0,0,2,0,0,0,0,0,2,0,0
0,0,0,0,0,0,0,0,0,0,0,0,0
0,0,0,0,2,0,2,2,2,0,2,0,0
0,0,0,0,2,0,17,20,0,0,5,0,0
0,0,0,0,5,5,2,2,2,2,5,0,0
0,0,0,0,0,0,0,0,0,0,0,0,0
0,0,0,0,0,0,0,0,0,0,0,0,0
0,0,0,0,0,0,0,0,0,0,0,0,0
0,0,0,0,0,0,0,0,0,0,0,0,0
:endlayer
layer: 15
0,0,0,0,0,0,0,0,0,0,0,0,0
0,0,0,0,0,0,0,0,0,0,0,0,0
0,0,0,0,5,5,2,22,2,2,5,0,0
0,0,0,0,2,0,0,0,0,0,5,0,0
0,0,0,0,2,0,0,0,0,0,2,0,0
0,0,0,0,23,0,0,8,0,0,20,0,0
0,0,0,0,2,0,2,2,2,0,2,0,0
0,0,0,0,5,0,0,0,17,24,2,0,0
0,0,0,0,5,2,2,2,2,5,5,0,0
0,0,0,0,0,0,0,0,0,0,0,0,0
0,0,0,0,0,0,0,0,0,0,0,0,0
0,0,0,0,0,0,0,0,0,0,0,0,0
0,0,0,0,0,0,0,0,0,0,0,0,0
:endlayer
layer: 16
0,0,0,0,0,0,0,0,0,0,0,0,0
0,0,0,26,27,26,26,27,26,26,27,26,0
0,0,0,28,5,2,2,2,2,5,5,28,0
0,0,0,26,5,15,15,15,15,15,2,26,0
0,0,0,26,2,15,15,15,15,15,2,26,0
0,0,0,28,2,15,15,15,15,15,2,28,0
0,0,0,26,2,15,2,2,2,25,2,26,0
0,0,0,26,2,0,0,11,0,0,5,26,0
0,0,0,28,5,5,2,2,2,2,5,28,0
0,0,0,26,27,26,26,27,26,26,27,26,0
0,0,0,0,0,0,0,0,0,0,0,0,0
0,0,0,0,0,0,0,0,0,0,0,0,0
0,0,0,0,0,0,0,0,0,0,0,0,0
:endlayer
layer: 17
0,0,0,0,0,0,0,0,0,0,0,0,0
0,0,0,29,30,30,30,29,30,30,30,29,0
0,0,0,30,31,31,31,31,31,31,31,30,0
0,0,0,30,31,31,31,31,31,31,31,30,0
0,0,0,30,31,31,31,31,31,31,31,30,0
0,0,0,29,31,31,31,31,31,31,31,29,0
0,0,0,30,31,31,31,31,31,0,31,30,0
0,0,0,30,31,31,0,0,0,0,31,30,0
0,0,0,30,31,31,31,31,31,31,31,30,0
0,0,0,29,30,30,30,29,30,30,30,29,0
0,0,0,0,0,0,0,0,0,0,0,0,0
0,0,0,0,0,0,0,0,0,0,0,0,0
0,0,0,0,0,0,0,0,0,0,0,0,0
:endlayer
layer: 18
0,0,0,0,0,0,0,0,0,0,0,0,0
0,0,0,29,30,0,30,29,30,0,30,29,0
0,0,0,30,0,0,0,0,0,0,0,30,0
0,0,0,0,0,0,0,0,0,0,0,0,0
0,0,0,30,0,0,0,0,0,0,0,30,0
0,0,0,29,0,0,0,0,0,0,0,29,0
0,0,0,30,0,0,0,0,0,0,0,30,0
0,0,0,0,0,0,0,0,0,0,0,0,0
0,0,0,30,0,0,0,0,0,0,0,30,0
0,0,0,29,30,0,30,29,30,0,30,29,0
0,0,0,0,0,0,0,0,0,0,0,0,0
0,0,0,0,0,0,0,0,0,0,0,0,0
0,0,0,0,0,0,0,0,0,0,0,0,0
:endlayer
layer: 19
0,0,0,0,0,0,0,0,0,0,0,0,0
0,0,0,29,30,30,30,29,30,30,30,29,0
0,0,0,30,0,0,0,11,0,0,0,30,0
0,0,0,30,0,0,0,0,0,0,0,30,0
0,0,0,30,0,0,0,0,0,0,0,30,0
0,0,0,29,10,0,0,0,0,0,9,29,0
0,0,0,30,0,0,0,0,0,0,0,30,0
0,0,0,30,0,0,0,0,0,0,0,30,0
0,0,0,30,0,0,0,8,0,0,0,30,0
0,0,0,29,30,30,30,29,30,30,30,29,0
0,0,0,0,0,0,0,0,0,0,0,0,0
0,0,0,0,0,0,0,0,0,0,0,0,0
0,0,0,0,0,0,0,0,0,0,0,0,0
:endlayer
layer: 20
0,0,32,33,33,33,33,33,33,33,33,33,34
0,0,32,29,28,28,28,29,28,28,28,29,34
0,0,32,27,0,0,0,27,0,0,0,27,34
0,0,32,27,0,0,0,27,0,0,0,27,34
0,0,32,27,0,0,0,27,0,0,0,27,34
0,0,32,29,28,28,28,29,28,28,28,29,34
0,0,32,27,0,0,0,27,0,0,0,27,34
0,0,32,27,0,0,0,27,0,0,0,27,34
0,0,32,27,0,0,0,27,0,0,0,27,34
0,0,32,29,28,28,28,29,28,28,28,29,34
0,0,32,35,35,35,35,35,35,35,35,35,35
0,0,0,0,0,0,0,0,0,0,0,0,0
0,0,0,0,0,0,0,0,0,0,0,0,0
:endlayer
layer: 21
0,0,0,0,0,0,0,0,0,0,0,0,0
0,0,0,32,33,33,33,33,33,33,33,34,0
0,0,0,32,36,36,36,36,36,36,37,34,0
0,0,0,32,38,0,0,0,0,0,37,34,0
0,0,0,32,38,0,0,0,0,0,37,34,0
0,0,0,32,38,0,0,29,0,0,37,34,0
0,0,0,32,38,0,0,0,0,0,37,34,0
0,0,0,32,38,0,0,0,0,0,37,34,0
0,0,0,32,38,39,39,39,39,39,39,34,0
0,0,0,32,35,35,35,35,35,35,35,35,0
0,0,0,0,0,0,0,0,0,0,0,0,0
0,0,0,0,0,0,0,0,0,0,0,0,0
0,0,0,0,0,0,0,0,0,0,0,0,0
:endlayer
layer: 22
0,0,0,0,0,0,0,0,0,0,0,0,0
0,0,0,0,0,0,0,0,0,0,0,0,0
0,0,0,0,32,33,33,33,33,33,34,0,0
0,0,0,0,32,36,36,36,36,37,34,0,0
0,0,0,0,32,38,0,0,0,37,34,0,0
0,0,0,0,32,38,0,29,0,37,34,0,0
0,0,0,0,32,38,0,0,0,37,34,0,0
0,0,0,0,32,39,39,39,39,39,34,0,0
0,0,0,0,32,35,35,35,35,35,35,0,0
0,0,0,0,0,0,0,0,0,0,0,0,0
0,0,0,0,0,0,0,0,0,0,0,0,0
0,0,0,0,0,0,0,0,0,0,0,0,0
0,0,0,0,0,0,0,0,0,0,0,0,0
:endlayer
layer: 23
0,0,0,0,0,0,0,0,0,0,0,0,0
0,0,0,0,0,0,0,0,0,0,0,0,0
0,0,0,0,0,0,0,0,0,0,0,0,0
0,0,0,0,0,40,40,40,40,40,0,0,0
0,0,0,0,0,40,0,0,0,40,0,0,0
0,0,0,0,0,40,0,29,0,40,0,0,0
0,0,0,0,0,40,0,0,0,40,0,0,0
0,0,0,0,0,40,40,40,40,40,0,0,0
0,0,0,0,0,0,0,0,0,0,0,0,0
0,0,0,0,0,0,0,0,0,0,0,0,0
0,0,0,0,0,0,0,0,0,0,0,0,0
0,0,0,0,0,0,0,0,0,0,0,0,0
0,0,0,0,0,0,0,0,0,0,0,0,0
:endlayer
layer: 24
0,0,0,0,0,0,0,0,0,0,0,0,0
0,0,0,0,0,0,0,0,0,0,0,0,0
0,0,0,0,0,0,0,0,0,0,0,0,0
0,0,0,0,0,32,33,33,33,33,0,0,0
0,0,0,0,0,32,38,36,36,34,0,0,0
0,0,0,0,0,32,38,29,37,34,0,0,0
0,0,0,0,0,32,38,39,37,34,0,0,0
0,0,0,0,0,32,35,35,35,34,0,0,0
0,0,0,0,0,0,0,0,0,0,0,0,0
0,0,0,0,0,0,0,0,0,0,0,0,0
0,0,0,0,0,0,0,0,0,0,0,0,0
0,0,0,0,0,0,0,0,0,0,0,0,0
0,0,0,0,0,0,0,0,0,0,0,0,0
:endlayer
layer: 25
0,0,0,0,0,0,0,0,0,0,0,0,0
0,0,0,0,0,0,0,0,0,0,0,0,0
0,0,0,0,0,0,0,0,0,0,0,0,0
0,0,0,0,0,0,0,0,0,0,0,0,0
0,0,0,0,0,0,40,40,40,0,0,0,0
0,0,0,0,0,0,40,29,40,0,0,0,0
0,0,0,0,0,0,40,40,40,0,0,0,0
0,0,0,0,0,0,0,0,0,0,0,0,0
0,0,0,0,0,0,0,0,0,0,0,0,0
0,0,0,0,0,0,0,0,0,0,0,0,0
0,0,0,0,0,0,0,0,0,0,0,0,0
0,0,0,0,0,0,0,0,0,0,0,0,0
0,0,0,0,0,0,0,0,0,0,0,0,0
:endlayer
layer: 26
0,0,0,0,0,0,0,0,0,0,0,0,0
0,0,0,0,0,0,0,0,0,0,0,0,0
0,0,0,0,0,0,0,0,0,0,0,0,0
0,0,0,0,0,0,0,0,0,0,0,0,0
0,0,0,0,0,0,40,40,40,0,0,0,0
0,0,0,0,0,0,40,29,40,0,0,0,0
0,0,0,0,0,0,40,40,40,0,0,0,0
0,0,0,0,0,0,0,0,0,0,0,0,0
0,0,0,0,0,0,0,0,0,0,0,0,0
0,0,0,0,0,0,0,0,0,0,0,0,0
0,0,0,0,0,0,0,0,0,0,0,0,0
0,0,0,0,0,0,0,0,0,0,0,0,0
0,0,0,0,0,0,0,0,0,0,0,0,0
:endlayer
layer: 27
0,0,0,0,0,0,0,0,0,0,0,0,0
0,0,0,0,0,0,0,0,0,0,0,0,0
0,0,0,0,0,0,0,0,0,0,0,0,0
0,0,0,0,0,0,0,0,0,0,0,0,0
0,0,0,0,0,0,33,33,34,0,0,0,0
0,0,0,0,0,0,32,40,34,0,0,0,0
0,0,0,0,0,0,35,35,34,0,0,0,0
0,0,0,0,0,0,0,0,0,0,0,0,0
0,0,0,0,0,0,0,0,0,0,0,0,0
0,0,0,0,0,0,0,0,0,0,0,0,0
0,0,0,0,0,0,0,0,0,0,0,0,0
0,0,0,0,0,0,0,0,0,0,0,0,0
0,0,0,0,0,0,0,0,0,0,0,0,0
:endlayer
layer: 28
0,0,0,0,0,0,0,0,0,0,0,0,0
0,0,0,0,0,0,0,0,0,0,0,0,0
0,0,0,0,0,0,0,0,0,0,0,0,0
0,0,0,0,0,0,0,0,0,0,0,0,0
0,0,0,0,0,0,0,0,0,0,0,0,0
0,0,0,0,0,0,0,40,0,0,0,0,0
0,0,0,0,0,0,0,0,0,0,0,0,0
0,0,0,0,0,0,0,0,0,0,0,0,0
0,0,0,0,0,0,0,0,0,0,0,0,0
0,0,0,0,0,0,0,0,0,0,0,0,0
0,0,0,0,0,0,0,0,0,0,0,0,0
0,0,0,0,0,0,0,0,0,0,0,0,0
0,0,0,0,0,0,0,0,0,0,0,0,0
:endlayer
layer: 29
0,0,0,0,0,0,0,0,0,0,0,0,0
0,0,0,0,0,0,0,0,0,0,0,0,0
0,0,0,0,0,0,0,0,0,0,0,0,0
0,0,0,0,0,0,0,0,0,0,0,0,0
0,0,0,0,0,0,0,0,0,0,0,0,0
0,0,0,0,0,0,0,40,0,0,0,0,0
0,0,0,0,0,0,0,0,0,0,0,0,0
0,0,0,0,0,0,0,0,0,0,0,0,0
0,0,0,0,0,0,0,0,0,0,0,0,0
0,0,0,0,0,0,0,0,0,0,0,0,0
0,0,0,0,0,0,0,0,0,0,0,0,0
0,0,0,0,0,0,0,0,0,0,0,0,0
0,0,0,0,0,0,0,0,0,0,0,0,0
:endlayer
layer: 30
0,0,0,0,0,0,0,0,0,0,0,0,0
0,0,0,0,0,0,0,0,0,0,0,0,0
0,0,0,0,0,0,0,0,0,0,0,0,0
0,0,0,0,0,0,0,0,0,0,0,0,0
0,0,0,0,0,0,0,0,0,0,0,0,0
0,0,0,0,0,0,0,40,0,0,0,0,0
0,0,0,0,0,0,0,0,0,0,0,0,0
0,0,0,0,0,0,0,0,0,0,0,0,0
0,0,0,0,0,0,0,0,0,0,0,0,0
0,0,0,0,0,0,0,0,0,0,0,0,0
0,0,0,0,0,0,0,0,0,0,0,0,0
0,0,0,0,0,0,0,0,0,0,0,0,0
0,0,0,0,0,0,0,0,0,0,0,0,0
:endlayer
layer: 31
0,0,0,0,0,0,0,0,0,0,0,0,0
0,0,0,0,0,0,0,0,0,0,0,0,0
0,0,0,0,0,0,0,0,0,0,0,0,0
0,0,0,0,0,0,0,0,0,0,0,0,0
0,0,0,0,0,0,0,0,0,0,0,0,0
0,0,0,0,0,0,0,18,0,0,0,0,0
0,0,0,0,0,0,0,0,0,0,0,0,0
0,0,0,0,0,0,0,0,0,0,0,0,0
0,0,0,0,0,0,0,0,0,0,0,0,0
0,0,0,0,0,0,0,0,0,0,0,0,0
0,0,0,0,0,0,0,0,0,0,0,0,0
0,0,0,0,0,0,0,0,0,0,0,0,0
0,0,0,0,0,0,0,0,0,0,0,0,0
:endlayer
layer: 32
0,0,0,0,0,0,0,0,0,0,0,0,0
0,0,0,0,0,0,0,0,0,0,0,0,0
0,0,0,0,0,0,0,0,0,0,0,0,0
0,0,0,0,0,0,0,0,0,0,0,0,0
0,0,0,0,0,0,0,0,0,0,0,0,0
0,0,0,0,0,0,0,18,0,0,0,0,0
0,0,0,0,0,0,0,0,0,0,0,0,0
0,0,0,0,0,0,0,0,0,0,0,0,0
0,0,0,0,0,0,0,0,0,0,0,0,0
0,0,0,0,0,0,0,0,0,0,0,0,0
0,0,0,0,0,0,0,0,0,0,0,0,0
0,0,0,0,0,0,0,0,0,0,0,0,0
0,0,0,0,0,0,0,0,0,0,0,0,0
:endlayer
layer: 33
0,0,0,0,0,0,0,0,0,0,0,0,0
0,0,0,0,0,0,0,0,0,0,0,0,0
0,0,0,0,0,0,0,0,0,0,0,0,0
0,0,0,0,0,0,0,0,0,0,0,0,0
0,0,0,0,0,0,0,0,0,0,0,0,0
0,0,0,0,0,0,0,18,0,0,0,0,0
0,0,0,0,0,0,0,0,0,0,0,0,0
0,0,0,0,0,0,0,0,0,0,0,0,0
0,0,0,0,0,0,0,0,0,0,0,0,0
0,0,0,0,0,0,0,0,0,0,0,0,0
0,0,0,0,0,0,0,0,0,0,0,0,0
0,0,0,0,0,0,0,0,0,0,0,0,0
0,0,0,0,0,0,0,0,0,0,0,0,0
:endlayer
layer: 34
0,0,0,0,0,0,0,0,0,0,0,0,0
0,0,0,0,0,0,0,0,0,0,0,0,0
0,0,0,0,0,0,0,0,0,0,0,0,0
0,0,0,0,0,0,0,0,0,0,0,0,0
0,0,0,0,0,0,0,0,0,0,0,0,0
0,0,0,0,0,0,0,18,0,0,0,0,0
0,0,0,0,0,0,0,0,0,0,0,0,0
0,0,0,0,0,0,0,0,0,0,0,0,0
0,0,0,0,0,0,0,0,0,0,0,0,0
0,0,0,0,0,0,0,0,0,0,0,0,0
0,0,0,0,0,0,0,0,0,0,0,0,0
0,0,0,0,0,0,0,0,0,0,0,0,0
0,0,0,0,0,0,0,0,0,0,0,0,0
:endlayer

#### RULES ####
rule:
plugin=vanillaBlocks
number=1
data:
JSON:{blockState:{blockName:"minecraft:grass",properties:{snowy:"false"}}}
:enddata
:endrule

rule:
plugin=vanillaBlocks
number=2
data:
JSON:{blockState:{blockName:"minecraft:stonebrick",properties:{variant:"stonebrick"}}}
:enddata
:endrule

rule:
plugin=vanillaBlocks
number=3
data:
JSON:{blockState:{blockName:"minecraft:cobblestone"}}
:enddata
:endrule

rule:
plugin=vanillaBlocks
number=4
data:
JSON:{blockState:{blockName:"minecraft:dirt",properties:{variant:"dirt",snowy:"false"}}}
:enddata
:endrule

rule:
plugin=vanillaBlocks
number=5
data:
JSON:{blockState:{blockName:"minecraft:stone",properties:{variant:"smooth_andesite"}}}
:enddata
:endrule

rule:
plugin=doors
number=6
data:
JSON:{blockState:{blockName:"minecraft:spruce_door",properties:{hinge:"left",half:"lower",powered:"false",facing:"south",open:"false"}}}
:enddata
:endrule

rule:
plugin=vanillaBlocks
number=7
data:
JSON:{blockState:{blockName:"minecraft:stone_stairs",properties:{half:"bottom",shape:"straight",facing:"west"}}}
:enddata
:endrule

rule:
plugin=vanillaBlocks
number=8
data:
JSON:{blockState:{blockName:"minecraft:torch",properties:{facing:"north"}}}
:enddata
:endrule

rule:
plugin=vanillaBlocks
number=9
data:
JSON:{blockState:{blockName:"minecraft:torch",properties:{facing:"west"}}}
:enddata
:endrule

rule:
plugin=vanillaBlocks
number=10
data:
JSON:{blockState:{blockName:"minecraft:torch",properties:{facing:"east"}}}
:enddata
:endrule

rule:
plugin=vanillaBlocks
number=11
data:
JSON:{blockState:{blockName:"minecraft:torch",properties:{facing:"south"}}}
:enddata
:endrule

rule:
plugin=doors
number=12
data:
JSON:{blockState:{blockName:"minecraft:spruce_door",properties:{hinge:"right",half:"upper",powered:"false",facing:"north",open:"false"}}}
:enddata
:endrule

rule:
plugin=vanillaBlocks
number=13
data:
JSON:{blockState:{blockName:"minecraft:stone_brick_stairs",properties:{half:"bottom",shape:"straight",facing:"west"}}}
:enddata
:endrule

rule:
plugin=vanillaBlocks
number=14
data:
JSON:{blockState:{blockName:"minecraft:iron_bars",properties:{east:"false",south:"false",north:"false",west:"false"}}}
:enddata
:endrule

rule:
plugin=vanillaBlocks
number=15
data:
JSON:{blockState:{blockName:"minecraft:wooden_slab",properties:{half:"top",variant:"spruce"}}}
:enddata
:endrule

rule:
plugin=vanillaBlocks
number=16
data:
JSON:{blockState:{blockName:"minecraft:stone_brick_stairs",properties:{half:"bottom",shape:"straight",facing:"south"}}}
:enddata
:endrule

rule:
plugin=vanillaBlocks
number=17
data:
JSON:{blockState:{blockName:"minecraft:stone_brick_stairs",properties:{half:"bottom",shape:"straight",facing:"east"}}}
:enddata
:endrule

rule:
plugin=vanillaBlocks
number=18
data:
JSON:{blockState:{blockName:"minecraft:spruce_fence",properties:{east:"false",south:"false",north:"false",west:"false"}}}
:enddata
:endrule

rule:
plugin=doors
number=19
data:
JSON:{blockState:{blockName:"minecraft:spruce_door",properties:{hinge:"left",half:"lower",powered:"false",facing:"west",open:"false"}}}
:enddata
:endrule

rule:
plugin=vanillaBlocks
number=20
data:
JSON:{blockState:{blockName:"minecraft:stone_brick_stairs",properties:{half:"top",shape:"straight",facing:"west"}}}
:enddata
:endrule

rule:
plugin=doors
number=21
data:
JSON:{blockState:{blockName:"minecraft:spruce_door",properties:{hinge:"left",half:"upper",powered:"false",facing:"north",open:"false"}}}
:enddata
:endrule

rule:
plugin=vanillaBlocks
number=22
data:
JSON:{blockState:{blockName:"minecraft:stone_brick_stairs",properties:{half:"top",shape:"straight",facing:"south"}}}
:enddata
:endrule

rule:
plugin=vanillaBlocks
number=23
data:
JSON:{blockState:{blockName:"minecraft:stone_brick_stairs",properties:{half:"top",shape:"straight",facing:"east"}}}
:enddata
:endrule

rule:
plugin=vanillaBlocks
number=24
data:
JSON:{blockState:{blockName:"minecraft:stone_slab",properties:{half:"top",variant:"stone_brick"}}}
:enddata
:endrule

rule:
plugin=vanillaBlocks
number=25
data:
JSON:{blockState:{blockName:"minecraft:stone_brick_stairs",properties:{half:"bottom",shape:"straight",facing:"north"}}}
:enddata
:endrule

rule:
plugin=vanillaBlocks
number=26
data:
JSON:{blockState:{blockName:"minecraft:wooden_slab",properties:{half:"top",variant:"dark_oak"}}}
:enddata
:endrule

rule:
plugin=vanillaBlocks
number=27
data:
JSON:{blockState:{blockName:"minecraft:log",properties:{variant:"spruce",axis:"z"}}}
:enddata
:endrule

rule:
plugin=vanillaBlocks
number=28
data:
JSON:{blockState:{blockName:"minecraft:log",properties:{variant:"spruce",axis:"x"}}}
:enddata
:endrule

rule:
plugin=vanillaBlocks
number=29
data:
JSON:{blockState:{blockName:"minecraft:log",properties:{variant:"spruce",axis:"y"}}}
:enddata
:endrule

rule:
plugin=vanillaBlocks
number=30
data:
JSON:{blockState:{blockName:"minecraft:stained_hardened_clay",properties:{color:"white"}}}
:enddata
:endrule

rule:
plugin=vanillaBlocks
number=31
data:
JSON:{blockState:{blockName:"minecraft:wooden_slab",properties:{half:"bottom",variant:"spruce"}}}
:enddata
:endrule

rule:
plugin=vanillaBlocks
number=32
data:
JSON:{blockState:{blockName:"minecraft:dark_oak_stairs",properties:{half:"bottom",shape:"straight",facing:"east"}}}
:enddata
:endrule

rule:
plugin=vanillaBlocks
number=33
data:
JSON:{blockState:{blockName:"minecraft:dark_oak_stairs",properties:{half:"bottom",shape:"straight",facing:"south"}}}
:enddata
:endrule

rule:
plugin=vanillaBlocks
number=34
data:
JSON:{blockState:{blockName:"minecraft:dark_oak_stairs",properties:{half:"bottom",shape:"straight",facing:"west"}}}
:enddata
:endrule

rule:
plugin=vanillaBlocks
number=35
data:
JSON:{blockState:{blockName:"minecraft:dark_oak_stairs",properties:{half:"bottom",shape:"straight",facing:"north"}}}
:enddata
:endrule

rule:
plugin=vanillaBlocks
number=36
data:
JSON:{blockState:{blockName:"minecraft:dark_oak_stairs",properties:{half:"top",shape:"straight",facing:"north"}}}
:enddata
:endrule

rule:
plugin=vanillaBlocks
number=37
data:
JSON:{blockState:{blockName:"minecraft:dark_oak_stairs",properties:{half:"top",shape:"straight",facing:"east"}}}
:enddata
:endrule

rule:
plugin=vanillaBlocks
number=38
data:
JSON:{blockState:{blockName:"minecraft:dark_oak_stairs",properties:{half:"top",shape:"straight",facing:"west"}}}
:enddata
:endrule

rule:
plugin=vanillaBlocks
number=39
data:
JSON:{blockState:{blockName:"minecraft:dark_oak_stairs",properties:{half:"top",shape:"straight",facing:"south"}}}
:enddata
:endrule

rule:
plugin=vanillaBlocks
number=40
data:
JSON:{blockState:{blockName:"minecraft:planks",properties:{variant:"dark_oak"}}}
:enddata
:endrule

#### ENTITIES ####
