# Ancient Warfare Structure Template File
# Auto-generated structure template file. created on: 1/17/2021 at: 23:38:41
# Lines beginning with # denote comments

header:
version=2.11
name=MaliceLeviathanDreadnaughtOfTheMalevolentRealm
mods=rustic,biomesoplenty,quark,ebwizardry
size=29,63,100
offset=14,7,87
:endheader

#### VALIDATION ####
validation:
type=water
structureAuthor=TheOddlySeagull
survival=false
worldGenEnabled=true
unique=false
preserveBlocks=false
preventNaturalHostileSpawns=true
selectionWeight=5
clusterValue=400
minDuplicateDistance=10000
dimensionWhiteList=true
dimensionList=0
biomeGroupList=
biomeWhiteList=true
biomeList=minecraft:ocean,minecraft:deep_ocean
leveling=0
fill=0
border=0
blockSwap=false
territoryName=malice
biomeReplacement=minecraft:
:endvalidation

#### LAYERS ####
layer: 0
1,1,1,1,1,1,1,1,1,1,1,1,1,1,1,1,1,1,1,1,1,1,1,1,1,1,1,1,1
1,1,1,1,1,1,1,1,1,1,1,1,1,1,1,1,1,1,1,1,1,1,1,1,1,1,1,1,1
1,1,1,1,1,1,1,1,1,1,1,1,1,1,1,1,1,1,1,1,1,1,1,1,1,1,1,1,1
1,1,1,1,1,1,1,1,1,1,1,1,1,1,1,1,1,1,1,1,1,1,1,1,1,1,1,1,1
1,1,1,1,1,1,1,1,1,1,1,1,1,1,1,1,1,1,1,1,1,1,1,1,1,1,1,1,1
1,1,1,1,1,1,1,1,1,1,1,1,1,1,1,1,1,1,1,1,1,1,1,1,1,1,1,1,1
1,1,1,1,1,1,1,1,1,1,1,1,1,1,1,1,1,1,1,1,1,1,1,1,1,1,1,1,1
1,1,1,1,1,1,1,1,1,1,1,1,1,1,1,1,1,1,1,1,1,1,1,1,1,1,1,1,1
1,1,1,1,1,1,1,1,1,1,1,1,1,1,1,1,1,1,1,1,1,1,1,1,1,1,1,1,1
1,1,1,1,1,1,1,1,1,1,1,1,1,1,1,1,1,1,1,1,1,1,1,1,1,1,1,1,1
1,1,1,1,1,1,1,1,1,1,1,1,1,1,2,1,1,1,1,1,1,1,1,1,1,1,1,1,1
1,1,1,1,1,1,1,1,1,1,1,1,1,1,2,1,1,1,1,1,1,1,1,1,1,1,1,1,1
1,1,1,1,1,1,1,1,1,1,1,1,1,1,2,1,1,1,1,1,1,1,1,1,1,1,1,1,1
1,1,1,1,1,1,1,1,1,1,1,1,1,1,2,1,1,1,1,1,1,1,1,1,1,1,1,1,1
1,1,1,1,1,1,1,1,1,1,1,1,1,1,2,1,1,1,1,1,1,1,1,1,1,1,1,1,1
1,1,1,1,1,1,1,1,1,1,1,1,1,1,2,1,1,1,1,1,1,1,1,1,1,1,1,1,1
1,1,1,1,1,1,1,1,1,1,1,1,1,1,2,1,1,1,1,1,1,1,1,1,1,1,1,1,1
1,1,1,1,1,1,1,1,1,1,1,1,1,1,2,1,1,1,1,1,1,1,1,1,1,1,1,1,1
1,1,1,1,1,1,1,1,1,1,1,1,1,1,2,1,1,1,1,1,1,1,1,1,1,1,1,1,1
1,1,1,1,1,1,1,1,1,1,1,1,1,1,2,1,1,1,1,1,1,1,1,1,1,1,1,1,1
1,1,1,1,1,1,1,1,1,1,1,1,1,1,2,1,1,1,1,1,1,1,1,1,1,1,1,1,1
1,1,1,1,1,1,1,1,1,1,1,1,1,1,2,1,1,1,1,1,1,1,1,1,1,1,1,1,1
1,1,1,1,1,1,1,1,1,1,1,1,1,1,2,1,1,1,1,1,1,1,1,1,1,1,1,1,1
1,1,1,1,1,1,1,1,1,1,1,1,1,1,2,1,1,1,1,1,1,1,1,1,1,1,1,1,1
1,1,1,1,1,1,1,1,1,1,1,1,1,1,2,1,1,1,1,1,1,1,1,1,1,1,1,1,1
1,1,1,1,1,1,1,1,1,1,1,1,1,1,2,1,1,1,1,1,1,1,1,1,1,1,1,1,1
1,1,1,1,1,1,1,1,1,1,1,1,1,1,2,1,1,1,1,1,1,1,1,1,1,1,1,1,1
1,1,1,1,1,1,1,1,1,1,1,1,1,1,2,1,1,1,1,1,1,1,1,1,1,1,1,1,1
1,1,1,1,1,1,1,1,1,1,1,1,1,1,2,1,1,1,1,1,1,1,1,1,1,1,1,1,1
1,1,1,1,1,1,1,1,1,1,1,1,1,1,2,1,1,1,1,1,1,1,1,1,1,1,1,1,1
1,1,1,1,1,1,1,1,1,1,1,1,1,1,2,1,1,1,1,1,1,1,1,1,1,1,1,1,1
1,1,1,1,1,1,1,1,1,1,1,1,1,1,2,1,1,1,1,1,1,1,1,1,1,1,1,1,1
1,1,1,1,1,1,1,1,1,1,1,1,1,1,2,1,1,1,1,1,1,1,1,1,1,1,1,1,1
1,1,1,1,1,1,1,1,1,1,1,1,1,1,2,1,1,1,1,1,1,1,1,1,1,1,1,1,1
1,1,1,1,1,1,1,1,1,1,1,1,1,1,2,1,1,1,1,1,1,1,1,1,1,1,1,1,1
1,1,1,1,1,1,1,1,1,1,1,1,1,1,2,1,1,1,1,1,1,1,1,1,1,1,1,1,1
1,1,1,1,1,1,1,1,1,1,1,1,1,1,2,1,1,1,1,1,1,1,1,1,1,1,1,1,1
1,1,1,1,1,1,1,1,1,1,1,1,1,1,2,1,1,1,1,1,1,1,1,1,1,1,1,1,1
1,1,1,1,1,1,1,1,1,1,1,1,1,1,2,1,1,1,1,1,1,1,1,1,1,1,1,1,1
1,1,1,1,1,1,1,1,1,1,1,1,1,1,2,1,1,1,1,1,1,1,1,1,1,1,1,1,1
1,1,1,1,1,1,1,1,1,1,1,1,1,1,2,1,1,1,1,1,1,1,1,1,1,1,1,1,1
1,1,1,1,1,1,1,1,1,1,1,1,1,1,2,1,1,1,1,1,1,1,1,1,1,1,1,1,1
1,1,1,1,1,1,1,1,1,1,1,1,1,1,2,1,1,1,1,1,1,1,1,1,1,1,1,1,1
1,1,1,1,1,1,1,1,1,1,1,1,1,1,2,1,1,1,1,1,1,1,1,1,1,1,1,1,1
1,1,1,1,1,1,1,1,1,1,1,1,1,1,2,1,1,1,1,1,1,1,1,1,1,1,1,1,1
1,1,1,1,1,1,1,1,1,1,1,1,1,1,2,1,1,1,1,1,1,1,1,1,1,1,1,1,1
1,1,1,1,1,1,1,1,1,1,1,1,1,1,2,1,1,1,1,1,1,1,1,1,1,1,1,1,1
1,1,1,1,1,1,1,1,1,1,1,1,1,1,2,1,1,1,1,1,1,1,1,1,1,1,1,1,1
1,1,1,1,1,1,1,1,1,1,1,1,1,1,2,1,1,1,1,1,1,1,1,1,1,1,1,1,1
1,1,1,1,1,1,1,1,1,1,1,1,1,1,2,1,1,1,1,1,1,1,1,1,1,1,1,1,1
1,1,1,1,1,1,1,1,1,1,1,1,1,1,2,1,1,1,1,1,1,1,1,1,1,1,1,1,1
1,1,1,1,1,1,1,1,1,1,1,1,1,1,2,1,1,1,1,1,1,1,1,1,1,1,1,1,1
1,1,1,1,1,1,1,1,1,1,1,1,1,1,2,1,1,1,1,1,1,1,1,1,1,1,1,1,1
1,1,1,1,1,1,1,1,1,1,1,1,1,1,2,1,1,1,1,1,1,1,1,1,1,1,1,1,1
1,1,1,1,1,1,1,1,1,1,1,1,1,1,2,1,1,1,1,1,1,1,1,1,1,1,1,1,1
1,1,1,1,1,1,1,1,1,1,1,1,1,1,2,1,1,1,1,1,1,1,1,1,1,1,1,1,1
1,1,1,1,1,1,1,1,1,1,1,1,1,1,2,1,1,1,1,1,1,1,1,1,1,1,1,1,1
1,1,1,1,1,1,1,1,1,1,1,1,1,1,2,1,1,1,1,1,1,1,1,1,1,1,1,1,1
1,1,1,1,1,1,1,1,1,1,1,1,1,1,2,1,1,1,1,1,1,1,1,1,1,1,1,1,1
1,1,1,1,1,1,1,1,1,1,1,1,1,1,2,1,1,1,1,1,1,1,1,1,1,1,1,1,1
1,1,1,1,1,1,1,1,1,1,1,1,1,1,2,1,1,1,1,1,1,1,1,1,1,1,1,1,1
1,1,1,1,1,1,1,1,1,1,1,1,1,1,2,1,1,1,1,1,1,1,1,1,1,1,1,1,1
1,1,1,1,1,1,1,1,1,1,1,1,1,1,2,1,1,1,1,1,1,1,1,1,1,1,1,1,1
1,1,1,1,1,1,1,1,1,1,1,1,1,1,2,1,1,1,1,1,1,1,1,1,1,1,1,1,1
1,1,1,1,1,1,1,1,1,1,1,1,1,1,2,1,1,1,1,1,1,1,1,1,1,1,1,1,1
1,1,1,1,1,1,1,1,1,1,1,1,1,1,2,1,1,1,1,1,1,1,1,1,1,1,1,1,1
1,1,1,1,1,1,1,1,1,1,1,1,1,1,2,1,1,1,1,1,1,1,1,1,1,1,1,1,1
1,1,1,1,1,1,1,1,1,1,1,1,1,1,2,1,1,1,1,1,1,1,1,1,1,1,1,1,1
1,1,1,1,1,1,1,1,1,1,1,1,1,1,2,1,1,1,1,1,1,1,1,1,1,1,1,1,1
1,1,1,1,1,1,1,1,1,1,1,1,1,1,2,1,1,1,1,1,1,1,1,1,1,1,1,1,1
1,1,1,1,1,1,1,1,1,1,1,1,1,1,2,1,1,1,1,1,1,1,1,1,1,1,1,1,1
1,1,1,1,1,1,1,1,1,1,1,1,1,1,1,1,1,1,1,1,1,1,1,1,1,1,1,1,1
1,1,1,1,1,1,1,1,1,1,1,1,1,1,1,1,1,1,1,1,1,1,1,1,1,1,1,1,1
1,1,1,1,1,1,1,1,1,1,1,1,1,1,1,1,1,1,1,1,1,1,1,1,1,1,1,1,1
1,1,1,1,1,1,1,1,1,1,1,1,1,1,1,1,1,1,1,1,1,1,1,1,1,1,1,1,1
1,1,1,1,1,1,1,1,1,1,1,1,1,1,1,1,1,1,1,1,1,1,1,1,1,1,1,1,1
1,1,1,1,1,1,1,1,1,1,1,1,1,1,1,1,1,1,1,1,1,1,1,1,1,1,1,1,1
1,1,1,1,1,1,1,1,1,1,1,1,1,1,1,1,1,1,1,1,1,1,1,1,1,1,1,1,1
1,1,1,1,1,1,1,1,1,1,1,1,1,1,1,1,1,1,1,1,1,1,1,1,1,1,1,1,1
1,1,1,1,1,1,1,1,1,1,1,1,1,1,1,1,1,1,1,1,1,1,1,1,1,1,1,1,1
1,1,1,1,1,1,1,1,1,1,1,1,1,1,1,1,1,1,1,1,1,1,1,1,1,1,1,1,1
1,1,1,1,1,1,1,1,1,1,1,1,1,1,1,1,1,1,1,1,1,1,1,1,1,1,1,1,1
1,1,1,1,1,1,1,1,1,1,1,1,1,1,1,1,1,1,1,1,1,1,1,1,1,1,1,1,1
1,1,1,1,1,1,1,1,1,1,1,1,1,1,1,1,1,1,1,1,1,1,1,1,1,1,1,1,1
1,1,1,1,1,1,1,1,1,1,1,1,1,1,1,1,1,1,1,1,1,1,1,1,1,1,1,1,1
1,1,1,1,1,1,1,1,1,1,1,1,1,1,1,1,1,1,1,1,1,1,1,1,1,1,1,1,1
1,1,1,1,1,1,1,1,1,1,1,1,1,1,1,1,1,1,1,1,1,1,1,1,1,1,1,1,1
1,1,1,1,1,1,1,1,1,1,1,1,1,1,1,1,1,1,1,1,1,1,1,1,1,1,1,1,1
1,1,1,1,1,1,1,1,1,1,1,1,1,1,1,1,1,1,1,1,1,1,1,1,1,1,1,1,1
1,1,1,1,1,1,1,1,1,1,1,1,1,1,1,1,1,1,1,1,1,1,1,1,1,1,1,1,1
1,1,1,1,1,1,1,1,1,1,1,1,1,1,1,1,1,1,1,1,1,1,1,1,1,1,1,1,1
1,1,1,1,1,1,1,1,1,1,1,1,1,1,1,1,1,1,1,1,1,1,1,1,1,1,1,1,1
1,1,1,1,1,1,1,1,1,1,1,1,1,1,1,1,1,1,1,1,1,1,1,1,1,1,1,1,1
1,1,1,1,1,1,1,1,1,1,1,1,1,1,1,1,1,1,1,1,1,1,1,1,1,1,1,1,1
1,1,1,1,1,1,1,1,1,1,1,1,1,1,1,1,1,1,1,1,1,1,1,1,1,1,1,1,1
1,1,1,1,1,1,1,1,1,1,1,1,1,1,1,1,1,1,1,1,1,1,1,1,1,1,1,1,1
1,1,1,1,1,1,1,1,1,1,1,1,1,1,1,1,1,1,1,1,1,1,1,1,1,1,1,1,1
1,1,1,1,1,1,1,1,1,1,1,1,1,1,1,1,1,1,1,1,1,1,1,1,1,1,1,1,1
1,1,1,1,1,1,1,1,1,1,1,1,1,1,1,1,1,1,1,1,1,1,1,1,1,1,1,1,1
1,1,1,1,1,1,1,1,1,1,1,1,1,1,1,1,1,1,1,1,1,1,1,1,1,1,1,1,1
:endlayer
layer: 1
1,1,1,1,1,1,1,1,1,1,1,1,1,1,1,1,1,1,1,1,1,1,1,1,1,1,1,1,1
1,1,1,1,1,1,1,1,1,1,1,1,1,1,1,1,1,1,1,1,1,1,1,1,1,1,1,1,1
1,1,1,1,1,1,1,1,1,1,1,1,1,1,1,1,1,1,1,1,1,1,1,1,1,1,1,1,1
1,1,1,1,1,1,1,1,1,1,1,1,1,1,1,1,1,1,1,1,1,1,1,1,1,1,1,1,1
1,1,1,1,1,1,1,1,1,1,1,1,1,1,1,1,1,1,1,1,1,1,1,1,1,1,1,1,1
1,1,1,1,1,1,1,1,1,1,1,1,1,1,1,1,1,1,1,1,1,1,1,1,1,1,1,1,1
1,1,1,1,1,1,1,1,1,1,1,1,1,1,1,1,1,1,1,1,1,1,1,1,1,1,1,1,1
1,1,1,1,1,1,1,1,1,1,1,1,1,1,1,1,1,1,1,1,1,1,1,1,1,1,1,1,1
1,1,1,1,1,1,1,1,1,1,1,1,1,1,2,1,1,1,1,1,1,1,1,1,1,1,1,1,1
1,1,1,1,1,1,1,1,1,1,1,1,1,1,2,1,1,1,1,1,1,1,1,1,1,1,1,1,1
1,1,1,1,1,1,1,1,1,1,1,1,1,1,2,1,1,1,1,1,1,1,1,1,1,1,1,1,1
1,1,1,1,1,1,1,1,1,1,1,1,1,1,2,1,1,1,1,1,1,1,1,1,1,1,1,1,1
1,1,1,1,1,1,1,1,1,1,1,1,1,1,2,1,1,1,1,1,1,1,1,1,1,1,1,1,1
1,1,1,1,1,1,1,1,1,1,1,1,3,3,3,3,3,1,1,1,1,1,1,1,1,1,1,1,1
1,1,1,1,1,1,1,1,1,1,1,1,3,3,3,3,3,1,1,1,1,1,1,1,1,1,1,1,1
1,1,1,1,1,1,1,1,1,1,1,1,3,3,3,3,3,1,1,1,1,1,1,1,1,1,1,1,1
1,1,1,1,1,1,1,1,1,1,1,1,3,3,3,3,3,1,1,1,1,1,1,1,1,1,1,1,1
1,1,1,1,1,1,1,1,1,1,1,1,3,3,3,3,3,1,1,1,1,1,1,1,1,1,1,1,1
1,1,1,1,1,1,1,1,1,1,1,1,3,3,3,3,3,1,1,1,1,1,1,1,1,1,1,1,1
1,1,1,1,1,1,1,1,1,1,1,1,3,3,3,3,3,1,1,1,1,1,1,1,1,1,1,1,1
1,1,1,1,1,1,1,1,1,1,1,1,3,3,3,3,3,1,1,1,1,1,1,1,1,1,1,1,1
1,1,1,1,1,1,1,1,1,1,1,1,3,3,3,3,3,1,1,1,1,1,1,1,1,1,1,1,1
1,1,1,1,1,1,1,1,1,1,1,1,3,3,3,3,3,1,1,1,1,1,1,1,1,1,1,1,1
1,1,1,1,1,1,1,1,1,1,1,1,3,3,3,3,3,1,1,1,1,1,1,1,1,1,1,1,1
1,1,1,1,1,1,1,1,1,1,1,1,3,3,3,3,3,1,1,1,1,1,1,1,1,1,1,1,1
1,1,1,1,1,1,1,1,1,1,1,1,3,3,3,3,3,1,1,1,1,1,1,1,1,1,1,1,1
1,1,1,1,1,1,1,1,1,1,1,1,3,3,3,3,3,1,1,1,1,1,1,1,1,1,1,1,1
1,1,1,1,1,1,1,1,1,1,1,1,3,3,3,3,3,1,1,1,1,1,1,1,1,1,1,1,1
1,1,1,1,1,1,1,1,1,1,1,1,3,3,3,3,3,1,1,1,1,1,1,1,1,1,1,1,1
1,1,1,1,1,1,1,1,1,1,1,1,3,3,3,3,3,1,1,1,1,1,1,1,1,1,1,1,1
1,1,1,1,1,1,1,1,1,1,1,1,3,3,3,3,3,1,1,1,1,1,1,1,1,1,1,1,1
1,1,1,1,1,1,1,1,1,1,1,1,3,3,3,3,3,1,1,1,1,1,1,1,1,1,1,1,1
1,1,1,1,1,1,1,1,1,1,1,1,3,3,3,3,3,1,1,1,1,1,1,1,1,1,1,1,1
1,1,1,1,1,1,1,1,1,1,1,1,3,3,3,3,3,1,1,1,1,1,1,1,1,1,1,1,1
1,1,1,1,1,1,1,1,1,1,1,1,3,3,3,3,3,1,1,1,1,1,1,1,1,1,1,1,1
1,1,1,1,1,1,1,1,1,1,1,1,3,3,3,3,3,1,1,1,1,1,1,1,1,1,1,1,1
1,1,1,1,1,1,1,1,1,1,1,1,3,3,3,3,3,1,1,1,1,1,1,1,1,1,1,1,1
1,1,1,1,1,1,1,1,1,1,1,1,3,3,3,3,3,1,1,1,1,1,1,1,1,1,1,1,1
1,1,1,1,1,1,1,1,1,1,1,1,3,3,3,3,3,1,1,1,1,1,1,1,1,1,1,1,1
1,1,1,1,1,1,1,1,1,1,1,1,3,3,3,3,3,1,1,1,1,1,1,1,1,1,1,1,1
1,1,1,1,1,1,1,1,1,1,1,1,3,3,3,3,3,1,1,1,1,1,1,1,1,1,1,1,1
1,1,1,1,1,1,1,1,1,1,1,1,3,3,3,3,3,1,1,1,1,1,1,1,1,1,1,1,1
1,1,1,1,1,1,1,1,1,1,1,1,3,3,3,3,3,1,1,1,1,1,1,1,1,1,1,1,1
1,1,1,1,1,1,1,1,1,1,1,1,3,3,3,3,3,1,1,1,1,1,1,1,1,1,1,1,1
1,1,1,1,1,1,1,1,1,1,1,1,3,3,3,3,3,1,1,1,1,1,1,1,1,1,1,1,1
1,1,1,1,1,1,1,1,1,1,1,1,3,3,3,3,3,1,1,1,1,1,1,1,1,1,1,1,1
1,1,1,1,1,1,1,1,1,1,1,1,3,3,3,3,3,1,1,1,1,1,1,1,1,1,1,1,1
1,1,1,1,1,1,1,1,1,1,1,1,3,3,3,3,3,1,1,1,1,1,1,1,1,1,1,1,1
1,1,1,1,1,1,1,1,1,1,1,1,3,3,3,3,3,1,1,1,1,1,1,1,1,1,1,1,1
1,1,1,1,1,1,1,1,1,1,1,1,3,3,3,3,3,1,1,1,1,1,1,1,1,1,1,1,1
1,1,1,1,1,1,1,1,1,1,1,1,3,3,3,3,3,1,1,1,1,1,1,1,1,1,1,1,1
1,1,1,1,1,1,1,1,1,1,1,1,3,3,3,3,3,1,1,1,1,1,1,1,1,1,1,1,1
1,1,1,1,1,1,1,1,1,1,1,1,3,3,3,3,3,1,1,1,1,1,1,1,1,1,1,1,1
1,1,1,1,1,1,1,1,1,1,1,1,3,3,3,3,3,1,1,1,1,1,1,1,1,1,1,1,1
1,1,1,1,1,1,1,1,1,1,1,1,3,3,3,3,3,1,1,1,1,1,1,1,1,1,1,1,1
1,1,1,1,1,1,1,1,1,1,1,1,3,3,3,3,3,1,1,1,1,1,1,1,1,1,1,1,1
1,1,1,1,1,1,1,1,1,1,1,1,3,3,3,3,3,1,1,1,1,1,1,1,1,1,1,1,1
1,1,1,1,1,1,1,1,1,1,1,1,3,3,3,3,3,1,1,1,1,1,1,1,1,1,1,1,1
1,1,1,1,1,1,1,1,1,1,1,1,3,3,3,3,3,1,1,1,1,1,1,1,1,1,1,1,1
1,1,1,1,1,1,1,1,1,1,1,1,3,3,3,3,3,1,1,1,1,1,1,1,1,1,1,1,1
1,1,1,1,1,1,1,1,1,1,1,1,3,3,3,3,3,1,1,1,1,1,1,1,1,1,1,1,1
1,1,1,1,1,1,1,1,1,1,1,1,3,3,3,3,3,1,1,1,1,1,1,1,1,1,1,1,1
1,1,1,1,1,1,1,1,1,1,1,1,3,3,3,3,3,1,1,1,1,1,1,1,1,1,1,1,1
1,1,1,1,1,1,1,1,1,1,1,1,3,3,3,3,3,1,1,1,1,1,1,1,1,1,1,1,1
1,1,1,1,1,1,1,1,1,1,1,1,3,3,3,3,3,1,1,1,1,1,1,1,1,1,1,1,1
1,1,1,1,1,1,1,1,1,1,1,1,3,3,3,3,3,1,1,1,1,1,1,1,1,1,1,1,1
1,1,1,1,1,1,1,1,1,1,1,1,3,3,3,3,3,1,1,1,1,1,1,1,1,1,1,1,1
1,1,1,1,1,1,1,1,1,1,1,1,3,3,3,3,3,1,1,1,1,1,1,1,1,1,1,1,1
1,1,1,1,1,1,1,1,1,1,1,1,3,3,3,3,3,1,1,1,1,1,1,1,1,1,1,1,1
1,1,1,1,1,1,1,1,1,1,1,1,1,3,3,3,1,1,1,1,1,1,1,1,1,1,1,1,1
1,1,1,1,1,1,1,1,1,1,1,1,1,3,3,3,1,1,1,1,1,1,1,1,1,1,1,1,1
1,1,1,1,1,1,1,1,1,1,1,1,1,1,2,1,1,1,1,1,1,1,1,1,1,1,1,1,1
1,1,1,1,1,1,1,1,1,1,1,1,1,1,2,1,1,1,1,1,1,1,1,1,1,1,1,1,1
1,1,1,1,1,1,1,1,1,1,1,1,1,1,1,1,1,1,1,1,1,1,1,1,1,1,1,1,1
1,1,1,1,1,1,1,1,1,1,1,1,1,1,1,1,1,1,1,1,1,1,1,1,1,1,1,1,1
1,1,1,1,1,1,1,1,1,1,1,1,1,1,1,1,1,1,1,1,1,1,1,1,1,1,1,1,1
1,1,1,1,1,1,1,1,1,1,1,1,1,1,1,1,1,1,1,1,1,1,1,1,1,1,1,1,1
1,1,1,1,1,1,1,1,1,1,1,1,1,1,1,1,1,1,1,1,1,1,1,1,1,1,1,1,1
1,1,1,1,1,1,1,1,1,1,1,1,1,1,1,1,1,1,1,1,1,1,1,1,1,1,1,1,1
1,1,1,1,1,1,1,1,1,1,1,1,1,1,1,1,1,1,1,1,1,1,1,1,1,1,1,1,1
1,1,1,1,1,1,1,1,1,1,1,1,1,1,1,1,1,1,1,1,1,1,1,1,1,1,1,1,1
1,1,1,1,1,1,1,1,1,1,1,1,1,1,1,1,1,1,1,1,1,1,1,1,1,1,1,1,1
1,1,1,1,1,1,1,1,1,1,1,1,1,1,1,1,1,1,1,1,1,1,1,1,1,1,1,1,1
1,1,1,1,1,1,1,1,1,1,1,1,1,1,1,1,1,1,1,1,1,1,1,1,1,1,1,1,1
1,1,1,1,1,1,1,1,1,1,1,1,1,1,1,1,1,1,1,1,1,1,1,1,1,1,1,1,1
1,1,1,1,1,1,1,1,1,1,1,1,1,1,1,1,1,1,1,1,1,1,1,1,1,1,1,1,1
1,1,1,1,1,1,1,1,1,1,1,1,1,1,1,1,1,1,1,1,1,1,1,1,1,1,1,1,1
1,1,1,1,1,1,1,1,1,1,1,1,1,1,1,1,1,1,1,1,1,1,1,1,1,1,1,1,1
1,1,1,1,1,1,1,1,1,1,1,1,1,1,1,1,1,1,1,1,1,1,1,1,1,1,1,1,1
1,1,1,1,1,1,1,1,1,1,1,1,1,1,1,1,1,1,1,1,1,1,1,1,1,1,1,1,1
1,1,1,1,1,1,1,1,1,1,1,1,1,1,1,1,1,1,1,1,1,1,1,1,1,1,1,1,1
1,1,1,1,1,1,1,1,1,1,1,1,1,1,1,1,1,1,1,1,1,1,1,1,1,1,1,1,1
1,1,1,1,1,1,1,1,1,1,1,1,1,1,1,1,1,1,1,1,1,1,1,1,1,1,1,1,1
1,1,1,1,1,1,1,1,1,1,1,1,1,1,1,1,1,1,1,1,1,1,1,1,1,1,1,1,1
1,1,1,1,1,1,1,1,1,1,1,1,1,1,1,1,1,1,1,1,1,1,1,1,1,1,1,1,1
1,1,1,1,1,1,1,1,1,1,1,1,1,1,1,1,1,1,1,1,1,1,1,1,1,1,1,1,1
1,1,1,1,1,1,1,1,1,1,1,1,1,1,1,1,1,1,1,1,1,1,1,1,1,1,1,1,1
1,1,1,1,1,1,1,1,1,1,1,1,1,1,1,1,1,1,1,1,1,1,1,1,1,1,1,1,1
1,1,1,1,1,1,1,1,1,1,1,1,1,1,1,1,1,1,1,1,1,1,1,1,1,1,1,1,1
1,1,1,1,1,1,1,1,1,1,1,1,1,1,1,1,1,1,1,1,1,1,1,1,1,1,1,1,1
:endlayer
layer: 2
1,1,1,1,1,1,1,1,1,1,1,1,1,1,1,1,1,1,1,1,1,1,1,1,1,1,1,1,1
1,1,1,1,1,1,1,1,1,1,1,1,1,1,1,1,1,1,1,1,1,1,1,1,1,1,1,1,1
1,1,1,1,1,1,1,1,1,1,1,1,1,1,1,1,1,1,1,1,1,1,1,1,1,1,1,1,1
1,1,1,1,1,1,1,1,1,1,1,1,1,1,1,1,1,1,1,1,1,1,1,1,1,1,1,1,1
1,1,1,1,1,1,1,1,1,1,1,1,1,1,1,1,1,1,1,1,1,1,1,1,1,1,1,1,1
1,1,1,1,1,1,1,1,1,1,1,1,1,1,1,1,1,1,1,1,1,1,1,1,1,1,1,1,1
1,1,1,1,1,1,1,1,1,1,1,1,1,1,1,1,1,1,1,1,1,1,1,1,1,1,1,1,1
1,1,1,1,1,1,1,1,1,1,1,1,1,1,2,1,1,1,1,1,1,1,1,1,1,1,1,1,1
1,1,1,1,1,1,1,1,1,1,1,1,1,1,2,1,1,1,1,1,1,1,1,1,1,1,1,1,1
1,1,1,1,1,1,1,1,1,1,1,1,1,1,2,1,1,1,1,1,1,1,1,1,1,1,1,1,1
1,1,1,1,1,1,1,1,1,1,1,1,1,1,2,1,1,1,1,1,1,1,1,1,1,1,1,1,1
1,1,1,1,1,1,1,1,1,1,1,1,3,3,4,3,3,1,1,1,1,1,1,1,1,1,1,1,1
1,1,1,1,1,1,1,1,1,1,1,1,3,3,4,3,3,1,1,1,1,1,1,1,1,1,1,1,1
1,1,1,1,1,1,1,1,1,1,3,3,3,3,4,3,3,3,3,1,1,1,1,1,1,1,1,1,1
1,1,1,1,1,1,1,1,1,1,3,3,3,3,3,3,3,3,3,1,1,1,1,1,1,1,1,1,1
1,1,1,1,1,1,1,1,1,1,3,3,3,3,3,3,3,3,3,1,1,1,1,1,1,1,1,1,1
1,1,1,1,1,1,1,1,1,1,3,3,3,3,3,3,3,3,3,1,1,1,1,1,1,1,1,1,1
1,1,1,1,1,1,1,1,1,1,3,3,3,3,3,3,3,3,3,1,1,1,1,1,1,1,1,1,1
1,1,1,1,1,1,1,1,1,1,3,3,3,3,3,3,3,3,3,1,1,1,1,1,1,1,1,1,1
1,1,1,1,1,1,1,1,1,1,3,3,3,3,3,3,3,3,3,1,1,1,1,1,1,1,1,1,1
1,1,1,1,1,1,1,1,1,1,3,3,3,3,3,3,3,3,3,1,1,1,1,1,1,1,1,1,1
1,1,1,1,1,1,1,1,1,1,3,3,3,3,3,3,3,3,3,1,1,1,1,1,1,1,1,1,1
1,1,1,1,1,1,1,1,1,1,3,3,3,3,3,3,3,3,3,1,1,1,1,1,1,1,1,1,1
1,1,1,1,1,1,1,1,1,1,3,3,3,3,3,3,3,3,3,1,1,1,1,1,1,1,1,1,1
1,1,1,1,1,1,1,1,1,1,3,3,3,3,4,3,3,3,3,1,1,1,1,1,1,1,1,1,1
1,1,1,1,1,1,1,1,1,1,3,3,3,4,4,4,3,3,3,1,1,1,1,1,1,1,1,1,1
1,1,1,1,1,1,1,1,1,1,3,3,3,3,4,3,3,3,3,1,1,1,1,1,1,1,1,1,1
1,1,1,1,1,1,1,1,1,1,3,3,3,3,3,3,3,3,3,1,1,1,1,1,1,1,1,1,1
1,1,1,1,1,1,1,1,1,1,3,3,3,3,3,3,3,3,3,1,1,1,1,1,1,1,1,1,1
1,1,1,1,1,1,1,1,1,1,3,3,3,3,3,3,3,3,3,1,1,1,1,1,1,1,1,1,1
1,1,1,1,1,1,1,1,1,1,3,3,3,3,3,3,3,3,3,1,1,1,1,1,1,1,1,1,1
1,1,1,1,1,1,1,1,1,1,3,3,3,3,3,3,3,3,3,1,1,1,1,1,1,1,1,1,1
1,1,1,1,1,1,1,1,1,1,3,3,3,3,3,3,3,3,3,1,1,1,1,1,1,1,1,1,1
1,1,1,1,1,1,1,1,1,1,3,3,3,3,3,3,3,3,3,1,1,1,1,1,1,1,1,1,1
1,1,1,1,1,1,1,1,1,1,3,3,3,3,3,3,3,3,3,1,1,1,1,1,1,1,1,1,1
1,1,1,1,1,1,1,1,1,1,3,3,3,3,3,3,3,3,3,1,1,1,1,1,1,1,1,1,1
1,1,1,1,1,1,1,1,1,1,3,3,3,3,3,3,3,3,3,1,1,1,1,1,1,1,1,1,1
1,1,1,1,1,1,1,1,1,1,3,3,3,3,4,3,3,3,3,1,1,1,1,1,1,1,1,1,1
1,1,1,1,1,1,1,1,1,1,3,3,3,4,4,4,3,3,3,1,1,1,1,1,1,1,1,1,1
1,1,1,1,1,1,1,1,1,1,3,3,3,3,4,3,3,3,3,1,1,1,1,1,1,1,1,1,1
1,1,1,1,1,1,1,1,1,1,3,3,3,3,3,3,3,3,3,1,1,1,1,1,1,1,1,1,1
1,1,1,1,1,1,1,1,1,1,3,3,3,3,3,3,3,3,3,1,1,1,1,1,1,1,1,1,1
1,1,1,1,1,1,1,1,1,1,3,3,3,3,3,3,3,3,3,1,1,1,1,1,1,1,1,1,1
1,1,1,1,1,1,1,1,1,1,3,3,3,3,3,3,3,3,3,1,1,1,1,1,1,1,1,1,1
1,1,1,1,1,1,1,1,1,1,3,3,3,3,3,3,3,3,3,1,1,1,1,1,1,1,1,1,1
1,1,1,1,1,1,1,1,1,1,3,3,3,3,3,3,3,3,3,1,1,1,1,1,1,1,1,1,1
1,1,1,1,1,1,1,1,1,1,3,3,3,3,3,3,3,3,3,1,1,1,1,1,1,1,1,1,1
1,1,1,1,1,1,1,1,1,1,3,3,3,3,3,3,3,3,3,1,1,1,1,1,1,1,1,1,1
1,1,1,1,1,1,1,1,1,1,3,3,3,3,3,3,3,3,3,1,1,1,1,1,1,1,1,1,1
1,1,1,1,1,1,1,1,1,1,3,3,3,3,3,3,3,3,3,1,1,1,1,1,1,1,1,1,1
1,1,1,1,1,1,1,1,1,1,3,3,3,3,4,3,3,3,3,1,1,1,1,1,1,1,1,1,1
1,1,1,1,1,1,1,1,1,1,3,3,3,4,4,4,3,3,3,1,1,1,1,1,1,1,1,1,1
1,1,1,1,1,1,1,1,1,1,3,3,3,3,4,3,3,3,3,1,1,1,1,1,1,1,1,1,1
1,1,1,1,1,1,1,1,1,1,3,3,3,3,3,3,3,3,3,1,1,1,1,1,1,1,1,1,1
1,1,1,1,1,1,1,1,1,1,3,3,3,3,3,3,3,3,3,1,1,1,1,1,1,1,1,1,1
1,1,1,1,1,1,1,1,1,1,3,3,3,3,3,3,3,3,3,1,1,1,1,1,1,1,1,1,1
1,1,1,1,1,1,1,1,1,1,3,3,3,3,3,3,3,3,3,1,1,1,1,1,1,1,1,1,1
1,1,1,1,1,1,1,1,1,1,3,3,3,3,3,3,3,3,3,1,1,1,1,1,1,1,1,1,1
1,1,1,1,1,1,1,1,1,1,3,3,3,3,3,3,3,3,3,1,1,1,1,1,1,1,1,1,1
1,1,1,1,1,1,1,1,1,1,3,3,3,3,3,3,3,3,3,1,1,1,1,1,1,1,1,1,1
1,1,1,1,1,1,1,1,1,1,3,3,3,3,3,3,3,3,3,1,1,1,1,1,1,1,1,1,1
1,1,1,1,1,1,1,1,1,1,3,3,3,3,3,3,3,3,3,1,1,1,1,1,1,1,1,1,1
1,1,1,1,1,1,1,1,1,1,3,3,3,3,3,3,3,3,3,1,1,1,1,1,1,1,1,1,1
1,1,1,1,1,1,1,1,1,1,3,3,3,3,4,3,3,3,3,1,1,1,1,1,1,1,1,1,1
1,1,1,1,1,1,1,1,1,1,3,3,3,4,4,4,3,3,3,1,1,1,1,1,1,1,1,1,1
1,1,1,1,1,1,1,1,1,1,3,3,3,3,4,3,3,3,3,1,1,1,1,1,1,1,1,1,1
1,1,1,1,1,1,1,1,1,1,3,3,3,3,3,3,3,3,3,1,1,1,1,1,1,1,1,1,1
1,1,1,1,1,1,1,1,1,1,3,3,3,3,3,3,3,3,3,1,1,1,1,1,1,1,1,1,1
1,1,1,1,1,1,1,1,1,1,3,3,3,3,3,3,3,3,3,1,1,1,1,1,1,1,1,1,1
1,1,1,1,1,1,1,1,1,1,1,3,3,3,3,3,3,3,1,1,1,1,1,1,1,1,1,1,1
1,1,1,1,1,1,1,1,1,1,1,3,3,3,3,3,3,3,1,1,1,1,1,1,1,1,1,1,1
1,1,1,1,1,1,1,1,1,1,1,1,3,3,3,3,3,1,1,1,1,1,1,1,1,1,1,1,1
1,1,1,1,1,1,1,1,1,1,1,1,3,3,3,3,3,1,1,1,1,1,1,1,1,1,1,1,1
1,1,1,1,1,1,1,1,1,1,1,1,1,3,3,3,1,1,1,1,1,1,1,1,1,1,1,1,1
1,1,1,1,1,1,1,1,1,1,1,1,1,3,3,3,1,1,1,1,1,1,1,1,1,1,1,1,1
1,1,1,1,1,1,1,1,1,1,1,1,1,1,3,1,1,1,1,1,1,1,1,1,1,1,1,1,1
1,1,1,1,1,1,1,1,1,1,1,1,1,1,3,1,1,1,1,1,1,1,1,1,1,1,1,1,1
1,1,1,1,1,1,1,1,1,1,1,1,1,1,1,1,1,1,1,1,1,1,1,1,1,1,1,1,1
1,1,1,1,1,1,1,1,1,1,1,1,1,1,1,1,1,1,1,1,1,1,1,1,1,1,1,1,1
1,1,1,1,1,1,1,1,1,1,1,1,1,1,1,1,1,1,1,1,1,1,1,1,1,1,1,1,1
1,1,1,1,1,1,1,1,1,1,1,1,1,1,1,1,1,1,1,1,1,1,1,1,1,1,1,1,1
1,1,1,1,1,1,1,1,1,1,1,1,1,1,1,1,1,1,1,1,1,1,1,1,1,1,1,1,1
1,1,1,1,1,1,1,1,1,1,1,1,1,1,1,1,1,1,1,1,1,1,1,1,1,1,1,1,1
1,1,1,1,1,1,1,1,1,1,1,1,1,1,1,1,1,1,1,1,1,1,1,1,1,1,1,1,1
1,1,1,1,1,1,1,1,1,1,1,1,1,1,1,1,1,1,1,1,1,1,1,1,1,1,1,1,1
1,1,1,1,1,1,1,1,1,1,1,1,1,1,1,1,1,1,1,1,1,1,1,1,1,1,1,1,1
1,1,1,1,1,1,1,1,1,1,1,1,1,1,1,1,1,1,1,1,1,1,1,1,1,1,1,1,1
1,1,1,1,1,1,1,1,1,1,1,1,1,1,1,1,1,1,1,1,1,1,1,1,1,1,1,1,1
1,1,1,1,1,1,1,1,1,1,1,1,1,1,1,1,1,1,1,1,1,1,1,1,1,1,1,1,1
1,1,1,1,1,1,1,1,1,1,1,1,1,1,1,1,1,1,1,1,1,1,1,1,1,1,1,1,1
1,1,1,1,1,1,1,1,1,1,1,1,1,1,1,1,1,1,1,1,1,1,1,1,1,1,1,1,1
1,1,1,1,1,1,1,1,1,1,1,1,1,1,1,1,1,1,1,1,1,1,1,1,1,1,1,1,1
1,1,1,1,1,1,1,1,1,1,1,1,1,1,1,1,1,1,1,1,1,1,1,1,1,1,1,1,1
1,1,1,1,1,1,1,1,1,1,1,1,1,1,1,1,1,1,1,1,1,1,1,1,1,1,1,1,1
1,1,1,1,1,1,1,1,1,1,1,1,1,1,1,1,1,1,1,1,1,1,1,1,1,1,1,1,1
1,1,1,1,1,1,1,1,1,1,1,1,1,1,1,1,1,1,1,1,1,1,1,1,1,1,1,1,1
1,1,1,1,1,1,1,1,1,1,1,1,1,1,1,1,1,1,1,1,1,1,1,1,1,1,1,1,1
1,1,1,1,1,1,1,1,1,1,1,1,1,1,1,1,1,1,1,1,1,1,1,1,1,1,1,1,1
1,1,1,1,1,1,1,1,1,1,1,1,1,1,1,1,1,1,1,1,1,1,1,1,1,1,1,1,1
1,1,1,1,1,1,1,1,1,1,1,1,1,1,1,1,1,1,1,1,1,1,1,1,1,1,1,1,1
:endlayer
layer: 3
1,1,1,1,1,1,1,1,1,1,1,1,1,1,1,1,1,1,1,1,1,1,1,1,1,1,1,1,1
1,1,1,1,1,1,1,1,1,1,1,1,1,1,1,1,1,1,1,1,1,1,1,1,1,1,1,1,1
1,1,1,1,1,1,1,1,1,1,1,1,1,1,1,1,1,1,1,1,1,1,1,1,1,1,1,1,1
1,1,1,1,1,1,1,1,1,1,1,1,1,1,1,1,1,1,1,1,1,1,1,1,1,1,1,1,1
1,1,1,1,1,1,1,1,1,1,1,1,1,1,1,1,1,1,1,1,1,1,1,1,1,1,1,1,1
1,1,1,1,1,1,1,1,1,1,1,1,1,1,1,1,1,1,1,1,1,1,1,1,1,1,1,1,1
1,1,1,1,1,1,1,1,1,1,1,1,1,1,1,1,1,1,1,1,1,1,1,1,1,1,1,1,1
1,1,1,1,1,1,1,1,1,1,1,1,1,1,2,1,1,1,1,1,1,1,1,1,1,1,1,1,1
1,1,1,1,1,1,1,1,1,1,1,1,1,1,2,1,1,1,1,1,1,1,1,1,1,1,1,1,1
1,1,1,1,1,1,1,1,1,1,1,1,1,1,2,1,1,1,1,1,1,1,1,1,1,1,1,1,1
1,1,1,1,1,1,1,1,1,1,1,1,1,3,3,3,1,1,1,1,1,1,1,1,1,1,1,1,1
1,1,1,1,1,1,1,1,1,1,1,3,3,3,4,3,3,3,1,1,1,1,1,1,1,1,1,1,1
1,1,1,1,1,1,1,1,1,1,3,68,0,4,4,4,119,3,3,1,1,1,1,1,1,1,1,1,1
1,1,1,1,1,1,1,1,1,3,68,0,0,51,4,118,0,117,116,3,1,1,1,1,1,1,1,1,1
1,1,1,1,1,1,1,1,1,68,0,115,0,51,0,108,51,51,51,3,1,1,1,1,1,1,1,1,1
1,1,1,1,1,1,1,1,1,68,114,0,0,105,113,0,102,0,0,100,1,1,1,1,1,1,1,1,1
1,1,1,1,1,1,1,1,1,3,51,51,51,51,0,0,102,112,0,100,1,1,1,1,1,1,1,1,1
1,1,1,1,1,1,1,1,1,68,0,0,111,51,0,110,51,51,51,3,1,1,1,1,1,1,1,1,1
1,1,1,1,1,1,1,1,1,68,0,0,0,51,0,109,102,0,108,100,1,1,1,1,1,1,1,1,1
1,1,1,1,1,1,1,1,1,68,0,107,0,51,0,0,102,106,0,100,1,1,1,1,1,1,1,1,1
1,1,1,1,1,1,1,1,1,68,0,0,0,105,0,0,51,51,51,3,1,1,1,1,1,1,1,1,1
1,1,1,1,1,1,1,1,1,68,0,0,0,51,0,0,102,104,0,100,1,1,1,1,1,1,1,1,1
1,1,1,1,1,1,1,1,1,3,51,51,51,51,103,0,102,0,101,100,1,1,1,1,1,1,1,1,1
1,1,1,1,1,1,1,1,1,3,0,0,0,0,0,0,51,51,51,3,1,1,1,1,1,1,1,1,1
1,1,1,1,1,1,1,1,1,3,0,99,0,98,4,97,96,95,94,3,1,1,1,1,1,1,1,1,1
1,1,1,1,1,1,1,1,1,3,0,0,3,4,4,4,3,3,3,3,1,1,1,1,1,1,1,1,1
1,1,1,1,1,1,1,1,1,3,0,0,43,43,4,43,43,0,93,3,1,1,1,1,1,1,1,1,1
1,1,1,1,1,1,1,1,1,3,92,0,0,0,0,43,43,0,0,3,1,1,1,1,1,1,1,1,1
1,1,1,1,1,1,1,1,1,3,0,66,0,0,91,43,43,0,0,3,1,1,1,1,1,1,1,1,1
1,1,1,1,1,1,1,1,1,3,66,90,66,0,0,43,43,0,0,3,1,1,1,1,1,1,1,1,1
1,1,1,1,1,1,1,1,1,3,0,66,0,0,0,0,0,89,0,3,1,1,1,1,1,1,1,1,1
1,1,1,1,1,1,1,1,1,3,0,0,0,0,0,0,0,0,0,3,1,1,1,1,1,1,1,1,1
1,1,1,1,1,1,1,1,1,3,3,3,0,88,0,3,3,3,3,3,1,1,1,1,1,1,1,1,1
1,1,1,1,1,1,1,1,1,3,65,0,0,0,0,0,70,0,65,3,1,1,1,1,1,1,1,1,1
1,1,1,1,1,1,1,1,1,3,76,0,0,0,0,0,81,0,69,3,1,1,1,1,1,1,1,1,1
1,1,1,1,1,1,1,1,1,68,65,0,0,87,0,0,70,0,86,3,1,1,1,1,1,1,1,1,1
1,1,1,1,1,1,1,1,1,3,0,0,0,0,0,0,66,85,0,3,1,1,1,1,1,1,1,1,1
1,1,1,1,1,1,1,1,1,3,0,0,0,0,4,74,66,66,66,3,1,1,1,1,1,1,1,1,1
1,1,1,1,1,1,1,1,1,68,65,0,0,4,4,4,66,76,76,3,1,1,1,1,1,1,1,1,1
1,1,1,1,1,1,1,1,1,3,76,0,0,0,4,0,70,0,65,3,1,1,1,1,1,1,1,1,1
1,1,1,1,1,1,1,1,1,3,65,0,0,84,0,0,81,83,69,3,1,1,1,1,1,1,1,1,1
1,1,1,1,1,1,1,1,1,68,82,0,0,0,0,74,70,66,66,3,1,1,1,1,1,1,1,1,1
1,1,1,1,1,1,1,1,1,3,0,0,0,0,0,0,81,0,65,3,1,1,1,1,1,1,1,1,1
1,1,1,1,1,1,1,1,1,3,0,0,0,0,80,0,70,0,69,3,1,1,1,1,1,1,1,1,1
1,1,1,1,1,1,1,1,1,68,79,0,65,78,78,78,66,77,0,3,1,1,1,1,1,1,1,1,1
1,1,1,1,1,1,1,1,1,3,0,0,76,75,75,75,66,0,0,3,1,1,1,1,1,1,1,1,1
1,1,1,1,1,1,1,1,1,3,0,0,65,0,0,74,66,66,66,3,1,1,1,1,1,1,1,1,1
1,1,1,1,1,1,1,1,1,68,73,0,0,0,0,0,70,0,0,3,1,1,1,1,1,1,1,1,1
1,1,1,1,1,1,1,1,1,3,0,0,3,0,0,0,72,0,0,3,1,1,1,1,1,1,1,1,1
1,1,1,1,1,1,1,1,1,3,0,0,71,3,0,0,70,0,69,3,1,1,1,1,1,1,1,1,1
1,1,1,1,1,1,1,1,1,68,67,0,0,0,4,0,66,0,65,3,1,1,1,1,1,1,1,1,1
1,1,1,1,1,1,1,1,1,3,36,36,3,4,4,4,3,3,3,3,1,1,1,1,1,1,1,1,1
1,1,1,1,1,1,1,1,1,3,36,36,43,43,4,51,64,63,51,3,1,1,1,1,1,1,1,1,1
1,1,1,1,1,1,1,1,1,3,36,36,43,43,3,51,0,0,62,3,1,1,1,1,1,1,1,1,1
1,1,1,1,1,1,1,1,1,3,36,36,43,43,3,61,0,0,55,3,1,1,1,1,1,1,1,1,1
1,1,1,1,1,1,1,1,1,3,36,36,60,59,3,58,0,0,37,3,1,1,1,1,1,1,1,1,1
1,1,1,1,1,1,1,1,1,3,36,36,36,57,3,51,56,0,55,3,1,1,1,1,1,1,1,1,1
1,1,1,1,1,1,1,1,1,3,36,36,36,54,3,53,0,52,0,3,1,1,1,1,1,1,1,1,1
1,1,1,1,1,1,1,1,1,3,36,36,36,51,3,3,0,0,3,3,1,1,1,1,1,1,1,1,1
1,1,1,1,1,1,1,1,1,3,36,36,36,0,0,0,0,0,50,3,1,1,1,1,1,1,1,1,1
1,1,1,1,1,1,1,1,1,3,36,36,36,0,0,0,49,0,0,3,1,1,1,1,1,1,1,1,1
1,1,1,1,1,1,1,1,1,3,36,36,43,43,0,48,47,46,0,3,1,1,1,1,1,1,1,1,1
1,1,1,1,1,1,1,1,1,3,36,36,43,43,45,0,44,0,0,3,1,1,1,1,1,1,1,1,1
1,1,1,1,1,1,1,1,1,3,36,36,43,43,4,42,0,0,0,3,1,1,1,1,1,1,1,1,1
1,1,1,1,1,1,1,1,1,3,36,36,36,4,4,4,41,41,41,3,1,1,1,1,1,1,1,1,1
1,1,1,1,1,1,1,1,1,3,36,36,36,40,4,37,39,38,37,3,1,1,1,1,1,1,1,1,1
1,1,1,1,1,1,1,1,1,3,36,36,36,3,35,3,3,3,3,3,1,1,1,1,1,1,1,1,1
1,1,1,1,1,1,1,1,1,3,33,34,33,0,32,31,30,29,3,3,1,1,1,1,1,1,1,1,1
1,1,1,1,1,1,1,1,1,3,28,0,27,26,23,23,25,24,3,3,1,1,1,1,1,1,1,1,1
1,1,1,1,1,1,1,1,1,1,3,19,0,0,23,23,22,21,3,1,1,1,1,1,1,1,1,1,1
1,1,1,1,1,1,1,1,1,1,3,5,0,20,19,5,0,18,3,1,1,1,1,1,1,1,1,1,1
1,1,1,1,1,1,1,1,1,1,1,3,17,0,0,16,0,3,1,1,1,1,1,1,1,1,1,1,1
1,1,1,1,1,1,1,1,1,1,1,3,15,14,13,12,11,3,1,1,1,1,1,1,1,1,1,1,1
1,1,1,1,1,1,1,1,1,1,1,1,3,10,9,8,3,1,1,1,1,1,1,1,1,1,1,1,1
1,1,1,1,1,1,1,1,1,1,1,1,3,7,0,6,3,1,1,1,1,1,1,1,1,1,1,1,1
1,1,1,1,1,1,1,1,1,1,1,1,1,3,5,3,1,1,1,1,1,1,1,1,1,1,1,1,1
1,1,1,1,1,1,1,1,1,1,1,1,1,3,4,3,1,1,1,1,1,1,1,1,1,1,1,1,1
1,1,1,1,1,1,1,1,1,1,1,1,1,1,3,1,1,1,1,1,1,1,1,1,1,1,1,1,1
1,1,1,1,1,1,1,1,1,1,1,1,1,1,3,1,1,1,1,1,1,1,1,1,1,1,1,1,1
1,1,1,1,1,1,1,1,1,1,1,1,1,1,1,1,1,1,1,1,1,1,1,1,1,1,1,1,1
1,1,1,1,1,1,1,1,1,1,1,1,1,1,1,1,1,1,1,1,1,1,1,1,1,1,1,1,1
1,1,1,1,1,1,1,1,1,1,1,1,1,1,1,1,1,1,1,1,1,1,1,1,1,1,1,1,1
1,1,1,1,1,1,1,1,1,1,1,1,1,1,1,1,1,1,1,1,1,1,1,1,1,1,1,1,1
1,1,1,1,1,1,1,1,1,1,1,1,1,1,1,1,1,1,1,1,1,1,1,1,1,1,1,1,1
1,1,1,1,1,1,1,1,1,1,1,1,1,1,1,1,1,1,1,1,1,1,1,1,1,1,1,1,1
1,1,1,1,1,1,1,1,1,1,1,1,1,1,1,1,1,1,1,1,1,1,1,1,1,1,1,1,1
1,1,1,1,1,1,1,1,1,1,1,1,1,1,1,1,1,1,1,1,1,1,1,1,1,1,1,1,1
1,1,1,1,1,1,1,1,1,1,1,1,1,1,1,1,1,1,1,1,1,1,1,1,1,1,1,1,1
1,1,1,1,1,1,1,1,1,1,1,1,1,1,1,1,1,1,1,1,1,1,1,1,1,1,1,1,1
1,1,1,1,1,1,1,1,1,1,1,1,1,1,1,1,1,1,1,1,1,1,1,1,1,1,1,1,1
1,1,1,1,1,1,1,1,1,1,1,1,1,1,1,1,1,1,1,1,1,1,1,1,1,1,1,1,1
1,1,1,1,1,1,1,1,1,1,1,1,1,1,1,1,1,1,1,1,1,1,1,1,1,1,1,1,1
1,1,1,1,1,1,1,1,1,1,1,1,1,1,1,1,1,1,1,1,1,1,1,1,1,1,1,1,1
1,1,1,1,1,1,1,1,1,1,1,1,1,1,1,1,1,1,1,1,1,1,1,1,1,1,1,1,1
1,1,1,1,1,1,1,1,1,1,1,1,1,1,1,1,1,1,1,1,1,1,1,1,1,1,1,1,1
1,1,1,1,1,1,1,1,1,1,1,1,1,1,1,1,1,1,1,1,1,1,1,1,1,1,1,1,1
1,1,1,1,1,1,1,1,1,1,1,1,1,1,1,1,1,1,1,1,1,1,1,1,1,1,1,1,1
1,1,1,1,1,1,1,1,1,1,1,1,1,1,1,1,1,1,1,1,1,1,1,1,1,1,1,1,1
1,1,1,1,1,1,1,1,1,1,1,1,1,1,1,1,1,1,1,1,1,1,1,1,1,1,1,1,1
1,1,1,1,1,1,1,1,1,1,1,1,1,1,1,1,1,1,1,1,1,1,1,1,1,1,1,1,1
:endlayer
layer: 4
1,1,1,1,1,1,1,1,1,1,1,1,1,1,1,1,1,1,1,1,1,1,1,1,1,1,1,1,1
1,1,1,1,1,1,1,1,1,1,1,1,1,1,1,1,1,1,1,1,1,1,1,1,1,1,1,1,1
1,1,1,1,1,1,1,1,1,1,1,1,1,1,1,1,1,1,1,1,1,1,1,1,1,1,1,1,1
1,1,1,1,1,1,1,1,1,1,1,1,1,1,1,1,1,1,1,1,1,1,1,1,1,1,1,1,1
1,1,1,1,1,1,1,1,1,1,1,1,1,1,1,1,1,1,1,1,1,1,1,1,1,1,1,1,1
1,1,1,1,1,1,1,1,1,1,1,1,1,1,1,1,1,1,1,1,1,1,1,1,1,1,1,1,1
1,1,1,1,1,1,1,1,1,1,1,1,1,1,1,1,1,1,1,1,1,1,1,1,1,1,1,1,1
1,1,1,1,1,1,1,1,1,1,1,1,1,1,2,1,1,1,1,1,1,1,1,1,1,1,1,1,1
1,1,1,1,1,1,1,1,1,1,1,1,1,1,2,1,1,1,1,1,1,1,1,1,1,1,1,1,1
1,1,1,1,1,1,1,1,1,1,1,1,1,1,2,1,1,1,1,1,1,1,1,1,1,1,1,1,1
1,1,1,1,1,1,1,1,1,1,1,1,3,3,3,3,3,1,1,1,1,1,1,1,1,1,1,1,1
1,1,1,1,1,1,1,1,1,1,3,3,68,252,4,251,250,3,3,1,1,1,1,1,1,1,1,1,1
1,1,1,1,1,1,1,1,1,3,68,0,0,4,4,4,0,249,248,3,1,1,1,1,1,1,1,1,1
1,1,1,1,1,1,1,1,3,68,0,0,0,0,4,118,0,0,0,247,3,1,1,1,1,1,1,1,1
1,1,1,1,1,1,1,1,68,0,0,0,0,0,0,0,51,51,51,3,3,1,1,1,1,1,1,1,1
1,1,1,1,1,1,1,1,68,0,0,0,0,0,0,0,0,0,0,118,100,1,1,1,1,1,1,1,1
1,1,1,1,1,1,1,1,3,3,238,0,0,51,0,0,0,0,0,0,100,1,1,1,1,1,1,1,1
1,1,1,1,1,1,1,1,68,0,0,0,0,0,0,0,51,51,51,51,3,1,1,1,1,1,1,1,1
1,1,1,1,1,1,1,1,68,0,0,0,0,0,0,0,0,0,0,0,100,1,1,1,1,1,1,1,1
1,1,1,1,1,1,1,1,68,0,0,0,0,0,0,0,0,0,0,0,100,1,1,1,1,1,1,1,1
1,1,1,1,1,1,1,1,68,0,0,0,0,0,0,0,51,51,51,51,3,1,1,1,1,1,1,1,1
1,1,1,1,1,1,1,1,68,0,0,0,0,0,0,0,0,0,0,0,100,1,1,1,1,1,1,1,1
1,1,1,1,1,1,1,1,3,3,238,0,0,51,0,0,0,0,0,0,100,1,1,1,1,1,1,1,1
1,1,1,1,1,1,1,1,3,246,0,0,0,0,0,0,51,51,51,3,3,1,1,1,1,1,1,1,1
1,1,1,1,1,1,1,1,3,245,0,0,0,0,4,0,0,0,0,244,3,1,1,1,1,1,1,1,1
1,1,1,1,1,1,1,1,3,3,0,0,3,4,4,4,3,3,3,3,3,1,1,1,1,1,1,1,1
1,1,1,1,1,1,1,1,3,243,0,0,242,0,4,0,0,0,0,241,3,1,1,1,1,1,1,1,1
1,1,1,1,1,1,1,1,3,240,0,0,0,0,0,0,0,0,0,239,3,1,1,1,1,1,1,1,1
1,1,1,1,1,1,1,1,3,3,238,66,0,0,0,0,0,0,237,3,3,1,1,1,1,1,1,1,1
1,1,1,1,1,1,1,1,3,0,66,66,66,0,0,0,0,0,0,0,3,1,1,1,1,1,1,1,1
1,1,1,1,1,1,1,1,3,0,0,66,0,0,0,0,0,0,0,0,3,1,1,1,1,1,1,1,1
1,1,1,1,1,1,1,1,3,0,0,160,0,0,0,160,0,0,0,0,3,1,1,1,1,1,1,1,1
1,1,1,1,1,1,1,1,3,3,3,3,0,0,0,3,3,3,3,3,3,1,1,1,1,1,1,1,1
1,1,1,1,1,1,1,1,3,236,0,186,0,0,0,186,70,0,0,211,3,1,1,1,1,1,1,1,1
1,1,1,1,1,1,1,1,3,235,0,0,0,0,0,0,226,0,69,3,3,1,1,1,1,1,1,1,1
1,1,1,1,1,1,1,1,3,212,234,0,0,0,0,224,70,0,0,223,3,1,1,1,1,1,1,1,1
1,1,1,1,1,1,1,1,3,233,0,0,0,0,0,0,66,0,0,221,3,1,1,1,1,1,1,1,1
1,1,1,1,1,1,1,1,3,232,0,0,0,0,4,0,66,66,66,66,3,1,1,1,1,1,1,1,1
1,1,1,1,1,1,1,1,3,212,231,0,0,4,4,4,66,211,0,219,3,1,1,1,1,1,1,1,1
1,1,1,1,1,1,1,1,3,230,211,0,0,0,4,224,70,0,0,216,3,1,1,1,1,1,1,1,1
1,1,1,1,1,1,1,1,3,229,0,0,0,0,0,0,228,0,69,3,3,1,1,1,1,1,1,1,1
1,1,1,1,1,1,1,1,3,212,0,0,0,0,0,0,70,66,66,66,3,1,1,1,1,1,1,1,1
1,1,1,1,1,1,1,1,3,227,0,0,0,0,0,0,226,0,0,211,3,1,1,1,1,1,1,1,1
1,1,1,1,1,1,1,1,3,225,0,0,0,0,0,224,70,0,69,3,3,1,1,1,1,1,1,1,1
1,1,1,1,1,1,1,1,3,212,0,0,0,0,0,0,66,0,0,223,3,1,1,1,1,1,1,1,1
1,1,1,1,1,1,1,1,3,222,0,0,211,78,78,78,66,0,0,221,3,1,1,1,1,1,1,1,1
1,1,1,1,1,1,1,1,3,220,0,0,0,75,75,75,66,66,66,66,3,1,1,1,1,1,1,1,1
1,1,1,1,1,1,1,1,3,212,0,0,0,0,0,0,70,0,0,219,3,1,1,1,1,1,1,1,1
1,1,1,1,1,1,1,1,3,218,0,0,3,0,0,0,217,0,0,216,3,1,1,1,1,1,1,1,1
1,1,1,1,1,1,1,1,3,215,0,0,214,3,0,213,70,0,69,3,3,1,1,1,1,1,1,1,1
1,1,1,1,1,1,1,1,3,212,0,0,0,0,4,0,66,0,0,211,3,1,1,1,1,1,1,1,1
1,1,1,1,1,1,1,1,3,3,0,0,3,4,4,4,3,3,3,3,3,1,1,1,1,1,1,1,1
1,1,1,1,1,1,1,1,3,186,132,138,186,51,4,51,210,209,51,208,3,1,1,1,1,1,1,1,1
1,1,1,1,1,1,1,1,3,207,132,138,206,205,3,51,0,0,0,204,3,1,1,1,1,1,1,1,1
1,1,1,1,1,1,1,1,3,203,132,138,202,201,3,200,0,0,0,199,3,1,1,1,1,1,1,1,1
1,1,1,1,1,1,1,1,3,198,132,0,135,135,3,197,0,0,196,195,3,1,1,1,1,1,1,1,1
1,1,1,1,1,1,1,1,3,194,132,0,193,0,3,51,0,0,0,192,3,1,1,1,1,1,1,1,1
1,1,1,1,1,1,1,1,3,191,132,0,0,0,3,160,0,0,160,190,3,1,1,1,1,1,1,1,1
1,1,1,1,1,1,1,1,3,189,132,0,0,51,3,3,0,0,3,3,3,1,1,1,1,1,1,1,1
1,1,1,1,1,1,1,1,3,188,132,187,0,0,0,186,0,0,138,185,3,1,1,1,1,1,1,1,1
1,1,1,1,1,1,1,1,3,184,132,0,126,126,0,0,183,0,138,182,3,1,1,1,1,1,1,1,1
1,1,1,1,1,1,1,1,3,181,132,138,180,179,132,0,178,177,138,176,3,1,1,1,1,1,1,1,1
1,1,1,1,1,1,1,1,3,175,132,138,174,173,132,0,172,0,138,171,3,1,1,1,1,1,1,1,1
1,1,1,1,1,1,1,1,3,170,132,138,169,168,4,0,0,0,138,167,3,1,1,1,1,1,1,1,1
1,1,1,1,1,1,1,1,3,166,132,0,135,4,4,4,0,0,138,165,3,1,1,1,1,1,1,1,1
1,1,1,1,1,1,1,1,3,160,132,164,163,160,4,160,162,161,138,160,3,1,1,1,1,1,1,1,1
1,1,1,1,1,1,1,1,3,3,0,0,0,3,159,3,3,3,3,3,3,1,1,1,1,1,1,1,1
1,1,1,1,1,1,1,1,3,158,156,157,156,0,126,126,155,138,154,153,3,1,1,1,1,1,1,1,1
1,1,1,1,1,1,1,1,3,152,126,126,0,138,151,150,132,138,149,148,3,1,1,1,1,1,1,1,1
1,1,1,1,1,1,1,1,1,3,147,146,132,138,145,144,132,138,143,3,1,1,1,1,1,1,1,1,1
1,1,1,1,1,1,1,1,1,3,142,141,132,138,140,139,132,138,137,3,1,1,1,1,1,1,1,1,1
1,1,1,1,1,1,1,1,1,1,3,136,132,0,135,135,0,134,3,1,1,1,1,1,1,1,1,1,1
1,1,1,1,1,1,1,1,1,1,3,133,132,0,0,0,0,131,3,1,1,1,1,1,1,1,1,1,1
1,1,1,1,1,1,1,1,1,1,1,3,130,129,0,0,128,3,1,1,1,1,1,1,1,1,1,1,1
1,1,1,1,1,1,1,1,1,1,1,3,127,126,126,126,125,3,1,1,1,1,1,1,1,1,1,1,1
1,1,1,1,1,1,1,1,1,1,1,1,3,124,123,122,3,1,1,1,1,1,1,1,1,1,1,1,1
1,1,1,1,1,1,1,1,1,1,1,1,3,121,4,120,3,1,1,1,1,1,1,1,1,1,1,1,1
1,1,1,1,1,1,1,1,1,1,1,1,1,3,4,3,1,1,1,1,1,1,1,1,1,1,1,1,1
1,1,1,1,1,1,1,1,1,1,1,1,1,3,4,3,1,1,1,1,1,1,1,1,1,1,1,1,1
1,1,1,1,1,1,1,1,1,1,1,1,1,1,3,1,1,1,1,1,1,1,1,1,1,1,1,1,1
1,1,1,1,1,1,1,1,1,1,1,1,1,1,3,1,1,1,1,1,1,1,1,1,1,1,1,1,1
1,1,1,1,1,1,1,1,1,1,1,1,1,1,1,1,1,1,1,1,1,1,1,1,1,1,1,1,1
1,1,1,1,1,1,1,1,1,1,1,1,1,1,1,1,1,1,1,1,1,1,1,1,1,1,1,1,1
1,1,1,1,1,1,1,1,1,1,1,1,1,1,1,1,1,1,1,1,1,1,1,1,1,1,1,1,1
1,1,1,1,1,1,1,1,1,1,1,1,1,1,1,1,1,1,1,1,1,1,1,1,1,1,1,1,1
1,1,1,1,1,1,1,1,1,1,1,1,1,1,1,1,1,1,1,1,1,1,1,1,1,1,1,1,1
1,1,1,1,1,1,1,1,1,1,1,1,1,1,1,1,1,1,1,1,1,1,1,1,1,1,1,1,1
1,1,1,1,1,1,1,1,1,1,1,1,1,1,1,1,1,1,1,1,1,1,1,1,1,1,1,1,1
1,1,1,1,1,1,1,1,1,1,1,1,1,1,1,1,1,1,1,1,1,1,1,1,1,1,1,1,1
1,1,1,1,1,1,1,1,1,1,1,1,1,1,1,1,1,1,1,1,1,1,1,1,1,1,1,1,1
1,1,1,1,1,1,1,1,1,1,1,1,1,1,1,1,1,1,1,1,1,1,1,1,1,1,1,1,1
1,1,1,1,1,1,1,1,1,1,1,1,1,1,1,1,1,1,1,1,1,1,1,1,1,1,1,1,1
1,1,1,1,1,1,1,1,1,1,1,1,1,1,1,1,1,1,1,1,1,1,1,1,1,1,1,1,1
1,1,1,1,1,1,1,1,1,1,1,1,1,1,1,1,1,1,1,1,1,1,1,1,1,1,1,1,1
1,1,1,1,1,1,1,1,1,1,1,1,1,1,1,1,1,1,1,1,1,1,1,1,1,1,1,1,1
1,1,1,1,1,1,1,1,1,1,1,1,1,1,1,1,1,1,1,1,1,1,1,1,1,1,1,1,1
1,1,1,1,1,1,1,1,1,1,1,1,1,1,1,1,1,1,1,1,1,1,1,1,1,1,1,1,1
1,1,1,1,1,1,1,1,1,1,1,1,1,1,1,1,1,1,1,1,1,1,1,1,1,1,1,1,1
1,1,1,1,1,1,1,1,1,1,1,1,1,1,1,1,1,1,1,1,1,1,1,1,1,1,1,1,1
1,1,1,1,1,1,1,1,1,1,1,1,1,1,1,1,1,1,1,1,1,1,1,1,1,1,1,1,1
:endlayer
layer: 5
1,1,1,1,1,1,1,1,1,1,1,1,1,1,1,1,1,1,1,1,1,1,1,1,1,1,1,1,1
1,1,1,1,1,1,1,1,1,1,1,1,1,1,1,1,1,1,1,1,1,1,1,1,1,1,1,1,1
1,1,1,1,1,1,1,1,1,1,1,1,1,1,1,1,1,1,1,1,1,1,1,1,1,1,1,1,1
1,1,1,1,1,1,1,1,1,1,1,1,1,1,1,1,1,1,1,1,1,1,1,1,1,1,1,1,1
1,1,1,1,1,1,1,1,1,1,1,1,1,1,1,1,1,1,1,1,1,1,1,1,1,1,1,1,1
1,1,1,1,1,1,1,1,1,1,1,1,1,1,1,1,1,1,1,1,1,1,1,1,1,1,1,1,1
1,1,1,1,1,1,1,1,1,1,1,1,1,1,1,1,1,1,1,1,1,1,1,1,1,1,1,1,1
1,1,1,1,1,1,1,1,1,1,1,1,1,1,1,1,1,1,1,1,1,1,1,1,1,1,1,1,1
1,1,1,1,1,1,1,1,1,1,1,1,1,1,2,1,1,1,1,1,1,1,1,1,1,1,1,1,1
1,1,1,1,1,1,1,1,1,1,1,1,1,1,2,1,1,1,1,1,1,1,1,1,1,1,1,1,1
1,1,1,1,1,1,1,1,1,1,1,3,3,3,3,3,3,3,1,1,1,1,1,1,1,1,1,1,1
1,1,1,1,1,1,1,1,1,3,3,68,0,255,4,260,260,3,3,3,1,1,1,1,1,1,1,1,1
1,1,1,1,1,1,1,1,3,68,0,0,0,4,4,4,0,260,260,3,3,1,1,1,1,1,1,1,1
1,1,1,1,1,1,1,3,68,0,0,0,0,51,4,0,0,0,0,255,3,3,1,1,1,1,1,1,1
1,1,1,1,1,1,1,3,0,0,0,0,0,51,186,0,51,51,51,3,3,3,1,1,1,1,1,1,1
1,1,1,1,1,1,1,3,0,0,0,0,0,51,0,0,51,0,0,0,0,3,1,1,1,1,1,1,1
1,1,1,1,1,1,1,3,3,3,51,51,51,51,0,0,51,0,0,0,237,3,1,1,1,1,1,1,1
1,1,1,1,1,1,1,3,0,0,0,0,0,51,0,0,51,51,51,51,51,3,1,1,1,1,1,1,1
1,1,1,1,1,1,1,3,0,0,0,0,0,51,0,0,51,0,0,0,0,3,1,1,1,1,1,1,1
1,1,1,1,1,1,1,3,0,0,0,0,0,51,0,0,51,0,0,0,237,3,1,1,1,1,1,1,1
1,1,1,1,1,1,1,3,0,0,0,0,0,51,0,0,51,51,51,51,51,3,1,1,1,1,1,1,1
1,1,1,1,1,1,1,3,0,0,0,0,0,51,0,0,51,0,0,0,0,3,1,1,1,1,1,1,1
1,1,1,1,1,1,1,3,3,3,51,51,51,51,0,0,51,0,0,0,237,3,1,1,1,1,1,1,1
1,1,1,1,1,1,1,3,3,256,0,0,0,0,160,0,51,51,51,3,3,3,1,1,1,1,1,1,1
1,1,1,1,1,1,1,3,3,256,0,0,0,0,4,0,0,0,0,255,3,3,1,1,1,1,1,1,1
1,1,1,1,1,1,1,3,3,3,256,255,3,4,4,4,3,3,3,3,3,3,1,1,1,1,1,1,1
1,1,1,1,1,1,1,3,3,256,0,0,0,0,4,0,0,0,0,255,3,3,1,1,1,1,1,1,1
1,1,1,1,1,1,1,3,3,256,0,0,0,0,186,0,0,0,0,255,3,3,1,1,1,1,1,1,1
1,1,1,1,1,1,1,3,3,3,0,0,0,0,0,0,0,0,0,3,3,3,1,1,1,1,1,1,1
1,1,1,1,1,1,1,3,3,256,0,0,0,0,0,0,0,0,0,255,3,3,1,1,1,1,1,1,1
1,1,1,1,1,1,1,3,3,256,0,0,0,0,0,0,0,0,0,255,3,3,1,1,1,1,1,1,1
1,1,1,1,1,1,1,3,3,256,0,0,0,0,0,0,0,0,0,255,3,3,1,1,1,1,1,1,1
1,1,1,1,1,1,1,3,3,3,3,3,256,261,255,3,3,3,3,3,3,3,1,1,1,1,1,1,1
1,1,1,1,1,1,1,3,3,263,0,0,0,0,0,0,70,0,0,0,3,3,1,1,1,1,1,1,1
1,1,1,1,1,1,1,3,3,263,0,0,0,0,0,0,70,0,69,3,3,3,1,1,1,1,1,1,1
1,1,1,1,1,1,1,3,3,263,0,0,0,0,0,0,70,0,0,223,3,3,1,1,1,1,1,1,1
1,1,1,1,1,1,1,3,3,263,0,0,0,0,160,0,66,0,0,221,3,3,1,1,1,1,1,1,1
1,1,1,1,1,1,1,3,3,263,0,0,0,0,4,0,66,66,66,66,3,3,1,1,1,1,1,1,1
1,1,1,1,1,1,1,3,3,263,0,0,0,4,4,4,66,0,0,219,3,3,1,1,1,1,1,1,1
1,1,1,1,1,1,1,3,3,263,0,0,0,0,4,0,70,0,0,216,3,3,1,1,1,1,1,1,1
1,1,1,1,1,1,1,3,3,263,0,0,0,0,186,0,70,0,69,3,3,3,1,1,1,1,1,1,1
1,1,1,1,1,1,1,3,3,263,0,0,0,0,0,0,70,66,66,66,3,3,1,1,1,1,1,1,1
1,1,1,1,1,1,1,3,3,263,0,0,0,0,0,0,70,0,0,0,3,3,1,1,1,1,1,1,1
1,1,1,1,1,1,1,3,3,263,0,0,0,0,0,0,70,0,69,3,3,3,1,1,1,1,1,1,1
1,1,1,1,1,1,1,3,3,263,0,0,0,0,0,0,66,0,0,223,3,3,1,1,1,1,1,1,1
1,1,1,1,1,1,1,3,3,263,0,0,0,0,0,0,66,0,0,221,3,3,1,1,1,1,1,1,1
1,1,1,1,1,1,1,3,3,263,0,0,0,78,78,78,66,66,66,66,3,3,1,1,1,1,1,1,1
1,1,1,1,1,1,1,3,3,263,0,0,262,75,75,75,70,0,0,219,3,3,1,1,1,1,1,1,1
1,1,1,1,1,1,1,3,3,263,0,0,3,0,0,0,70,0,0,216,3,3,1,1,1,1,1,1,1
1,1,1,1,1,1,1,3,3,263,0,0,0,3,160,0,70,0,69,3,3,3,1,1,1,1,1,1,1
1,1,1,1,1,1,1,3,3,263,0,0,0,255,4,0,66,0,0,0,3,3,1,1,1,1,1,1,1
1,1,1,1,1,1,1,3,3,3,256,255,3,4,4,4,3,3,3,3,3,3,1,1,1,1,1,1,1
1,1,1,1,1,1,1,3,3,257,0,0,258,51,4,260,261,261,260,255,3,3,1,1,1,1,1,1,1
1,1,1,1,1,1,1,3,3,257,0,0,258,0,3,256,0,0,0,255,3,3,1,1,1,1,1,1,1
1,1,1,1,1,1,1,3,3,257,0,0,258,259,3,261,0,0,0,255,3,3,1,1,1,1,1,1,1
1,1,1,1,1,1,1,3,3,257,0,0,0,0,3,261,0,0,0,255,3,3,1,1,1,1,1,1,1
1,1,1,1,1,1,1,3,3,257,0,0,0,0,3,256,0,0,0,255,3,3,1,1,1,1,1,1,1
1,1,1,1,1,1,1,3,3,257,0,0,0,0,3,262,261,261,262,255,3,3,1,1,1,1,1,1,1
1,1,1,1,1,1,1,3,3,257,0,0,0,51,3,3,256,255,3,3,3,3,1,1,1,1,1,1,1
1,1,1,1,1,1,1,3,3,257,0,0,0,0,0,0,0,0,0,258,3,3,1,1,1,1,1,1,1
1,1,1,1,1,1,1,3,3,257,0,0,0,0,0,0,0,0,0,258,3,3,1,1,1,1,1,1,1
1,1,1,1,1,1,1,3,3,257,0,0,258,254,0,0,0,0,0,258,3,3,1,1,1,1,1,1,1
1,1,1,1,1,1,1,3,3,257,0,0,258,257,0,0,0,0,0,258,3,3,1,1,1,1,1,1,1
1,1,1,1,1,1,1,3,3,257,0,0,259,257,4,0,0,0,0,258,3,3,1,1,1,1,1,1,1
1,1,1,1,1,1,1,3,3,257,0,0,0,4,4,4,0,0,0,258,3,3,1,1,1,1,1,1,1
1,1,1,1,1,1,1,3,3,257,0,0,0,0,4,0,0,0,0,258,3,3,1,1,1,1,1,1,1
1,1,1,1,1,1,1,3,3,3,256,261,255,3,260,3,3,3,3,3,3,3,1,1,1,1,1,1,1
1,1,1,1,1,1,1,3,3,256,156,156,156,0,0,0,0,0,258,253,3,3,1,1,1,1,1,1,1
1,1,1,1,1,1,1,3,3,256,0,0,0,0,258,254,0,0,258,253,3,3,1,1,1,1,1,1,1
1,1,1,1,1,1,1,1,3,3,254,257,0,0,258,257,0,0,258,3,3,1,1,1,1,1,1,1,1
1,1,1,1,1,1,1,1,3,3,253,257,0,0,259,257,0,0,258,3,3,1,1,1,1,1,1,1,1
1,1,1,1,1,1,1,1,1,3,3,257,0,0,0,0,0,255,3,3,1,1,1,1,1,1,1,1,1
1,1,1,1,1,1,1,1,1,3,3,257,0,0,0,0,0,255,3,3,1,1,1,1,1,1,1,1,1
1,1,1,1,1,1,1,1,1,1,3,3,256,0,0,0,255,3,3,1,1,1,1,1,1,1,1,1,1
1,1,1,1,1,1,1,1,1,1,3,3,256,0,0,0,255,3,3,1,1,1,1,1,1,1,1,1,1
1,1,1,1,1,1,1,1,1,1,1,3,3,254,254,254,3,3,1,1,1,1,1,1,1,1,1,1,1
1,1,1,1,1,1,1,1,1,1,1,3,3,253,4,253,3,3,1,1,1,1,1,1,1,1,1,1,1
1,1,1,1,1,1,1,1,1,1,1,1,3,4,4,4,3,1,1,1,1,1,1,1,1,1,1,1,1
1,1,1,1,1,1,1,1,1,1,1,1,3,3,4,3,3,1,1,1,1,1,1,1,1,1,1,1,1
1,1,1,1,1,1,1,1,1,1,1,1,1,3,3,3,1,1,1,1,1,1,1,1,1,1,1,1,1
1,1,1,1,1,1,1,1,1,1,1,1,1,3,3,3,1,1,1,1,1,1,1,1,1,1,1,1,1
1,1,1,1,1,1,1,1,1,1,1,1,1,1,3,1,1,1,1,1,1,1,1,1,1,1,1,1,1
1,1,1,1,1,1,1,1,1,1,1,1,1,1,3,1,1,1,1,1,1,1,1,1,1,1,1,1,1
1,1,1,1,1,1,1,1,1,1,1,1,1,1,1,1,1,1,1,1,1,1,1,1,1,1,1,1,1
1,1,1,1,1,1,1,1,1,1,1,1,1,1,1,1,1,1,1,1,1,1,1,1,1,1,1,1,1
1,1,1,1,1,1,1,1,1,1,1,1,1,1,1,1,1,1,1,1,1,1,1,1,1,1,1,1,1
1,1,1,1,1,1,1,1,1,1,1,1,1,1,1,1,1,1,1,1,1,1,1,1,1,1,1,1,1
1,1,1,1,1,1,1,1,1,1,1,1,1,1,1,1,1,1,1,1,1,1,1,1,1,1,1,1,1
1,1,1,1,1,1,1,1,1,1,1,1,1,1,1,1,1,1,1,1,1,1,1,1,1,1,1,1,1
1,1,1,1,1,1,1,1,1,1,1,1,1,1,1,1,1,1,1,1,1,1,1,1,1,1,1,1,1
1,1,1,1,1,1,1,1,1,1,1,1,1,1,1,1,1,1,1,1,1,1,1,1,1,1,1,1,1
1,1,1,1,1,1,1,1,1,1,1,1,1,1,1,1,1,1,1,1,1,1,1,1,1,1,1,1,1
1,1,1,1,1,1,1,1,1,1,1,1,1,1,1,1,1,1,1,1,1,1,1,1,1,1,1,1,1
1,1,1,1,1,1,1,1,1,1,1,1,1,1,1,1,1,1,1,1,1,1,1,1,1,1,1,1,1
1,1,1,1,1,1,1,1,1,1,1,1,1,1,1,1,1,1,1,1,1,1,1,1,1,1,1,1,1
1,1,1,1,1,1,1,1,1,1,1,1,1,1,1,1,1,1,1,1,1,1,1,1,1,1,1,1,1
1,1,1,1,1,1,1,1,1,1,1,1,1,1,1,1,1,1,1,1,1,1,1,1,1,1,1,1,1
1,1,1,1,1,1,1,1,1,1,1,1,1,1,1,1,1,1,1,1,1,1,1,1,1,1,1,1,1
1,1,1,1,1,1,1,1,1,1,1,1,1,1,1,1,1,1,1,1,1,1,1,1,1,1,1,1,1
1,1,1,1,1,1,1,1,1,1,1,1,1,1,1,1,1,1,1,1,1,1,1,1,1,1,1,1,1
:endlayer
layer: 6
1,1,1,1,1,1,1,1,1,1,1,1,1,1,1,1,1,1,1,1,1,1,1,1,1,1,1,1,1
1,1,1,1,1,1,1,1,1,1,1,1,1,1,1,1,1,1,1,1,1,1,1,1,1,1,1,1,1
1,1,1,1,1,1,1,1,1,1,1,1,1,1,1,1,1,1,1,1,1,1,1,1,1,1,1,1,1
1,1,1,1,1,1,1,1,1,1,1,1,1,1,1,1,1,1,1,1,1,1,1,1,1,1,1,1,1
1,1,1,1,1,1,1,1,1,1,1,1,1,1,1,1,1,1,1,1,1,1,1,1,1,1,1,1,1
1,1,1,1,1,1,1,1,1,1,1,1,1,1,1,1,1,1,1,1,1,1,1,1,1,1,1,1,1
1,1,1,1,1,1,1,1,1,1,1,1,1,1,1,1,1,1,1,1,1,1,1,1,1,1,1,1,1
1,1,1,1,1,1,1,1,1,1,1,1,1,1,1,1,1,1,1,1,1,1,1,1,1,1,1,1,1
1,1,1,1,1,1,1,1,1,1,1,1,1,1,1,1,1,1,1,1,1,1,1,1,1,1,1,1,1
1,1,1,1,1,1,1,1,1,1,1,3,3,3,3,3,3,3,1,1,1,1,1,1,1,1,1,1,1
1,1,1,1,1,1,1,1,1,3,3,264,264,264,264,264,264,264,3,3,1,1,1,1,1,1,1,1,1
1,1,1,1,1,1,1,1,3,264,264,264,264,264,4,264,264,264,264,264,3,1,1,1,1,1,1,1,1
1,1,1,1,1,1,1,1,3,264,264,264,264,4,4,4,264,264,264,264,3,1,1,1,1,1,1,1,1
1,1,1,1,1,1,1,3,264,264,264,264,264,264,4,264,264,264,264,264,264,3,1,1,1,1,1,1,1
1,1,1,1,1,1,1,3,264,264,264,264,264,264,264,264,264,264,264,264,264,3,1,1,1,1,1,1,1
1,1,1,1,1,1,1,3,264,264,264,264,264,264,264,264,264,264,264,264,264,3,1,1,1,1,1,1,1
1,1,1,1,1,1,1,3,264,264,264,264,264,264,264,264,264,264,264,264,264,3,1,1,1,1,1,1,1
1,1,1,1,1,1,1,3,264,264,264,264,264,264,264,264,264,264,264,264,264,3,1,1,1,1,1,1,1
1,1,1,1,1,1,1,3,264,264,264,264,264,264,264,264,264,264,264,264,264,3,1,1,1,1,1,1,1
1,1,1,1,1,1,1,3,264,264,264,264,264,264,264,264,264,264,264,264,264,3,1,1,1,1,1,1,1
1,1,1,1,1,1,1,3,264,264,264,264,264,264,264,264,264,264,264,264,264,3,1,1,1,1,1,1,1
1,1,1,1,1,1,1,3,264,264,264,264,264,264,264,264,264,264,264,264,264,3,1,1,1,1,1,1,1
1,1,1,1,1,1,1,3,264,264,264,264,264,264,264,264,264,264,264,264,264,3,1,1,1,1,1,1,1
1,1,1,1,1,1,1,3,264,264,264,264,264,264,264,264,264,264,264,264,264,3,1,1,1,1,1,1,1
1,1,1,1,1,1,1,3,264,264,264,264,264,264,4,264,264,264,264,264,264,3,1,1,1,1,1,1,1
1,1,1,1,1,1,1,3,264,264,264,264,264,4,4,4,264,264,264,264,264,3,1,1,1,1,1,1,1
1,1,1,1,1,1,1,3,264,264,264,264,264,264,4,264,264,264,264,264,264,3,1,1,1,1,1,1,1
1,1,1,1,1,1,1,3,264,264,264,264,264,264,264,264,264,264,264,264,264,3,1,1,1,1,1,1,1
1,1,1,1,1,1,1,3,264,264,264,264,264,264,264,264,264,264,264,264,264,3,1,1,1,1,1,1,1
1,1,1,1,1,1,1,3,264,264,264,264,264,264,264,264,264,264,264,264,264,3,1,1,1,1,1,1,1
1,1,1,1,1,1,1,3,264,264,264,264,264,264,264,264,264,264,264,264,264,3,1,1,1,1,1,1,1
1,1,1,1,1,1,1,3,264,264,264,264,264,264,264,264,264,264,264,264,264,3,1,1,1,1,1,1,1
1,1,1,1,1,1,1,3,264,264,264,264,264,264,264,264,264,264,264,264,264,3,1,1,1,1,1,1,1
1,1,1,1,1,1,1,3,264,264,264,264,264,264,264,264,264,264,264,264,264,3,1,1,1,1,1,1,1
1,1,1,1,1,1,1,3,264,264,264,264,264,264,264,264,264,264,264,264,264,3,1,1,1,1,1,1,1
1,1,1,1,1,1,1,3,264,264,264,264,264,264,264,264,264,264,264,264,264,3,1,1,1,1,1,1,1
1,1,1,1,1,1,1,3,264,264,264,264,264,264,264,264,264,264,264,264,264,3,1,1,1,1,1,1,1
1,1,1,1,1,1,1,3,264,264,264,264,264,264,4,264,264,264,264,264,264,3,1,1,1,1,1,1,1
1,1,1,1,1,1,1,3,264,264,264,264,264,4,4,4,264,264,264,264,264,3,1,1,1,1,1,1,1
1,1,1,1,1,1,1,3,264,264,264,264,264,264,4,264,264,264,264,264,264,3,1,1,1,1,1,1,1
1,1,1,1,1,1,1,3,264,264,264,264,264,264,264,264,264,264,264,264,264,3,1,1,1,1,1,1,1
1,1,1,1,1,1,1,3,264,264,264,264,264,264,264,264,264,264,264,264,264,3,1,1,1,1,1,1,1
1,1,1,1,1,1,1,3,264,264,264,264,264,75,75,75,3,264,264,264,264,3,1,1,1,1,1,1,1
1,1,1,1,1,1,1,3,264,264,264,264,264,0,0,0,3,264,264,264,264,3,1,1,1,1,1,1,1
1,1,1,1,1,1,1,3,264,264,264,264,264,0,0,0,3,264,264,264,264,3,1,1,1,1,1,1,1
1,1,1,1,1,1,1,3,264,264,264,264,264,0,0,0,3,264,264,264,264,3,1,1,1,1,1,1,1
1,1,1,1,1,1,1,3,264,264,264,264,264,0,0,0,3,264,264,264,264,3,1,1,1,1,1,1,1
1,1,1,1,1,1,1,3,264,264,264,264,264,78,78,78,3,264,264,264,264,3,1,1,1,1,1,1,1
1,1,1,1,1,1,1,3,264,264,264,264,264,264,264,264,264,264,264,264,264,3,1,1,1,1,1,1,1
1,1,1,1,1,1,1,3,264,264,264,264,264,264,264,264,264,264,264,264,264,3,1,1,1,1,1,1,1
1,1,1,1,1,1,1,3,264,264,264,264,264,264,4,264,264,264,264,264,264,3,1,1,1,1,1,1,1
1,1,1,1,1,1,1,3,264,264,264,264,264,4,4,4,264,264,264,264,264,3,1,1,1,1,1,1,1
1,1,1,1,1,1,1,3,264,264,264,264,264,264,4,264,264,264,264,264,264,3,1,1,1,1,1,1,1
1,1,1,1,1,1,1,3,264,264,264,264,264,264,264,264,264,264,264,264,264,3,1,1,1,1,1,1,1
1,1,1,1,1,1,1,3,264,264,264,264,264,264,264,264,264,264,264,264,264,3,1,1,1,1,1,1,1
1,1,1,1,1,1,1,3,264,264,264,264,264,264,264,264,264,264,264,264,264,3,1,1,1,1,1,1,1
1,1,1,1,1,1,1,3,264,264,264,264,264,264,264,264,264,264,264,264,264,3,1,1,1,1,1,1,1
1,1,1,1,1,1,1,3,264,264,264,264,264,264,264,264,264,264,264,264,264,3,1,1,1,1,1,1,1
1,1,1,1,1,1,1,3,264,264,264,264,264,264,264,264,264,264,264,264,264,3,1,1,1,1,1,1,1
1,1,1,1,1,1,1,3,264,264,264,264,264,264,264,264,264,264,264,264,264,3,1,1,1,1,1,1,1
1,1,1,1,1,1,1,3,264,264,264,264,264,264,264,264,264,264,264,264,264,3,1,1,1,1,1,1,1
1,1,1,1,1,1,1,3,264,264,264,264,264,264,264,264,264,264,264,264,264,3,1,1,1,1,1,1,1
1,1,1,1,1,1,1,3,264,264,264,264,264,264,264,264,264,264,264,264,264,3,1,1,1,1,1,1,1
1,1,1,1,1,1,1,3,264,264,264,264,264,264,4,264,264,264,264,264,264,3,1,1,1,1,1,1,1
1,1,1,1,1,1,1,3,264,264,264,264,264,4,4,4,264,264,264,264,264,3,1,1,1,1,1,1,1
1,1,1,1,1,1,1,3,264,264,264,264,264,264,4,264,264,264,264,264,264,3,1,1,1,1,1,1,1
1,1,1,1,1,1,1,3,264,264,264,264,264,264,264,264,264,264,264,264,264,3,1,1,1,1,1,1,1
1,1,1,1,1,1,1,3,264,264,264,264,264,264,264,264,264,264,264,264,3,3,1,1,1,1,1,1,1
1,1,1,1,1,1,1,3,264,264,264,264,264,264,264,264,264,264,264,264,3,3,1,1,1,1,1,1,1
1,1,1,1,1,1,1,3,264,264,264,264,264,264,264,264,264,264,264,264,264,3,1,1,1,1,1,1,1
1,1,1,1,1,1,1,3,3,264,264,264,264,264,264,264,264,264,264,264,3,3,1,1,1,1,1,1,1
1,1,1,1,1,1,1,1,3,264,264,264,264,264,264,264,264,264,264,264,3,1,1,1,1,1,1,1,1
1,1,1,1,1,1,1,1,3,3,264,264,264,264,264,264,264,264,264,3,3,1,1,1,1,1,1,1,1
1,1,1,1,1,1,1,1,1,3,264,264,264,264,264,264,264,264,264,3,1,1,1,1,1,1,1,1,1
1,1,1,1,1,1,1,1,1,3,3,264,264,264,264,264,264,264,3,3,1,1,1,1,1,1,1,1,1
1,1,1,1,1,1,1,1,1,1,3,264,264,264,264,264,264,264,3,1,1,1,1,1,1,1,1,1,1
1,1,1,1,1,1,1,1,1,1,3,3,3,3,4,3,3,3,3,1,1,1,1,1,1,1,1,1,1
1,1,1,1,1,1,1,1,1,1,1,3,3,4,4,4,3,3,1,1,1,1,1,1,1,1,1,1,1
1,1,1,1,1,1,1,1,1,1,1,3,3,3,4,3,3,3,1,1,1,1,1,1,1,1,1,1,1
1,1,1,1,1,1,1,1,1,1,1,1,3,3,3,3,3,1,1,1,1,1,1,1,1,1,1,1,1
1,1,1,1,1,1,1,1,1,1,1,1,3,3,3,3,3,1,1,1,1,1,1,1,1,1,1,1,1
1,1,1,1,1,1,1,1,1,1,1,1,1,3,3,3,1,1,1,1,1,1,1,1,1,1,1,1,1
1,1,1,1,1,1,1,1,1,1,1,1,1,3,3,3,1,1,1,1,1,1,1,1,1,1,1,1,1
1,1,1,1,1,1,1,1,1,1,1,1,1,1,3,1,1,1,1,1,1,1,1,1,1,1,1,1,1
1,1,1,1,1,1,1,1,1,1,1,1,1,1,3,1,1,1,1,1,1,1,1,1,1,1,1,1,1
1,1,1,1,1,1,1,1,1,1,1,1,1,1,1,1,1,1,1,1,1,1,1,1,1,1,1,1,1
1,1,1,1,1,1,1,1,1,1,1,1,1,1,1,1,1,1,1,1,1,1,1,1,1,1,1,1,1
1,1,1,1,1,1,1,1,1,1,1,1,1,1,1,1,1,1,1,1,1,1,1,1,1,1,1,1,1
1,1,1,1,1,1,1,1,1,1,1,1,1,1,1,1,1,1,1,1,1,1,1,1,1,1,1,1,1
1,1,1,1,1,1,1,1,1,1,1,1,1,1,1,1,1,1,1,1,1,1,1,1,1,1,1,1,1
1,1,1,1,1,1,1,1,1,1,1,1,1,1,1,1,1,1,1,1,1,1,1,1,1,1,1,1,1
1,1,1,1,1,1,1,1,1,1,1,1,1,1,1,1,1,1,1,1,1,1,1,1,1,1,1,1,1
1,1,1,1,1,1,1,1,1,1,1,1,1,1,1,1,1,1,1,1,1,1,1,1,1,1,1,1,1
1,1,1,1,1,1,1,1,1,1,1,1,1,1,1,1,1,1,1,1,1,1,1,1,1,1,1,1,1
1,1,1,1,1,1,1,1,1,1,1,1,1,1,1,1,1,1,1,1,1,1,1,1,1,1,1,1,1
1,1,1,1,1,1,1,1,1,1,1,1,1,1,1,1,1,1,1,1,1,1,1,1,1,1,1,1,1
1,1,1,1,1,1,1,1,1,1,1,1,1,1,1,1,1,1,1,1,1,1,1,1,1,1,1,1,1
1,1,1,1,1,1,1,1,1,1,1,1,1,1,1,1,1,1,1,1,1,1,1,1,1,1,1,1,1
1,1,1,1,1,1,1,1,1,1,1,1,1,1,1,1,1,1,1,1,1,1,1,1,1,1,1,1,1
1,1,1,1,1,1,1,1,1,1,1,1,1,1,1,1,1,1,1,1,1,1,1,1,1,1,1,1,1
:endlayer
layer: 7
0,0,0,0,0,0,0,0,0,0,0,0,0,0,0,0,0,0,0,0,0,0,0,0,0,0,0,0,0
0,0,0,0,0,0,0,0,0,0,0,0,0,0,0,0,0,0,0,0,0,0,0,0,0,0,0,0,0
0,0,0,0,0,0,0,0,0,0,0,0,0,0,0,0,0,0,0,0,0,0,0,0,0,0,0,0,0
0,0,0,0,0,0,0,0,0,0,0,0,0,0,0,0,0,0,0,0,0,0,0,0,0,0,0,0,0
0,0,0,0,0,0,0,0,0,0,0,0,0,0,0,0,0,0,0,0,0,0,0,0,0,0,0,0,0
0,0,0,0,0,0,0,0,0,0,0,0,0,0,0,0,0,0,0,0,0,0,0,0,0,0,0,0,0
0,0,0,0,0,0,0,0,0,0,0,0,0,0,0,0,0,0,0,0,0,0,0,0,0,0,0,0,0
0,0,0,0,0,0,0,0,0,0,0,0,0,0,0,0,0,0,0,0,0,0,0,0,0,0,0,0,0
0,0,0,0,0,0,0,0,0,0,0,0,261,3,3,3,261,0,0,0,0,0,0,0,0,0,0,0,0
0,0,0,0,0,0,0,0,0,255,3,3,3,458,457,456,3,3,3,256,0,0,0,0,0,0,0,0,0
0,0,0,0,0,0,0,255,3,3,455,0,454,0,0,0,0,0,453,3,3,256,0,0,0,0,0,0,0
0,0,0,0,0,0,0,3,452,0,0,0,0,0,4,451,0,450,0,0,449,3,0,0,0,0,0,0,0
0,0,0,0,0,0,261,3,448,0,412,0,0,4,4,4,0,0,412,0,447,3,261,0,0,0,0,0,0
0,0,0,0,0,0,3,446,0,0,0,445,0,429,4,0,0,0,0,0,0,444,3,0,0,0,0,0,0
0,0,0,0,0,0,3,443,422,422,442,0,422,422,422,422,422,0,441,0,0,440,3,0,0,0,0,0,0
0,0,0,0,0,0,3,412,422,422,0,0,422,43,43,43,422,0,0,0,0,0,3,0,0,0,0,0,0
0,0,0,0,0,0,3,412,422,422,412,439,422,43,43,43,422,0,412,0,438,412,3,0,0,0,0,0,0
0,0,0,0,0,0,3,412,422,422,437,436,422,43,43,43,422,0,0,0,0,23,3,0,0,0,0,0,0
0,0,0,0,0,0,3,412,422,422,435,0,422,43,43,43,422,0,434,433,432,23,3,0,0,0,0,0,0
0,0,0,0,0,0,3,412,422,422,0,0,422,43,43,43,422,0,0,0,0,23,3,0,0,0,0,0,0
0,0,0,0,0,0,3,431,422,422,412,430,422,43,43,43,422,429,412,428,0,412,3,0,0,0,0,0,0
0,0,0,0,0,0,3,427,0,0,0,426,422,43,43,43,422,0,0,0,0,425,3,0,0,0,0,0,0
0,0,0,0,0,0,3,424,0,0,423,0,422,422,422,422,422,0,0,0,0,421,3,0,0,0,0,0,0
0,0,0,0,0,0,3,420,419,418,0,417,417,417,0,0,0,0,416,0,0,415,3,0,0,0,0,0,0
0,0,0,0,0,0,3,413,414,413,412,411,411,411,4,410,0,0,0,0,409,408,3,0,0,0,0,0,0
0,0,0,0,0,0,3,3,3,3,3,3,3,4,4,4,3,0,407,0,3,3,3,0,0,0,0,0,0
0,0,0,0,0,0,3,406,0,405,404,260,403,402,4,401,400,0,0,0,0,65,3,0,0,0,0,0,0
0,0,0,0,0,0,3,399,398,0,0,0,0,0,0,0,0,0,0,0,0,386,3,0,0,0,0,0,0
0,0,0,0,0,0,3,3,319,0,69,3,397,3,319,0,396,0,395,0,0,65,3,0,0,0,0,0,0
0,0,0,0,0,0,3,322,321,0,326,325,3,322,321,0,69,3,394,3,319,0,3,0,0,0,0,0,0
0,0,0,0,0,0,3,322,321,393,326,325,3,322,321,0,326,325,3,322,321,0,3,0,0,0,0,0,0
0,0,0,0,0,0,3,322,321,0,326,325,3,322,321,0,326,325,3,322,321,392,3,0,0,0,0,0,0
0,0,0,0,0,0,3,322,321,0,326,325,3,322,321,0,326,325,3,322,321,0,3,0,0,0,0,0,0
0,0,0,0,0,0,3,322,321,391,326,325,3,322,321,0,69,3,390,3,319,0,3,0,0,0,0,0,0
0,0,0,0,0,0,3,3,319,0,69,3,389,3,319,0,0,388,0,0,0,65,3,0,0,0,0,0,0
0,0,0,0,0,0,3,387,0,0,0,0,0,0,0,0,0,0,0,0,0,386,3,0,0,0,0,0,0
0,0,0,0,0,0,3,3,3,3,3,3,308,309,385,384,0,0,383,0,0,65,3,0,0,0,0,0,0
0,0,0,0,0,0,3,212,382,381,212,380,3,307,4,3,3,0,0,0,3,3,3,0,0,0,0,0,0
0,0,0,0,0,0,3,379,0,0,378,377,3,4,4,4,376,0,0,0,326,325,3,0,0,0,0,0,0
0,0,0,0,0,0,3,375,0,37,0,374,3,373,4,372,0,0,371,0,326,325,3,0,0,0,0,0,0
0,0,0,0,0,0,3,212,0,37,0,370,3,0,0,369,0,0,0,0,326,325,3,0,0,0,0,0,0
0,0,0,0,0,0,3,368,0,37,0,0,3,0,0,0,55,37,55,0,326,325,3,0,0,0,0,0,0
0,0,0,0,0,0,3,367,0,366,0,212,3,78,78,78,51,365,0,0,326,325,3,0,0,0,0,0,0
0,0,0,0,0,0,3,212,0,37,364,363,3,75,75,75,51,0,0,0,326,325,3,0,0,0,0,0,0
0,0,0,0,0,0,3,362,0,37,0,361,3,0,0,0,51,55,0,0,69,3,3,0,0,0,0,0,0
0,0,0,0,0,0,3,360,0,37,0,212,3,0,0,0,51,37,0,0,326,325,3,0,0,0,0,0,0
0,0,0,0,0,0,3,212,0,37,0,359,3,0,0,0,51,55,0,0,326,325,3,0,0,0,0,0,0
0,0,0,0,0,0,3,358,0,37,0,357,3,0,0,0,51,0,0,356,326,325,3,0,0,0,0,0,0
0,0,0,0,0,0,3,355,0,0,0,212,3,0,354,0,0,353,0,0,326,325,3,0,0,0,0,0,0
0,0,0,0,0,0,3,212,0,0,0,352,3,55,0,0,0,0,0,0,326,325,3,0,0,0,0,0,0
0,0,0,0,0,0,3,351,0,0,0,350,3,349,4,348,347,0,0,0,326,325,3,0,0,0,0,0,0
0,0,0,0,0,0,3,346,212,345,344,212,3,4,4,4,3,0,343,0,3,3,3,0,0,0,0,0,0
0,0,0,0,0,0,3,3,3,3,3,3,342,341,4,340,0,0,0,0,55,339,3,0,0,0,0,0,0
0,0,0,0,0,0,3,3,319,338,37,55,0,0,0,0,36,36,0,336,37,37,3,0,0,0,0,0,0
0,0,0,0,0,0,3,322,321,0,55,0,337,0,0,0,36,36,0,336,37,37,3,0,0,0,0,0,0
0,0,0,0,0,0,3,322,321,0,0,0,0,0,0,0,36,36,0,336,37,37,3,0,0,0,0,0,0
0,0,0,0,0,0,3,322,321,0,0,335,69,3,3,0,0,0,0,0,55,334,3,0,0,0,0,0,0
0,0,0,0,0,0,3,322,321,0,55,0,326,325,3,3,3,0,0,0,3,3,3,0,0,0,0,0,0
0,0,0,0,0,0,3,322,321,0,37,0,326,325,3,43,333,0,0,0,332,43,3,0,0,0,0,0,0
0,0,0,0,0,0,3,3,319,0,55,0,326,325,3,43,0,74,331,323,0,43,3,0,0,0,0,0,0
0,0,0,0,0,0,3,322,321,0,0,0,326,325,3,43,0,0,0,0,0,43,3,0,0,0,0,0,0
0,0,0,0,0,0,3,322,321,330,0,0,326,325,3,43,329,74,0,323,0,43,3,0,0,0,0,0,0
0,0,0,0,0,0,3,322,321,0,55,0,326,325,3,43,328,0,0,0,0,43,3,0,0,0,0,0,0
0,0,0,0,0,0,3,322,321,0,327,0,326,325,4,43,324,0,0,323,0,43,3,0,0,0,0,0,0
0,0,0,0,0,0,3,322,321,0,320,0,69,4,4,4,314,0,0,0,0,43,3,0,0,0,0,0,0
0,0,0,0,0,0,3,3,319,0,37,0,318,317,4,316,3,315,0,0,0,314,3,0,0,0,0,0,0
0,0,0,0,0,0,3,313,0,0,0,0,0,0,312,0,0,0,0,311,311,311,3,0,0,0,0,0,0
0,0,0,0,0,0,3,310,309,309,309,308,0,0,0,0,0,0,0,304,1,1,3,0,0,0,0,0,0
0,0,0,0,0,0,3,3,307,307,307,3,306,0,0,0,305,0,0,304,1,1,3,0,0,0,0,0,0
0,0,0,0,0,0,3,3,3,3,3,3,3,0,303,0,3,3,3,3,3,3,3,0,0,0,0,0,0
0,0,0,0,0,0,3,3,302,301,289,0,278,0,0,280,293,288,284,298,300,3,3,0,0,0,0,0,0
0,0,0,0,0,0,261,3,299,0,0,295,290,295,0,0,280,0,298,290,297,3,261,0,0,0,0,0,0
0,0,0,0,0,0,0,3,3,296,0,295,290,290,294,0,289,293,288,292,3,3,0,0,0,0,0,0,0
0,0,0,0,0,0,0,261,3,291,289,0,290,0,0,289,0,288,288,287,3,261,0,0,0,0,0,0,0
0,0,0,0,0,0,0,0,3,3,286,0,285,280,284,283,0,278,282,3,3,0,0,0,0,0,0,0,0
0,0,0,0,0,0,0,0,261,3,281,280,0,279,279,279,0,278,277,3,261,0,0,0,0,0,0,0,0
0,0,0,0,0,0,0,0,0,3,3,3,276,3,4,3,275,3,3,3,0,0,0,0,0,0,0,0,0
0,0,0,0,0,0,0,0,0,261,3,274,0,4,4,4,0,273,3,261,0,0,0,0,0,0,0,0,0
0,0,0,0,0,0,0,0,0,0,3,3,0,0,4,0,0,3,3,0,0,0,0,0,0,0,0,0,0
0,0,0,0,0,0,0,0,0,0,261,3,272,0,0,0,272,3,261,0,0,0,0,0,0,0,0,0,0
0,0,0,0,0,0,0,0,0,0,0,3,3,271,0,270,3,3,0,0,0,0,0,0,0,0,0,0,0
0,0,0,0,0,0,0,0,0,0,0,261,3,269,0,268,3,261,0,0,0,0,0,0,0,0,0,0,0
0,0,0,0,0,0,0,0,0,0,0,0,3,3,0,3,3,0,0,0,0,0,0,0,0,0,0,0,0
0,0,0,0,0,0,0,0,0,0,0,0,261,3,267,3,261,0,0,0,0,0,0,0,0,0,0,0,0
0,0,0,0,0,0,0,0,0,0,0,0,0,3,266,3,0,0,0,0,0,0,0,0,0,0,0,0,0
0,0,0,0,0,0,0,0,0,0,0,0,0,261,3,261,0,0,0,0,0,0,0,0,0,0,0,0,0
0,0,0,0,0,0,0,0,0,0,0,0,0,0,3,0,0,0,0,0,0,0,0,0,0,0,0,0,0
0,0,0,0,0,0,0,0,0,0,0,0,0,0,265,0,0,0,0,0,0,0,0,0,0,0,0,0,0
0,0,0,0,0,0,0,0,0,0,0,0,0,0,0,0,0,0,0,0,0,0,0,0,0,0,0,0,0
0,0,0,0,0,0,0,0,0,0,0,0,0,0,0,0,0,0,0,0,0,0,0,0,0,0,0,0,0
0,0,0,0,0,0,0,0,0,0,0,0,0,0,0,0,0,0,0,0,0,0,0,0,0,0,0,0,0
0,0,0,0,0,0,0,0,0,0,0,0,0,0,0,0,0,0,0,0,0,0,0,0,0,0,0,0,0
0,0,0,0,0,0,0,0,0,0,0,0,0,0,0,0,0,0,0,0,0,0,0,0,0,0,0,0,0
0,0,0,0,0,0,0,0,0,0,0,0,0,0,0,0,0,0,0,0,0,0,0,0,0,0,0,0,0
0,0,0,0,0,0,0,0,0,0,0,0,0,0,0,0,0,0,0,0,0,0,0,0,0,0,0,0,0
0,0,0,0,0,0,0,0,0,0,0,0,0,0,0,0,0,0,0,0,0,0,0,0,0,0,0,0,0
0,0,0,0,0,0,0,0,0,0,0,0,0,0,0,0,0,0,0,0,0,0,0,0,0,0,0,0,0
0,0,0,0,0,0,0,0,0,0,0,0,0,0,0,0,0,0,0,0,0,0,0,0,0,0,0,0,0
0,0,0,0,0,0,0,0,0,0,0,0,0,0,0,0,0,0,0,0,0,0,0,0,0,0,0,0,0
0,0,0,0,0,0,0,0,0,0,0,0,0,0,0,0,0,0,0,0,0,0,0,0,0,0,0,0,0
:endlayer
layer: 8
0,0,0,0,0,0,0,0,0,0,0,0,0,0,0,0,0,0,0,0,0,0,0,0,0,0,0,0,0
0,0,0,0,0,0,0,0,0,0,0,0,0,0,0,0,0,0,0,0,0,0,0,0,0,0,0,0,0
0,0,0,0,0,0,0,0,0,0,0,0,0,0,0,0,0,0,0,0,0,0,0,0,0,0,0,0,0
0,0,0,0,0,0,0,0,0,0,0,0,0,0,0,0,0,0,0,0,0,0,0,0,0,0,0,0,0
0,0,0,0,0,0,0,0,0,0,0,0,0,0,0,0,0,0,0,0,0,0,0,0,0,0,0,0,0
0,0,0,0,0,0,0,0,0,0,0,0,0,0,0,0,0,0,0,0,0,0,0,0,0,0,0,0,0
0,0,0,0,0,0,0,0,0,0,0,0,0,0,0,0,0,0,0,0,0,0,0,0,0,0,0,0,0
0,0,0,0,0,0,0,0,0,0,0,0,0,468,468,468,0,0,0,0,0,0,0,0,0,0,0,0,0
0,0,0,0,0,0,0,0,0,261,3,3,459,3,459,3,459,3,3,261,0,0,0,0,0,0,0,0,0
0,0,0,0,0,0,51,255,3,3,577,576,575,0,574,0,573,572,571,3,3,256,51,0,0,0,0,0,0
0,0,0,0,0,0,262,3,570,569,568,0,0,0,0,0,0,0,298,23,23,3,262,0,0,0,0,0,0
0,0,0,0,0,0,3,23,0,0,0,0,0,0,4,0,0,0,0,0,0,23,3,0,0,0,0,0,0
0,0,0,0,0,0,3,413,0,0,412,0,0,4,4,4,0,0,412,0,0,413,3,0,0,0,0,0,0
0,0,0,0,0,0,3,0,0,0,0,0,0,429,4,0,0,0,0,0,0,567,3,0,0,0,0,0,0
0,0,0,0,0,261,565,0,0,0,0,0,0,429,0,566,0,0,0,0,0,0,565,261,0,0,0,0,0
0,0,0,0,0,261,68,564,0,0,0,0,0,0,563,0,0,0,0,0,0,0,100,261,0,0,0,0,0
0,0,0,0,0,261,68,0,0,0,412,0,0,0,562,561,0,0,412,0,0,413,100,261,0,0,0,0,0
0,0,0,0,0,261,68,560,0,0,0,0,0,559,558,548,0,0,0,0,0,23,100,261,0,0,0,0,0
0,0,0,0,0,261,68,0,0,0,0,0,0,548,557,556,0,0,0,0,0,23,100,261,0,0,0,0,0
0,0,0,0,0,261,68,555,0,0,0,0,0,554,167,0,429,429,0,0,0,23,100,261,0,0,0,0,0
0,0,0,0,0,261,68,0,0,0,412,0,0,553,552,551,0,429,412,0,0,413,100,261,0,0,0,0,0
0,0,0,0,0,261,68,298,0,0,0,0,0,0,550,548,0,429,0,0,0,0,100,261,0,0,0,0,0
0,0,0,0,0,261,68,0,0,0,0,0,0,0,0,0,0,0,0,0,0,0,100,261,0,0,0,0,0
0,0,0,0,0,261,68,548,549,548,0,0,0,0,0,0,0,0,0,0,0,0,100,261,0,0,0,0,0
0,0,0,0,0,261,68,413,548,413,412,547,547,547,4,0,0,0,0,0,0,278,100,261,0,0,0,0,0
0,0,0,0,0,261,3,3,3,3,3,3,3,4,4,4,3,0,0,0,3,3,3,261,0,0,0,0,0
0,0,0,0,0,261,68,406,0,0,0,522,0,0,4,546,545,0,0,0,0,0,100,261,0,0,0,0,0
0,0,0,0,0,261,68,399,0,0,0,0,0,0,0,0,0,0,0,0,0,522,100,261,0,0,0,0,0
0,0,0,0,0,261,3,3,319,0,69,3,544,3,319,0,0,0,0,0,0,0,100,261,0,0,0,0,0
0,0,0,0,0,261,68,322,321,0,326,325,3,322,321,0,69,3,543,3,319,0,100,261,0,0,0,0,0
0,0,0,0,0,261,68,322,321,0,326,325,3,322,321,0,326,325,3,322,321,0,100,261,0,0,0,0,0
0,0,0,0,0,261,68,322,321,0,326,325,3,322,321,0,326,325,3,322,321,0,100,261,0,0,0,0,0
0,0,0,0,0,261,68,322,321,0,326,325,3,322,321,0,326,325,3,322,321,0,100,261,0,0,0,0,0
0,0,0,0,0,261,68,322,321,0,326,325,3,322,321,0,69,3,542,3,319,0,100,261,0,0,0,0,0
0,0,0,0,0,261,3,3,319,0,69,3,541,3,319,0,0,0,0,0,0,0,100,261,0,0,0,0,0
0,0,0,0,0,261,68,540,0,0,0,0,0,0,0,0,0,0,0,0,0,522,100,261,0,0,0,0,0
0,0,0,0,0,261,3,3,3,3,3,3,308,309,0,0,0,0,0,0,0,0,100,261,0,0,0,0,0
0,0,0,0,0,261,68,212,539,538,212,537,3,307,4,3,3,0,0,0,3,3,3,261,0,0,0,0,0
0,0,0,0,0,261,68,536,0,0,0,374,3,4,4,4,535,0,0,0,326,325,100,261,0,0,0,0,0
0,0,0,0,0,261,68,534,0,518,0,370,3,533,4,0,0,0,0,0,326,325,100,261,0,0,0,0,0
0,0,0,0,0,261,68,212,0,532,0,0,3,0,0,0,0,0,0,0,326,325,100,261,0,0,0,0,0
0,0,0,0,0,261,68,531,0,530,0,0,3,0,0,0,0,214,0,0,326,325,100,261,0,0,0,0,0
0,0,0,0,0,261,68,529,0,0,0,212,3,0,0,0,51,0,0,0,326,325,100,261,0,0,0,0,0
0,0,0,0,0,261,68,212,0,518,0,528,3,78,78,78,0,0,0,0,326,325,100,261,0,0,0,0,0
0,0,0,0,0,261,68,527,0,526,0,525,3,75,75,75,0,0,0,0,69,3,3,261,0,0,0,0,0
0,0,0,0,0,261,68,524,0,523,0,212,3,0,0,0,0,522,0,0,326,325,100,261,0,0,0,0,0
0,0,0,0,0,261,68,212,0,521,0,520,3,0,0,0,0,0,0,0,326,325,100,261,0,0,0,0,0
0,0,0,0,0,261,68,519,0,518,0,517,3,0,0,0,51,0,0,0,326,325,100,261,0,0,0,0,0
0,0,0,0,0,261,68,516,0,0,0,212,3,0,0,0,0,0,0,0,326,325,100,261,0,0,0,0,0
0,0,0,0,0,261,68,212,0,0,0,515,3,0,0,0,0,0,0,0,326,325,100,261,0,0,0,0,0
0,0,0,0,0,261,68,514,0,0,0,513,3,512,4,511,510,0,0,0,326,325,100,261,0,0,0,0,0
0,0,0,0,0,261,68,509,212,508,507,212,3,4,4,4,3,0,0,0,3,3,3,261,0,0,0,0,0
0,0,0,0,0,261,3,3,3,3,3,3,506,505,4,238,186,0,0,0,186,504,100,261,0,0,0,0,0
0,0,0,0,0,261,3,3,319,0,214,0,0,0,0,0,0,0,0,0,0,0,100,261,0,0,0,0,0
0,0,0,0,0,261,68,322,321,0,0,0,0,0,0,0,0,0,0,503,502,0,100,261,0,0,0,0,0
0,0,0,0,0,261,68,322,321,0,0,0,0,0,0,0,501,0,0,0,0,500,100,261,0,0,0,0,0
0,0,0,0,0,261,68,322,321,0,0,0,69,3,3,238,160,0,0,0,160,499,100,261,0,0,0,0,0
0,0,0,0,0,261,68,322,321,0,0,0,326,325,3,3,3,0,0,0,3,3,3,261,0,0,0,0,0
0,0,0,0,0,261,68,322,321,0,214,0,326,325,3,314,0,0,0,0,0,0,100,261,0,0,0,0,0
0,0,0,0,0,261,3,3,319,0,0,0,326,325,3,498,0,0,0,0,0,0,100,261,0,0,0,0,0
0,0,0,0,0,261,68,322,321,0,0,0,326,325,3,497,0,0,0,0,0,0,100,261,0,0,0,0,0
0,0,0,0,0,261,68,322,321,0,0,0,326,325,3,314,0,0,0,0,0,0,100,261,0,0,0,0,0
0,0,0,0,0,261,68,322,321,0,0,0,326,325,3,496,0,0,0,0,0,0,100,261,0,0,0,0,0
0,0,0,0,0,261,68,322,321,0,0,0,326,325,4,495,0,0,0,0,0,0,100,261,0,0,0,0,0
0,0,0,0,0,261,68,322,321,0,0,0,69,4,4,4,314,0,0,0,0,494,100,261,0,0,0,0,0
0,0,0,0,0,261,3,3,319,0,214,0,0,493,4,237,3,0,0,0,0,314,100,261,0,0,0,0,0
0,0,0,0,0,261,68,492,0,0,0,0,0,0,0,0,0,0,0,0,0,0,100,261,0,0,0,0,0
0,0,0,0,0,261,68,491,309,309,309,308,0,0,0,0,0,0,0,0,0,0,100,261,0,0,0,0,0
0,0,0,0,0,468,3,3,307,307,307,3,160,0,0,0,0,0,0,0,0,237,3,468,0,0,0,0,0
0,0,0,0,0,468,3,3,3,3,3,3,3,0,0,0,3,3,3,3,3,3,3,468,0,0,0,0,0
0,0,0,0,0,0,3,490,0,0,301,278,186,0,0,280,186,288,0,0,298,489,3,0,0,0,0,0,0
0,0,0,0,0,0,3,488,0,0,0,0,290,295,0,0,0,0,0,295,0,487,3,0,0,0,0,0,0
0,0,0,0,0,0,260,3,486,0,0,295,290,295,0,0,289,0,293,0,485,3,260,0,0,0,0,0,0
0,0,0,0,0,0,0,3,484,0,289,0,295,0,0,301,0,288,288,0,483,3,0,0,0,0,0,0,0
0,0,0,0,0,0,0,260,3,482,0,0,0,280,284,0,0,0,0,481,3,260,0,0,0,0,0,0,0
0,0,0,0,0,0,0,0,3,480,280,160,0,284,279,284,0,160,278,479,3,0,0,0,0,0,0,0,0
0,0,0,0,0,0,0,0,260,3,3,3,478,3,4,3,477,3,3,3,260,0,0,0,0,0,0,0,0
0,0,0,0,0,0,0,0,0,3,476,0,0,4,4,4,0,0,475,3,0,0,0,0,0,0,0,0,0
0,0,0,0,0,0,0,0,0,260,3,474,0,0,4,0,0,473,3,260,0,0,0,0,0,0,0,0,0
0,0,0,0,0,0,0,0,0,468,3,472,0,0,186,0,0,471,3,468,0,0,0,0,0,0,0,0,0
0,0,0,0,0,0,0,0,0,468,260,3,470,0,0,0,469,3,260,468,0,0,0,0,0,0,0,0,0
0,0,0,0,0,0,0,0,0,0,460,3,467,0,0,0,466,3,460,0,0,0,0,0,0,0,0,0,0
0,0,0,0,0,0,0,0,0,0,460,260,3,465,0,464,3,260,460,0,0,0,0,0,0,0,0,0,0
0,0,0,0,0,0,0,0,0,0,0,460,3,463,0,462,3,460,0,0,0,0,0,0,0,0,0,0,0
0,0,0,0,0,0,0,0,0,0,0,460,260,3,0,3,260,460,0,0,0,0,0,0,0,0,0,0,0
0,0,0,0,0,0,0,0,0,0,0,0,460,3,461,3,460,0,0,0,0,0,0,0,0,0,0,0,0
0,0,0,0,0,0,0,0,0,0,0,0,460,260,3,260,460,0,0,0,0,0,0,0,0,0,0,0,0
0,0,0,0,0,0,0,0,0,0,0,0,0,460,3,460,0,0,0,0,0,0,0,0,0,0,0,0,0
0,0,0,0,0,0,0,0,0,0,0,0,0,0,459,0,0,0,0,0,0,0,0,0,0,0,0,0,0
0,0,0,0,0,0,0,0,0,0,0,0,0,0,0,0,0,0,0,0,0,0,0,0,0,0,0,0,0
0,0,0,0,0,0,0,0,0,0,0,0,0,0,0,0,0,0,0,0,0,0,0,0,0,0,0,0,0
0,0,0,0,0,0,0,0,0,0,0,0,0,0,0,0,0,0,0,0,0,0,0,0,0,0,0,0,0
0,0,0,0,0,0,0,0,0,0,0,0,0,0,0,0,0,0,0,0,0,0,0,0,0,0,0,0,0
0,0,0,0,0,0,0,0,0,0,0,0,0,0,0,0,0,0,0,0,0,0,0,0,0,0,0,0,0
0,0,0,0,0,0,0,0,0,0,0,0,0,0,0,0,0,0,0,0,0,0,0,0,0,0,0,0,0
0,0,0,0,0,0,0,0,0,0,0,0,0,0,0,0,0,0,0,0,0,0,0,0,0,0,0,0,0
0,0,0,0,0,0,0,0,0,0,0,0,0,0,0,0,0,0,0,0,0,0,0,0,0,0,0,0,0
0,0,0,0,0,0,0,0,0,0,0,0,0,0,0,0,0,0,0,0,0,0,0,0,0,0,0,0,0
0,0,0,0,0,0,0,0,0,0,0,0,0,0,0,0,0,0,0,0,0,0,0,0,0,0,0,0,0
0,0,0,0,0,0,0,0,0,0,0,0,0,0,0,0,0,0,0,0,0,0,0,0,0,0,0,0,0
:endlayer
layer: 9
0,0,0,0,0,0,0,0,0,0,0,0,0,0,0,0,0,0,0,0,0,0,0,0,0,0,0,0,0
0,0,0,0,0,0,0,0,0,0,0,0,0,0,0,0,0,0,0,0,0,0,0,0,0,0,0,0,0
0,0,0,0,0,0,0,0,0,0,0,0,0,0,0,0,0,0,0,0,0,0,0,0,0,0,0,0,0
0,0,0,0,0,0,0,0,0,0,0,0,0,0,0,0,0,0,0,0,0,0,0,0,0,0,0,0,0
0,0,0,0,0,0,0,0,0,0,0,0,0,0,0,0,0,0,0,0,0,0,0,0,0,0,0,0,0
0,0,0,0,0,0,0,0,0,0,0,0,0,0,0,0,0,0,0,0,0,0,0,0,0,0,0,0,0
0,0,0,0,0,0,0,0,0,0,0,0,0,0,0,0,0,0,0,0,0,0,0,0,0,0,0,0,0
0,0,0,0,0,0,0,0,0,0,0,0,0,51,0,51,0,0,0,0,0,0,0,0,0,0,0,0,0
0,0,0,0,0,0,51,51,255,3,459,3,587,3,587,3,587,3,459,3,256,51,51,0,0,0,0,0,0
0,0,0,0,0,51,459,3,3,599,0,0,278,0,0,0,598,0,0,597,3,3,459,51,0,0,0,0,0
0,0,0,0,0,51,3,596,0,0,278,0,0,0,0,0,0,0,298,0,0,595,3,51,0,0,0,0,0
0,0,0,0,0,262,3,594,0,0,0,0,0,0,4,0,0,0,0,0,0,593,3,262,0,0,0,0,0
0,0,0,0,0,3,3,256,261,255,592,256,255,4,4,4,256,255,592,256,261,255,3,3,0,0,0,0,0
0,0,0,0,0,3,3,238,0,0,260,0,429,0,4,0,0,0,260,0,0,237,3,3,0,0,0,0,0
0,0,0,0,0,3,260,0,0,0,261,0,429,429,186,0,0,0,261,0,0,0,260,3,0,0,0,0,0
0,0,0,0,0,3,0,0,0,0,262,0,0,429,0,0,0,0,262,0,0,0,0,3,0,0,0,0,0
0,0,0,0,0,587,0,0,0,0,592,0,0,0,0,0,0,0,592,413,413,413,0,587,0,0,0,0,0
0,0,0,0,0,3,0,0,0,0,260,0,0,0,0,0,0,0,260,0,0,23,0,3,0,0,0,0,0
0,0,0,0,0,587,0,0,0,0,261,0,0,0,0,0,429,429,261,0,0,23,0,587,0,0,0,0,0
0,0,0,0,0,3,0,0,0,0,262,0,0,0,0,0,429,0,262,0,0,23,0,3,0,0,0,0,0
0,0,0,0,255,3,238,0,0,0,592,0,0,0,0,0,0,429,592,413,413,413,237,3,256,0,0,0,0
0,0,0,0,0,3,0,298,0,0,260,0,0,0,0,0,0,429,260,0,0,0,0,3,0,0,0,0,0
0,0,0,0,0,587,0,0,0,0,261,0,0,0,0,0,0,0,261,0,0,0,0,587,0,0,0,0,0
0,0,0,0,0,3,0,0,0,0,262,0,0,0,160,0,0,0,261,0,0,0,0,3,0,0,0,0,0
0,0,0,0,0,587,0,413,413,413,592,0,0,0,4,0,0,0,261,0,0,278,0,587,0,0,0,0,0
0,0,0,0,0,3,3,3,3,3,3,3,3,4,4,4,3,256,261,255,3,3,3,3,0,0,0,0,0
0,0,0,0,0,587,0,406,0,0,0,0,0,0,4,0,0,0,0,0,0,0,0,587,0,0,0,0,0
0,0,0,0,0,3,0,399,0,0,0,0,0,0,186,0,0,0,591,0,0,0,0,3,0,0,0,0,0
0,0,0,0,255,3,3,3,319,0,69,3,262,3,319,0,0,0,0,0,0,0,0,3,256,0,0,0,0
0,0,0,0,0,3,0,322,321,0,326,325,3,322,321,0,69,3,262,3,319,0,0,3,0,0,0,0,0
0,0,0,0,0,587,0,322,321,0,326,325,3,322,321,0,326,325,3,322,321,0,0,587,0,0,0,0,0
0,0,0,0,0,3,0,322,321,591,326,325,3,322,321,0,326,325,3,322,321,0,0,3,0,0,0,0,0
0,0,0,0,0,587,0,322,321,0,326,325,3,322,321,0,326,325,3,322,321,0,0,587,0,0,0,0,0
0,0,0,0,0,3,0,322,321,0,326,325,3,322,321,0,69,3,260,3,319,0,0,3,0,0,0,0,0
0,0,0,0,0,3,3,3,319,0,69,3,260,3,319,0,0,0,0,0,0,0,0,587,0,0,0,0,0
0,0,0,0,0,3,0,591,0,0,0,0,0,0,0,0,0,0,591,0,0,0,0,3,0,0,0,0,0
0,0,0,0,255,3,3,3,3,3,3,3,308,309,160,0,0,0,0,0,0,0,0,3,256,0,0,0,0
0,0,0,0,0,3,212,212,468,468,212,374,3,307,4,3,3,256,261,255,3,3,3,3,0,0,0,0,0
0,0,0,0,0,587,0,460,0,0,0,370,3,4,4,4,0,0,0,0,326,325,0,587,0,0,0,0,0
0,0,0,0,0,3,212,460,0,0,0,0,3,214,4,0,0,0,0,0,326,325,0,3,0,0,0,0,0
0,0,0,0,0,587,0,460,0,0,0,0,3,0,0,0,0,0,0,0,326,325,0,587,0,0,0,0,0
0,0,0,0,0,3,212,460,0,0,0,0,3,0,0,0,0,0,0,0,326,325,0,3,0,0,0,0,0
0,0,0,0,0,587,0,460,0,0,0,212,3,0,0,0,51,0,0,0,326,325,0,587,0,0,0,0,0
0,0,0,0,0,3,212,460,0,0,0,468,3,0,0,0,51,0,0,0,326,325,0,3,0,0,0,0,0
0,0,0,0,255,3,238,460,0,0,0,468,3,78,78,78,51,0,0,0,69,3,3,3,256,0,0,0,0
0,0,0,0,0,3,212,460,0,0,0,212,3,75,75,75,51,0,591,0,326,325,0,3,0,0,0,0,0
0,0,0,0,0,587,0,460,0,0,0,468,3,0,0,0,51,0,0,0,326,325,0,587,0,0,0,0,0
0,0,0,0,0,3,212,460,0,0,0,468,3,0,0,0,51,0,0,0,326,325,0,3,0,0,0,0,0
0,0,0,0,0,587,0,460,0,0,0,212,3,0,0,0,0,0,0,0,326,325,0,587,0,0,0,0,0
0,0,0,0,0,3,212,460,0,0,0,468,3,0,160,0,0,0,0,0,326,325,0,3,0,0,0,0,0
0,0,0,0,0,587,0,460,0,0,0,468,3,0,4,0,0,0,0,0,326,325,0,587,0,0,0,0,0
0,0,0,0,0,3,212,460,212,468,468,212,3,4,4,4,3,256,261,255,3,3,3,3,0,0,0,0,0
0,0,0,0,255,3,3,3,3,3,3,3,260,260,4,0,0,0,0,0,0,0,0,3,256,0,0,0,0
0,0,0,0,0,3,3,3,319,0,0,0,0,0,260,0,0,0,0,0,0,0,0,3,0,0,0,0,0
0,0,0,0,0,587,0,322,321,0,0,0,0,0,261,0,0,0,0,0,0,0,0,587,0,0,0,0,0
0,0,0,0,0,3,0,322,321,0,0,0,0,0,262,0,0,0,0,0,0,0,0,3,0,0,0,0,0
0,0,0,0,0,587,0,322,321,0,0,0,69,3,3,0,0,0,590,0,0,0,0,587,0,0,0,0,0
0,0,0,0,0,3,0,322,321,0,0,0,326,325,3,3,3,256,261,255,3,3,3,3,0,0,0,0,0
0,0,0,0,0,587,0,322,321,0,0,0,326,325,3,314,0,0,0,0,0,0,0,587,0,0,0,0,0
0,0,0,0,0,3,3,3,319,0,0,0,326,325,3,0,0,0,0,0,0,0,0,3,0,0,0,0,0
0,0,0,0,255,3,0,322,321,0,0,0,326,325,3,0,0,0,0,0,0,0,237,3,256,0,0,0,0
0,0,0,0,0,3,0,322,321,0,0,0,326,325,3,314,0,0,0,0,0,0,0,3,0,0,0,0,0
0,0,0,0,0,587,0,322,321,0,0,0,326,325,3,589,0,0,0,0,0,0,0,587,0,0,0,0,0
0,0,0,0,0,3,0,322,321,0,0,0,326,325,4,588,0,0,0,0,0,0,0,3,0,0,0,0,0
0,0,0,0,0,587,0,322,321,0,0,0,69,4,4,4,314,0,0,0,0,0,0,587,0,0,0,0,0
0,0,0,0,0,3,3,3,319,0,0,0,0,0,4,0,3,0,0,0,0,314,314,3,0,0,0,0,0
0,0,0,0,0,587,0,0,0,0,0,0,0,0,0,0,260,0,0,0,0,0,0,587,0,0,0,0,0
0,0,0,0,0,3,0,0,309,309,309,308,0,0,0,586,261,0,0,0,0,0,0,3,0,0,0,0,0
0,0,0,0,0,459,3,3,307,307,307,3,0,0,585,0,262,0,0,0,0,0,3,459,0,0,0,0,0
0,0,0,0,0,261,3,3,3,3,3,3,3,256,261,255,3,3,3,3,3,3,3,261,0,0,0,0,0
0,0,0,0,0,460,3,256,0,0,0,278,0,0,280,0,0,0,0,0,298,255,3,460,0,0,0,0,0
0,0,0,0,0,460,3,256,0,0,0,0,295,0,0,0,0,0,0,0,0,255,3,460,0,0,0,0,0
0,0,0,0,0,460,3,3,256,0,0,0,290,0,0,0,301,0,0,0,255,3,3,460,0,0,0,0,0
0,0,0,0,0,0,460,3,256,0,301,0,0,0,0,0,0,293,288,278,255,3,460,0,0,0,0,0,0
0,0,0,0,0,0,460,3,3,256,0,0,0,0,0,0,0,0,0,255,3,3,460,0,0,0,0,0,0
0,0,0,0,0,0,0,460,3,256,280,0,280,280,279,284,0,278,0,255,3,460,0,0,0,0,0,0,0
0,0,0,0,0,0,0,460,3,3,3,3,3,3,4,3,3,3,3,3,3,460,0,0,0,0,0,0,0
0,0,0,0,0,0,0,0,460,3,256,584,0,4,4,4,0,583,255,3,460,0,0,0,0,0,0,0,0
0,0,0,0,0,0,0,0,460,3,3,256,0,0,4,0,0,255,3,3,460,0,0,0,0,0,0,0,0
0,0,0,0,0,0,0,0,0,0,3,256,582,0,0,0,581,255,3,0,0,0,0,0,0,0,0,0,0
0,0,0,0,0,0,0,0,0,0,3,3,256,0,0,0,255,3,3,0,0,0,0,0,0,0,0,0,0
0,0,0,0,0,0,0,0,0,0,468,3,256,580,0,579,255,3,468,0,0,0,0,0,0,0,0,0,0
0,0,0,0,0,0,0,0,0,0,468,3,3,256,0,255,3,3,468,0,0,0,0,0,0,0,0,0,0
0,0,0,0,0,0,0,0,0,0,0,468,3,256,0,255,3,468,0,0,0,0,0,0,0,0,0,0,0
0,0,0,0,0,0,0,0,0,0,0,468,3,3,578,3,3,468,0,0,0,0,0,0,0,0,0,0,0
0,0,0,0,0,0,0,0,0,0,0,0,468,3,262,3,468,0,0,0,0,0,0,0,0,0,0,0,0
0,0,0,0,0,0,0,0,0,0,0,0,468,3,3,3,468,0,0,0,0,0,0,0,0,0,0,0,0
0,0,0,0,0,0,0,0,0,0,0,0,0,468,3,468,0,0,0,0,0,0,0,0,0,0,0,0,0
0,0,0,0,0,0,0,0,0,0,0,0,0,0,3,0,0,0,0,0,0,0,0,0,0,0,0,0,0
0,0,0,0,0,0,0,0,0,0,0,0,0,0,265,0,0,0,0,0,0,0,0,0,0,0,0,0,0
0,0,0,0,0,0,0,0,0,0,0,0,0,0,0,0,0,0,0,0,0,0,0,0,0,0,0,0,0
0,0,0,0,0,0,0,0,0,0,0,0,0,0,0,0,0,0,0,0,0,0,0,0,0,0,0,0,0
0,0,0,0,0,0,0,0,0,0,0,0,0,0,0,0,0,0,0,0,0,0,0,0,0,0,0,0,0
0,0,0,0,0,0,0,0,0,0,0,0,0,0,0,0,0,0,0,0,0,0,0,0,0,0,0,0,0
0,0,0,0,0,0,0,0,0,0,0,0,0,0,0,0,0,0,0,0,0,0,0,0,0,0,0,0,0
0,0,0,0,0,0,0,0,0,0,0,0,0,0,0,0,0,0,0,0,0,0,0,0,0,0,0,0,0
0,0,0,0,0,0,0,0,0,0,0,0,0,0,0,0,0,0,0,0,0,0,0,0,0,0,0,0,0
0,0,0,0,0,0,0,0,0,0,0,0,0,0,0,0,0,0,0,0,0,0,0,0,0,0,0,0,0
0,0,0,0,0,0,0,0,0,0,0,0,0,0,0,0,0,0,0,0,0,0,0,0,0,0,0,0,0
0,0,0,0,0,0,0,0,0,0,0,0,0,0,0,0,0,0,0,0,0,0,0,0,0,0,0,0,0
:endlayer
layer: 10
0,0,0,0,0,0,0,0,0,0,0,0,0,0,0,0,0,0,0,0,0,0,0,0,0,0,0,0,0
0,0,0,0,0,0,0,0,0,0,0,0,0,0,0,0,0,0,0,0,0,0,0,0,0,0,0,0,0
0,0,0,0,0,0,0,0,0,0,0,0,0,0,0,0,0,0,0,0,0,0,0,0,0,0,0,0,0
0,0,0,0,0,0,0,0,0,0,0,0,0,0,0,0,0,0,0,0,0,0,0,0,0,0,0,0,0
0,0,0,0,0,0,0,0,0,0,0,0,0,0,0,0,0,0,0,0,0,0,0,0,0,0,0,0,0
0,0,0,0,0,0,0,0,0,0,0,0,0,0,0,0,0,0,0,0,0,0,0,0,0,0,0,0,0
0,0,0,0,0,0,0,0,0,0,0,0,0,0,0,0,0,0,0,0,0,0,0,0,0,0,0,0,0
0,0,0,0,0,0,0,0,0,51,0,51,0,51,0,51,0,51,0,51,0,0,0,0,0,0,0,0,0
0,0,0,0,0,468,51,600,3,3,587,3,587,3,587,3,587,3,587,3,3,263,51,468,0,0,0,0,0
0,0,0,0,0,51,3,3,3,260,0,602,278,0,0,0,598,602,0,260,3,3,3,51,0,0,0,0,0
0,0,0,0,0,601,3,256,0,0,0,0,0,0,0,0,0,0,0,0,0,255,3,601,0,0,0,0,0
0,0,0,0,0,3,3,256,0,0,0,0,0,0,4,0,0,0,0,0,0,255,3,3,0,0,0,0,0
0,0,0,0,0,3,3,412,412,412,412,412,412,4,4,4,412,412,412,412,412,412,3,3,0,0,0,0,0
0,0,0,0,0,3,264,264,264,264,264,264,264,264,4,264,264,264,264,264,264,264,264,3,0,0,0,0,0
0,0,0,0,261,3,264,264,264,264,264,264,264,264,264,264,264,264,264,264,264,264,264,3,261,0,0,0,0
0,0,0,0,261,3,264,264,264,264,264,264,264,264,264,264,264,264,264,264,264,264,264,3,261,0,0,0,0
0,0,0,0,261,3,264,264,264,264,264,264,264,264,264,264,264,264,264,264,264,264,264,3,261,0,0,0,0
0,0,0,0,261,3,264,264,264,264,264,264,264,264,264,264,264,264,264,264,264,264,264,3,261,0,0,0,0
0,0,0,0,261,3,264,264,264,264,264,264,264,264,264,264,264,264,264,264,264,264,264,3,261,0,0,0,0
0,0,0,261,600,3,264,264,264,264,264,264,264,264,264,264,264,264,264,264,264,264,264,3,263,261,0,0,0
0,0,0,261,2,3,264,264,264,264,264,264,264,264,264,264,264,264,264,264,264,264,264,3,2,261,0,0,0
0,0,0,261,600,3,264,264,264,264,264,264,264,264,264,264,264,264,264,264,264,264,264,3,263,261,0,0,0
0,0,0,0,261,3,264,264,264,264,264,264,264,264,264,264,264,264,264,264,264,264,264,3,261,0,0,0,0
0,0,0,0,261,3,264,264,264,264,264,264,264,264,264,264,264,264,264,264,264,264,264,3,261,0,0,0,0
0,0,0,0,261,3,264,264,264,264,264,264,264,264,4,264,264,264,264,264,264,264,264,3,261,0,0,0,0
0,0,0,0,261,3,264,264,264,264,264,264,264,4,4,4,264,264,264,264,264,264,264,3,261,0,0,0,0
0,0,0,0,261,3,264,264,264,264,264,264,264,264,4,264,264,264,264,264,264,264,264,3,261,0,0,0,0
0,0,0,261,600,3,264,264,264,264,264,264,264,264,264,264,264,264,264,264,264,264,264,3,263,261,0,0,0
0,0,0,261,2,3,264,264,264,264,264,264,264,264,264,264,264,264,264,264,264,264,264,3,2,261,0,0,0
0,0,0,261,600,3,264,264,264,264,264,264,264,264,264,264,264,264,264,264,264,264,264,3,263,261,0,0,0
0,0,0,0,261,3,264,264,264,264,264,264,264,264,264,264,264,264,264,264,264,264,264,3,261,0,0,0,0
0,0,0,0,261,3,264,264,264,264,264,264,264,264,264,264,264,264,264,264,264,264,264,3,261,0,0,0,0
0,0,0,0,261,3,264,264,264,264,264,264,264,264,264,264,264,264,264,264,264,264,264,3,261,0,0,0,0
0,0,0,0,261,3,264,264,264,264,264,264,264,264,264,264,264,264,264,264,264,264,264,3,261,0,0,0,0
0,0,0,0,261,3,264,264,264,264,264,264,264,264,264,264,264,264,264,264,264,264,264,3,261,0,0,0,0
0,0,0,261,600,3,264,264,264,264,264,264,264,264,264,264,264,264,264,264,264,264,264,3,263,261,0,0,0
0,0,0,261,2,3,264,264,264,264,264,264,264,264,264,264,264,264,264,264,264,264,264,3,2,261,0,0,0
0,0,0,261,600,3,264,264,264,264,264,370,3,264,4,264,264,264,264,264,264,264,264,3,263,261,0,0,0
0,0,0,0,261,3,264,264,264,264,264,0,3,4,4,4,264,264,264,264,264,264,264,3,261,0,0,0,0
0,0,0,0,261,3,264,264,264,264,264,0,3,0,4,0,264,264,264,264,264,264,264,3,261,0,0,0,0
0,0,0,0,261,3,264,264,264,264,264,0,3,0,186,0,264,264,264,264,264,264,264,3,261,0,0,0,0
0,0,0,0,261,3,264,264,264,264,264,374,3,0,0,0,264,264,264,264,264,264,264,3,261,0,0,0,0
0,0,0,0,261,3,264,264,264,264,264,264,3,0,0,0,264,264,264,264,264,264,264,3,261,0,0,0,0
0,0,0,261,600,3,264,264,264,264,264,264,3,0,0,0,264,264,264,264,264,264,264,3,263,261,0,0,0
0,0,0,261,2,3,264,264,264,264,264,264,3,0,0,0,264,264,264,264,264,264,264,3,2,261,0,0,0
0,0,0,261,600,3,264,264,264,264,264,264,3,78,78,78,264,264,264,264,264,264,264,3,263,261,0,0,0
0,0,0,0,261,3,264,264,264,264,264,264,264,264,264,264,264,264,264,264,264,264,264,3,261,0,0,0,0
0,0,0,0,261,3,264,264,264,264,264,264,264,264,264,264,264,264,264,264,264,264,264,3,261,0,0,0,0
0,0,0,0,261,3,264,264,264,264,264,264,264,264,264,264,264,264,264,264,264,264,264,3,261,0,0,0,0
0,0,0,0,261,3,264,264,264,264,264,264,264,264,264,264,264,264,264,264,264,264,264,3,261,0,0,0,0
0,0,0,0,261,3,264,264,264,264,264,264,264,264,4,264,264,264,264,264,264,264,264,3,261,0,0,0,0
0,0,0,261,600,3,264,264,264,264,264,264,264,4,4,4,264,264,264,264,264,264,264,3,263,261,0,0,0
0,0,0,261,2,3,264,264,264,264,264,264,264,264,4,264,264,264,264,264,264,264,264,3,2,261,0,0,0
0,0,0,261,600,3,264,264,264,264,264,264,264,264,264,264,264,264,264,264,264,264,264,3,263,261,0,0,0
0,0,0,0,261,3,264,264,264,264,264,264,264,264,264,264,264,264,264,264,264,264,264,3,261,0,0,0,0
0,0,0,0,261,3,264,264,264,264,264,264,264,264,264,264,264,264,264,264,264,264,264,3,261,0,0,0,0
0,0,0,0,261,3,264,264,264,264,264,264,264,264,264,264,264,264,264,264,264,264,264,3,261,0,0,0,0
0,0,0,0,261,3,264,264,264,264,264,264,264,264,264,264,264,264,264,264,264,264,264,3,261,0,0,0,0
0,0,0,0,261,3,264,264,264,264,264,264,264,264,264,264,264,264,264,264,264,264,264,3,261,0,0,0,0
0,0,0,261,600,3,264,264,264,264,264,264,264,264,264,264,264,264,264,264,264,264,264,3,263,261,0,0,0
0,0,0,261,2,3,264,264,264,264,264,264,264,264,264,264,264,264,264,264,264,264,264,3,2,261,0,0,0
0,0,0,261,600,3,264,264,264,264,264,264,264,264,264,264,264,264,264,264,264,264,264,3,263,261,0,0,0
0,0,0,0,261,3,264,264,264,264,264,264,264,264,264,264,264,264,264,264,264,264,264,3,261,0,0,0,0
0,0,0,0,261,3,264,264,264,264,264,264,264,264,4,264,264,264,264,264,264,264,264,3,261,0,0,0,0
0,0,0,0,261,3,264,264,264,264,264,264,264,4,4,4,264,264,264,264,264,264,264,3,261,0,0,0,0
0,0,0,0,261,3,264,264,264,264,264,264,264,264,4,264,264,264,264,264,264,264,264,3,261,0,0,0,0
0,0,0,0,261,3,264,264,264,264,264,264,264,264,264,264,264,264,264,264,264,264,264,3,261,0,0,0,0
0,0,0,0,0,3,264,264,264,264,264,264,264,264,264,264,264,264,264,264,264,264,264,3,0,0,0,0,0
0,0,0,0,0,3,264,264,264,264,264,264,264,264,264,264,264,264,264,264,264,264,264,3,0,0,0,0,0
0,0,0,0,0,3,264,264,264,264,264,264,264,264,264,264,264,264,264,264,264,264,264,3,0,0,0,0,0
0,0,0,0,0,260,3,3,3,3,3,3,264,264,264,264,264,3,3,3,3,3,3,260,0,0,0,0,0
0,0,0,0,0,0,3,264,264,264,264,264,264,264,264,264,264,264,264,264,264,264,3,0,0,0,0,0,0
0,0,0,0,0,0,3,264,264,264,264,264,264,264,264,264,264,264,264,264,264,264,3,0,0,0,0,0,0
0,0,0,0,0,0,0,3,264,264,264,264,264,264,264,264,264,264,264,264,264,3,0,0,0,0,0,0,0
0,0,0,0,0,0,0,3,3,264,264,264,264,264,264,264,264,264,264,264,3,3,0,0,0,0,0,0,0
0,0,0,0,0,0,0,0,3,3,264,264,264,264,264,264,264,264,264,3,3,0,0,0,0,0,0,0,0
0,0,0,0,0,0,0,0,3,3,264,264,264,264,4,264,264,264,264,3,3,0,0,0,0,0,0,0,0
0,0,0,0,0,0,0,0,468,3,264,264,264,4,4,4,264,264,264,3,468,0,0,0,0,0,0,0,0
0,0,0,0,0,0,0,0,468,565,3,264,264,264,4,264,264,264,3,565,468,0,0,0,0,0,0,0,0
0,0,0,0,0,0,0,0,0,460,3,264,264,264,264,264,264,264,3,460,0,0,0,0,0,0,0,0,0
0,0,0,0,0,0,0,0,0,460,565,3,264,264,264,264,264,3,565,460,0,0,0,0,0,0,0,0,0
0,0,0,0,0,0,0,0,0,0,0,3,264,264,264,264,264,3,0,0,0,0,0,0,0,0,0,0,0
0,0,0,0,0,0,0,0,0,0,0,565,3,264,264,264,3,565,0,0,0,0,0,0,0,0,0,0,0
0,0,0,0,0,0,0,0,0,0,0,0,3,264,264,264,3,0,0,0,0,0,0,0,0,0,0,0,0
0,0,0,0,0,0,0,0,0,0,0,0,3,264,264,264,3,0,0,0,0,0,0,0,0,0,0,0,0
0,0,0,0,0,0,0,0,0,0,0,0,260,3,264,3,260,0,0,0,0,0,0,0,0,0,0,0,0
0,0,0,0,0,0,0,0,0,0,0,0,0,3,3,3,0,0,0,0,0,0,0,0,0,0,0,0,0
0,0,0,0,0,0,0,0,0,0,0,0,0,260,3,260,0,0,0,0,0,0,0,0,0,0,0,0,0
0,0,0,0,0,0,0,0,0,0,0,0,0,460,3,460,0,0,0,0,0,0,0,0,0,0,0,0,0
0,0,0,0,0,0,0,0,0,0,0,0,0,468,459,468,0,0,0,0,0,0,0,0,0,0,0,0,0
0,0,0,0,0,0,0,0,0,0,0,0,0,0,0,0,0,0,0,0,0,0,0,0,0,0,0,0,0
0,0,0,0,0,0,0,0,0,0,0,0,0,0,0,0,0,0,0,0,0,0,0,0,0,0,0,0,0
0,0,0,0,0,0,0,0,0,0,0,0,0,0,0,0,0,0,0,0,0,0,0,0,0,0,0,0,0
0,0,0,0,0,0,0,0,0,0,0,0,0,0,0,0,0,0,0,0,0,0,0,0,0,0,0,0,0
0,0,0,0,0,0,0,0,0,0,0,0,0,0,0,0,0,0,0,0,0,0,0,0,0,0,0,0,0
0,0,0,0,0,0,0,0,0,0,0,0,0,0,0,0,0,0,0,0,0,0,0,0,0,0,0,0,0
0,0,0,0,0,0,0,0,0,0,0,0,0,0,0,0,0,0,0,0,0,0,0,0,0,0,0,0,0
0,0,0,0,0,0,0,0,0,0,0,0,0,0,0,0,0,0,0,0,0,0,0,0,0,0,0,0,0
0,0,0,0,0,0,0,0,0,0,0,0,0,0,0,0,0,0,0,0,0,0,0,0,0,0,0,0,0
0,0,0,0,0,0,0,0,0,0,0,0,0,0,0,0,0,0,0,0,0,0,0,0,0,0,0,0,0
:endlayer
layer: 11
0,0,0,0,0,0,0,0,0,0,0,0,0,0,0,0,0,0,0,0,0,0,0,0,0,0,0,0,0
0,0,0,0,0,0,0,0,0,0,0,0,0,0,0,0,0,0,0,0,0,0,0,0,0,0,0,0,0
0,0,0,0,0,0,0,0,0,0,0,0,0,0,0,0,0,0,0,0,0,0,0,0,0,0,0,0,0
0,0,0,0,0,0,0,0,0,0,0,0,0,0,0,0,0,0,0,0,0,0,0,0,0,0,0,0,0
0,0,0,0,0,0,0,0,0,0,0,0,0,0,0,0,0,0,0,0,0,0,0,0,0,0,0,0,0
0,0,0,0,0,0,0,0,0,0,0,0,0,0,0,0,0,0,0,0,0,0,0,0,0,0,0,0,0
0,0,0,0,0,0,0,0,0,0,261,261,261,261,261,261,261,261,261,0,0,0,0,0,0,0,0,0,0
0,0,0,0,0,601,468,601,468,262,261,262,262,262,261,262,262,262,261,262,468,601,468,601,0,0,0,0,0
0,0,0,0,600,3,3,3,2,3,3,3,3,3,3,3,3,3,3,3,2,3,3,3,263,0,0,0,0
0,0,0,0,468,3,264,264,264,264,264,264,264,264,264,264,264,264,264,264,264,264,264,3,468,0,0,0,0
0,0,0,0,600,3,264,264,264,264,264,264,264,264,264,264,264,264,264,264,264,264,264,3,263,0,0,0,0
0,0,0,0,0,3,264,264,264,264,264,264,264,264,4,264,264,264,264,264,264,264,264,3,0,0,0,0,0
0,0,0,0,262,3,3,3,3,565,565,565,3,4,4,4,3,565,565,565,3,3,3,3,262,0,0,0,0
0,0,0,0,3,780,0,779,3,0,0,0,778,765,4,777,776,0,0,0,3,775,0,774,3,0,0,0,0
0,0,0,0,3,773,0,43,3,0,772,0,771,765,3,0,0,0,0,0,3,43,0,770,3,0,0,0,0
0,0,0,0,3,3,616,3,68,0,0,0,0,765,3,0,37,37,0,769,100,3,616,3,3,0,0,0,0
0,0,0,0,3,0,0,0,0,0,36,36,0,764,3,0,37,37,0,0,0,0,0,55,3,0,0,0,0
0,0,0,0,3,0,768,768,768,0,36,36,0,767,3,0,37,37,0,36,36,36,0,692,3,0,0,0,0
0,0,0,0,3,0,765,765,765,0,36,36,0,766,3,0,0,0,0,36,36,36,0,55,3,0,0,0,0
0,0,0,51,3,0,765,765,765,0,36,36,0,764,3,0,0,0,0,0,0,0,0,0,3,51,0,0,0
0,0,0,51,654,0,763,763,763,762,761,0,0,0,3,0,0,55,37,55,760,759,0,0,649,51,0,0,0
0,0,0,51,3,3,3,3,3,3,3,3,698,697,3,698,697,3,3,3,3,3,3,3,3,51,0,0,0
0,0,0,0,3,743,742,758,758,741,740,3,757,0,702,0,756,702,755,0,0,754,753,752,3,0,0,0,0
0,0,0,0,3,0,0,0,0,0,0,3,0,0,41,41,41,41,711,0,0,0,751,750,3,0,0,0,0
0,0,0,0,3,743,742,0,749,741,740,3,41,41,4,3,3,3,3,212,0,748,0,212,3,0,0,0,0
0,0,0,0,3,0,0,0,0,747,0,3,746,4,4,4,745,708,0,0,0,0,0,744,3,0,0,0,0
0,0,0,0,3,743,742,0,0,741,740,739,3,738,4,37,3,212,0,37,37,37,0,212,3,0,0,0,0
0,0,0,51,3,3,3,698,697,3,3,3,3,737,702,702,0,0,0,37,37,37,0,736,3,51,0,0,0
0,0,0,51,654,0,0,0,0,212,735,735,3,0,734,0,733,0,0,732,0,0,731,0,649,51,0,0,0
0,0,0,51,3,730,729,0,0,212,728,728,3,0,0,0,0,0,0,0,0,0,0,0,3,51,0,0,0
0,0,0,0,3,212,212,0,0,212,0,0,0,0,0,0,3,212,0,0,2,0,0,212,3,0,0,0,0
0,0,0,0,3,727,0,0,726,0,0,0,0,0,0,0,3,37,0,0,2,0,725,724,3,0,0,0,0
0,0,0,0,3,0,212,723,212,0,212,0,0,0,0,692,3,37,0,722,2,0,0,721,3,0,0,0,0
0,0,0,0,3,720,212,720,212,720,212,720,3,692,719,0,3,37,0,0,2,0,0,718,3,0,0,0,0
0,0,0,0,3,717,212,717,212,717,212,717,3,692,0,0,3,212,716,0,2,0,0,212,3,0,0,0,0
0,0,0,51,3,3,3,3,3,3,3,3,3,692,0,0,0,3,0,0,0,0,0,37,3,51,0,0,0
0,0,0,51,654,0,0,715,714,713,712,0,711,41,41,0,0,710,3,0,0,0,0,0,649,51,0,0,0
0,0,0,51,3,43,0,0,0,709,0,0,3,37,4,708,0,0,694,3,0,0,0,0,3,51,0,0,0
0,0,0,0,3,43,707,0,43,0,51,0,3,4,4,4,51,0,694,3,212,706,705,212,3,0,0,0,0
0,0,0,0,3,43,0,0,0,0,51,0,3,0,4,0,51,0,694,3,3,3,3,3,3,0,0,0,0
0,0,0,0,3,43,704,703,51,0,51,51,3,0,0,0,51,0,702,3,701,700,699,694,3,0,0,0,0
0,0,0,0,3,3,3,3,3,698,697,3,3,0,0,0,51,696,0,3,692,0,0,694,3,0,0,0,0
0,0,0,0,3,0,0,0,695,0,0,669,3,0,0,0,51,0,23,3,692,0,0,694,3,0,0,0,0
0,0,0,51,3,0,648,648,648,648,0,37,3,0,0,0,51,0,23,3,692,693,0,212,3,51,0,0,0
0,0,0,51,654,0,37,37,37,37,0,661,3,0,0,0,51,0,692,3,23,0,0,0,649,51,0,0,0
0,0,0,51,3,0,37,37,37,37,0,0,3,0,0,0,51,0,692,3,23,0,0,0,3,51,0,0,0
0,0,0,0,3,0,648,648,648,648,0,0,0,0,0,0,0,0,37,3,23,691,0,690,3,0,0,0,0
0,0,0,0,3,0,0,0,0,0,0,0,689,0,0,0,688,0,55,3,212,0,687,686,3,0,0,0,0
0,0,0,0,3,0,648,648,648,648,0,0,0,0,685,0,0,0,0,684,0,0,683,682,3,0,0,0,0
0,0,0,0,3,0,37,37,37,37,0,0,3,0,0,0,0,0,0,3,212,0,0,681,3,0,0,0,0
0,0,0,0,3,0,37,37,37,37,0,669,3,680,4,3,616,3,3,3,19,19,5,212,3,0,0,0,0
0,0,0,51,3,0,648,648,648,648,0,37,3,4,4,4,679,0,3,3,3,3,3,3,3,51,0,0,0
0,0,0,51,654,0,0,0,678,0,677,661,3,676,4,649,675,0,674,0,673,0,672,0,649,51,0,0,0
0,0,0,51,3,0,648,648,648,648,0,0,3,288,293,0,3,0,671,0,65,0,670,0,3,51,0,0,0
0,0,0,0,3,0,37,37,37,37,0,669,3,288,293,0,3,668,667,666,665,664,663,662,3,0,0,0,0
0,0,0,0,3,0,37,37,37,37,0,37,3,293,0,0,3,422,422,422,422,422,422,422,3,0,0,0,0
0,0,0,0,3,0,648,648,648,648,0,661,3,0,660,659,3,422,422,422,422,422,422,422,3,0,0,0,0
0,0,0,0,3,0,0,0,0,0,658,0,3,264,264,264,3,646,646,646,422,646,646,646,3,0,0,0,0
0,0,0,0,3,0,648,648,648,648,0,0,3,370,370,370,3,657,0,656,422,655,0,0,3,0,0,0,0
0,0,0,51,3,0,37,37,37,37,0,0,3,0,0,0,3,646,646,646,422,646,646,646,3,51,0,0,0
0,0,0,51,654,0,37,37,37,37,653,0,0,0,652,0,651,0,0,0,422,0,650,0,649,51,0,0,0
0,0,0,51,3,0,648,648,648,648,0,0,647,0,0,0,0,646,646,646,422,646,646,646,3,51,0,0,0
0,0,0,0,3,0,0,0,0,0,0,0,0,0,74,0,645,644,0,0,422,0,0,643,3,0,0,0,0
0,0,0,0,3,3,3,3,640,3,3,3,3,642,4,641,3,3,3,3,640,3,3,3,3,0,0,0,0
0,0,0,0,3,37,0,0,0,212,639,638,212,4,4,4,212,637,636,212,0,0,0,37,3,0,0,0,0
0,0,0,0,3,0,0,635,0,336,0,0,634,0,4,0,633,0,0,336,0,0,0,0,3,0,0,0,0
0,0,0,0,3,632,0,0,0,336,631,0,0,0,0,0,0,0,0,336,0,630,0,37,3,0,0,0,0
0,0,0,0,3,51,629,628,0,336,0,0,627,0,626,625,0,0,0,336,0,0,624,51,3,0,0,0,0
0,0,0,0,260,3,623,0,0,0,0,212,3,3,3,3,3,212,0,0,0,0,622,3,260,0,0,0,0
0,0,0,0,0,3,621,0,0,0,620,619,0,0,0,0,0,619,618,0,0,0,617,3,0,0,0,0,0
0,0,0,0,0,3,3,3,3,616,3,3,0,0,0,0,0,3,3,616,3,3,3,3,0,0,0,0,0
0,0,0,0,0,0,3,615,0,0,0,3,0,0,0,0,0,3,0,0,0,614,3,0,0,0,0,0,0
0,0,0,0,0,0,3,613,0,612,0,3,0,212,0,0,0,3,0,611,0,610,3,0,0,0,0,0,0
0,0,0,0,0,0,468,3,272,0,0,3,0,0,0,212,0,3,0,0,272,3,468,0,0,0,0,0,0
0,0,0,0,0,0,468,3,3,0,0,3,0,0,0,0,0,3,0,0,3,3,468,0,0,0,0,0,0
0,0,0,0,0,0,0,460,603,51,0,3,0,0,212,0,0,3,0,51,603,460,0,0,0,0,0,0,0
0,0,0,0,0,0,0,460,603,51,0,0,3,0,4,0,3,0,0,51,603,460,0,0,0,0,0,0,0
0,0,0,0,0,0,0,0,0,51,609,0,3,4,4,4,3,0,608,51,0,0,0,0,0,0,0,0,0
0,0,0,0,0,0,0,0,0,51,51,0,0,3,4,3,0,0,51,51,0,0,0,0,0,0,0,0,0
0,0,0,0,0,0,0,0,0,0,51,0,0,3,3,3,0,0,51,0,0,0,0,0,0,0,0,0,0
0,0,0,0,0,0,0,0,0,0,51,51,0,607,603,606,0,51,51,0,0,0,0,0,0,0,0,0,0
0,0,0,0,0,0,0,0,0,0,0,51,605,78,603,78,604,51,0,0,0,0,0,0,0,0,0,0,0
0,0,0,0,0,0,0,0,0,0,0,51,272,603,603,603,272,51,0,0,0,0,0,0,0,0,0,0,0
0,0,0,0,0,0,0,0,0,0,0,0,3,603,603,603,3,0,0,0,0,0,0,0,0,0,0,0,0
0,0,0,0,0,0,0,0,0,0,0,0,3,603,603,603,3,0,0,0,0,0,0,0,0,0,0,0,0
0,0,0,0,0,0,0,0,0,0,0,0,565,3,603,3,565,0,0,0,0,0,0,0,0,0,0,0,0
0,0,0,0,0,0,0,0,0,0,0,0,0,3,3,3,0,0,0,0,0,0,0,0,0,0,0,0,0
0,0,0,0,0,0,0,0,0,0,0,0,0,565,3,565,0,0,0,0,0,0,0,0,0,0,0,0,0
0,0,0,0,0,0,0,0,0,0,0,0,0,601,3,601,0,0,0,0,0,0,0,0,0,0,0,0,0
0,0,0,0,0,0,0,0,0,0,0,0,0,468,565,468,0,0,0,0,0,0,0,0,0,0,0,0,0
0,0,0,0,0,0,0,0,0,0,0,0,0,0,265,0,0,0,0,0,0,0,0,0,0,0,0,0,0
0,0,0,0,0,0,0,0,0,0,0,0,0,0,468,0,0,0,0,0,0,0,0,0,0,0,0,0,0
0,0,0,0,0,0,0,0,0,0,0,0,0,0,0,0,0,0,0,0,0,0,0,0,0,0,0,0,0
0,0,0,0,0,0,0,0,0,0,0,0,0,0,0,0,0,0,0,0,0,0,0,0,0,0,0,0,0
0,0,0,0,0,0,0,0,0,0,0,0,0,0,0,0,0,0,0,0,0,0,0,0,0,0,0,0,0
0,0,0,0,0,0,0,0,0,0,0,0,0,0,0,0,0,0,0,0,0,0,0,0,0,0,0,0,0
0,0,0,0,0,0,0,0,0,0,0,0,0,0,0,0,0,0,0,0,0,0,0,0,0,0,0,0,0
0,0,0,0,0,0,0,0,0,0,0,0,0,0,0,0,0,0,0,0,0,0,0,0,0,0,0,0,0
0,0,0,0,0,0,0,0,0,0,0,0,0,0,0,0,0,0,0,0,0,0,0,0,0,0,0,0,0
0,0,0,0,0,0,0,0,0,0,0,0,0,0,0,0,0,0,0,0,0,0,0,0,0,0,0,0,0
:endlayer
layer: 12
0,0,0,0,0,0,0,0,0,0,0,0,0,0,0,0,0,0,0,0,0,0,0,0,0,0,0,0,0
0,0,0,0,0,0,0,0,0,0,0,0,0,0,0,0,0,0,0,0,0,0,0,0,0,0,0,0,0
0,0,0,0,0,0,0,0,0,0,0,0,0,0,0,0,0,0,0,0,0,0,0,0,0,0,0,0,0
0,0,0,0,0,0,0,0,0,0,0,0,0,0,0,0,0,0,0,0,0,0,0,0,0,0,0,0,0
0,0,0,0,0,0,0,0,0,0,0,0,0,0,0,0,0,0,0,0,0,0,0,0,0,0,0,0,0
0,0,0,0,0,0,0,0,0,0,0,0,0,0,0,0,0,0,0,0,0,0,0,0,0,0,0,0,0
0,0,0,0,0,0,0,0,0,0,51,51,51,51,51,51,51,51,51,0,0,0,0,0,0,0,0,0,0
0,0,0,0,51,459,272,459,51,51,51,0,51,0,906,0,51,0,51,51,51,459,272,459,51,0,0,0,0
0,0,0,0,459,901,900,0,3,905,275,905,3,905,275,905,3,905,275,905,3,904,903,902,459,0,0,0,0
0,0,0,0,100,901,900,0,3,0,0,55,3,37,0,898,898,898,898,898,3,0,899,0,100,0,0,0,0
0,0,0,0,459,746,0,0,711,0,0,37,3,55,0,898,898,898,898,898,684,0,0,0,459,0,0,0,0
0,0,0,0,51,459,0,0,3,0,0,55,3,692,4,898,898,898,898,898,3,692,692,459,51,0,0,0,0
0,0,0,0,459,3,3,3,3,0,0,0,3,4,4,4,3,0,0,0,3,3,3,3,459,0,0,0,0
0,0,0,0,3,897,0,896,3,0,0,0,0,0,4,0,0,0,0,0,3,897,0,896,3,0,0,0,0
0,0,0,0,587,897,0,896,3,0,0,0,0,837,3,0,0,0,0,0,3,897,0,896,587,0,0,0,0
0,0,0,0,3,3,786,3,0,0,0,0,0,895,3,0,0,0,0,0,894,3,785,3,3,0,0,0,0
0,0,0,0,587,0,0,0,0,0,0,0,0,764,3,0,0,0,0,0,0,0,0,0,587,0,0,0,0
0,0,0,0,3,893,0,0,0,0,0,0,0,892,3,0,0,0,0,0,0,0,0,0,3,0,0,0,0
0,0,0,0,587,0,0,0,214,0,0,0,0,891,3,0,0,0,0,0,890,0,0,0,587,0,0,0,0
0,0,0,51,3,889,0,0,0,0,0,0,0,764,3,0,0,0,0,0,0,0,0,0,3,51,0,0,0
0,0,0,0,477,0,0,0,0,0,0,0,0,0,3,0,0,0,888,0,887,886,0,0,478,0,0,0,0
0,0,0,51,3,3,3,3,3,3,3,3,477,478,3,477,478,3,3,3,3,3,3,3,3,51,0,0,0
0,0,0,0,587,0,0,885,884,0,0,3,0,0,0,0,0,0,785,0,0,880,883,0,587,0,0,0,0
0,0,0,0,3,882,0,0,0,0,881,3,0,0,0,0,0,0,786,0,0,0,0,880,3,0,0,0,0
0,0,0,0,587,0,0,0,0,0,0,3,0,0,4,3,3,3,3,212,0,0,0,212,587,0,0,0,0
0,0,0,0,3,879,0,0,0,0,878,3,214,4,4,4,877,0,0,0,0,0,0,0,3,0,0,0,0
0,0,0,0,587,0,0,0,0,0,0,876,3,875,4,874,3,212,0,0,873,872,0,212,587,0,0,0,0
0,0,0,51,3,3,3,477,478,3,3,3,3,0,0,0,0,0,0,871,0,870,0,0,3,51,0,0,0
0,0,0,0,477,0,0,0,0,212,0,0,3,869,0,0,0,0,0,0,0,0,0,0,478,0,0,0,0
0,0,0,51,3,0,0,0,0,212,0,0,3,0,0,0,0,0,0,0,0,0,0,0,3,51,0,0,0
0,0,0,0,587,0,0,0,0,212,0,0,0,0,0,0,3,212,0,0,868,0,0,212,587,0,0,0,0
0,0,0,0,3,867,0,0,0,0,0,0,0,0,0,866,3,865,0,0,864,0,0,0,3,0,0,0,0
0,0,0,0,587,0,212,0,212,0,212,0,0,863,0,0,3,143,0,0,862,0,0,0,587,0,0,0,0
0,0,0,0,3,0,212,0,212,0,212,0,3,692,0,861,3,860,0,0,859,0,0,0,3,0,0,0,0
0,0,0,0,587,0,212,0,212,0,212,0,3,692,0,0,3,212,0,0,143,0,0,212,587,0,0,0,0
0,0,0,51,3,3,3,3,3,3,3,3,3,692,0,0,0,3,0,0,0,0,0,858,3,51,0,0,0
0,0,0,0,477,0,0,853,853,853,0,0,785,857,0,0,0,0,3,0,0,0,0,0,478,0,0,0,0
0,0,0,51,3,853,0,0,0,0,0,0,3,856,4,0,0,0,694,3,0,0,0,0,3,51,0,0,0
0,0,0,0,587,853,0,0,853,0,0,0,3,4,4,4,51,0,694,3,212,855,854,212,587,0,0,0,0
0,0,0,0,3,853,0,0,0,0,0,0,3,0,4,0,0,0,694,3,3,3,3,3,3,0,0,0,0
0,0,0,0,587,853,852,851,51,0,0,0,3,0,0,0,0,0,737,3,701,850,849,694,587,0,0,0,0
0,0,0,0,3,3,3,3,3,477,478,3,3,0,0,0,0,0,0,3,692,0,0,694,3,0,0,0,0
0,0,0,0,587,0,0,0,0,0,0,848,3,0,0,0,0,0,23,3,692,0,0,694,587,0,0,0,0
0,0,0,51,3,0,0,847,0,0,0,548,3,0,0,0,0,0,23,3,692,0,0,212,3,51,0,0,0
0,0,0,0,477,0,846,0,845,211,0,844,3,0,0,0,0,0,843,3,23,0,0,0,478,0,0,0,0
0,0,0,51,3,0,548,0,842,0,0,0,3,0,0,0,51,0,841,3,23,0,0,0,3,51,0,0,0
0,0,0,0,587,0,0,840,0,0,0,0,0,0,0,0,0,0,839,3,23,0,0,838,587,0,0,0,0
0,0,0,0,3,0,0,0,0,0,0,0,0,0,0,0,0,0,0,3,212,0,0,837,3,0,0,0,0
0,0,0,0,587,0,0,0,836,0,0,0,0,0,0,0,0,0,0,786,0,0,0,835,587,0,0,0,0
0,0,0,0,3,0,0,0,834,0,0,0,3,0,0,0,0,0,0,3,212,0,0,833,3,0,0,0,0
0,0,0,0,587,0,832,831,0,548,0,0,3,830,4,3,786,3,3,3,19,19,5,212,587,0,0,0,0
0,0,0,51,3,0,0,829,828,0,0,0,3,4,4,4,0,0,3,3,3,3,3,3,3,51,0,0,0
0,0,0,0,477,0,0,0,0,0,0,0,3,827,4,478,0,0,0,0,826,0,0,825,478,0,0,0,0
0,0,0,51,3,0,824,0,0,823,0,0,3,293,0,0,3,0,822,0,821,0,820,0,3,51,0,0,0
0,0,0,0,587,0,0,211,819,818,0,0,3,288,293,0,3,0,814,817,816,815,814,0,587,0,0,0,0
0,0,0,0,3,0,0,813,0,0,0,211,3,0,0,0,3,0,0,0,0,0,0,0,3,0,0,0,0
0,0,0,0,587,0,0,0,812,0,0,0,3,374,374,374,3,811,810,0,0,0,809,808,587,0,0,0,0
0,0,0,0,3,0,0,0,0,0,0,0,3,370,370,370,3,0,0,0,0,0,0,0,3,0,0,0,0
0,0,0,0,587,0,0,807,0,0,0,0,3,0,0,0,3,0,0,0,0,0,0,0,587,0,0,0,0
0,0,0,51,3,0,548,0,806,0,0,0,3,0,0,0,3,0,0,0,0,0,0,0,3,51,0,0,0
0,0,0,0,477,0,805,804,0,803,0,0,0,0,0,0,0,0,0,0,0,0,0,802,478,0,0,0,0
0,0,0,51,3,0,0,801,800,0,0,0,0,0,0,0,0,0,0,0,0,0,0,0,3,51,0,0,0
0,0,0,0,587,0,0,0,0,0,0,0,0,0,0,0,0,0,0,0,799,0,0,798,587,0,0,0,0
0,0,0,0,3,3,3,3,785,3,3,3,3,797,4,796,3,3,3,3,786,3,3,3,3,0,0,0,0
0,0,0,0,587,0,0,0,0,212,795,794,212,4,4,4,212,793,792,212,0,0,0,0,587,0,0,0,0
0,0,0,0,3,0,0,0,0,0,0,0,0,0,4,0,0,0,0,0,0,0,0,0,3,0,0,0,0
0,0,0,0,587,0,0,0,0,0,0,0,0,0,791,0,0,0,0,0,0,0,0,0,587,0,0,0,0
0,0,0,0,3,51,0,0,0,0,0,0,0,0,0,0,0,0,0,0,0,0,0,51,3,0,0,0,0
0,0,0,0,459,3,790,0,0,0,0,212,0,0,0,0,0,212,0,0,0,0,789,3,459,0,0,0,0
0,0,0,0,468,3,788,0,0,0,0,0,0,0,0,0,0,0,0,0,0,0,787,3,468,0,0,0,0
0,0,0,0,468,3,3,3,3,786,3,3,0,0,0,0,0,3,3,785,3,3,3,3,468,0,0,0,0
0,0,0,0,0,460,3,256,0,0,0,3,0,0,0,0,0,3,0,0,0,255,3,460,0,0,0,0,0
0,0,0,0,0,460,3,256,0,0,0,587,0,108,0,0,0,587,0,0,0,255,3,460,0,0,0,0,0
0,0,0,0,0,0,0,3,51,0,0,3,0,0,0,108,0,3,0,0,51,3,0,0,0,0,0,0,0
0,0,0,0,0,0,0,565,51,0,0,587,0,0,0,0,0,587,0,0,51,565,0,0,0,0,0,0,0
0,0,0,0,0,0,0,0,784,783,0,3,0,0,108,0,0,3,0,783,784,0,0,0,0,0,0,0,0
0,0,0,0,0,0,0,0,784,0,0,0,3,160,4,160,3,0,0,0,784,0,0,0,0,0,0,0,0
0,0,0,0,0,0,0,0,0,0,0,0,3,4,4,4,3,0,0,0,0,0,0,0,0,0,0,0,0
0,0,0,0,0,0,0,0,0,0,783,0,468,3,4,3,468,0,783,0,0,0,0,0,0,0,0,0,0
0,0,0,0,0,0,0,0,0,0,0,0,468,3,3,3,468,0,0,0,0,0,0,0,0,0,0,0,0
0,0,0,0,0,0,0,0,0,0,0,783,0,460,3,460,0,783,0,0,0,0,0,0,0,0,0,0,0
0,0,0,0,0,0,0,0,0,0,0,0,0,460,459,460,0,0,0,0,0,0,0,0,0,0,0,0,0
0,0,0,0,0,0,0,0,0,0,0,0,51,460,603,460,51,0,0,0,0,0,0,0,0,0,0,0,0
0,0,0,0,0,0,0,0,0,0,0,0,51,460,603,460,51,0,0,0,0,0,0,0,0,0,0,0,0
0,0,0,0,0,0,0,0,0,0,0,0,51,78,603,78,51,0,0,0,0,0,0,0,0,0,0,0,0
0,0,0,0,0,0,0,0,0,0,0,0,782,603,603,603,782,0,0,0,0,0,0,0,0,0,0,0,0
0,0,0,0,0,0,0,0,0,0,0,0,468,603,603,603,468,0,0,0,0,0,0,0,0,0,0,0,0
0,0,0,0,0,0,0,0,0,0,0,0,0,75,603,75,0,0,0,0,0,0,0,0,0,0,0,0,0
0,0,0,0,0,0,0,0,0,0,0,0,0,782,603,782,0,0,0,0,0,0,0,0,0,0,0,0,0
0,0,0,0,0,0,0,0,0,0,0,0,0,459,3,459,0,0,0,0,0,0,0,0,0,0,0,0,0
0,0,0,0,0,0,0,0,0,0,0,0,0,468,781,468,0,0,0,0,0,0,0,0,0,0,0,0,0
0,0,0,0,0,0,0,0,0,0,0,0,0,468,3,468,0,0,0,0,0,0,0,0,0,0,0,0,0
0,0,0,0,0,0,0,0,0,0,0,0,0,0,265,0,0,0,0,0,0,0,0,0,0,0,0,0,0
0,0,0,0,0,0,0,0,0,0,0,0,0,0,0,0,0,0,0,0,0,0,0,0,0,0,0,0,0
0,0,0,0,0,0,0,0,0,0,0,0,0,0,0,0,0,0,0,0,0,0,0,0,0,0,0,0,0
0,0,0,0,0,0,0,0,0,0,0,0,0,0,0,0,0,0,0,0,0,0,0,0,0,0,0,0,0
0,0,0,0,0,0,0,0,0,0,0,0,0,0,0,0,0,0,0,0,0,0,0,0,0,0,0,0,0
0,0,0,0,0,0,0,0,0,0,0,0,0,0,0,0,0,0,0,0,0,0,0,0,0,0,0,0,0
0,0,0,0,0,0,0,0,0,0,0,0,0,0,0,0,0,0,0,0,0,0,0,0,0,0,0,0,0
0,0,0,0,0,0,0,0,0,0,0,0,0,0,0,0,0,0,0,0,0,0,0,0,0,0,0,0,0
:endlayer
layer: 13
0,0,0,0,0,0,0,0,0,0,0,0,0,0,0,0,0,0,0,0,0,0,0,0,0,0,0,0,0
0,0,0,0,0,0,0,0,0,0,0,0,0,0,0,0,0,0,0,0,0,0,0,0,0,0,0,0,0
0,0,0,0,0,0,0,0,0,0,0,0,0,0,0,0,0,0,0,0,0,0,0,0,0,0,0,0,0
0,0,0,0,0,0,0,0,0,0,0,0,0,0,0,0,0,0,0,0,0,0,0,0,0,0,0,0,0
0,0,0,0,0,0,0,0,0,0,0,0,0,0,0,0,0,0,0,0,0,0,0,0,0,0,0,0,0
0,0,0,0,0,0,0,0,0,0,0,0,0,0,0,0,0,0,0,0,0,0,0,0,0,0,0,0,0
0,0,0,0,0,0,0,0,0,0,0,0,783,0,0,0,783,0,0,0,0,0,0,0,0,0,0,0,0
0,0,0,0,51,3,587,3,51,0,0,0,51,0,0,0,51,0,0,0,51,3,587,3,51,0,0,0,0
0,0,0,0,3,0,0,0,3,905,478,905,3,905,477,905,3,905,477,905,3,888,0,0,3,0,0,0,0
0,0,0,0,587,0,0,0,3,0,0,0,3,888,0,0,0,0,0,0,3,0,0,0,587,0,0,0,0
0,0,0,0,3,214,0,0,786,0,0,0,3,0,0,0,0,0,0,0,786,0,0,0,3,0,0,0,0
0,0,0,0,51,3,0,0,3,0,0,0,3,692,4,0,0,0,0,0,3,0,888,3,51,0,0,0,0
0,0,0,0,272,3,3,3,3,0,0,0,3,4,4,4,3,0,0,0,3,3,3,3,272,0,0,0,0
0,0,0,0,3,0,913,0,3,0,0,0,0,966,4,0,913,0,0,0,3,0,913,0,3,0,0,0,0
0,0,0,0,3,0,0,0,3,0,0,0,0,965,3,0,0,0,0,0,3,0,0,0,3,0,0,0,0
0,0,0,0,3,3,3,3,964,0,0,0,0,963,3,0,0,0,0,0,962,3,3,3,3,0,0,0,0
0,0,0,0,3,909,0,0,0,0,0,0,0,764,3,0,0,0,0,0,0,0,0,908,3,0,0,0,0
0,0,0,0,3,0,0,0,0,0,0,0,0,961,3,909,0,0,0,0,0,0,0,960,3,0,0,0,0
0,0,0,0,3,0,0,0,0,0,0,0,0,959,3,0,0,0,0,0,0,0,0,0,3,0,0,0,0
0,0,0,918,3,0,0,0,0,0,0,0,0,764,3,0,0,0,0,0,0,0,0,958,3,918,0,0,0
0,0,0,255,3,0,0,0,0,0,0,0,0,0,3,0,0,0,957,910,0,0,0,0,3,255,0,0,0
0,0,0,918,3,3,3,3,3,3,3,3,3,3,3,3,3,3,3,3,3,3,3,3,3,918,0,0,0
0,0,0,0,3,954,0,0,0,0,953,3,0,0,913,0,0,0,3,0,913,0,0,0,3,0,0,0,0
0,0,0,0,3,954,0,0,0,0,953,3,0,0,0,956,0,0,3,0,0,0,0,0,3,0,0,0,0
0,0,0,0,3,954,591,0,0,591,953,3,0,955,4,3,3,3,3,256,261,261,261,255,3,0,0,0,0
0,0,0,0,3,954,0,0,0,0,953,3,0,4,4,4,909,0,0,0,0,0,0,0,3,0,0,0,0
0,0,0,0,3,954,0,0,0,0,953,952,3,951,4,950,3,256,261,261,261,261,261,255,3,0,0,0,0
0,0,0,918,3,3,3,3,3,3,3,3,3,0,913,0,260,0,0,0,0,0,0,0,3,918,0,0,0
0,0,0,255,3,909,0,0,0,212,0,0,3,0,0,0,261,0,0,0,0,0,0,908,3,255,0,0,0
0,0,0,918,3,0,0,0,0,212,0,0,3,0,0,0,262,0,0,0,0,0,0,0,3,918,0,0,0
0,0,0,0,3,0,0,0,591,212,0,0,260,0,0,0,3,256,261,261,261,261,261,255,3,0,0,0,0
0,0,0,0,3,0,0,0,0,0,0,0,261,0,0,0,3,0,0,0,0,0,0,0,3,0,0,0,0
0,0,0,0,3,0,212,0,212,0,212,0,262,0,0,908,3,0,0,0,0,0,0,0,3,0,0,0,0
0,0,0,0,3,0,212,0,212,0,212,0,3,460,0,0,3,0,0,0,0,0,0,0,3,0,0,0,0
0,0,0,0,3,0,212,0,212,0,212,0,3,460,0,0,3,256,261,261,261,261,261,255,3,0,0,0,0
0,0,0,918,3,3,3,3,3,3,3,3,3,460,0,0,0,3,0,0,0,0,0,0,3,918,0,0,0
0,0,0,255,3,0,0,0,913,0,0,0,3,0,910,0,0,0,3,0,0,0,0,908,3,255,0,0,0
0,0,0,918,3,0,0,0,0,0,0,0,3,0,4,0,0,0,694,3,0,0,0,0,3,918,0,0,0
0,0,0,0,3,909,0,0,0,0,0,908,3,4,4,4,51,0,694,3,256,261,261,255,3,0,0,0,0
0,0,0,0,3,0,0,0,0,0,0,0,3,0,4,0,51,0,694,3,3,3,3,3,3,0,0,0,0
0,0,0,0,3,0,949,948,51,0,0,0,3,0,0,0,51,0,737,3,701,468,468,694,3,0,0,0,0
0,0,0,0,3,3,3,3,3,3,3,3,3,909,0,0,51,0,908,3,692,0,0,694,3,0,0,0,0
0,0,0,0,3,0,0,0,0,0,0,0,3,0,0,0,51,0,0,3,692,0,0,694,3,0,0,0,0
0,0,0,918,3,947,0,0,0,0,0,946,3,0,0,0,51,0,0,3,692,0,0,212,3,918,0,0,0
0,0,0,255,3,0,0,0,0,0,0,0,3,909,0,0,51,0,908,3,23,0,0,908,3,255,0,0,0
0,0,0,918,3,945,0,0,0,0,0,944,3,0,0,0,51,0,0,3,23,0,0,0,3,918,0,0,0
0,0,0,0,3,0,0,0,0,0,0,0,260,0,0,0,0,0,0,3,23,0,0,0,3,0,0,0,0
0,0,0,0,3,943,0,0,0,0,0,0,261,0,0,0,0,0,908,3,212,0,0,0,3,0,0,0,0
0,0,0,0,3,0,0,0,0,0,0,0,262,0,0,0,0,0,0,3,0,0,0,0,3,0,0,0,0
0,0,0,0,3,942,0,0,0,0,0,941,3,0,0,0,910,0,0,3,212,0,0,0,3,0,0,0,0
0,0,0,0,3,0,0,0,0,0,0,0,3,262,4,3,3,3,3,3,19,19,5,212,3,0,0,0,0
0,0,0,918,3,940,0,0,0,0,0,939,3,4,4,4,0,255,3,3,3,3,3,3,3,918,0,0,0
0,0,0,255,3,0,0,0,0,0,0,0,3,260,4,260,262,0,468,468,938,468,468,937,3,255,0,0,0
0,0,0,918,3,936,0,0,0,0,0,935,3,0,913,0,3,922,0,0,0,0,0,919,3,918,0,0,0
0,0,0,0,3,0,0,0,0,0,0,0,3,293,0,0,3,934,814,0,0,0,814,933,3,0,0,0,0
0,0,0,0,3,932,0,0,0,0,0,931,3,374,374,374,3,922,0,0,0,0,0,919,3,0,0,0,0
0,0,0,0,3,0,0,0,0,0,0,0,3,370,370,370,3,930,0,0,0,0,0,929,3,0,0,0,0
0,0,0,0,3,928,0,0,0,0,0,927,3,0,0,0,3,922,0,0,0,0,0,919,3,0,0,0,0
0,0,0,0,3,0,0,0,0,0,0,0,3,0,0,0,3,926,0,0,0,0,0,925,3,0,0,0,0
0,0,0,918,3,924,0,0,0,0,0,923,3,0,0,0,3,922,0,0,0,0,0,919,3,918,0,0,0
0,0,0,255,3,0,0,0,0,0,0,0,260,0,0,0,260,0,0,0,0,0,0,921,3,255,0,0,0
0,0,0,918,3,920,0,0,0,0,0,0,261,0,0,0,261,0,0,0,0,0,0,919,3,918,0,0,0
0,0,0,0,3,0,0,0,0,0,0,0,262,0,910,0,262,0,0,917,0,917,0,916,3,0,0,0,0
0,0,0,0,3,3,3,3,3,3,3,3,3,0,4,0,3,3,3,3,3,3,3,3,3,0,0,0,0
0,0,0,0,3,0,915,0,0,212,468,468,212,4,4,4,212,468,468,212,0,0,914,0,3,0,0,0,0
0,0,0,0,3,909,0,0,0,0,0,0,0,0,4,0,0,0,0,0,0,0,0,908,3,0,0,0,0
0,0,0,0,3,0,0,0,0,0,0,0,0,0,913,0,0,0,0,0,0,0,0,0,3,0,0,0,0
0,0,0,0,3,51,51,0,0,0,0,0,0,0,0,0,0,0,0,0,0,0,51,51,3,0,0,0,0
0,0,0,0,565,3,256,0,0,0,0,212,212,212,212,212,212,212,0,0,0,0,255,3,565,0,0,0,0
0,0,0,0,0,3,256,910,0,0,912,212,0,0,0,0,0,212,911,0,0,910,255,3,0,0,0,0,0
0,0,0,0,0,3,3,3,3,3,3,3,0,0,0,0,0,3,3,3,3,3,3,3,0,0,0,0,0
0,0,0,0,0,0,3,51,0,0,0,3,909,0,0,0,908,3,0,0,0,51,3,0,0,0,0,0,0
0,0,0,0,0,0,565,51,0,0,0,587,0,0,0,0,0,587,0,0,0,51,565,0,0,0,0,0,0
0,0,0,0,0,0,0,51,783,0,0,3,0,0,0,0,0,3,0,0,783,51,0,0,0,0,0,0,0
0,0,0,0,0,0,0,0,0,0,468,3,0,0,0,0,0,3,468,0,0,0,0,0,0,0,0,0,0
0,0,0,0,0,0,0,0,784,0,468,565,262,0,262,0,262,565,468,0,784,0,0,0,0,0,0,0,0
0,0,0,0,0,0,0,0,784,0,0,460,3,262,4,262,3,460,0,0,784,0,0,0,0,0,0,0,0
0,0,0,0,0,0,0,0,0,0,0,460,565,4,4,4,565,460,0,0,0,0,0,0,0,0,0,0,0
0,0,0,0,0,0,0,0,0,0,0,0,0,3,4,3,0,0,0,0,0,0,0,0,0,0,0,0,0
0,0,0,0,0,0,0,0,0,0,0,0,0,565,3,565,0,0,0,0,0,0,0,0,0,0,0,0,0
0,0,0,0,0,0,0,0,0,0,0,0,0,468,3,468,0,0,0,0,0,0,0,0,0,0,0,0,0
0,0,0,0,0,0,0,0,0,0,0,0,0,468,565,468,0,0,0,0,0,0,0,0,0,0,0,0,0
0,0,0,0,0,0,0,0,0,0,0,0,0,468,0,468,0,0,0,0,0,0,0,0,0,0,0,0,0
0,0,0,0,0,0,0,0,0,0,0,0,0,460,0,460,0,0,0,0,0,0,0,0,0,0,0,0,0
0,0,0,0,0,0,0,0,0,0,0,0,907,460,78,460,907,0,0,0,0,0,0,0,0,0,0,0,0
0,0,0,0,0,0,0,0,0,0,0,0,0,460,603,460,0,0,0,0,0,0,0,0,0,0,0,0,0
0,0,0,0,0,0,0,0,0,0,0,0,0,78,603,78,0,0,0,0,0,0,0,0,0,0,0,0,0
0,0,0,0,0,0,0,0,0,0,0,0,460,603,603,603,460,0,0,0,0,0,0,0,0,0,0,0,0
0,0,0,0,0,0,0,0,0,0,0,0,468,603,603,603,468,0,0,0,0,0,0,0,0,0,0,0,0
0,0,0,0,0,0,0,0,0,0,0,0,0,75,603,75,0,0,0,0,0,0,0,0,0,0,0,0,0
0,0,0,0,0,0,0,0,0,0,0,0,0,0,603,0,0,0,0,0,0,0,0,0,0,0,0,0,0
0,0,0,0,0,0,0,0,0,0,0,0,0,0,75,0,0,0,0,0,0,0,0,0,0,0,0,0,0
0,0,0,0,0,0,0,0,0,0,0,0,0,0,782,0,0,0,0,0,0,0,0,0,0,0,0,0,0
0,0,0,0,0,0,0,0,0,0,0,0,0,0,468,0,0,0,0,0,0,0,0,0,0,0,0,0,0
0,0,0,0,0,0,0,0,0,0,0,0,0,0,0,0,0,0,0,0,0,0,0,0,0,0,0,0,0
0,0,0,0,0,0,0,0,0,0,0,0,0,0,0,0,0,0,0,0,0,0,0,0,0,0,0,0,0
0,0,0,0,0,0,0,0,0,0,0,0,0,0,0,0,0,0,0,0,0,0,0,0,0,0,0,0,0
0,0,0,0,0,0,0,0,0,0,0,0,0,0,0,0,0,0,0,0,0,0,0,0,0,0,0,0,0
0,0,0,0,0,0,0,0,0,0,0,0,0,0,0,0,0,0,0,0,0,0,0,0,0,0,0,0,0
0,0,0,0,0,0,0,0,0,0,0,0,0,0,0,0,0,0,0,0,0,0,0,0,0,0,0,0,0
:endlayer
layer: 14
0,0,0,0,0,0,0,0,0,0,0,0,0,0,0,0,0,0,0,0,0,0,0,0,0,0,0,0,0
0,0,0,0,0,0,0,0,0,0,0,0,0,0,0,0,0,0,0,0,0,0,0,0,0,0,0,0,0
0,0,0,0,0,0,0,0,0,0,0,0,0,0,0,0,0,0,0,0,0,0,0,0,0,0,0,0,0
0,0,0,0,0,0,0,0,0,0,0,0,0,0,0,0,0,0,0,0,0,0,0,0,0,0,0,0,0
0,0,0,0,0,0,0,0,0,0,0,0,0,0,0,0,0,0,0,0,0,0,0,0,0,0,0,0,0
0,0,0,0,0,0,0,0,0,0,0,0,0,0,0,0,0,0,0,0,0,0,0,0,0,0,0,0,0
0,0,0,0,0,0,0,0,0,0,0,0,0,0,0,0,0,0,0,0,0,0,0,0,0,0,0,0,0
0,0,0,0,51,3,587,3,51,0,0,0,51,0,0,0,51,0,0,0,51,3,587,3,51,0,0,0,0
0,0,0,0,3,0,0,0,3,905,905,905,3,905,905,905,3,905,905,905,3,973,0,0,3,0,0,0,0
0,0,0,0,587,0,591,0,3,0,0,0,3,0,0,0,913,0,0,0,3,0,591,0,587,0,0,0,0
0,0,0,0,3,0,0,0,3,909,0,0,3,0,0,0,0,0,0,0,3,0,0,972,3,0,0,0,0
0,0,0,0,51,3,601,601,3,0,0,0,3,692,4,0,971,0,0,0,3,0,0,3,51,0,0,0,0
0,0,0,0,0,3,3,3,3,256,261,255,3,4,4,4,3,256,261,255,3,3,3,3,0,0,0,0,0
0,0,0,0,468,3,264,264,3,0,0,0,0,0,4,0,0,0,0,0,3,264,264,3,468,0,0,0,0
0,0,0,0,468,3,264,264,3,0,0,0,0,908,3,0,0,0,0,0,3,264,264,3,468,0,0,0,0
0,0,0,0,460,3,264,264,256,0,0,0,0,0,3,0,0,0,0,0,255,264,264,3,460,0,0,0,0
0,0,0,0,468,3,264,264,967,0,0,0,0,970,3,0,0,0,0,0,967,264,264,3,468,0,0,0,0
0,0,0,0,460,3,264,264,967,0,0,0,0,969,3,0,0,0,0,0,967,264,264,3,460,0,0,0,0
0,0,0,0,468,3,264,264,967,0,0,0,0,969,3,0,0,0,0,0,967,264,264,3,468,0,0,0,0
0,0,0,0,468,3,264,264,967,0,0,0,0,968,3,0,0,0,0,0,967,264,264,3,468,0,0,0,0
0,0,0,0,100,3,264,264,967,910,0,0,0,0,3,0,0,0,0,0,967,264,264,3,68,0,0,0,0
0,0,0,0,468,3,264,264,3,3,3,3,3,3,3,3,3,3,3,3,3,264,264,3,468,0,0,0,0
0,0,0,0,468,3,264,264,264,264,264,264,264,264,264,264,264,264,264,264,264,264,264,3,468,0,0,0,0
0,0,0,0,460,3,264,264,264,264,264,264,264,264,264,264,264,264,264,264,264,264,264,3,460,0,0,0,0
0,0,0,0,468,3,264,264,264,264,264,264,264,264,4,264,264,264,264,264,264,264,264,3,468,0,0,0,0
0,0,0,0,460,3,264,264,264,264,264,264,264,4,4,4,264,264,264,264,264,264,264,3,460,0,0,0,0
0,0,0,0,468,3,264,264,264,264,264,264,264,264,4,264,264,264,264,264,264,264,264,3,468,0,0,0,0
0,0,0,0,468,3,264,264,264,264,264,264,264,264,264,264,264,264,264,264,264,264,264,3,468,0,0,0,0
0,0,0,0,100,3,264,264,264,264,264,264,264,264,264,264,264,264,264,264,264,264,264,3,68,0,0,0,0
0,0,0,0,468,3,264,264,264,264,264,264,264,264,264,264,264,264,264,264,264,264,264,3,468,0,0,0,0
0,0,0,0,468,3,264,264,264,264,264,264,264,264,264,264,264,264,264,264,264,264,264,3,468,0,0,0,0
0,0,0,0,460,3,264,264,264,264,264,264,264,264,264,264,264,264,264,264,264,264,264,3,460,0,0,0,0
0,0,0,0,468,3,264,264,264,264,264,264,264,264,264,264,264,264,264,264,264,264,264,3,468,0,0,0,0
0,0,0,0,460,3,264,264,264,264,264,264,264,264,264,264,264,264,264,264,264,264,264,3,460,0,0,0,0
0,0,0,0,468,3,264,264,264,264,264,264,264,264,264,264,264,264,264,264,264,264,264,3,468,0,0,0,0
0,0,0,0,468,3,264,264,264,264,264,264,264,264,264,264,264,264,264,264,264,264,264,3,468,0,0,0,0
0,0,0,0,100,3,264,264,264,264,264,264,264,264,264,264,264,264,264,264,264,264,264,3,68,0,0,0,0
0,0,0,0,468,3,264,264,264,264,264,264,264,264,4,264,264,264,264,264,264,264,264,3,468,0,0,0,0
0,0,0,0,468,3,264,264,264,264,264,264,264,4,4,4,264,264,264,264,264,264,264,3,468,0,0,0,0
0,0,0,0,460,3,264,264,264,264,264,264,264,264,4,264,264,264,264,264,264,264,264,3,460,0,0,0,0
0,0,0,0,468,3,264,264,264,264,264,264,264,264,264,264,264,264,264,264,264,264,264,3,468,0,0,0,0
0,0,0,0,460,3,264,264,264,264,264,264,264,264,264,264,264,264,264,264,264,264,264,3,460,0,0,0,0
0,0,0,0,468,3,264,264,264,264,264,264,264,264,264,264,264,264,264,264,264,264,264,3,468,0,0,0,0
0,0,0,0,468,3,264,264,264,264,264,264,264,264,264,264,264,264,264,264,264,264,264,3,468,0,0,0,0
0,0,0,0,100,3,264,264,264,264,264,264,264,264,264,264,264,264,264,264,264,264,264,3,68,0,0,0,0
0,0,0,0,468,3,264,264,264,264,264,264,264,264,264,264,264,264,264,264,264,264,264,3,468,0,0,0,0
0,0,0,0,468,3,264,264,264,264,264,264,264,264,264,264,264,264,264,264,264,264,264,3,468,0,0,0,0
0,0,0,0,460,3,264,264,264,264,264,264,264,264,264,264,264,264,264,264,264,264,264,3,460,0,0,0,0
0,0,0,0,468,3,264,264,264,264,264,264,264,264,264,264,264,264,264,264,264,264,264,3,468,0,0,0,0
0,0,0,0,460,3,264,264,264,264,264,264,264,264,264,264,264,264,264,264,264,264,264,3,460,0,0,0,0
0,0,0,0,468,3,264,264,264,264,264,264,264,264,4,264,264,264,264,264,264,264,264,3,468,0,0,0,0
0,0,0,0,468,3,264,264,264,264,264,264,264,4,4,4,264,264,264,264,264,264,264,3,468,0,0,0,0
0,0,0,0,100,3,264,264,264,264,264,264,264,264,4,264,264,264,264,264,264,264,264,3,68,0,0,0,0
0,0,0,0,468,3,264,264,264,264,264,264,264,264,264,264,264,264,264,264,264,264,264,3,468,0,0,0,0
0,0,0,0,468,3,264,264,264,264,264,264,264,264,264,264,264,264,264,264,264,264,264,3,468,0,0,0,0
0,0,0,0,460,3,264,264,264,264,264,264,3,370,370,370,3,264,264,264,264,264,264,3,460,0,0,0,0
0,0,0,0,468,3,264,264,264,264,264,264,3,0,0,0,3,264,264,264,264,264,264,3,468,0,0,0,0
0,0,0,0,460,3,264,264,264,264,264,264,3,0,0,0,3,264,264,264,264,264,264,3,460,0,0,0,0
0,0,0,0,468,3,264,264,264,264,264,264,3,0,0,0,3,264,264,264,264,264,264,3,468,0,0,0,0
0,0,0,0,468,3,264,264,264,264,264,264,3,0,0,0,3,264,264,264,264,264,264,3,468,0,0,0,0
0,0,0,0,100,3,264,264,264,264,264,264,3,374,374,374,3,264,264,264,264,264,264,3,68,0,0,0,0
0,0,0,0,468,3,264,264,264,264,264,264,3,967,967,967,3,264,264,264,264,264,264,3,468,0,0,0,0
0,0,0,0,468,3,264,264,264,264,264,264,3,967,967,967,3,264,264,264,264,264,264,3,468,0,0,0,0
0,0,0,0,460,3,264,264,264,264,264,264,3,967,4,967,3,264,264,264,264,264,264,3,460,0,0,0,0
0,0,0,0,468,3,264,264,264,264,264,264,264,4,4,4,264,264,264,264,264,264,264,3,468,0,0,0,0
0,0,0,0,460,3,264,264,264,264,264,264,264,264,4,264,264,264,264,264,264,264,264,3,460,0,0,0,0
0,0,0,0,468,3,264,264,264,264,264,264,264,264,264,264,264,264,264,264,264,264,264,3,468,0,0,0,0
0,0,0,0,468,3,264,264,264,264,264,264,264,264,264,264,264,264,264,264,264,264,264,3,468,0,0,0,0
0,0,0,0,0,3,264,264,264,264,264,264,264,264,264,264,264,264,264,264,264,264,264,3,0,0,0,0,0
0,0,0,0,0,3,264,264,264,264,264,264,264,264,264,264,264,264,264,264,264,264,264,3,0,0,0,0,0
0,0,0,0,0,565,3,3,3,3,3,3,264,264,264,264,264,3,3,3,3,3,3,565,0,0,0,0,0
0,0,0,0,0,0,0,0,0,0,468,3,264,264,264,264,264,3,468,0,0,0,0,0,0,0,0,0,0
0,0,0,0,0,0,0,0,0,0,460,3,264,264,264,264,264,3,460,0,0,0,0,0,0,0,0,0,0
0,0,0,0,0,0,0,0,0,0,460,565,3,264,264,264,3,565,460,0,0,0,0,0,0,0,0,0,0
0,0,0,0,0,0,0,0,0,0,0,0,3,264,264,264,3,0,0,0,0,0,0,0,0,0,0,0,0
0,0,0,0,0,0,0,0,784,0,0,0,565,3,264,3,565,0,0,0,784,0,0,0,0,0,0,0,0
0,0,0,0,0,0,0,784,784,0,0,0,0,3,4,3,0,0,0,0,784,784,0,0,0,0,0,0,0
0,0,0,0,0,0,0,784,0,0,0,0,0,4,4,4,0,0,0,0,0,784,0,0,0,0,0,0,0
0,0,0,0,0,0,0,0,0,0,0,0,0,460,4,460,0,0,0,0,0,0,0,0,0,0,0,0,0
0,0,0,0,0,0,0,0,0,0,0,0,0,460,565,460,0,0,0,0,0,0,0,0,0,0,0,0,0
