# Ancient Warfare Structure Template File
# Auto-generated structure template file. created on: 5/17/2021 at: 20:38:49
# Lines beginning with # denote comments

header:
version=2.11
name=SurvivalBuildHarborJettyStart
mods=
size=16,12,16
offset=15,5,15
:endheader

#### VALIDATION ####
validation:
type=ground
structureAuthor=Loki61089
survival=true
worldGenEnabled=false
unique=false
preserveBlocks=true
preventNaturalHostileSpawns=false
selectionWeight=1
clusterValue=1
minDuplicateDistance=1
dimensionWhiteList=true
dimensionList=
biomeGroupList=
biomeWhiteList=true
biomeList=
leveling=0
fill=0
border=0
blockSwap=false
territoryName=
biomeReplacement=minecraft:
minGenerationHeight=0
maxGenerationHeight=255
:endvalidation

#### LAYERS ####
layer: 0
4,4,4,4,4,4,4,4,4,4,4,4,4,4,4,4
4,4,4,4,4,4,4,4,4,4,4,4,4,4,4,4
4,4,4,4,4,4,4,4,4,4,4,4,4,4,4,4
4,4,4,4,4,4,4,4,4,4,4,4,4,4,4,4
4,4,4,4,4,4,4,4,4,4,4,4,4,4,4,4
4,4,4,4,4,4,4,4,4,4,4,4,4,4,4,4
4,4,4,4,4,4,4,4,4,4,4,4,4,4,4,4
3,4,0,0,0,4,4,0,0,4,4,0,0,0,4,3
3,4,4,4,4,4,4,0,0,4,4,4,4,4,4,3
3,3,3,3,3,3,4,0,0,4,3,3,3,3,3,3
2,0,0,0,0,2,4,0,0,4,2,0,0,0,0,2
0,0,0,0,0,2,4,0,0,4,2,0,0,0,0,0
0,0,0,0,0,2,4,0,0,4,2,0,0,0,0,0
0,0,0,0,0,2,4,0,0,4,2,0,0,0,0,0
1,0,0,0,0,2,4,0,0,4,2,0,0,0,0,1
0,1,0,0,0,2,2,2,2,2,2,0,0,0,1,0
:endlayer
layer: 1
4,4,4,4,4,4,4,4,4,4,4,4,4,4,4,4
4,4,4,4,4,4,4,4,4,4,4,4,4,4,4,4
4,4,4,4,4,4,4,4,4,4,4,4,4,4,4,4
4,4,4,4,4,4,4,4,4,4,4,4,4,4,4,4
4,4,4,4,4,4,4,4,4,4,4,4,4,4,4,4
4,4,4,4,4,4,4,4,4,4,4,4,4,4,4,4
4,4,4,4,4,4,4,4,4,4,4,4,4,4,4,4
3,4,0,0,0,4,4,0,0,4,4,0,0,0,4,3
3,4,4,4,4,4,4,0,0,4,4,4,4,4,4,3
3,3,3,3,3,3,4,0,0,4,3,3,3,3,3,3
2,0,0,0,0,2,4,0,0,4,2,0,0,0,0,2
0,0,0,0,0,2,4,0,0,4,2,0,0,0,0,0
0,0,0,0,0,2,4,0,0,4,2,0,0,0,0,0
0,0,0,0,0,2,4,0,0,4,2,0,0,0,0,0
1,0,0,0,0,2,4,0,0,4,2,0,0,0,0,1
0,1,0,0,0,2,2,2,2,2,2,0,0,0,1,0
:endlayer
layer: 2
4,4,4,4,4,4,4,4,4,4,4,4,4,4,4,4
4,4,4,4,4,4,4,4,4,4,4,4,4,4,4,4
4,4,4,4,4,4,4,4,4,4,4,4,4,4,4,4
4,4,4,4,4,4,4,4,4,4,4,4,4,4,4,4
4,4,4,4,4,4,4,4,4,4,4,4,4,4,4,4
4,4,4,4,4,4,4,4,4,4,4,4,4,4,4,4
4,4,4,4,4,4,4,4,4,4,4,4,4,4,4,4
3,2,0,0,0,2,2,0,0,2,2,0,0,0,2,3
3,2,2,2,2,2,2,0,0,2,2,2,2,2,2,3
3,3,3,3,3,3,2,0,0,2,3,3,3,3,3,3
2,0,0,0,0,2,2,0,0,2,2,0,0,0,0,2
0,0,0,0,0,2,2,0,0,2,2,0,0,0,0,0
0,0,0,0,0,2,2,0,0,2,2,0,0,0,0,0
0,0,0,0,0,2,2,0,0,2,2,0,0,0,0,0
1,0,0,0,0,2,2,0,0,2,2,0,0,0,0,1
0,1,0,0,0,2,2,2,2,2,2,0,0,0,1,0
:endlayer
layer: 3
4,4,4,4,4,4,4,4,4,4,4,4,4,4,4,4
4,4,4,4,4,4,4,4,4,4,4,4,4,4,4,4
4,4,4,4,4,4,4,4,4,4,4,4,4,4,4,4
4,4,4,4,4,4,4,4,4,4,4,4,4,4,4,4
4,4,4,4,4,4,4,4,4,4,4,4,4,4,4,4
4,4,4,4,4,4,4,4,4,4,4,4,4,4,4,4
4,4,4,4,4,4,4,4,4,4,4,4,4,4,4,4
3,4,0,0,0,4,4,0,0,4,4,0,0,0,4,3
3,4,4,4,4,4,4,0,0,4,4,4,4,4,4,3
3,3,3,3,3,3,4,0,0,4,3,3,3,3,3,3
2,0,0,0,0,2,4,0,0,4,2,0,0,0,0,2
0,0,0,0,0,2,4,0,0,4,2,0,0,0,0,0
0,0,0,0,0,2,4,0,0,4,2,0,0,0,0,0
0,0,0,0,0,2,4,0,0,4,2,0,0,0,0,0
1,0,0,0,0,2,4,0,0,4,2,0,0,0,0,1
0,1,0,0,0,2,2,2,2,2,2,0,0,0,1,0
:endlayer
layer: 4
4,4,4,4,4,4,4,4,4,4,4,4,4,4,4,4
4,4,4,4,4,4,4,4,4,4,4,4,4,4,4,4
4,4,4,4,4,4,4,4,4,4,4,4,4,4,4,4
4,4,4,4,4,4,4,4,4,4,4,4,4,4,4,4
4,4,4,4,4,4,4,4,4,4,4,4,4,4,4,4
4,4,4,4,4,4,4,4,4,4,4,4,4,4,4,4
4,4,4,4,4,4,4,4,4,4,4,4,4,4,4,4
3,4,0,0,0,4,4,0,0,4,4,0,0,0,4,3
3,4,4,4,4,4,4,0,0,4,4,4,4,4,4,3
3,3,3,3,3,3,4,0,0,4,3,3,3,3,3,3
2,0,0,0,0,2,4,0,0,4,2,0,0,0,0,2
0,0,0,0,0,2,4,0,0,4,2,0,0,0,0,0
0,0,0,0,0,2,4,0,0,4,2,0,0,0,0,0
0,0,0,0,0,2,4,0,0,4,2,0,0,0,0,0
1,0,0,0,0,2,4,0,0,4,2,0,0,0,0,1
0,1,0,0,0,2,2,2,2,2,2,0,0,0,1,0
:endlayer
layer: 5
4,4,4,4,4,4,4,4,4,4,4,4,4,4,4,4
4,4,4,4,4,4,4,4,4,4,4,4,4,4,4,4
4,4,4,4,4,4,4,4,4,4,4,4,4,4,4,4
4,4,4,4,4,4,4,4,4,4,4,4,4,4,4,4
4,4,4,4,4,4,4,4,4,4,4,4,4,4,4,4
4,4,4,4,4,4,4,4,4,4,4,4,4,4,4,4
4,4,4,4,4,4,4,4,4,4,4,4,4,4,4,4
3,4,4,4,4,4,4,4,4,4,4,4,4,4,4,3
3,4,4,4,4,4,4,4,4,4,4,4,4,4,4,3
3,3,3,3,3,3,4,4,4,4,3,3,3,3,3,3
2,5,5,5,5,2,4,4,4,4,2,5,5,5,5,2
5,5,5,5,5,3,3,3,3,3,3,5,5,5,5,5
5,5,5,5,5,3,3,3,3,3,3,5,5,5,5,5
5,5,5,5,5,3,3,3,3,3,3,5,5,5,5,5
1,5,5,5,5,2,4,4,4,4,2,5,5,5,5,1
0,1,5,5,5,2,2,2,2,2,2,5,5,5,1,0
:endlayer
layer: 6
3,3,3,3,3,3,3,3,3,3,3,3,3,3,3,3
3,4,4,4,4,4,4,4,4,4,4,4,4,4,4,3
3,4,4,4,4,4,4,4,4,4,4,4,4,4,4,3
3,4,4,4,4,4,4,4,4,4,4,4,4,4,4,3
3,4,4,4,4,4,4,4,4,4,4,4,4,4,4,3
3,4,4,4,4,3,4,4,4,4,3,4,4,4,4,3
3,4,4,4,4,3,4,4,4,4,3,4,4,4,4,3
3,4,4,4,4,3,4,4,4,4,3,4,4,4,4,3
3,4,4,4,4,3,4,4,4,4,3,4,4,4,4,3
2,6,6,6,6,2,4,4,4,4,2,6,6,6,6,2
2,0,0,0,0,2,2,2,2,2,2,0,0,0,0,2
0,0,0,0,0,0,0,0,0,0,0,0,0,0,0,0
0,0,0,0,0,0,0,0,0,0,0,0,0,0,0,0
0,0,0,0,0,0,0,0,0,0,0,0,0,0,0,0
1,0,0,0,0,2,2,2,2,2,2,0,0,0,0,1
0,1,0,0,0,2,2,2,2,2,2,0,0,0,1,0
:endlayer
layer: 7
3,3,3,3,3,3,3,3,3,3,3,3,3,3,3,3
3,4,4,4,4,4,4,4,4,4,4,4,4,4,4,3
3,4,4,4,4,4,4,4,4,4,4,4,4,4,4,3
3,4,4,4,4,4,4,4,4,4,4,4,4,4,4,3
3,4,4,4,4,4,4,4,4,4,4,4,4,4,4,3
3,4,4,4,4,3,4,4,4,4,3,4,4,4,4,3
3,4,4,4,4,3,4,4,4,4,3,4,4,4,4,3
3,4,4,4,4,3,4,4,4,4,3,4,4,4,4,3
2,6,6,6,6,2,4,4,4,4,2,6,6,6,6,2
2,0,0,0,0,2,4,4,4,4,2,0,0,0,0,2
2,0,0,0,0,2,2,2,2,2,2,0,0,0,0,2
7,0,0,0,0,0,7,0,0,7,0,0,0,0,0,7
0,0,0,0,0,0,0,0,0,0,0,0,0,0,0,0
0,0,0,0,0,0,9,0,0,9,0,0,0,0,0,0
0,0,0,0,0,2,2,2,2,2,2,0,0,0,0,0
0,0,0,0,8,2,2,2,2,2,2,10,0,0,0,0
:endlayer
layer: 8
3,3,3,3,3,3,3,3,3,3,3,3,3,3,3,3
3,4,4,4,4,4,4,4,4,4,4,4,4,4,4,3
3,4,4,4,4,4,4,4,4,4,4,4,4,4,4,3
3,4,4,4,4,4,4,4,4,4,4,4,4,4,4,3
3,4,4,4,4,4,4,4,4,4,4,4,4,4,4,3
3,4,4,4,4,3,4,4,4,4,3,4,4,4,4,3
3,4,4,4,4,3,4,4,4,4,3,4,4,4,4,3
2,6,6,6,6,2,4,4,4,4,2,6,6,6,6,2
2,0,0,0,0,2,4,4,4,4,2,0,0,0,0,2
2,0,0,0,0,2,4,4,4,4,2,0,0,0,0,2
2,0,0,0,0,2,2,2,2,2,2,0,0,0,0,2
0,0,0,0,0,13,13,13,13,13,13,0,0,0,0,0
0,0,0,0,0,12,12,12,12,12,12,0,0,0,0,0
0,0,0,0,0,11,11,11,11,11,11,0,0,0,0,0
0,0,0,0,0,2,2,2,2,2,2,0,0,0,0,0
0,0,0,0,0,2,2,2,2,2,2,0,0,0,0,0
:endlayer
layer: 9
3,3,3,3,3,3,3,3,3,3,3,3,3,3,3,3
3,3,3,3,3,3,3,3,3,3,3,3,3,3,3,3
3,3,3,3,3,3,3,3,3,3,3,3,3,3,3,3
3,3,3,3,3,3,3,3,3,3,3,3,3,3,3,3
3,3,3,3,3,3,3,3,3,3,3,3,3,3,3,3
14,3,3,3,3,14,3,3,3,3,14,3,3,3,3,14
14,6,6,6,6,14,3,3,3,3,14,6,6,6,6,14
14,0,0,0,0,14,3,3,3,3,14,0,0,0,0,14
14,0,0,0,0,14,3,3,3,3,14,0,0,0,0,14
14,0,0,0,0,14,3,3,3,3,14,0,0,0,0,14
14,0,0,0,0,14,3,3,3,3,14,0,0,0,0,14
0,0,0,0,0,14,3,3,3,3,14,0,0,0,0,0
0,0,0,0,0,14,3,3,3,3,14,0,0,0,0,0
0,0,0,0,0,14,3,3,3,3,14,0,0,0,0,0
0,0,0,0,0,14,3,3,3,3,14,0,0,0,0,0
0,0,0,0,0,14,3,3,3,3,14,0,0,0,0,0
:endlayer
layer: 10
0,0,0,0,0,0,0,0,0,0,0,0,0,0,0,0
0,0,16,0,0,0,0,0,0,0,0,0,0,16,0,0
0,0,0,0,0,0,0,0,0,0,0,0,0,0,0,0
0,0,0,0,0,0,0,0,0,0,0,0,0,0,0,0
0,0,0,0,0,0,0,0,0,0,0,0,0,0,0,0
14,0,0,0,0,14,0,0,0,0,14,0,0,0,0,14
15,0,0,0,0,15,0,0,0,0,15,0,0,0,0,15
15,0,0,0,0,15,0,0,0,0,15,0,0,0,0,15
15,0,0,0,0,15,0,0,0,0,15,0,0,0,0,15
15,0,0,0,0,15,0,0,0,0,15,0,0,0,0,15
14,0,0,0,0,14,0,0,0,0,14,0,0,0,0,14
0,0,0,0,0,0,0,0,0,0,0,0,0,0,0,0
0,0,0,0,0,0,0,0,0,0,0,0,0,0,0,0
0,0,0,0,0,0,0,0,0,0,0,0,0,0,0,0
0,0,0,0,0,0,0,0,16,0,0,0,0,0,0,0
0,0,0,0,0,0,0,0,0,0,0,0,0,0,0,0
:endlayer
layer: 11
0,0,0,0,0,0,0,0,0,0,0,0,0,0,0,0
0,0,0,0,0,0,0,0,0,0,0,0,0,0,0,0
0,0,0,0,0,0,0,0,0,0,0,0,0,0,0,0
0,0,0,0,0,0,0,0,0,0,0,0,0,0,0,0
0,0,0,0,0,0,0,0,0,0,0,0,0,0,0,0
16,0,0,0,0,16,0,0,0,0,16,0,0,0,0,16
0,0,0,0,0,0,0,0,0,0,0,0,0,0,0,0
0,0,0,0,0,0,0,0,0,0,0,0,0,0,0,0
0,0,0,0,0,0,0,0,0,0,0,0,0,0,0,0
0,0,0,0,0,0,0,0,0,0,0,0,0,0,0,0
16,0,0,0,0,16,0,0,0,0,16,0,0,0,0,16
0,0,0,0,0,0,0,0,0,0,0,0,0,0,0,0
0,0,0,0,0,0,0,0,0,0,0,0,0,0,0,0
0,0,0,0,0,0,0,0,0,0,0,0,0,0,0,0
0,0,0,0,0,0,0,0,0,0,0,0,0,0,0,0
0,0,0,0,0,0,0,0,0,0,0,0,0,0,0,0
:endlayer

#### RULES ####
rule:
plugin=vanillaBlocks
number=1
data:
JSON:{blockState:{blockName:"minecraft:log",properties:{variant:"spruce",axis:"y"}}}
:enddata
:endrule

rule:
plugin=vanillaBlocks
number=2
data:
JSON:{blockState:{blockName:"minecraft:stonebrick",properties:{variant:"stonebrick"}}}
:enddata
:endrule

rule:
plugin=vanillaBlocks
number=3
data:
JSON:{blockState:{blockName:"minecraft:cobblestone"}}
:enddata
:endrule

rule:
plugin=vanillaBlocks
number=4
data:
JSON:{blockState:{blockName:"minecraft:dirt",properties:{variant:"dirt",snowy:"false"}}}
:enddata
:endrule

rule:
plugin=vanillaBlocks
number=5
data:
JSON:{blockState:{blockName:"minecraft:wooden_slab",properties:{half:"top",variant:"spruce"}}}
:enddata
:endrule

rule:
plugin=vanillaBlocks
number=6
data:
JSON:{blockState:{blockName:"minecraft:spruce_stairs",properties:{half:"bottom",shape:"straight",facing:"north"}}}
:enddata
:endrule

rule:
plugin=vanillaBlocks
number=7
data:
JSON:{blockState:{blockName:"minecraft:torch",properties:{facing:"south"}}}
:enddata
:endrule

rule:
plugin=vanillaBlocks
number=8
data:
JSON:{blockState:{blockName:"minecraft:torch",properties:{facing:"west"}}}
:enddata
:endrule

rule:
plugin=vanillaBlocks
number=9
data:
JSON:{blockState:{blockName:"minecraft:torch",properties:{facing:"north"}}}
:enddata
:endrule

rule:
plugin=vanillaBlocks
number=10
data:
JSON:{blockState:{blockName:"minecraft:torch",properties:{facing:"east"}}}
:enddata
:endrule

rule:
plugin=vanillaBlocks
number=11
data:
JSON:{blockState:{blockName:"minecraft:stone_brick_stairs",properties:{half:"top",shape:"straight",facing:"south"}}}
:enddata
:endrule

rule:
plugin=vanillaBlocks
number=12
data:
JSON:{blockState:{blockName:"minecraft:stone_slab",properties:{half:"top",variant:"stone_brick"}}}
:enddata
:endrule

rule:
plugin=vanillaBlocks
number=13
data:
JSON:{blockState:{blockName:"minecraft:stone_brick_stairs",properties:{half:"top",shape:"straight",facing:"north"}}}
:enddata
:endrule

rule:
plugin=vanillaBlocks
number=14
data:
JSON:{blockState:{blockName:"minecraft:stone",properties:{variant:"smooth_andesite"}}}
:enddata
:endrule

rule:
plugin=vanillaBlocks
number=15
data:
JSON:{blockState:{blockName:"minecraft:spruce_fence",properties:{east:"false",south:"false",north:"false",west:"false"}}}
:enddata
:endrule

rule:
plugin=vanillaBlocks
number=16
data:
JSON:{blockState:{blockName:"minecraft:torch",properties:{facing:"up"}}}
:enddata
:endrule

#### ENTITIES ####
