# Ancient Warfare Structure Template File
# Auto-generated structure template file. created on: 12/12/2023 at: 22:28:3
# Lines beginning with # denote comments

header:
version=2.11
name=Reiksgard_Farm_Grape_Large_rustic
mods=rustic
size=26,18,29
offset=13,5,16
:endheader

#### VALIDATION ####
validation:
type=ground
structureAuthor=TheOddlySeagull
survival=false
worldGenEnabled=true
unique=false
preserveBlocks=false
preventNaturalHostileSpawns=true
selectionWeight=30
clusterValue=30
minDuplicateDistance=1000
dimensionWhiteList=true
dimensionList=0
biomeGroupList=
biomeWhiteList=true
biomeList=nt:blossom_forest_hills,nt:royal_forest,biomesoplenty:mystic_grove,biomesoplenty:origin_island,nt:blossom_forest,biomesoplenty:cherry_blossom_grove,biomesoplenty:lavender_fields,nt:royal_forest_hills
leveling=30
fill=10
border=5
blockSwap=false
territoryName=reiksgard
biomeReplacement=minecraft:
minGenerationHeight=0
maxGenerationHeight=0
:endvalidation

#### LAYERS ####
layer: 0
1,1,1,1,1,1,1,1,1,1,1,1,1,1,1,1,1,1,1,1,1,1,1,1,1,1
1,1,1,1,1,1,1,1,1,1,1,1,1,1,1,1,1,1,1,1,1,1,1,1,1,1
1,1,1,1,1,1,1,1,1,1,1,1,1,1,1,1,1,1,1,1,1,1,1,1,1,1
1,1,1,1,1,1,1,1,1,1,1,1,1,1,1,1,1,1,1,1,1,1,1,1,1,1
1,1,1,1,1,1,1,1,1,1,1,1,1,1,1,1,1,1,1,1,1,1,1,1,1,1
1,1,1,1,1,1,1,1,1,1,1,1,1,1,1,1,1,1,1,1,1,1,1,1,1,1
1,1,1,1,1,1,1,1,1,1,1,1,1,1,1,1,1,1,1,1,1,1,1,1,1,1
1,1,1,1,1,1,1,1,1,1,1,1,1,1,1,1,1,1,1,1,1,1,1,1,1,1
1,1,1,1,1,1,1,1,1,1,1,1,1,1,1,1,1,1,1,1,1,1,1,1,1,1
1,1,1,1,1,1,1,1,1,1,1,1,1,1,1,1,1,1,1,1,1,1,1,1,1,1
1,1,1,1,1,1,1,1,1,1,1,1,1,1,1,1,1,1,1,1,1,1,1,1,1,1
1,1,1,1,1,1,1,1,1,1,1,1,1,1,1,1,1,1,1,1,1,1,1,1,1,1
1,1,1,1,1,1,1,1,1,1,1,1,1,1,1,1,1,1,1,1,1,1,1,1,1,1
1,1,1,1,1,1,1,1,1,1,1,1,1,1,1,1,1,1,1,1,1,1,1,1,1,1
1,1,1,1,1,1,1,1,1,1,1,1,1,1,1,1,1,1,1,1,1,1,1,1,1,1
1,1,1,1,1,1,1,1,1,1,1,1,1,1,1,1,1,1,1,1,1,1,1,1,1,1
1,1,1,1,1,1,1,1,1,1,1,1,1,1,1,1,1,1,1,1,1,1,1,1,1,1
1,1,1,1,1,1,1,1,1,1,1,1,1,1,1,1,1,1,1,1,1,1,1,1,1,1
1,1,1,1,1,1,1,1,1,1,1,1,1,1,1,1,1,1,1,1,1,1,1,1,1,1
1,1,1,1,1,1,1,1,1,1,1,1,1,1,1,1,1,1,1,1,1,1,1,1,1,1
1,1,1,1,1,1,1,1,1,1,1,1,1,1,1,1,1,1,1,1,1,1,1,1,1,1
1,1,1,1,1,1,1,1,1,1,1,1,1,1,1,1,1,1,1,1,1,1,1,1,1,1
1,1,1,1,1,1,1,1,1,1,1,1,1,1,1,1,1,1,1,1,1,1,1,1,1,1
1,1,1,1,1,1,1,1,1,1,1,1,1,1,1,1,1,1,1,1,1,1,1,1,1,1
1,1,1,1,1,1,1,1,1,1,1,1,1,1,1,1,1,1,1,1,1,1,1,1,1,1
1,1,1,1,1,1,1,1,1,1,1,1,1,1,1,1,1,1,1,1,1,1,1,1,1,1
1,1,1,1,1,1,1,1,1,1,1,1,1,1,1,1,1,1,1,1,1,1,1,1,1,1
1,1,1,1,1,1,1,1,1,1,1,1,1,1,1,1,1,1,1,1,1,1,1,1,1,1
1,1,1,1,1,1,1,1,1,1,1,1,1,1,1,1,1,1,1,1,1,1,1,1,1,1
:endlayer
layer: 1
1,1,1,1,1,1,1,1,1,1,1,1,1,1,1,1,1,1,1,1,1,1,1,1,1,1
1,1,1,1,1,1,1,1,1,1,1,1,1,1,1,1,1,1,1,1,1,1,1,1,1,1
1,1,1,1,1,1,1,1,1,1,1,1,1,1,1,1,1,1,1,1,1,1,1,1,1,1
1,1,1,1,1,1,1,1,1,1,1,1,1,1,1,1,1,1,1,1,1,1,1,1,1,1
1,1,1,1,1,1,1,1,1,1,1,1,1,1,1,1,1,1,1,1,1,1,1,1,1,1
1,1,1,1,1,1,1,1,1,1,1,1,1,1,1,1,1,1,1,1,1,1,1,1,1,1
1,1,1,1,1,1,1,1,1,1,1,1,1,1,1,1,1,1,1,1,1,1,1,1,1,1
1,1,1,1,1,1,1,1,1,1,1,1,1,1,1,1,1,1,1,1,1,1,1,1,1,1
1,1,1,1,1,1,1,1,1,1,1,1,1,1,1,1,1,1,1,1,1,1,1,1,1,1
1,1,1,1,1,1,1,1,1,1,1,1,1,1,1,1,1,1,1,1,1,1,1,1,1,1
1,1,1,1,1,1,1,1,1,1,1,1,1,1,1,1,1,1,1,1,1,1,1,1,1,1
1,1,1,1,1,1,1,1,1,1,1,1,1,1,1,1,1,1,1,1,1,1,1,1,1,1
1,1,1,1,1,1,1,1,1,1,1,1,1,1,1,1,1,1,1,1,1,1,1,1,1,1
1,1,1,1,1,1,1,1,1,1,1,1,1,1,1,1,1,1,1,1,1,1,1,1,1,1
1,1,1,1,1,1,1,1,1,1,1,1,1,1,1,1,1,1,1,1,1,1,1,1,1,1
1,1,1,1,1,1,1,1,1,1,1,1,1,1,1,1,1,1,1,1,1,1,1,1,1,1
1,1,1,1,1,1,1,1,1,1,1,1,1,1,1,1,1,1,1,1,1,1,1,1,1,1
1,1,1,1,1,1,1,1,1,1,1,1,1,1,1,1,1,1,1,1,1,1,1,1,1,1
1,1,1,1,1,1,1,1,1,1,1,1,1,1,1,1,1,1,1,1,1,1,1,1,1,1
1,1,1,1,1,1,1,1,1,1,1,1,1,1,1,1,1,1,1,1,1,1,1,1,1,1
1,1,1,1,1,1,1,1,1,1,1,1,1,1,1,1,1,1,1,1,1,1,1,1,1,1
1,1,1,1,1,1,1,1,1,1,1,1,1,1,1,1,1,1,1,1,1,1,1,1,1,1
1,1,1,1,1,1,1,1,1,1,1,1,1,1,1,1,1,1,1,1,1,1,1,1,1,1
1,1,1,1,1,1,1,1,1,1,1,1,1,1,1,1,1,1,1,1,1,1,1,1,1,1
1,1,1,1,1,1,1,1,1,1,1,1,1,1,1,1,1,1,1,1,1,1,1,1,1,1
1,1,1,1,1,1,1,1,1,1,1,1,1,1,1,1,1,1,1,1,1,1,1,1,1,1
1,1,1,1,1,1,1,1,1,1,1,1,1,1,1,1,1,1,1,1,1,1,1,1,1,1
1,1,1,1,1,1,1,1,1,1,1,1,1,1,1,1,1,1,1,1,1,1,1,1,1,1
1,1,1,1,1,1,1,1,1,1,1,1,1,1,1,1,1,1,1,1,1,1,1,1,1,1
:endlayer
layer: 2
1,1,1,1,1,1,1,1,1,1,1,1,1,1,1,1,1,1,1,1,1,1,1,1,1,1
1,1,1,1,1,1,1,1,1,1,1,1,1,1,1,1,1,1,1,1,1,1,1,1,1,1
1,1,1,1,1,1,1,1,1,1,1,1,1,1,1,1,1,1,1,1,1,1,1,1,1,1
1,1,1,1,1,1,1,1,1,1,1,1,1,1,1,1,1,1,1,1,1,1,1,1,1,1
1,1,1,1,1,1,1,1,1,1,1,1,1,1,1,1,1,1,1,1,1,1,1,1,1,1
1,1,1,1,1,1,1,1,1,1,1,1,1,1,1,1,1,1,1,1,1,1,1,1,1,1
1,1,1,1,1,1,1,1,1,1,1,1,1,1,1,1,1,1,1,1,1,1,1,1,1,1
1,1,1,1,1,1,1,1,1,1,1,1,1,1,1,1,1,1,1,1,1,1,1,1,1,1
1,1,1,1,1,1,1,1,1,1,1,1,1,1,1,1,1,1,1,1,1,1,1,1,1,1
1,1,1,1,1,1,1,1,1,1,1,1,1,1,1,1,1,1,1,1,1,1,1,1,1,1
1,1,1,1,1,1,1,1,1,1,1,1,1,1,1,1,1,1,1,1,1,1,1,1,1,1
1,1,1,1,1,1,1,1,1,1,1,1,1,1,1,1,1,1,1,1,1,1,1,1,1,1
1,1,1,1,1,1,1,1,1,1,1,1,1,1,1,1,1,1,1,1,1,1,1,1,1,1
1,1,1,1,1,1,1,1,1,1,1,1,1,1,1,1,1,1,1,1,1,1,1,1,1,1
1,1,1,1,1,1,1,1,1,1,1,1,1,1,1,1,1,1,1,1,1,1,1,1,1,1
1,1,1,1,1,1,1,1,1,1,1,1,1,1,1,1,1,1,1,1,1,1,1,1,1,1
1,1,1,1,1,1,1,1,1,1,1,1,1,1,1,1,1,1,1,1,1,1,1,1,1,1
1,1,1,1,1,1,1,1,1,1,1,1,1,1,1,1,1,1,1,1,1,1,1,1,1,1
1,1,1,1,1,1,1,1,1,1,1,1,1,1,1,1,1,1,1,1,1,1,1,1,1,1
1,1,1,1,1,1,1,1,1,1,1,1,1,1,1,1,1,1,1,1,1,1,1,1,1,1
1,1,1,1,1,1,1,1,1,1,1,1,1,1,1,1,1,1,1,1,1,1,1,1,1,1
1,1,1,1,1,1,1,1,1,1,1,1,1,1,1,1,1,1,1,1,1,1,1,1,1,1
1,1,1,1,1,1,1,1,1,1,1,1,1,1,1,1,1,1,1,1,1,1,1,1,1,1
1,1,1,1,1,1,1,1,1,1,1,1,1,1,1,1,1,1,1,1,1,1,1,1,1,1
1,1,1,1,1,1,1,1,1,1,1,1,1,1,1,1,1,1,1,1,1,1,1,1,1,1
1,1,1,1,1,1,1,1,1,1,1,1,1,1,1,1,1,1,1,1,1,1,1,1,1,1
1,1,1,1,1,1,1,1,1,1,1,1,1,1,1,1,1,1,1,1,1,1,1,1,1,1
1,1,1,1,1,1,1,1,1,1,1,1,1,1,1,1,1,1,1,1,1,1,1,1,1,1
1,1,1,1,1,1,1,1,1,1,1,1,1,1,1,1,1,1,1,1,1,1,1,1,1,1
:endlayer
layer: 3
2,2,2,2,2,2,2,2,2,2,2,2,2,2,2,2,2,2,2,2,2,2,2,2,2,2
2,2,2,2,2,2,2,2,2,2,2,2,2,2,2,2,2,2,2,2,2,2,2,2,2,2
2,2,4,5,5,4,5,5,4,2,2,2,2,2,2,2,2,2,2,2,2,2,2,2,2,2
2,2,5,5,5,5,5,5,5,2,2,2,2,2,2,2,4,6,6,4,6,6,4,2,2,2
2,2,5,5,5,5,5,5,5,2,2,2,2,2,2,2,6,2,2,2,2,2,6,2,2,2
2,2,4,5,5,5,5,5,4,5,5,4,2,2,2,2,6,2,2,2,2,2,6,2,2,2
2,2,5,5,5,5,5,5,5,5,5,5,2,2,2,2,4,2,2,2,2,2,4,2,2,2
2,2,5,5,5,5,5,5,5,5,5,5,2,2,2,2,6,2,2,2,2,2,6,2,2,2
2,2,4,5,5,5,5,5,5,5,5,4,2,2,2,2,6,2,2,2,2,2,6,2,2,2
2,2,5,5,5,5,5,5,5,5,5,5,2,2,2,2,4,2,2,2,2,2,4,2,2,2
2,2,5,5,5,5,5,5,5,5,5,5,2,2,2,2,6,2,2,2,2,2,6,2,2,2
2,2,4,5,5,4,5,5,4,5,5,4,2,2,2,2,6,2,2,2,2,2,6,2,2,2
2,2,2,2,2,2,2,2,2,2,2,2,2,2,2,2,4,6,6,6,6,6,4,2,2,2
2,2,2,2,2,2,2,2,2,2,2,2,2,2,2,2,2,2,2,2,2,2,2,2,2,2
2,2,2,2,2,2,2,2,2,2,2,2,2,2,2,2,2,2,2,2,2,2,2,2,2,2
2,2,2,2,2,2,2,2,2,2,2,2,2,2,2,2,2,2,2,2,2,2,2,2,2,2
2,2,2,2,2,2,2,2,2,2,2,2,2,2,2,2,2,2,2,2,2,2,2,2,2,2
2,2,2,2,2,2,2,2,2,2,2,2,2,2,2,2,2,2,2,2,2,2,2,2,2,2
2,2,2,2,2,2,2,2,2,2,2,2,2,2,2,2,2,2,2,2,2,2,2,2,2,2
2,2,2,2,2,2,2,2,2,2,2,2,2,2,2,2,2,2,2,2,2,2,2,2,2,2
2,2,2,2,2,2,2,2,2,2,2,2,2,2,2,2,2,2,2,2,2,2,2,2,2,2
2,2,2,2,2,2,2,2,2,2,2,2,2,2,2,2,2,2,2,2,2,2,2,2,2,2
2,2,2,2,2,2,2,2,2,2,2,2,2,2,2,2,2,2,2,2,2,2,2,2,2,2
2,2,3,2,2,2,2,2,2,2,2,2,2,2,2,2,2,2,2,2,2,2,2,2,2,2
2,2,2,2,2,2,2,2,2,2,2,2,2,2,2,2,2,2,2,2,2,2,2,2,2,2
2,2,2,2,2,2,2,2,2,2,2,2,2,2,2,2,2,2,2,2,2,2,2,2,2,2
2,2,2,2,2,2,2,2,2,2,2,2,2,2,2,2,2,2,2,2,2,2,2,2,2,2
2,2,2,2,2,2,2,2,2,2,2,2,2,2,2,2,2,2,2,2,2,2,2,2,2,2
2,2,2,2,2,2,2,2,2,2,2,2,2,2,2,2,2,2,2,2,2,2,2,2,2,2
:endlayer
layer: 4
3,3,3,3,3,3,7,7,3,3,3,3,3,7,7,3,3,3,3,3,3,3,3,3,3,3
3,3,3,3,3,3,7,7,3,3,3,3,3,7,7,3,3,3,3,3,3,3,3,3,3,3
3,3,4,5,5,4,5,5,4,3,3,3,3,7,7,3,3,3,3,3,3,3,3,3,3,3
3,3,5,5,5,5,5,5,5,3,3,3,3,7,7,3,4,6,6,4,6,6,4,3,3,3
3,3,5,5,5,5,5,5,5,3,3,3,3,7,7,3,6,11,3,3,11,11,6,3,3,3
3,3,4,5,5,5,5,5,4,5,5,4,3,7,7,3,6,10,11,11,3,3,6,3,3,3
3,3,5,5,5,5,5,5,5,5,5,5,3,7,7,3,4,11,10,10,11,11,4,3,3,3
3,3,5,5,5,5,5,5,5,5,5,5,3,7,7,3,6,10,10,3,10,11,6,3,3,3
3,3,4,5,5,5,5,5,5,5,5,4,3,7,7,3,6,3,3,10,11,11,6,3,3,3
3,3,5,5,5,5,5,5,5,5,5,5,3,7,7,3,4,3,10,10,10,11,4,3,3,3
3,3,5,5,5,5,5,5,5,5,5,5,3,7,7,3,6,10,11,3,11,11,6,3,3,3
3,3,4,5,5,4,5,5,4,5,5,4,3,7,7,3,6,3,11,3,3,3,6,3,3,3
3,3,3,3,3,3,7,7,3,3,3,3,3,7,7,3,4,6,5,5,5,6,4,3,3,3
3,3,3,3,3,3,7,7,3,3,3,3,3,7,7,3,3,3,7,7,7,3,3,3,3,3
3,3,3,3,3,3,7,7,3,3,3,3,3,7,7,3,3,3,7,7,7,3,3,3,3,3
7,7,7,7,7,7,7,7,7,7,7,7,7,7,7,7,7,7,7,7,7,7,7,7,7,7
7,7,7,7,7,7,7,7,7,7,7,7,7,7,7,7,7,7,7,7,7,7,7,7,7,7
7,7,7,7,7,7,7,7,7,7,7,7,7,7,7,7,7,7,7,7,7,7,7,7,7,7
3,3,3,3,3,3,3,3,3,3,3,3,3,3,3,3,3,3,3,3,3,3,3,3,3,3
3,3,3,3,3,3,3,3,3,3,3,3,3,3,3,3,3,3,3,3,3,3,3,3,3,3
3,3,3,3,3,3,3,3,3,3,3,3,3,3,3,3,3,3,3,3,3,3,3,3,3,3
3,3,8,3,3,8,3,3,8,3,3,8,3,3,8,3,3,8,3,3,8,3,3,8,3,3
3,3,3,3,3,3,3,3,3,3,3,3,3,3,3,3,3,3,3,3,3,3,3,3,3,3
3,3,9,3,3,9,3,3,9,3,3,9,3,3,9,3,3,9,3,3,9,3,3,9,3,3
3,3,3,3,3,3,3,3,3,3,3,3,3,3,3,3,3,3,3,3,3,3,3,3,3,3
3,3,8,3,3,8,3,3,8,3,3,8,3,3,8,3,3,8,3,3,8,3,3,8,3,3
3,3,3,3,3,3,3,3,3,3,3,3,3,3,3,3,3,3,3,3,3,3,3,3,3,3
3,3,3,3,3,3,3,3,3,3,3,3,3,3,3,3,3,3,3,3,3,3,3,3,3,3
3,3,3,3,3,3,3,3,3,3,3,3,3,3,3,3,3,3,3,3,3,3,3,3,3,3
:endlayer
layer: 5
12,12,12,0,0,12,0,0,12,12,12,0,0,0,0,0,0,0,12,12,0,0,0,0,0,0
12,12,12,15,15,29,0,0,0,13,12,12,12,0,0,0,12,12,19,12,12,0,0,13,12,12
12,12,4,5,5,4,32,32,4,0,12,12,12,0,0,0,12,0,0,12,0,12,0,12,19,12
12,0,5,25,0,0,0,0,5,12,12,12,12,0,0,0,4,6,6,4,6,6,4,13,12,19
0,0,5,24,0,28,0,0,5,40,0,12,0,0,0,0,6,48,50,0,53,57,6,12,12,12
0,0,4,23,0,27,27,0,4,5,5,4,12,0,0,12,6,0,0,0,0,56,6,0,12,0
0,15,5,22,0,27,27,0,38,38,38,5,0,44,0,12,4,0,0,0,0,0,4,0,0,0
12,15,5,0,0,27,27,35,37,37,37,5,0,0,0,15,6,0,0,0,0,0,6,12,12,12
12,12,4,21,0,0,31,0,37,37,37,4,12,0,0,15,6,0,0,0,0,0,6,12,12,0
12,12,5,20,0,0,0,0,36,39,42,5,12,0,0,0,4,47,0,0,0,0,4,12,12,12
12,0,5,0,0,0,0,0,0,0,41,5,12,0,0,0,6,0,0,0,0,55,6,12,12,12
0,12,4,5,5,4,30,34,4,5,5,4,12,0,0,0,6,46,0,0,0,54,6,12,12,0
0,13,12,15,15,0,0,0,0,15,15,0,12,0,0,12,4,6,49,51,52,6,4,0,0,0
0,12,12,12,0,0,0,0,19,12,12,12,13,0,0,0,13,12,0,0,0,12,13,0,12,0
12,12,12,12,12,26,0,0,0,13,12,13,0,0,0,45,13,12,0,0,0,0,13,12,12,12
0,0,0,0,0,0,0,0,0,0,0,0,0,0,0,0,0,0,0,0,0,0,0,0,0,0
0,14,0,0,0,0,0,33,0,0,0,0,0,43,0,0,0,0,0,0,0,0,0,0,58,0
0,0,0,0,0,0,0,0,0,0,0,0,0,0,0,0,0,0,0,0,0,0,0,0,0,0
12,12,12,12,0,12,0,12,12,12,0,0,0,0,12,12,12,13,13,0,0,12,0,12,13,12
12,13,16,0,0,16,12,12,16,0,0,16,0,0,16,12,12,16,0,0,16,0,13,16,12,12
0,0,12,0,0,0,0,12,12,0,0,0,0,0,12,0,12,12,12,0,0,0,12,12,12,12
0,12,17,12,0,17,0,0,17,12,0,17,0,0,17,0,0,17,19,0,17,0,12,17,13,12
0,12,0,0,0,0,0,12,19,12,12,0,0,0,0,0,0,0,0,0,0,0,0,0,0,12
12,12,18,0,0,18,0,0,18,12,19,18,0,0,18,0,0,18,0,0,18,0,0,18,0,0
12,12,0,0,0,0,0,0,12,0,12,12,0,0,0,0,0,0,0,0,0,0,0,0,0,0
13,0,17,0,0,17,0,12,17,12,12,17,0,0,17,0,12,17,0,0,17,0,0,17,0,13
12,0,12,19,12,0,0,12,12,0,12,0,0,0,12,0,12,0,0,0,0,12,0,0,12,0
12,12,16,13,12,16,12,12,16,12,0,16,12,12,16,12,19,16,0,0,16,0,12,16,12,0
0,12,12,12,0,0,0,12,12,12,0,0,0,0,0,12,12,0,0,0,12,12,12,12,0,0
:endlayer
layer: 6
0,0,0,0,0,0,0,0,0,0,0,0,0,0,0,0,0,0,0,0,0,0,0,0,0,0
0,0,0,0,0,67,0,0,0,0,0,0,0,0,0,0,0,0,0,0,0,0,0,0,0,0
0,0,4,64,64,4,69,68,4,0,0,0,0,0,0,0,0,0,0,0,0,0,0,0,0,0
0,0,5,65,0,0,0,0,5,0,0,0,0,0,0,0,4,6,6,4,6,6,4,0,0,0
0,0,5,65,0,0,0,0,5,0,0,0,0,0,0,0,6,0,0,0,0,0,6,0,0,0
0,0,4,65,0,0,0,0,4,64,64,4,0,0,0,0,6,0,0,0,0,0,6,0,0,0
0,0,64,0,0,0,0,0,0,0,0,64,0,0,0,0,4,77,0,0,0,83,4,0,0,0
0,0,64,21,0,0,0,0,0,0,74,64,0,0,0,0,6,78,0,0,0,0,6,0,0,0
0,0,4,20,0,0,0,0,0,0,0,4,0,0,0,0,6,78,0,0,0,0,6,0,0,0
0,0,5,0,0,0,0,0,71,72,73,64,0,0,0,0,4,77,0,0,0,83,4,0,0,0
0,0,5,0,0,0,0,0,0,0,0,64,0,0,0,0,6,0,0,0,0,82,6,0,0,0
0,0,4,64,64,4,68,69,4,64,64,4,0,0,0,0,6,76,0,0,0,0,6,0,0,0
0,0,0,0,0,0,0,0,70,0,0,0,0,0,0,0,4,6,79,80,81,6,4,0,0,0
0,0,0,0,0,0,0,0,0,0,0,0,0,0,0,0,0,0,0,0,0,0,0,0,0,0
0,0,0,0,0,66,0,0,0,0,0,0,0,0,0,75,0,0,0,0,0,0,0,0,0,0
0,0,0,0,0,0,0,0,0,0,0,0,0,0,0,0,0,0,0,0,0,0,0,0,0,0
0,0,0,0,0,0,0,0,0,0,0,0,0,0,0,0,0,0,0,0,0,0,0,0,0,0
0,0,0,0,0,0,0,0,0,0,0,0,0,0,0,0,0,0,0,0,0,0,0,0,0,0
0,0,0,0,0,0,0,0,0,0,0,0,0,0,0,0,0,0,0,0,0,0,0,0,0,0
0,0,63,0,0,63,0,0,63,0,0,63,0,0,63,0,0,63,0,0,63,0,0,63,0,0
0,0,60,0,0,60,0,0,60,0,0,60,0,0,60,0,0,60,0,0,60,0,0,60,0,0
0,0,61,0,0,61,0,0,61,0,0,61,0,0,61,0,0,61,0,0,61,0,0,61,0,0
0,0,60,0,0,60,0,0,60,0,0,60,0,0,60,0,0,60,0,0,60,0,0,60,0,0
0,0,62,0,0,62,0,0,62,0,0,62,0,0,62,0,0,62,0,0,62,0,0,62,0,0
0,0,60,0,0,60,0,0,60,0,0,60,0,0,60,0,0,60,0,0,60,0,0,60,0,0
0,0,61,0,0,61,0,0,61,0,0,61,0,0,61,0,0,61,0,0,61,0,0,61,0,0
0,0,60,0,0,60,0,0,60,0,0,60,0,0,60,0,0,60,0,0,60,0,0,60,0,0
0,0,59,0,0,59,0,0,59,0,0,59,0,0,59,0,0,59,0,0,59,0,0,59,0,0
0,0,0,0,0,0,0,0,0,0,0,0,0,0,0,0,0,0,0,0,0,0,0,0,0,0
:endlayer
layer: 7
0,0,0,0,0,0,0,0,0,0,0,0,0,0,0,0,0,0,0,0,0,0,0,0,0,0
0,0,0,0,0,0,0,0,0,0,0,0,0,0,0,0,0,0,0,0,0,0,0,0,0,0
0,0,4,64,64,4,5,5,4,0,0,0,0,0,0,0,0,0,0,0,0,0,0,0,0,0
0,0,5,0,0,84,0,0,5,0,0,0,0,0,0,16,4,6,6,4,6,6,4,16,0,0
0,0,5,0,0,0,0,0,5,0,0,0,0,0,0,0,6,0,0,93,78,78,6,0,0,0
0,0,4,85,0,0,0,83,4,64,64,4,0,0,0,0,6,0,0,0,0,78,6,0,0,0
0,0,64,21,0,0,0,0,84,0,0,64,0,0,0,16,4,90,0,0,0,95,4,16,0,0
0,0,64,20,0,0,0,0,0,0,0,64,0,0,0,0,16,89,0,0,0,0,16,0,0,0
0,0,4,85,0,0,0,0,0,0,83,4,0,0,0,0,16,88,0,0,0,0,16,0,0,0
0,0,5,0,0,0,0,0,0,0,0,64,0,0,0,16,4,0,0,0,0,0,4,16,0,0
0,0,5,0,0,86,0,0,86,0,0,64,0,0,0,0,6,0,0,0,0,0,6,0,0,0
0,0,4,64,64,4,5,5,4,64,64,4,0,0,0,0,6,0,0,0,0,0,6,0,0,0
0,0,84,0,0,84,87,0,84,0,0,84,0,0,0,16,4,6,91,92,94,6,4,16,0,0
0,0,0,0,0,0,0,0,0,0,0,0,0,0,0,0,0,0,0,0,0,0,0,0,0,0
0,0,0,0,0,0,0,0,0,0,0,0,0,0,0,0,0,0,0,0,0,0,0,0,0,0
0,0,0,0,0,0,0,0,0,0,0,0,0,0,0,0,0,0,0,0,0,0,0,0,0,0
0,0,0,0,0,0,0,0,0,0,0,0,0,0,0,0,0,0,0,0,0,0,0,0,0,0
0,0,0,0,0,0,0,0,0,0,0,0,0,0,0,0,0,0,0,0,0,0,0,0,0,0
0,0,0,0,0,0,0,0,0,0,0,0,0,0,0,0,0,0,0,0,0,0,0,0,0,0
0,0,0,0,0,0,0,0,0,0,0,0,0,0,0,0,0,0,0,0,0,0,0,0,0,0
0,0,0,0,0,0,0,0,0,0,0,0,0,0,0,0,0,0,0,0,0,0,0,0,0,0
0,0,0,0,0,0,0,0,0,0,0,0,0,0,0,0,0,0,0,0,0,0,0,0,0,0
0,0,0,0,0,0,0,0,0,0,0,0,0,0,0,0,0,0,0,0,0,0,0,0,0,0
0,0,0,0,0,0,0,0,0,0,0,0,0,0,0,0,0,0,0,0,0,0,0,0,0,0
0,0,0,0,0,0,0,0,0,0,0,0,0,0,0,0,0,0,0,0,0,0,0,0,0,0
0,0,0,0,0,0,0,0,0,0,0,0,0,0,0,0,0,0,0,0,0,0,0,0,0,0
0,0,0,0,0,0,0,0,0,0,0,0,0,0,0,0,0,0,0,0,0,0,0,0,0,0
0,0,0,0,0,0,0,0,0,0,0,0,0,0,0,0,0,0,0,0,0,0,0,0,0,0
0,0,0,0,0,0,0,0,0,0,0,0,0,0,0,0,0,0,0,0,0,0,0,0,0,0
:endlayer
layer: 8
0,0,0,0,0,0,0,0,0,0,0,0,0,0,0,0,0,0,0,0,0,0,0,0,0,0
0,0,0,0,0,0,0,0,0,0,0,0,0,0,0,0,0,0,0,0,0,0,0,0,0,0
0,0,4,97,97,97,97,97,4,0,0,0,0,0,0,101,77,0,0,86,0,0,95,104,0,0
0,0,96,98,98,98,98,98,96,0,0,0,0,0,0,101,4,97,97,97,97,97,4,104,0,0
0,0,96,6,6,6,6,6,96,63,63,63,63,0,0,101,96,0,0,102,0,0,96,104,0,0
0,0,96,21,98,98,98,98,96,97,97,4,93,0,0,101,96,0,0,0,0,103,96,104,0,0
0,0,96,20,6,6,6,6,96,0,0,96,0,0,0,101,96,85,0,0,0,0,96,104,0,0
0,0,96,0,99,98,98,98,96,0,0,96,0,0,0,101,96,0,0,0,0,0,96,104,0,0
0,0,96,0,99,6,6,6,96,0,0,96,85,0,0,101,96,0,0,0,0,0,96,104,0,0
0,0,96,0,99,98,98,98,96,0,0,96,0,0,0,101,96,85,0,0,0,0,96,104,0,0
0,0,96,0,99,6,6,6,96,0,0,96,0,0,0,101,96,78,78,78,78,78,96,104,0,0
0,0,4,97,97,97,97,97,4,97,97,4,100,0,0,101,96,100,78,100,78,100,96,104,0,0
0,0,0,0,0,0,0,0,59,59,59,59,59,0,0,101,4,97,97,97,97,97,4,104,0,0
0,0,0,0,0,0,0,0,0,0,0,0,0,0,0,101,77,0,0,84,0,0,95,104,0,0
0,0,0,0,0,0,0,0,0,0,0,0,0,0,0,0,0,0,0,0,0,0,0,0,0,0
0,0,0,0,0,0,0,0,0,0,0,0,0,0,0,0,0,0,0,0,0,0,0,0,0,0
0,0,0,0,0,0,0,0,0,0,0,0,0,0,0,0,0,0,0,0,0,0,0,0,0,0
0,0,0,0,0,0,0,0,0,0,0,0,0,0,0,0,0,0,0,0,0,0,0,0,0,0
0,0,0,0,0,0,0,0,0,0,0,0,0,0,0,0,0,0,0,0,0,0,0,0,0,0
0,0,0,0,0,0,0,0,0,0,0,0,0,0,0,0,0,0,0,0,0,0,0,0,0,0
0,0,0,0,0,0,0,0,0,0,0,0,0,0,0,0,0,0,0,0,0,0,0,0,0,0
0,0,0,0,0,0,0,0,0,0,0,0,0,0,0,0,0,0,0,0,0,0,0,0,0,0
0,0,0,0,0,0,0,0,0,0,0,0,0,0,0,0,0,0,0,0,0,0,0,0,0,0
0,0,0,0,0,0,0,0,0,0,0,0,0,0,0,0,0,0,0,0,0,0,0,0,0,0
0,0,0,0,0,0,0,0,0,0,0,0,0,0,0,0,0,0,0,0,0,0,0,0,0,0
0,0,0,0,0,0,0,0,0,0,0,0,0,0,0,0,0,0,0,0,0,0,0,0,0,0
0,0,0,0,0,0,0,0,0,0,0,0,0,0,0,0,0,0,0,0,0,0,0,0,0,0
0,0,0,0,0,0,0,0,0,0,0,0,0,0,0,0,0,0,0,0,0,0,0,0,0,0
0,0,0,0,0,0,0,0,0,0,0,0,0,0,0,0,0,0,0,0,0,0,0,0,0,0
:endlayer
layer: 9
0,0,0,0,0,0,0,0,0,0,0,0,0,0,0,0,0,0,0,0,0,0,0,0,0,0
0,0,0,0,0,0,0,0,0,0,0,0,0,0,0,0,0,0,0,0,0,0,0,0,0,0
0,0,4,105,105,4,105,105,4,0,0,0,0,0,0,0,115,0,0,0,0,0,115,0,0,0
0,0,105,106,37,106,0,114,105,0,0,0,0,0,0,0,115,4,6,6,6,4,115,0,0,0
0,0,105,106,37,106,0,113,105,0,0,0,0,0,0,0,115,0,0,0,0,0,115,0,0,0
0,0,4,0,0,0,0,0,4,115,115,115,115,0,0,0,115,0,0,0,0,0,115,0,0,0
0,0,105,0,0,0,0,112,105,0,0,4,0,0,0,0,115,4,0,0,0,4,115,0,0,0
0,0,105,0,107,109,0,0,105,0,0,105,0,0,0,0,115,0,0,0,0,0,115,0,0,0
0,0,4,0,107,0,0,106,4,0,0,105,0,0,0,0,115,0,0,0,0,0,115,0,0,0
0,0,105,0,107,0,110,111,105,0,0,105,0,0,0,0,115,4,0,0,0,4,115,0,0,0
0,0,105,0,107,108,110,111,105,0,0,4,0,0,0,0,115,0,0,0,0,119,115,0,0,0
0,0,4,105,105,4,105,105,4,115,115,115,115,0,0,0,115,0,116,0,117,118,115,0,0,0
0,0,0,0,0,0,0,0,0,0,0,0,0,0,0,0,115,4,6,0,6,4,115,0,0,0
0,0,0,0,0,0,0,0,0,0,0,0,0,0,0,0,115,0,0,0,0,0,115,0,0,0
0,0,0,0,0,0,0,0,0,0,0,0,0,0,0,0,0,0,0,0,0,0,0,0,0,0
0,0,0,0,0,0,0,0,0,0,0,0,0,0,0,0,0,0,0,0,0,0,0,0,0,0
0,0,0,0,0,0,0,0,0,0,0,0,0,0,0,0,0,0,0,0,0,0,0,0,0,0
0,0,0,0,0,0,0,0,0,0,0,0,0,0,0,0,0,0,0,0,0,0,0,0,0,0
0,0,0,0,0,0,0,0,0,0,0,0,0,0,0,0,0,0,0,0,0,0,0,0,0,0
0,0,0,0,0,0,0,0,0,0,0,0,0,0,0,0,0,0,0,0,0,0,0,0,0,0
0,0,0,0,0,0,0,0,0,0,0,0,0,0,0,0,0,0,0,0,0,0,0,0,0,0
0,0,0,0,0,0,0,0,0,0,0,0,0,0,0,0,0,0,0,0,0,0,0,0,0,0
0,0,0,0,0,0,0,0,0,0,0,0,0,0,0,0,0,0,0,0,0,0,0,0,0,0
0,0,0,0,0,0,0,0,0,0,0,0,0,0,0,0,0,0,0,0,0,0,0,0,0,0
0,0,0,0,0,0,0,0,0,0,0,0,0,0,0,0,0,0,0,0,0,0,0,0,0,0
0,0,0,0,0,0,0,0,0,0,0,0,0,0,0,0,0,0,0,0,0,0,0,0,0,0
0,0,0,0,0,0,0,0,0,0,0,0,0,0,0,0,0,0,0,0,0,0,0,0,0,0
0,0,0,0,0,0,0,0,0,0,0,0,0,0,0,0,0,0,0,0,0,0,0,0,0,0
0,0,0,0,0,0,0,0,0,0,0,0,0,0,0,0,0,0,0,0,0,0,0,0,0,0
:endlayer
layer: 10
0,0,0,0,0,0,0,0,0,0,0,0,0,0,0,0,0,0,0,0,0,0,0,0,0,0
0,0,0,0,0,0,0,0,0,0,0,0,0,0,0,0,0,0,0,0,0,0,0,0,0,0
0,0,4,64,64,4,64,64,4,0,0,0,0,0,0,0,101,77,0,0,0,95,104,0,0,0
0,0,64,0,120,0,0,0,64,0,0,0,0,0,0,0,101,4,6,6,6,4,104,0,0,0
0,0,64,0,0,0,0,0,64,0,0,0,0,0,0,0,101,77,0,0,0,95,104,0,0,0
0,0,4,0,0,0,0,0,4,63,63,63,63,0,0,0,101,77,0,0,0,95,104,0,0,0
0,0,64,0,0,0,0,121,105,93,93,4,93,0,0,0,101,4,0,0,0,4,104,0,0,0
0,0,64,0,0,0,0,0,105,0,0,105,0,0,0,0,101,77,0,0,0,95,104,0,0,0
0,0,4,0,0,0,0,0,4,0,0,105,0,0,0,0,101,77,0,0,0,95,104,0,0,0
0,0,64,0,0,0,0,0,105,0,0,105,0,0,0,0,101,4,0,0,0,4,104,0,0,0
0,0,64,0,0,0,0,0,105,100,100,4,100,0,0,0,101,77,0,0,0,95,104,0,0,0
0,0,4,64,64,4,64,64,4,59,59,59,59,0,0,0,101,77,0,0,0,95,104,0,0,0
0,0,0,0,0,0,0,0,0,0,0,0,0,0,0,0,101,4,6,0,6,4,104,0,0,0
0,0,0,0,0,0,0,0,0,0,0,0,0,0,0,0,101,77,0,0,0,95,104,0,0,0
0,0,0,0,0,0,0,0,0,0,0,0,0,0,0,0,0,0,0,0,0,0,0,0,0,0
0,0,0,0,0,0,0,0,0,0,0,0,0,0,0,0,0,0,0,0,0,0,0,0,0,0
0,0,0,0,0,0,0,0,0,0,0,0,0,0,0,0,0,0,0,0,0,0,0,0,0,0
0,0,0,0,0,0,0,0,0,0,0,0,0,0,0,0,0,0,0,0,0,0,0,0,0,0
0,0,0,0,0,0,0,0,0,0,0,0,0,0,0,0,0,0,0,0,0,0,0,0,0,0
0,0,0,0,0,0,0,0,0,0,0,0,0,0,0,0,0,0,0,0,0,0,0,0,0,0
0,0,0,0,0,0,0,0,0,0,0,0,0,0,0,0,0,0,0,0,0,0,0,0,0,0
0,0,0,0,0,0,0,0,0,0,0,0,0,0,0,0,0,0,0,0,0,0,0,0,0,0
0,0,0,0,0,0,0,0,0,0,0,0,0,0,0,0,0,0,0,0,0,0,0,0,0,0
0,0,0,0,0,0,0,0,0,0,0,0,0,0,0,0,0,0,0,0,0,0,0,0,0,0
0,0,0,0,0,0,0,0,0,0,0,0,0,0,0,0,0,0,0,0,0,0,0,0,0,0
0,0,0,0,0,0,0,0,0,0,0,0,0,0,0,0,0,0,0,0,0,0,0,0,0,0
0,0,0,0,0,0,0,0,0,0,0,0,0,0,0,0,0,0,0,0,0,0,0,0,0,0
0,0,0,0,0,0,0,0,0,0,0,0,0,0,0,0,0,0,0,0,0,0,0,0,0,0
0,0,0,0,0,0,0,0,0,0,0,0,0,0,0,0,0,0,0,0,0,0,0,0,0,0
:endlayer
layer: 11
0,0,0,0,0,0,0,0,0,0,0,0,0,0,0,0,0,0,0,0,0,0,0,0,0,0
0,0,0,0,0,0,0,0,0,0,0,0,0,0,0,0,0,0,0,0,0,0,0,0,0,0
0,0,4,64,64,4,64,64,4,0,0,0,0,0,0,0,0,101,77,0,95,104,0,0,0,0
0,0,64,0,0,84,0,0,64,0,0,0,0,0,0,0,0,101,4,6,4,104,0,0,0,0
0,0,64,0,0,0,0,0,64,0,0,0,0,0,0,0,0,101,77,0,95,104,0,0,0,0
0,0,4,85,0,0,0,83,4,0,0,0,0,0,0,0,0,101,77,0,95,104,0,0,0,0
0,0,64,0,0,0,0,0,105,63,63,63,63,0,0,0,0,101,4,0,4,104,0,0,0,0
0,0,64,0,0,0,0,0,105,93,93,4,93,0,0,0,0,101,77,0,95,104,0,0,0,0
0,0,4,85,0,0,0,83,4,0,0,105,0,0,0,0,0,101,77,0,95,104,0,0,0,0
0,0,64,0,0,0,0,0,105,100,100,4,100,0,0,0,0,101,4,0,4,104,0,0,0,0
0,0,64,0,0,86,0,0,105,59,59,59,59,0,0,0,0,101,77,0,95,104,0,0,0,0
0,0,4,64,64,4,64,64,4,0,0,0,0,0,0,0,0,101,77,86,95,104,0,0,0,0
0,0,0,0,0,0,0,0,0,0,0,0,0,0,0,0,0,101,4,6,4,104,0,0,0,0
0,0,0,0,0,0,0,0,0,0,0,0,0,0,0,0,0,101,77,16,95,104,0,0,0,0
0,0,0,0,0,0,0,0,0,0,0,0,0,0,0,0,0,0,0,16,0,0,0,0,0,0
0,0,0,0,0,0,0,0,0,0,0,0,0,0,0,0,0,0,0,0,0,0,0,0,0,0
0,0,0,0,0,0,0,0,0,0,0,0,0,0,0,0,0,0,0,0,0,0,0,0,0,0
0,0,0,0,0,0,0,0,0,0,0,0,0,0,0,0,0,0,0,0,0,0,0,0,0,0
0,0,0,0,0,0,0,0,0,0,0,0,0,0,0,0,0,0,0,0,0,0,0,0,0,0
0,0,0,0,0,0,0,0,0,0,0,0,0,0,0,0,0,0,0,0,0,0,0,0,0,0
0,0,0,0,0,0,0,0,0,0,0,0,0,0,0,0,0,0,0,0,0,0,0,0,0,0
0,0,0,0,0,0,0,0,0,0,0,0,0,0,0,0,0,0,0,0,0,0,0,0,0,0
0,0,0,0,0,0,0,0,0,0,0,0,0,0,0,0,0,0,0,0,0,0,0,0,0,0
0,0,0,0,0,0,0,0,0,0,0,0,0,0,0,0,0,0,0,0,0,0,0,0,0,0
0,0,0,0,0,0,0,0,0,0,0,0,0,0,0,0,0,0,0,0,0,0,0,0,0,0
0,0,0,0,0,0,0,0,0,0,0,0,0,0,0,0,0,0,0,0,0,0,0,0,0,0
0,0,0,0,0,0,0,0,0,0,0,0,0,0,0,0,0,0,0,0,0,0,0,0,0,0
0,0,0,0,0,0,0,0,0,0,0,0,0,0,0,0,0,0,0,0,0,0,0,0,0,0
0,0,0,0,0,0,0,0,0,0,0,0,0,0,0,0,0,0,0,0,0,0,0,0,0,0
:endlayer
layer: 12
0,0,0,0,0,0,0,0,0,0,0,0,0,0,0,0,0,0,0,0,0,0,0,0,0,0
0,101,77,0,0,0,0,0,95,104,0,0,0,0,0,0,0,0,0,0,0,0,0,0,0,0
0,101,4,97,97,97,97,97,4,104,0,0,0,0,0,0,0,0,101,100,104,0,0,0,0,0
0,101,96,0,0,93,0,0,96,104,0,0,0,0,0,0,0,0,101,4,104,0,0,0,0,0
0,101,96,0,0,0,0,0,96,104,0,0,0,0,0,0,0,0,101,93,104,0,0,0,0,0
0,101,96,0,0,0,0,0,96,104,0,0,0,0,0,0,0,0,101,100,104,0,0,0,0,0
0,101,96,0,0,0,0,0,96,104,0,0,0,0,0,0,0,0,101,4,104,0,0,0,0,0
0,101,96,0,0,0,0,0,96,63,63,63,63,0,0,0,0,0,101,93,104,0,0,0,0,0
0,101,96,0,0,0,0,0,96,77,95,4,77,0,0,0,0,0,101,100,104,0,0,0,0,0
0,101,96,0,0,0,0,0,96,59,59,59,59,0,0,0,0,0,101,4,104,0,0,0,0,0
0,101,96,0,0,0,0,0,96,104,0,0,0,0,0,0,0,0,101,93,104,0,0,0,0,0
0,101,4,97,97,97,97,97,4,104,0,0,0,0,0,0,0,0,101,100,104,0,0,0,0,0
0,101,77,0,0,0,0,0,95,104,0,0,0,0,0,0,0,0,101,4,104,0,0,0,0,0
0,0,0,0,0,0,0,0,0,0,0,0,0,0,0,0,0,0,101,93,104,0,0,0,0,0
0,0,0,0,0,0,0,0,0,0,0,0,0,0,0,0,0,0,0,0,0,0,0,0,0,0
0,0,0,0,0,0,0,0,0,0,0,0,0,0,0,0,0,0,0,0,0,0,0,0,0,0
0,0,0,0,0,0,0,0,0,0,0,0,0,0,0,0,0,0,0,0,0,0,0,0,0,0
0,0,0,0,0,0,0,0,0,0,0,0,0,0,0,0,0,0,0,0,0,0,0,0,0,0
0,0,0,0,0,0,0,0,0,0,0,0,0,0,0,0,0,0,0,0,0,0,0,0,0,0
0,0,0,0,0,0,0,0,0,0,0,0,0,0,0,0,0,0,0,0,0,0,0,0,0,0
0,0,0,0,0,0,0,0,0,0,0,0,0,0,0,0,0,0,0,0,0,0,0,0,0,0
0,0,0,0,0,0,0,0,0,0,0,0,0,0,0,0,0,0,0,0,0,0,0,0,0,0
0,0,0,0,0,0,0,0,0,0,0,0,0,0,0,0,0,0,0,0,0,0,0,0,0,0
0,0,0,0,0,0,0,0,0,0,0,0,0,0,0,0,0,0,0,0,0,0,0,0,0,0
0,0,0,0,0,0,0,0,0,0,0,0,0,0,0,0,0,0,0,0,0,0,0,0,0,0
0,0,0,0,0,0,0,0,0,0,0,0,0,0,0,0,0,0,0,0,0,0,0,0,0,0
0,0,0,0,0,0,0,0,0,0,0,0,0,0,0,0,0,0,0,0,0,0,0,0,0,0
0,0,0,0,0,0,0,0,0,0,0,0,0,0,0,0,0,0,0,0,0,0,0,0,0,0
0,0,0,0,0,0,0,0,0,0,0,0,0,0,0,0,0,0,0,0,0,0,0,0,0,0
:endlayer
layer: 13
0,0,0,0,0,0,0,0,0,0,0,0,0,0,0,0,0,0,0,0,0,0,0,0,0,0
0,0,115,0,0,0,0,0,115,0,0,0,0,0,0,0,0,0,0,0,0,0,0,0,0,0
0,0,115,4,105,105,105,4,115,0,0,0,0,0,0,0,0,0,0,123,0,0,0,0,0,0
0,0,115,0,0,122,0,0,115,0,0,0,0,0,0,0,0,0,0,123,0,0,0,0,0,0
0,0,115,0,0,0,0,0,115,0,0,0,0,0,0,0,0,0,0,123,0,0,0,0,0,0
0,0,115,4,0,0,0,4,115,0,0,0,0,0,0,0,0,0,0,123,0,0,0,0,0,0
0,0,115,0,0,0,0,0,115,0,0,0,0,0,0,0,0,0,0,123,0,0,0,0,0,0
0,0,115,0,0,0,0,0,115,0,0,0,0,0,0,0,0,0,0,123,0,0,0,0,0,0
0,0,115,4,0,0,0,4,115,123,123,123,123,0,0,0,0,0,0,123,0,0,0,0,0,0
0,0,115,0,0,0,0,0,115,0,0,0,0,0,0,0,0,0,0,123,0,0,0,0,0,0
0,0,115,0,0,0,0,0,115,0,0,0,0,0,0,0,0,0,0,123,0,0,0,0,0,0
0,0,115,4,105,105,105,4,115,0,0,0,0,0,0,0,0,0,0,123,0,0,0,0,0,0
0,0,115,0,0,0,0,0,115,0,0,0,0,0,0,0,0,0,0,123,0,0,0,0,0,0
0,0,0,0,0,0,0,0,0,0,0,0,0,0,0,0,0,0,0,123,0,0,0,0,0,0
0,0,0,0,0,0,0,0,0,0,0,0,0,0,0,0,0,0,0,0,0,0,0,0,0,0
0,0,0,0,0,0,0,0,0,0,0,0,0,0,0,0,0,0,0,0,0,0,0,0,0,0
0,0,0,0,0,0,0,0,0,0,0,0,0,0,0,0,0,0,0,0,0,0,0,0,0,0
0,0,0,0,0,0,0,0,0,0,0,0,0,0,0,0,0,0,0,0,0,0,0,0,0,0
0,0,0,0,0,0,0,0,0,0,0,0,0,0,0,0,0,0,0,0,0,0,0,0,0,0
0,0,0,0,0,0,0,0,0,0,0,0,0,0,0,0,0,0,0,0,0,0,0,0,0,0
0,0,0,0,0,0,0,0,0,0,0,0,0,0,0,0,0,0,0,0,0,0,0,0,0,0
0,0,0,0,0,0,0,0,0,0,0,0,0,0,0,0,0,0,0,0,0,0,0,0,0,0
0,0,0,0,0,0,0,0,0,0,0,0,0,0,0,0,0,0,0,0,0,0,0,0,0,0
0,0,0,0,0,0,0,0,0,0,0,0,0,0,0,0,0,0,0,0,0,0,0,0,0,0
0,0,0,0,0,0,0,0,0,0,0,0,0,0,0,0,0,0,0,0,0,0,0,0,0,0
0,0,0,0,0,0,0,0,0,0,0,0,0,0,0,0,0,0,0,0,0,0,0,0,0,0
0,0,0,0,0,0,0,0,0,0,0,0,0,0,0,0,0,0,0,0,0,0,0,0,0,0
0,0,0,0,0,0,0,0,0,0,0,0,0,0,0,0,0,0,0,0,0,0,0,0,0,0
0,0,0,0,0,0,0,0,0,0,0,0,0,0,0,0,0,0,0,0,0,0,0,0,0,0
:endlayer
layer: 14
0,0,0,0,0,0,0,0,0,0,0,0,0,0,0,0,0,0,0,0,0,0,0,0,0,0
0,0,101,77,0,0,0,95,104,0,0,0,0,0,0,0,0,0,0,0,0,0,0,0,0,0
0,0,101,4,105,105,105,4,104,0,0,0,0,0,0,0,0,0,0,0,0,0,0,0,0,0
0,0,101,77,0,0,0,95,104,0,0,0,0,0,0,0,0,0,0,0,0,0,0,0,0,0
0,0,101,77,0,0,0,95,104,0,0,0,0,0,0,0,0,0,0,0,0,0,0,0,0,0
0,0,101,4,0,0,0,4,104,0,0,0,0,0,0,0,0,0,0,0,0,0,0,0,0,0
0,0,101,77,0,0,0,95,104,0,0,0,0,0,0,0,0,0,0,0,0,0,0,0,0,0
0,0,101,77,0,0,0,95,104,0,0,0,0,0,0,0,0,0,0,0,0,0,0,0,0,0
0,0,101,4,0,0,0,4,104,0,0,0,0,0,0,0,0,0,0,0,0,0,0,0,0,0
0,0,101,77,0,0,0,95,104,0,0,0,0,0,0,0,0,0,0,0,0,0,0,0,0,0
0,0,101,77,0,0,0,95,104,0,0,0,0,0,0,0,0,0,0,0,0,0,0,0,0,0
0,0,101,4,105,105,105,4,104,0,0,0,0,0,0,0,0,0,0,0,0,0,0,0,0,0
0,0,101,77,0,0,0,95,104,0,0,0,0,0,0,0,0,0,0,0,0,0,0,0,0,0
0,0,0,0,0,0,0,0,0,0,0,0,0,0,0,0,0,0,0,0,0,0,0,0,0,0
0,0,0,0,0,0,0,0,0,0,0,0,0,0,0,0,0,0,0,0,0,0,0,0,0,0
0,0,0,0,0,0,0,0,0,0,0,0,0,0,0,0,0,0,0,0,0,0,0,0,0,0
0,0,0,0,0,0,0,0,0,0,0,0,0,0,0,0,0,0,0,0,0,0,0,0,0,0
0,0,0,0,0,0,0,0,0,0,0,0,0,0,0,0,0,0,0,0,0,0,0,0,0,0
0,0,0,0,0,0,0,0,0,0,0,0,0,0,0,0,0,0,0,0,0,0,0,0,0,0
0,0,0,0,0,0,0,0,0,0,0,0,0,0,0,0,0,0,0,0,0,0,0,0,0,0
0,0,0,0,0,0,0,0,0,0,0,0,0,0,0,0,0,0,0,0,0,0,0,0,0,0
0,0,0,0,0,0,0,0,0,0,0,0,0,0,0,0,0,0,0,0,0,0,0,0,0,0
0,0,0,0,0,0,0,0,0,0,0,0,0,0,0,0,0,0,0,0,0,0,0,0,0,0
0,0,0,0,0,0,0,0,0,0,0,0,0,0,0,0,0,0,0,0,0,0,0,0,0,0
0,0,0,0,0,0,0,0,0,0,0,0,0,0,0,0,0,0,0,0,0,0,0,0,0,0
0,0,0,0,0,0,0,0,0,0,0,0,0,0,0,0,0,0,0,0,0,0,0,0,0,0
0,0,0,0,0,0,0,0,0,0,0,0,0,0,0,0,0,0,0,0,0,0,0,0,0,0
0,0,0,0,0,0,0,0,0,0,0,0,0,0,0,0,0,0,0,0,0,0,0,0,0,0
0,0,0,0,0,0,0,0,0,0,0,0,0,0,0,0,0,0,0,0,0,0,0,0,0,0
:endlayer
layer: 15
0,0,0,0,0,0,0,0,0,0,0,0,0,0,0,0,0,0,0,0,0,0,0,0,0,0
0,0,0,101,77,0,95,104,0,0,0,0,0,0,0,0,0,0,0,0,0,0,0,0,0,0
0,0,0,101,4,105,4,104,0,0,0,0,0,0,0,0,0,0,0,0,0,0,0,0,0,0
0,0,0,101,77,0,95,104,0,0,0,0,0,0,0,0,0,0,0,0,0,0,0,0,0,0
0,0,0,101,77,0,95,104,0,0,0,0,0,0,0,0,0,0,0,0,0,0,0,0,0,0
0,0,0,101,4,0,4,104,0,0,0,0,0,0,0,0,0,0,0,0,0,0,0,0,0,0
0,0,0,101,77,0,95,104,0,0,0,0,0,0,0,0,0,0,0,0,0,0,0,0,0,0
0,0,0,101,77,0,95,104,0,0,0,0,0,0,0,0,0,0,0,0,0,0,0,0,0,0
0,0,0,101,4,0,4,104,0,0,0,0,0,0,0,0,0,0,0,0,0,0,0,0,0,0
0,0,0,101,77,0,95,104,0,0,0,0,0,0,0,0,0,0,0,0,0,0,0,0,0,0
0,0,0,101,77,0,95,104,0,0,0,0,0,0,0,0,0,0,0,0,0,0,0,0,0,0
0,0,0,101,4,105,4,104,0,0,0,0,0,0,0,0,0,0,0,0,0,0,0,0,0,0
0,0,0,101,77,0,95,104,0,0,0,0,0,0,0,0,0,0,0,0,0,0,0,0,0,0
0,0,0,0,0,0,0,0,0,0,0,0,0,0,0,0,0,0,0,0,0,0,0,0,0,0
0,0,0,0,0,0,0,0,0,0,0,0,0,0,0,0,0,0,0,0,0,0,0,0,0,0
0,0,0,0,0,0,0,0,0,0,0,0,0,0,0,0,0,0,0,0,0,0,0,0,0,0
0,0,0,0,0,0,0,0,0,0,0,0,0,0,0,0,0,0,0,0,0,0,0,0,0,0
0,0,0,0,0,0,0,0,0,0,0,0,0,0,0,0,0,0,0,0,0,0,0,0,0,0
0,0,0,0,0,0,0,0,0,0,0,0,0,0,0,0,0,0,0,0,0,0,0,0,0,0
0,0,0,0,0,0,0,0,0,0,0,0,0,0,0,0,0,0,0,0,0,0,0,0,0,0
0,0,0,0,0,0,0,0,0,0,0,0,0,0,0,0,0,0,0,0,0,0,0,0,0,0
0,0,0,0,0,0,0,0,0,0,0,0,0,0,0,0,0,0,0,0,0,0,0,0,0,0
0,0,0,0,0,0,0,0,0,0,0,0,0,0,0,0,0,0,0,0,0,0,0,0,0,0
0,0,0,0,0,0,0,0,0,0,0,0,0,0,0,0,0,0,0,0,0,0,0,0,0,0
0,0,0,0,0,0,0,0,0,0,0,0,0,0,0,0,0,0,0,0,0,0,0,0,0,0
0,0,0,0,0,0,0,0,0,0,0,0,0,0,0,0,0,0,0,0,0,0,0,0,0,0
0,0,0,0,0,0,0,0,0,0,0,0,0,0,0,0,0,0,0,0,0,0,0,0,0,0
0,0,0,0,0,0,0,0,0,0,0,0,0,0,0,0,0,0,0,0,0,0,0,0,0,0
0,0,0,0,0,0,0,0,0,0,0,0,0,0,0,0,0,0,0,0,0,0,0,0,0,0
:endlayer
layer: 16
0,0,0,0,0,0,0,0,0,0,0,0,0,0,0,0,0,0,0,0,0,0,0,0,0,0
0,0,0,0,101,100,104,0,0,0,0,0,0,0,0,0,0,0,0,0,0,0,0,0,0,0
0,0,0,0,101,4,104,0,0,0,0,0,0,0,0,0,0,0,0,0,0,0,0,0,0,0
0,0,0,0,101,93,104,0,0,0,0,0,0,0,0,0,0,0,0,0,0,0,0,0,0,0
0,0,0,0,101,100,104,0,0,0,0,0,0,0,0,0,0,0,0,0,0,0,0,0,0,0
0,0,0,0,101,4,104,0,0,0,0,0,0,0,0,0,0,0,0,0,0,0,0,0,0,0
0,0,0,0,101,93,104,0,0,0,0,0,0,0,0,0,0,0,0,0,0,0,0,0,0,0
0,0,0,0,101,100,104,0,0,0,0,0,0,0,0,0,0,0,0,0,0,0,0,0,0,0
0,0,0,0,101,4,104,0,0,0,0,0,0,0,0,0,0,0,0,0,0,0,0,0,0,0
0,0,0,0,101,93,104,0,0,0,0,0,0,0,0,0,0,0,0,0,0,0,0,0,0,0
0,0,0,0,101,100,104,0,0,0,0,0,0,0,0,0,0,0,0,0,0,0,0,0,0,0
0,0,0,0,101,4,104,0,0,0,0,0,0,0,0,0,0,0,0,0,0,0,0,0,0,0
0,0,0,0,101,93,104,0,0,0,0,0,0,0,0,0,0,0,0,0,0,0,0,0,0,0
0,0,0,0,0,0,0,0,0,0,0,0,0,0,0,0,0,0,0,0,0,0,0,0,0,0
0,0,0,0,0,0,0,0,0,0,0,0,0,0,0,0,0,0,0,0,0,0,0,0,0,0
0,0,0,0,0,0,0,0,0,0,0,0,0,0,0,0,0,0,0,0,0,0,0,0,0,0
0,0,0,0,0,0,0,0,0,0,0,0,0,0,0,0,0,0,0,0,0,0,0,0,0,0
0,0,0,0,0,0,0,0,0,0,0,0,0,0,0,0,0,0,0,0,0,0,0,0,0,0
0,0,0,0,0,0,0,0,0,0,0,0,0,0,0,0,0,0,0,0,0,0,0,0,0,0
0,0,0,0,0,0,0,0,0,0,0,0,0,0,0,0,0,0,0,0,0,0,0,0,0,0
0,0,0,0,0,0,0,0,0,0,0,0,0,0,0,0,0,0,0,0,0,0,0,0,0,0
0,0,0,0,0,0,0,0,0,0,0,0,0,0,0,0,0,0,0,0,0,0,0,0,0,0
0,0,0,0,0,0,0,0,0,0,0,0,0,0,0,0,0,0,0,0,0,0,0,0,0,0
0,0,0,0,0,0,0,0,0,0,0,0,0,0,0,0,0,0,0,0,0,0,0,0,0,0
0,0,0,0,0,0,0,0,0,0,0,0,0,0,0,0,0,0,0,0,0,0,0,0,0,0
0,0,0,0,0,0,0,0,0,0,0,0,0,0,0,0,0,0,0,0,0,0,0,0,0,0
0,0,0,0,0,0,0,0,0,0,0,0,0,0,0,0,0,0,0,0,0,0,0,0,0,0
0,0,0,0,0,0,0,0,0,0,0,0,0,0,0,0,0,0,0,0,0,0,0,0,0,0
0,0,0,0,0,0,0,0,0,0,0,0,0,0,0,0,0,0,0,0,0,0,0,0,0,0
:endlayer
layer: 17
0,0,0,0,0,0,0,0,0,0,0,0,0,0,0,0,0,0,0,0,0,0,0,0,0,0
0,0,0,0,0,123,0,0,0,0,0,0,0,0,0,0,0,0,0,0,0,0,0,0,0,0
0,0,0,0,0,123,0,0,0,0,0,0,0,0,0,0,0,0,0,0,0,0,0,0,0,0
0,0,0,0,0,123,0,0,0,0,0,0,0,0,0,0,0,0,0,0,0,0,0,0,0,0
0,0,0,0,0,123,0,0,0,0,0,0,0,0,0,0,0,0,0,0,0,0,0,0,0,0
0,0,0,0,0,123,0,0,0,0,0,0,0,0,0,0,0,0,0,0,0,0,0,0,0,0
0,0,0,0,0,123,0,0,0,0,0,0,0,0,0,0,0,0,0,0,0,0,0,0,0,0
0,0,0,0,0,123,0,0,0,0,0,0,0,0,0,0,0,0,0,0,0,0,0,0,0,0
0,0,0,0,0,123,0,0,0,0,0,0,0,0,0,0,0,0,0,0,0,0,0,0,0,0
0,0,0,0,0,123,0,0,0,0,0,0,0,0,0,0,0,0,0,0,0,0,0,0,0,0
0,0,0,0,0,123,0,0,0,0,0,0,0,0,0,0,0,0,0,0,0,0,0,0,0,0
0,0,0,0,0,123,0,0,0,0,0,0,0,0,0,0,0,0,0,0,0,0,0,0,0,0
0,0,0,0,0,123,0,0,0,0,0,0,0,0,0,0,0,0,0,0,0,0,0,0,0,0
0,0,0,0,0,0,0,0,0,0,0,0,0,0,0,0,0,0,0,0,0,0,0,0,0,0
0,0,0,0,0,0,0,0,0,0,0,0,0,0,0,0,0,0,0,0,0,0,0,0,0,0
0,0,0,0,0,0,0,0,0,0,0,0,0,0,0,0,0,0,0,0,0,0,0,0,0,0
0,0,0,0,0,0,0,0,0,0,0,0,0,0,0,0,0,0,0,0,0,0,0,0,0,0
0,0,0,0,0,0,0,0,0,0,0,0,0,0,0,0,0,0,0,0,0,0,0,0,0,0
0,0,0,0,0,0,0,0,0,0,0,0,0,0,0,0,0,0,0,0,0,0,0,0,0,0
0,0,0,0,0,0,0,0,0,0,0,0,0,0,0,0,0,0,0,0,0,0,0,0,0,0
0,0,0,0,0,0,0,0,0,0,0,0,0,0,0,0,0,0,0,0,0,0,0,0,0,0
0,0,0,0,0,0,0,0,0,0,0,0,0,0,0,0,0,0,0,0,0,0,0,0,0,0
0,0,0,0,0,0,0,0,0,0,0,0,0,0,0,0,0,0,0,0,0,0,0,0,0,0
0,0,0,0,0,0,0,0,0,0,0,0,0,0,0,0,0,0,0,0,0,0,0,0,0,0
0,0,0,0,0,0,0,0,0,0,0,0,0,0,0,0,0,0,0,0,0,0,0,0,0,0
0,0,0,0,0,0,0,0,0,0,0,0,0,0,0,0,0,0,0,0,0,0,0,0,0,0
0,0,0,0,0,0,0,0,0,0,0,0,0,0,0,0,0,0,0,0,0,0,0,0,0,0
0,0,0,0,0,0,0,0,0,0,0,0,0,0,0,0,0,0,0,0,0,0,0,0,0,0
0,0,0,0,0,0,0,0,0,0,0,0,0,0,0,0,0,0,0,0,0,0,0,0,0,0
:endlayer

#### RULES ####
rule:
plugin=vanillaBlocks
number=1
data:
JSON:{blockState:{blockName:"minecraft:stone",properties:{variant:"stone"}}}
:enddata
:endrule

rule:
plugin=vanillaBlocks
number=2
data:
JSON:{blockState:{blockName:"minecraft:dirt",properties:{variant:"dirt",snowy:"false"}}}
:enddata
:endrule

rule:
plugin=vanillaBlocks
number=3
data:
JSON:{blockState:{blockName:"minecraft:grass",properties:{snowy:"false"}}}
:enddata
:endrule

rule:
plugin=vanillaBlocks
number=4
data:
JSON:{blockState:{blockName:"minecraft:log",properties:{variant:"oak",axis:"y"}}}
:enddata
:endrule

rule:
plugin=vanillaBlocks
number=5
data:
JSON:{blockState:{blockName:"minecraft:stonebrick",properties:{variant:"stonebrick"}}}
:enddata
:endrule

rule:
plugin=vanillaBlocks
number=6
data:
JSON:{blockState:{blockName:"minecraft:planks",properties:{variant:"oak"}}}
:enddata
:endrule

rule:
plugin=vanillaBlocks
number=7
data:
JSON:{blockState:{blockName:"minecraft:gravel"}}
:enddata
:endrule

rule:
plugin=vanillaBlocks
number=8
data:
JSON:{blockState:{blockName:"minecraft:farmland",properties:{moisture:"7"}}}
:enddata
:endrule

rule:
plugin=fluid
number=9
data:
JSON:{blockState:{blockName:"minecraft:water",properties:{level:"0"}}}
:enddata
:endrule

rule:
plugin=vanillaBlocks
number=10
data:
JSON:{blockState:{blockName:"minecraft:grass_path"}}
:enddata
:endrule

rule:
plugin=vanillaBlocks
number=11
data:
JSON:{blockState:{blockName:"minecraft:dirt",properties:{variant:"coarse_dirt",snowy:"false"}}}
:enddata
:endrule

rule:
plugin=vanillaBlocks
number=12
data:
JSON:{blockState:{blockName:"minecraft:tallgrass",properties:{type:"tall_grass"}}}
:enddata
:endrule

rule:
plugin=vanillaBlocks
number=13
data:
JSON:{blockState:{blockName:"minecraft:yellow_flower",properties:{type:"dandelion"}}}
:enddata
:endrule

rule:
plugin=blockTile
number=14
data:
JSON:{blockState:{blockName:"ancientwarfarestructure:advanced_spawner",properties:{transparent:"true"}},teData:{id:"ancientwarfarestructure:advanced_spawner_tile",spawnerSettings:{minDelay:10,spawnDelay:9,lightSensitive:0b,spawnGroups:[{settingsList:[{remainingSpawnCount:1,hostile:1b,customTag:{ArmorDropChances:[0.085f,0.085f,0.085f,0.085f],CustomName:"Reiksgard Soldier",hasCustomEquipment:1b,ArmorItems:[{},{},{},{}],skinSettings:{npcTypeName:"reiksgard.soldier",skinTypeSelected:"npc_type"},HandDropChances:[0.085f,0.085f],factionName:"empire",HandItems:[{id:"minecraft:iron_sword",Count:1b,Damage:0s},{id:"ancientwarfarenpc:iron_shield",Count:1b,Damage:0s}]},maxToSpawn:1,entityId:"ancientwarfarenpc:faction.soldier",minToSpawn:1}],groupWeight:1}],playerRange:16,respondToRedstone:0b,inventory:{Size:9,Items:[]},spawnRange:0,transparent:1b,maxDelay:10,spawnYOffset:0,xpToDrop:0,mobRange:0,debugMode:0b,maxNearbyMonsters:0}}}
:enddata
:endrule

rule:
plugin=vanillaBlocks
number=15
data:
JSON:{blockState:{blockName:"biomesoplenty:leaves_2",properties:{check_decay:"false",decayable:"false",variant:"white_cherry"}}}
:enddata
:endrule

rule:
plugin=vanillaBlocks
number=16
data:
JSON:{blockState:{blockName:"minecraft:spruce_fence",properties:{east:"false",south:"false",north:"false",west:"false"}}}
:enddata
:endrule

rule:
plugin=vanillaBlocks
number=17
data:
JSON:{blockState:{blockName:"rustic:grape_stem",properties:{age:"3"}}}
:enddata
:endrule

rule:
plugin=vanillaBlocks
number=18
data:
JSON:{blockState:{blockName:"minecraft:waterlily"}}
:enddata
:endrule

rule:
plugin=vanillaBlocks
number=19
data:
JSON:{blockState:{blockName:"minecraft:red_flower",properties:{type:"poppy"}}}
:enddata
:endrule

rule:
plugin=vanillaBlocks
number=20
data:
JSON:{blockState:{blockName:"minecraft:oak_stairs",properties:{half:"bottom",shape:"straight",facing:"north"}}}
:enddata
:endrule

rule:
plugin=vanillaBlocks
number=21
data:
JSON:{blockState:{blockName:"minecraft:oak_stairs",properties:{half:"top",shape:"straight",facing:"south"}}}
:enddata
:endrule

rule:
plugin=blockTile
number=22
data:
JSON:{blockState:{blockName:"ancientwarfarestructure:advanced_loot_chest",properties:{facing:"east"}},teData:{lootSettings:{lootRolls:1,splashPotion:0b,hasMessage:0b,hasLoot:1b,lootTableName:"ancientwarfare:chests/castle_pantry_mixed",spawnEntity:0b,entity:"minecraft:"},Items:[],id:"ancientwarfarestructure:advanced_loot_chest_tile",Lock:""}}
:enddata
:endrule

rule:
plugin=vanillaBlocks
number=23
data:
JSON:{blockState:{blockName:"minecraft:stone",properties:{variant:"smooth_andesite"}}}
:enddata
:endrule

rule:
plugin=inventory
number=24
data:
JSON:{blockState:{blockName:"minecraft:furnace",properties:{facing:"east"}},lootLevel:0,teData:{CookTime:0,BurnTime:0,Items:[],id:"minecraft:furnace",CookTimeTotal:0,Lock:""},inventoryData:{length:0,inventoryContents:[]},legacyFeatures:0b}
:enddata
:endrule

rule:
plugin=inventory
number=25
data:
JSON:{blockState:{blockName:"minecraft:furnace",properties:{facing:"east"}},lootLevel:0,teData:{CookTime:0,BurnTime:0,Items:[],id:"minecraft:furnace",CookTimeTotal:0,Lock:""},inventoryData:{length:0,inventoryContents:[]},legacyFeatures:0b}
:enddata
:endrule

rule:
plugin=blockTile
number=26
data:
JSON:{blockState:{blockName:"ancientwarfarestructure:urn"},teData:{lootSettings:{lootRolls:0,splashPotion:0b,hasMessage:0b,hasLoot:0b,lootTableName:"minecraft:",spawnEntity:0b,entity:"minecraft:"},id:"ancientwarfarestructure:urn_tile"}}
:enddata
:endrule

rule:
plugin=vanillaBlocks
number=27
data:
JSON:{blockState:{blockName:"minecraft:carpet",properties:{color:"red"}}}
:enddata
:endrule

rule:
plugin=blockTile
number=28
data:
JSON:{blockState:{blockName:"ancientwarfarestructure:advanced_spawner",properties:{transparent:"true"}},teData:{id:"ancientwarfarestructure:advanced_spawner_tile",spawnerSettings:{minDelay:10,spawnDelay:6,lightSensitive:0b,spawnGroups:[{settingsList:[{remainingSpawnCount:1,hostile:1b,customTag:{ArmorDropChances:[0.085f,0.085f,0.085f,0.085f],hasCustomEquipment:0b,ArmorItems:[{},{},{},{}],skinSettings:{npcTypeName:"custom",skinTypeSelected:"default"},HandDropChances:[0.085f,0.085f],factionName:"reiksgard",HandItems:[{},{}]},maxToSpawn:1,entityId:"ancientwarfarenpc:faction.civilian.female",minToSpawn:1}],groupWeight:1}],playerRange:16,respondToRedstone:0b,inventory:{Size:9,Items:[]},spawnRange:0,transparent:1b,maxDelay:10,spawnYOffset:0,xpToDrop:0,mobRange:0,debugMode:0b,maxNearbyMonsters:0}}}
:enddata
:endrule

rule:
plugin=blockTile
number=29
data:
JSON:{blockState:{blockName:"ancientwarfarestructure:urn"},teData:{lootSettings:{lootRolls:0,splashPotion:0b,hasMessage:0b,hasLoot:0b,lootTableName:"minecraft:",spawnEntity:0b,entity:"minecraft:"},id:"ancientwarfarestructure:urn_tile"}}
:enddata
:endrule

rule:
plugin=doors
number=30
data:
JSON:{blockState:{blockName:"minecraft:spruce_door",properties:{hinge:"left",half:"lower",powered:"false",facing:"north",open:"false"}}}
:enddata
:endrule

rule:
plugin=blockTile
number=31
data:
JSON:{blockState:{blockName:"ancientwarfarestructure:advanced_spawner",properties:{transparent:"true"}},teData:{id:"ancientwarfarestructure:advanced_spawner_tile",spawnerSettings:{minDelay:10,spawnDelay:3,lightSensitive:0b,spawnGroups:[{settingsList:[{remainingSpawnCount:1,hostile:1b,customTag:{ArmorDropChances:[0.085f,0.085f,0.085f,0.085f],CustomName:"Reiksgard Soldier",hasCustomEquipment:1b,ArmorItems:[{},{},{},{}],skinSettings:{npcTypeName:"reiksgard.soldier",skinTypeSelected:"npc_type"},HandDropChances:[0.085f,0.085f],factionName:"empire",HandItems:[{id:"minecraft:iron_sword",Count:1b,Damage:0s},{id:"ancientwarfarenpc:iron_shield",Count:1b,Damage:0s}]},maxToSpawn:1,entityId:"ancientwarfarenpc:faction.soldier",minToSpawn:1}],groupWeight:1}],playerRange:16,respondToRedstone:0b,inventory:{Size:9,Items:[]},spawnRange:0,transparent:1b,maxDelay:10,spawnYOffset:0,xpToDrop:0,mobRange:0,debugMode:0b,maxNearbyMonsters:0}}}
:enddata
:endrule

rule:
plugin=doors
number=32
data:
JSON:{blockState:{blockName:"minecraft:spruce_door",properties:{hinge:"left",half:"lower",powered:"false",facing:"south",open:"false"}}}
:enddata
:endrule

rule:
plugin=blockTile
number=33
data:
JSON:{blockState:{blockName:"ancientwarfarestructure:advanced_spawner",properties:{transparent:"true"}},teData:{id:"ancientwarfarestructure:advanced_spawner_tile",spawnerSettings:{minDelay:10,spawnDelay:8,lightSensitive:0b,spawnGroups:[{settingsList:[{remainingSpawnCount:1,hostile:1b,customTag:{ArmorDropChances:[0.085f,0.085f,0.085f,0.085f],CustomName:"Reiksgard Soldier",hasCustomEquipment:1b,ArmorItems:[{},{},{},{}],skinSettings:{npcTypeName:"reiksgard.soldier",skinTypeSelected:"npc_type"},HandDropChances:[0.085f,0.085f],factionName:"empire",HandItems:[{id:"minecraft:iron_sword",Count:1b,Damage:0s},{id:"ancientwarfarenpc:iron_shield",Count:1b,Damage:0s}]},maxToSpawn:1,entityId:"ancientwarfarenpc:faction.soldier",minToSpawn:1}],groupWeight:1}],playerRange:16,respondToRedstone:0b,inventory:{Size:9,Items:[]},spawnRange:0,transparent:1b,maxDelay:10,spawnYOffset:0,xpToDrop:0,mobRange:0,debugMode:0b,maxNearbyMonsters:0}}}
:enddata
:endrule

rule:
plugin=doors
number=34
data:
JSON:{blockState:{blockName:"minecraft:spruce_door",properties:{hinge:"right",half:"lower",powered:"false",facing:"north",open:"false"}}}
:enddata
:endrule

rule:
plugin=vanillaBlocks
number=35
data:
JSON:{blockState:{blockName:"ancientwarfarestructure:stool",properties:{variant:"spruce"}}}
:enddata
:endrule

rule:
plugin=blockTile
number=36
data:
JSON:{blockState:{blockName:"ancientwarfarestructure:chair",properties:{visible:"true",variant:"spruce",facing:"west"}},facing:"north",teData:{facing:"east",id:"ancientwarfarestructure:chair_tile"}}
:enddata
:endrule

rule:
plugin=vanillaBlocks
number=37
data:
JSON:{blockState:{blockName:"ancientwarfarestructure:table",properties:{leg_southwest:"true",leg_northwest:"true",variant:"spruce",leg_northeast:"true",leg_southeast:"true"}}}
:enddata
:endrule

rule:
plugin=vanillaBlocks
number=38
data:
JSON:{blockState:{blockName:"ancientwarfarestructure:bench",properties:{legs:"none",variant:"spruce",axis:"x"}}}
:enddata
:endrule

rule:
plugin=blockTile
number=39
data:
JSON:{blockState:{blockName:"ancientwarfarestructure:chair",properties:{visible:"true",variant:"spruce",facing:"west"}},facing:"north",teData:{facing:"east",id:"ancientwarfarestructure:chair_tile"}}
:enddata
:endrule

rule:
plugin=inventory
number=40
data:
JSON:{blockState:{blockName:"rustic:barrel"},lootLevel:0,teData:{ForgeCaps:{},id:"rustic:tileentitybarrel",items:{Size:27,Items:[]},Lock:""},inventoryData:{length:0,inventoryContents:[]},legacyFeatures:0b}
:enddata
:endrule

rule:
plugin=blockTile
number=41
data:
JSON:{blockState:{blockName:"ancientwarfarestructure:advanced_loot_chest",properties:{facing:"west"}},teData:{lootSettings:{lootRolls:1,splashPotion:0b,hasMessage:0b,hasLoot:1b,lootTableName:"ancientwarfare:chests/citizen_medium_value",spawnEntity:0b},Items:[],id:"ancientwarfarestructure:advanced_loot_chest_tile",Lock:""}}
:enddata
:endrule

rule:
plugin=blockTile
number=42
data:
JSON:{blockState:{blockName:"ancientwarfarestructure:chair",properties:{visible:"true",variant:"spruce",facing:"west"}},facing:"north",teData:{facing:"east",id:"ancientwarfarestructure:chair_tile"}}
:enddata
:endrule

rule:
plugin=blockTile
number=43
data:
JSON:{blockState:{blockName:"ancientwarfarestructure:advanced_spawner",properties:{transparent:"true"}},teData:{id:"ancientwarfarestructure:advanced_spawner_tile",spawnerSettings:{minDelay:10,spawnDelay:10,lightSensitive:0b,spawnGroups:[{settingsList:[{remainingSpawnCount:1,hostile:1b,customTag:{ArmorDropChances:[0.085f,0.085f,0.085f,0.085f],CustomName:"Reiksgard Soldier",hasCustomEquipment:1b,ArmorItems:[{},{},{},{}],skinSettings:{npcTypeName:"reiksgard.soldier",skinTypeSelected:"npc_type"},HandDropChances:[0.085f,0.085f],factionName:"empire",HandItems:[{id:"minecraft:iron_sword",Count:1b,Damage:0s},{id:"ancientwarfarenpc:iron_shield",Count:1b,Damage:0s}]},maxToSpawn:1,entityId:"ancientwarfarenpc:faction.soldier",minToSpawn:1}],groupWeight:1}],playerRange:16,respondToRedstone:0b,inventory:{Size:9,Items:[]},spawnRange:0,transparent:1b,maxDelay:10,spawnYOffset:0,xpToDrop:0,mobRange:0,debugMode:0b,maxNearbyMonsters:0}}}
:enddata
:endrule

rule:
plugin=blockTile
number=44
data:
JSON:{blockState:{blockName:"ancientwarfarestructure:advanced_spawner",properties:{transparent:"true"}},teData:{id:"ancientwarfarestructure:advanced_spawner_tile",spawnerSettings:{minDelay:10,spawnDelay:5,lightSensitive:0b,spawnGroups:[{settingsList:[{remainingSpawnCount:1,hostile:1b,customTag:{ArmorDropChances:[0.085f,0.085f,0.085f,0.085f],CustomName:"Reiksgard Soldier",hasCustomEquipment:1b,ArmorItems:[{},{},{},{}],skinSettings:{npcTypeName:"reiksgard.soldier",skinTypeSelected:"npc_type"},HandDropChances:[0.085f,0.085f],factionName:"empire",HandItems:[{id:"minecraft:iron_sword",Count:1b,Damage:0s},{id:"ancientwarfarenpc:iron_shield",Count:1b,Damage:0s}]},maxToSpawn:1,entityId:"ancientwarfarenpc:faction.soldier",minToSpawn:1}],groupWeight:1}],playerRange:16,respondToRedstone:0b,inventory:{Size:9,Items:[]},spawnRange:0,transparent:1b,maxDelay:10,spawnYOffset:0,xpToDrop:0,mobRange:0,debugMode:0b,maxNearbyMonsters:0}}}
:enddata
:endrule

rule:
plugin=blockTile
number=45
data:
JSON:{blockState:{blockName:"ancientwarfarestructure:urn"},teData:{lootSettings:{splashPotion:0b,hasMessage:0b,hasLoot:0b,spawnEntity:0b},id:"ancientwarfarestructure:urn_tile"}}
:enddata
:endrule

rule:
plugin=inventory
number=46
data:
JSON:{blockState:{blockName:"rustic:barrel"},lootLevel:0,teData:{ForgeCaps:{},id:"rustic:tileentitybarrel",items:{Size:27,Items:[]},Lock:""},inventoryData:{length:0,inventoryContents:[]},legacyFeatures:0b}
:enddata
:endrule

rule:
plugin=inventory
number=47
data:
JSON:{blockState:{blockName:"rustic:barrel"},lootLevel:0,teData:{ForgeCaps:{},id:"rustic:tileentitybarrel",items:{Size:27,Items:[]},Lock:""},inventoryData:{length:0,inventoryContents:[]},legacyFeatures:0b}
:enddata
:endrule

rule:
plugin=inventory
number=48
data:
JSON:{blockState:{blockName:"ancientwarfarestructure:loot_basket",properties:{visible:"true",double:"true",facing:"south"}},lootLevel:0,teData:{ForgeData:{},lootSettings:{splashPotion:0b,hasMessage:0b,hasLoot:0b,spawnEntity:0b},Items:[],id:"ancientwarfarestructure:loot_basket",Lock:""},inventoryData:{length:0,inventoryContents:[]},legacyFeatures:0b}
:enddata
:endrule

rule:
plugin=blockTile
number=49
data:
JSON:{blockState:{blockName:"ancientwarfarestructure:gate_proxy"},teData:{lsb:-7895142016560034607L,id:"ancientwarfarestructure:gate_proxy_tile",msb:-2487146401443855706L,render:1b}}
:enddata
:endrule

rule:
plugin=vanillaSkull
number=50
data:
JSON:{blockState:{blockName:"minecraft:skull",properties:{nodrop:"false",facing:"up"}},skullRotation:7,teData:{Owner:{Id:"c665ce53-a512-4eeb-96cf-7057c816a3ea",Properties:{textures:[{Value:"eyJ0ZXh0dXJlcyI6eyJTS0lOIjp7InVybCI6Imh0dHA6Ly90ZXh0dXJlcy5taW5lY3JhZnQubmV0L3RleHR1cmUvMTVhMjYzZDY1NTE2N2YwMDA4NTFhMDVhMTgzMTcyNmU3ZGI5ZTFmZjgzZDg3YzQyMzkzMmIzZTMxNzY5YWE4OSJ9fX0="}]}},Rot:11b,id:"minecraft:skull",SkullType:3b}}
:enddata
:endrule

rule:
plugin=blockTile
number=51
data:
JSON:{blockState:{blockName:"ancientwarfarestructure:gate_proxy"},teData:{lsb:-7895142016560034607L,id:"ancientwarfarestructure:gate_proxy_tile",msb:-2487146401443855706L,render:0b}}
:enddata
:endrule

rule:
plugin=blockTile
number=52
data:
JSON:{blockState:{blockName:"ancientwarfarestructure:gate_proxy"},teData:{lsb:-7895142016560034607L,id:"ancientwarfarestructure:gate_proxy_tile",msb:-2487146401443855706L,render:0b}}
:enddata
:endrule

rule:
plugin=blockTile
number=53
data:
JSON:{blockState:{blockName:"ancientwarfarestructure:advanced_loot_chest",properties:{facing:"south"}},teData:{lootSettings:{lootRolls:1,splashPotion:0b,hasMessage:0b,hasLoot:1b,lootTableName:"ancientwarfare:chests/compat/rustic/rustic_village_farm_wine",spawnEntity:0b},Items:[],id:"ancientwarfarestructure:advanced_loot_chest_tile",Lock:""}}
:enddata
:endrule

rule:
plugin=blockTile
number=54
data:
JSON:{blockState:{blockName:"rustic:liquid_barrel"},teData:{Empty:"",id:"rustic:tileentityliquidbarrel"}}
:enddata
:endrule

rule:
plugin=blockTile
number=55
data:
JSON:{blockState:{blockName:"ancientwarfarestructure:advanced_loot_chest",properties:{facing:"west"}},teData:{lootSettings:{lootRolls:1,splashPotion:0b,hasMessage:0b,hasLoot:1b,lootTableName:"ancientwarfare:chests/compat/rustic/rustic_village_farm_wine",spawnEntity:0b},Items:[],id:"ancientwarfarestructure:advanced_loot_chest_tile",Lock:""}}
:enddata
:endrule

rule:
plugin=vanillaSkull
number=56
data:
JSON:{blockState:{blockName:"minecraft:skull",properties:{nodrop:"false",facing:"up"}},skullRotation:10,teData:{Owner:{Id:"c665ce53-a512-4eeb-96cf-7057c816a3ea",Properties:{textures:[{Value:"eyJ0ZXh0dXJlcyI6eyJTS0lOIjp7InVybCI6Imh0dHA6Ly90ZXh0dXJlcy5taW5lY3JhZnQubmV0L3RleHR1cmUvMTVhMjYzZDY1NTE2N2YwMDA4NTFhMDVhMTgzMTcyNmU3ZGI5ZTFmZjgzZDg3YzQyMzkzMmIzZTMxNzY5YWE4OSJ9fX0="}]}},Rot:14b,id:"minecraft:skull",SkullType:3b}}
:enddata
:endrule

rule:
plugin=blockTile
number=57
data:
JSON:{blockState:{blockName:"ancientwarfarestructure:advanced_loot_chest",properties:{facing:"south"}},teData:{lootSettings:{lootRolls:1,splashPotion:0b,hasMessage:0b,hasLoot:1b,lootTableName:"ancientwarfare:chests/compat/rustic/rustic_village_farm_wine",spawnEntity:0b},Items:[],id:"ancientwarfarestructure:advanced_loot_chest_tile",Lock:""}}
:enddata
:endrule

rule:
plugin=blockTile
number=58
data:
JSON:{blockState:{blockName:"ancientwarfarestructure:advanced_spawner",properties:{transparent:"true"}},teData:{id:"ancientwarfarestructure:advanced_spawner_tile",spawnerSettings:{minDelay:10,spawnDelay:7,lightSensitive:0b,spawnGroups:[{settingsList:[{remainingSpawnCount:1,hostile:1b,customTag:{ArmorDropChances:[0.085f,0.085f,0.085f,0.085f],CustomName:"Reiksgard Soldier",hasCustomEquipment:1b,ArmorItems:[{},{},{},{}],skinSettings:{npcTypeName:"reiksgard.soldier",skinTypeSelected:"npc_type"},HandDropChances:[0.085f,0.085f],factionName:"empire",HandItems:[{id:"minecraft:iron_sword",Count:1b,Damage:0s},{id:"ancientwarfarenpc:iron_shield",Count:1b,Damage:0s}]},maxToSpawn:1,entityId:"ancientwarfarenpc:faction.soldier",minToSpawn:1}],groupWeight:1}],playerRange:16,respondToRedstone:0b,inventory:{Size:9,Items:[]},spawnRange:0,transparent:1b,maxDelay:10,spawnYOffset:0,xpToDrop:0,mobRange:0,debugMode:0b,maxNearbyMonsters:0}}}
:enddata
:endrule

rule:
plugin=vanillaBlocks
number=59
data:
JSON:{blockState:{blockName:"minecraft:spruce_stairs",properties:{half:"bottom",shape:"straight",facing:"north"}}}
:enddata
:endrule

rule:
plugin=vanillaBlocks
number=60
data:
JSON:{blockState:{blockName:"rustic:grape_leaves",properties:{dangle:"true",distance:"1",axis:"z",grapes:"true"}}}
:enddata
:endrule

rule:
plugin=vanillaBlocks
number=61
data:
JSON:{blockState:{blockName:"rustic:grape_leaves",properties:{dangle:"true",distance:"0",axis:"z",grapes:"false"}}}
:enddata
:endrule

rule:
plugin=vanillaBlocks
number=62
data:
JSON:{blockState:{blockName:"rustic:rope",properties:{dangle:"true",axis:"z"}}}
:enddata
:endrule

rule:
plugin=vanillaBlocks
number=63
data:
JSON:{blockState:{blockName:"minecraft:spruce_stairs",properties:{half:"bottom",shape:"straight",facing:"south"}}}
:enddata
:endrule

rule:
plugin=vanillaBlocks
number=64
data:
JSON:{blockState:{blockName:"minecraft:glass_pane",properties:{east:"false",south:"false",north:"false",west:"false"}}}
:enddata
:endrule

rule:
plugin=vanillaBlocks
number=65
data:
JSON:{blockState:{blockName:"minecraft:stone_pressure_plate",properties:{powered:"false"}}}
:enddata
:endrule

rule:
plugin=vanillaSkull
number=66
data:
JSON:{blockState:{blockName:"minecraft:skull",properties:{nodrop:"false",facing:"up"}},skullRotation:6,teData:{Owner:{Id:"1fb051b1-7582-4f44-8914-8e5e65865e92",Properties:{textures:[{Value:"eyJ0ZXh0dXJlcyI6eyJTS0lOIjp7InVybCI6Imh0dHA6Ly90ZXh0dXJlcy5taW5lY3JhZnQubmV0L3RleHR1cmUvMzBhMzlkYTJjMDk5ZjcyNzc5NjkxODRjYTMyYTc0YTUzYWVhNWJjOGI2NDVmYmRmNWYzMWU1ZmJiYTc1Zjg0NCJ9fX0="}]}},Rot:10b,id:"minecraft:skull",SkullType:3b}}
:enddata
:endrule

rule:
plugin=vanillaSkull
number=67
data:
JSON:{blockState:{blockName:"minecraft:skull",properties:{nodrop:"false",facing:"up"}},skullRotation:0,teData:{Owner:{Id:"1fb051b1-7582-4f44-8914-8e5e65865e92",Properties:{textures:[{Value:"eyJ0ZXh0dXJlcyI6eyJTS0lOIjp7InVybCI6Imh0dHA6Ly90ZXh0dXJlcy5taW5lY3JhZnQubmV0L3RleHR1cmUvMzBhMzlkYTJjMDk5ZjcyNzc5NjkxODRjYTMyYTc0YTUzYWVhNWJjOGI2NDVmYmRmNWYzMWU1ZmJiYTc1Zjg0NCJ9fX0="}]}},Rot:4b,id:"minecraft:skull",SkullType:3b}}
:enddata
:endrule

rule:
plugin=doors
number=68
data:
JSON:{blockState:{blockName:"minecraft:spruce_door",properties:{hinge:"left",half:"upper",powered:"false",facing:"west",open:"false"}}}
:enddata
:endrule

rule:
plugin=doors
number=69
data:
JSON:{blockState:{blockName:"minecraft:spruce_door",properties:{hinge:"right",half:"upper",powered:"false",facing:"west",open:"false"}}}
:enddata
:endrule

rule:
plugin=blockTile
number=70
data:
JSON:{blockState:{blockName:"ancientwarfarestructure:advanced_spawner",properties:{transparent:"true"}},teData:{id:"ancientwarfarestructure:advanced_spawner_tile",spawnerSettings:{minDelay:10,spawnDelay:10,lightSensitive:0b,spawnGroups:[{settingsList:[{remainingSpawnCount:1,hostile:1b,customTag:{ArmorDropChances:[0.085f,0.085f,0.085f,0.085f],hasCustomEquipment:0b,ArmorItems:[{},{},{},{}],skinSettings:{npcTypeName:"custom",skinTypeSelected:"default"},HandDropChances:[0.085f,0.085f],factionName:"reiksgard",HandItems:[{},{}]},maxToSpawn:1,entityId:"ancientwarfarenpc:faction.civilian.female",minToSpawn:1}],groupWeight:1}],playerRange:16,respondToRedstone:0b,inventory:{Size:9,Items:[]},spawnRange:0,transparent:1b,maxDelay:10,spawnYOffset:0,xpToDrop:0,mobRange:0,debugMode:0b,maxNearbyMonsters:0}}}
:enddata
:endrule

rule:
plugin=blockTile
number=71
data:
JSON:{blockState:{blockName:"ancientwarfarestructure:chair",properties:{visible:"false",variant:"spruce",facing:"west"}},facing:"north",teData:{facing:"east",id:"ancientwarfarestructure:chair_tile",mainBlockPos:-241067186192991L}}
:enddata
:endrule

rule:
plugin=blockTile
number=72
data:
JSON:{blockState:{blockName:"ancientwarfarestructure:chair",properties:{visible:"false",variant:"spruce",facing:"west"}},facing:"north",teData:{facing:"east",id:"ancientwarfarestructure:chair_tile",mainBlockPos:-241067186192990L}}
:enddata
:endrule

rule:
plugin=blockTile
number=73
data:
JSON:{blockState:{blockName:"ancientwarfarestructure:chair",properties:{visible:"false",variant:"spruce",facing:"west"}},facing:"north",teData:{facing:"east",id:"ancientwarfarestructure:chair_tile",mainBlockPos:-241067186192989L}}
:enddata
:endrule

rule:
plugin=vanillaSkull
number=74
data:
JSON:{blockState:{blockName:"minecraft:skull",properties:{nodrop:"false",facing:"up"}},skullRotation:11,teData:{Owner:{Id:"4de3b638-7661-4808-a322-bdc6d361a5cc",Properties:{textures:[{Value:"eyJ0ZXh0dXJlcyI6eyJTS0lOIjp7InVybCI6Imh0dHA6Ly90ZXh0dXJlcy5taW5lY3JhZnQubmV0L3RleHR1cmUvMTk1NTY2OTVhOWVhMjQxMTZkNjY4N2FmMjY3NGEzNmVhZTVkZDVkYTNmYWFhOWI4Y2YxNTNmOWZlMDJiZjVjZCJ9fX0="}]}},Rot:15b,id:"minecraft:skull",SkullType:3b}}
:enddata
:endrule

rule:
plugin=vanillaSkull
number=75
data:
JSON:{blockState:{blockName:"minecraft:skull",properties:{nodrop:"false",facing:"up"}},skullRotation:8,teData:{Owner:{Id:"1fb051b1-7582-4f44-8914-8e5e65865e92",Properties:{textures:[{Value:"eyJ0ZXh0dXJlcyI6eyJTS0lOIjp7InVybCI6Imh0dHA6Ly90ZXh0dXJlcy5taW5lY3JhZnQubmV0L3RleHR1cmUvMzBhMzlkYTJjMDk5ZjcyNzc5NjkxODRjYTMyYTc0YTUzYWVhNWJjOGI2NDVmYmRmNWYzMWU1ZmJiYTc1Zjg0NCJ9fX0="}]}},Rot:12b,id:"minecraft:skull",SkullType:3b}}
:enddata
:endrule

rule:
plugin=vanillaSkull
number=76
data:
JSON:{blockState:{blockName:"minecraft:skull",properties:{nodrop:"false",facing:"up"}},skullRotation:2,teData:{Owner:{Id:"529a5bd7-3dc1-40c8-afdc-f689f53ed2a0",Properties:{textures:[{Value:"eyJ0ZXh0dXJlcyI6eyJTS0lOIjp7InVybCI6Imh0dHA6Ly90ZXh0dXJlcy5taW5lY3JhZnQubmV0L3RleHR1cmUvZTJiZGYwMTI4MTMxNmM5MjViN2E2ZmZiMzA1MjZkODAyYzEzOTg2YmQwYmRjNTAxNjZkMzE2MWRmYzk0YWI5MyJ9fX0="}]}},Rot:6b,id:"minecraft:skull",SkullType:3b}}
:enddata
:endrule

rule:
plugin=vanillaBlocks
number=77
data:
JSON:{blockState:{blockName:"minecraft:spruce_stairs",properties:{half:"top",shape:"straight",facing:"west"}}}
:enddata
:endrule

rule:
plugin=vanillaBlocks
number=78
data:
JSON:{blockState:{blockName:"minecraft:wooden_slab",properties:{half:"top",variant:"spruce"}}}
:enddata
:endrule

rule:
plugin=blockTile
number=79
data:
JSON:{blockState:{blockName:"ancientwarfarestructure:gate_proxy"},teData:{lsb:-7895142016560034607L,id:"ancientwarfarestructure:gate_proxy_tile",msb:-2487146401443855706L,render:0b}}
:enddata
:endrule

rule:
plugin=blockTile
number=80
data:
JSON:{blockState:{blockName:"ancientwarfarestructure:gate_proxy"},teData:{lsb:-7895142016560034607L,id:"ancientwarfarestructure:gate_proxy_tile",msb:-2487146401443855706L,render:0b}}
:enddata
:endrule

rule:
plugin=blockTile
number=81
data:
JSON:{blockState:{blockName:"ancientwarfarestructure:gate_proxy"},teData:{lsb:-7895142016560034607L,id:"ancientwarfarestructure:gate_proxy_tile",msb:-2487146401443855706L,render:0b}}
:enddata
:endrule

rule:
plugin=inventory
number=82
data:
JSON:{blockState:{blockName:"rustic:barrel"},lootLevel:0,teData:{ForgeCaps:{},id:"rustic:tileentitybarrel",items:{Size:27,Items:[]},Lock:""},inventoryData:{length:0,inventoryContents:[]},legacyFeatures:0b}
:enddata
:endrule

rule:
plugin=vanillaBlocks
number=83
data:
JSON:{blockState:{blockName:"minecraft:torch",properties:{facing:"west"}}}
:enddata
:endrule

rule:
plugin=vanillaBlocks
number=84
data:
JSON:{blockState:{blockName:"minecraft:torch",properties:{facing:"south"}}}
:enddata
:endrule

rule:
plugin=vanillaBlocks
number=85
data:
JSON:{blockState:{blockName:"minecraft:torch",properties:{facing:"east"}}}
:enddata
:endrule

rule:
plugin=vanillaBlocks
number=86
data:
JSON:{blockState:{blockName:"minecraft:torch",properties:{facing:"north"}}}
:enddata
:endrule

rule:
plugin=blockTile
number=87
data:
JSON:{blockState:{blockName:"ancientwarfarestructure:advanced_spawner",properties:{transparent:"true"}},teData:{id:"ancientwarfarestructure:advanced_spawner_tile",spawnerSettings:{minDelay:10,spawnDelay:1,lightSensitive:0b,spawnGroups:[{settingsList:[{remainingSpawnCount:1,hostile:1b,customTag:{ArmorDropChances:[0.085f,0.085f,0.085f,0.085f],hasCustomEquipment:0b,ArmorItems:[{},{},{},{}],skinSettings:{npcTypeName:"custom",skinTypeSelected:"default"},HandDropChances:[0.085f,0.085f],factionName:"reiksgard",HandItems:[{},{}]},maxToSpawn:1,entityId:"ancientwarfarenpc:faction.civilian.female",minToSpawn:1}],groupWeight:1}],playerRange:16,respondToRedstone:0b,inventory:{Size:9,Items:[]},spawnRange:0,transparent:1b,maxDelay:10,spawnYOffset:0,xpToDrop:0,mobRange:0,debugMode:0b,maxNearbyMonsters:0}}}
:enddata
:endrule

rule:
plugin=vanillaSkull
number=88
data:
JSON:{blockState:{blockName:"minecraft:skull",properties:{nodrop:"false",facing:"up"}},skullRotation:5,teData:{Owner:{Id:"c665ce53-a512-4eeb-96cf-7057c816a3ea",Properties:{textures:[{Value:"eyJ0ZXh0dXJlcyI6eyJTS0lOIjp7InVybCI6Imh0dHA6Ly90ZXh0dXJlcy5taW5lY3JhZnQubmV0L3RleHR1cmUvMTVhMjYzZDY1NTE2N2YwMDA4NTFhMDVhMTgzMTcyNmU3ZGI5ZTFmZjgzZDg3YzQyMzkzMmIzZTMxNzY5YWE4OSJ9fX0="}]}},Rot:9b,id:"minecraft:skull",SkullType:3b}}
:enddata
:endrule

rule:
plugin=vanillaSkull
number=89
data:
JSON:{blockState:{blockName:"minecraft:skull",properties:{nodrop:"false",facing:"up"}},skullRotation:6,teData:{Owner:{Id:"529a5bd7-3dc1-40c8-afdc-f689f53ed2a0",Properties:{textures:[{Value:"eyJ0ZXh0dXJlcyI6eyJTS0lOIjp7InVybCI6Imh0dHA6Ly90ZXh0dXJlcy5taW5lY3JhZnQubmV0L3RleHR1cmUvZTJiZGYwMTI4MTMxNmM5MjViN2E2ZmZiMzA1MjZkODAyYzEzOTg2YmQwYmRjNTAxNjZkMzE2MWRmYzk0YWI5MyJ9fX0="}]}},Rot:10b,id:"minecraft:skull",SkullType:3b}}
:enddata
:endrule

rule:
plugin=blockTile
number=90
data:
JSON:{blockState:{blockName:"ancientwarfarestructure:advanced_loot_chest",properties:{facing:"east"}},teData:{lootSettings:{lootRolls:1,splashPotion:0b,hasMessage:0b,hasLoot:1b,lootTableName:"ancientwarfare:chests/compat/rustic/rustic_village_farm_wine",spawnEntity:0b},Items:[],id:"ancientwarfarestructure:advanced_loot_chest_tile",Lock:""}}
:enddata
:endrule

rule:
plugin=blockTile
number=91
data:
JSON:{blockState:{blockName:"ancientwarfarestructure:gate_proxy"},teData:{lsb:-7895142016560034607L,id:"ancientwarfarestructure:gate_proxy_tile",msb:-2487146401443855706L,render:0b}}
:enddata
:endrule

rule:
plugin=blockTile
number=92
data:
JSON:{blockState:{blockName:"ancientwarfarestructure:gate_proxy"},teData:{lsb:-7895142016560034607L,id:"ancientwarfarestructure:gate_proxy_tile",msb:-2487146401443855706L,render:0b}}
:enddata
:endrule

rule:
plugin=vanillaBlocks
number=93
data:
JSON:{blockState:{blockName:"minecraft:spruce_stairs",properties:{half:"top",shape:"straight",facing:"north"}}}
:enddata
:endrule

rule:
plugin=blockTile
number=94
data:
JSON:{blockState:{blockName:"ancientwarfarestructure:gate_proxy"},teData:{lsb:-7895142016560034607L,id:"ancientwarfarestructure:gate_proxy_tile",msb:-2487146401443855706L,render:0b}}
:enddata
:endrule

rule:
plugin=vanillaBlocks
number=95
data:
JSON:{blockState:{blockName:"minecraft:spruce_stairs",properties:{half:"top",shape:"straight",facing:"east"}}}
:enddata
:endrule

rule:
plugin=vanillaBlocks
number=96
data:
JSON:{blockState:{blockName:"minecraft:log",properties:{variant:"oak",axis:"z"}}}
:enddata
:endrule

rule:
plugin=vanillaBlocks
number=97
data:
JSON:{blockState:{blockName:"minecraft:log",properties:{variant:"oak",axis:"x"}}}
:enddata
:endrule

rule:
plugin=vanillaBlocks
number=98
data:
JSON:{blockState:{blockName:"minecraft:wooden_slab",properties:{half:"top",variant:"oak"}}}
:enddata
:endrule

rule:
plugin=vanillaBlocks
number=99
data:
JSON:{blockState:{blockName:"minecraft:oak_stairs",properties:{half:"top",shape:"straight",facing:"east"}}}
:enddata
:endrule

rule:
plugin=vanillaBlocks
number=100
data:
JSON:{blockState:{blockName:"minecraft:spruce_stairs",properties:{half:"top",shape:"straight",facing:"south"}}}
:enddata
:endrule

rule:
plugin=vanillaBlocks
number=101
data:
JSON:{blockState:{blockName:"minecraft:spruce_stairs",properties:{half:"bottom",shape:"straight",facing:"east"}}}
:enddata
:endrule

rule:
plugin=inventory
number=102
data:
JSON:{blockState:{blockName:"rustic:barrel"},lootLevel:0,teData:{ForgeCaps:{},id:"rustic:tileentitybarrel",items:{Size:27,Items:[]},Lock:""},inventoryData:{length:0,inventoryContents:[]},legacyFeatures:0b}
:enddata
:endrule

rule:
plugin=vanillaSkull
number=103
data:
JSON:{blockState:{blockName:"minecraft:skull",properties:{nodrop:"false",facing:"up"}},skullRotation:11,teData:{Owner:{Id:"529a5bd7-3dc1-40c8-afdc-f689f53ed2a0",Properties:{textures:[{Value:"eyJ0ZXh0dXJlcyI6eyJTS0lOIjp7InVybCI6Imh0dHA6Ly90ZXh0dXJlcy5taW5lY3JhZnQubmV0L3RleHR1cmUvZTJiZGYwMTI4MTMxNmM5MjViN2E2ZmZiMzA1MjZkODAyYzEzOTg2YmQwYmRjNTAxNjZkMzE2MWRmYzk0YWI5MyJ9fX0="}]}},Rot:15b,id:"minecraft:skull",SkullType:3b}}
:enddata
:endrule

rule:
plugin=vanillaBlocks
number=104
data:
JSON:{blockState:{blockName:"minecraft:spruce_stairs",properties:{half:"bottom",shape:"straight",facing:"west"}}}
:enddata
:endrule

rule:
plugin=vanillaBlocks
number=105
data:
JSON:{blockState:{blockName:"minecraft:concrete",properties:{color:"cyan"}}}
:enddata
:endrule

rule:
plugin=vanillaBlocks
number=106
data:
JSON:{blockState:{blockName:"ancientwarfarestructure:bench",properties:{legs:"none",variant:"spruce",axis:"z"}}}
:enddata
:endrule

rule:
plugin=vanillaBlocks
number=107
data:
JSON:{blockState:{blockName:"minecraft:fence",properties:{east:"false",south:"false",north:"false",west:"false"}}}
:enddata
:endrule

rule:
plugin=blockTile
number=108
data:
JSON:{blockState:{blockName:"ancientwarfarestructure:advanced_loot_chest",properties:{facing:"north"}},teData:{lootSettings:{lootRolls:1,splashPotion:0b,hasMessage:0b,hasLoot:1b,lootTableName:"ancientwarfare:chests/castle_treasury_low_value",spawnEntity:0b},Items:[],id:"ancientwarfarestructure:advanced_loot_chest_tile",Lock:""}}
:enddata
:endrule

rule:
plugin=blockTile
number=109
data:
JSON:{blockState:{blockName:"ancientwarfarestructure:advanced_spawner",properties:{transparent:"true"}},teData:{id:"ancientwarfarestructure:advanced_spawner_tile",spawnerSettings:{minDelay:10,spawnDelay:1,lightSensitive:0b,spawnGroups:[{settingsList:[{remainingSpawnCount:1,hostile:1b,customTag:{ArmorDropChances:[0.085f,0.085f,0.085f,0.085f],hasCustomEquipment:0b,ArmorItems:[{},{},{},{}],skinSettings:{npcTypeName:"custom",skinTypeSelected:"default"},HandDropChances:[0.085f,0.085f],factionName:"reiksgard",HandItems:[{},{}]},maxToSpawn:1,entityId:"ancientwarfarenpc:faction.civilian.female",minToSpawn:1}],groupWeight:1}],playerRange:16,respondToRedstone:0b,inventory:{Size:9,Items:[]},spawnRange:0,transparent:1b,maxDelay:10,spawnYOffset:0,xpToDrop:0,mobRange:0,debugMode:0b,maxNearbyMonsters:0}}}
:enddata
:endrule

rule:
plugin=bed
number=110
data:
JSON:{blockState:{blockName:"minecraft:bed",properties:{part:"foot",facing:"east",occupied:"false"}},bedColor:14}
:enddata
:endrule

rule:
plugin=bed
number=111
data:
JSON:{blockState:{blockName:"minecraft:bed",properties:{part:"head",facing:"east",occupied:"false"}},bedColor:14}
:enddata
:endrule

rule:
plugin=blockTile
number=112
data:
JSON:{blockState:{blockName:"ancientwarfarestructure:urn"},teData:{lootSettings:{splashPotion:0b,hasMessage:0b,hasLoot:0b,spawnEntity:0b},id:"ancientwarfarestructure:urn_tile"}}
:enddata
:endrule

rule:
plugin=bed
number=113
data:
JSON:{blockState:{blockName:"minecraft:bed",properties:{part:"foot",facing:"north",occupied:"false"}},bedColor:14}
:enddata
:endrule

rule:
plugin=bed
number=114
data:
JSON:{blockState:{blockName:"minecraft:bed",properties:{part:"head",facing:"north",occupied:"false"}},bedColor:14}
:enddata
:endrule

rule:
plugin=vanillaBlocks
number=115
data:
JSON:{blockState:{blockName:"minecraft:planks",properties:{variant:"spruce"}}}
:enddata
:endrule

rule:
plugin=inventory
number=116
data:
JSON:{blockState:{blockName:"rustic:barrel"},lootLevel:0,teData:{ForgeCaps:{},id:"rustic:tileentitybarrel",items:{Size:27,Items:[]},Lock:""},inventoryData:{length:0,inventoryContents:[]},legacyFeatures:0b}
:enddata
:endrule

rule:
plugin=vanillaSkull
number=117
data:
JSON:{blockState:{blockName:"minecraft:skull",properties:{nodrop:"false",facing:"up"}},skullRotation:14,teData:{Owner:{Id:"529a5bd7-3dc1-40c8-afdc-f689f53ed2a0",Properties:{textures:[{Value:"eyJ0ZXh0dXJlcyI6eyJTS0lOIjp7InVybCI6Imh0dHA6Ly90ZXh0dXJlcy5taW5lY3JhZnQubmV0L3RleHR1cmUvZTJiZGYwMTI4MTMxNmM5MjViN2E2ZmZiMzA1MjZkODAyYzEzOTg2YmQwYmRjNTAxNjZkMzE2MWRmYzk0YWI5MyJ9fX0="}]}},Rot:2b,id:"minecraft:skull",SkullType:3b}}
:enddata
:endrule

rule:
plugin=blockTile
number=118
data:
JSON:{blockState:{blockName:"ancientwarfarestructure:advanced_loot_chest",properties:{facing:"west"}},teData:{lootSettings:{lootRolls:1,splashPotion:0b,hasMessage:0b,hasLoot:1b,lootTableName:"ancientwarfare:chests/compat/rustic/rustic_village_farm_wine",spawnEntity:0b},Items:[],id:"ancientwarfarestructure:advanced_loot_chest_tile",Lock:""}}
:enddata
:endrule

rule:
plugin=blockTile
number=119
data:
JSON:{blockState:{blockName:"ancientwarfarestructure:advanced_loot_chest",properties:{facing:"west"}},teData:{lootSettings:{lootRolls:1,splashPotion:0b,hasMessage:0b,hasLoot:1b,lootTableName:"ancientwarfare:chests/compat/rustic/rustic_village_farm_wine",spawnEntity:0b},Items:[],id:"ancientwarfarestructure:advanced_loot_chest_tile",Lock:""}}
:enddata
:endrule

rule:
plugin=vanillaSkull
number=120
data:
JSON:{blockState:{blockName:"minecraft:skull",properties:{nodrop:"false",facing:"up"}},skullRotation:8,teData:{Owner:{Id:"4de3b638-7661-4808-a322-bdc6d361a5cc",Properties:{textures:[{Value:"eyJ0ZXh0dXJlcyI6eyJTS0lOIjp7InVybCI6Imh0dHA6Ly90ZXh0dXJlcy5taW5lY3JhZnQubmV0L3RleHR1cmUvMTk1NTY2OTVhOWVhMjQxMTZkNjY4N2FmMjY3NGEzNmVhZTVkZDVkYTNmYWFhOWI4Y2YxNTNmOWZlMDJiZjVjZCJ9fX0="}]}},Rot:12b,id:"minecraft:skull",SkullType:3b}}
:enddata
:endrule

rule:
plugin=vanillaSkull
number=121
data:
JSON:{blockState:{blockName:"minecraft:skull",properties:{nodrop:"false",facing:"up"}},skullRotation:12,teData:{Owner:{Id:"1fb051b1-7582-4f44-8914-8e5e65865e92",Properties:{textures:[{Value:"eyJ0ZXh0dXJlcyI6eyJTS0lOIjp7InVybCI6Imh0dHA6Ly90ZXh0dXJlcy5taW5lY3JhZnQubmV0L3RleHR1cmUvMzBhMzlkYTJjMDk5ZjcyNzc5NjkxODRjYTMyYTc0YTUzYWVhNWJjOGI2NDVmYmRmNWYzMWU1ZmJiYTc1Zjg0NCJ9fX0="}]}},Rot:0b,id:"minecraft:skull",SkullType:3b}}
:enddata
:endrule

rule:
plugin=flag
number=122
data:
JSON:{blockState:{blockName:"ancientwarfarestructure:protection_flag",properties:{rotation:"0"}},teData:{name:"reiksgard",id:"ancientwarfarestructure:protection_flag_tile"}}
:enddata
:endrule

rule:
plugin=vanillaBlocks
number=123
data:
JSON:{blockState:{blockName:"minecraft:wooden_slab",properties:{half:"bottom",variant:"spruce"}}}
:enddata
:endrule

#### ENTITIES ####
entity:
plugin=awGate
number=0
data:
JSON:{owner:"",orientation:2b,pos1:{x:-1,y:0,z:0},pos2:{x:1,y:2,z:0},position:5223015776268L,gateType:"gate.verticalWooden"}
:enddata
:endentity

