# Ancient Warfare Structure Template File
# Auto-generated structure template file. created on: 3/14/2024 at: 22:44:57
# Lines beginning with # denote comments

header:
version=2.11
name=MerchantGuildDomusSmall1
mods=
size=22,12,39
offset=13,5,38
:endheader

#### VALIDATION ####
validation:
type=ground
structureAuthor=TheOddlySeagull
survival=false
worldGenEnabled=true
unique=false
preserveBlocks=false
preventNaturalHostileSpawns=true
selectionWeight=20
clusterValue=100
minDuplicateDistance=7000
dimensionWhiteList=true
dimensionList=0
biomeGroupList=
biomeWhiteList=true
biomeList=minecraft:savanna_rock,minecraft:savanna
leveling=6
fill=6
border=10
blockSwap=false
territoryName=guild
biomeReplacement=minecraft:
minGenerationHeight=0
maxGenerationHeight=255
:endvalidation

#### LAYERS ####
layer: 0
1,1,1,1,1,1,1,1,1,1,1,1,1,1,1,1,1,1,1,1,1,1
1,1,1,1,1,1,1,1,1,1,1,1,1,1,1,1,1,1,1,1,1,1
1,1,1,1,1,1,1,1,1,1,1,1,1,1,1,1,1,1,1,1,1,1
1,1,1,1,1,1,1,1,1,1,1,1,1,1,1,1,1,1,1,1,1,1
1,1,1,1,1,1,1,1,1,1,1,1,1,1,1,1,1,1,1,1,1,1
1,1,1,1,1,1,1,1,1,1,1,1,1,1,1,1,1,1,1,1,1,1
1,1,1,1,1,1,1,1,1,1,1,1,1,1,1,1,1,1,1,1,1,1
1,1,1,1,1,1,1,1,1,1,1,1,1,1,1,1,1,1,1,1,1,1
1,1,1,1,1,1,1,1,1,1,1,1,1,1,1,1,1,1,1,1,1,1
1,1,1,1,1,1,1,1,1,1,1,1,1,1,1,1,1,1,1,1,1,1
1,1,1,1,1,1,1,1,1,1,1,1,1,1,1,1,1,1,1,1,1,1
1,1,1,1,1,1,1,1,1,1,1,1,1,1,1,1,1,1,1,1,1,1
1,1,1,1,1,1,1,1,1,1,1,1,1,1,1,1,1,1,1,1,1,1
1,1,1,1,1,1,1,1,1,1,1,1,1,1,1,1,1,1,1,1,1,1
1,1,1,1,1,1,1,1,1,1,1,1,1,1,1,1,1,1,1,1,1,1
1,1,1,1,1,1,1,1,1,1,1,1,1,1,1,1,1,1,1,1,1,1
1,1,1,1,1,1,1,1,1,1,1,1,1,1,1,1,1,1,1,1,1,1
1,1,1,1,1,1,1,1,1,1,1,1,1,1,1,1,1,1,1,1,1,1
1,1,1,1,1,1,1,1,1,1,1,1,1,1,1,1,1,1,1,1,1,1
1,1,1,1,1,1,1,1,1,1,1,1,1,1,1,1,1,1,1,1,1,1
1,1,1,1,1,1,1,1,1,1,1,1,1,1,1,1,1,1,1,1,1,1
1,1,1,1,1,1,1,1,1,1,1,1,1,1,1,1,1,1,1,1,1,1
1,1,1,1,1,1,1,1,1,1,1,1,1,1,1,1,1,1,1,1,1,1
1,1,1,1,1,1,1,1,1,1,1,1,1,1,1,1,1,1,1,1,1,1
1,1,1,1,1,1,1,1,1,1,1,1,1,1,1,1,1,1,1,1,1,1
1,1,1,1,1,1,1,1,1,1,1,1,1,1,1,1,1,1,1,1,1,1
1,1,1,1,1,1,1,1,1,1,1,1,1,1,1,1,1,1,1,1,1,1
1,1,1,1,1,1,1,1,1,1,1,1,1,1,1,1,1,1,1,1,1,1
1,1,1,1,1,1,1,1,1,1,1,1,1,1,1,1,1,1,1,1,1,1
1,1,1,1,1,1,1,1,1,1,1,1,1,1,1,1,1,1,1,1,1,1
1,1,1,1,1,1,1,1,1,1,1,1,1,1,1,1,1,1,1,1,1,1
1,1,1,1,1,1,1,1,1,1,1,1,1,1,1,1,1,1,1,1,1,1
1,1,1,1,1,1,1,1,1,1,1,1,1,1,1,1,1,1,1,1,1,1
1,1,1,1,1,1,1,1,1,1,1,1,1,1,1,1,1,1,1,1,1,1
1,1,1,1,1,1,1,1,1,1,1,1,1,1,1,1,1,1,1,1,1,1
1,1,1,1,1,1,1,1,1,1,1,1,1,1,1,1,1,1,1,1,1,1
1,1,1,1,1,1,1,1,1,1,1,1,1,1,1,1,1,1,1,1,1,1
1,1,1,1,1,1,1,1,1,1,1,1,1,1,1,1,1,1,1,1,1,1
1,1,1,1,1,1,1,1,1,1,1,1,1,1,1,1,1,1,1,1,1,1
:endlayer
layer: 1
1,1,1,1,1,1,1,1,1,1,1,1,1,1,1,1,1,1,1,1,1,1
1,1,1,1,1,1,1,1,1,1,1,1,1,1,1,1,1,1,1,1,1,1
1,1,1,1,1,1,1,1,1,1,1,1,1,1,1,1,1,1,1,1,1,1
1,1,1,1,1,1,1,1,1,1,1,1,1,1,1,1,1,1,1,1,1,1
1,1,1,1,1,1,1,1,1,1,1,1,1,1,1,1,1,1,1,1,1,1
1,1,1,1,1,1,1,1,1,1,1,1,1,1,1,1,1,1,1,1,1,1
1,1,1,1,1,1,1,1,1,1,1,1,1,1,1,1,1,1,1,1,1,1
1,1,1,1,1,1,1,1,1,1,1,1,1,1,1,1,1,1,1,1,1,1
1,1,1,1,1,1,1,1,1,1,1,1,1,1,1,1,1,1,1,1,1,1
1,1,1,1,1,1,1,1,1,1,1,1,1,1,1,1,1,1,1,1,1,1
1,1,1,1,1,1,1,1,1,1,1,1,1,1,1,1,1,1,1,1,1,1
1,1,1,1,1,1,1,1,1,1,1,1,1,1,1,1,1,1,1,1,1,1
1,1,1,1,1,1,1,1,1,1,1,1,1,1,1,1,1,1,1,1,1,1
1,1,1,1,1,1,1,1,1,1,1,1,1,1,1,1,1,1,1,1,1,1
1,1,1,1,1,1,1,1,1,1,1,1,1,1,1,1,1,1,1,1,1,1
1,1,1,1,1,1,1,1,1,1,1,1,1,1,1,1,1,1,1,1,1,1
1,1,1,1,1,1,1,1,1,1,1,1,1,1,1,1,1,1,1,1,1,1
1,1,1,1,1,1,1,1,1,1,1,1,1,1,1,1,1,1,1,1,1,1
1,1,1,1,1,1,1,1,1,1,1,1,1,1,1,1,1,1,1,1,1,1
1,1,1,1,1,1,1,1,1,1,1,1,1,1,1,1,1,1,1,1,1,1
1,1,1,1,1,1,1,1,1,1,1,1,1,1,1,1,1,1,1,1,1,1
1,1,1,1,1,1,1,1,1,1,1,1,1,1,1,1,1,1,1,1,1,1
1,1,1,1,1,1,1,1,1,1,1,1,1,1,1,1,1,1,1,1,1,1
1,1,1,1,1,1,1,1,1,1,1,1,1,1,1,1,1,1,1,1,1,1
1,1,1,1,1,1,1,1,1,1,1,1,1,1,1,1,1,1,1,1,1,1
1,1,1,1,1,1,1,1,1,1,1,1,1,1,1,1,1,1,1,1,1,1
1,1,1,1,1,1,1,1,1,1,1,1,1,1,1,1,1,1,1,1,1,1
1,1,1,1,1,1,1,1,1,1,1,1,1,1,1,1,1,1,1,1,1,1
1,1,1,1,1,1,1,1,1,1,1,1,1,1,1,1,1,1,1,1,1,1
1,1,1,1,1,1,1,1,1,1,1,1,1,1,1,1,1,1,1,1,1,1
1,1,1,1,1,1,1,1,1,1,1,1,1,1,1,1,1,1,1,1,1,1
1,1,1,1,1,1,1,1,1,1,1,1,1,1,1,1,1,1,1,1,1,1
1,1,1,1,1,1,1,1,1,1,1,1,1,1,1,1,1,1,1,1,1,1
1,1,1,1,1,1,1,1,1,1,1,1,1,1,1,1,1,1,1,1,1,1
1,1,1,1,1,1,1,1,1,1,1,1,1,1,1,1,1,1,1,1,1,1
1,1,1,1,1,1,1,1,1,1,1,1,1,1,1,1,1,1,1,1,1,1
1,1,1,1,1,1,1,1,1,1,1,1,1,1,1,1,1,1,1,1,1,1
1,1,1,1,1,1,1,1,1,1,1,1,1,1,1,1,1,1,1,1,1,1
1,1,1,1,1,1,1,1,1,1,1,1,1,1,1,1,1,1,1,1,1,1
:endlayer
layer: 2
1,1,1,1,1,1,1,1,1,1,1,1,1,1,1,1,1,1,1,1,1,1
1,1,1,1,1,1,1,1,1,1,1,1,1,1,1,1,1,1,1,1,1,1
1,1,1,1,1,1,1,1,1,1,1,1,1,1,1,1,1,1,1,1,1,1
1,1,1,1,1,1,1,1,1,1,1,1,1,1,1,1,1,1,1,1,1,1
1,1,1,1,1,1,1,1,1,1,1,1,1,1,1,1,1,1,1,1,1,1
1,1,1,1,1,1,1,1,1,1,1,1,1,1,1,1,1,1,1,1,1,1
1,1,1,1,1,1,1,1,1,1,1,1,1,1,1,1,1,1,1,1,1,1
1,1,1,1,1,1,1,1,1,1,1,1,1,1,1,1,1,1,1,1,1,1
1,1,1,1,1,1,1,1,1,1,1,1,1,1,1,1,1,1,1,1,1,1
1,1,1,1,1,1,1,1,1,1,1,1,1,1,1,1,1,1,1,1,1,1
1,1,1,1,1,1,1,1,1,1,1,1,1,1,1,1,1,1,1,1,1,1
1,1,1,1,1,1,1,1,1,1,1,1,1,1,1,1,1,1,1,1,1,1
1,1,1,1,1,1,1,1,1,1,1,1,1,1,1,1,1,1,1,1,1,1
1,1,1,1,1,1,1,1,1,1,1,1,1,1,1,1,1,1,1,1,1,1
1,1,1,1,1,1,1,1,1,1,1,1,1,1,1,1,1,1,1,1,1,1
1,1,1,1,1,1,1,1,1,1,1,1,1,1,1,1,1,1,1,1,1,1
1,1,1,1,1,1,1,1,1,1,1,1,1,1,1,1,1,1,1,1,1,1
1,1,1,1,1,1,1,1,1,1,1,1,1,1,1,1,1,1,1,1,1,1
1,1,1,1,1,1,1,1,1,1,1,1,1,1,1,1,1,1,1,1,1,1
1,1,1,1,1,1,1,1,1,1,1,1,1,1,1,1,1,1,1,1,1,1
1,1,1,1,1,1,1,1,1,1,1,1,1,1,1,1,1,1,1,1,1,1
1,1,1,1,1,1,1,1,1,1,1,1,1,1,1,1,1,1,1,1,1,1
1,1,1,1,1,1,1,1,1,1,1,1,1,1,1,1,1,1,1,1,1,1
1,1,1,1,1,1,1,1,1,1,1,1,1,1,1,1,1,1,1,1,1,1
1,1,1,1,1,1,1,1,1,1,1,1,1,1,1,1,1,1,1,1,1,1
1,1,1,1,1,1,1,1,1,1,1,1,1,1,1,1,1,1,1,1,1,1
1,1,1,1,1,1,1,1,1,1,1,1,1,1,1,1,1,1,1,1,1,1
1,1,1,1,1,1,1,1,1,1,1,1,1,1,1,1,1,1,1,1,1,1
1,1,1,1,1,1,1,1,1,1,1,1,1,1,1,1,1,1,1,1,1,1
1,1,1,1,1,1,1,1,1,1,1,1,1,1,1,1,1,1,1,1,1,1
1,1,1,1,1,1,1,1,1,1,1,1,1,1,1,1,1,1,1,1,1,1
1,1,1,1,1,1,1,1,1,1,1,1,1,1,1,1,1,1,1,1,1,1
1,1,1,1,1,1,1,1,1,1,1,1,1,1,1,1,1,1,1,1,1,1
1,1,1,1,1,1,1,1,1,1,1,1,1,1,1,1,1,1,1,1,1,1
1,1,1,1,1,1,1,1,1,1,1,1,1,1,1,1,1,1,1,1,1,1
1,1,1,1,1,1,1,1,1,1,1,1,1,1,1,1,1,1,1,1,1,1
1,1,1,1,1,1,1,1,1,1,1,1,1,1,1,1,1,1,1,1,1,1
1,1,1,1,1,1,1,1,1,1,1,1,1,1,1,1,1,1,1,1,1,1
1,1,1,1,1,1,1,1,1,1,1,1,1,1,1,1,1,1,1,1,1,1
:endlayer
layer: 3
2,2,2,2,2,2,2,2,2,2,2,2,2,2,2,2,2,2,2,2,2,2
2,2,2,2,2,2,2,2,2,2,2,2,2,2,2,2,2,2,2,2,2,2
2,2,3,3,3,3,3,3,3,3,3,3,3,3,3,3,3,3,3,3,2,2
2,2,3,3,3,3,3,3,3,3,3,3,3,3,3,3,3,3,3,3,2,2
2,2,3,3,3,3,3,3,3,3,3,3,3,3,3,3,3,3,3,3,2,2
2,2,3,3,3,3,3,3,3,3,3,3,3,3,3,3,3,3,3,3,2,2
2,2,3,3,3,3,3,3,3,3,3,3,3,3,3,3,3,3,3,3,2,2
2,2,3,3,3,3,3,3,3,3,3,3,3,3,3,3,3,3,3,3,2,2
2,2,3,3,3,3,3,3,3,3,3,3,3,3,3,3,3,3,3,3,2,2
2,2,3,3,3,3,3,3,3,3,3,3,3,3,3,3,3,3,3,3,2,2
2,2,3,3,3,3,3,3,3,3,3,3,3,3,3,3,3,3,3,3,2,2
2,2,3,3,3,3,3,3,3,3,3,3,3,3,3,3,3,3,3,3,2,2
2,2,3,3,3,3,3,3,3,3,3,3,3,3,3,3,3,3,3,3,2,2
2,2,3,3,3,3,3,3,3,3,3,3,3,3,3,3,3,3,3,3,2,2
2,2,3,3,3,3,3,3,3,3,3,3,3,3,3,3,3,3,3,3,2,2
2,2,3,3,3,3,3,3,3,3,3,3,3,3,3,3,3,3,3,3,2,2
2,2,3,3,3,3,3,3,3,3,3,3,3,3,3,3,3,3,3,3,2,2
2,2,3,3,3,3,3,3,3,3,3,3,3,3,3,3,3,3,3,3,2,2
2,2,3,3,3,3,3,3,3,3,3,3,3,3,3,3,3,3,3,3,2,2
2,2,3,3,3,3,3,3,3,3,3,3,3,3,3,3,3,3,3,3,2,2
2,2,3,3,3,3,3,3,3,3,3,3,3,3,3,3,3,3,3,3,2,2
2,2,3,3,3,3,3,3,3,3,3,3,3,3,3,3,3,3,3,3,2,2
2,2,3,3,3,3,3,3,3,3,4,4,3,3,3,3,3,3,3,3,2,2
2,2,3,3,3,3,3,3,3,3,5,5,3,3,3,3,3,3,3,3,2,2
2,2,3,3,3,3,3,3,3,3,4,4,3,3,3,3,3,3,3,3,2,2
2,2,3,3,3,3,3,3,3,3,4,4,3,3,3,3,3,3,3,3,2,2
2,2,3,3,3,3,3,3,3,3,5,5,3,3,3,3,3,3,3,3,2,2
2,2,3,3,3,3,3,3,3,3,4,4,3,3,3,3,3,3,3,3,2,2
2,2,3,3,3,3,3,3,3,3,3,3,3,3,3,3,3,3,3,3,2,2
2,2,3,3,3,3,3,3,3,3,3,3,3,3,3,3,3,3,3,3,2,2
2,2,3,3,3,3,3,3,3,3,3,3,3,3,3,3,3,3,3,3,2,2
2,2,3,3,3,3,3,3,3,3,3,3,3,3,3,3,3,3,3,3,2,2
2,2,3,3,3,3,3,3,3,3,3,3,3,3,3,3,3,3,3,3,2,2
2,2,3,3,3,3,3,3,3,3,3,3,3,3,3,3,3,3,3,3,2,2
2,2,3,3,3,3,3,3,3,3,3,3,3,3,3,3,3,3,3,3,2,2
2,2,3,3,3,3,3,3,3,3,3,3,3,3,3,3,3,3,3,3,2,2
2,2,3,3,3,3,3,3,3,3,3,3,3,3,3,3,3,3,3,3,2,2
2,2,2,2,2,2,2,2,2,2,2,2,2,2,2,2,2,2,2,2,2,2
2,2,2,2,2,2,2,2,2,2,2,2,2,2,2,2,2,2,2,2,2,2
:endlayer
layer: 4
6,6,6,6,6,6,6,6,6,6,6,6,6,6,6,6,6,6,6,6,6,6
6,6,6,6,6,6,6,6,6,6,6,6,6,6,6,6,6,6,6,6,6,6
6,6,7,7,7,7,7,7,7,7,7,7,7,7,7,7,7,7,7,7,6,6
6,6,7,56,57,56,57,56,52,53,52,53,52,53,52,53,52,53,52,7,6,6
6,6,7,54,55,54,55,54,50,51,50,51,50,51,50,51,50,51,50,7,6,6
6,6,7,56,57,56,57,56,52,53,6,6,6,6,39,39,28,53,52,7,6,6
6,6,7,54,55,54,55,54,50,51,6,6,6,6,30,29,28,51,50,7,6,6
6,6,7,7,7,7,7,7,52,53,6,6,6,6,30,29,28,53,52,7,6,6
6,6,7,21,15,21,15,21,50,51,6,6,6,6,30,27,27,51,50,7,6,6
6,6,7,20,14,20,14,20,52,53,52,53,52,53,52,53,52,53,52,7,6,6
6,6,7,21,15,21,15,21,50,51,50,51,50,51,50,51,50,51,50,7,6,6
6,6,7,7,7,7,7,7,7,7,7,7,7,10,9,7,7,7,7,7,6,6
6,6,7,49,49,49,49,7,45,44,45,44,7,13,12,7,8,8,8,7,6,6
6,6,7,48,48,48,48,7,47,46,47,46,7,10,9,7,8,8,8,7,6,6
6,6,7,49,49,49,49,7,45,44,45,44,7,13,12,7,8,8,8,7,6,6
6,6,7,48,48,48,48,7,47,46,47,46,7,10,9,7,8,8,8,7,6,6
6,6,7,7,7,7,7,7,45,44,45,44,7,13,12,7,7,7,7,7,6,6
6,6,7,43,42,43,42,7,47,46,47,46,7,10,9,43,42,43,42,7,6,6
6,6,7,41,40,41,40,7,45,44,45,44,7,13,12,41,40,41,40,7,6,6
6,6,7,43,42,43,42,23,22,23,22,23,22,23,22,43,42,43,42,7,6,6
6,6,7,41,40,41,40,17,16,17,16,17,16,17,16,41,40,41,40,7,6,6
6,6,7,7,7,7,7,23,22,26,39,39,26,23,22,7,7,7,7,7,6,6
6,6,7,37,38,37,7,17,16,30,29,29,28,17,16,7,35,36,35,7,6,6
6,6,7,33,34,33,7,23,22,26,29,29,26,23,22,7,31,32,31,7,6,6
6,6,7,37,38,37,7,17,16,30,29,29,28,17,16,7,35,36,35,7,6,6
6,6,7,33,34,33,7,23,22,30,29,29,28,23,22,7,31,32,31,7,6,6
6,6,7,7,7,7,7,17,16,26,29,29,26,17,16,7,7,7,7,7,6,6
6,6,7,24,25,24,7,23,22,30,29,29,28,23,22,7,20,21,20,7,6,6
6,6,7,18,19,18,7,17,16,26,27,27,26,17,16,7,14,15,14,7,6,6
6,6,7,24,25,24,7,23,22,23,22,23,22,23,22,7,20,21,20,7,6,6
6,6,7,18,19,18,7,17,16,17,16,17,16,17,16,7,14,15,14,7,6,6
6,6,7,7,7,7,7,7,7,7,7,7,7,10,9,7,7,7,7,7,6,6
6,6,7,3,3,3,7,11,11,11,11,11,7,13,12,7,8,8,8,7,6,6
6,6,7,3,3,3,7,11,11,11,11,11,7,10,9,7,8,8,8,7,6,6
6,6,7,3,3,3,7,11,11,11,11,11,7,13,12,7,8,8,8,7,6,6
6,6,7,3,3,3,7,11,11,11,11,11,7,10,9,7,8,8,8,7,6,6
6,6,7,7,7,7,7,7,7,7,7,7,7,7,7,7,7,7,7,7,6,6
6,6,6,6,6,6,6,6,6,6,6,6,6,6,6,6,6,6,6,6,6,6
6,6,6,6,6,6,6,6,6,6,6,6,6,6,6,6,6,6,6,6,6,6
:endlayer
layer: 5
0,0,0,0,0,0,0,0,0,0,0,0,0,0,0,0,0,101,0,0,0,0
0,0,0,0,0,0,0,0,0,0,0,0,0,0,0,0,0,0,0,0,0,0
0,0,60,60,60,60,60,60,60,60,60,60,60,60,60,60,60,100,60,60,0,0
0,0,60,99,64,64,64,99,0,0,0,0,0,0,0,0,0,0,83,60,0,0
0,0,60,67,0,0,0,0,0,0,0,0,0,0,0,0,0,0,0,60,0,0
0,0,60,67,0,0,0,0,0,0,75,0,0,75,0,0,75,0,0,60,0,0
0,0,60,99,64,64,64,99,0,0,83,0,0,83,0,0,0,0,0,60,0,0
0,0,60,60,60,60,60,60,0,0,83,0,0,83,0,0,0,0,0,60,0,0
0,0,60,83,64,64,64,83,0,0,75,0,0,75,0,0,75,0,0,60,0,0
0,0,60,67,0,84,84,0,0,0,0,0,0,0,0,0,0,0,0,60,0,0
0,0,60,83,0,0,0,0,0,0,0,0,0,0,0,0,0,0,83,60,0,0
0,0,60,60,60,98,98,60,60,98,98,60,60,0,0,60,60,98,60,60,0,0
0,0,60,0,0,0,0,60,0,0,0,0,60,0,0,60,97,0,96,60,0,0
0,0,60,95,84,84,94,60,0,0,0,85,60,0,0,60,93,0,8,60,0,0
0,0,60,92,84,84,91,60,0,0,0,90,60,0,0,60,0,0,8,60,0,0
0,0,60,0,0,0,0,60,0,89,88,87,60,0,0,60,0,0,86,60,0,0
0,0,60,60,60,60,60,60,0,84,84,85,60,0,0,60,61,60,60,60,0,0
0,0,60,83,64,64,83,60,0,0,0,0,60,0,0,0,0,0,83,60,0,0
0,0,60,67,0,84,0,60,0,0,0,0,60,0,0,0,84,0,67,60,0,0
0,0,60,67,0,0,0,0,0,0,0,0,0,0,0,0,0,0,67,60,0,0
0,0,60,83,64,64,0,0,0,0,0,0,0,0,0,83,64,64,83,60,0,0
0,0,60,60,60,60,60,0,0,75,0,0,75,0,0,60,60,60,60,60,0,0
0,0,60,82,0,0,60,0,0,0,0,0,0,0,0,60,0,0,0,60,0,0
0,0,60,81,80,0,72,0,0,75,0,0,75,0,0,71,0,79,78,60,0,0
0,0,60,81,80,0,72,0,0,0,0,0,0,0,0,71,0,79,78,60,0,0
0,0,60,0,0,0,60,0,0,0,0,0,0,0,0,60,0,0,77,60,0,0
0,0,60,60,60,60,60,0,0,75,0,0,75,0,0,60,60,60,60,60,0,0
0,0,60,76,0,0,60,0,0,0,0,0,0,0,0,60,0,0,0,60,0,0
0,0,60,74,73,0,72,0,0,75,0,0,75,0,0,71,0,70,69,60,0,0
0,0,60,74,73,0,72,0,0,0,0,0,0,0,0,71,0,70,69,60,0,0
0,0,60,0,0,0,60,0,0,0,0,0,0,0,0,60,0,0,68,60,0,0
0,0,60,60,60,60,60,60,60,60,60,60,60,0,0,60,60,60,60,60,0,0
0,0,60,64,0,0,60,64,64,0,67,65,60,0,0,60,0,0,66,60,0,0
0,0,60,0,0,0,60,65,65,0,0,0,60,0,0,60,0,0,0,60,0,0
0,0,60,65,65,0,60,64,64,0,0,0,60,0,0,60,63,62,62,60,0,0
0,0,60,0,0,0,60,0,0,0,0,0,60,0,0,60,0,0,0,60,0,0
0,0,60,0,0,0,60,0,0,60,0,0,60,61,61,60,0,0,0,60,0,0
0,0,0,0,0,0,0,0,0,0,0,0,59,0,0,58,0,0,0,0,0,0
0,0,0,0,0,0,0,0,0,0,0,0,0,0,0,0,0,0,0,0,0,0
:endlayer
layer: 6
0,0,0,0,0,0,0,0,0,0,0,0,0,0,0,0,0,0,0,0,0,0
0,0,0,0,0,0,0,0,0,0,0,0,0,0,0,0,0,0,0,0,0,0
0,0,103,103,103,120,103,103,103,103,103,120,120,103,120,120,103,105,103,103,0,0
0,0,103,102,0,0,0,102,0,0,102,0,0,102,0,0,102,0,83,103,0,0
0,0,110,0,0,0,0,0,0,0,0,0,0,0,0,0,0,0,0,103,0,0
0,0,110,0,0,0,0,0,0,0,75,0,0,75,0,0,75,0,107,103,0,0
0,0,103,115,0,0,0,115,0,0,0,0,0,0,0,0,0,0,0,109,0,0
0,0,103,106,106,106,106,106,0,0,0,0,0,0,0,0,0,0,0,109,0,0
0,0,103,83,0,0,0,83,0,0,75,0,0,75,0,0,75,0,107,103,0,0
0,0,103,108,0,0,0,0,0,0,0,0,0,0,0,0,0,0,0,103,0,0
0,0,103,83,0,0,0,0,0,0,0,0,0,0,0,0,115,0,83,103,0,0
0,0,103,106,106,104,105,106,106,104,105,106,106,0,0,106,106,105,106,103,0,0
0,0,103,102,0,0,0,7,0,0,0,0,7,0,0,103,112,0,112,103,0,0
0,0,110,119,0,0,118,7,0,0,0,112,7,0,0,103,112,0,112,103,0,0
0,0,110,117,0,0,116,7,0,0,0,112,7,0,0,103,0,0,112,103,0,0
0,0,103,115,0,0,115,7,0,0,114,112,7,0,0,103,0,0,112,109,0,0
0,0,103,7,7,7,7,7,0,113,0,112,7,0,0,103,105,103,103,103,0,0
0,0,103,83,0,0,83,7,0,0,0,0,7,0,0,0,0,0,83,103,0,0
0,0,110,0,0,111,0,106,0,0,0,0,106,0,0,0,111,0,0,109,0,0
0,0,110,0,0,0,0,0,0,0,0,0,0,0,0,0,0,0,0,109,0,0
0,0,103,83,0,0,0,0,0,0,0,0,0,0,0,83,0,0,83,103,0,0
0,0,103,103,103,103,106,0,0,75,0,0,75,0,0,106,103,103,103,103,0,0
0,0,103,108,0,0,106,0,0,0,0,0,0,0,0,106,0,0,107,103,0,0
0,0,103,0,0,0,104,0,0,75,0,0,75,0,0,105,0,0,0,103,0,0
0,0,103,0,0,0,105,0,0,0,0,0,0,0,0,104,0,0,0,103,0,0
0,0,103,108,0,0,106,0,0,0,0,0,0,0,0,106,0,0,107,103,0,0
0,0,103,103,103,103,106,0,0,75,0,0,75,0,0,106,103,103,103,103,0,0
0,0,103,108,0,0,106,0,0,0,0,0,0,0,0,106,0,0,107,103,0,0
0,0,103,0,0,0,104,0,0,75,0,0,75,0,0,105,0,0,0,103,0,0
0,0,110,0,0,0,105,0,0,0,0,0,0,0,0,104,0,0,0,109,0,0
0,0,103,108,0,0,106,0,0,0,0,0,0,0,0,106,0,0,107,103,0,0
0,0,103,103,103,103,106,106,106,106,106,106,106,0,0,106,103,103,103,103,0,0
0,0,103,0,0,0,103,0,0,0,0,0,103,0,0,103,0,0,0,103,0,0
0,0,103,0,0,0,103,0,0,0,0,0,103,0,0,103,0,0,0,103,0,0
0,0,103,0,0,0,103,0,0,0,0,0,103,0,0,103,0,0,0,103,0,0
0,0,103,0,0,0,103,0,0,0,0,0,103,0,0,103,0,0,0,103,0,0
0,0,103,0,0,0,103,0,0,103,0,0,103,105,104,103,0,0,0,103,0,0
0,0,102,0,0,0,102,0,0,102,0,0,102,0,0,102,0,0,0,102,0,0
0,0,0,0,0,0,0,0,0,0,0,0,0,0,0,0,0,0,0,0,0,0
:endlayer
layer: 7
0,0,0,0,0,0,0,0,0,0,0,0,0,0,0,0,0,0,0,0,0,0
0,121,126,121,126,121,126,121,126,121,126,121,126,121,126,121,126,121,126,121,121,0
0,124,103,103,103,103,103,103,103,103,103,103,103,103,103,103,103,103,103,103,123,0
0,121,103,125,125,125,125,125,121,121,121,121,121,121,121,121,121,121,121,103,121,0
0,124,103,125,0,0,0,125,121,0,0,0,0,0,0,0,0,0,121,103,123,0
0,121,103,125,0,0,0,125,121,0,75,0,0,75,0,0,75,0,121,103,121,0
0,124,103,125,125,125,125,125,121,0,0,0,0,0,0,0,0,0,121,103,123,0
0,121,103,106,106,106,106,106,121,0,0,0,0,0,0,0,0,0,121,103,121,0
0,124,103,125,125,125,125,125,121,0,75,0,0,75,0,0,75,0,121,103,123,0
0,121,103,125,0,0,0,125,121,0,0,0,0,0,0,0,0,0,121,103,121,0
0,124,103,125,125,125,125,125,121,121,121,121,121,121,121,121,121,121,121,103,123,0
0,121,103,106,106,106,106,106,106,106,106,106,106,106,106,106,106,106,106,103,121,0
0,124,103,125,125,125,125,7,0,0,0,0,7,121,121,103,121,121,121,103,123,0
0,121,103,125,0,0,125,7,108,0,0,107,7,0,0,103,121,0,121,103,121,0
0,124,103,125,0,0,125,7,0,0,0,0,7,0,0,103,121,0,121,103,123,0
0,121,103,125,125,125,125,7,0,0,0,0,7,108,107,103,121,121,121,103,121,0
0,124,103,7,7,7,7,7,0,0,0,0,7,0,0,103,103,103,103,103,123,0
0,121,103,125,125,125,125,7,108,0,0,107,7,0,0,125,125,125,125,103,121,0
0,124,103,125,0,0,125,106,0,0,0,0,106,121,121,125,0,0,125,103,123,0
0,121,103,125,0,0,125,121,121,121,121,121,121,121,121,125,0,0,125,103,121,0
0,124,103,125,125,125,125,121,0,0,0,0,0,0,121,125,125,125,125,103,123,0
0,121,103,103,103,103,106,121,0,75,0,0,75,0,121,106,103,103,103,103,121,0
0,124,103,125,125,125,106,121,0,0,0,0,0,0,121,106,125,125,125,103,123,0
0,121,103,125,0,125,106,121,0,75,0,0,75,0,121,106,125,0,125,103,121,0
0,124,103,125,0,125,106,121,0,0,0,0,0,0,121,106,125,0,125,103,123,0
0,121,103,125,125,125,106,121,0,0,0,0,0,0,121,106,125,125,125,103,121,0
0,124,103,103,103,103,106,121,0,75,0,0,75,0,121,106,103,103,103,103,123,0
0,121,103,121,121,121,106,121,0,0,0,0,0,0,121,106,125,125,125,103,121,0
0,124,103,121,0,121,106,121,0,75,0,0,75,0,121,106,125,0,125,103,123,0
0,121,103,121,0,121,106,121,0,0,0,0,0,0,121,106,125,0,125,103,121,0
0,124,103,121,121,121,106,121,121,121,121,121,121,121,121,106,125,125,125,103,123,0
0,121,103,103,103,103,106,106,106,106,106,106,106,121,121,106,103,103,103,103,121,0
0,124,103,0,0,0,103,0,0,0,0,0,103,0,0,103,0,0,0,103,123,0
0,121,103,0,0,0,103,0,0,0,0,0,103,0,0,103,0,0,0,103,121,0
0,124,103,0,0,0,103,0,0,0,0,0,103,0,0,103,0,0,0,103,123,0
0,121,103,0,0,0,103,0,0,0,0,0,103,121,121,103,0,0,0,103,121,0
0,124,103,103,103,103,103,103,103,103,103,103,103,103,103,103,103,103,103,103,123,0
0,121,122,121,122,121,122,121,122,121,122,121,122,121,122,121,122,121,122,121,121,0
0,0,0,0,0,0,0,0,0,0,0,0,0,0,0,0,0,0,0,0,0,0
:endlayer
layer: 8
0,0,0,0,0,0,0,0,0,0,0,0,0,0,0,0,0,0,0,0,0,0
0,0,0,0,0,0,0,0,0,0,0,0,0,0,0,0,0,0,0,0,0,0
0,0,127,127,127,127,127,127,127,127,127,127,127,127,127,127,127,127,127,127,0,0
0,0,127,128,128,128,128,128,128,128,128,128,128,128,128,128,128,128,128,127,0,0
0,0,127,128,136,136,136,7,128,128,128,128,128,128,128,128,128,128,128,127,0,0
0,0,127,128,136,136,136,7,128,128,127,127,127,127,127,127,127,128,128,127,0,0
0,0,127,128,136,136,136,7,128,128,127,0,0,0,0,0,127,128,128,127,0,0
0,0,127,128,7,7,7,7,128,128,127,0,0,0,0,0,127,128,128,127,0,0
0,0,127,128,130,130,130,130,128,128,127,127,127,127,127,127,127,128,128,127,0,0
0,0,127,128,130,130,130,130,128,128,128,128,128,128,128,128,128,128,128,127,0,0
0,0,127,128,130,130,130,130,128,128,128,128,128,128,128,128,128,128,128,127,0,0
0,0,127,128,7,7,7,7,7,7,7,7,7,7,7,7,7,7,128,127,0,0
0,0,127,128,136,136,136,7,135,135,135,135,7,134,134,7,129,129,128,127,0,0
0,0,127,128,136,136,136,7,135,135,135,135,7,134,134,7,129,129,128,127,0,0
0,0,127,128,136,136,136,7,135,135,135,135,7,134,134,7,129,129,128,127,0,0
0,0,127,128,136,136,136,7,135,135,135,135,7,134,134,7,129,129,128,127,0,0
0,0,127,128,7,7,7,7,135,135,135,135,7,134,134,7,7,7,128,127,0,0
0,0,127,128,134,134,134,7,135,135,135,135,7,134,134,134,134,134,128,127,0,0
0,0,127,128,134,134,134,7,135,135,135,135,7,134,134,134,134,134,128,127,0,0
0,0,127,128,134,134,134,128,128,128,128,128,128,128,128,134,134,134,128,127,0,0
0,0,127,128,134,134,134,128,128,128,128,128,128,128,128,134,134,134,128,127,0,0
0,0,127,128,7,7,7,128,128,127,127,127,127,128,128,7,7,7,128,127,0,0
0,0,127,128,133,133,7,128,128,127,0,0,127,128,128,7,132,132,128,127,0,0
0,0,127,128,133,133,7,128,128,127,0,0,127,128,128,7,132,132,128,127,0,0
0,0,127,128,133,133,7,128,128,127,0,0,127,128,128,7,132,132,128,127,0,0
0,0,127,128,133,133,7,128,128,127,0,0,127,128,128,7,132,132,128,127,0,0
0,0,127,128,7,7,7,128,128,127,0,0,127,128,128,7,7,7,128,127,0,0
0,0,127,128,131,131,7,128,128,127,0,0,127,128,128,7,130,130,128,127,0,0
0,0,127,128,131,131,7,128,128,127,127,127,127,128,128,7,130,130,128,127,0,0
0,0,127,128,131,131,7,128,128,128,128,128,128,128,128,7,130,130,128,127,0,0
0,0,127,128,131,131,7,128,128,128,128,128,128,128,128,7,130,130,128,127,0,0
0,0,127,128,7,7,7,7,7,7,7,7,7,129,129,7,7,7,128,127,0,0
0,0,127,128,128,128,7,128,128,128,128,128,7,129,129,7,128,128,128,127,0,0
0,0,127,128,128,128,7,128,128,128,128,128,7,129,129,7,128,128,128,127,0,0
0,0,127,128,128,128,7,128,128,128,128,128,7,129,129,7,128,128,128,127,0,0
0,0,127,128,128,128,128,128,128,128,128,128,128,128,128,128,128,128,128,127,0,0
0,0,127,127,127,127,127,127,127,127,127,127,127,127,127,127,127,127,127,127,0,0
0,0,0,0,0,0,0,0,0,0,0,0,0,0,0,0,0,0,0,0,0,0
0,0,0,0,0,0,0,0,0,0,0,0,0,0,0,0,0,0,0,0,0,0
:endlayer
layer: 9
0,0,0,0,0,0,0,0,0,0,0,0,0,0,0,0,0,0,0,0,0,0
0,0,0,0,0,0,0,0,0,0,0,0,0,0,0,0,0,0,0,0,0,0
0,0,0,0,0,0,0,0,0,0,0,0,0,0,0,0,0,0,0,0,0,0
0,0,0,0,0,0,0,0,0,0,0,0,0,0,0,0,0,0,0,0,0,0
0,0,0,0,127,127,127,127,127,0,0,0,0,0,0,0,0,0,0,0,0,0
0,0,0,0,127,128,128,128,127,0,0,0,0,0,0,0,0,0,0,0,0,0
0,0,0,0,127,128,128,128,127,0,0,0,0,0,0,0,0,0,0,0,0,0
0,0,0,0,127,128,7,128,127,0,0,0,0,0,0,0,0,0,0,0,0,0
0,0,0,0,127,128,128,128,127,0,0,0,0,0,0,0,0,0,0,0,0,0
0,0,0,0,127,128,128,128,127,0,0,0,0,0,0,0,0,0,0,0,0,0
0,0,0,0,127,128,128,128,127,127,127,127,127,127,127,127,127,127,0,0,0,0
0,0,0,0,127,128,128,128,128,128,128,128,128,128,128,128,128,127,0,0,0,0
0,0,0,0,127,128,128,7,128,128,128,128,7,128,128,7,128,127,0,0,0,0
0,0,0,0,127,128,128,7,128,128,128,128,7,128,128,7,128,127,0,0,0,0
0,0,0,0,127,128,128,7,128,128,128,128,7,128,128,7,128,127,0,0,0,0
0,0,0,0,127,128,128,7,128,128,128,128,7,128,128,7,128,127,0,0,0,0
0,0,0,0,127,128,7,7,128,128,128,128,7,128,128,7,128,127,0,0,0,0
0,0,0,0,127,128,128,7,128,128,128,128,7,128,128,128,128,127,0,0,0,0
0,0,0,0,127,128,128,128,128,128,128,128,128,128,128,128,128,127,0,0,0,0
0,0,0,0,127,128,128,127,127,127,127,127,127,127,127,128,128,127,0,0,0,0
0,0,0,0,127,128,128,127,0,0,0,0,0,0,127,128,128,127,0,0,0,0
0,0,0,0,127,128,128,127,0,0,0,0,0,0,127,128,128,127,0,0,0,0
0,0,0,0,127,128,128,127,0,0,0,0,0,0,127,128,128,127,0,0,0,0
0,0,0,0,127,128,128,127,0,0,0,0,0,0,127,128,128,127,0,0,0,0
0,0,0,0,127,128,128,127,0,0,0,0,0,0,127,128,128,127,0,0,0,0
0,0,0,0,127,128,128,127,0,0,0,0,0,0,127,128,128,127,0,0,0,0
0,0,0,0,127,128,128,127,0,0,0,0,0,0,127,128,128,127,0,0,0,0
0,0,0,0,127,128,128,127,0,0,0,0,0,0,127,128,128,127,0,0,0,0
0,0,0,0,127,128,128,127,0,0,0,0,0,0,127,128,128,127,0,0,0,0
0,0,0,0,127,128,128,127,0,0,0,0,0,0,127,128,128,127,0,0,0,0
0,0,0,0,127,128,128,127,127,127,127,127,127,127,127,128,128,127,0,0,0,0
0,0,0,0,127,128,128,128,128,128,128,128,128,128,128,128,128,127,0,0,0,0
0,0,0,0,127,128,7,128,128,128,128,128,7,128,128,7,128,127,0,0,0,0
0,0,0,0,127,128,128,128,128,128,128,128,128,128,128,128,128,127,0,0,0,0
0,0,0,0,127,127,127,127,127,127,127,127,127,127,127,127,127,127,0,0,0,0
0,0,0,0,0,0,0,0,0,0,0,0,0,0,0,0,0,0,0,0,0,0
0,0,0,0,0,0,0,0,0,0,0,0,0,0,0,0,0,0,0,0,0,0
0,0,0,0,0,0,0,0,0,0,0,0,0,0,0,0,0,0,0,0,0,0
0,0,0,0,0,0,0,0,0,0,0,0,0,0,0,0,0,0,0,0,0,0
:endlayer
layer: 10
0,0,0,0,0,0,0,0,0,0,0,0,0,0,0,0,0,0,0,0,0,0
0,0,0,0,0,0,0,0,0,0,0,0,0,0,0,0,0,0,0,0,0,0
0,0,0,0,0,0,0,0,0,0,0,0,0,0,0,0,0,0,0,0,0,0
0,0,0,0,0,0,0,0,0,0,0,0,0,0,0,0,0,0,0,0,0,0
0,0,0,0,0,0,0,0,0,0,0,0,0,0,0,0,0,0,0,0,0,0
0,0,0,0,0,0,0,0,0,0,0,0,0,0,0,0,0,0,0,0,0,0
0,0,0,0,0,0,127,0,0,0,0,0,0,0,0,0,0,0,0,0,0,0
0,0,0,0,0,0,127,0,0,0,0,0,0,0,0,0,0,0,0,0,0,0
0,0,0,0,0,0,127,0,0,0,0,0,0,0,0,0,0,0,0,0,0,0
0,0,0,0,0,0,127,0,0,0,0,0,0,0,0,0,0,0,0,0,0,0
0,0,0,0,0,0,127,0,0,0,0,0,0,0,0,0,0,0,0,0,0,0
0,0,0,0,0,0,127,0,0,0,0,0,0,0,0,0,0,0,0,0,0,0
0,0,0,0,0,0,127,127,127,127,127,127,127,127,127,127,0,0,0,0,0,0
0,0,0,0,0,0,127,128,128,128,128,128,128,128,128,127,0,0,0,0,0,0
0,0,0,0,0,0,127,128,128,128,128,128,128,128,128,127,0,0,0,0,0,0
0,0,0,0,0,0,127,128,128,128,128,128,128,128,128,127,0,0,0,0,0,0
0,0,0,0,0,0,127,128,128,128,128,128,128,128,128,127,0,0,0,0,0,0
0,0,0,0,0,0,127,127,127,127,127,127,127,127,127,127,0,0,0,0,0,0
0,0,0,0,0,0,0,0,0,0,0,0,0,0,0,0,0,0,0,0,0,0
0,0,0,0,0,0,0,0,0,0,0,0,0,0,0,0,0,0,0,0,0,0
0,0,0,0,0,0,0,0,0,0,0,0,0,0,0,0,0,0,0,0,0,0
0,0,0,0,0,0,0,0,0,0,0,0,0,0,0,0,0,0,0,0,0,0
0,0,0,0,0,0,0,0,0,0,0,0,0,0,0,0,0,0,0,0,0,0
0,0,0,0,0,0,0,0,0,0,0,0,0,0,0,0,0,0,0,0,0,0
0,0,0,0,0,0,0,0,0,0,0,0,0,0,0,0,0,0,0,0,0,0
0,0,0,0,0,0,0,0,0,0,0,0,0,0,0,0,0,0,0,0,0,0
0,0,0,0,0,0,0,0,0,0,0,0,0,0,0,0,0,0,0,0,0,0
0,0,0,0,0,0,0,0,0,0,0,0,0,0,0,0,0,0,0,0,0,0
0,0,0,0,0,0,0,0,0,0,0,0,0,0,0,0,0,0,0,0,0,0
0,0,0,0,0,0,0,0,0,0,0,0,0,0,0,0,0,0,0,0,0,0
0,0,0,0,0,0,0,0,0,0,0,0,0,0,0,0,0,0,0,0,0,0
0,0,0,0,0,0,0,0,0,0,0,0,0,0,0,0,0,0,0,0,0,0
0,0,0,0,0,0,127,127,127,127,127,127,127,127,127,127,0,0,0,0,0,0
0,0,0,0,0,0,0,0,0,0,0,0,0,0,0,0,0,0,0,0,0,0
0,0,0,0,0,0,0,0,0,0,0,0,0,0,0,0,0,0,0,0,0,0
0,0,0,0,0,0,0,0,0,0,0,0,0,0,0,0,0,0,0,0,0,0
0,0,0,0,0,0,0,0,0,0,0,0,0,0,0,0,0,0,0,0,0,0
0,0,0,0,0,0,0,0,0,0,0,0,0,0,0,0,0,0,0,0,0,0
0,0,0,0,0,0,0,0,0,0,0,0,0,0,0,0,0,0,0,0,0,0
:endlayer
layer: 11
0,0,0,0,0,0,0,0,0,0,0,0,0,0,0,0,0,0,0,0,0,0
0,0,0,0,0,0,0,0,0,0,0,0,0,0,0,0,0,0,0,0,0,0
0,0,0,0,0,0,0,0,0,0,0,0,0,0,0,0,0,0,0,0,0,0
0,0,0,0,0,0,0,0,0,0,0,0,0,0,0,0,0,0,0,0,0,0
0,0,0,0,0,0,0,0,0,0,0,0,0,0,0,0,0,0,0,0,0,0
0,0,0,0,0,0,0,0,0,0,0,0,0,0,0,0,0,0,0,0,0,0
0,0,0,0,0,0,0,0,0,0,0,0,0,0,0,0,0,0,0,0,0,0
0,0,0,0,0,0,0,0,0,0,0,0,0,0,0,0,0,0,0,0,0,0
0,0,0,0,0,0,0,0,0,0,0,0,0,0,0,0,0,0,0,0,0,0
0,0,0,0,0,0,0,0,0,0,0,0,0,0,0,0,0,0,0,0,0,0
0,0,0,0,0,0,0,0,0,0,0,0,0,0,0,0,0,0,0,0,0,0
0,0,0,0,0,0,0,0,0,0,0,0,0,0,0,0,0,0,0,0,0,0
0,0,0,0,0,0,0,0,0,0,0,0,0,0,0,0,0,0,0,0,0,0
0,0,0,0,0,0,0,0,0,0,0,0,0,0,0,0,0,0,0,0,0,0
0,0,0,0,0,0,0,0,127,127,127,127,127,127,0,0,0,0,0,0,0,0
0,0,0,0,0,0,0,0,127,127,127,127,127,127,0,0,0,0,0,0,0,0
0,0,0,0,0,0,0,0,0,0,0,0,0,0,0,0,0,0,0,0,0,0
0,0,0,0,0,0,0,0,0,0,0,0,0,0,0,0,0,0,0,0,0,0
0,0,0,0,0,0,0,0,0,0,0,0,0,0,0,0,0,0,0,0,0,0
0,0,0,0,0,0,0,0,0,0,0,0,0,0,0,0,0,0,0,0,0,0
0,0,0,0,0,0,0,0,0,0,0,0,0,0,0,0,0,0,0,0,0,0
0,0,0,0,0,0,0,0,0,0,0,0,0,0,0,0,0,0,0,0,0,0
0,0,0,0,0,0,0,0,0,0,0,0,0,0,0,0,0,0,0,0,0,0
0,0,0,0,0,0,0,0,0,0,0,0,0,0,0,0,0,0,0,0,0,0
0,0,0,0,0,0,0,0,0,0,0,0,0,0,0,0,0,0,0,0,0,0
0,0,0,0,0,0,0,0,0,0,0,0,0,0,0,0,0,0,0,0,0,0
0,0,0,0,0,0,0,0,0,0,0,0,0,0,0,0,0,0,0,0,0,0
0,0,0,0,0,0,0,0,0,0,0,0,0,0,0,0,0,0,0,0,0,0
0,0,0,0,0,0,0,0,0,0,0,0,0,0,0,0,0,0,0,0,0,0
0,0,0,0,0,0,0,0,0,0,0,0,0,0,0,0,0,0,0,0,0,0
0,0,0,0,0,0,0,0,0,0,0,0,0,0,0,0,0,0,0,0,0,0
0,0,0,0,0,0,0,0,0,0,0,0,0,0,0,0,0,0,0,0,0,0
0,0,0,0,0,0,0,0,0,0,0,0,0,0,0,0,0,0,0,0,0,0
0,0,0,0,0,0,0,0,0,0,0,0,0,0,0,0,0,0,0,0,0,0
0,0,0,0,0,0,0,0,0,0,0,0,0,0,0,0,0,0,0,0,0,0
0,0,0,0,0,0,0,0,0,0,0,0,0,0,0,0,0,0,0,0,0,0
0,0,0,0,0,0,0,0,0,0,0,0,0,0,0,0,0,0,0,0,0,0
0,0,0,0,0,0,0,0,0,0,0,0,0,0,0,0,0,0,0,0,0,0
0,0,0,0,0,0,0,0,0,0,0,0,0,0,0,0,0,0,0,0,0,0
:endlayer

#### RULES ####
rule:
plugin=vanillaBlocks
number=1
data:
JSON:{blockState:{blockName:"minecraft:stone",properties:{variant:"stone"}}}
:enddata
:endrule

rule:
plugin=vanillaBlocks
number=2
data:
JSON:{blockState:{blockName:"minecraft:dirt",properties:{variant:"dirt",snowy:"false"}}}
:enddata
:endrule

rule:
plugin=vanillaBlocks
number=3
data:
JSON:{blockState:{blockName:"minecraft:cobblestone"}}
:enddata
:endrule

rule:
plugin=vanillaBlocks
number=4
data:
JSON:{blockState:{blockName:"minecraft:quartz_block",properties:{variant:"default"}}}
:enddata
:endrule

rule:
plugin=vanillaBlocks
number=5
data:
JSON:{blockState:{blockName:"minecraft:quartz_block",properties:{variant:"lines_x"}}}
:enddata
:endrule

rule:
plugin=vanillaBlocks
number=6
data:
JSON:{blockState:{blockName:"minecraft:grass",properties:{snowy:"false"}}}
:enddata
:endrule

rule:
plugin=vanillaBlocks
number=7
data:
JSON:{blockState:{blockName:"minecraft:stained_hardened_clay",properties:{color:"white"}}}
:enddata
:endrule

rule:
plugin=vanillaBlocks
number=8
data:
JSON:{blockState:{blockName:"minecraft:stone",properties:{variant:"smooth_andesite"}}}
:enddata
:endrule

rule:
plugin=vanillaBlocks
number=9
data:
JSON:{blockState:{blockName:"minecraft:gray_glazed_terracotta",properties:{facing:"west"}}}
:enddata
:endrule

rule:
plugin=vanillaBlocks
number=10
data:
JSON:{blockState:{blockName:"minecraft:gray_glazed_terracotta",properties:{facing:"south"}}}
:enddata
:endrule

rule:
plugin=vanillaBlocks
number=11
data:
JSON:{blockState:{blockName:"minecraft:stone",properties:{variant:"andesite"}}}
:enddata
:endrule

rule:
plugin=vanillaBlocks
number=12
data:
JSON:{blockState:{blockName:"minecraft:gray_glazed_terracotta",properties:{facing:"north"}}}
:enddata
:endrule

rule:
plugin=vanillaBlocks
number=13
data:
JSON:{blockState:{blockName:"minecraft:gray_glazed_terracotta",properties:{facing:"east"}}}
:enddata
:endrule

rule:
plugin=vanillaBlocks
number=14
data:
JSON:{blockState:{blockName:"minecraft:yellow_glazed_terracotta",properties:{facing:"north"}}}
:enddata
:endrule

rule:
plugin=vanillaBlocks
number=15
data:
JSON:{blockState:{blockName:"minecraft:yellow_glazed_terracotta",properties:{facing:"east"}}}
:enddata
:endrule

rule:
plugin=vanillaBlocks
number=16
data:
JSON:{blockState:{blockName:"minecraft:blue_glazed_terracotta",properties:{facing:"north"}}}
:enddata
:endrule

rule:
plugin=vanillaBlocks
number=17
data:
JSON:{blockState:{blockName:"minecraft:blue_glazed_terracotta",properties:{facing:"east"}}}
:enddata
:endrule

rule:
plugin=vanillaBlocks
number=18
data:
JSON:{blockState:{blockName:"minecraft:white_glazed_terracotta",properties:{facing:"north"}}}
:enddata
:endrule

rule:
plugin=vanillaBlocks
number=19
data:
JSON:{blockState:{blockName:"minecraft:white_glazed_terracotta",properties:{facing:"east"}}}
:enddata
:endrule

rule:
plugin=vanillaBlocks
number=20
data:
JSON:{blockState:{blockName:"minecraft:yellow_glazed_terracotta",properties:{facing:"west"}}}
:enddata
:endrule

rule:
plugin=vanillaBlocks
number=21
data:
JSON:{blockState:{blockName:"minecraft:yellow_glazed_terracotta",properties:{facing:"south"}}}
:enddata
:endrule

rule:
plugin=vanillaBlocks
number=22
data:
JSON:{blockState:{blockName:"minecraft:blue_glazed_terracotta",properties:{facing:"west"}}}
:enddata
:endrule

rule:
plugin=vanillaBlocks
number=23
data:
JSON:{blockState:{blockName:"minecraft:blue_glazed_terracotta",properties:{facing:"south"}}}
:enddata
:endrule

rule:
plugin=vanillaBlocks
number=24
data:
JSON:{blockState:{blockName:"minecraft:white_glazed_terracotta",properties:{facing:"west"}}}
:enddata
:endrule

rule:
plugin=vanillaBlocks
number=25
data:
JSON:{blockState:{blockName:"minecraft:white_glazed_terracotta",properties:{facing:"south"}}}
:enddata
:endrule

rule:
plugin=vanillaBlocks
number=26
data:
JSON:{blockState:{blockName:"minecraft:quartz_block",properties:{variant:"lines_y"}}}
:enddata
:endrule

rule:
plugin=vanillaBlocks
number=27
data:
JSON:{blockState:{blockName:"minecraft:quartz_stairs",properties:{half:"bottom",shape:"straight",facing:"north"}}}
:enddata
:endrule

rule:
plugin=vanillaBlocks
number=28
data:
JSON:{blockState:{blockName:"minecraft:quartz_stairs",properties:{half:"bottom",shape:"straight",facing:"west"}}}
:enddata
:endrule

rule:
plugin=fluid
number=29
data:
JSON:{blockState:{blockName:"minecraft:water",properties:{level:"0"}}}
:enddata
:endrule

rule:
plugin=vanillaBlocks
number=30
data:
JSON:{blockState:{blockName:"minecraft:quartz_stairs",properties:{half:"bottom",shape:"straight",facing:"east"}}}
:enddata
:endrule

rule:
plugin=vanillaBlocks
number=31
data:
JSON:{blockState:{blockName:"minecraft:orange_glazed_terracotta",properties:{facing:"west"}}}
:enddata
:endrule

rule:
plugin=vanillaBlocks
number=32
data:
JSON:{blockState:{blockName:"minecraft:orange_glazed_terracotta",properties:{facing:"south"}}}
:enddata
:endrule

rule:
plugin=vanillaBlocks
number=33
data:
JSON:{blockState:{blockName:"minecraft:silver_glazed_terracotta",properties:{facing:"north"}}}
:enddata
:endrule

rule:
plugin=vanillaBlocks
number=34
data:
JSON:{blockState:{blockName:"minecraft:silver_glazed_terracotta",properties:{facing:"west"}}}
:enddata
:endrule

rule:
plugin=vanillaBlocks
number=35
data:
JSON:{blockState:{blockName:"minecraft:orange_glazed_terracotta",properties:{facing:"north"}}}
:enddata
:endrule

rule:
plugin=vanillaBlocks
number=36
data:
JSON:{blockState:{blockName:"minecraft:orange_glazed_terracotta",properties:{facing:"east"}}}
:enddata
:endrule

rule:
plugin=vanillaBlocks
number=37
data:
JSON:{blockState:{blockName:"minecraft:silver_glazed_terracotta",properties:{facing:"east"}}}
:enddata
:endrule

rule:
plugin=vanillaBlocks
number=38
data:
JSON:{blockState:{blockName:"minecraft:silver_glazed_terracotta",properties:{facing:"south"}}}
:enddata
:endrule

rule:
plugin=vanillaBlocks
number=39
data:
JSON:{blockState:{blockName:"minecraft:quartz_stairs",properties:{half:"bottom",shape:"straight",facing:"south"}}}
:enddata
:endrule

rule:
plugin=vanillaBlocks
number=40
data:
JSON:{blockState:{blockName:"minecraft:brown_glazed_terracotta",properties:{facing:"north"}}}
:enddata
:endrule

rule:
plugin=vanillaBlocks
number=41
data:
JSON:{blockState:{blockName:"minecraft:brown_glazed_terracotta",properties:{facing:"east"}}}
:enddata
:endrule

rule:
plugin=vanillaBlocks
number=42
data:
JSON:{blockState:{blockName:"minecraft:brown_glazed_terracotta",properties:{facing:"west"}}}
:enddata
:endrule

rule:
plugin=vanillaBlocks
number=43
data:
JSON:{blockState:{blockName:"minecraft:brown_glazed_terracotta",properties:{facing:"south"}}}
:enddata
:endrule

rule:
plugin=vanillaBlocks
number=44
data:
JSON:{blockState:{blockName:"minecraft:green_glazed_terracotta",properties:{facing:"west"}}}
:enddata
:endrule

rule:
plugin=vanillaBlocks
number=45
data:
JSON:{blockState:{blockName:"minecraft:green_glazed_terracotta",properties:{facing:"south"}}}
:enddata
:endrule

rule:
plugin=vanillaBlocks
number=46
data:
JSON:{blockState:{blockName:"minecraft:green_glazed_terracotta",properties:{facing:"north"}}}
:enddata
:endrule

rule:
plugin=vanillaBlocks
number=47
data:
JSON:{blockState:{blockName:"minecraft:green_glazed_terracotta",properties:{facing:"east"}}}
:enddata
:endrule

rule:
plugin=vanillaBlocks
number=48
data:
JSON:{blockState:{blockName:"minecraft:red_glazed_terracotta",properties:{facing:"north"}}}
:enddata
:endrule

rule:
plugin=vanillaBlocks
number=49
data:
JSON:{blockState:{blockName:"minecraft:red_glazed_terracotta",properties:{facing:"south"}}}
:enddata
:endrule

rule:
plugin=vanillaBlocks
number=50
data:
JSON:{blockState:{blockName:"minecraft:lime_glazed_terracotta",properties:{facing:"north"}}}
:enddata
:endrule

rule:
plugin=vanillaBlocks
number=51
data:
JSON:{blockState:{blockName:"minecraft:lime_glazed_terracotta",properties:{facing:"east"}}}
:enddata
:endrule

rule:
plugin=vanillaBlocks
number=52
data:
JSON:{blockState:{blockName:"minecraft:lime_glazed_terracotta",properties:{facing:"west"}}}
:enddata
:endrule

rule:
plugin=vanillaBlocks
number=53
data:
JSON:{blockState:{blockName:"minecraft:lime_glazed_terracotta",properties:{facing:"south"}}}
:enddata
:endrule

rule:
plugin=vanillaBlocks
number=54
data:
JSON:{blockState:{blockName:"minecraft:black_glazed_terracotta",properties:{facing:"south"}}}
:enddata
:endrule

rule:
plugin=vanillaBlocks
number=55
data:
JSON:{blockState:{blockName:"minecraft:black_glazed_terracotta",properties:{facing:"west"}}}
:enddata
:endrule

rule:
plugin=vanillaBlocks
number=56
data:
JSON:{blockState:{blockName:"minecraft:black_glazed_terracotta",properties:{facing:"east"}}}
:enddata
:endrule

rule:
plugin=vanillaBlocks
number=57
data:
JSON:{blockState:{blockName:"minecraft:black_glazed_terracotta",properties:{facing:"north"}}}
:enddata
:endrule

rule:
plugin=blockTile
number=58
data:
JSON:{blockState:{blockName:"ancientwarfarestructure:advanced_spawner",properties:{transparent:"true"}},teData:{id:"ancientwarfarestructure:advanced_spawner_tile",spawnerSettings:{minDelay:10,spawnDelay:7,lightSensitive:0b,spawnGroups:[{settingsList:[{remainingSpawnCount:1,hostile:1b,customTag:{ArmorDropChances:[0.085f,0.085f,0.085f,0.085f],hasCustomEquipment:0b,ArmorItems:[{},{},{},{}],skinSettings:{npcTypeName:"custom",skinTypeSelected:"default"},HandDropChances:[0.085f,0.085f],factionName:"guild",HandItems:[{id:"ancientwarfarenpc:iron_spear",Count:1b,Damage:0s},{id:"ancientwarfarenpc:iron_shield",Count:1b,Damage:0s}]},maxToSpawn:1,entityId:"ancientwarfarenpc:faction.soldier",minToSpawn:1}],groupWeight:1}],playerRange:16,respondToRedstone:0b,inventory:{Size:9,Items:[]},spawnRange:0,transparent:1b,maxDelay:10,spawnYOffset:0,xpToDrop:0,mobRange:0,debugMode:0b,maxNearbyMonsters:0}}}
:enddata
:endrule

rule:
plugin=blockTile
number=59
data:
JSON:{blockState:{blockName:"ancientwarfarestructure:advanced_spawner",properties:{transparent:"true"}},teData:{id:"ancientwarfarestructure:advanced_spawner_tile",spawnerSettings:{minDelay:10,spawnDelay:6,lightSensitive:0b,spawnGroups:[{settingsList:[{remainingSpawnCount:1,hostile:1b,customTag:{ArmorDropChances:[0.085f,0.085f,0.085f,0.085f],hasCustomEquipment:0b,ArmorItems:[{},{},{},{}],skinSettings:{npcTypeName:"custom",skinTypeSelected:"default"},HandDropChances:[0.085f,0.085f],factionName:"guild",HandItems:[{id:"ancientwarfarenpc:iron_spear",Count:1b,Damage:0s},{id:"ancientwarfarenpc:iron_shield",Count:1b,Damage:0s}]},maxToSpawn:1,entityId:"ancientwarfarenpc:faction.soldier",minToSpawn:1}],groupWeight:1}],playerRange:16,respondToRedstone:0b,inventory:{Size:9,Items:[]},spawnRange:0,transparent:1b,maxDelay:10,spawnYOffset:0,xpToDrop:0,mobRange:0,debugMode:0b,maxNearbyMonsters:0}}}
:enddata
:endrule

rule:
plugin=vanillaBlocks
number=60
data:
JSON:{blockState:{blockName:"minecraft:stained_hardened_clay",properties:{color:"pink"}}}
:enddata
:endrule

rule:
plugin=doors
number=61
data:
JSON:{blockState:{blockName:"minecraft:spruce_door",properties:{hinge:"left",half:"lower",powered:"false",facing:"north",open:"false"}}}
:enddata
:endrule

rule:
plugin=vanillaBlocks
number=62
data:
JSON:{blockState:{blockName:"minecraft:planks",properties:{variant:"spruce"}}}
:enddata
:endrule

rule:
plugin=vanillaBlocks
number=63
data:
JSON:{blockState:{blockName:"minecraft:trapdoor",properties:{half:"top",facing:"west",open:"false"}}}
:enddata
:endrule

rule:
plugin=vanillaBlocks
number=64
data:
JSON:{blockState:{blockName:"ancientwarfarestructure:bench",properties:{legs:"none",variant:"spruce",axis:"x"}}}
:enddata
:endrule

rule:
plugin=vanillaBlocks
number=65
data:
JSON:{blockState:{blockName:"ancientwarfarestructure:table",properties:{leg_southwest:"true",leg_northwest:"true",variant:"spruce",leg_northeast:"true",leg_southeast:"true"}}}
:enddata
:endrule

rule:
plugin=inventory
number=66
data:
JSON:{blockState:{blockName:"minecraft:chest",properties:{facing:"south"}},lootLevel:0,teData:{Items:[],id:"minecraft:chest",Lock:""},inventoryData:{length:0,inventoryContents:[]},legacyFeatures:1b}
:enddata
:endrule

rule:
plugin=vanillaBlocks
number=67
data:
JSON:{blockState:{blockName:"ancientwarfarestructure:bench",properties:{legs:"none",variant:"spruce",axis:"z"}}}
:enddata
:endrule

rule:
plugin=inventory
number=68
data:
JSON:{blockState:{blockName:"minecraft:chest",properties:{facing:"west"}},lootLevel:0,teData:{Items:[],id:"minecraft:chest",Lock:""},inventoryData:{length:0,inventoryContents:[]},legacyFeatures:1b}
:enddata
:endrule

rule:
plugin=bed
number=69
data:
JSON:{blockState:{blockName:"minecraft:bed",properties:{part:"head",facing:"east",occupied:"false"}},bedColor:4}
:enddata
:endrule

rule:
plugin=bed
number=70
data:
JSON:{blockState:{blockName:"minecraft:bed",properties:{part:"foot",facing:"east",occupied:"false"}},bedColor:4}
:enddata
:endrule

rule:
plugin=doors
number=71
data:
JSON:{blockState:{blockName:"minecraft:spruce_door",properties:{hinge:"left",half:"lower",powered:"false",facing:"east",open:"false"}}}
:enddata
:endrule

rule:
plugin=doors
number=72
data:
JSON:{blockState:{blockName:"minecraft:spruce_door",properties:{hinge:"left",half:"lower",powered:"false",facing:"west",open:"false"}}}
:enddata
:endrule

rule:
plugin=bed
number=73
data:
JSON:{blockState:{blockName:"minecraft:bed",properties:{part:"foot",facing:"west",occupied:"false"}},bedColor:0}
:enddata
:endrule

rule:
plugin=bed
number=74
data:
JSON:{blockState:{blockName:"minecraft:bed",properties:{part:"head",facing:"west",occupied:"false"}},bedColor:0}
:enddata
:endrule

rule:
plugin=vanillaBlocks
number=75
data:
JSON:{blockState:{blockName:"minecraft:birch_fence",properties:{east:"false",south:"false",north:"false",west:"false"}}}
:enddata
:endrule

rule:
plugin=inventory
number=76
data:
JSON:{blockState:{blockName:"minecraft:chest",properties:{facing:"east"}},lootLevel:0,teData:{Items:[],id:"minecraft:chest",Lock:""},inventoryData:{length:0,inventoryContents:[]},legacyFeatures:1b}
:enddata
:endrule

rule:
plugin=inventory
number=77
data:
JSON:{blockState:{blockName:"minecraft:chest",properties:{facing:"west"}},lootLevel:0,teData:{Items:[],id:"minecraft:chest",Lock:""},inventoryData:{length:0,inventoryContents:[]},legacyFeatures:1b}
:enddata
:endrule

rule:
plugin=bed
number=78
data:
JSON:{blockState:{blockName:"minecraft:bed",properties:{part:"head",facing:"east",occupied:"false"}},bedColor:1}
:enddata
:endrule

rule:
plugin=bed
number=79
data:
JSON:{blockState:{blockName:"minecraft:bed",properties:{part:"foot",facing:"east",occupied:"false"}},bedColor:1}
:enddata
:endrule

rule:
plugin=bed
number=80
data:
JSON:{blockState:{blockName:"minecraft:bed",properties:{part:"foot",facing:"west",occupied:"false"}},bedColor:8}
:enddata
:endrule

rule:
plugin=bed
number=81
data:
JSON:{blockState:{blockName:"minecraft:bed",properties:{part:"head",facing:"west",occupied:"false"}},bedColor:8}
:enddata
:endrule

rule:
plugin=inventory
number=82
data:
JSON:{blockState:{blockName:"minecraft:chest",properties:{facing:"east"}},lootLevel:0,teData:{Items:[],id:"minecraft:chest",Lock:""},inventoryData:{length:0,inventoryContents:[]},legacyFeatures:1b}
:enddata
:endrule

rule:
plugin=vanillaBlocks
number=83
data:
JSON:{blockState:{blockName:"minecraft:leaves",properties:{check_decay:"false",decayable:"false",variant:"oak"}}}
:enddata
:endrule

rule:
plugin=vanillaBlocks
number=84
data:
JSON:{blockState:{blockName:"ancientwarfarestructure:table",properties:{leg_southwest:"true",leg_northwest:"true",variant:"oak",leg_northeast:"true",leg_southeast:"true"}}}
:enddata
:endrule

rule:
plugin=vanillaBlocks
number=85
data:
JSON:{blockState:{blockName:"minecraft:fence",properties:{east:"false",south:"false",north:"false",west:"false"}}}
:enddata
:endrule

rule:
plugin=inventory
number=86
data:
JSON:{blockState:{blockName:"minecraft:furnace",properties:{facing:"west"}},lootLevel:0,teData:{CookTime:0,BurnTime:0,Items:[],id:"minecraft:furnace",CookTimeTotal:0,Lock:""},inventoryData:{length:0,inventoryContents:[]},legacyFeatures:0b}
:enddata
:endrule

rule:
plugin=inventory
number=87
data:
JSON:{blockState:{blockName:"minecraft:chest",properties:{facing:"west"}},lootLevel:0,teData:{Items:[],id:"minecraft:chest",Lock:""},inventoryData:{length:0,inventoryContents:[]},legacyFeatures:1b}
:enddata
:endrule

rule:
plugin=blockTile
number=88
data:
JSON:{blockState:{blockName:"ancientwarfarestructure:chair",properties:{visible:"true",variant:"oak",facing:"south"}},facing:"south",teData:{facing:"north",id:"ancientwarfarestructure:chair_tile"}}
:enddata
:endrule

rule:
plugin=blockTile
number=89
data:
JSON:{blockState:{blockName:"ancientwarfarestructure:advanced_spawner",properties:{transparent:"true"}},teData:{id:"ancientwarfarestructure:advanced_spawner_tile",spawnerSettings:{minDelay:10,spawnDelay:8,lightSensitive:0b,spawnGroups:[{settingsList:[{remainingSpawnCount:1,hostile:1b,customTag:{ArmorDropChances:[0.085f,0.085f,0.085f,0.085f],hasCustomEquipment:0b,ArmorItems:[{},{},{},{}],skinSettings:{npcTypeName:"custom",skinTypeSelected:"default"},HandDropChances:[0.085f,0.085f],factionName:"guild",HandItems:[{id:"ancientwarfarenpc:iron_halberd",Count:1b,Damage:0s},{}]},maxToSpawn:1,entityId:"ancientwarfarenpc:faction.leader",minToSpawn:1}],groupWeight:1}],playerRange:16,respondToRedstone:0b,inventory:{Size:9,Items:[]},spawnRange:0,transparent:1b,maxDelay:10,spawnYOffset:0,xpToDrop:0,mobRange:0,debugMode:0b,maxNearbyMonsters:0}}}
:enddata
:endrule

rule:
plugin=inventory
number=90
data:
JSON:{blockState:{blockName:"minecraft:chest",properties:{facing:"west"}},lootLevel:0,teData:{Items:[],id:"minecraft:chest",Lock:""},inventoryData:{length:0,inventoryContents:[]},legacyFeatures:1b}
:enddata
:endrule

rule:
plugin=blockTile
number=91
data:
JSON:{blockState:{blockName:"ancientwarfarestructure:chair",properties:{visible:"true",variant:"oak",facing:"south"}},facing:"west",teData:{facing:"east",id:"ancientwarfarestructure:chair_tile"}}
:enddata
:endrule

rule:
plugin=blockTile
number=92
data:
JSON:{blockState:{blockName:"ancientwarfarestructure:chair",properties:{visible:"true",variant:"oak",facing:"south"}},facing:"east",teData:{facing:"west",id:"ancientwarfarestructure:chair_tile"}}
:enddata
:endrule

rule:
plugin=inventory
number=93
data:
JSON:{blockState:{blockName:"minecraft:chest",properties:{facing:"east"}},lootLevel:0,teData:{Items:[],id:"minecraft:chest",Lock:""},inventoryData:{length:0,inventoryContents:[]},legacyFeatures:1b}
:enddata
:endrule

rule:
plugin=blockTile
number=94
data:
JSON:{blockState:{blockName:"ancientwarfarestructure:chair",properties:{visible:"true",variant:"oak",facing:"south"}},facing:"west",teData:{facing:"east",id:"ancientwarfarestructure:chair_tile"}}
:enddata
:endrule

rule:
plugin=blockTile
number=95
data:
JSON:{blockState:{blockName:"ancientwarfarestructure:chair",properties:{visible:"true",variant:"oak",facing:"south"}},facing:"east",teData:{facing:"west",id:"ancientwarfarestructure:chair_tile"}}
:enddata
:endrule

rule:
plugin=inventory
number=96
data:
JSON:{blockState:{blockName:"minecraft:furnace",properties:{facing:"west"}},lootLevel:0,teData:{CookTime:0,BurnTime:0,Items:[],id:"minecraft:furnace",CookTimeTotal:0,Lock:""},inventoryData:{length:0,inventoryContents:[]},legacyFeatures:0b}
:enddata
:endrule

rule:
plugin=inventory
number=97
data:
JSON:{blockState:{blockName:"minecraft:chest",properties:{facing:"east"}},lootLevel:0,teData:{Items:[],id:"minecraft:chest",Lock:""},inventoryData:{length:0,inventoryContents:[]},legacyFeatures:1b}
:enddata
:endrule

rule:
plugin=doors
number=98
data:
JSON:{blockState:{blockName:"minecraft:spruce_door",properties:{hinge:"left",half:"lower",powered:"false",facing:"south",open:"true"}}}
:enddata
:endrule

rule:
plugin=vanillaBlocks
number=99
data:
JSON:{blockState:{blockName:"minecraft:leaves",properties:{check_decay:"true",decayable:"false",variant:"oak"}}}
:enddata
:endrule

rule:
plugin=doors
number=100
data:
JSON:{blockState:{blockName:"minecraft:spruce_door",properties:{hinge:"left",half:"lower",powered:"false",facing:"south",open:"false"}}}
:enddata
:endrule

rule:
plugin=blockTile
number=101
data:
JSON:{blockState:{blockName:"ancientwarfarestructure:advanced_spawner",properties:{transparent:"true"}},teData:{id:"ancientwarfarestructure:advanced_spawner_tile",spawnerSettings:{minDelay:10,spawnDelay:9,lightSensitive:0b,spawnGroups:[{settingsList:[{remainingSpawnCount:1,hostile:1b,customTag:{ArmorDropChances:[0.085f,0.085f,0.085f,0.085f],hasCustomEquipment:0b,ArmorItems:[{},{},{},{}],skinSettings:{npcTypeName:"custom",skinTypeSelected:"default"},HandDropChances:[0.085f,0.085f],factionName:"guild",HandItems:[{id:"ancientwarfarenpc:iron_spear",Count:1b,Damage:0s},{id:"ancientwarfarenpc:iron_shield",Count:1b,Damage:0s}]},maxToSpawn:1,entityId:"ancientwarfarenpc:faction.soldier",minToSpawn:1}],groupWeight:1}],playerRange:16,respondToRedstone:0b,inventory:{Size:9,Items:[]},spawnRange:0,transparent:1b,maxDelay:10,spawnYOffset:0,xpToDrop:0,mobRange:0,debugMode:0b,maxNearbyMonsters:0}}}
:enddata
:endrule

rule:
plugin=vanillaBlocks
number=102
data:
JSON:{blockState:{blockName:"minecraft:torch",properties:{facing:"south"}}}
:enddata
:endrule

rule:
plugin=vanillaBlocks
number=103
data:
JSON:{blockState:{blockName:"minecraft:stained_hardened_clay",properties:{color:"silver"}}}
:enddata
:endrule

rule:
plugin=doors
number=104
data:
JSON:{blockState:{blockName:"minecraft:spruce_door",properties:{hinge:"right",half:"upper",powered:"false",facing:"south",open:"false"}}}
:enddata
:endrule

rule:
plugin=doors
number=105
data:
JSON:{blockState:{blockName:"minecraft:spruce_door",properties:{hinge:"left",half:"upper",powered:"false",facing:"south",open:"false"}}}
:enddata
:endrule

rule:
plugin=vanillaBlocks
number=106
data:
JSON:{blockState:{blockName:"minecraft:stained_hardened_clay",properties:{color:"green"}}}
:enddata
:endrule

rule:
plugin=vanillaBlocks
number=107
data:
JSON:{blockState:{blockName:"minecraft:torch",properties:{facing:"west"}}}
:enddata
:endrule

rule:
plugin=vanillaBlocks
number=108
data:
JSON:{blockState:{blockName:"minecraft:torch",properties:{facing:"east"}}}
:enddata
:endrule

rule:
plugin=vanillaBlocks
number=109
data:
JSON:{blockState:{blockName:"minecraft:trapdoor",properties:{half:"bottom",facing:"west",open:"true"}}}
:enddata
:endrule

rule:
plugin=vanillaBlocks
number=110
data:
JSON:{blockState:{blockName:"minecraft:trapdoor",properties:{half:"bottom",facing:"east",open:"true"}}}
:enddata
:endrule

rule:
plugin=vanillaBlocks
number=111
data:
JSON:{blockState:{blockName:"minecraft:torch",properties:{facing:"up"}}}
:enddata
:endrule

rule:
plugin=vanillaBlocks
number=112
data:
JSON:{blockState:{blockName:"minecraft:carpet",properties:{color:"silver"}}}
:enddata
:endrule

rule:
plugin=vanillaBlocks
number=113
data:
JSON:{blockState:{blockName:"ancientwarfarestructure:coin_stack_copper",properties:{size:"8"}}}
:enddata
:endrule

rule:
plugin=blockTile
number=114
data:
JSON:{blockState:{blockName:"ancientwarfarestructure:chair",properties:{visible:"false",variant:"oak",facing:"south"}},facing:"south",teData:{facing:"north",id:"ancientwarfarestructure:chair_tile",mainBlockPos:-26662351667908L}}
:enddata
:endrule

rule:
plugin=vanillaBlocks
number=115
data:
JSON:{blockState:{blockName:"minecraft:torch",properties:{facing:"north"}}}
:enddata
:endrule

rule:
plugin=blockTile
number=116
data:
JSON:{blockState:{blockName:"ancientwarfarestructure:chair",properties:{visible:"false",variant:"oak",facing:"south"}},facing:"west",teData:{facing:"east",id:"ancientwarfarestructure:chair_tile",mainBlockPos:-25562840040131L}}
:enddata
:endrule

rule:
plugin=blockTile
number=117
data:
JSON:{blockState:{blockName:"ancientwarfarestructure:chair",properties:{visible:"false",variant:"oak",facing:"south"}},facing:"east",teData:{facing:"west",id:"ancientwarfarestructure:chair_tile",mainBlockPos:-24738206319299L}}
:enddata
:endrule

rule:
plugin=blockTile
number=118
data:
JSON:{blockState:{blockName:"ancientwarfarestructure:chair",properties:{visible:"false",variant:"oak",facing:"south"}},facing:"west",teData:{facing:"east",id:"ancientwarfarestructure:chair_tile",mainBlockPos:-25562840040130L}}
:enddata
:endrule

rule:
plugin=blockTile
number=119
data:
JSON:{blockState:{blockName:"ancientwarfarestructure:chair",properties:{visible:"false",variant:"oak",facing:"south"}},facing:"east",teData:{facing:"west",id:"ancientwarfarestructure:chair_tile",mainBlockPos:-24738206319298L}}
:enddata
:endrule

rule:
plugin=vanillaBlocks
number=120
data:
JSON:{blockState:{blockName:"minecraft:trapdoor",properties:{half:"bottom",facing:"south",open:"true"}}}
:enddata
:endrule

rule:
plugin=vanillaBlocks
number=121
data:
JSON:{blockState:{blockName:"minecraft:wooden_slab",properties:{half:"top",variant:"acacia"}}}
:enddata
:endrule

rule:
plugin=vanillaBlocks
number=122
data:
JSON:{blockState:{blockName:"minecraft:acacia_stairs",properties:{half:"top",shape:"straight",facing:"north"}}}
:enddata
:endrule

rule:
plugin=vanillaBlocks
number=123
data:
JSON:{blockState:{blockName:"minecraft:acacia_stairs",properties:{half:"top",shape:"straight",facing:"west"}}}
:enddata
:endrule

rule:
plugin=vanillaBlocks
number=124
data:
JSON:{blockState:{blockName:"minecraft:acacia_stairs",properties:{half:"top",shape:"straight",facing:"east"}}}
:enddata
:endrule

rule:
plugin=vanillaBlocks
number=125
data:
JSON:{blockState:{blockName:"minecraft:stone_slab",properties:{half:"top",variant:"quartz"}}}
:enddata
:endrule

rule:
plugin=vanillaBlocks
number=126
data:
JSON:{blockState:{blockName:"minecraft:acacia_stairs",properties:{half:"top",shape:"straight",facing:"south"}}}
:enddata
:endrule

rule:
plugin=vanillaBlocks
number=127
data:
JSON:{blockState:{blockName:"minecraft:wooden_slab",properties:{half:"bottom",variant:"acacia"}}}
:enddata
:endrule

rule:
plugin=vanillaBlocks
number=128
data:
JSON:{blockState:{blockName:"minecraft:planks",properties:{variant:"acacia"}}}
:enddata
:endrule

rule:
plugin=vanillaBlocks
number=129
data:
JSON:{blockState:{blockName:"minecraft:wool",properties:{color:"gray"}}}
:enddata
:endrule

rule:
plugin=vanillaBlocks
number=130
data:
JSON:{blockState:{blockName:"minecraft:wool",properties:{color:"yellow"}}}
:enddata
:endrule

rule:
plugin=vanillaBlocks
number=131
data:
JSON:{blockState:{blockName:"minecraft:wool",properties:{color:"white"}}}
:enddata
:endrule

rule:
plugin=vanillaBlocks
number=132
data:
JSON:{blockState:{blockName:"minecraft:wool",properties:{color:"orange"}}}
:enddata
:endrule

rule:
plugin=vanillaBlocks
number=133
data:
JSON:{blockState:{blockName:"minecraft:wool",properties:{color:"silver"}}}
:enddata
:endrule

rule:
plugin=vanillaBlocks
number=134
data:
JSON:{blockState:{blockName:"minecraft:wool",properties:{color:"brown"}}}
:enddata
:endrule

rule:
plugin=vanillaBlocks
number=135
data:
JSON:{blockState:{blockName:"minecraft:wool",properties:{color:"lime"}}}
:enddata
:endrule

rule:
plugin=vanillaBlocks
number=136
data:
JSON:{blockState:{blockName:"minecraft:wool",properties:{color:"red"}}}
:enddata
:endrule

#### ENTITIES ####
