# Ancient Warfare Structure Template File
# Auto-generated structure template file. created on: 3/14/2024 at: 22:44:20
# Lines beginning with # denote comments

header:
version=2.11
name=MerchantGuildDomusMedium1
mods=
size=26,13,56
offset=13,5,55
:endheader

#### VALIDATION ####
validation:
type=ground
structureAuthor=TheOddlySeagull
survival=false
worldGenEnabled=true
unique=false
preserveBlocks=false
preventNaturalHostileSpawns=true
selectionWeight=20
clusterValue=100
minDuplicateDistance=7000
dimensionWhiteList=true
dimensionList=0
biomeGroupList=
biomeWhiteList=true
biomeList=minecraft:savanna_rock,minecraft:savanna
leveling=6
fill=6
border=10
blockSwap=false
territoryName=guild
biomeReplacement=minecraft:
minGenerationHeight=0
maxGenerationHeight=255
:endvalidation

#### LAYERS ####
layer: 0
1,1,1,1,1,1,1,1,1,1,1,1,1,1,1,1,1,1,1,1,1,1,1,1,1,1
1,1,1,1,1,1,1,1,1,1,1,1,1,1,1,1,1,1,1,1,1,1,1,1,1,1
1,1,1,1,1,1,1,1,1,1,1,1,1,1,1,1,1,1,1,1,1,1,1,1,1,1
1,1,1,1,1,1,1,1,1,1,1,1,1,1,1,1,1,1,1,1,1,1,1,1,1,1
1,1,1,1,1,1,1,1,1,1,1,1,1,1,1,1,1,1,1,1,1,1,1,1,1,1
1,1,1,1,1,1,1,1,1,1,1,1,1,1,1,1,1,1,1,1,1,1,1,1,1,1
1,1,1,1,1,1,1,1,1,1,1,1,1,1,1,1,1,1,1,1,1,1,1,1,1,1
1,1,1,1,1,1,1,1,1,1,1,1,1,1,1,1,1,1,1,1,1,1,1,1,1,1
1,1,1,1,1,1,1,1,1,1,1,1,1,1,1,1,1,1,1,1,1,1,1,1,1,1
1,1,1,1,1,1,1,1,1,1,1,1,1,1,1,1,1,1,1,1,1,1,1,1,1,1
1,1,1,1,1,1,1,1,1,1,1,1,1,1,1,1,1,1,1,1,1,1,1,1,1,1
1,1,1,1,1,1,1,1,1,1,1,1,1,1,1,1,1,1,1,1,1,1,1,1,1,1
1,1,1,1,1,1,1,1,1,1,1,1,1,1,1,1,1,1,1,1,1,1,1,1,1,1
1,1,1,1,1,1,1,1,1,1,1,1,1,1,1,1,1,1,1,1,1,1,1,1,1,1
1,1,1,1,1,1,1,1,1,1,1,1,1,1,1,1,1,1,1,1,1,1,1,1,1,1
1,1,1,1,1,1,1,1,1,1,1,1,1,1,1,1,1,1,1,1,1,1,1,1,1,1
1,1,1,1,1,1,1,1,1,1,1,1,1,1,1,1,1,1,1,1,1,1,1,1,1,1
1,1,1,1,1,1,1,1,1,1,1,1,1,1,1,1,1,1,1,1,1,1,1,1,1,1
1,1,1,1,1,1,1,1,1,1,1,1,1,1,1,1,1,1,1,1,1,1,1,1,1,1
1,1,1,1,1,1,1,1,1,1,1,1,1,1,1,1,1,1,1,1,1,1,1,1,1,1
1,1,1,1,1,1,1,1,1,1,1,1,1,1,1,1,1,1,1,1,1,1,1,1,1,1
1,1,1,1,1,1,1,1,1,1,1,1,1,1,1,1,1,1,1,1,1,1,1,1,1,1
1,1,1,1,1,1,1,1,1,1,1,1,1,1,1,1,1,1,1,1,1,1,1,1,1,1
1,1,1,1,1,1,1,1,1,1,1,1,1,1,1,1,1,1,1,1,1,1,1,1,1,1
1,1,1,1,1,1,1,1,1,1,1,1,1,1,1,1,1,1,1,1,1,1,1,1,1,1
1,1,1,1,1,1,1,1,1,1,1,1,1,1,1,1,1,1,1,1,1,1,1,1,1,1
1,1,1,1,1,1,1,1,1,1,1,1,1,1,1,1,1,1,1,1,1,1,1,1,1,1
1,1,1,1,1,1,1,1,1,1,1,1,1,1,1,1,1,1,1,1,1,1,1,1,1,1
1,1,1,1,1,1,1,1,1,1,1,1,1,1,1,1,1,1,1,1,1,1,1,1,1,1
1,1,1,1,1,1,1,1,1,1,1,1,1,1,1,1,1,1,1,1,1,1,1,1,1,1
1,1,1,1,1,1,1,1,1,1,1,1,1,1,1,1,1,1,1,1,1,1,1,1,1,1
1,1,1,1,1,1,1,1,1,1,1,1,1,1,1,1,1,1,1,1,1,1,1,1,1,1
1,1,1,1,1,1,1,1,1,1,1,1,1,1,1,1,1,1,1,1,1,1,1,1,1,1
1,1,1,1,1,1,1,1,1,1,1,1,1,1,1,1,1,1,1,1,1,1,1,1,1,1
1,1,1,1,1,1,1,1,1,1,1,1,1,1,1,1,1,1,1,1,1,1,1,1,1,1
1,1,1,1,1,1,1,1,1,1,1,1,1,1,1,1,1,1,1,1,1,1,1,1,1,1
1,1,1,1,1,1,1,1,1,1,1,1,1,1,1,1,1,1,1,1,1,1,1,1,1,1
1,1,1,1,1,1,1,1,1,1,1,1,1,1,1,1,1,1,1,1,1,1,1,1,1,1
1,1,1,1,1,1,1,1,1,1,1,1,1,1,1,1,1,1,1,1,1,1,1,1,1,1
1,1,1,1,1,1,1,1,1,1,1,1,1,1,1,1,1,1,1,1,1,1,1,1,1,1
1,1,1,1,1,1,1,1,1,1,1,1,1,1,1,1,1,1,1,1,1,1,1,1,1,1
1,1,1,1,1,1,1,1,1,1,1,1,1,1,1,1,1,1,1,1,1,1,1,1,1,1
1,1,1,1,1,1,1,1,1,1,1,1,1,1,1,1,1,1,1,1,1,1,1,1,1,1
1,1,1,1,1,1,1,1,1,1,1,1,1,1,1,1,1,1,1,1,1,1,1,1,1,1
1,1,1,1,1,1,1,1,1,1,1,1,1,1,1,1,1,1,1,1,1,1,1,1,1,1
1,1,1,1,1,1,1,1,1,1,1,1,1,1,1,1,1,1,1,1,1,1,1,1,1,1
1,1,1,1,1,1,1,1,1,1,1,1,1,1,1,1,1,1,1,1,1,1,1,1,1,1
1,1,1,1,1,1,1,1,1,1,1,1,1,1,1,1,1,1,1,1,1,1,1,1,1,1
1,1,1,1,1,1,1,1,1,1,1,1,1,1,1,1,1,1,1,1,1,1,1,1,1,1
1,1,1,1,1,1,1,1,1,1,1,1,1,1,1,1,1,1,1,1,1,1,1,1,1,1
1,1,1,1,1,1,1,1,1,1,1,1,1,1,1,1,1,1,1,1,1,1,1,1,1,1
1,1,1,1,1,1,1,1,1,1,1,1,1,1,1,1,1,1,1,1,1,1,1,1,1,1
1,1,1,1,1,1,1,1,1,1,1,1,1,1,1,1,1,1,1,1,1,1,1,1,1,1
1,1,1,1,1,1,1,1,1,1,1,1,1,1,1,1,1,1,1,1,1,1,1,1,1,1
1,1,1,1,1,1,1,1,1,1,1,1,1,1,1,1,1,1,1,1,1,1,1,1,1,1
1,1,1,1,1,1,1,1,1,1,1,1,1,1,1,1,1,1,1,1,1,1,1,1,1,1
:endlayer
layer: 1
1,1,1,1,1,1,1,1,1,1,1,1,1,1,1,1,1,1,1,1,1,1,1,1,1,1
1,1,1,1,1,1,1,1,1,1,1,1,1,1,1,1,1,1,1,1,1,1,1,1,1,1
1,1,1,1,1,1,1,1,1,1,1,1,1,1,1,1,1,1,1,1,1,1,1,1,1,1
1,1,1,1,1,1,1,1,1,1,1,1,1,1,1,1,1,1,1,1,1,1,1,1,1,1
1,1,1,1,1,1,1,1,1,1,1,1,1,1,1,1,1,1,1,1,1,1,1,1,1,1
1,1,1,1,1,1,1,1,1,1,1,1,1,1,1,1,1,1,1,1,1,1,1,1,1,1
1,1,1,1,1,1,1,1,1,1,1,1,1,1,1,1,1,1,1,1,1,1,1,1,1,1
1,1,1,1,1,1,1,1,1,1,1,1,1,1,1,1,1,1,1,1,1,1,1,1,1,1
1,1,1,1,1,1,1,1,1,1,1,1,1,1,1,1,1,1,1,1,1,1,1,1,1,1
1,1,1,1,1,1,1,1,1,1,1,1,1,1,1,1,1,1,1,1,1,1,1,1,1,1
1,1,1,1,1,1,1,1,1,1,1,1,1,1,1,1,1,1,1,1,1,1,1,1,1,1
1,1,1,1,1,1,1,1,1,1,1,1,1,1,1,1,1,1,1,1,1,1,1,1,1,1
1,1,1,1,1,1,1,1,1,1,1,1,1,1,1,1,1,1,1,1,1,1,1,1,1,1
1,1,1,1,1,1,1,1,1,1,1,1,1,1,1,1,1,1,1,1,1,1,1,1,1,1
1,1,1,1,1,1,1,1,1,1,1,1,1,1,1,1,1,1,1,1,1,1,1,1,1,1
1,1,1,1,1,1,1,1,1,1,1,1,1,1,1,1,1,1,1,1,1,1,1,1,1,1
1,1,1,1,1,1,1,1,1,1,1,1,1,1,1,1,1,1,1,1,1,1,1,1,1,1
1,1,1,1,1,1,1,1,1,1,1,1,1,1,1,1,1,1,1,1,1,1,1,1,1,1
1,1,1,1,1,1,1,1,1,1,1,1,1,1,1,1,1,1,1,1,1,1,1,1,1,1
1,1,1,1,1,1,1,1,1,1,1,1,1,1,1,1,1,1,1,1,1,1,1,1,1,1
1,1,1,1,1,1,1,1,1,1,1,1,1,1,1,1,1,1,1,1,1,1,1,1,1,1
1,1,1,1,1,1,1,1,1,1,1,1,1,1,1,1,1,1,1,1,1,1,1,1,1,1
1,1,1,1,1,1,1,1,1,1,1,1,1,1,1,1,1,1,1,1,1,1,1,1,1,1
1,1,1,1,1,1,1,1,1,1,1,1,1,1,1,1,1,1,1,1,1,1,1,1,1,1
1,1,1,1,1,1,1,1,1,1,1,1,1,1,1,1,1,1,1,1,1,1,1,1,1,1
1,1,1,1,1,1,1,1,1,1,1,1,1,1,1,1,1,1,1,1,1,1,1,1,1,1
1,1,1,1,1,1,1,1,1,1,1,1,1,1,1,1,1,1,1,1,1,1,1,1,1,1
1,1,1,1,1,1,1,1,1,1,1,1,1,1,1,1,1,1,1,1,1,1,1,1,1,1
1,1,1,1,1,1,1,1,1,1,1,1,1,1,1,1,1,1,1,1,1,1,1,1,1,1
1,1,1,1,1,1,1,1,1,1,1,1,1,1,1,1,1,1,1,1,1,1,1,1,1,1
1,1,1,1,1,1,1,1,1,1,1,1,1,1,1,1,1,1,1,1,1,1,1,1,1,1
1,1,1,1,1,1,1,1,1,1,1,1,1,1,1,1,1,1,1,1,1,1,1,1,1,1
1,1,1,1,1,1,1,1,1,1,1,1,1,1,1,1,1,1,1,1,1,1,1,1,1,1
1,1,1,1,1,1,1,1,1,1,1,1,1,1,1,1,1,1,1,1,1,1,1,1,1,1
1,1,1,1,1,1,1,1,1,1,1,1,1,1,1,1,1,1,1,1,1,1,1,1,1,1
1,1,1,1,1,1,1,1,1,1,1,1,1,1,1,1,1,1,1,1,1,1,1,1,1,1
1,1,1,1,1,1,1,1,1,1,1,1,1,1,1,1,1,1,1,1,1,1,1,1,1,1
1,1,1,1,1,1,1,1,1,1,1,1,1,1,1,1,1,1,1,1,1,1,1,1,1,1
1,1,1,1,1,1,1,1,1,1,1,1,1,1,1,1,1,1,1,1,1,1,1,1,1,1
1,1,1,1,1,1,1,1,1,1,1,1,1,1,1,1,1,1,1,1,1,1,1,1,1,1
1,1,1,1,1,1,1,1,1,1,1,1,1,1,1,1,1,1,1,1,1,1,1,1,1,1
1,1,1,1,1,1,1,1,1,1,1,1,1,1,1,1,1,1,1,1,1,1,1,1,1,1
1,1,1,1,1,1,1,1,1,1,1,1,1,1,1,1,1,1,1,1,1,1,1,1,1,1
1,1,1,1,1,1,1,1,1,1,1,1,1,1,1,1,1,1,1,1,1,1,1,1,1,1
1,1,1,1,1,1,1,1,1,1,1,1,1,1,1,1,1,1,1,1,1,1,1,1,1,1
1,1,1,1,1,1,1,1,1,1,1,1,1,1,1,1,1,1,1,1,1,1,1,1,1,1
1,1,1,1,1,1,1,1,1,1,1,1,1,1,1,1,1,1,1,1,1,1,1,1,1,1
1,1,1,1,1,1,1,1,1,1,1,1,1,1,1,1,1,1,1,1,1,1,1,1,1,1
1,1,1,1,1,1,1,1,1,1,1,1,1,1,1,1,1,1,1,1,1,1,1,1,1,1
1,1,1,1,1,1,1,1,1,1,1,1,1,1,1,1,1,1,1,1,1,1,1,1,1,1
1,1,1,1,1,1,1,1,1,1,1,1,1,1,1,1,1,1,1,1,1,1,1,1,1,1
1,1,1,1,1,1,1,1,1,1,1,1,1,1,1,1,1,1,1,1,1,1,1,1,1,1
1,1,1,1,1,1,1,1,1,1,1,1,1,1,1,1,1,1,1,1,1,1,1,1,1,1
1,1,1,1,1,1,1,1,1,1,1,1,1,1,1,1,1,1,1,1,1,1,1,1,1,1
1,1,1,1,1,1,1,1,1,1,1,1,1,1,1,1,1,1,1,1,1,1,1,1,1,1
1,1,1,1,1,1,1,1,1,1,1,1,1,1,1,1,1,1,1,1,1,1,1,1,1,1
:endlayer
layer: 2
1,1,1,1,1,1,1,1,1,1,1,1,1,1,1,1,1,1,1,1,1,1,1,1,1,1
1,1,1,1,1,1,1,1,1,1,1,1,1,1,1,1,1,1,1,1,1,1,1,1,1,1
1,1,1,1,1,1,1,1,1,1,1,1,1,1,1,1,1,1,1,1,1,1,1,1,1,1
1,1,1,1,1,1,1,1,1,1,1,1,1,1,1,1,1,1,1,1,1,1,1,1,1,1
1,1,1,1,1,1,1,1,1,1,1,1,1,1,1,1,1,1,1,1,1,1,1,1,1,1
1,1,1,1,1,1,1,1,1,1,1,1,1,1,1,1,1,1,1,1,1,1,1,1,1,1
1,1,1,1,1,1,1,1,1,1,1,1,1,1,1,1,1,1,1,1,1,1,1,1,1,1
1,1,1,1,1,1,1,1,1,1,1,1,1,1,1,1,1,1,1,1,1,1,1,1,1,1
1,1,1,1,1,1,1,1,1,1,1,1,1,1,1,1,1,1,1,1,1,1,1,1,1,1
1,1,1,1,1,1,1,1,1,1,1,1,1,1,1,1,1,1,1,1,1,1,1,1,1,1
1,1,1,1,1,1,1,1,1,1,1,1,1,1,1,1,1,1,1,1,1,1,1,1,1,1
1,1,1,1,1,1,1,1,1,1,1,1,1,1,1,1,1,1,1,1,1,1,1,1,1,1
1,1,1,1,1,1,1,1,1,1,1,1,1,1,1,1,1,1,1,1,1,1,1,1,1,1
1,1,1,1,1,1,1,1,1,1,1,1,1,1,1,1,1,1,1,1,1,1,1,1,1,1
1,1,1,1,1,1,1,1,1,1,1,1,1,1,1,1,1,1,1,1,1,1,1,1,1,1
1,1,1,1,1,1,1,1,1,1,1,1,1,1,1,1,1,1,1,1,1,1,1,1,1,1
1,1,1,1,1,1,1,1,1,1,1,1,1,1,1,1,1,1,1,1,1,1,1,1,1,1
1,1,1,1,1,1,1,1,1,1,1,1,1,1,1,1,1,1,1,1,1,1,1,1,1,1
1,1,1,1,1,1,1,1,1,1,1,1,1,1,1,1,1,1,1,1,1,1,1,1,1,1
1,1,1,1,1,1,1,1,1,1,1,1,1,1,1,1,1,1,1,1,1,1,1,1,1,1
1,1,1,1,1,1,1,1,1,1,1,1,1,1,1,1,1,1,1,1,1,1,1,1,1,1
1,1,1,1,1,1,1,1,1,1,1,1,1,1,1,1,1,1,1,1,1,1,1,1,1,1
1,1,1,1,1,1,1,1,1,1,1,1,1,1,1,1,1,1,1,1,1,1,1,1,1,1
1,1,1,1,1,1,1,1,1,1,1,1,1,1,1,1,1,1,1,1,1,1,1,1,1,1
1,1,1,1,1,1,1,1,1,1,1,1,1,1,1,1,1,1,1,1,1,1,1,1,1,1
1,1,1,1,1,1,1,1,1,1,1,1,1,1,1,1,1,1,1,1,1,1,1,1,1,1
1,1,1,1,1,1,1,1,1,1,1,1,1,1,1,1,1,1,1,1,1,1,1,1,1,1
1,1,1,1,1,1,1,1,1,1,1,1,1,1,1,1,1,1,1,1,1,1,1,1,1,1
1,1,1,1,1,1,1,1,1,1,1,1,1,1,1,1,1,1,1,1,1,1,1,1,1,1
1,1,1,1,1,1,1,1,1,1,1,1,1,1,1,1,1,1,1,1,1,1,1,1,1,1
1,1,1,1,1,1,1,1,1,1,1,1,1,1,1,1,1,1,1,1,1,1,1,1,1,1
1,1,1,1,1,1,1,1,1,1,1,1,1,1,1,1,1,1,1,1,1,1,1,1,1,1
1,1,1,1,1,1,1,1,1,1,1,1,1,1,1,1,1,1,1,1,1,1,1,1,1,1
1,1,1,1,1,1,1,1,1,1,1,1,1,1,1,1,1,1,1,1,1,1,1,1,1,1
1,1,1,1,1,1,1,1,1,1,1,1,1,1,1,1,1,1,1,1,1,1,1,1,1,1
1,1,1,1,1,1,1,1,1,1,1,1,1,1,1,1,1,1,1,1,1,1,1,1,1,1
1,1,1,1,1,1,1,1,1,1,1,1,1,1,1,1,1,1,1,1,1,1,1,1,1,1
1,1,1,1,1,1,1,1,1,1,1,1,1,1,1,1,1,1,1,1,1,1,1,1,1,1
1,1,1,1,1,1,1,1,1,1,1,1,1,1,1,1,1,1,1,1,1,1,1,1,1,1
1,1,1,1,1,1,1,1,1,1,1,1,1,1,1,1,1,1,1,1,1,1,1,1,1,1
1,1,1,1,1,1,1,1,1,1,1,1,1,1,1,1,1,1,1,1,1,1,1,1,1,1
1,1,1,1,1,1,1,1,1,1,1,1,1,1,1,1,1,1,1,1,1,1,1,1,1,1
1,1,1,1,1,1,1,1,1,1,1,1,1,1,1,1,1,1,1,1,1,1,1,1,1,1
1,1,1,1,1,1,1,1,1,1,1,1,1,1,1,1,1,1,1,1,1,1,1,1,1,1
1,1,1,1,1,1,1,1,1,1,1,1,1,1,1,1,1,1,1,1,1,1,1,1,1,1
1,1,1,1,1,1,1,1,1,1,1,1,1,1,1,1,1,1,1,1,1,1,1,1,1,1
1,1,1,1,1,1,1,1,1,1,1,1,1,1,1,1,1,1,1,1,1,1,1,1,1,1
1,1,1,1,1,1,1,1,1,1,1,1,1,1,1,1,1,1,1,1,1,1,1,1,1,1
1,1,1,1,1,1,1,1,1,1,1,1,1,1,1,1,1,1,1,1,1,1,1,1,1,1
1,1,1,1,1,1,1,1,1,1,1,1,1,1,1,1,1,1,1,1,1,1,1,1,1,1
1,1,1,1,1,1,1,1,1,1,1,1,1,1,1,1,1,1,1,1,1,1,1,1,1,1
1,1,1,1,1,1,1,1,1,1,1,1,1,1,1,1,1,1,1,1,1,1,1,1,1,1
1,1,1,1,1,1,1,1,1,1,1,1,1,1,1,1,1,1,1,1,1,1,1,1,1,1
1,1,1,1,1,1,1,1,1,1,1,1,1,1,1,1,1,1,1,1,1,1,1,1,1,1
1,1,1,1,1,1,1,1,1,1,1,1,1,1,1,1,1,1,1,1,1,1,1,1,1,1
1,1,1,1,1,1,1,1,1,1,1,1,1,1,1,1,1,1,1,1,1,1,1,1,1,1
:endlayer
layer: 3
2,2,2,2,2,2,2,2,2,2,2,2,2,2,2,2,2,2,2,2,2,2,2,2,2,2
2,2,2,2,2,2,2,2,2,2,2,2,2,2,2,2,2,2,2,2,2,2,2,2,2,2
2,2,2,2,2,2,2,2,2,2,2,2,2,2,2,2,2,2,2,2,2,2,2,2,2,2
2,2,2,2,2,2,2,2,2,2,2,2,2,2,2,2,2,2,2,2,2,2,2,2,2,2
2,2,2,2,2,2,2,2,2,2,2,2,2,2,2,2,2,2,2,2,2,2,2,2,2,2
2,2,2,2,2,2,2,2,2,2,2,2,2,2,2,2,2,2,2,2,2,2,2,2,2,2
2,2,2,2,2,2,2,2,2,2,2,2,2,2,2,2,2,2,2,2,2,2,2,2,2,2
2,2,2,2,2,2,2,2,2,2,2,2,2,2,2,2,2,2,2,2,2,2,2,2,2,2
2,2,2,2,2,2,2,2,2,2,2,2,2,2,2,2,2,2,2,2,2,2,2,2,2,2
2,2,2,2,2,2,2,2,2,2,2,2,2,2,2,2,2,2,2,2,2,2,2,2,2,2
2,2,2,2,2,2,2,2,2,2,2,2,2,2,2,2,2,2,2,2,2,2,2,2,2,2
2,2,2,2,2,2,2,2,2,2,2,2,2,2,2,2,2,2,2,2,2,2,2,2,2,2
2,2,2,2,2,2,2,3,3,3,3,3,3,3,2,2,2,2,2,2,2,2,2,2,2,2
2,2,2,2,2,2,2,3,4,9,9,9,4,3,2,2,2,2,2,2,2,2,2,2,2,2
2,2,2,2,2,2,2,3,8,7,7,7,6,3,2,2,2,2,2,2,2,2,2,2,2,2
2,2,2,2,2,2,2,3,8,7,7,7,6,3,2,2,2,2,2,2,2,2,2,2,2,2
2,2,2,2,2,2,2,3,8,7,7,7,6,3,2,2,2,2,2,2,2,2,2,2,2,2
2,2,2,2,2,2,2,3,4,5,5,5,4,3,2,2,2,2,2,2,2,2,2,2,2,2
2,2,2,2,2,2,2,3,3,3,3,3,3,3,2,2,2,2,2,2,2,2,2,2,2,2
2,2,2,2,2,2,2,3,3,3,3,3,3,3,2,2,2,2,2,2,2,2,2,2,2,2
2,2,2,2,2,2,2,3,3,3,3,3,3,3,2,2,2,2,2,2,2,2,2,2,2,2
2,2,2,2,2,2,2,3,3,3,3,3,3,3,2,2,2,2,2,2,2,2,2,2,2,2
2,2,2,2,2,2,2,3,3,3,3,3,3,3,2,2,2,2,2,2,2,2,2,2,2,2
2,2,2,2,2,2,2,2,2,2,2,2,2,2,2,2,2,2,2,2,2,2,2,2,2,2
2,2,2,2,2,2,2,2,2,2,2,2,2,2,2,2,2,2,2,2,2,2,2,2,2,2
2,2,2,2,2,2,2,2,2,2,2,2,2,2,2,2,2,2,2,2,2,2,2,2,2,2
2,2,2,2,2,2,2,2,2,2,2,2,2,2,2,2,2,2,2,2,2,2,2,2,2,2
2,2,2,2,2,2,2,2,2,2,2,2,2,2,2,2,2,2,2,2,2,2,2,2,2,2
2,2,2,2,2,2,2,2,2,2,2,2,2,2,2,2,2,2,2,2,2,2,2,2,2,2
2,2,2,2,2,2,2,2,2,2,2,2,2,2,2,2,2,2,2,2,2,2,2,2,2,2
2,2,2,2,2,2,2,2,2,2,2,2,2,2,2,2,2,2,2,2,2,2,2,2,2,2
2,2,2,2,2,2,2,2,2,2,2,2,2,2,2,2,2,2,2,2,2,2,2,2,2,2
2,2,2,2,2,2,2,2,2,2,2,2,2,2,2,2,2,2,2,2,2,2,2,2,2,2
2,2,2,2,2,2,2,2,2,2,2,2,2,2,2,2,2,2,2,2,2,2,2,2,2,2
2,2,2,2,2,2,2,2,2,2,2,2,2,2,2,2,2,2,2,2,2,2,2,2,2,2
2,2,2,2,2,2,2,2,2,2,2,2,2,2,2,2,2,2,2,2,2,2,2,2,2,2
2,2,2,2,2,2,2,2,2,2,2,2,2,2,2,2,2,2,2,2,2,2,2,2,2,2
2,2,2,2,2,2,2,2,2,2,2,1,1,1,1,2,2,2,2,2,2,2,2,2,2,2
2,2,2,2,2,2,2,2,2,2,2,1,1,1,1,2,2,2,2,2,2,2,2,2,2,2
2,2,2,2,2,2,2,2,2,2,2,1,1,1,1,2,2,2,2,2,2,2,2,2,2,2
2,2,2,2,2,2,2,2,2,2,2,1,1,1,1,2,2,2,2,2,2,2,2,2,2,2
2,2,2,2,2,2,2,2,2,2,2,1,1,1,1,2,2,2,2,2,2,2,2,2,2,2
2,2,2,2,2,2,2,2,2,2,2,1,1,1,1,2,2,2,2,2,2,2,2,2,2,2
2,2,2,2,2,2,2,2,2,2,2,1,1,1,1,2,2,2,2,2,2,2,2,2,2,2
2,2,2,2,2,2,2,2,2,2,2,1,1,1,1,2,2,2,2,2,2,2,2,2,2,2
2,2,2,2,2,2,2,2,2,2,2,1,1,1,1,2,2,2,2,2,2,2,2,2,2,2
2,2,2,2,2,2,2,2,2,2,2,2,2,2,2,2,2,2,2,2,2,2,2,2,2,2
2,2,2,2,2,2,2,2,2,2,2,2,2,2,2,2,2,2,2,2,2,2,2,2,2,2
2,2,2,2,2,2,2,2,2,2,2,2,2,2,2,2,2,2,2,2,2,2,2,2,2,2
2,2,2,2,2,2,2,2,2,2,2,2,2,2,2,2,2,2,2,2,2,2,2,2,2,2
2,2,2,2,2,2,2,2,2,2,2,2,2,2,2,2,2,2,2,2,2,2,2,2,2,2
2,2,2,2,2,2,2,2,2,2,2,2,2,2,2,2,2,2,2,2,2,2,2,2,2,2
2,2,2,2,2,2,2,2,2,2,2,2,2,2,2,2,2,2,2,2,2,2,2,2,2,2
2,2,2,2,2,2,2,2,2,2,2,2,2,2,2,2,2,2,2,2,2,2,2,2,2,2
2,2,2,2,2,2,2,2,2,2,2,2,2,2,2,2,2,2,2,2,2,2,2,2,2,2
2,2,2,2,2,2,2,2,2,2,2,2,2,2,2,2,2,2,2,2,2,2,2,2,2,2
:endlayer
layer: 4
3,3,3,3,3,3,3,3,3,3,3,3,3,3,3,3,3,3,3,3,3,3,3,3,3,3
3,3,3,3,3,3,3,3,3,3,3,3,3,3,3,3,3,3,3,3,3,3,3,3,3,3
3,3,13,13,13,13,13,13,13,13,13,13,13,13,13,13,13,13,13,13,13,13,13,13,3,3
3,3,13,81,82,81,82,81,82,81,13,37,36,37,36,13,81,82,81,82,81,82,81,13,3,3
3,3,13,79,80,79,80,79,80,79,13,35,34,35,34,13,79,80,79,80,79,80,79,13,3,3
3,3,13,81,82,81,82,81,82,81,13,37,36,37,36,13,81,82,81,82,81,82,81,13,3,3
3,3,13,79,80,79,80,79,80,79,13,35,34,35,34,13,79,80,79,80,79,80,79,13,3,3
3,3,13,13,13,13,13,13,13,13,13,37,36,37,36,13,13,13,13,13,13,13,13,13,3,3
3,3,13,36,58,37,51,52,51,52,51,52,51,52,51,36,58,37,13,11,11,11,11,13,3,3
3,3,13,55,54,53,56,57,56,57,56,57,56,57,56,55,54,53,13,11,11,11,11,13,3,3
3,3,13,37,50,35,52,52,51,52,51,52,51,52,51,37,50,35,13,13,13,13,13,13,3,3
3,3,13,56,57,56,60,78,78,78,60,78,78,78,60,56,57,56,13,28,32,28,32,13,3,3
3,3,13,51,52,51,66,63,63,63,65,63,64,68,62,51,52,51,13,27,31,27,31,13,3,3
3,3,13,56,57,56,66,64,77,0,0,0,76,64,62,56,57,56,13,28,32,28,32,13,3,3
3,3,13,51,52,51,66,68,0,0,75,0,0,68,62,51,52,51,13,27,31,27,31,13,3,3
3,3,13,56,57,56,60,68,0,75,7,75,0,64,60,56,57,56,13,13,13,13,13,13,3,3
3,3,13,51,52,51,66,0,0,0,75,0,0,64,62,51,52,51,13,72,71,72,71,13,3,3
3,3,13,56,57,56,66,64,74,0,0,0,73,63,62,56,57,56,13,70,69,70,69,13,3,3
3,3,13,51,52,51,66,63,65,65,67,0,65,63,62,51,52,51,13,72,71,72,71,13,3,3
3,3,13,56,57,56,60,0,0,64,68,68,68,64,60,56,57,56,13,70,69,70,69,13,3,3
3,3,13,51,52,51,66,0,67,68,67,63,67,63,62,51,52,51,13,13,13,13,13,13,3,3
3,3,13,56,57,56,66,65,67,68,67,64,67,0,62,56,57,56,13,59,59,59,59,13,3,3
3,3,13,51,52,51,66,0,0,65,63,64,63,0,62,51,52,51,13,59,59,59,59,13,3,3
3,3,13,52,51,52,60,61,61,61,60,61,61,61,60,56,57,56,13,59,59,59,59,13,3,3
3,3,13,36,58,37,51,52,51,52,51,52,51,52,51,36,58,37,13,13,13,13,13,13,3,3
3,3,13,55,54,53,56,57,56,57,56,57,56,57,56,55,54,53,11,11,11,11,11,13,3,3
3,3,13,37,50,35,52,52,51,52,51,52,51,52,51,37,50,35,11,11,11,11,11,13,3,3
3,3,13,13,13,13,13,13,11,11,13,13,13,13,13,13,11,11,13,13,13,13,13,13,3,3
3,3,13,45,44,45,44,13,11,11,13,47,46,47,46,13,11,11,13,45,44,45,44,13,3,3
3,3,13,49,48,49,48,13,11,11,13,43,42,43,42,13,11,11,13,49,48,49,48,13,3,3
3,3,13,45,44,45,44,13,11,11,13,47,46,47,46,13,11,11,13,45,44,45,44,13,3,3
3,3,13,49,48,49,48,13,11,11,13,43,42,43,42,13,11,11,13,49,48,49,48,13,3,3
3,3,13,45,44,45,44,13,11,11,13,47,46,47,46,13,11,11,13,45,44,45,44,13,3,3
3,3,13,13,13,13,13,13,11,11,13,43,42,43,42,13,11,11,13,13,13,13,13,13,3,3
3,3,13,38,39,38,39,38,17,16,17,16,17,16,17,16,17,16,38,39,38,39,38,13,3,3
3,3,13,40,41,40,41,40,19,18,19,18,19,18,19,18,19,18,40,41,40,41,40,13,3,3
3,3,13,38,39,38,39,38,17,16,17,16,17,16,17,16,17,16,38,39,38,39,38,13,3,3
3,3,13,40,41,40,41,40,19,18,19,4,9,9,4,18,19,18,40,41,40,41,40,13,3,3
3,3,13,38,39,38,39,38,17,16,17,8,7,7,6,16,17,16,38,39,38,39,38,13,3,3
3,3,13,13,13,13,13,13,19,18,19,4,7,7,4,18,19,18,13,13,13,13,13,13,3,3
3,3,13,29,30,30,29,13,17,16,17,8,7,7,6,16,17,16,13,32,31,32,31,13,3,3
3,3,13,33,37,36,33,13,19,18,19,4,7,7,4,18,19,18,13,28,27,28,27,13,3,3
3,3,13,33,35,34,33,13,17,16,17,8,7,7,6,16,17,16,13,32,31,32,31,13,3,3
3,3,13,29,30,30,29,13,19,18,19,4,7,7,4,18,19,18,13,28,27,28,27,13,3,3
3,3,13,13,13,13,13,13,17,16,17,8,7,7,6,16,17,16,13,13,13,13,13,13,3,3
3,3,13,26,25,26,25,13,19,18,19,4,5,5,4,18,19,18,13,20,21,21,20,13,3,3
3,3,13,23,22,23,22,13,17,16,17,16,17,16,17,16,17,16,13,21,24,24,21,13,3,3
3,3,13,26,25,26,25,13,19,18,19,18,19,18,19,18,19,18,13,21,24,24,21,13,3,3
3,3,13,23,22,23,22,13,17,16,17,16,17,16,17,16,17,16,13,20,21,21,20,13,3,3
3,3,13,13,13,13,13,13,13,13,13,13,19,18,13,13,13,13,13,13,13,13,13,13,3,3
3,3,13,11,11,13,15,15,15,15,15,13,17,16,13,15,15,13,14,14,14,14,14,13,3,3
3,3,13,11,11,13,15,15,15,15,15,13,19,18,13,15,15,13,14,14,14,14,14,13,3,3
3,3,13,11,11,13,15,15,15,15,15,13,17,16,13,15,15,13,14,14,14,14,14,13,3,3
3,3,13,13,13,13,13,13,13,13,13,13,13,13,13,13,13,13,13,13,13,13,13,13,3,3
3,3,12,10,10,12,10,10,12,10,10,12,11,11,12,10,10,12,10,10,12,10,10,12,3,3
3,3,10,10,10,10,10,10,10,10,10,10,11,11,10,10,10,10,10,10,10,10,10,10,3,3
:endlayer
layer: 5
0,83,0,0,0,0,0,83,83,0,0,0,0,0,63,0,83,83,83,0,0,0,83,83,83,0
83,83,83,0,0,0,0,83,83,83,0,0,0,83,83,83,83,83,0,0,0,0,0,83,83,83
83,83,60,60,60,60,60,60,60,60,60,60,60,60,60,60,60,60,60,60,60,60,60,60,83,83
0,83,60,67,90,90,0,116,116,116,60,67,90,90,67,60,67,90,90,90,67,152,0,60,83,0
83,0,60,87,0,0,151,116,116,116,60,86,0,0,86,60,0,0,87,0,0,116,116,60,0,0
0,0,60,87,0,0,0,0,150,0,60,86,0,0,86,60,0,0,0,0,0,116,116,60,83,0
0,0,60,67,0,0,0,0,0,0,60,67,0,0,67,60,0,0,0,0,0,0,149,60,0,83
0,0,60,60,60,60,0,0,0,0,60,90,0,0,90,60,0,0,60,60,60,60,60,60,0,0
83,83,60,0,0,0,0,0,0,0,0,0,0,0,0,0,0,0,60,148,11,147,146,60,0,83
0,83,60,0,0,0,0,0,0,0,0,0,0,0,0,0,0,0,98,0,0,145,144,60,83,83
83,83,60,0,0,0,0,0,0,0,0,0,0,0,0,0,0,0,60,60,60,60,60,60,83,83
137,83,60,0,0,0,4,0,0,0,4,0,0,0,4,0,0,0,60,0,0,0,87,60,0,83
83,83,60,0,0,0,0,0,0,0,0,0,0,0,0,0,0,0,138,0,0,109,108,60,83,0
0,0,60,0,0,0,0,0,0,0,0,0,0,0,0,0,0,0,138,0,0,109,108,60,0,0
83,83,60,0,0,0,0,0,0,0,0,0,0,0,0,0,0,0,60,0,0,0,143,60,0,0
83,83,60,0,0,0,4,0,0,0,0,0,0,0,4,0,0,0,60,60,60,60,60,60,0,0
83,83,60,0,0,0,0,0,0,0,0,0,0,0,0,0,0,0,60,0,0,0,142,60,0,0
83,83,60,0,0,0,0,0,0,0,0,0,0,0,0,0,0,0,138,0,0,97,96,60,0,0
0,83,60,0,0,0,0,0,0,0,67,0,0,0,0,0,0,0,138,0,0,97,96,60,83,83
0,83,60,0,0,0,4,0,0,0,0,0,0,0,4,0,0,0,60,0,0,0,87,60,0,83
0,0,60,0,0,0,0,0,0,0,0,0,0,0,0,0,0,0,60,60,60,60,60,60,89,83
83,0,60,0,0,0,0,0,0,0,0,0,0,0,0,0,0,0,60,141,140,139,11,60,83,83
0,83,60,0,0,0,0,0,0,0,0,0,0,0,0,0,0,0,138,0,0,0,11,60,0,137
83,83,60,0,0,0,4,0,0,0,4,0,0,0,4,0,0,0,60,136,135,11,11,60,0,0
83,83,60,0,0,0,0,0,0,0,0,0,0,0,0,0,0,0,60,60,60,60,60,60,0,0
0,83,60,0,0,0,0,0,0,0,0,0,0,0,0,0,0,0,0,0,0,0,0,99,0,0
0,0,60,0,0,0,0,0,0,0,0,0,0,0,0,0,0,0,0,0,0,0,0,99,134,0
0,83,60,60,0,0,60,60,0,0,60,60,133,133,60,60,0,0,60,60,60,60,60,60,0,0
0,0,60,0,0,0,0,60,0,0,60,132,0,0,131,60,0,0,60,0,0,0,0,60,0,0
0,0,60,130,116,116,129,60,0,0,60,0,0,0,128,60,0,0,60,127,116,116,126,60,0,0
0,0,60,125,116,116,124,60,0,0,60,0,0,123,122,60,0,0,60,121,116,116,120,60,0,83
0,0,60,119,116,116,118,60,0,0,60,0,87,87,87,60,0,0,60,117,116,116,115,60,83,83
0,0,60,0,0,0,0,60,0,0,60,0,0,0,0,60,0,0,60,0,0,0,0,60,83,83
83,0,60,60,60,60,60,60,0,0,60,0,0,0,0,60,0,0,60,60,0,0,60,60,83,83
0,0,60,67,0,90,90,90,0,0,0,0,0,0,0,0,0,0,67,0,0,0,0,60,0,0
0,0,60,86,0,0,0,0,0,0,0,0,0,0,0,0,0,0,0,0,0,0,86,60,0,0
83,83,60,86,0,87,0,0,0,0,0,0,0,0,0,0,0,0,0,0,87,0,86,60,0,0
105,83,60,86,0,0,0,0,0,0,0,104,0,0,104,0,0,0,0,0,0,0,86,60,0,0
83,83,60,0,90,90,90,67,0,0,0,0,0,0,0,0,0,0,90,90,90,0,67,60,0,0
83,83,60,60,60,60,60,60,0,0,0,104,0,0,104,0,0,0,60,60,60,60,60,60,0,0
0,0,60,87,0,0,0,60,0,114,0,0,0,0,0,0,0,0,60,0,0,0,113,60,83,0
0,0,60,112,111,0,0,102,0,0,0,104,0,0,104,0,0,0,98,0,0,109,108,60,0,0
0,0,60,112,111,0,0,99,0,0,0,0,0,0,0,0,0,0,110,0,0,109,108,60,83,83
0,0,60,107,0,0,0,60,0,0,0,104,0,0,104,0,0,0,60,0,0,0,87,60,83,83
0,83,60,60,60,60,60,60,106,0,0,0,0,0,0,0,0,0,60,60,60,60,60,60,83,83
105,83,60,87,0,0,0,60,0,0,0,104,0,0,104,0,0,0,60,0,0,0,103,60,83,83
83,83,60,101,100,0,0,102,0,0,0,0,0,0,0,0,0,0,98,0,0,97,96,60,0,83
83,0,60,101,100,0,0,99,0,0,0,0,0,0,0,0,0,0,98,0,0,97,96,60,0,0
83,0,60,95,0,0,0,60,0,0,0,0,0,0,0,0,0,0,60,0,0,0,87,60,0,83
0,0,60,60,60,60,60,60,60,60,60,60,0,0,60,60,60,60,60,60,60,60,60,60,0,0
0,0,60,0,94,60,93,0,0,0,90,60,0,0,60,0,92,60,0,91,0,0,86,60,0,0
0,83,60,0,87,60,87,87,0,86,87,60,0,0,60,0,87,60,87,87,87,0,86,60,0,0
83,83,60,0,0,60,0,0,0,0,90,60,0,0,60,0,0,60,0,0,0,0,0,60,0,0
89,89,60,0,0,60,0,0,60,0,0,60,88,88,60,0,0,60,0,0,60,0,0,60,0,0
83,83,0,0,0,0,0,86,87,86,0,85,0,0,84,0,0,0,0,0,0,0,0,0,83,83
0,83,0,0,0,0,0,0,0,0,0,0,0,0,0,0,0,0,0,0,0,0,0,0,83,83
:endlayer
layer: 6
0,0,0,0,0,0,0,0,0,0,0,0,0,0,0,0,0,0,0,0,0,0,0,0,0,0
0,0,0,0,0,0,0,0,0,0,0,0,0,0,0,0,0,0,0,0,0,0,0,0,0,0
0,0,13,13,13,13,13,13,13,13,13,13,13,13,13,13,13,13,13,13,13,13,13,13,0,0
0,0,13,67,0,0,0,0,0,0,13,67,0,0,67,13,67,0,0,0,67,195,0,13,0,0
0,0,13,0,0,0,194,0,0,0,13,0,0,0,0,13,0,0,0,0,0,0,0,13,0,0
0,0,13,155,0,0,0,0,193,0,13,0,0,0,0,13,0,0,0,0,0,0,0,13,0,0
0,0,13,67,0,0,0,0,0,0,13,67,0,0,67,13,0,0,0,0,0,0,192,13,0,0
0,0,13,158,158,158,0,0,0,0,158,0,0,0,0,158,0,0,158,13,13,13,13,13,0,0
0,0,13,0,0,0,0,0,0,0,0,0,0,0,0,0,0,0,158,0,191,190,189,13,0,0
0,0,13,0,0,0,0,0,0,0,0,0,0,0,0,0,0,0,153,0,0,188,187,13,0,0
0,0,13,0,0,0,0,0,0,0,0,0,0,0,0,0,0,0,158,13,13,13,13,13,0,0
0,0,13,0,0,0,4,0,0,0,4,0,0,0,4,0,0,0,158,0,0,0,186,13,0,0
0,0,13,0,0,0,0,0,0,0,0,0,0,0,0,0,0,0,154,0,0,0,0,13,0,0
0,0,13,0,0,0,0,0,0,0,0,0,0,0,0,0,0,0,153,0,0,0,0,13,0,0
0,0,13,0,0,0,0,0,0,0,0,0,0,0,0,0,0,0,158,0,0,0,0,13,0,0
0,0,13,0,0,0,4,0,0,0,0,0,0,0,4,0,0,0,158,13,13,13,13,13,0,0
0,0,13,0,0,0,0,0,0,0,0,0,0,0,0,0,0,0,158,0,0,0,0,13,0,0
0,0,13,0,0,0,0,0,0,0,0,0,0,0,0,0,0,0,154,0,0,0,0,13,0,0
0,0,13,0,0,0,0,0,0,0,0,0,0,0,0,0,0,0,153,0,0,0,0,13,0,0
0,0,13,0,0,0,4,0,0,0,0,0,0,0,4,0,0,0,158,0,0,0,185,13,0,0
0,0,13,0,0,0,0,0,0,0,0,0,0,0,0,0,0,0,158,13,13,13,13,13,0,0
0,0,13,0,0,0,0,0,0,0,0,0,0,0,0,0,0,0,158,139,139,155,182,13,0,0
0,0,13,0,0,0,0,0,0,0,0,0,0,0,0,0,0,0,154,0,0,0,182,13,0,0
0,0,13,0,0,0,4,0,0,0,4,0,0,0,4,0,0,0,158,184,183,182,182,13,0,0
0,0,13,0,0,0,0,0,0,0,0,0,0,0,0,0,0,0,158,13,13,13,13,13,0,0
0,0,13,0,0,0,0,0,0,0,0,0,0,0,0,0,0,0,0,0,0,0,0,153,0,0
0,0,13,0,0,0,0,0,0,0,0,0,0,0,0,0,0,0,0,0,0,0,0,154,0,0
0,0,13,158,0,0,158,158,0,0,158,158,153,154,158,158,0,0,158,13,13,13,13,13,0,0
0,0,13,0,0,0,0,13,0,0,164,181,0,0,0,164,0,0,13,0,0,0,0,13,0,0
0,0,13,180,0,0,179,13,0,0,164,0,0,0,0,164,0,0,13,178,0,0,177,13,0,0
0,0,13,176,0,0,175,13,0,0,164,0,0,174,173,164,0,0,13,172,0,0,171,13,0,0
0,0,13,170,0,0,169,13,0,0,164,0,168,0,167,164,0,0,13,166,0,0,165,13,0,0
0,0,13,0,0,0,0,13,0,0,164,0,0,0,0,164,0,0,13,0,0,0,0,13,0,0
0,0,13,158,158,158,158,158,0,0,158,0,0,0,0,158,0,0,158,158,0,0,158,13,0,0
0,0,13,67,0,0,0,0,0,0,0,0,0,0,0,0,0,0,67,0,0,0,0,13,0,0
0,0,13,0,0,0,0,0,0,0,0,0,0,0,0,0,0,0,0,0,0,0,0,13,0,0
0,0,13,0,0,0,0,0,0,0,0,0,0,0,0,0,0,0,0,0,163,0,0,13,0,0
0,0,13,0,0,0,0,0,0,0,0,104,0,0,104,0,0,0,0,0,0,0,0,13,0,0
0,0,13,0,0,0,0,67,0,0,0,0,0,0,0,0,0,0,0,0,0,0,67,13,0,0
0,0,13,158,158,158,158,158,0,0,0,104,0,0,104,0,0,0,158,158,158,158,158,13,0,0
0,0,13,162,0,0,0,158,0,0,0,0,0,0,0,0,0,0,158,0,0,0,0,13,0,0
0,0,13,0,0,0,0,153,0,0,0,104,0,0,104,0,0,0,154,0,0,0,0,13,0,0
0,0,13,0,0,0,0,154,0,0,0,0,0,0,0,0,0,0,153,0,0,0,0,13,0,0
0,0,13,0,0,0,0,158,0,0,0,104,0,0,104,0,0,0,158,0,0,0,161,13,0,0
0,0,13,157,157,157,157,158,0,0,0,0,0,0,0,0,0,0,158,157,157,157,157,13,0,0
0,0,13,160,0,0,0,158,0,0,0,104,0,0,104,0,0,0,158,0,0,0,0,13,0,0
0,0,13,0,0,0,0,153,0,0,0,0,0,0,0,0,0,0,154,0,0,0,0,13,0,0
0,0,13,0,0,0,0,154,0,0,0,0,0,0,0,0,0,0,153,0,0,0,0,13,0,0
0,0,13,0,0,0,0,158,0,0,0,0,0,0,0,0,0,0,158,0,0,0,159,13,0,0
0,0,13,158,158,158,158,158,158,158,158,158,0,0,158,158,158,158,157,157,157,157,157,13,0,0
0,0,13,0,0,13,0,0,0,0,0,13,0,0,13,0,0,13,0,0,0,0,0,13,0,0
0,0,13,0,156,13,0,0,0,0,0,13,0,0,13,0,0,13,155,0,0,0,0,13,0,0
0,0,13,0,0,13,0,0,0,0,0,13,0,0,13,0,0,13,0,0,0,0,0,13,0,0
0,0,13,0,0,13,0,0,13,0,0,13,154,153,13,0,0,13,0,0,13,0,0,13,0,0
0,0,0,0,0,0,0,0,0,0,0,0,0,0,0,0,0,0,0,0,0,0,0,0,0,0
0,0,0,0,0,0,0,0,0,0,0,0,0,0,0,0,0,0,0,0,0,0,0,0,0,0
:endlayer
layer: 7
0,0,0,0,0,0,0,0,0,0,0,0,0,0,0,0,0,0,0,0,0,0,0,0,0,0
0,0,0,0,0,0,0,0,0,0,0,0,0,0,0,0,0,0,0,0,0,0,0,0,0,0
0,0,13,13,13,13,205,13,13,13,13,13,205,205,13,13,13,13,13,205,13,13,13,13,0,0
0,0,13,0,0,0,0,0,0,0,13,0,0,0,0,13,0,0,0,0,0,0,0,13,0,0
0,0,13,0,0,0,0,0,0,0,13,0,0,0,0,13,0,0,0,0,0,0,0,197,0,0
0,0,13,0,0,0,0,0,0,0,13,0,0,0,0,13,0,0,0,0,0,0,0,197,0,0
0,0,13,0,0,0,0,0,0,0,13,0,0,0,0,13,0,0,0,0,0,0,0,13,0,0
0,0,13,158,158,158,0,0,0,0,158,0,0,0,0,158,0,0,158,13,13,13,13,13,0,0
0,0,13,0,0,0,0,0,0,0,0,0,0,0,0,0,0,0,158,0,0,0,204,13,0,0
0,0,200,0,0,0,0,0,0,0,0,0,0,0,0,0,0,0,201,0,0,0,203,13,0,0
0,0,13,0,0,0,0,0,0,0,0,0,0,0,0,0,0,0,158,13,13,13,13,13,0,0
0,0,13,0,0,0,4,0,0,0,4,0,0,0,4,0,0,0,158,0,0,0,0,13,0,0
0,0,13,0,0,0,0,0,0,0,0,0,0,0,0,0,0,0,201,0,0,0,0,197,0,0
0,0,200,0,0,0,0,0,0,0,0,0,0,0,0,0,0,0,201,0,0,0,0,197,0,0
0,0,13,0,0,0,0,0,0,0,0,0,0,0,0,0,0,0,158,0,0,0,0,13,0,0
0,0,13,0,0,0,4,0,0,0,0,0,0,0,4,0,0,0,158,13,13,13,13,13,0,0
0,0,13,0,0,0,0,0,0,0,0,0,0,0,0,0,0,0,158,0,0,0,0,13,0,0
0,0,200,0,0,0,0,0,0,0,0,0,0,0,0,0,0,0,201,0,0,0,0,13,0,0
0,0,13,0,0,0,0,0,0,0,0,0,0,0,0,0,0,0,201,0,0,0,0,13,0,0
0,0,13,0,0,0,4,0,0,0,0,0,0,0,4,0,0,0,158,0,0,0,0,13,0,0
0,0,13,0,0,0,0,0,0,0,0,0,0,0,0,0,0,0,158,13,13,13,13,13,0,0
0,0,200,0,0,0,0,0,0,0,0,0,0,0,0,0,0,0,158,139,139,0,0,13,0,0
0,0,13,0,0,0,0,0,0,0,0,0,0,0,0,0,0,0,201,0,0,0,0,197,0,0
0,0,13,0,0,0,4,0,0,0,4,0,0,0,4,0,0,0,158,182,182,0,0,13,0,0
0,0,13,0,0,0,0,0,0,0,0,0,0,0,0,0,0,0,158,13,13,13,13,13,199,0
0,0,200,0,0,0,0,0,0,0,0,0,0,0,0,0,0,0,0,0,0,0,0,13,0,0
0,0,13,0,0,0,0,0,0,0,0,0,0,0,0,0,0,0,0,0,0,0,0,13,0,0
0,0,13,158,0,0,158,158,0,0,158,158,201,201,158,158,0,0,158,13,13,13,13,13,0,0
0,0,13,0,0,0,0,13,0,0,164,0,0,0,0,164,0,0,13,0,0,0,0,13,0,0
0,0,13,0,0,0,0,13,0,0,164,0,0,0,0,164,0,0,13,0,0,0,0,13,0,0
0,0,200,0,0,0,198,13,0,0,164,199,0,0,198,164,0,0,13,199,0,0,0,197,0,0
0,0,13,0,0,0,0,13,0,0,164,0,0,0,0,164,0,0,13,0,0,0,0,13,0,0
0,0,13,0,0,0,0,13,0,0,164,0,0,0,0,164,0,0,13,0,0,0,0,13,0,0
0,0,13,158,158,158,158,158,0,0,158,0,0,0,0,158,0,0,158,158,0,0,158,13,0,0
0,0,13,199,0,0,0,0,0,0,0,0,0,0,0,0,0,0,0,0,0,0,198,13,0,0
0,0,13,0,0,0,0,0,0,0,0,0,0,0,0,0,0,0,0,0,0,0,0,13,0,0
0,0,200,0,0,0,0,0,0,0,0,0,0,0,0,0,0,0,0,0,0,0,0,197,0,0
0,0,13,0,0,0,0,0,0,0,0,104,0,0,104,0,0,0,0,0,0,0,0,13,0,0
0,0,13,199,0,0,0,0,0,0,0,0,0,0,0,0,0,0,0,0,0,0,198,13,0,0
0,0,13,158,158,158,158,158,199,0,0,104,0,0,104,0,0,198,158,158,158,158,158,13,0,0
0,0,13,0,0,0,0,158,0,0,0,0,0,0,0,0,0,0,158,0,0,0,0,13,0,0
0,0,13,0,0,0,0,201,0,0,0,104,0,0,104,0,0,0,201,0,0,0,0,197,0,0
0,0,13,0,0,0,0,201,0,0,0,0,0,0,0,0,0,0,201,0,0,0,0,197,0,0
0,0,13,0,0,0,0,158,0,0,0,104,0,0,104,0,0,0,158,0,0,0,0,13,0,0
0,0,13,157,157,157,157,158,199,0,0,0,0,0,0,0,0,198,158,157,157,157,157,13,0,0
0,0,13,0,0,0,0,158,0,0,0,104,0,0,104,0,0,0,158,0,0,0,0,13,0,0
0,0,200,0,0,0,0,201,0,0,0,0,0,0,0,0,0,0,201,0,0,0,0,13,0,0
0,0,200,0,0,0,0,201,0,0,0,0,0,0,0,0,0,0,201,0,0,0,0,13,0,0
0,0,13,0,0,0,0,158,0,0,202,0,0,0,0,202,0,0,158,0,0,0,0,13,0,0
0,0,13,158,158,158,158,158,158,158,158,158,201,201,158,158,158,158,157,157,157,157,157,13,0,0
0,0,13,0,0,13,0,0,0,0,0,13,0,0,13,0,0,13,0,0,0,0,0,13,0,0
0,0,200,0,0,13,0,0,0,0,0,13,199,198,13,0,0,13,0,0,0,0,0,197,0,0
0,0,13,0,0,13,0,0,0,0,0,13,0,0,13,0,0,13,0,0,0,0,0,13,0,0
0,0,13,13,13,13,13,13,13,13,13,13,13,13,13,13,13,13,13,13,13,13,13,13,0,0
0,0,196,0,0,196,0,0,196,0,0,196,0,0,196,0,0,196,0,0,196,0,0,196,0,0
0,0,0,0,0,0,0,0,0,0,0,0,0,0,0,0,0,0,0,0,0,0,0,0,0,0
:endlayer
layer: 8
0,0,0,0,0,0,0,0,0,0,0,0,0,0,0,0,0,0,0,0,0,0,0,0,0,0
0,206,206,216,206,216,206,216,206,216,206,216,206,216,206,216,206,216,206,216,206,216,206,216,206,0
0,210,59,59,59,59,59,59,59,59,59,59,59,59,59,59,59,59,59,59,59,59,59,59,206,0
0,206,59,206,206,206,206,206,206,206,13,206,206,206,206,13,206,206,206,206,206,206,206,59,208,0
0,210,59,206,0,0,0,0,0,206,13,206,0,0,206,13,206,0,0,0,0,0,206,59,206,0
0,206,59,206,0,0,0,0,0,206,13,206,0,0,206,13,206,0,0,0,0,0,206,59,208,0
0,210,59,206,206,206,206,206,206,206,13,206,206,206,206,13,206,206,206,206,206,206,206,59,206,0
0,206,59,158,158,158,158,158,158,158,158,158,158,158,158,158,158,158,158,13,13,13,13,59,208,0
0,210,59,206,0,0,0,0,0,0,0,0,0,0,0,0,0,0,158,206,206,206,206,59,206,0
0,206,59,206,0,0,0,0,0,0,0,0,0,0,0,0,0,0,158,206,206,206,206,59,208,0
0,210,59,206,0,0,202,0,0,0,202,0,0,0,202,0,0,0,158,13,13,13,13,59,206,0
0,206,59,206,0,198,60,213,0,212,60,213,0,212,60,199,0,0,158,206,206,206,206,59,208,0
0,210,59,206,0,0,215,0,0,0,196,0,0,0,215,0,0,0,158,206,0,0,206,59,206,0
0,206,59,206,0,0,0,0,0,0,0,0,0,0,0,0,0,0,158,206,0,0,206,59,208,0
0,210,59,206,0,0,214,0,0,0,0,0,0,0,214,0,0,0,158,206,206,206,206,59,206,0
0,206,59,206,0,198,60,199,0,0,0,0,0,198,60,199,0,0,158,13,13,13,13,59,208,0
0,210,59,206,0,0,215,0,0,0,0,0,0,0,215,0,0,0,158,206,206,206,206,59,206,0
0,206,59,206,0,0,0,0,0,0,0,0,0,0,0,0,0,0,158,206,0,0,206,59,208,0
0,210,59,206,0,0,214,0,0,0,0,0,0,0,214,0,0,0,158,206,0,0,206,59,206,0
0,206,59,206,0,198,60,199,0,0,0,0,0,198,60,199,0,0,158,206,206,206,206,59,208,0
0,210,59,206,0,0,215,0,0,0,0,0,0,0,215,0,0,0,158,13,13,13,13,59,206,0
0,206,59,206,0,0,0,0,0,0,0,0,0,0,0,0,0,0,158,206,206,206,206,59,208,0
0,210,59,206,0,0,214,0,0,0,202,0,0,0,214,0,0,0,158,206,0,0,206,59,206,0
0,206,59,206,0,198,60,213,0,212,60,213,0,212,60,199,0,0,158,206,206,206,206,59,208,0
0,210,59,206,0,0,196,0,0,0,196,0,0,0,196,0,0,0,158,13,13,13,13,59,206,0
0,206,59,206,0,0,0,0,0,0,0,0,0,0,0,0,0,0,158,206,206,206,206,59,208,0
0,210,59,206,0,0,0,0,0,0,0,0,0,0,0,0,0,0,158,206,206,206,206,59,206,0
0,206,59,158,158,158,158,158,158,158,158,158,158,158,158,158,158,158,158,13,13,13,13,59,208,0
0,210,59,206,206,206,206,13,0,0,164,206,206,206,206,164,0,0,13,206,206,206,206,59,206,0
0,206,59,206,0,0,206,13,0,0,164,206,0,0,206,164,0,0,13,206,0,0,206,59,208,0
0,210,59,206,0,0,206,13,199,198,164,206,0,0,206,164,199,198,13,206,0,0,206,59,206,0
0,206,59,206,0,0,206,13,0,0,164,206,0,0,206,164,0,0,13,206,0,0,206,59,208,0
0,210,59,206,206,206,206,13,0,0,164,206,206,206,206,164,0,0,13,206,206,206,206,59,206,0
0,206,59,158,158,158,158,158,158,158,158,158,158,158,158,158,158,158,158,158,158,158,158,59,208,0
0,0,59,206,206,206,206,206,206,206,206,206,206,206,206,206,206,206,206,206,206,206,206,59,206,0
0,0,59,206,0,0,0,0,206,0,0,0,0,0,0,0,0,206,0,0,0,0,206,59,208,0
0,198,59,206,0,0,0,0,206,0,206,206,206,206,206,206,0,206,0,0,0,0,206,59,206,0
0,0,59,206,0,0,0,0,206,0,206,211,211,211,211,206,0,206,0,0,0,0,206,59,208,0
0,0,59,206,206,206,206,206,206,0,206,211,0,0,211,206,0,206,206,206,206,206,206,59,206,0
0,206,59,158,158,158,158,158,206,0,206,211,0,0,211,206,0,206,158,158,158,158,158,59,208,0
0,210,59,206,206,206,206,158,206,0,206,211,0,0,211,206,0,206,158,206,206,206,206,59,206,0
0,206,59,206,0,0,206,158,206,0,206,211,0,0,211,206,0,206,158,206,0,0,206,59,208,0
0,210,59,206,0,0,206,158,206,0,206,211,0,0,211,206,0,206,158,206,0,0,206,59,206,0
0,206,59,206,206,206,206,158,206,0,206,211,0,0,211,206,0,206,158,206,206,206,206,59,208,0
0,210,59,157,157,157,157,158,206,0,206,211,0,0,211,206,0,206,158,157,157,157,157,59,206,0
0,206,59,206,206,206,206,158,206,0,206,211,211,211,211,206,0,206,158,206,206,206,206,59,208,0
0,210,59,206,0,0,206,158,206,0,206,206,206,206,206,206,0,206,158,206,0,0,206,59,206,0
0,206,59,206,0,0,206,158,206,0,0,0,0,0,0,0,0,206,158,206,0,0,206,59,208,0
0,210,59,206,206,206,206,158,206,206,206,206,206,206,206,206,206,206,158,206,206,206,206,59,206,0
0,206,59,158,158,158,158,158,158,158,158,158,158,158,158,158,158,158,157,157,157,157,157,59,208,0
0,210,59,0,0,13,0,0,196,0,0,13,209,209,13,0,0,13,0,0,196,0,0,59,206,0
0,206,59,199,0,13,0,0,0,0,0,13,209,209,13,199,198,13,0,0,0,0,0,59,208,0
0,210,59,0,0,13,0,0,0,0,0,13,209,209,13,0,0,13,0,0,0,0,0,59,206,0
0,206,59,59,59,59,59,59,59,59,59,59,59,59,59,59,59,59,59,59,59,59,59,59,208,0
0,206,207,206,207,206,207,206,207,206,207,206,207,206,207,206,207,206,207,206,207,206,207,206,206,0
0,0,0,0,0,0,0,0,0,0,0,0,0,0,0,0,0,0,0,0,0,0,0,0,0,0
:endlayer
layer: 9
0,0,0,0,0,0,0,0,0,0,0,0,0,0,0,0,0,0,0,0,0,0,0,0,0,0
0,0,0,0,0,0,0,0,0,0,0,0,0,0,0,0,0,0,0,0,0,0,0,0,0,0
0,0,211,211,211,211,211,211,211,211,211,211,211,211,211,211,211,211,211,211,211,211,211,211,0,0
0,0,211,217,217,217,217,217,217,217,217,217,217,217,217,217,217,217,217,217,217,217,217,211,0,0
0,0,211,217,224,224,224,224,224,224,13,223,223,223,223,13,209,209,209,209,209,209,217,211,0,0
0,0,211,217,224,224,224,224,224,224,13,223,223,223,223,13,209,209,209,209,209,209,217,211,0,0
0,0,211,217,224,224,224,224,224,224,13,223,223,223,223,13,209,209,209,209,209,209,217,211,0,0
0,0,211,217,13,13,13,13,13,13,13,13,13,13,13,13,13,13,13,13,13,13,217,211,0,0
0,0,211,217,223,224,222,224,223,224,222,224,223,224,222,224,223,223,13,223,223,223,217,211,0,0
0,0,211,217,224,222,222,222,224,222,222,222,224,222,222,222,224,223,13,223,223,223,217,211,0,0
0,0,211,217,222,221,222,221,222,221,222,221,222,221,222,221,222,224,13,13,13,13,217,211,0,0
0,0,211,217,222,222,225,225,225,225,225,225,225,225,225,222,222,222,13,219,219,219,217,211,0,0
0,0,211,217,222,221,225,206,206,206,207,206,206,206,225,221,222,224,13,219,219,219,217,211,0,0
0,0,211,217,224,222,225,206,0,0,0,0,0,206,225,222,224,223,13,219,219,219,217,211,0,0
0,0,211,217,222,221,225,206,0,0,0,0,0,206,225,221,222,224,13,219,219,219,217,211,0,0
0,0,211,217,222,222,225,208,0,0,0,0,0,210,225,222,222,222,13,13,13,13,217,211,0,0
0,0,211,217,222,221,225,206,0,0,0,0,0,206,225,221,222,224,13,218,218,218,217,211,0,0
0,0,211,217,224,222,225,206,0,0,0,0,0,206,225,222,224,223,13,218,218,218,217,211,0,0
0,0,211,217,222,221,225,206,0,0,0,0,0,206,225,221,222,224,13,218,218,218,217,211,0,0
0,0,211,217,222,222,225,208,0,0,0,0,0,210,225,222,222,222,13,218,218,218,217,211,0,0
0,0,211,217,222,221,225,206,0,0,0,0,0,206,225,221,222,224,13,13,13,13,217,211,0,0
0,0,211,217,224,222,225,206,0,0,0,0,0,206,225,222,224,223,13,221,221,221,217,211,0,0
0,0,211,217,222,221,225,206,206,206,216,206,206,206,225,221,222,224,13,221,59,59,217,211,0,0
0,0,211,217,222,222,225,225,225,225,225,225,225,225,225,222,222,222,13,221,221,221,217,211,0,0
0,0,211,217,222,221,222,221,222,221,222,221,222,221,222,221,222,224,13,13,13,13,217,211,0,0
0,0,211,217,224,222,222,222,224,222,222,222,224,222,222,222,224,223,13,217,217,217,217,211,0,0
0,0,211,217,223,224,222,224,223,224,222,224,223,224,222,224,223,223,13,217,217,217,217,211,0,0
0,0,211,217,13,13,13,13,13,13,13,13,13,13,13,13,13,13,13,13,13,13,217,211,0,0
0,0,211,217,222,222,222,13,221,221,13,219,219,219,219,13,221,221,13,218,218,218,217,211,0,0
0,0,211,217,222,222,222,13,221,221,13,219,219,219,219,13,221,221,13,218,218,218,217,211,0,0
0,0,211,217,222,222,222,13,221,221,13,219,219,219,219,13,221,221,13,218,218,218,217,211,0,0
0,0,211,217,222,222,222,13,221,221,13,219,219,219,219,13,221,221,13,218,218,218,217,211,0,0
0,0,211,217,222,222,222,13,221,221,13,219,219,219,219,13,221,221,13,218,218,218,217,211,0,0
0,211,211,217,13,13,13,13,13,13,13,13,13,13,13,13,13,13,13,13,13,13,217,211,0,0
0,217,217,217,217,217,217,217,217,217,217,217,217,217,217,217,217,217,209,209,209,209,217,211,0,0
0,206,59,217,220,220,220,220,217,211,211,211,211,211,211,211,211,217,209,209,209,209,217,211,0,0
0,0,59,217,220,220,220,220,217,211,0,0,0,0,0,0,211,217,209,209,209,209,217,211,0,0
0,206,59,217,220,220,220,220,217,211,0,0,0,0,0,0,211,217,209,209,209,209,217,211,0,0
0,217,217,217,217,217,217,217,217,211,0,0,0,0,0,0,211,217,209,209,209,209,217,211,0,0
0,211,211,217,13,13,13,13,217,211,0,0,0,0,0,0,211,217,13,13,13,13,217,211,0,0
0,0,211,217,220,220,220,13,217,211,0,0,0,0,0,0,211,217,13,219,219,219,217,211,0,0
0,0,211,217,220,220,220,13,217,211,0,0,0,0,0,0,211,217,13,219,219,219,217,211,0,0
0,0,211,217,220,220,220,13,217,211,0,0,0,0,0,0,211,217,13,219,219,219,217,211,0,0
0,0,211,217,220,220,220,13,217,211,0,0,0,0,0,0,211,217,13,219,219,219,217,211,0,0
0,0,211,217,13,13,13,13,217,211,0,0,0,0,0,0,211,217,13,13,13,13,217,211,0,0
0,0,211,217,209,209,209,13,217,211,0,0,0,0,0,0,211,217,13,218,218,218,217,211,0,0
0,0,211,217,209,209,209,13,217,211,0,0,0,0,0,0,211,217,13,218,218,218,217,211,0,0
0,0,211,217,209,209,209,13,217,211,211,211,211,211,211,211,211,217,13,218,218,218,217,211,0,0
0,0,211,217,209,209,209,13,217,217,217,217,217,217,217,217,217,217,13,218,218,218,217,211,0,0
0,0,211,217,13,13,13,13,13,13,13,13,13,13,13,13,13,13,13,13,13,13,217,211,0,0
0,0,211,217,217,13,217,217,217,217,217,13,209,209,13,217,217,13,217,217,217,217,217,211,0,0
0,0,211,217,217,13,217,217,217,217,217,13,209,209,13,217,217,13,217,217,217,217,217,211,0,0
0,0,211,217,217,217,217,217,217,217,217,217,217,217,217,217,217,217,217,217,217,217,217,211,0,0
0,0,211,211,211,211,211,211,211,211,211,211,211,211,211,211,211,211,211,211,211,211,211,211,0,0
0,0,0,0,0,0,0,0,0,0,0,0,0,0,0,0,0,0,0,0,0,0,0,0,0,0
0,0,0,0,0,0,0,0,0,0,0,0,0,0,0,0,0,0,0,0,0,0,0,0,0,0
:endlayer
layer: 10
0,0,0,0,0,0,0,0,0,0,0,0,0,0,0,0,0,0,0,0,0,0,0,0,0,0
0,0,0,0,0,0,0,0,0,0,0,0,0,0,0,0,0,0,0,0,0,0,0,0,0,0
0,0,0,0,0,0,0,0,0,0,0,0,0,0,0,0,0,0,0,0,0,0,0,0,0,0
0,0,0,0,0,0,0,0,0,0,0,0,0,0,0,0,0,0,0,0,0,0,0,0,0,0
0,0,0,0,211,211,211,211,211,211,211,211,211,211,211,211,211,211,211,211,211,211,0,0,0,0
0,0,0,0,211,217,217,217,217,217,217,217,217,217,217,217,217,217,217,217,217,211,0,0,0,0
0,0,0,0,211,217,217,217,217,217,217,217,217,217,217,217,217,217,217,217,217,211,0,0,0,0
0,0,0,0,211,217,217,217,217,217,217,217,217,217,217,217,217,217,217,217,217,211,0,0,0,0
0,0,0,0,211,217,217,217,217,217,217,217,217,217,217,217,217,217,217,217,217,211,0,0,0,0
0,0,0,0,211,217,217,217,217,217,217,217,217,217,217,217,217,217,217,217,217,211,0,0,0,0
0,0,0,0,211,217,217,217,217,217,217,217,217,217,217,217,217,217,217,217,217,211,0,0,0,0
0,0,0,0,211,217,211,211,211,211,211,211,211,211,211,217,217,217,217,217,217,211,0,0,0,0
0,0,0,0,211,217,211,0,0,0,0,0,0,0,211,217,217,217,217,217,217,211,0,0,0,0
0,0,0,0,211,217,211,0,0,0,0,0,0,0,211,217,217,217,217,217,217,211,0,0,0,0
0,0,0,0,211,217,211,0,0,0,0,0,0,0,211,217,217,217,217,217,217,211,0,0,0,0
0,0,0,0,211,217,211,0,0,0,0,0,0,0,211,217,217,217,217,217,217,211,0,0,0,0
0,0,0,0,211,217,211,0,0,0,0,0,0,0,211,217,217,217,217,217,217,211,0,0,0,0
0,0,0,0,211,217,211,0,0,0,0,0,0,0,211,217,217,217,217,217,217,211,0,0,0,0
0,0,0,0,211,217,211,0,0,0,0,0,0,0,211,217,217,217,217,217,217,211,0,0,0,0
0,0,0,0,211,217,211,0,0,0,0,0,0,0,211,217,217,217,217,217,217,211,0,0,0,0
0,0,0,0,211,217,211,0,0,0,0,0,0,0,211,217,217,217,217,217,217,211,0,0,0,0
0,0,0,0,211,217,211,0,0,0,0,0,0,0,211,217,217,217,217,217,217,211,0,0,0,0
0,0,0,0,211,217,211,0,0,0,0,0,0,0,211,217,217,217,217,217,217,211,0,0,0,0
0,0,0,0,211,217,211,211,211,211,211,211,211,211,211,217,217,217,217,217,217,211,0,0,0,0
0,0,0,0,211,217,217,217,217,217,217,217,217,217,217,217,217,217,217,217,217,211,0,0,0,0
0,0,0,0,211,217,217,217,217,217,217,217,217,217,217,217,217,217,217,217,217,211,0,0,0,0
0,0,0,0,211,217,217,217,217,217,217,217,217,217,217,217,217,217,217,217,217,211,0,0,0,0
0,0,0,0,211,217,217,217,217,217,217,217,217,217,217,217,217,217,217,217,217,211,0,0,0,0
0,0,0,0,211,217,217,217,217,217,217,217,217,217,217,217,217,217,217,217,217,211,0,0,0,0
0,0,0,0,211,217,217,217,217,217,217,217,217,217,217,217,217,217,217,217,217,211,0,0,0,0
0,0,0,0,211,217,217,217,217,217,217,217,217,217,217,217,217,217,217,217,217,211,0,0,0,0
0,0,0,0,211,217,217,217,217,217,217,217,217,217,217,217,217,217,217,217,217,211,0,0,0,0
0,0,0,0,211,217,217,217,217,217,217,217,217,217,217,217,217,217,217,217,217,211,0,0,0,0
0,0,0,0,211,217,217,211,211,211,211,211,211,211,211,211,211,211,211,217,217,211,0,0,0,0
0,0,0,0,211,217,217,211,0,0,0,0,0,0,0,0,0,0,211,217,217,211,0,0,0,0
0,211,211,211,211,217,217,211,0,0,0,0,0,0,0,0,0,0,211,217,217,211,0,0,0,0
0,217,217,217,217,217,217,211,0,0,0,0,0,0,0,0,0,0,211,217,217,211,0,0,0,0
0,211,211,211,211,217,217,211,0,0,0,0,0,0,0,0,0,0,211,217,217,211,0,0,0,0
0,0,0,0,211,217,217,211,0,0,0,0,0,0,0,0,0,0,211,217,217,211,0,0,0,0
0,0,0,0,211,217,217,211,0,0,0,0,0,0,0,0,0,0,211,217,217,211,0,0,0,0
0,0,0,0,211,217,217,211,0,0,0,0,0,0,0,0,0,0,211,217,217,211,0,0,0,0
0,0,0,0,211,217,217,211,0,0,0,0,0,0,0,0,0,0,211,217,217,211,0,0,0,0
0,0,0,0,211,217,217,211,0,0,0,0,0,0,0,0,0,0,211,217,217,211,0,0,0,0
0,0,0,0,211,217,217,211,0,0,0,0,0,0,0,0,0,0,211,217,217,211,0,0,0,0
0,0,0,0,211,217,217,211,0,0,0,0,0,0,0,0,0,0,211,217,217,211,0,0,0,0
0,0,0,0,211,217,217,211,0,0,0,0,0,0,0,0,0,0,211,217,217,211,0,0,0,0
0,0,0,0,211,217,217,211,0,0,0,0,0,0,0,0,0,0,211,217,217,211,0,0,0,0
0,0,0,0,211,217,217,211,0,0,0,0,0,0,0,0,0,0,211,217,217,211,0,0,0,0
0,0,0,0,211,217,217,211,0,0,0,0,0,0,0,0,0,0,211,217,217,211,0,0,0,0
0,0,0,0,211,217,217,211,211,211,211,211,211,211,211,211,211,211,211,217,217,211,0,0,0,0
0,0,0,0,211,217,217,217,217,217,217,217,217,217,217,217,217,217,217,217,217,211,0,0,0,0
0,0,0,0,211,211,211,211,211,211,211,211,211,211,211,211,211,211,211,211,211,211,0,0,0,0
0,0,0,0,0,0,0,0,0,0,0,0,0,0,0,0,0,0,0,0,0,0,0,0,0,0
0,0,0,0,0,0,0,0,0,0,0,0,0,0,0,0,0,0,0,0,0,0,0,0,0,0
0,0,0,0,0,0,0,0,0,0,0,0,0,0,0,0,0,0,0,0,0,0,0,0,0,0
0,0,0,0,0,0,0,0,0,0,0,0,0,0,0,0,0,0,0,0,0,0,0,0,0,0
:endlayer
layer: 11
0,0,0,0,0,0,0,0,0,0,0,0,0,0,0,0,0,0,0,0,0,0,0,0,0,0
0,0,0,0,0,0,0,0,0,0,0,0,0,0,0,0,0,0,0,0,0,0,0,0,0,0
0,0,0,0,0,0,0,0,0,0,0,0,0,0,0,0,0,0,0,0,0,0,0,0,0,0
0,0,0,0,0,0,0,0,0,0,0,0,0,0,0,0,0,0,0,0,0,0,0,0,0,0
0,0,0,0,0,0,0,0,0,0,0,0,0,0,0,0,0,0,0,0,0,0,0,0,0,0
0,0,0,0,0,0,0,0,0,0,0,0,0,0,0,0,0,0,0,0,0,0,0,0,0,0
0,0,0,0,0,0,211,211,211,211,211,211,211,211,211,211,211,211,211,211,0,0,0,0,0,0
0,0,0,0,0,0,211,217,217,217,217,217,217,217,217,217,217,217,217,211,0,0,0,0,0,0
0,0,0,0,0,0,211,217,217,217,217,217,217,217,217,217,217,217,217,211,0,0,0,0,0,0
0,0,0,0,0,0,211,211,211,211,211,211,211,211,211,211,211,217,217,211,0,0,0,0,0,0
0,0,0,0,0,0,0,0,0,0,0,0,0,0,0,0,211,217,217,211,0,0,0,0,0,0
0,0,0,0,0,0,0,0,0,0,0,0,0,0,0,0,211,217,217,211,0,0,0,0,0,0
0,0,0,0,0,0,0,0,0,0,0,0,0,0,0,0,211,217,217,211,0,0,0,0,0,0
0,0,0,0,0,0,0,0,0,0,0,0,0,0,0,0,211,217,217,211,0,0,0,0,0,0
0,0,0,0,0,0,0,0,0,0,0,0,0,0,0,0,211,217,217,211,0,0,0,0,0,0
0,0,0,0,0,0,0,0,0,0,0,0,0,0,0,0,211,217,217,211,0,0,0,0,0,0
0,0,0,0,0,0,0,0,0,0,0,0,0,0,0,0,211,217,217,211,0,0,0,0,0,0
0,0,0,0,0,0,0,0,0,0,0,0,0,0,0,0,211,217,217,211,0,0,0,0,0,0
0,0,0,0,0,0,0,0,0,0,0,0,0,0,0,0,211,217,217,211,0,0,0,0,0,0
0,0,0,0,0,0,0,0,0,0,0,0,0,0,0,0,211,217,217,211,0,0,0,0,0,0
0,0,0,0,0,0,0,0,0,0,0,0,0,0,0,0,211,217,217,211,0,0,0,0,0,0
0,0,0,0,0,0,0,0,0,0,0,0,0,0,0,0,211,217,217,211,0,0,0,0,0,0
0,0,0,0,0,0,0,0,0,0,0,0,0,0,0,0,211,217,217,211,0,0,0,0,0,0
0,0,0,0,0,0,0,0,0,0,0,0,0,0,0,0,211,217,217,211,0,0,0,0,0,0
0,0,0,0,0,0,0,0,0,0,0,0,0,0,0,0,211,217,217,211,0,0,0,0,0,0
0,0,0,0,0,0,211,211,211,211,211,211,211,211,211,211,211,217,217,211,0,0,0,0,0,0
0,0,0,0,0,0,211,217,217,217,217,217,217,217,217,217,217,217,217,211,0,0,0,0,0,0
0,0,0,0,0,0,211,217,217,217,217,217,217,217,217,217,217,217,217,211,0,0,0,0,0,0
0,0,0,0,0,0,211,217,217,217,217,217,217,217,217,217,217,217,217,211,0,0,0,0,0,0
0,0,0,0,0,0,211,217,217,217,217,217,217,217,217,217,217,217,217,211,0,0,0,0,0,0
0,0,0,0,0,0,211,217,217,217,217,217,217,217,217,217,217,217,217,211,0,0,0,0,0,0
0,0,0,0,0,0,211,211,211,211,211,211,211,211,211,211,211,211,211,211,0,0,0,0,0,0
0,0,0,0,0,0,0,0,0,0,0,0,0,0,0,0,0,0,0,0,0,0,0,0,0,0
0,0,0,0,0,0,0,0,0,0,0,0,0,0,0,0,0,0,0,0,0,0,0,0,0,0
0,0,0,0,0,0,0,0,0,0,0,0,0,0,0,0,0,0,0,0,0,0,0,0,0,0
0,0,0,0,0,0,0,0,0,0,0,0,0,0,0,0,0,0,0,0,0,0,0,0,0,0
0,0,0,0,0,0,0,0,0,0,0,0,0,0,0,0,0,0,0,0,0,0,0,0,0,0
0,0,0,0,0,0,0,0,0,0,0,0,0,0,0,0,0,0,0,0,0,0,0,0,0,0
0,0,0,0,0,0,0,0,0,0,0,0,0,0,0,0,0,0,0,0,0,0,0,0,0,0
0,0,0,0,0,0,0,0,0,0,0,0,0,0,0,0,0,0,0,0,0,0,0,0,0,0
0,0,0,0,0,0,0,0,0,0,0,0,0,0,0,0,0,0,0,0,0,0,0,0,0,0
0,0,0,0,0,0,0,0,0,0,0,0,0,0,0,0,0,0,0,0,0,0,0,0,0,0
0,0,0,0,0,0,0,0,0,0,0,0,0,0,0,0,0,0,0,0,0,0,0,0,0,0
0,0,0,0,0,0,0,0,0,0,0,0,0,0,0,0,0,0,0,0,0,0,0,0,0,0
0,0,0,0,0,0,0,0,0,0,0,0,0,0,0,0,0,0,0,0,0,0,0,0,0,0
0,0,0,0,0,0,0,0,0,0,0,0,0,0,0,0,0,0,0,0,0,0,0,0,0,0
0,0,0,0,0,0,0,0,0,0,0,0,0,0,0,0,0,0,0,0,0,0,0,0,0,0
0,0,0,0,0,0,0,0,0,0,0,0,0,0,0,0,0,0,0,0,0,0,0,0,0,0
0,0,0,0,0,0,0,0,0,0,0,0,0,0,0,0,0,0,0,0,0,0,0,0,0,0
0,0,0,0,0,0,0,0,0,0,0,0,0,0,0,0,0,0,0,0,0,0,0,0,0,0
0,0,0,0,0,0,0,0,0,0,0,0,0,0,0,0,0,0,0,0,0,0,0,0,0,0
0,0,0,0,0,0,0,0,0,0,0,0,0,0,0,0,0,0,0,0,0,0,0,0,0,0
0,0,0,0,0,0,0,0,0,0,0,0,0,0,0,0,0,0,0,0,0,0,0,0,0,0
0,0,0,0,0,0,0,0,0,0,0,0,0,0,0,0,0,0,0,0,0,0,0,0,0,0
0,0,0,0,0,0,0,0,0,0,0,0,0,0,0,0,0,0,0,0,0,0,0,0,0,0
0,0,0,0,0,0,0,0,0,0,0,0,0,0,0,0,0,0,0,0,0,0,0,0,0,0
:endlayer
layer: 12
0,0,0,0,0,0,0,0,0,0,0,0,0,0,0,0,0,0,0,0,0,0,0,0,0,0
0,0,0,0,0,0,0,0,0,0,0,0,0,0,0,0,0,0,0,0,0,0,0,0,0,0
0,0,0,0,0,0,0,0,0,0,0,0,0,0,0,0,0,0,0,0,0,0,0,0,0,0
0,0,0,0,0,0,0,0,0,0,0,0,0,0,0,0,0,0,0,0,0,0,0,0,0,0
0,0,0,0,0,0,0,0,0,0,0,0,0,0,0,0,0,0,0,0,0,0,0,0,0,0
0,0,0,0,0,0,0,0,0,0,0,0,0,0,0,0,0,0,0,0,0,0,0,0,0,0
0,0,0,0,0,0,0,0,0,0,0,0,0,0,0,0,0,0,0,0,0,0,0,0,0,0
0,0,0,0,0,0,0,0,0,0,0,0,0,0,0,0,0,0,0,0,0,0,0,0,0,0
0,0,0,0,0,0,0,0,0,0,0,0,0,0,0,0,0,0,0,0,0,0,0,0,0,0
0,0,0,0,0,0,0,0,0,0,0,0,0,0,0,0,0,0,0,0,0,0,0,0,0,0
0,0,0,0,0,0,0,0,0,0,0,0,0,0,0,0,0,0,0,0,0,0,0,0,0,0
0,0,0,0,0,0,0,0,0,0,0,0,0,0,0,0,0,0,0,0,0,0,0,0,0,0
0,0,0,0,0,0,0,0,0,0,0,0,0,0,0,0,0,0,0,0,0,0,0,0,0,0
0,0,0,0,0,0,0,0,0,0,0,0,0,0,0,0,0,0,0,0,0,0,0,0,0,0
0,0,0,0,0,0,0,0,0,0,0,0,0,0,0,0,0,0,0,0,0,0,0,0,0,0
0,0,0,0,0,0,0,0,0,0,0,0,0,0,0,0,0,0,0,0,0,0,0,0,0,0
0,0,0,0,0,0,0,0,0,0,0,0,0,0,0,0,0,0,0,0,0,0,0,0,0,0
0,0,0,0,0,0,0,0,0,0,0,0,0,0,0,0,0,0,0,0,0,0,0,0,0,0
0,0,0,0,0,0,0,0,0,0,0,0,0,0,0,0,0,0,0,0,0,0,0,0,0,0
0,0,0,0,0,0,0,0,0,0,0,0,0,0,0,0,0,0,0,0,0,0,0,0,0,0
0,0,0,0,0,0,0,0,0,0,0,0,0,0,0,0,0,0,0,0,0,0,0,0,0,0
0,0,0,0,0,0,0,0,0,0,0,0,0,0,0,0,0,0,0,0,0,0,0,0,0,0
0,0,0,0,0,0,0,0,0,0,0,0,0,0,0,0,0,0,0,0,0,0,0,0,0,0
0,0,0,0,0,0,0,0,0,0,0,0,0,0,0,0,0,0,0,0,0,0,0,0,0,0
0,0,0,0,0,0,0,0,0,0,0,0,0,0,0,0,0,0,0,0,0,0,0,0,0,0
0,0,0,0,0,0,0,0,0,0,0,0,0,0,0,0,0,0,0,0,0,0,0,0,0,0
0,0,0,0,0,0,0,0,0,0,0,0,0,0,0,0,0,0,0,0,0,0,0,0,0,0
0,0,0,0,0,0,0,0,211,211,211,211,211,211,211,211,211,211,0,0,0,0,0,0,0,0
0,0,0,0,0,0,0,0,211,217,217,217,217,217,217,217,217,211,0,0,0,0,0,0,0,0
0,0,0,0,0,0,0,0,211,211,211,211,211,211,211,211,211,211,0,0,0,0,0,0,0,0
0,0,0,0,0,0,0,0,0,0,0,0,0,0,0,0,0,0,0,0,0,0,0,0,0,0
0,0,0,0,0,0,0,0,0,0,0,0,0,0,0,0,0,0,0,0,0,0,0,0,0,0
0,0,0,0,0,0,0,0,0,0,0,0,0,0,0,0,0,0,0,0,0,0,0,0,0,0
0,0,0,0,0,0,0,0,0,0,0,0,0,0,0,0,0,0,0,0,0,0,0,0,0,0
0,0,0,0,0,0,0,0,0,0,0,0,0,0,0,0,0,0,0,0,0,0,0,0,0,0
0,0,0,0,0,0,0,0,0,0,0,0,0,0,0,0,0,0,0,0,0,0,0,0,0,0
0,0,0,0,0,0,0,0,0,0,0,0,0,0,0,0,0,0,0,0,0,0,0,0,0,0
0,0,0,0,0,0,0,0,0,0,0,0,0,0,0,0,0,0,0,0,0,0,0,0,0,0
0,0,0,0,0,0,0,0,0,0,0,0,0,0,0,0,0,0,0,0,0,0,0,0,0,0
0,0,0,0,0,0,0,0,0,0,0,0,0,0,0,0,0,0,0,0,0,0,0,0,0,0
0,0,0,0,0,0,0,0,0,0,0,0,0,0,0,0,0,0,0,0,0,0,0,0,0,0
0,0,0,0,0,0,0,0,0,0,0,0,0,0,0,0,0,0,0,0,0,0,0,0,0,0
0,0,0,0,0,0,0,0,0,0,0,0,0,0,0,0,0,0,0,0,0,0,0,0,0,0
0,0,0,0,0,0,0,0,0,0,0,0,0,0,0,0,0,0,0,0,0,0,0,0,0,0
0,0,0,0,0,0,0,0,0,0,0,0,0,0,0,0,0,0,0,0,0,0,0,0,0,0
0,0,0,0,0,0,0,0,0,0,0,0,0,0,0,0,0,0,0,0,0,0,0,0,0,0
0,0,0,0,0,0,0,0,0,0,0,0,0,0,0,0,0,0,0,0,0,0,0,0,0,0
0,0,0,0,0,0,0,0,0,0,0,0,0,0,0,0,0,0,0,0,0,0,0,0,0,0
0,0,0,0,0,0,0,0,0,0,0,0,0,0,0,0,0,0,0,0,0,0,0,0,0,0
0,0,0,0,0,0,0,0,0,0,0,0,0,0,0,0,0,0,0,0,0,0,0,0,0,0
0,0,0,0,0,0,0,0,0,0,0,0,0,0,0,0,0,0,0,0,0,0,0,0,0,0
0,0,0,0,0,0,0,0,0,0,0,0,0,0,0,0,0,0,0,0,0,0,0,0,0,0
0,0,0,0,0,0,0,0,0,0,0,0,0,0,0,0,0,0,0,0,0,0,0,0,0,0
0,0,0,0,0,0,0,0,0,0,0,0,0,0,0,0,0,0,0,0,0,0,0,0,0,0
0,0,0,0,0,0,0,0,0,0,0,0,0,0,0,0,0,0,0,0,0,0,0,0,0,0
0,0,0,0,0,0,0,0,0,0,0,0,0,0,0,0,0,0,0,0,0,0,0,0,0,0
:endlayer

#### RULES ####
rule:
plugin=vanillaBlocks
number=1
data:
JSON:{blockState:{blockName:"minecraft:stone",properties:{variant:"stone"}}}
:enddata
:endrule

rule:
plugin=vanillaBlocks
number=2
data:
JSON:{blockState:{blockName:"minecraft:dirt",properties:{variant:"dirt",snowy:"false"}}}
:enddata
:endrule

rule:
plugin=vanillaBlocks
number=3
data:
JSON:{blockState:{blockName:"minecraft:grass",properties:{snowy:"false"}}}
:enddata
:endrule

rule:
plugin=vanillaBlocks
number=4
data:
JSON:{blockState:{blockName:"minecraft:quartz_block",properties:{variant:"lines_y"}}}
:enddata
:endrule

rule:
plugin=vanillaBlocks
number=5
data:
JSON:{blockState:{blockName:"minecraft:quartz_stairs",properties:{half:"bottom",shape:"straight",facing:"north"}}}
:enddata
:endrule

rule:
plugin=vanillaBlocks
number=6
data:
JSON:{blockState:{blockName:"minecraft:quartz_stairs",properties:{half:"bottom",shape:"straight",facing:"west"}}}
:enddata
:endrule

rule:
plugin=fluid
number=7
data:
JSON:{blockState:{blockName:"minecraft:water",properties:{level:"0"}}}
:enddata
:endrule

rule:
plugin=vanillaBlocks
number=8
data:
JSON:{blockState:{blockName:"minecraft:quartz_stairs",properties:{half:"bottom",shape:"straight",facing:"east"}}}
:enddata
:endrule

rule:
plugin=vanillaBlocks
number=9
data:
JSON:{blockState:{blockName:"minecraft:quartz_stairs",properties:{half:"bottom",shape:"straight",facing:"south"}}}
:enddata
:endrule

rule:
plugin=vanillaBlocks
number=10
data:
JSON:{blockState:{blockName:"minecraft:stonebrick",properties:{variant:"stonebrick"}}}
:enddata
:endrule

rule:
plugin=vanillaBlocks
number=11
data:
JSON:{blockState:{blockName:"minecraft:stone",properties:{variant:"smooth_andesite"}}}
:enddata
:endrule

rule:
plugin=vanillaBlocks
number=12
data:
JSON:{blockState:{blockName:"minecraft:stonebrick",properties:{variant:"chiseled_stonebrick"}}}
:enddata
:endrule

rule:
plugin=vanillaBlocks
number=13
data:
JSON:{blockState:{blockName:"minecraft:stained_hardened_clay",properties:{color:"white"}}}
:enddata
:endrule

rule:
plugin=vanillaBlocks
number=14
data:
JSON:{blockState:{blockName:"minecraft:stone",properties:{variant:"smooth_granite"}}}
:enddata
:endrule

rule:
plugin=vanillaBlocks
number=15
data:
JSON:{blockState:{blockName:"minecraft:stone",properties:{variant:"andesite"}}}
:enddata
:endrule

rule:
plugin=vanillaBlocks
number=16
data:
JSON:{blockState:{blockName:"minecraft:silver_glazed_terracotta",properties:{facing:"west"}}}
:enddata
:endrule

rule:
plugin=vanillaBlocks
number=17
data:
JSON:{blockState:{blockName:"minecraft:silver_glazed_terracotta",properties:{facing:"north"}}}
:enddata
:endrule

rule:
plugin=vanillaBlocks
number=18
data:
JSON:{blockState:{blockName:"minecraft:silver_glazed_terracotta",properties:{facing:"south"}}}
:enddata
:endrule

rule:
plugin=vanillaBlocks
number=19
data:
JSON:{blockState:{blockName:"minecraft:silver_glazed_terracotta",properties:{facing:"east"}}}
:enddata
:endrule

rule:
plugin=vanillaBlocks
number=20
data:
JSON:{blockState:{blockName:"minecraft:prismarine",properties:{variant:"dark_prismarine"}}}
:enddata
:endrule

rule:
plugin=vanillaBlocks
number=21
data:
JSON:{blockState:{blockName:"minecraft:prismarine",properties:{variant:"prismarine_bricks"}}}
:enddata
:endrule

rule:
plugin=vanillaBlocks
number=22
data:
JSON:{blockState:{blockName:"minecraft:red_glazed_terracotta",properties:{facing:"west"}}}
:enddata
:endrule

rule:
plugin=vanillaBlocks
number=23
data:
JSON:{blockState:{blockName:"minecraft:red_glazed_terracotta",properties:{facing:"north"}}}
:enddata
:endrule

rule:
plugin=vanillaBlocks
number=24
data:
JSON:{blockState:{blockName:"minecraft:prismarine",properties:{variant:"prismarine"}}}
:enddata
:endrule

rule:
plugin=vanillaBlocks
number=25
data:
JSON:{blockState:{blockName:"minecraft:red_glazed_terracotta",properties:{facing:"south"}}}
:enddata
:endrule

rule:
plugin=vanillaBlocks
number=26
data:
JSON:{blockState:{blockName:"minecraft:red_glazed_terracotta",properties:{facing:"east"}}}
:enddata
:endrule

rule:
plugin=vanillaBlocks
number=27
data:
JSON:{blockState:{blockName:"minecraft:orange_glazed_terracotta",properties:{facing:"north"}}}
:enddata
:endrule

rule:
plugin=vanillaBlocks
number=28
data:
JSON:{blockState:{blockName:"minecraft:orange_glazed_terracotta",properties:{facing:"east"}}}
:enddata
:endrule

rule:
plugin=vanillaBlocks
number=29
data:
JSON:{blockState:{blockName:"minecraft:quartz_block",properties:{variant:"chiseled"}}}
:enddata
:endrule

rule:
plugin=vanillaBlocks
number=30
data:
JSON:{blockState:{blockName:"minecraft:quartz_block",properties:{variant:"lines_x"}}}
:enddata
:endrule

rule:
plugin=vanillaBlocks
number=31
data:
JSON:{blockState:{blockName:"minecraft:orange_glazed_terracotta",properties:{facing:"west"}}}
:enddata
:endrule

rule:
plugin=vanillaBlocks
number=32
data:
JSON:{blockState:{blockName:"minecraft:orange_glazed_terracotta",properties:{facing:"south"}}}
:enddata
:endrule

rule:
plugin=vanillaBlocks
number=33
data:
JSON:{blockState:{blockName:"minecraft:quartz_block",properties:{variant:"lines_z"}}}
:enddata
:endrule

rule:
plugin=vanillaBlocks
number=34
data:
JSON:{blockState:{blockName:"minecraft:light_blue_glazed_terracotta",properties:{facing:"north"}}}
:enddata
:endrule

rule:
plugin=vanillaBlocks
number=35
data:
JSON:{blockState:{blockName:"minecraft:light_blue_glazed_terracotta",properties:{facing:"east"}}}
:enddata
:endrule

rule:
plugin=vanillaBlocks
number=36
data:
JSON:{blockState:{blockName:"minecraft:light_blue_glazed_terracotta",properties:{facing:"west"}}}
:enddata
:endrule

rule:
plugin=vanillaBlocks
number=37
data:
JSON:{blockState:{blockName:"minecraft:light_blue_glazed_terracotta",properties:{facing:"south"}}}
:enddata
:endrule

rule:
plugin=vanillaBlocks
number=38
data:
JSON:{blockState:{blockName:"minecraft:green_glazed_terracotta",properties:{facing:"north"}}}
:enddata
:endrule

rule:
plugin=vanillaBlocks
number=39
data:
JSON:{blockState:{blockName:"minecraft:green_glazed_terracotta",properties:{facing:"east"}}}
:enddata
:endrule

rule:
plugin=vanillaBlocks
number=40
data:
JSON:{blockState:{blockName:"minecraft:green_glazed_terracotta",properties:{facing:"west"}}}
:enddata
:endrule

rule:
plugin=vanillaBlocks
number=41
data:
JSON:{blockState:{blockName:"minecraft:green_glazed_terracotta",properties:{facing:"south"}}}
:enddata
:endrule

rule:
plugin=vanillaBlocks
number=42
data:
JSON:{blockState:{blockName:"minecraft:gray_glazed_terracotta",properties:{facing:"north"}}}
:enddata
:endrule

rule:
plugin=vanillaBlocks
number=43
data:
JSON:{blockState:{blockName:"minecraft:gray_glazed_terracotta",properties:{facing:"east"}}}
:enddata
:endrule

rule:
plugin=vanillaBlocks
number=44
data:
JSON:{blockState:{blockName:"minecraft:brown_glazed_terracotta",properties:{facing:"east"}}}
:enddata
:endrule

rule:
plugin=vanillaBlocks
number=45
data:
JSON:{blockState:{blockName:"minecraft:brown_glazed_terracotta",properties:{facing:"north"}}}
:enddata
:endrule

rule:
plugin=vanillaBlocks
number=46
data:
JSON:{blockState:{blockName:"minecraft:gray_glazed_terracotta",properties:{facing:"west"}}}
:enddata
:endrule

rule:
plugin=vanillaBlocks
number=47
data:
JSON:{blockState:{blockName:"minecraft:gray_glazed_terracotta",properties:{facing:"south"}}}
:enddata
:endrule

rule:
plugin=vanillaBlocks
number=48
data:
JSON:{blockState:{blockName:"minecraft:brown_glazed_terracotta",properties:{facing:"south"}}}
:enddata
:endrule

rule:
plugin=vanillaBlocks
number=49
data:
JSON:{blockState:{blockName:"minecraft:brown_glazed_terracotta",properties:{facing:"west"}}}
:enddata
:endrule

rule:
plugin=vanillaBlocks
number=50
data:
JSON:{blockState:{blockName:"minecraft:blue_glazed_terracotta",properties:{facing:"north"}}}
:enddata
:endrule

rule:
plugin=vanillaBlocks
number=51
data:
JSON:{blockState:{blockName:"minecraft:cyan_glazed_terracotta",properties:{facing:"north"}}}
:enddata
:endrule

rule:
plugin=vanillaBlocks
number=52
data:
JSON:{blockState:{blockName:"minecraft:cyan_glazed_terracotta",properties:{facing:"east"}}}
:enddata
:endrule

rule:
plugin=vanillaBlocks
number=53
data:
JSON:{blockState:{blockName:"minecraft:blue_glazed_terracotta",properties:{facing:"west"}}}
:enddata
:endrule

rule:
plugin=vanillaBlocks
number=54
data:
JSON:{blockState:{blockName:"minecraft:lapis_block"}}
:enddata
:endrule

rule:
plugin=vanillaBlocks
number=55
data:
JSON:{blockState:{blockName:"minecraft:blue_glazed_terracotta",properties:{facing:"east"}}}
:enddata
:endrule

rule:
plugin=vanillaBlocks
number=56
data:
JSON:{blockState:{blockName:"minecraft:cyan_glazed_terracotta",properties:{facing:"west"}}}
:enddata
:endrule

rule:
plugin=vanillaBlocks
number=57
data:
JSON:{blockState:{blockName:"minecraft:cyan_glazed_terracotta",properties:{facing:"south"}}}
:enddata
:endrule

rule:
plugin=vanillaBlocks
number=58
data:
JSON:{blockState:{blockName:"minecraft:blue_glazed_terracotta",properties:{facing:"south"}}}
:enddata
:endrule

rule:
plugin=vanillaBlocks
number=59
data:
JSON:{blockState:{blockName:"minecraft:stained_hardened_clay",properties:{color:"cyan"}}}
:enddata
:endrule

rule:
plugin=vanillaBlocks
number=60
data:
JSON:{blockState:{blockName:"minecraft:stained_hardened_clay",properties:{color:"red"}}}
:enddata
:endrule

rule:
plugin=vanillaBlocks
number=61
data:
JSON:{blockState:{blockName:"minecraft:stone_brick_stairs",properties:{half:"bottom",shape:"straight",facing:"south"}}}
:enddata
:endrule

rule:
plugin=vanillaBlocks
number=62
data:
JSON:{blockState:{blockName:"minecraft:stone_brick_stairs",properties:{half:"bottom",shape:"straight",facing:"east"}}}
:enddata
:endrule

rule:
plugin=vanillaBlocks
number=63
data:
JSON:{blockState:{blockName:"minecraft:red_flower",properties:{type:"white_tulip"}}}
:enddata
:endrule

rule:
plugin=vanillaBlocks
number=64
data:
JSON:{blockState:{blockName:"minecraft:red_flower",properties:{type:"orange_tulip"}}}
:enddata
:endrule

rule:
plugin=vanillaBlocks
number=65
data:
JSON:{blockState:{blockName:"minecraft:red_flower",properties:{type:"pink_tulip"}}}
:enddata
:endrule

rule:
plugin=vanillaBlocks
number=66
data:
JSON:{blockState:{blockName:"minecraft:stone_brick_stairs",properties:{half:"bottom",shape:"straight",facing:"west"}}}
:enddata
:endrule

rule:
plugin=vanillaBlocks
number=67
data:
JSON:{blockState:{blockName:"minecraft:leaves",properties:{check_decay:"false",decayable:"false",variant:"oak"}}}
:enddata
:endrule

rule:
plugin=vanillaBlocks
number=68
data:
JSON:{blockState:{blockName:"minecraft:red_flower",properties:{type:"red_tulip"}}}
:enddata
:endrule

rule:
plugin=vanillaBlocks
number=69
data:
JSON:{blockState:{blockName:"minecraft:purple_glazed_terracotta",properties:{facing:"north"}}}
:enddata
:endrule

rule:
plugin=vanillaBlocks
number=70
data:
JSON:{blockState:{blockName:"minecraft:purple_glazed_terracotta",properties:{facing:"east"}}}
:enddata
:endrule

rule:
plugin=vanillaBlocks
number=71
data:
JSON:{blockState:{blockName:"minecraft:purple_glazed_terracotta",properties:{facing:"west"}}}
:enddata
:endrule

rule:
plugin=vanillaBlocks
number=72
data:
JSON:{blockState:{blockName:"minecraft:purple_glazed_terracotta",properties:{facing:"south"}}}
:enddata
:endrule

rule:
plugin=blockTile
number=73
data:
JSON:{blockState:{blockName:"ancientwarfarestructure:altar_candle"},teData:{customColor:0b,dyeColor:15,customData:"",id:"ancientwarfarestructure:altar_candle_tile",unlocalizedNamePart:""}}
:enddata
:endrule

rule:
plugin=blockTile
number=74
data:
JSON:{blockState:{blockName:"ancientwarfarestructure:altar_candle"},teData:{customColor:0b,dyeColor:15,customData:"",id:"ancientwarfarestructure:altar_candle_tile",unlocalizedNamePart:""}}
:enddata
:endrule

rule:
plugin=fluid
number=75
data:
JSON:{blockState:{blockName:"minecraft:water",properties:{level:"1"}}}
:enddata
:endrule

rule:
plugin=blockTile
number=76
data:
JSON:{blockState:{blockName:"ancientwarfarestructure:altar_candle"},teData:{customColor:0b,dyeColor:15,customData:"",id:"ancientwarfarestructure:altar_candle_tile",unlocalizedNamePart:""}}
:enddata
:endrule

rule:
plugin=blockTile
number=77
data:
JSON:{blockState:{blockName:"ancientwarfarestructure:altar_candle"},teData:{customColor:0b,dyeColor:15,customData:"",id:"ancientwarfarestructure:altar_candle_tile",unlocalizedNamePart:""}}
:enddata
:endrule

rule:
plugin=vanillaBlocks
number=78
data:
JSON:{blockState:{blockName:"minecraft:stone_brick_stairs",properties:{half:"bottom",shape:"straight",facing:"north"}}}
:enddata
:endrule

rule:
plugin=vanillaBlocks
number=79
data:
JSON:{blockState:{blockName:"minecraft:lime_glazed_terracotta",properties:{facing:"east"}}}
:enddata
:endrule

rule:
plugin=vanillaBlocks
number=80
data:
JSON:{blockState:{blockName:"minecraft:lime_glazed_terracotta",properties:{facing:"north"}}}
:enddata
:endrule

rule:
plugin=vanillaBlocks
number=81
data:
JSON:{blockState:{blockName:"minecraft:lime_glazed_terracotta",properties:{facing:"south"}}}
:enddata
:endrule

rule:
plugin=vanillaBlocks
number=82
data:
JSON:{blockState:{blockName:"minecraft:lime_glazed_terracotta",properties:{facing:"west"}}}
:enddata
:endrule

rule:
plugin=vanillaBlocks
number=83
data:
JSON:{blockState:{blockName:"minecraft:tallgrass",properties:{type:"tall_grass"}}}
:enddata
:endrule

rule:
plugin=blockTile
number=84
data:
JSON:{blockState:{blockName:"ancientwarfarestructure:advanced_spawner",properties:{transparent:"true"}},teData:{id:"ancientwarfarestructure:advanced_spawner_tile",spawnerSettings:{minDelay:10,spawnDelay:4,lightSensitive:0b,spawnGroups:[{settingsList:[{remainingSpawnCount:1,hostile:1b,customTag:{ArmorDropChances:[0.085f,0.085f,0.085f,0.085f],hasCustomEquipment:0b,ArmorItems:[{},{},{},{}],skinSettings:{npcTypeName:"custom",skinTypeSelected:"default"},HandDropChances:[0.085f,0.085f],factionName:"guild",HandItems:[{id:"ancientwarfarenpc:iron_spear",Count:1b,Damage:0s},{id:"ancientwarfarenpc:iron_shield",Count:1b,Damage:0s}]},maxToSpawn:1,entityId:"ancientwarfarenpc:faction.soldier",minToSpawn:1}],groupWeight:1}],playerRange:16,respondToRedstone:0b,inventory:{Size:9,Items:[]},spawnRange:0,transparent:1b,maxDelay:10,spawnYOffset:0,xpToDrop:0,mobRange:0,debugMode:0b,maxNearbyMonsters:0}}}
:enddata
:endrule

rule:
plugin=blockTile
number=85
data:
JSON:{blockState:{blockName:"ancientwarfarestructure:advanced_spawner",properties:{transparent:"true"}},teData:{id:"ancientwarfarestructure:advanced_spawner_tile",spawnerSettings:{minDelay:10,spawnDelay:9,lightSensitive:0b,spawnGroups:[{settingsList:[{remainingSpawnCount:1,hostile:1b,customTag:{ArmorDropChances:[0.085f,0.085f,0.085f,0.085f],hasCustomEquipment:0b,ArmorItems:[{},{},{},{}],skinSettings:{npcTypeName:"custom",skinTypeSelected:"default"},HandDropChances:[0.085f,0.085f],factionName:"guild",HandItems:[{id:"ancientwarfarenpc:iron_spear",Count:1b,Damage:0s},{id:"ancientwarfarenpc:iron_shield",Count:1b,Damage:0s}]},maxToSpawn:1,entityId:"ancientwarfarenpc:faction.soldier",minToSpawn:1}],groupWeight:1}],playerRange:16,respondToRedstone:0b,inventory:{Size:9,Items:[]},spawnRange:0,transparent:1b,maxDelay:10,spawnYOffset:0,xpToDrop:0,mobRange:0,debugMode:0b,maxNearbyMonsters:0}}}
:enddata
:endrule

rule:
plugin=vanillaBlocks
number=86
data:
JSON:{blockState:{blockName:"ancientwarfarestructure:bench",properties:{legs:"none",variant:"spruce",axis:"z"}}}
:enddata
:endrule

rule:
plugin=vanillaBlocks
number=87
data:
JSON:{blockState:{blockName:"ancientwarfarestructure:table",properties:{leg_southwest:"true",leg_northwest:"true",variant:"spruce",leg_northeast:"true",leg_southeast:"true"}}}
:enddata
:endrule

rule:
plugin=doors
number=88
data:
JSON:{blockState:{blockName:"minecraft:spruce_door",properties:{hinge:"left",half:"lower",powered:"false",facing:"north",open:"false"}}}
:enddata
:endrule

rule:
plugin=vanillaBlocks
number=89
data:
JSON:{blockState:{blockName:"minecraft:red_flower",properties:{type:"houstonia"}}}
:enddata
:endrule

rule:
plugin=vanillaBlocks
number=90
data:
JSON:{blockState:{blockName:"ancientwarfarestructure:bench",properties:{legs:"none",variant:"spruce",axis:"x"}}}
:enddata
:endrule

rule:
plugin=blockTile
number=91
data:
JSON:{blockState:{blockName:"ancientwarfarestructure:advanced_spawner",properties:{transparent:"true"}},teData:{id:"ancientwarfarestructure:advanced_spawner_tile",spawnerSettings:{minDelay:10,spawnDelay:9,lightSensitive:0b,spawnGroups:[{settingsList:[{remainingSpawnCount:1,hostile:1b,customTag:{ArmorDropChances:[0.085f,0.085f,0.085f,0.085f],hasCustomEquipment:0b,ArmorItems:[{},{},{},{}],skinSettings:{npcTypeName:"custom",skinTypeSelected:"default"},HandDropChances:[0.085f,0.085f],factionName:"guild",tradeList:{tradeList:[{refillFrequency:6000,currentAvailable:7,inputItems:[{id:"ancientwarfarenpc:coin",Count:16b,tag:{metal:"gold"},slot:4,Damage:0s}],outputItems:[{id:"minecraft:golden_apple",Count:1b,slot:4,Damage:0s}],refillTime:-1L,maxAvailable:7},{refillFrequency:6000,currentAvailable:4,inputItems:[{id:"ancientwarfarenpc:coin",Count:1b,tag:{metal:"silver"},slot:1,Damage:0s},{id:"ancientwarfarenpc:coin",Count:3b,tag:{metal:"copper"},slot:4,Damage:0s}],outputItems:[{id:"minecraft:golden_carrot",Count:1b,slot:4,Damage:0s}],refillTime:-1L,maxAvailable:4},{refillFrequency:6000,currentAvailable:2,inputItems:[{id:"ancientwarfarenpc:coin",Count:1b,tag:{metal:"silver"},slot:1,Damage:0s},{id:"ancientwarfarenpc:coin",Count:2b,tag:{metal:"copper"},slot:4,Damage:0s}],outputItems:[{id:"minecraft:speckled_melon",Count:1b,slot:4,Damage:0s}],refillTime:-1L,maxAvailable:2},{refillFrequency:6000,currentAvailable:6,inputItems:[{id:"ancientwarfarenpc:coin",Count:8b,tag:{metal:"silver"},slot:4,Damage:0s}],outputItems:[{id:"minecraft:gold_nugget",Count:1b,slot:4,Damage:0s}],refillTime:-1L,maxAvailable:6},{refillFrequency:6000,currentAvailable:1,inputItems:[{id:"ancientwarfarenpc:coin",Count:1b,tag:{metal:"ancient"},slot:4,Damage:0s}],outputItems:[{id:"minecraft:golden_apple",Count:1b,slot:4,Damage:1s}],refillTime:-1L,maxAvailable:1},{refillFrequency:6000,currentAvailable:5,inputItems:[{id:"minecraft:gold_nugget",Count:1b,slot:4,Damage:0s}],outputItems:[{id:"ancientwarfarenpc:coin",Count:4b,tag:{metal:"silver"},slot:4,Damage:0s}],refillTime:-1L,maxAvailable:5}]},HandItems:[{id:"minecraft:book",Count:1b,Damage:0s},{}]},maxToSpawn:1,entityId:"ancientwarfarenpc:faction.trader",minToSpawn:1}],groupWeight:1}],playerRange:16,respondToRedstone:0b,inventory:{Size:9,Items:[]},spawnRange:0,transparent:1b,maxDelay:10,spawnYOffset:0,xpToDrop:0,mobRange:0,debugMode:0b,maxNearbyMonsters:0}}}
:enddata
:endrule

rule:
plugin=blockTile
number=92
data:
JSON:{blockState:{blockName:"ancientwarfarestructure:advanced_spawner",properties:{transparent:"true"}},teData:{id:"ancientwarfarestructure:advanced_spawner_tile",spawnerSettings:{minDelay:10,spawnDelay:10,lightSensitive:0b,spawnGroups:[{settingsList:[{remainingSpawnCount:1,hostile:1b,customTag:{ArmorDropChances:[0.085f,0.085f,0.085f,0.085f],hasCustomEquipment:0b,ArmorItems:[{},{},{},{}],skinSettings:{npcTypeName:"custom",skinTypeSelected:"default"},HandDropChances:[0.085f,0.085f],factionName:"guild",tradeList:{tradeList:[{refillFrequency:6000,currentAvailable:11,inputItems:[{id:"ancientwarfarenpc:coin",Count:1b,tag:{metal:"silver"},slot:4,Damage:0s}],outputItems:[{id:"minecraft:coal",Count:5b,slot:4,Damage:0s}],refillTime:14359302L,maxAvailable:11},{refillFrequency:6000,currentAvailable:8,inputItems:[{id:"ancientwarfarenpc:coin",Count:1b,tag:{metal:"silver"},slot:4,Damage:0s}],outputItems:[{id:"minecraft:coal",Count:6b,slot:4,Damage:1s}],refillTime:14359302L,maxAvailable:8},{refillFrequency:6000,currentAvailable:4,inputItems:[{id:"ancientwarfarenpc:coin",Count:4b,tag:{metal:"silver"},slot:4,Damage:0s}],outputItems:[{id:"minecraft:gunpowder",Count:16b,slot:4,Damage:0s}],refillTime:14359302L,maxAvailable:4},{refillFrequency:6000,currentAvailable:3,inputItems:[{id:"ancientwarfarenpc:coin",Count:1b,tag:{metal:"silver"},slot:4,Damage:0s}],outputItems:[{id:"minecraft:leather",Count:1b,slot:4,Damage:0s}],refillTime:14359302L,maxAvailable:3},{refillFrequency:6000,currentAvailable:4,inputItems:[{id:"ancientwarfarenpc:coin",Count:3b,tag:{metal:"copper"},slot:4,Damage:0s}],outputItems:[{id:"minecraft:feather",Count:8b,slot:4,Damage:0s}],refillTime:14359302L,maxAvailable:4}]},HandItems:[{id:"minecraft:book",Count:1b,Damage:0s},{}]},maxToSpawn:1,entityId:"ancientwarfarenpc:faction.trader",minToSpawn:1}],groupWeight:1}],playerRange:16,respondToRedstone:0b,inventory:{Size:9,Items:[]},spawnRange:0,transparent:1b,maxDelay:10,spawnYOffset:0,xpToDrop:0,mobRange:0,debugMode:0b,maxNearbyMonsters:0}}}
:enddata
:endrule

rule:
plugin=blockTile
number=93
data:
JSON:{blockState:{blockName:"ancientwarfarestructure:advanced_spawner",properties:{transparent:"true"}},teData:{id:"ancientwarfarestructure:advanced_spawner_tile",spawnerSettings:{minDelay:10,spawnDelay:3,lightSensitive:0b,spawnGroups:[{settingsList:[{remainingSpawnCount:1,hostile:1b,customTag:{ArmorDropChances:[0.085f,0.085f,0.085f,0.085f],hasCustomEquipment:0b,ArmorItems:[{},{},{},{}],skinSettings:{npcTypeName:"custom",skinTypeSelected:"default"},HandDropChances:[0.085f,0.085f],factionName:"guild",tradeList:{tradeList:[{refillFrequency:6000,currentAvailable:11,inputItems:[{id:"ancientwarfarenpc:coin",Count:3b,tag:{metal:"copper"},slot:4,Damage:0s}],outputItems:[{id:"minecraft:carrot",Count:1b,slot:4,Damage:0s}],refillTime:14360104L,maxAvailable:11},{refillFrequency:6000,currentAvailable:6,inputItems:[{id:"ancientwarfarenpc:coin",Count:5b,tag:{metal:"copper"},slot:4,Damage:0s}],outputItems:[{id:"minecraft:baked_potato",Count:1b,slot:4,Damage:0s}],refillTime:14360104L,maxAvailable:6},{refillFrequency:6000,currentAvailable:7,inputItems:[{id:"ancientwarfarenpc:coin",Count:6b,tag:{metal:"copper"},slot:4,Damage:0s}],outputItems:[{id:"minecraft:cooked_mutton",Count:1b,slot:4,Damage:0s}],refillTime:14360104L,maxAvailable:7},{refillFrequency:6000,currentAvailable:9,inputItems:[{id:"ancientwarfarenpc:coin",Count:6b,tag:{metal:"copper"},slot:4,Damage:0s}],outputItems:[{id:"minecraft:beetroot_soup",Count:1b,slot:4,Damage:0s}],refillTime:14360104L,maxAvailable:9},{refillFrequency:6000,currentAvailable:4,inputItems:[{id:"ancientwarfarenpc:coin",Count:10b,tag:{metal:"copper"},slot:4,Damage:0s}],outputItems:[{id:"minecraft:rabbit_stew",Count:1b,slot:4,Damage:0s}],refillTime:14360104L,maxAvailable:4}]},HandItems:[{id:"minecraft:book",Count:1b,Damage:0s},{}]},maxToSpawn:1,entityId:"ancientwarfarenpc:faction.trader",minToSpawn:1}],groupWeight:1}],playerRange:16,respondToRedstone:0b,inventory:{Size:9,Items:[]},spawnRange:0,transparent:1b,maxDelay:10,spawnYOffset:0,xpToDrop:0,mobRange:0,debugMode:0b,maxNearbyMonsters:0}}}
:enddata
:endrule

rule:
plugin=blockTile
number=94
data:
JSON:{blockState:{blockName:"ancientwarfarestructure:advanced_spawner",properties:{transparent:"true"}},teData:{id:"ancientwarfarestructure:advanced_spawner_tile",spawnerSettings:{minDelay:10,spawnDelay:6,lightSensitive:0b,spawnGroups:[{settingsList:[{remainingSpawnCount:1,hostile:1b,customTag:{ArmorDropChances:[0.085f,0.085f,0.085f,0.085f],hasCustomEquipment:0b,ArmorItems:[{},{},{},{}],skinSettings:{npcTypeName:"custom",skinTypeSelected:"default"},HandDropChances:[0.085f,0.085f],factionName:"guild",tradeList:{tradeList:[{refillFrequency:6000,currentAvailable:3,inputItems:[{id:"ancientwarfarenpc:coin",Count:3b,tag:{metal:"copper"},slot:1,Damage:0s},{id:"ancientwarfarenpc:coin",Count:2b,tag:{metal:"silver"},slot:4,Damage:0s},{id:"ancientwarfarenpc:coin",Count:2b,tag:{metal:"gold"},slot:7,Damage:0s}],outputItems:[{id:"minecraft:potion",Count:1b,tag:{CustomPotionEffects:[{ShowParticles:0b,Duration:2400,Id:1b,Amplifier:1b},{ShowParticles:0b,Duration:1200,Id:11b,Amplifier:0b},{ShowParticles:0b,Duration:200,Id:23b,Amplifier:0b}],CustomPotionColor:5373952,HideFlags:32,display:{Lore:["made from red grapes"],Name:"Red Wine"}},slot:4,Damage:0s}],refillTime:14360478L,maxAvailable:3},{refillFrequency:6000,currentAvailable:5,inputItems:[{id:"ancientwarfarenpc:coin",Count:3b,tag:{metal:"copper"},slot:1,Damage:0s},{id:"ancientwarfarenpc:coin",Count:2b,tag:{metal:"silver"},slot:4,Damage:0s},{id:"ancientwarfarenpc:coin",Count:2b,tag:{metal:"gold"},slot:7,Damage:0s}],outputItems:[{id:"minecraft:potion",Count:1b,tag:{CustomPotionEffects:[{ShowParticles:0b,Duration:2400,Id:1b,Amplifier:1b},{ShowParticles:0b,Duration:1200,Id:11b,Amplifier:0b},{ShowParticles:0b,Duration:200,Id:23b,Amplifier:0b}],CustomPotionColor:14277081,HideFlags:32,display:{Lore:["made from white grapes"],Name:"White Wine"}},slot:4,Damage:0s}],refillTime:14360478L,maxAvailable:5},{refillFrequency:6000,currentAvailable:4,inputItems:[{id:"ancientwarfarenpc:coin",Count:3b,tag:{metal:"copper"},slot:1,Damage:0s},{id:"ancientwarfarenpc:coin",Count:2b,tag:{metal:"silver"},slot:4,Damage:0s},{id:"ancientwarfarenpc:coin",Count:2b,tag:{metal:"gold"},slot:7,Damage:0s}],outputItems:[{id:"minecraft:potion",Count:1b,tag:{CustomPotionEffects:[{ShowParticles:0b,Duration:2400,Id:1b,Amplifier:1b},{ShowParticles:0b,Duration:1200,Id:11b,Amplifier:0b},{ShowParticles:0b,Duration:200,Id:23b,Amplifier:0b}],CustomPotionColor:13041592,HideFlags:32,display:{Lore:["made from green grapes"],Name:"Green Wine"}},slot:4,Damage:0s}],refillTime:14360478L,maxAvailable:4},{refillFrequency:6000,currentAvailable:1,inputItems:[{id:"ancientwarfarenpc:coin",Count:8b,tag:{metal:"copper"},slot:1,Damage:0s},{id:"ancientwarfarenpc:coin",Count:5b,tag:{metal:"silver"},slot:4,Damage:0s},{id:"ancientwarfarenpc:coin",Count:7b,tag:{metal:"gold"},slot:7,Damage:0s}],outputItems:[{id:"minecraft:potion",Count:1b,tag:{CustomPotionEffects:[{ShowParticles:0b,Duration:2400,Id:1b,Amplifier:2b},{ShowParticles:0b,Duration:600,Id:3b,Amplifier:1b},{ShowParticles:0b,Duration:10,Id:9b,Amplifier:0b},{ShowParticles:0b,Duration:1200,Id:11b,Amplifier:1b},{ShowParticles:0b,Duration:600,Id:23b,Amplifier:1b},{ShowParticles:0b,Duration:1200,Id:27b,Amplifier:1b}],CustomPotionColor:6358277,HideFlags:32,display:{Lore:["The best of the best!"],Name:"Vintage Wine"}},slot:4,Damage:0s}],refillTime:14360478L,maxAvailable:1}]},HandItems:[{id:"minecraft:book",Count:1b,Damage:0s},{}]},maxToSpawn:1,entityId:"ancientwarfarenpc:faction.trader",minToSpawn:1}],groupWeight:1}],playerRange:16,respondToRedstone:0b,inventory:{Size:9,Items:[]},spawnRange:0,transparent:1b,maxDelay:10,spawnYOffset:0,xpToDrop:0,mobRange:0,debugMode:0b,maxNearbyMonsters:0}}}
:enddata
:endrule

rule:
plugin=blockTile
number=95
data:
JSON:{blockState:{blockName:"ancientwarfarestructure:advanced_loot_chest",properties:{facing:"east"}},teData:{lootSettings:{lootRolls:1,splashPotion:0b,hasMessage:0b,hasLoot:1b,lootTableName:"ancientwarfare:chests/castle_treasury_low_value",spawnEntity:0b,entity:"minecraft:"},Items:[],id:"ancientwarfarestructure:advanced_loot_chest_tile",Lock:""}}
:enddata
:endrule

rule:
plugin=bed
number=96
data:
JSON:{blockState:{blockName:"minecraft:bed",properties:{part:"head",facing:"east",occupied:"false"}},bedColor:10}
:enddata
:endrule

rule:
plugin=bed
number=97
data:
JSON:{blockState:{blockName:"minecraft:bed",properties:{part:"foot",facing:"east",occupied:"false"}},bedColor:10}
:enddata
:endrule

rule:
plugin=doors
number=98
data:
JSON:{blockState:{blockName:"minecraft:spruce_door",properties:{hinge:"left",half:"lower",powered:"false",facing:"east",open:"false"}}}
:enddata
:endrule

rule:
plugin=doors
number=99
data:
JSON:{blockState:{blockName:"minecraft:spruce_door",properties:{hinge:"left",half:"lower",powered:"false",facing:"west",open:"false"}}}
:enddata
:endrule

rule:
plugin=bed
number=100
data:
JSON:{blockState:{blockName:"minecraft:bed",properties:{part:"foot",facing:"west",occupied:"false"}},bedColor:14}
:enddata
:endrule

rule:
plugin=bed
number=101
data:
JSON:{blockState:{blockName:"minecraft:bed",properties:{part:"head",facing:"west",occupied:"false"}},bedColor:14}
:enddata
:endrule

rule:
plugin=doors
number=102
data:
JSON:{blockState:{blockName:"minecraft:spruce_door",properties:{hinge:"right",half:"lower",powered:"false",facing:"west",open:"false"}}}
:enddata
:endrule

rule:
plugin=blockTile
number=103
data:
JSON:{blockState:{blockName:"ancientwarfarestructure:advanced_loot_chest",properties:{facing:"west"}},teData:{lootSettings:{lootRolls:1,splashPotion:0b,hasMessage:0b,hasLoot:1b,lootTableName:"ancientwarfare:chests/castle_treasury_low_value",spawnEntity:0b,entity:"minecraft:"},Items:[],id:"ancientwarfarestructure:advanced_loot_chest_tile",Lock:""}}
:enddata
:endrule

rule:
plugin=vanillaBlocks
number=104
data:
JSON:{blockState:{blockName:"minecraft:cobblestone_wall",properties:{east:"false",south:"false",north:"false",variant:"cobblestone",west:"false",up:"false"}}}
:enddata
:endrule

rule:
plugin=vanillaBlocks
number=105
data:
JSON:{blockState:{blockName:"minecraft:red_flower",properties:{type:"poppy"}}}
:enddata
:endrule

rule:
plugin=blockTile
number=106
data:
JSON:{blockState:{blockName:"ancientwarfarestructure:advanced_loot_chest",properties:{facing:"east"}},teData:{lootSettings:{lootRolls:1,splashPotion:0b,hasMessage:0b,hasLoot:1b,lootTableName:"ancientwarfare:chests/guild",spawnEntity:0b,entity:"minecraft:"},Items:[],id:"ancientwarfarestructure:advanced_loot_chest_tile",Lock:""}}
:enddata
:endrule

rule:
plugin=blockTile
number=107
data:
JSON:{blockState:{blockName:"ancientwarfarestructure:advanced_loot_chest",properties:{facing:"east"}},teData:{lootSettings:{lootRolls:1,splashPotion:0b,hasMessage:0b,hasLoot:1b,lootTableName:"ancientwarfare:chests/castle_treasury_low_value",spawnEntity:0b,entity:"minecraft:"},Items:[],id:"ancientwarfarestructure:advanced_loot_chest_tile",Lock:""}}
:enddata
:endrule

rule:
plugin=bed
number=108
data:
JSON:{blockState:{blockName:"minecraft:bed",properties:{part:"head",facing:"east",occupied:"false"}},bedColor:1}
:enddata
:endrule

rule:
plugin=bed
number=109
data:
JSON:{blockState:{blockName:"minecraft:bed",properties:{part:"foot",facing:"east",occupied:"false"}},bedColor:1}
:enddata
:endrule

rule:
plugin=doors
number=110
data:
JSON:{blockState:{blockName:"minecraft:spruce_door",properties:{hinge:"right",half:"lower",powered:"false",facing:"east",open:"false"}}}
:enddata
:endrule

rule:
plugin=bed
number=111
data:
JSON:{blockState:{blockName:"minecraft:bed",properties:{part:"foot",facing:"west",occupied:"false"}},bedColor:0}
:enddata
:endrule

rule:
plugin=bed
number=112
data:
JSON:{blockState:{blockName:"minecraft:bed",properties:{part:"head",facing:"west",occupied:"false"}},bedColor:0}
:enddata
:endrule

rule:
plugin=blockTile
number=113
data:
JSON:{blockState:{blockName:"ancientwarfarestructure:advanced_loot_chest",properties:{facing:"west"}},teData:{lootSettings:{lootRolls:1,splashPotion:0b,hasMessage:0b,hasLoot:1b,lootTableName:"ancientwarfare:chests/castle_treasury_low_value",spawnEntity:0b,entity:"minecraft:"},Items:[],id:"ancientwarfarestructure:advanced_loot_chest_tile",Lock:""}}
:enddata
:endrule

rule:
plugin=blockTile
number=114
data:
JSON:{blockState:{blockName:"ancientwarfarestructure:advanced_spawner",properties:{transparent:"true"}},teData:{id:"ancientwarfarestructure:advanced_spawner_tile",spawnerSettings:{minDelay:10,spawnDelay:4,lightSensitive:0b,spawnGroups:[{settingsList:[{remainingSpawnCount:1,hostile:1b,customTag:{ArmorDropChances:[0.085f,0.085f,0.085f,0.085f],hasCustomEquipment:0b,ArmorItems:[{},{},{},{}],skinSettings:{npcTypeName:"custom",skinTypeSelected:"default"},HandDropChances:[0.085f,0.085f],factionName:"guild",HandItems:[{id:"ancientwarfarenpc:iron_halberd",Count:1b,Damage:0s},{}]},maxToSpawn:1,entityId:"ancientwarfarenpc:faction.leader",minToSpawn:1}],groupWeight:1}],playerRange:16,respondToRedstone:0b,inventory:{Size:9,Items:[]},spawnRange:0,transparent:1b,maxDelay:10,spawnYOffset:0,xpToDrop:0,mobRange:0,debugMode:0b,maxNearbyMonsters:0}}}
:enddata
:endrule

rule:
plugin=blockTile
number=115
data:
JSON:{blockState:{blockName:"ancientwarfarestructure:chair",properties:{visible:"true",variant:"oak",facing:"south"}},facing:"west",teData:{facing:"east",id:"ancientwarfarestructure:chair_tile"}}
:enddata
:endrule

rule:
plugin=vanillaBlocks
number=116
data:
JSON:{blockState:{blockName:"ancientwarfarestructure:table",properties:{leg_southwest:"true",leg_northwest:"true",variant:"oak",leg_northeast:"true",leg_southeast:"true"}}}
:enddata
:endrule

rule:
plugin=blockTile
number=117
data:
JSON:{blockState:{blockName:"ancientwarfarestructure:chair",properties:{visible:"true",variant:"oak",facing:"south"}},facing:"east",teData:{facing:"west",id:"ancientwarfarestructure:chair_tile"}}
:enddata
:endrule

rule:
plugin=blockTile
number=118
data:
JSON:{blockState:{blockName:"ancientwarfarestructure:chair",properties:{visible:"true",variant:"oak",facing:"south"}},facing:"west",teData:{facing:"east",id:"ancientwarfarestructure:chair_tile"}}
:enddata
:endrule

rule:
plugin=blockTile
number=119
data:
JSON:{blockState:{blockName:"ancientwarfarestructure:chair",properties:{visible:"true",variant:"oak",facing:"south"}},facing:"east",teData:{facing:"west",id:"ancientwarfarestructure:chair_tile"}}
:enddata
:endrule

rule:
plugin=blockTile
number=120
data:
JSON:{blockState:{blockName:"ancientwarfarestructure:chair",properties:{visible:"true",variant:"oak",facing:"south"}},facing:"west",teData:{facing:"east",id:"ancientwarfarestructure:chair_tile"}}
:enddata
:endrule

rule:
plugin=blockTile
number=121
data:
JSON:{blockState:{blockName:"ancientwarfarestructure:chair",properties:{visible:"true",variant:"oak",facing:"south"}},facing:"east",teData:{facing:"west",id:"ancientwarfarestructure:chair_tile"}}
:enddata
:endrule

rule:
plugin=blockTile
number=122
data:
JSON:{blockState:{blockName:"minecraft:ender_chest",properties:{facing:"west"}},teData:{id:"minecraft:ender_chest"}}
:enddata
:endrule

rule:
plugin=blockTile
number=123
data:
JSON:{blockState:{blockName:"ancientwarfarestructure:chair",properties:{visible:"true",variant:"birch",facing:"south"}},facing:"south",teData:{facing:"north",id:"ancientwarfarestructure:chair_tile"}}
:enddata
:endrule

rule:
plugin=blockTile
number=124
data:
JSON:{blockState:{blockName:"ancientwarfarestructure:chair",properties:{visible:"true",variant:"oak",facing:"south"}},facing:"west",teData:{facing:"east",id:"ancientwarfarestructure:chair_tile"}}
:enddata
:endrule

rule:
plugin=blockTile
number=125
data:
JSON:{blockState:{blockName:"ancientwarfarestructure:chair",properties:{visible:"true",variant:"oak",facing:"south"}},facing:"east",teData:{facing:"west",id:"ancientwarfarestructure:chair_tile"}}
:enddata
:endrule

rule:
plugin=blockTile
number=126
data:
JSON:{blockState:{blockName:"ancientwarfarestructure:chair",properties:{visible:"true",variant:"oak",facing:"south"}},facing:"west",teData:{facing:"east",id:"ancientwarfarestructure:chair_tile"}}
:enddata
:endrule

rule:
plugin=blockTile
number=127
data:
JSON:{blockState:{blockName:"ancientwarfarestructure:chair",properties:{visible:"true",variant:"oak",facing:"south"}},facing:"east",teData:{facing:"west",id:"ancientwarfarestructure:chair_tile"}}
:enddata
:endrule

rule:
plugin=vanillaBlocks
number=128
data:
JSON:{blockState:{blockName:"minecraft:anvil",properties:{damage:"0",facing:"south"}}}
:enddata
:endrule

rule:
plugin=blockTile
number=129
data:
JSON:{blockState:{blockName:"ancientwarfarestructure:chair",properties:{visible:"true",variant:"oak",facing:"south"}},facing:"west",teData:{facing:"east",id:"ancientwarfarestructure:chair_tile"}}
:enddata
:endrule

rule:
plugin=blockTile
number=130
data:
JSON:{blockState:{blockName:"ancientwarfarestructure:chair",properties:{visible:"true",variant:"oak",facing:"south"}},facing:"east",teData:{facing:"west",id:"ancientwarfarestructure:chair_tile"}}
:enddata
:endrule

rule:
plugin=blockTile
number=131
data:
JSON:{blockState:{blockName:"ancientwarfarestructure:advanced_loot_chest",properties:{facing:"west"}},teData:{lootSettings:{lootRolls:1,splashPotion:0b,hasMessage:0b,hasLoot:1b,lootTableName:"ancientwarfare:chests/castle_treasury_medium_value",spawnEntity:0b,entity:"minecraft:"},Items:[],id:"ancientwarfarestructure:advanced_loot_chest_tile",Lock:""}}
:enddata
:endrule

rule:
plugin=blockTile
number=132
data:
JSON:{blockState:{blockName:"ancientwarfarestructure:advanced_loot_chest",properties:{facing:"south"}},teData:{lootSettings:{lootRolls:1,splashPotion:0b,hasMessage:0b,hasLoot:1b,lootTableName:"ancientwarfare:chests/guild",spawnEntity:0b,entity:"minecraft:"},Items:[],id:"ancientwarfarestructure:advanced_loot_chest_tile",Lock:""}}
:enddata
:endrule

rule:
plugin=doors
number=133
data:
JSON:{blockState:{blockName:"minecraft:spruce_door",properties:{hinge:"left",half:"lower",powered:"false",facing:"south",open:"true"}}}
:enddata
:endrule

rule:
plugin=blockTile
number=134
data:
JSON:{blockState:{blockName:"ancientwarfarestructure:advanced_spawner",properties:{transparent:"true"}},teData:{id:"ancientwarfarestructure:advanced_spawner_tile",spawnerSettings:{minDelay:10,spawnDelay:4,lightSensitive:0b,spawnGroups:[{settingsList:[{remainingSpawnCount:1,hostile:1b,customTag:{ArmorDropChances:[0.085f,0.085f,0.085f,0.085f],hasCustomEquipment:0b,ArmorItems:[{},{},{},{}],skinSettings:{npcTypeName:"custom",skinTypeSelected:"default"},HandDropChances:[0.085f,0.085f],factionName:"guild",HandItems:[{id:"ancientwarfarenpc:iron_spear",Count:1b,Damage:0s},{id:"ancientwarfarenpc:iron_shield",Count:1b,Damage:0s}]},maxToSpawn:1,entityId:"ancientwarfarenpc:faction.soldier",minToSpawn:1}],groupWeight:1}],playerRange:16,respondToRedstone:0b,inventory:{Size:9,Items:[]},spawnRange:0,transparent:1b,maxDelay:10,spawnYOffset:0,xpToDrop:0,mobRange:0,debugMode:0b,maxNearbyMonsters:0}}}
:enddata
:endrule

rule:
plugin=inventory
number=135
data:
JSON:{blockState:{blockName:"minecraft:furnace",properties:{facing:"north"}},lootLevel:0,teData:{CookTime:0,BurnTime:0,Items:[],id:"minecraft:furnace",CookTimeTotal:0,Lock:""},inventoryData:{length:0,inventoryContents:[]},legacyFeatures:0b}
:enddata
:endrule

rule:
plugin=inventory
number=136
data:
JSON:{blockState:{blockName:"minecraft:furnace",properties:{facing:"north"}},lootLevel:0,teData:{CookTime:0,BurnTime:0,Items:[],id:"minecraft:furnace",CookTimeTotal:0,Lock:""},inventoryData:{length:0,inventoryContents:[]},legacyFeatures:0b}
:enddata
:endrule

rule:
plugin=vanillaBlocks
number=137
data:
JSON:{blockState:{blockName:"minecraft:yellow_flower",properties:{type:"dandelion"}}}
:enddata
:endrule

rule:
plugin=doors
number=138
data:
JSON:{blockState:{blockName:"minecraft:spruce_door",properties:{hinge:"left",half:"lower",powered:"false",facing:"east",open:"true"}}}
:enddata
:endrule

rule:
plugin=vanillaBlocks
number=139
data:
JSON:{blockState:{blockName:"minecraft:stone_slab",properties:{half:"top",variant:"stone_brick"}}}
:enddata
:endrule

rule:
plugin=blockTile
number=140
data:
JSON:{blockState:{blockName:"ancientwarfarestructure:advanced_loot_chest",properties:{facing:"south"}},teData:{lootSettings:{lootRolls:1,splashPotion:0b,hasMessage:0b,hasLoot:1b,lootTableName:"ancientwarfare:chests/village_farm_mixed",spawnEntity:0b,entity:"minecraft:"},Items:[],id:"ancientwarfarestructure:advanced_loot_chest_tile",Lock:""}}
:enddata
:endrule

rule:
plugin=blockTile
number=141
data:
JSON:{blockState:{blockName:"ancientwarfarestructure:advanced_loot_chest",properties:{facing:"south"}},teData:{lootSettings:{lootRolls:1,splashPotion:0b,hasMessage:0b,hasLoot:1b,lootTableName:"ancientwarfare:chests/village_farm_mixed",spawnEntity:0b,entity:"minecraft:"},Items:[],id:"ancientwarfarestructure:advanced_loot_chest_tile",Lock:""}}
:enddata
:endrule

rule:
plugin=blockTile
number=142
data:
JSON:{blockState:{blockName:"ancientwarfarestructure:advanced_loot_chest",properties:{facing:"west"}},teData:{lootSettings:{lootRolls:1,splashPotion:0b,hasMessage:0b,hasLoot:1b,lootTableName:"ancientwarfare:chests/castle_treasury_low_value",spawnEntity:0b,entity:"minecraft:"},Items:[],id:"ancientwarfarestructure:advanced_loot_chest_tile",Lock:""}}
:enddata
:endrule

rule:
plugin=blockTile
number=143
data:
JSON:{blockState:{blockName:"ancientwarfarestructure:advanced_loot_chest",properties:{facing:"west"}},teData:{lootSettings:{lootRolls:1,splashPotion:0b,hasMessage:0b,hasLoot:1b,lootTableName:"ancientwarfare:chests/castle_treasury_low_value",spawnEntity:0b,entity:"minecraft:"},Items:[],id:"ancientwarfarestructure:advanced_loot_chest_tile",Lock:""}}
:enddata
:endrule

rule:
plugin=blockTile
number=144
data:
JSON:{blockState:{blockName:"ancientwarfarestructure:advanced_loot_chest",properties:{facing:"west"}},teData:{lootSettings:{lootRolls:1,splashPotion:0b,hasMessage:0b,hasLoot:1b,lootTableName:"ancientwarfare:chests/castle_treasury_low_value",spawnEntity:0b,entity:"minecraft:"},Items:[],id:"ancientwarfarestructure:advanced_loot_chest_tile",Lock:""}}
:enddata
:endrule

rule:
plugin=blockTile
number=145
data:
JSON:{blockState:{blockName:"ancientwarfarestructure:chair",properties:{visible:"true",variant:"birch",facing:"south"}},facing:"west",teData:{facing:"east",id:"ancientwarfarestructure:chair_tile"}}
:enddata
:endrule

rule:
plugin=blockTile
number=146
data:
JSON:{blockState:{blockName:"ancientwarfarestructure:advanced_loot_chest",properties:{facing:"west"}},teData:{lootSettings:{lootRolls:1,splashPotion:0b,hasMessage:0b,hasLoot:1b,lootTableName:"ancientwarfare:chests/castle_treasury_low_value",spawnEntity:0b,entity:"minecraft:"},Items:[],id:"ancientwarfarestructure:advanced_loot_chest_tile",Lock:""}}
:enddata
:endrule

rule:
plugin=blockTile
number=147
data:
JSON:{blockState:{blockName:"ancientwarfarestructure:chair",properties:{visible:"true",variant:"birch",facing:"south"}},facing:"south",teData:{facing:"north",id:"ancientwarfarestructure:chair_tile"}}
:enddata
:endrule

rule:
plugin=blockTile
number=148
data:
JSON:{blockState:{blockName:"ancientwarfarestructure:advanced_loot_chest",properties:{facing:"south"}},teData:{lootSettings:{lootRolls:1,splashPotion:0b,hasMessage:0b,hasLoot:1b,lootTableName:"ancientwarfare:chests/castle_treasury_low_value",spawnEntity:0b,entity:"minecraft:"},Items:[],id:"ancientwarfarestructure:advanced_loot_chest_tile",Lock:""}}
:enddata
:endrule

rule:
plugin=blockTile
number=149
data:
JSON:{blockState:{blockName:"ancientwarfarestructure:chair",properties:{visible:"true",variant:"oak",facing:"south"}},facing:"north",teData:{facing:"south",id:"ancientwarfarestructure:chair_tile"}}
:enddata
:endrule

rule:
plugin=blockTile
number=150
data:
JSON:{blockState:{blockName:"ancientwarfarestructure:chair",properties:{visible:"true",variant:"oak",facing:"south"}},facing:"north",teData:{facing:"south",id:"ancientwarfarestructure:chair_tile"}}
:enddata
:endrule

rule:
plugin=blockTile
number=151
data:
JSON:{blockState:{blockName:"ancientwarfarestructure:chair",properties:{visible:"true",variant:"oak",facing:"south"}},facing:"east",teData:{facing:"west",id:"ancientwarfarestructure:chair_tile"}}
:enddata
:endrule

rule:
plugin=blockTile
number=152
data:
JSON:{blockState:{blockName:"ancientwarfarestructure:chair",properties:{visible:"true",variant:"oak",facing:"south"}},facing:"south",teData:{facing:"north",id:"ancientwarfarestructure:chair_tile"}}
:enddata
:endrule

rule:
plugin=doors
number=153
data:
JSON:{blockState:{blockName:"minecraft:spruce_door",properties:{hinge:"right",half:"upper",powered:"false",facing:"south",open:"false"}}}
:enddata
:endrule

rule:
plugin=doors
number=154
data:
JSON:{blockState:{blockName:"minecraft:spruce_door",properties:{hinge:"left",half:"upper",powered:"false",facing:"south",open:"false"}}}
:enddata
:endrule

rule:
plugin=vanillaBlocks
number=155
data:
JSON:{blockState:{blockName:"ancientwarfarestructure:coin_stack_silver",properties:{size:"8"}}}
:enddata
:endrule

rule:
plugin=vanillaFlowerPot
number=156
data:
JSON:{blockState:{blockName:"minecraft:flower_pot",properties:{contents:"empty",custom:"false",legacy_data:"0"}},itemMeta:0}
:enddata
:endrule

rule:
plugin=vanillaBlocks
number=157
data:
JSON:{blockState:{blockName:"minecraft:stained_hardened_clay",properties:{color:"yellow"}}}
:enddata
:endrule

rule:
plugin=vanillaBlocks
number=158
data:
JSON:{blockState:{blockName:"minecraft:stained_hardened_clay",properties:{color:"green"}}}
:enddata
:endrule

rule:
plugin=blockTile
number=159
data:
JSON:{blockState:{blockName:"ancientwarfarestructure:altar_candle"},teData:{customColor:0b,dyeColor:15,customData:"",id:"ancientwarfarestructure:altar_candle_tile",unlocalizedNamePart:""}}
:enddata
:endrule

rule:
plugin=blockTile
number=160
data:
JSON:{blockState:{blockName:"ancientwarfarestructure:altar_candle"},teData:{customColor:0b,dyeColor:15,customData:"",id:"ancientwarfarestructure:altar_candle_tile",unlocalizedNamePart:""}}
:enddata
:endrule

rule:
plugin=blockTile
number=161
data:
JSON:{blockState:{blockName:"ancientwarfarestructure:altar_candle"},teData:{customColor:0b,dyeColor:15,customData:"",id:"ancientwarfarestructure:altar_candle_tile",unlocalizedNamePart:""}}
:enddata
:endrule

rule:
plugin=blockTile
number=162
data:
JSON:{blockState:{blockName:"ancientwarfarestructure:altar_candle"},teData:{customColor:0b,dyeColor:15,customData:"",id:"ancientwarfarestructure:altar_candle_tile",unlocalizedNamePart:""}}
:enddata
:endrule

rule:
plugin=vanillaBlocks
number=163
data:
JSON:{blockState:{blockName:"ancientwarfarestructure:coin_stack_gold",properties:{size:"16"}}}
:enddata
:endrule

rule:
plugin=vanillaBlocks
number=164
data:
JSON:{blockState:{blockName:"minecraft:stained_hardened_clay",properties:{color:"light_blue"}}}
:enddata
:endrule

rule:
plugin=blockTile
number=165
data:
JSON:{blockState:{blockName:"ancientwarfarestructure:chair",properties:{visible:"false",variant:"oak",facing:"south"}},facing:"west",teData:{facing:"east",id:"ancientwarfarestructure:chair_tile",mainBlockPos:-20065281901255L}}
:enddata
:endrule

rule:
plugin=blockTile
number=166
data:
JSON:{blockState:{blockName:"ancientwarfarestructure:chair",properties:{visible:"false",variant:"oak",facing:"south"}},facing:"east",teData:{facing:"west",id:"ancientwarfarestructure:chair_tile",mainBlockPos:-19240648180423L}}
:enddata
:endrule

rule:
plugin=vanillaBlocks
number=167
data:
JSON:{blockState:{blockName:"ancientwarfarestructure:coin_stack_gold",properties:{size:"8"}}}
:enddata
:endrule

rule:
plugin=blockTile
number=168
data:
JSON:{blockState:{blockName:"ancientwarfarestructure:altar_candle"},teData:{customColor:0b,dyeColor:15,customData:"",id:"ancientwarfarestructure:altar_candle_tile",unlocalizedNamePart:""}}
:enddata
:endrule

rule:
plugin=blockTile
number=169
data:
JSON:{blockState:{blockName:"ancientwarfarestructure:chair",properties:{visible:"false",variant:"oak",facing:"south"}},facing:"west",teData:{facing:"east",id:"ancientwarfarestructure:chair_tile",mainBlockPos:-15667235390151L}}
:enddata
:endrule

rule:
plugin=blockTile
number=170
data:
JSON:{blockState:{blockName:"ancientwarfarestructure:chair",properties:{visible:"false",variant:"oak",facing:"south"}},facing:"east",teData:{facing:"west",id:"ancientwarfarestructure:chair_tile",mainBlockPos:-14842601669319L}}
:enddata
:endrule

rule:
plugin=blockTile
number=171
data:
JSON:{blockState:{blockName:"ancientwarfarestructure:chair",properties:{visible:"false",variant:"oak",facing:"south"}},facing:"west",teData:{facing:"east",id:"ancientwarfarestructure:chair_tile",mainBlockPos:-20065281901254L}}
:enddata
:endrule

rule:
plugin=blockTile
number=172
data:
JSON:{blockState:{blockName:"ancientwarfarestructure:chair",properties:{visible:"false",variant:"oak",facing:"south"}},facing:"east",teData:{facing:"west",id:"ancientwarfarestructure:chair_tile",mainBlockPos:-19240648180422L}}
:enddata
:endrule

rule:
plugin=vanillaBlocks
number=173
data:
JSON:{blockState:{blockName:"ancientwarfarestructure:coin_stack_copper",properties:{size:"16"}}}
:enddata
:endrule

rule:
plugin=blockTile
number=174
data:
JSON:{blockState:{blockName:"ancientwarfarestructure:chair",properties:{visible:"false",variant:"birch",facing:"south"}},facing:"south",teData:{facing:"north",id:"ancientwarfarestructure:chair_tile",mainBlockPos:-17591380738758L}}
:enddata
:endrule

rule:
plugin=blockTile
number=175
data:
JSON:{blockState:{blockName:"ancientwarfarestructure:chair",properties:{visible:"false",variant:"oak",facing:"south"}},facing:"west",teData:{facing:"east",id:"ancientwarfarestructure:chair_tile",mainBlockPos:-15667235390150L}}
:enddata
:endrule

rule:
plugin=blockTile
number=176
data:
JSON:{blockState:{blockName:"ancientwarfarestructure:chair",properties:{visible:"false",variant:"oak",facing:"south"}},facing:"east",teData:{facing:"west",id:"ancientwarfarestructure:chair_tile",mainBlockPos:-14842601669318L}}
:enddata
:endrule

rule:
plugin=blockTile
number=177
data:
JSON:{blockState:{blockName:"ancientwarfarestructure:chair",properties:{visible:"false",variant:"oak",facing:"south"}},facing:"west",teData:{facing:"east",id:"ancientwarfarestructure:chair_tile",mainBlockPos:-20065281901253L}}
:enddata
:endrule

rule:
plugin=blockTile
number=178
data:
JSON:{blockState:{blockName:"ancientwarfarestructure:chair",properties:{visible:"false",variant:"oak",facing:"south"}},facing:"east",teData:{facing:"west",id:"ancientwarfarestructure:chair_tile",mainBlockPos:-19240648180421L}}
:enddata
:endrule

rule:
plugin=blockTile
number=179
data:
JSON:{blockState:{blockName:"ancientwarfarestructure:chair",properties:{visible:"false",variant:"oak",facing:"south"}},facing:"west",teData:{facing:"east",id:"ancientwarfarestructure:chair_tile",mainBlockPos:-15667235390149L}}
:enddata
:endrule

rule:
plugin=blockTile
number=180
data:
JSON:{blockState:{blockName:"ancientwarfarestructure:chair",properties:{visible:"false",variant:"oak",facing:"south"}},facing:"east",teData:{facing:"west",id:"ancientwarfarestructure:chair_tile",mainBlockPos:-14842601669317L}}
:enddata
:endrule

rule:
plugin=flag
number=181
data:
JSON:{blockState:{blockName:"ancientwarfarestructure:protection_flag",properties:{rotation:"14"}},teData:{name:"guild",id:"ancientwarfarestructure:protection_flag_tile"}}
:enddata
:endrule

rule:
plugin=vanillaBlocks
number=182
data:
JSON:{blockState:{blockName:"minecraft:stone_pressure_plate",properties:{powered:"false"}}}
:enddata
:endrule

rule:
plugin=inventory
number=183
data:
JSON:{blockState:{blockName:"minecraft:furnace",properties:{facing:"north"}},lootLevel:0,teData:{CookTime:0,BurnTime:0,Items:[],id:"minecraft:furnace",CookTimeTotal:0,Lock:""},inventoryData:{length:0,inventoryContents:[]},legacyFeatures:0b}
:enddata
:endrule

rule:
plugin=inventory
number=184
data:
JSON:{blockState:{blockName:"minecraft:furnace",properties:{facing:"north"}},lootLevel:0,teData:{CookTime:0,BurnTime:0,Items:[],id:"minecraft:furnace",CookTimeTotal:0,Lock:""},inventoryData:{length:0,inventoryContents:[]},legacyFeatures:0b}
:enddata
:endrule

rule:
plugin=blockTile
number=185
data:
JSON:{blockState:{blockName:"ancientwarfarestructure:altar_candle"},teData:{customColor:0b,dyeColor:15,customData:"",id:"ancientwarfarestructure:altar_candle_tile",unlocalizedNamePart:""}}
:enddata
:endrule

rule:
plugin=blockTile
number=186
data:
JSON:{blockState:{blockName:"ancientwarfarestructure:altar_candle"},teData:{customColor:0b,dyeColor:15,customData:"",id:"ancientwarfarestructure:altar_candle_tile",unlocalizedNamePart:""}}
:enddata
:endrule

rule:
plugin=blockTile
number=187
data:
JSON:{blockState:{blockName:"ancientwarfarestructure:advanced_loot_chest",properties:{facing:"west"}},teData:{lootSettings:{lootRolls:1,splashPotion:0b,hasMessage:0b,hasLoot:1b,lootTableName:"ancientwarfare:chests/village_farm_mixed",spawnEntity:0b,entity:"minecraft:"},Items:[],id:"ancientwarfarestructure:advanced_loot_chest_tile",Lock:""}}
:enddata
:endrule

rule:
plugin=blockTile
number=188
data:
JSON:{blockState:{blockName:"ancientwarfarestructure:chair",properties:{visible:"false",variant:"birch",facing:"south"}},facing:"west",teData:{facing:"east",id:"ancientwarfarestructure:chair_tile",mainBlockPos:-19790403994289L}}
:enddata
:endrule

rule:
plugin=blockTile
number=189
data:
JSON:{blockState:{blockName:"ancientwarfarestructure:advanced_loot_chest",properties:{facing:"west"}},teData:{lootSettings:{lootRolls:1,splashPotion:0b,hasMessage:0b,hasLoot:1b,lootTableName:"ancientwarfare:chests/village_farm_mixed",spawnEntity:0b,entity:"minecraft:"},Items:[],id:"ancientwarfarestructure:advanced_loot_chest_tile",Lock:""}}
:enddata
:endrule

rule:
plugin=blockTile
number=190
data:
JSON:{blockState:{blockName:"ancientwarfarestructure:chair",properties:{visible:"false",variant:"birch",facing:"south"}},facing:"south",teData:{facing:"north",id:"ancientwarfarestructure:chair_tile",mainBlockPos:-19790403994288L}}
:enddata
:endrule

rule:
plugin=blockTile
number=191
data:
JSON:{blockState:{blockName:"ancientwarfarestructure:altar_candle"},teData:{customColor:0b,dyeColor:15,customData:"",id:"ancientwarfarestructure:altar_candle_tile",unlocalizedNamePart:""}}
:enddata
:endrule

rule:
plugin=blockTile
number=192
data:
