# Ancient Warfare Structure Template File
# Auto-generated structure template file. created on: 5/27/2021 at: 22:18:13
# Lines beginning with # denote comments

header:
version=2.11
name=SurvivalBuildHarborSWAirshipTower
mods=
size=16,49,16
offset=15,5,15
:endheader

#### VALIDATION ####
validation:
type=ground
structureAuthor=Loki61089
survival=true
worldGenEnabled=false
unique=false
preserveBlocks=true
preventNaturalHostileSpawns=false
selectionWeight=1
clusterValue=1
minDuplicateDistance=1
dimensionWhiteList=true
dimensionList=
biomeGroupList=
biomeWhiteList=true
biomeList=
leveling=0
fill=0
border=0
blockSwap=false
territoryName=
biomeReplacement=minecraft:
minGenerationHeight=0
maxGenerationHeight=255
:endvalidation

#### LAYERS ####
layer: 0
4,4,4,4,4,4,4,4,4,4,4,4,4,4,4,4
4,4,4,4,4,4,4,4,4,4,4,4,4,4,4,4
4,4,4,4,4,4,4,4,4,4,4,4,4,4,4,4
4,4,4,4,4,4,4,4,4,4,4,4,4,4,4,4
4,4,4,4,4,4,4,4,4,4,4,4,4,4,4,4
4,4,4,4,4,4,4,4,4,4,4,4,4,4,4,4
4,4,4,4,4,4,4,4,4,4,4,4,4,4,4,4
3,4,4,4,4,4,4,4,4,4,4,4,4,4,4,3
3,4,4,4,4,4,4,4,4,4,4,4,4,4,4,3
3,3,3,3,3,3,3,3,3,3,3,3,3,3,3,3
2,0,0,0,2,3,3,3,3,3,3,2,0,0,0,2
0,0,0,0,5,2,3,3,3,3,2,5,0,0,0,0
0,0,0,0,0,0,5,2,2,5,0,0,0,0,0,0
0,0,0,0,0,0,0,0,0,0,0,0,0,0,0,0
1,0,0,0,0,1,0,0,0,0,1,0,0,0,0,1
0,0,0,0,0,0,0,0,0,0,0,0,0,0,0,0
:endlayer
layer: 1
4,4,4,4,4,4,4,4,4,4,4,4,4,4,4,4
4,4,4,4,4,4,4,4,4,4,4,4,4,4,4,4
4,4,4,4,4,4,4,4,4,4,4,4,4,4,4,4
4,4,4,4,4,4,4,4,4,4,4,4,4,4,4,4
4,4,4,4,4,4,4,4,4,4,4,4,4,4,4,4
4,4,4,4,4,4,4,4,4,4,4,4,4,4,4,4
4,4,4,4,4,4,4,4,4,4,4,4,4,4,4,4
3,4,4,4,4,4,4,4,4,4,4,4,4,4,4,3
3,4,4,4,4,4,4,4,4,4,4,4,4,4,4,3
3,3,3,3,3,3,3,3,3,3,3,3,3,3,3,3
2,0,0,0,2,3,3,3,3,3,3,2,0,0,0,2
0,0,0,0,5,2,3,3,3,3,2,5,0,0,0,0
0,0,0,0,0,0,5,2,2,5,0,0,0,0,0,0
0,0,0,0,0,0,0,0,0,0,0,0,0,0,0,0
1,0,0,0,0,1,0,0,0,0,1,0,0,0,0,1
0,0,0,0,0,0,0,0,0,0,0,0,0,0,0,0
:endlayer
layer: 2
4,4,4,4,4,4,4,4,4,4,4,4,4,4,4,4
4,4,4,4,4,4,4,4,4,4,4,4,4,4,4,4
4,4,4,4,4,4,4,4,4,4,4,4,4,4,4,4
4,4,4,4,4,4,4,4,4,4,4,4,4,4,4,4
4,4,4,4,4,4,4,4,4,4,4,4,4,4,4,4
4,4,4,4,4,4,4,4,4,4,4,4,4,4,4,4
4,4,4,4,4,4,4,4,4,4,4,4,4,4,4,4
3,4,4,4,4,4,4,4,4,4,4,4,4,4,4,3
3,4,4,4,4,4,4,4,4,4,4,4,4,4,4,3
3,3,3,3,3,3,3,3,3,3,3,3,3,3,3,3
2,0,0,0,2,3,3,3,3,3,3,2,0,0,0,2
0,0,0,0,5,2,3,3,3,3,2,5,0,0,0,0
0,0,0,0,0,0,5,2,2,5,0,0,0,0,0,0
0,0,0,0,0,0,0,0,0,0,0,0,0,0,0,0
1,0,0,0,0,1,0,0,0,0,1,0,0,0,0,1
0,0,0,0,0,0,0,0,0,0,0,0,0,0,0,0
:endlayer
layer: 3
4,4,4,4,4,4,4,4,4,4,4,4,4,4,4,4
4,4,4,4,4,4,4,4,4,4,4,4,4,4,4,4
4,4,4,4,4,4,4,4,4,4,4,4,4,4,4,4
4,4,4,4,4,4,4,4,4,4,4,4,4,4,4,4
4,4,4,4,4,4,4,4,4,4,4,4,4,4,4,4
4,4,4,4,4,4,4,4,4,4,4,4,4,4,4,4
4,4,4,4,4,4,4,4,4,4,4,4,4,4,4,4
3,4,4,4,4,4,4,4,4,4,4,4,4,4,4,3
3,4,4,4,4,4,4,4,4,4,4,4,4,4,4,3
3,3,3,3,3,3,3,3,3,3,3,3,3,3,3,3
2,0,0,0,2,3,3,3,3,3,3,2,0,0,0,2
0,0,0,0,5,2,3,3,3,3,2,5,0,0,0,0
0,0,0,0,0,0,5,2,2,5,0,0,0,0,0,0
0,0,0,0,0,0,0,0,0,0,0,0,0,0,0,0
1,0,0,0,0,1,0,0,0,0,1,0,0,0,0,1
0,0,0,0,0,0,0,0,0,0,0,0,0,0,0,0
:endlayer
layer: 4
4,4,4,4,4,4,4,4,4,4,4,4,4,4,4,4
4,4,4,4,4,4,4,4,4,4,4,4,4,4,4,4
4,4,4,4,4,4,4,4,4,4,4,4,4,4,4,4
4,4,4,4,4,4,4,4,4,4,4,4,4,4,4,4
4,4,4,4,4,4,4,4,4,4,4,4,4,4,4,4
4,4,4,4,4,4,4,4,4,4,4,4,4,4,4,4
4,4,4,4,4,4,4,4,4,4,4,4,4,4,4,4
3,4,0,4,4,4,4,4,4,4,4,4,4,4,4,3
3,4,4,4,4,4,4,4,4,4,4,4,4,4,4,3
3,3,3,3,3,3,3,3,3,3,3,3,3,3,3,3
2,0,0,0,2,3,3,3,3,3,3,2,0,0,0,2
0,0,0,0,5,2,3,3,3,3,2,5,0,0,0,0
0,0,0,0,0,0,5,2,2,5,0,0,0,0,0,0
0,0,0,0,0,0,0,0,0,0,0,0,0,0,0,0
1,0,0,0,0,1,0,0,0,0,1,0,0,0,0,1
0,0,0,0,0,0,0,0,0,0,0,0,0,0,0,0
:endlayer
layer: 5
4,4,4,4,4,4,4,4,4,4,4,4,4,4,4,4
4,4,4,4,4,4,4,4,4,4,4,4,4,4,4,4
4,4,4,4,4,4,4,4,4,4,4,4,4,4,4,4
4,4,4,4,4,4,4,4,4,4,4,4,4,4,4,4
4,4,4,4,4,4,4,4,4,3,4,4,4,4,4,4
4,4,4,4,4,4,4,4,4,3,3,3,4,4,4,4
4,4,4,4,4,4,4,4,4,3,3,3,4,4,4,4
3,4,4,4,4,4,4,4,4,3,3,3,4,4,4,3
3,4,4,4,4,4,4,4,4,3,3,3,4,4,4,3
3,3,3,3,3,3,3,3,3,3,3,3,3,3,3,3
2,6,6,6,2,3,3,3,3,3,3,2,6,6,6,2
6,6,6,6,5,2,3,3,3,3,2,5,6,6,6,6
6,6,6,6,6,6,5,2,2,5,6,6,6,6,6,6
6,6,6,6,6,6,6,6,6,6,6,6,6,6,6,6
1,6,6,6,6,1,6,6,6,6,1,6,6,6,6,1
0,0,0,0,0,0,0,0,0,0,0,0,0,0,0,0
:endlayer
layer: 6
3,3,3,3,3,3,3,3,3,3,3,3,3,3,3,3
3,4,4,4,4,4,4,4,4,4,4,4,4,4,4,3
3,4,4,4,4,4,4,4,4,4,4,4,4,4,4,3
3,4,4,4,4,4,4,4,4,2,4,4,4,4,4,3
3,4,4,4,4,4,4,4,4,3,2,4,4,4,4,3
3,4,4,4,4,4,4,4,4,3,3,2,4,4,4,3
3,4,4,4,4,4,4,4,4,3,3,3,2,4,4,3
3,4,4,4,4,4,4,4,4,3,3,3,2,4,4,3
3,4,4,4,4,4,2,2,2,7,7,2,2,4,4,3
3,3,3,3,3,2,0,0,0,0,0,2,2,3,3,3
2,0,0,0,2,2,0,0,0,0,0,2,0,0,0,2
0,0,0,0,5,2,0,0,0,0,2,5,0,0,0,0
0,0,0,0,0,0,5,0,0,5,0,0,0,0,0,0
0,0,0,0,0,0,0,0,0,0,0,0,0,0,0,0
1,0,0,0,0,1,0,0,0,0,1,0,0,0,0,1
0,0,0,0,0,0,0,0,0,0,0,0,0,0,0,0
:endlayer
layer: 7
3,3,3,3,3,3,3,3,3,3,3,3,3,3,3,3
3,4,4,4,4,4,4,4,4,4,4,4,4,4,4,3
3,4,4,4,4,4,4,4,4,4,4,4,4,4,4,3
3,4,4,4,4,4,4,4,4,2,4,4,4,4,4,3
3,4,4,4,4,4,4,4,4,2,2,4,4,4,4,3
3,4,4,4,4,4,4,4,4,2,2,2,4,4,4,3
3,4,4,4,4,4,4,4,4,2,2,2,2,4,4,3
3,4,4,4,4,4,4,4,2,7,7,2,2,4,4,3
3,4,4,4,4,4,2,2,2,0,0,2,2,4,4,3
3,3,3,3,3,2,0,0,0,0,0,2,2,3,3,3
2,0,0,0,2,2,0,0,0,0,0,2,0,0,0,2
8,0,0,0,5,2,0,0,0,0,2,5,0,0,0,8
0,0,0,0,0,0,5,0,0,5,0,0,0,0,0,0
0,0,0,0,0,0,0,0,0,0,0,0,0,0,0,0
0,0,0,0,0,0,0,0,0,0,0,0,0,0,0,0
0,0,0,0,0,0,0,0,0,0,0,0,0,0,0,0
:endlayer
layer: 8
3,3,3,3,3,3,3,3,3,3,3,3,3,3,3,3
3,4,4,4,4,4,4,4,4,4,4,4,4,4,4,3
3,4,4,4,4,4,4,4,4,4,4,4,4,4,4,3
3,4,4,4,4,4,4,4,4,2,4,4,4,4,4,3
3,4,4,4,4,4,4,2,2,2,2,4,4,4,4,3
3,4,4,4,4,4,2,2,10,0,0,2,4,4,4,3
3,4,4,4,4,4,4,2,10,0,0,2,2,4,4,3
3,4,4,4,4,4,4,4,2,0,0,2,2,4,4,3
3,4,4,4,4,4,2,2,2,0,0,2,2,4,4,3
3,3,3,3,3,2,0,0,0,0,0,2,2,3,3,3
2,9,0,0,2,2,0,0,0,0,0,2,0,0,11,2
0,0,0,0,5,2,0,0,0,0,2,5,0,0,0,0
0,0,0,0,0,0,5,2,2,5,0,0,0,0,0,0
0,0,0,0,0,0,0,0,0,0,0,0,0,0,0,0
0,0,0,0,0,0,0,0,0,0,0,0,0,0,0,0
0,0,0,0,0,0,0,0,0,0,0,0,0,0,0,0
:endlayer
layer: 9
3,3,3,3,3,3,3,3,3,3,3,3,3,3,3,3
3,3,3,3,3,3,3,3,3,3,3,3,3,3,3,3
3,3,3,3,3,3,3,3,3,3,3,3,3,3,3,3
3,3,3,3,3,3,3,5,5,2,3,3,3,3,3,3
3,3,3,3,3,5,2,2,2,2,5,3,3,3,3,3
3,3,3,3,5,2,2,10,0,0,0,5,3,3,3,3
3,3,3,3,3,2,2,10,0,0,0,2,2,3,3,3
3,3,3,3,3,2,2,2,2,0,0,2,2,3,3,3
3,3,3,3,3,2,2,2,2,0,0,2,2,3,3,3
3,3,3,3,3,2,2,9,0,0,0,2,2,3,3,3
5,5,5,5,5,2,2,9,0,0,0,5,5,5,5,5
0,0,0,0,5,5,2,12,12,12,5,5,0,0,0,0
0,0,0,0,0,0,5,5,5,5,0,0,0,0,0,0
0,0,0,0,0,0,0,0,0,0,0,0,0,0,0,0
0,0,0,0,0,0,0,0,0,0,0,0,0,0,0,0
0,0,0,0,0,0,0,0,0,0,0,0,0,0,0,0
:endlayer
layer: 10
0,0,0,0,0,0,0,0,0,0,0,0,0,0,0,0
0,0,0,0,0,0,0,0,0,0,0,0,0,0,0,0
0,0,14,0,0,0,0,0,0,0,0,0,0,14,0,0
0,0,0,0,0,0,5,16,16,5,0,0,0,0,0,0
0,0,0,0,5,2,2,7,7,2,2,5,0,0,0,0
0,0,0,0,2,0,0,0,0,0,0,2,0,0,0,0
0,0,0,5,0,0,0,0,0,0,0,2,5,0,0,0
0,0,0,0,0,0,0,2,2,0,0,15,10,0,0,0
0,0,0,0,0,0,0,2,2,0,0,15,10,0,0,0
0,0,0,5,0,0,0,15,9,0,0,2,5,0,0,0
5,13,13,13,2,0,0,15,9,0,0,2,13,13,13,5
0,0,0,0,5,2,2,2,2,2,2,5,0,0,0,0
0,0,0,0,0,0,5,2,2,5,0,0,0,0,0,0
0,0,0,0,0,0,0,0,0,0,0,0,0,0,0,0
0,0,0,0,0,0,0,0,0,0,0,0,0,0,0,0
0,0,0,0,0,0,0,0,0,0,0,0,0,0,0,0
:endlayer
layer: 11
0,0,0,0,0,0,0,0,0,0,0,0,0,0,0,0
0,0,0,0,0,0,0,0,0,0,0,0,0,0,0,0
0,0,0,0,0,0,0,0,0,0,0,0,0,0,0,0
0,0,0,0,0,0,5,0,0,5,0,0,0,0,0,0
0,0,0,0,5,2,2,0,0,2,2,5,0,0,0,0
0,0,0,0,2,0,0,0,0,0,0,2,0,0,0,0
0,0,0,5,0,0,0,0,0,0,0,2,5,0,0,0
0,0,0,0,0,0,0,2,2,0,0,0,0,0,0,0
0,0,0,0,0,0,0,2,2,0,0,0,0,0,0,0
0,0,0,5,0,0,0,0,15,17,17,2,5,0,0,0
14,0,0,0,2,0,0,0,15,17,17,2,0,0,0,14
0,0,0,0,5,2,2,2,2,2,2,5,0,0,0,0
0,0,0,0,0,0,5,2,2,5,0,0,0,0,0,0
0,0,0,0,0,0,0,0,0,0,0,0,0,0,0,0
0,0,0,0,0,0,0,0,0,0,0,0,0,0,0,0
0,0,0,0,0,0,0,0,0,0,0,0,0,0,0,0
:endlayer
layer: 12
0,0,0,0,0,0,0,0,0,0,0,0,0,0,0,0
0,0,0,0,0,0,0,0,0,0,0,0,0,0,0,0
0,0,0,0,0,0,0,0,0,0,0,0,0,0,0,0
0,0,0,0,0,0,5,0,0,5,0,0,0,0,0,0
0,0,0,0,5,2,2,0,0,2,2,5,0,0,0,0
0,0,0,0,2,0,0,0,0,0,0,2,0,0,0,0
0,0,0,5,0,0,0,0,0,0,0,2,5,0,0,0
0,0,0,0,0,0,0,2,2,12,12,11,9,0,0,0
0,0,0,0,0,0,0,2,2,7,7,11,9,0,0,0
0,0,0,5,0,0,0,0,0,0,0,2,5,0,0,0
0,0,0,0,2,0,0,0,0,0,0,2,0,0,0,0
0,0,0,0,5,2,2,2,2,2,2,5,0,0,0,0
0,0,0,0,0,0,5,2,2,5,0,0,0,0,0,0
0,0,0,0,0,0,0,0,0,0,0,0,0,0,0,0
0,0,0,0,0,0,0,0,0,0,0,0,0,0,0,0
0,0,0,0,0,0,0,0,0,0,0,0,0,0,0,0
:endlayer
layer: 13
0,0,0,0,0,0,0,0,0,0,0,0,0,0,0,0
0,0,0,0,0,0,0,0,0,0,0,0,0,0,0,0
0,0,0,0,0,0,0,0,0,0,0,0,0,0,0,0
0,0,0,0,0,0,5,12,12,5,0,0,0,0,0,0
0,0,0,0,5,2,2,18,18,2,2,5,0,0,0,0
0,0,0,0,2,0,0,0,0,17,17,2,0,0,0,0
0,0,0,5,0,0,0,0,0,17,17,2,5,0,0,0
0,0,0,0,0,0,0,2,2,7,7,2,2,0,0,0
0,0,0,0,0,0,0,2,2,0,0,2,2,0,0,0
0,0,0,5,0,0,0,0,0,0,0,2,5,0,0,0
0,0,0,0,2,0,0,0,0,0,0,2,0,0,0,0
0,0,0,0,5,2,2,2,2,2,2,5,0,0,0,0
0,0,0,0,0,0,5,2,2,5,0,0,0,0,0,0
0,0,0,0,0,0,0,0,0,0,0,0,0,0,0,0
0,0,0,0,0,0,0,0,0,0,0,0,0,0,0,0
0,0,0,0,0,0,0,0,0,0,0,0,0,0,0,0
:endlayer
layer: 14
0,0,0,0,0,0,0,0,0,0,0,0,0,0,0,0
0,0,0,0,0,0,0,0,0,0,0,0,0,0,0,0
0,0,0,0,0,0,0,0,0,0,0,0,0,0,0,0
0,0,0,0,0,0,5,5,5,5,0,0,0,0,0,0
0,0,0,0,5,5,2,2,2,2,5,5,0,0,0,0
0,0,0,0,5,0,0,11,10,0,0,5,0,0,0,0
0,0,0,5,2,0,0,11,10,0,0,2,5,0,0,0
0,0,0,5,2,0,0,2,2,0,0,2,5,0,0,0
0,0,0,5,2,0,0,2,2,0,0,2,5,0,0,0
0,0,0,5,2,0,0,0,0,0,0,2,5,0,0,0
0,0,0,0,5,0,0,0,0,0,0,5,0,0,0,0
0,0,0,0,5,5,2,2,2,2,5,5,0,0,0,0
0,0,0,0,0,0,5,5,5,5,0,0,0,0,0,0
0,0,0,0,0,0,0,0,0,0,0,0,0,0,0,0
0,0,0,0,0,0,0,0,0,0,0,0,0,0,0,0
0,0,0,0,0,0,0,0,0,0,0,0,0,0,0,0
:endlayer
layer: 15
0,0,0,0,0,0,0,0,0,0,0,0,0,0,0,0
0,0,0,0,0,0,0,0,0,0,0,0,0,0,0,0
0,0,0,0,0,0,0,0,0,0,0,0,0,0,0,0
0,0,0,0,0,0,5,2,2,5,0,0,0,0,0,0
0,0,0,0,5,2,2,2,2,2,2,5,0,0,0,0
0,0,0,0,2,17,17,10,0,0,0,2,0,0,0,0
0,0,0,5,2,17,17,10,0,0,0,2,5,0,0,0
0,0,0,2,2,0,0,2,2,0,0,2,2,0,0,0
0,0,0,2,2,0,0,2,2,0,0,2,2,0,0,0
0,0,0,5,2,0,0,0,0,0,0,2,5,0,0,0
0,0,0,0,2,0,0,0,0,0,0,2,0,0,0,0
0,0,0,0,5,2,2,2,2,2,2,5,0,0,0,0
0,0,0,0,0,0,5,2,2,5,0,0,0,0,0,0
0,0,0,0,0,0,0,0,0,0,0,0,0,0,0,0
0,0,0,0,0,0,0,0,0,0,0,0,0,0,0,0
0,0,0,0,0,0,0,0,0,0,0,0,0,0,0,0
:endlayer
layer: 16
0,0,0,0,0,0,0,0,0,0,0,0,0,0,0,0
0,0,0,0,0,0,0,0,0,0,0,0,0,0,0,0
0,0,0,0,0,0,0,0,0,0,0,0,0,0,0,0
0,0,0,0,0,0,5,2,2,5,0,0,0,0,0,0
0,0,0,0,5,2,2,2,2,2,2,5,0,0,0,0
0,0,0,0,2,0,0,0,0,0,0,2,0,0,0,0
0,0,0,5,2,0,0,0,0,0,0,2,5,0,0,0
0,0,0,2,2,16,16,2,2,0,0,2,2,0,0,0
0,0,0,2,2,18,18,2,2,0,0,2,2,0,0,0
0,0,0,5,2,0,0,0,0,0,0,2,5,0,0,0
0,0,0,0,2,0,0,0,0,0,0,2,0,0,0,0
0,0,0,0,5,2,2,2,2,2,2,5,0,0,0,0
0,0,0,0,0,0,5,2,2,5,0,0,0,0,0,0
0,0,0,0,0,0,0,0,0,0,0,0,0,0,0,0
0,0,0,0,0,0,0,0,0,0,0,0,0,0,0,0
0,0,0,0,0,0,0,0,0,0,0,0,0,0,0,0
:endlayer
layer: 17
0,0,0,0,0,0,0,0,0,0,0,0,0,0,0,0
0,0,0,0,0,0,0,0,0,0,0,0,0,0,0,0
0,0,0,0,0,0,0,0,0,0,0,0,0,0,0,0
0,0,0,0,0,0,5,2,2,5,0,0,0,0,0,0
0,0,0,0,5,2,2,2,2,2,2,5,0,0,0,0
0,0,0,0,2,0,0,0,0,0,0,2,0,0,0,0
0,0,0,5,2,0,0,0,0,0,0,2,5,0,0,0
0,0,0,2,2,0,0,2,2,0,0,2,2,0,0,0
0,0,0,2,2,16,16,2,2,0,0,2,2,0,0,0
0,0,0,5,2,17,17,0,0,0,0,2,5,0,0,0
0,0,0,0,2,17,17,0,0,0,0,2,0,0,0,0
0,0,0,0,5,2,2,2,2,2,2,5,0,0,0,0
0,0,0,0,0,0,5,2,2,5,0,0,0,0,0,0
0,0,0,0,0,0,0,0,0,0,0,0,0,0,0,0
0,0,0,0,0,0,0,0,0,0,0,0,0,0,0,0
0,0,0,0,0,0,0,0,0,0,0,0,0,0,0,0
:endlayer
layer: 18
0,0,0,0,0,0,0,0,0,0,0,0,0,0,0,0
0,0,0,0,0,0,0,0,0,0,0,0,0,0,0,0
0,0,0,0,0,0,0,0,0,0,0,0,0,0,0,0
0,0,0,0,0,0,5,2,2,5,0,0,0,0,0,0
0,0,0,0,5,2,2,2,2,2,2,5,0,0,0,0
0,0,0,0,2,0,0,0,0,0,0,2,0,0,0,0
0,0,0,5,2,0,0,0,0,0,0,2,5,0,0,0
0,0,0,2,2,0,0,2,2,0,0,2,2,0,0,0
0,0,0,2,2,0,0,2,2,0,0,2,2,0,0,0
0,0,0,5,2,0,0,15,9,0,0,2,5,0,0,0
0,0,0,0,2,0,0,15,9,0,0,2,0,0,0,0
0,0,0,0,5,2,2,2,2,2,2,5,0,0,0,0
0,0,0,0,0,0,5,2,2,5,0,0,0,0,0,0
0,0,0,0,0,0,0,0,0,0,0,0,0,0,0,0
0,0,0,0,0,0,0,0,0,0,0,0,0,0,0,0
0,0,0,0,0,0,0,0,0,0,0,0,0,0,0,0
:endlayer
layer: 19
0,0,0,0,0,0,0,0,0,0,0,0,0,0,0,0
0,0,0,0,0,0,0,0,0,0,0,0,0,0,0,0
0,0,0,0,0,0,0,0,0,0,0,0,0,0,0,0
0,0,0,0,0,0,5,2,2,5,0,0,0,0,0,0
0,0,0,0,5,2,2,2,2,2,2,5,0,0,0,0
0,0,0,0,2,0,0,0,0,0,0,2,0,0,0,0
0,0,0,5,2,0,0,0,0,0,0,2,5,0,0,0
0,0,0,2,2,0,0,2,2,0,0,2,2,0,0,0
0,0,0,2,2,0,0,2,2,0,0,2,2,0,0,0
0,0,0,5,2,0,0,0,15,17,17,2,5,0,0,0
0,0,0,0,2,0,0,0,15,17,17,2,0,0,0,0
0,0,0,0,5,2,2,2,2,2,2,5,0,0,0,0
0,0,0,0,0,0,5,2,2,5,0,0,0,0,0,0
0,0,0,0,0,0,0,0,0,0,0,0,0,0,0,0
0,0,0,0,0,0,0,0,0,0,0,0,0,0,0,0
0,0,0,0,0,0,0,0,0,0,0,0,0,0,0,0
:endlayer
layer: 20
0,0,0,0,0,0,0,0,0,0,0,0,0,0,0,0
0,0,0,0,0,0,0,0,0,0,0,0,0,0,0,0
0,0,0,0,0,0,0,0,0,0,0,0,0,0,0,0
0,0,0,0,0,0,5,2,2,5,0,0,0,0,0,0
0,0,0,0,5,2,2,2,2,2,2,5,0,0,0,0
0,0,0,0,2,0,0,0,0,0,0,2,0,0,0,0
0,0,0,5,2,0,0,0,0,0,0,2,5,0,0,0
0,0,0,2,2,0,0,2,2,12,12,2,2,0,0,0
0,0,0,2,2,0,0,2,2,7,7,2,2,0,0,0
0,0,0,5,2,0,0,0,0,0,0,2,5,0,0,0
0,0,0,0,2,0,0,0,0,0,0,2,0,0,0,0
0,0,0,0,5,2,2,2,2,2,2,5,0,0,0,0
0,0,0,0,0,0,5,2,2,5,0,0,0,0,0,0
0,0,0,0,0,0,0,0,0,0,0,0,0,0,0,0
0,0,0,0,0,0,0,0,0,0,0,0,0,0,0,0
0,0,0,0,0,0,0,0,0,0,0,0,0,0,0,0
:endlayer
layer: 21
0,0,0,0,0,0,0,0,0,0,0,0,0,0,0,0
0,0,0,0,0,0,0,0,0,0,0,0,0,0,0,0
0,0,0,0,0,0,0,0,0,0,0,0,0,0,0,0
0,0,0,0,0,0,5,2,2,5,0,0,0,0,0,0
0,0,0,0,5,2,2,2,2,2,2,5,0,0,0,0
0,0,0,0,2,0,0,0,0,17,17,2,0,0,0,0
0,0,0,5,2,0,0,0,0,17,17,2,5,0,0,0
0,0,0,2,2,0,0,2,2,7,7,2,2,0,0,0
0,0,0,2,2,0,0,2,2,0,0,2,2,0,0,0
0,0,0,5,2,0,0,0,0,0,0,2,5,0,0,0
0,0,0,0,2,0,0,0,0,0,0,2,0,0,0,0
0,0,0,0,5,2,2,2,2,2,2,5,0,0,0,0
0,0,0,0,0,0,5,2,2,5,0,0,0,0,0,0
0,0,0,0,0,0,0,0,0,0,0,0,0,0,0,0
0,0,0,0,0,0,0,0,0,0,0,0,0,0,0,0
0,0,0,0,0,0,0,0,0,0,0,0,0,0,0,0
:endlayer
layer: 22
0,0,0,0,0,0,0,0,0,0,0,0,0,0,0,0
0,0,0,0,0,0,0,0,0,0,0,0,0,0,0,0
0,0,0,0,0,0,0,0,0,0,0,0,0,0,0,0
0,0,0,0,0,0,5,2,2,5,0,0,0,0,0,0
0,0,0,0,5,2,2,2,2,2,2,5,0,0,0,0
0,0,0,0,2,0,0,11,10,0,0,2,0,0,0,0
0,0,0,5,2,0,0,11,10,0,0,2,5,0,0,0
0,0,0,2,2,0,0,2,2,0,0,2,2,0,0,0
0,0,0,2,2,0,0,2,2,0,0,2,2,0,0,0
0,0,0,5,2,0,0,0,0,0,0,2,5,0,0,0
0,0,0,0,2,0,0,0,0,0,0,2,0,0,0,0
0,0,0,0,5,2,2,2,2,2,2,5,0,0,0,0
0,0,0,0,0,0,5,2,2,5,0,0,0,0,0,0
0,0,0,0,0,0,0,0,0,0,0,0,0,0,0,0
0,0,0,0,0,0,0,0,0,0,0,0,0,0,0,0
0,0,0,0,0,0,0,0,0,0,0,0,0,0,0,0
:endlayer
layer: 23
0,0,0,0,0,0,0,0,0,0,0,0,0,0,0,0
0,0,0,0,0,0,0,0,0,0,0,0,0,0,0,0
0,0,0,0,0,0,0,0,0,0,0,0,0,0,0,0
0,0,0,0,0,0,5,2,2,5,0,0,0,0,0,0
0,0,0,0,5,2,2,2,2,2,2,5,0,0,0,0
0,0,0,0,2,17,17,10,0,0,0,2,0,0,0,0
0,0,0,5,2,17,17,10,0,0,0,2,5,0,0,0
0,0,0,2,2,0,0,2,2,0,0,2,2,0,0,0
0,0,0,2,2,0,0,2,2,0,0,2,2,0,0,0
0,0,0,5,2,0,0,0,0,0,0,2,5,0,0,0
0,0,0,0,2,0,0,0,0,0,0,2,0,0,0,0
0,0,0,0,5,2,2,2,2,2,2,5,0,0,0,0
0,0,0,0,0,0,5,2,2,5,0,0,0,0,0,0
0,0,0,0,0,0,0,0,0,0,0,0,0,0,0,0
0,0,0,0,0,0,0,0,0,0,0,0,0,0,0,0
0,0,0,0,0,0,0,0,0,0,0,0,0,0,0,0
:endlayer
layer: 24
0,0,0,0,0,0,0,0,0,0,0,0,0,0,0,0
0,0,0,0,0,0,0,0,0,0,0,0,0,0,0,0
0,0,0,0,0,0,0,0,0,0,0,0,0,0,0,0
0,0,0,0,0,0,5,2,2,5,0,0,0,0,0,0
0,0,0,0,5,2,2,2,2,2,2,5,0,0,0,0
0,0,0,0,2,0,0,0,0,0,0,2,0,0,0,0
0,0,0,5,2,0,0,0,0,0,0,2,5,0,0,0
0,0,0,2,2,16,16,2,2,0,0,2,2,0,0,0
0,0,0,2,2,18,18,2,2,0,0,2,2,0,0,0
0,0,0,5,2,0,0,0,0,0,0,2,5,0,0,0
0,0,0,0,2,0,0,0,0,0,0,2,0,0,0,0
0,0,0,0,5,2,2,2,2,2,2,5,0,0,0,0
0,0,0,0,0,0,5,2,2,5,0,0,0,0,0,0
0,0,0,0,0,0,0,0,0,0,0,0,0,0,0,0
0,0,0,0,0,0,0,0,0,0,0,0,0,0,0,0
0,0,0,0,0,0,0,0,0,0,0,0,0,0,0,0
:endlayer
layer: 25
0,0,0,0,0,0,0,0,0,0,0,0,0,0,0,0
0,0,0,0,0,0,0,0,0,0,0,0,0,0,0,0
0,0,0,0,0,0,0,0,0,0,0,0,0,0,0,0
0,0,0,0,0,0,5,2,2,5,0,0,0,0,0,0
0,0,0,0,5,2,2,2,2,2,2,5,0,0,0,0
0,0,0,0,2,0,0,0,0,0,0,2,0,0,0,0
0,0,0,5,2,0,0,0,0,0,0,2,5,0,0,0
0,0,0,2,2,0,0,2,2,0,0,2,2,0,0,0
0,0,0,2,2,16,16,2,2,0,0,2,2,0,0,0
0,0,0,5,2,17,17,0,0,0,0,2,5,0,0,0
0,0,0,0,2,17,17,0,0,0,0,2,0,0,0,0
0,0,0,0,5,2,2,2,2,2,2,5,0,0,0,0
0,0,0,0,0,0,5,2,2,5,0,0,0,0,0,0
0,0,0,0,0,0,0,0,0,0,0,0,0,0,0,0
0,0,0,0,0,0,0,0,0,0,0,0,0,0,0,0
0,0,0,0,0,0,0,0,0,0,0,0,0,0,0,0
:endlayer
layer: 26
0,0,0,0,0,0,0,0,0,0,0,0,0,0,0,0
0,0,0,0,0,0,0,0,0,0,0,0,0,0,0,0
0,0,0,0,0,0,0,0,0,0,0,0,0,0,0,0
0,0,0,0,0,0,5,2,2,5,0,0,0,0,0,0
0,0,0,0,5,2,2,2,2,2,2,5,0,0,0,0
0,0,0,0,2,0,0,0,0,0,0,2,0,0,0,0
0,0,0,5,2,0,0,0,0,0,0,2,5,0,0,0
0,0,0,2,2,0,0,2,2,0,0,2,2,0,0,0
0,0,0,2,2,0,0,2,2,0,0,2,2,0,0,0
0,0,0,5,2,0,0,15,9,0,0,2,5,0,0,0
0,0,0,0,2,0,0,15,9,0,0,2,0,0,0,0
0,0,0,0,5,2,2,2,2,2,2,5,0,0,0,0
0,0,0,0,0,0,5,2,2,5,0,0,0,0,0,0
0,0,0,0,0,0,0,0,0,0,0,0,0,0,0,0
0,0,0,0,0,0,0,0,0,0,0,0,0,0,0,0
0,0,0,0,0,0,0,0,0,0,0,0,0,0,0,0
:endlayer
layer: 27
0,0,0,0,0,0,0,0,0,0,0,0,0,0,0,0
0,0,0,0,0,0,0,0,0,0,0,0,0,0,0,0
0,0,0,0,0,0,0,0,0,0,0,0,0,0,0,0
0,0,0,0,0,0,5,2,2,5,0,0,0,0,0,0
0,0,0,0,5,2,2,2,2,2,2,5,0,0,0,0
0,0,0,0,2,0,0,0,0,0,0,2,0,0,0,0
0,0,0,5,2,0,0,0,0,0,0,2,5,0,0,0
0,0,0,2,2,0,0,2,2,0,0,2,2,0,0,0
0,0,0,2,2,0,0,2,2,0,0,2,2,0,0,0
0,0,0,5,2,0,0,0,15,17,17,2,5,0,0,0
0,0,0,0,2,0,0,0,15,17,17,2,0,0,0,0
0,0,0,0,5,2,2,2,2,2,2,5,0,0,0,0
0,0,0,0,0,0,5,2,2,5,0,0,0,0,0,0
0,0,0,0,0,0,0,0,0,0,0,0,0,0,0,0
0,0,0,0,0,0,0,0,0,0,0,0,0,0,0,0
0,0,0,0,0,0,0,0,0,0,0,0,0,0,0,0
:endlayer
layer: 28
0,0,0,0,0,0,0,0,0,0,0,0,0,0,0,0
0,0,0,0,0,0,0,0,0,0,0,0,0,0,0,0
0,0,0,0,0,0,0,0,0,0,0,0,0,0,0,0
0,0,0,0,0,0,5,2,2,5,0,0,0,0,0,0
0,0,0,0,5,2,2,2,2,2,2,5,0,0,0,0
0,0,0,0,2,0,0,0,0,0,0,2,0,0,0,0
0,0,0,5,2,0,0,0,0,0,0,2,5,0,0,0
0,0,0,2,2,0,0,2,2,12,12,2,2,0,0,0
0,0,0,2,2,0,0,2,2,7,7,2,2,0,0,0
0,0,0,5,2,0,0,0,0,0,0,2,5,0,0,0
0,0,0,0,2,0,0,0,0,0,0,2,0,0,0,0
0,0,0,0,5,2,2,2,2,2,2,5,0,0,0,0
0,0,0,0,0,0,5,2,2,5,0,0,0,0,0,0
0,0,0,0,0,0,0,0,0,0,0,0,0,0,0,0
0,0,0,0,0,0,0,0,0,0,0,0,0,0,0,0
0,0,0,0,0,0,0,0,0,0,0,0,0,0,0,0
:endlayer
layer: 29
0,0,0,0,0,0,0,0,0,0,0,0,0,0,0,0
0,0,0,0,0,0,0,0,0,0,0,0,0,0,0,0
0,0,0,0,0,0,0,0,0,0,0,0,0,0,0,0
0,0,0,0,0,0,5,2,2,5,0,0,0,0,0,0
0,0,0,0,5,2,2,2,2,2,2,5,0,0,0,0
0,0,0,0,2,0,0,0,0,17,17,2,0,0,0,0
0,0,0,5,2,0,0,0,0,17,17,2,5,0,0,0
0,0,0,2,2,0,0,2,2,7,7,2,2,0,0,0
0,0,0,2,2,0,0,2,2,0,0,2,2,0,0,0
0,0,0,5,2,0,0,0,0,0,0,2,5,0,0,0
0,0,0,0,2,0,0,0,0,0,0,2,0,0,0,0
0,0,0,0,5,2,2,2,2,2,2,5,0,0,0,0
0,0,0,0,0,0,5,2,2,5,0,0,0,0,0,0
0,0,0,0,0,0,0,0,0,0,0,0,0,0,0,0
0,0,0,0,0,0,0,0,0,0,0,0,0,0,0,0
0,0,0,0,0,0,0,0,0,0,0,0,0,0,0,0
:endlayer
layer: 30
0,0,0,0,0,0,0,0,0,0,0,0,0,0,0,0
0,0,0,0,0,0,0,0,0,0,0,0,0,0,0,0
0,0,0,0,0,0,0,0,0,0,0,0,0,0,0,0
0,0,0,0,0,0,5,2,2,5,0,0,0,0,0,0
0,0,0,0,5,2,2,2,2,2,2,5,0,0,0,0
0,0,0,0,2,0,0,11,10,0,0,2,0,0,0,0
0,0,0,5,2,0,0,11,10,0,0,2,5,0,0,0
0,0,0,2,2,0,0,2,2,0,0,2,2,0,0,0
0,0,0,2,2,0,0,2,2,0,0,2,2,0,0,0
0,0,0,5,2,0,0,0,0,0,0,2,5,0,0,0
0,0,0,0,2,0,0,0,0,0,0,2,0,0,0,0
0,0,0,0,5,2,2,2,2,2,2,5,0,0,0,0
0,0,0,0,0,0,5,2,2,5,0,0,0,0,0,0
0,0,0,0,0,0,0,0,0,0,0,0,0,0,0,0
0,0,0,0,0,0,0,0,0,0,0,0,0,0,0,0
0,0,0,0,0,0,0,0,0,0,0,0,0,0,0,0
:endlayer
layer: 31
0,0,0,0,0,0,0,0,0,0,0,0,0,0,0,0
0,0,0,0,0,0,0,0,0,0,0,0,0,0,0,0
0,0,0,0,0,0,0,0,0,0,0,0,0,0,0,0
0,0,0,0,0,0,5,2,2,5,0,0,0,0,0,0
0,0,0,0,5,2,2,2,2,2,2,5,0,0,0,0
0,0,0,0,2,17,17,10,0,0,0,2,0,0,0,0
0,0,0,5,2,17,17,10,0,0,0,2,5,0,0,0
0,0,0,2,2,0,0,2,2,0,0,2,2,0,0,0
0,0,0,2,2,0,0,2,2,0,0,2,2,0,0,0
0,0,0,5,2,0,0,0,0,0,0,2,5,0,0,0
0,0,0,0,2,0,0,0,0,0,0,2,0,0,0,0
0,0,0,0,5,2,2,2,2,2,2,5,0,0,0,0
0,0,0,0,0,0,5,2,2,5,0,0,0,0,0,0
0,0,0,0,0,0,0,0,0,0,0,0,0,0,0,0
0,0,0,0,0,0,0,0,0,0,0,0,0,0,0,0
0,0,0,0,0,0,0,0,0,0,0,0,0,0,0,0
:endlayer
layer: 32
0,0,0,0,0,0,0,0,0,0,0,0,0,0,0,0
0,0,0,0,0,0,0,0,0,0,0,0,0,0,0,0
0,0,0,0,0,0,0,0,0,0,0,0,0,0,0,0
0,0,0,0,0,0,5,2,2,5,0,0,0,0,0,0
0,0,0,0,5,2,2,2,2,2,2,5,0,0,0,0
0,0,0,0,2,0,0,0,0,0,0,2,0,0,0,0
0,0,0,5,2,0,0,0,0,0,0,2,5,0,0,0
0,0,0,2,2,16,16,2,2,0,0,2,2,0,0,0
0,0,0,2,2,18,18,2,2,0,0,2,2,0,0,0
0,0,0,5,2,0,0,0,0,0,0,2,5,0,0,0
0,0,0,0,2,0,0,0,0,0,0,2,0,0,0,0
0,0,0,0,5,2,2,2,2,2,2,5,0,0,0,0
0,0,0,0,0,0,5,2,2,5,0,0,0,0,0,0
0,0,0,0,0,0,0,0,0,0,0,0,0,0,0,0
0,0,0,0,0,0,0,0,0,0,0,0,0,0,0,0
0,0,0,0,0,0,0,0,0,0,0,0,0,0,0,0
:endlayer
layer: 33
0,0,0,0,0,0,0,0,0,0,0,0,0,0,0,0
0,0,0,0,0,0,0,0,0,0,0,0,0,0,0,0
0,0,0,0,11,12,12,12,12,12,12,9,0,0,0,0
0,0,0,11,12,2,5,2,2,5,2,12,9,0,0,0
0,0,11,12,5,2,2,2,2,2,2,5,12,9,0,0
0,0,11,2,2,0,0,0,0,0,0,2,2,9,0,0
0,0,11,5,2,0,0,0,0,0,0,2,5,9,0,0
0,0,11,2,2,0,0,2,2,0,0,2,2,9,0,0
0,0,11,2,2,16,16,2,2,0,0,2,2,9,0,0
0,0,11,5,2,17,17,0,0,0,0,2,5,9,0,0
0,0,11,2,2,17,17,0,0,0,0,2,2,9,0,0
0,0,18,11,5,2,2,2,2,2,2,5,9,18,0,0
0,0,0,18,18,2,5,2,2,5,2,9,18,0,0,0
0,0,0,0,11,18,18,18,18,18,18,18,0,0,0,0
0,0,0,0,0,0,0,0,0,0,0,0,0,0,0,0
0,0,0,0,0,0,0,0,0,0,0,0,0,0,0,0
:endlayer
layer: 34
0,0,0,0,0,0,0,0,0,0,0,0,0,0,0,0
0,0,0,0,0,0,0,0,0,0,0,0,0,0,0,0
0,0,0,0,2,2,2,2,2,2,2,2,0,0,0,0
0,0,0,2,2,2,5,2,2,5,2,2,2,0,0,0
0,0,2,2,5,2,2,2,2,2,2,5,2,2,0,0
0,0,2,2,2,0,0,0,0,0,0,2,2,2,0,0
0,0,2,5,2,0,0,0,0,0,0,2,5,2,0,0
0,0,2,2,2,0,0,2,2,0,0,2,2,2,0,0
0,0,2,2,2,0,0,2,2,0,0,2,2,2,0,0
0,0,2,5,2,0,0,15,9,0,0,2,5,2,0,0
0,0,2,2,2,0,0,15,9,0,0,2,2,2,0,0
0,0,2,2,5,2,2,2,2,2,2,5,2,2,0,0
0,0,0,2,2,2,5,2,2,5,2,2,2,0,0,0
0,0,0,0,2,2,2,2,2,2,2,2,0,0,0,0
0,0,0,0,0,0,0,0,0,0,0,0,0,0,0,0
0,0,0,0,0,0,0,0,0,0,0,0,0,0,0,0
:endlayer
layer: 35
0,0,0,0,0,12,0,0,0,0,12,0,0,0,0,0
0,0,0,11,12,2,12,12,12,12,2,12,12,0,0,0
0,0,11,12,2,2,2,2,2,2,2,2,9,12,0,0
0,11,12,2,2,2,5,2,2,5,2,2,2,9,12,0
0,11,2,2,5,2,2,2,2,2,2,5,2,2,9,0
11,2,2,2,2,0,0,0,0,0,0,2,2,2,2,9
0,11,2,5,2,0,0,0,0,0,0,2,5,2,9,0
0,11,2,2,2,0,0,2,2,0,0,2,5,2,9,0
0,11,2,2,2,0,0,2,2,0,0,2,5,2,9,0
0,11,2,5,2,0,0,0,15,17,17,2,5,2,9,0
11,2,2,2,2,0,0,0,15,17,17,2,2,2,2,9
0,11,2,2,5,2,2,2,2,2,2,5,2,2,9,0
0,11,18,2,2,2,5,5,5,5,2,2,2,18,9,0
0,0,11,18,2,2,2,2,2,2,2,2,18,9,0,0
0,0,0,11,18,2,18,18,18,18,2,18,9,0,0,0
0,0,0,0,0,18,0,0,0,0,18,0,0,0,0,0
:endlayer
layer: 36
0,0,0,0,0,23,12,12,12,12,23,0,0,0,0,0
0,0,0,2,2,23,20,20,20,20,23,2,2,0,0,0
0,0,1,2,6,23,20,20,20,20,23,20,2,1,0,0
0,2,2,22,22,23,20,20,20,20,23,20,20,2,2,0
0,2,6,21,20,5,2,2,2,2,5,20,20,20,2,0
19,19,19,19,5,6,6,6,6,6,6,5,19,19,19,19
20,20,20,20,20,6,6,6,6,6,6,20,20,20,20,24
20,20,20,20,20,6,6,20,20,6,6,20,20,20,20,24
20,20,20,20,2,6,6,20,20,7,7,2,20,20,20,24
20,20,20,20,2,0,0,0,0,0,0,2,20,20,20,24
19,19,19,19,5,0,0,0,0,0,0,5,19,19,19,19
0,2,20,20,20,5,2,2,2,2,5,20,20,20,2,0
0,2,2,20,20,23,20,20,20,20,23,20,20,2,2,0
0,0,1,2,20,23,20,20,20,20,23,20,2,1,0,0
0,0,0,2,2,23,20,20,20,20,23,2,2,0,0,0
0,0,0,0,0,23,18,18,18,18,23,0,0,0,0,0
:endlayer
layer: 37
0,0,0,0,0,1,13,13,13,13,1,0,0,0,0,0
0,0,0,13,13,13,0,0,0,0,13,13,13,0,0,0
0,0,1,13,0,0,0,0,0,0,0,0,13,1,0,0
0,13,13,0,0,0,0,0,0,0,0,0,0,13,13,0
0,13,0,0,0,5,2,2,2,2,5,0,0,0,13,0
1,13,0,0,5,0,0,0,0,0,0,5,0,0,13,1
0,0,0,0,0,0,0,0,0,0,0,0,0,0,0,0
0,0,0,0,0,0,0,0,0,0,0,0,0,0,0,0
0,0,0,0,2,13,13,13,13,0,0,2,0,0,0,0
0,0,0,0,2,0,0,0,0,0,0,2,0,0,0,0
1,13,0,0,5,0,0,0,0,0,0,5,0,0,13,1
0,13,0,0,0,5,2,2,2,2,5,0,0,0,13,0
0,13,13,0,0,0,0,0,0,0,0,0,0,13,13,0
0,0,1,13,0,0,0,0,0,0,0,0,13,1,0,0
0,0,0,13,13,13,0,0,0,0,13,13,13,0,0,0
0,0,0,0,0,1,13,13,13,13,1,0,0,0,0,0
:endlayer
layer: 38
0,0,0,0,0,0,0,0,0,0,0,0,0,0,0,0
0,0,0,0,0,0,0,0,0,0,0,0,0,0,0,0
0,0,0,0,0,0,0,0,0,0,0,0,0,0,0,0
0,0,0,0,0,0,0,0,0,0,0,0,0,0,0,0
0,0,0,0,0,5,2,0,0,2,5,0,0,0,0,0
0,0,0,0,5,0,0,0,0,0,0,5,0,0,0,0
0,0,0,0,0,0,0,0,0,0,0,0,0,0,0,0
0,0,0,0,0,0,0,0,0,0,0,0,0,0,0,0
0,0,0,0,2,0,0,0,0,0,0,2,0,0,0,0
0,0,0,0,2,0,0,0,0,0,0,2,0,0,0,0
0,0,0,0,5,0,0,0,0,0,0,5,0,0,0,0
0,0,0,0,0,5,2,0,0,2,5,0,0,0,0,0
0,0,0,0,0,0,0,0,0,0,0,0,0,0,0,0
0,0,0,0,0,0,0,0,0,0,0,0,0,0,0,0
0,0,0,0,0,0,0,0,0,0,0,0,0,0,0,0
0,0,0,0,0,0,0,0,0,0,0,0,0,0,0,0
:endlayer
layer: 39
0,0,0,0,0,0,0,0,0,0,0,0,0,0,0,0
0,0,0,0,0,0,0,0,0,0,0,0,0,0,0,0
0,0,0,0,0,0,0,0,0,0,0,0,0,0,0,0
0,0,0,0,0,0,0,0,0,0,0,0,0,0,0,0
0,0,0,0,0,5,2,0,0,2,5,0,0,0,0,0
0,0,0,0,5,0,0,0,0,0,0,5,0,0,0,0
0,0,0,0,2,0,0,0,0,0,0,2,0,0,0,0
0,0,0,0,2,0,0,0,0,0,0,2,0,0,0,0
0,0,0,0,2,0,0,0,0,0,0,2,0,0,0,0
0,0,0,0,2,0,0,0,0,0,0,2,0,0,0,0
0,0,0,0,5,0,0,0,0,0,0,5,0,0,0,0
0,0,0,0,0,5,2,0,0,2,5,0,0,0,0,0
0,0,0,0,0,0,0,0,0,0,0,0,0,0,0,0
0,0,0,0,0,0,0,0,0,0,0,0,0,0,0,0
0,0,0,0,0,0,0,0,0,0,0,0,0,0,0,0
0,0,0,0,0,0,0,0,0,0,0,0,0,0,0,0
:endlayer
layer: 40
0,0,0,0,0,0,0,0,0,0,0,0,0,0,0,0
0,0,0,0,0,0,0,0,0,0,0,0,0,0,0,0
0,0,0,0,0,0,0,0,0,0,0,0,0,0,0,0
0,0,0,0,26,26,26,26,26,26,26,28,0,0,0,0
0,0,0,26,25,5,5,5,5,5,5,26,28,0,0,0
0,0,0,25,5,6,6,6,6,6,6,5,28,0,0,0
0,0,0,25,5,6,6,6,6,6,6,5,28,0,0,0
0,0,0,25,5,6,6,6,6,6,6,5,28,0,0,0
0,0,0,25,5,6,6,6,6,6,6,5,28,0,0,0
0,0,0,25,5,6,6,6,6,6,6,5,28,0,0,0
0,0,0,25,5,6,6,6,6,6,6,5,28,0,0,0
0,0,0,25,27,5,5,5,5,5,5,27,28,0,0,0
0,0,0,0,25,27,27,27,27,27,27,28,0,0,0,0
0,0,0,0,0,0,0,0,0,0,0,0,0,0,0,0
0,0,0,0,0,0,0,0,0,0,0,0,0,0,0,0
0,0,0,0,0,0,0,0,0,0,0,0,0,0,0,0
:endlayer
layer: 41
0,0,0,0,0,0,0,0,0,0,0,0,0,0,0,0
0,0,0,0,0,0,0,0,0,0,0,0,0,0,0,0
0,0,0,0,0,0,0,0,0,0,0,0,0,0,0,0
0,0,0,0,0,0,0,0,0,0,0,0,0,0,0,0
0,0,0,0,0,20,20,20,20,20,20,0,0,0,0,0
0,0,0,0,20,20,20,20,20,20,20,20,0,0,0,0
0,0,0,0,20,20,20,20,20,20,20,20,0,0,0,0
0,0,0,0,20,20,20,20,20,20,20,20,0,0,0,0
0,0,0,0,20,20,20,20,20,20,20,20,0,0,0,0
0,0,0,0,20,20,20,20,20,20,20,20,0,0,0,0
0,0,0,0,20,20,20,20,20,20,20,20,0,0,0,0
0,0,0,0,0,20,20,20,20,20,20,0,0,0,0,0
0,0,0,0,0,0,0,0,0,0,0,0,0,0,0,0
0,0,0,0,0,0,0,0,0,0,0,0,0,0,0,0
0,0,0,0,0,0,0,0,0,0,0,0,0,0,0,0
0,0,0,0,0,0,0,0,0,0,0,0,0,0,0,0
:endlayer
layer: 42
0,0,0,0,0,0,0,0,0,0,0,0,0,0,0,0
0,0,0,0,0,0,0,0,0,0,0,0,0,0,0,0
0,0,0,0,0,0,0,0,0,0,0,0,0,0,0,0
0,0,0,0,0,0,0,0,0,0,0,0,0,0,0,0
0,0,0,0,0,26,26,26,26,26,28,0,0,0,0,0
0,0,0,0,26,25,20,20,20,20,26,28,0,0,0,0
0,0,0,0,25,20,20,20,20,20,20,28,0,0,0,0
0,0,0,0,25,20,20,20,20,20,20,28,0,0,0,0
0,0,0,0,25,20,20,20,20,20,20,28,0,0,0,0
0,0,0,0,25,20,20,20,20,20,20,28,0,0,0,0
0,0,0,0,25,27,20,20,20,20,27,28,0,0,0,0
0,0,0,0,0,25,27,27,27,27,28,0,0,0,0,0
0,0,0,0,0,0,0,0,0,0,0,0,0,0,0,0
0,0,0,0,0,0,0,0,0,0,0,0,0,0,0,0
0,0,0,0,0,0,0,0,0,0,0,0,0,0,0,0
0,0,0,0,0,0,0,0,0,0,0,0,0,0,0,0
:endlayer
layer: 43
0,0,0,0,0,0,0,0,0,0,0,0,0,0,0,0
0,0,0,0,0,0,0,0,0,0,0,0,0,0,0,0
0,0,0,0,0,0,0,0,0,0,0,0,0,0,0,0
0,0,0,0,0,0,0,0,0,0,0,0,0,0,0,0
0,0,0,0,0,0,0,0,0,0,0,0,0,0,0,0
0,0,0,0,0,0,20,20,20,20,0,0,0,0,0,0
0,0,0,0,0,20,20,20,20,20,20,0,0,0,0,0
0,0,0,0,0,20,20,20,20,20,20,0,0,0,0,0
0,0,0,0,0,20,20,20,20,20,20,0,0,0,0,0
0,0,0,0,0,20,20,20,20,20,20,0,0,0,0,0
0,0,0,0,0,0,20,20,20,20,0,0,0,0,0,0
0,0,0,0,0,0,0,0,0,0,0,0,0,0,0,0
0,0,0,0,0,0,0,0,0,0,0,0,0,0,0,0
0,0,0,0,0,0,0,0,0,0,0,0,0,0,0,0
0,0,0,0,0,0,0,0,0,0,0,0,0,0,0,0
0,0,0,0,0,0,0,0,0,0,0,0,0,0,0,0
:endlayer
layer: 44
0,0,0,0,0,0,0,0,0,0,0,0,0,0,0,0
0,0,0,0,0,0,0,0,0,0,0,0,0,0,0,0
0,0,0,0,0,0,0,0,0,0,0,0,0,0,0,0
0,0,0,0,0,0,0,0,0,0,0,0,0,0,0,0
0,0,0,0,0,0,0,0,0,0,0,0,0,0,0,0
0,0,0,0,0,0,25,26,26,28,0,0,0,0,0,0
0,0,0,0,0,25,26,20,20,28,26,0,0,0,0,0
0,0,0,0,0,25,20,20,20,20,28,0,0,0,0,0
0,0,0,0,0,25,20,20,20,20,28,0,0,0,0,0
0,0,0,0,0,27,25,20,20,28,27,0,0,0,0,0
0,0,0,0,0,0,27,27,27,27,0,0,0,0,0,0
0,0,0,0,0,0,0,0,0,0,0,0,0,0,0,0
0,0,0,0,0,0,0,0,0,0,0,0,0,0,0,0
0,0,0,0,0,0,0,0,0,0,0,0,0,0,0,0
0,0,0,0,0,0,0,0,0,0,0,0,0,0,0,0
0,0,0,0,0,0,0,0,0,0,0,0,0,0,0,0
:endlayer
layer: 45
0,0,0,0,0,0,0,0,0,0,0,0,0,0,0,0
0,0,0,0,0,0,0,0,0,0,0,0,0,0,0,0
0,0,0,0,0,0,0,0,0,0,0,0,0,0,0,0
0,0,0,0,0,0,0,0,0,0,0,0,0,0,0,0
0,0,0,0,0,0,0,0,0,0,0,0,0,0,0,0
0,0,0,0,0,0,0,0,0,0,0,0,0,0,0,0
0,0,0,0,0,0,0,20,20,0,0,0,0,0,0,0
0,0,0,0,0,0,20,20,20,20,0,0,0,0,0,0
0,0,0,0,0,0,20,20,20,20,0,0,0,0,0,0
0,0,0,0,0,0,0,20,20,0,0,0,0,0,0,0
0,0,0,0,0,0,0,0,0,0,0,0,0,0,0,0
0,0,0,0,0,0,0,0,0,0,0,0,0,0,0,0
0,0,0,0,0,0,0,0,0,0,0,0,0,0,0,0
0,0,0,0,0,0,0,0,0,0,0,0,0,0,0,0
0,0,0,0,0,0,0,0,0,0,0,0,0,0,0,0
0,0,0,0,0,0,0,0,0,0,0,0,0,0,0,0
:endlayer
layer: 46
0,0,0,0,0,0,0,0,0,0,0,0,0,0,0,0
0,0,0,0,0,0,0,0,0,0,0,0,0,0,0,0
0,0,0,0,0,0,0,0,0,0,0,0,0,0,0,0
0,0,0,0,0,0,0,0,0,0,0,0,0,0,0,0
0,0,0,0,0,0,0,0,0,0,0,0,0,0,0,0
0,0,0,0,0,0,0,0,0,0,0,0,0,0,0,0
0,0,0,0,0,0,0,25,28,0,0,0,0,0,0,0
0,0,0,0,0,0,26,20,20,26,0,0,0,0,0,0
0,0,0,0,0,0,27,20,20,27,0,0,0,0,0,0
0,0,0,0,0,0,0,25,28,0,0,0,0,0,0,0
0,0,0,0,0,0,0,0,0,0,0,0,0,0,0,0
0,0,0,0,0,0,0,0,0,0,0,0,0,0,0,0
0,0,0,0,0,0,0,0,0,0,0,0,0,0,0,0
0,0,0,0,0,0,0,0,0,0,0,0,0,0,0,0
0,0,0,0,0,0,0,0,0,0,0,0,0,0,0,0
0,0,0,0,0,0,0,0,0,0,0,0,0,0,0,0
:endlayer
layer: 47
0,0,0,0,0,0,0,0,0,0,0,0,0,0,0,0
0,0,0,0,0,0,0,0,0,0,0,0,0,0,0,0
0,0,0,0,0,0,0,0,0,0,0,0,0,0,0,0
0,0,0,0,0,0,0,0,0,0,0,0,0,0,0,0
0,0,0,0,0,0,0,0,0,0,0,0,0,0,0,0
0,0,0,0,0,0,0,0,0,0,0,0,0,0,0,0
0,0,0,0,0,0,0,0,0,0,0,0,0,0,0,0
0,0,0,0,0,0,0,20,20,0,0,0,0,0,0,0
0,0,0,0,0,0,0,20,20,0,0,0,0,0,0,0
0,0,0,0,0,0,0,0,0,0,0,0,0,0,0,0
0,0,0,0,0,0,0,0,0,0,0,0,0,0,0,0
0,0,0,0,0,0,0,0,0,0,0,0,0,0,0,0
0,0,0,0,0,0,0,0,0,0,0,0,0,0,0,0
0,0,0,0,0,0,0,0,0,0,0,0,0,0,0,0
0,0,0,0,0,0,0,0,0,0,0,0,0,0,0,0
0,0,0,0,0,0,0,0,0,0,0,0,0,0,0,0
:endlayer
layer: 48
0,0,0,0,0,0,0,0,0,0,0,0,0,0,0,0
0,0,0,0,0,0,0,0,0,0,0,0,0,0,0,0
0,0,0,0,0,0,0,0,0,0,0,0,0,0,0,0
0,0,0,0,0,0,0,0,0,0,0,0,0,0,0,0
0,0,0,0,0,0,0,0,0,0,0,0,0,0,0,0
0,0,0,0,0,0,0,0,0,0,0,0,0,0,0,0
0,0,0,0,0,0,0,0,0,0,0,0,0,0,0,0
0,0,0,0,0,0,0,26,28,0,0,0,0,0,0,0
0,0,0,0,0,0,0,25,27,0,0,0,0,0,0,0
0,0,0,0,0,0,0,0,0,0,0,0,0,0,0,0
0,0,0,0,0,0,0,0,0,0,0,0,0,0,0,0
0,0,0,0,0,0,0,0,0,0,0,0,0,0,0,0
0,0,0,0,0,0,0,0,0,0,0,0,0,0,0,0
0,0,0,0,0,0,0,0,0,0,0,0,0,0,0,0
0,0,0,0,0,0,0,0,0,0,0,0,0,0,0,0
0,0,0,0,0,0,0,0,0,0,0,0,0,0,0,0
:endlayer

#### RULES ####
rule:
plugin=vanillaBlocks
number=1
data:
JSON:{blockState:{blockName:"minecraft:log",properties:{variant:"spruce",axis:"y"}}}
:enddata
:endrule

rule:
plugin=vanillaBlocks
number=2
data:
JSON:{blockState:{blockName:"minecraft:stonebrick",properties:{variant:"stonebrick"}}}
:enddata
:endrule

rule:
plugin=vanillaBlocks
number=3
data:
JSON:{blockState:{blockName:"minecraft:cobblestone"}}
:enddata
:endrule

rule:
plugin=vanillaBlocks
number=4
data:
JSON:{blockState:{blockName:"minecraft:dirt",properties:{variant:"dirt",snowy:"false"}}}
:enddata
:endrule

rule:
plugin=vanillaBlocks
number=5
data:
JSON:{blockState:{blockName:"minecraft:stone",properties:{variant:"smooth_andesite"}}}
:enddata
:endrule

rule:
plugin=vanillaBlocks
number=6
data:
JSON:{blockState:{blockName:"minecraft:wooden_slab",properties:{half:"top",variant:"spruce"}}}
:enddata
:endrule

rule:
plugin=vanillaBlocks
number=7
data:
JSON:{blockState:{blockName:"minecraft:stone_brick_stairs",properties:{half:"bottom",shape:"straight",facing:"north"}}}
:enddata
:endrule

rule:
plugin=vanillaBlocks
number=8
data:
JSON:{blockState:{blockName:"minecraft:torch",properties:{facing:"south"}}}
:enddata
:endrule

rule:
plugin=vanillaBlocks
number=9
data:
JSON:{blockState:{blockName:"minecraft:stone_brick_stairs",properties:{half:"top",shape:"straight",facing:"west"}}}
:enddata
:endrule

rule:
plugin=vanillaBlocks
number=10
data:
JSON:{blockState:{blockName:"minecraft:stone_brick_stairs",properties:{half:"bottom",shape:"straight",facing:"west"}}}
:enddata
:endrule

rule:
plugin=vanillaBlocks
number=11
data:
JSON:{blockState:{blockName:"minecraft:stone_brick_stairs",properties:{half:"top",shape:"straight",facing:"east"}}}
:enddata
:endrule

rule:
plugin=vanillaBlocks
number=12
data:
JSON:{blockState:{blockName:"minecraft:stone_brick_stairs",properties:{half:"top",shape:"straight",facing:"south"}}}
:enddata
:endrule

rule:
plugin=vanillaBlocks
number=13
data:
JSON:{blockState:{blockName:"minecraft:spruce_fence",properties:{east:"false",south:"false",north:"false",west:"false"}}}
:enddata
:endrule

rule:
plugin=vanillaBlocks
number=14
data:
JSON:{blockState:{blockName:"minecraft:torch",properties:{facing:"up"}}}
:enddata
:endrule

rule:
plugin=vanillaBlocks
number=15
data:
JSON:{blockState:{blockName:"minecraft:stone_brick_stairs",properties:{half:"bottom",shape:"straight",facing:"east"}}}
:enddata
:endrule

rule:
plugin=vanillaBlocks
number=16
data:
JSON:{blockState:{blockName:"minecraft:stone_brick_stairs",properties:{half:"bottom",shape:"straight",facing:"south"}}}
:enddata
:endrule

rule:
plugin=vanillaBlocks
number=17
data:
JSON:{blockState:{blockName:"minecraft:stone_slab",properties:{half:"top",variant:"stone_brick"}}}
:enddata
:endrule

rule:
plugin=vanillaBlocks
number=18
data:
JSON:{blockState:{blockName:"minecraft:stone_brick_stairs",properties:{half:"top",shape:"straight",facing:"north"}}}
:enddata
:endrule

rule:
plugin=vanillaBlocks
number=19
data:
JSON:{blockState:{blockName:"minecraft:log",properties:{variant:"spruce",axis:"x"}}}
:enddata
:endrule

rule:
plugin=vanillaBlocks
number=20
data:
JSON:{blockState:{blockName:"minecraft:planks",properties:{variant:"spruce"}}}
:enddata
:endrule

rule:
plugin=vanillaBlocks
number=21
data:
JSON:{blockState:{blockName:"minecraft:spruce_stairs",properties:{half:"top",shape:"straight",facing:"east"}}}
:enddata
:endrule

rule:
plugin=vanillaBlocks
number=22
data:
JSON:{blockState:{blockName:"minecraft:spruce_stairs",properties:{half:"top",shape:"straight",facing:"south"}}}
:enddata
:endrule

rule:
plugin=vanillaBlocks
number=23
data:
JSON:{blockState:{blockName:"minecraft:log",properties:{variant:"spruce",axis:"z"}}}
:enddata
:endrule

rule:
plugin=vanillaBlocks
number=24
data:
JSON:{blockState:{blockName:"minecraft:spruce_stairs",properties:{half:"top",shape:"straight",facing:"west"}}}
:enddata
:endrule

rule:
plugin=vanillaBlocks
number=25
data:
JSON:{blockState:{blockName:"minecraft:spruce_stairs",properties:{half:"bottom",shape:"straight",facing:"east"}}}
:enddata
:endrule

rule:
plugin=vanillaBlocks
number=26
data:
JSON:{blockState:{blockName:"minecraft:spruce_stairs",properties:{half:"bottom",shape:"straight",facing:"south"}}}
:enddata
:endrule

rule:
plugin=vanillaBlocks
number=27
data:
JSON:{blockState:{blockName:"minecraft:spruce_stairs",properties:{half:"bottom",shape:"straight",facing:"north"}}}
:enddata
:endrule

rule:
plugin=vanillaBlocks
number=28
data:
JSON:{blockState:{blockName:"minecraft:spruce_stairs",properties:{half:"bottom",shape:"straight",facing:"west"}}}
:enddata
:endrule

#### ENTITIES ####
