# Ancient Warfare Structure Template File
# Auto-generated structure template file. created on: 5/27/2021 at: 22:16:55
# Lines beginning with # denote comments

header:
version=2.11
name=SurvivalBuildHarborOCLighthouse
mods=
size=16,42,16
offset=15,5,15
:endheader

#### VALIDATION ####
validation:
type=ground
structureAuthor=Loki61089
survival=true
worldGenEnabled=false
unique=false
preserveBlocks=true
preventNaturalHostileSpawns=false
selectionWeight=1
clusterValue=1
minDuplicateDistance=1
dimensionWhiteList=true
dimensionList=
biomeGroupList=
biomeWhiteList=true
biomeList=
leveling=0
fill=0
border=0
blockSwap=false
territoryName=
biomeReplacement=minecraft:
minGenerationHeight=0
maxGenerationHeight=255
:endvalidation

#### LAYERS ####
layer: 0
4,4,4,4,4,4,4,3,3,3,2,0,0,0,1,0
4,4,4,4,4,4,4,3,3,3,0,0,0,0,0,0
4,4,4,4,4,4,4,3,3,3,0,0,0,0,0,0
4,4,4,4,4,4,4,3,3,3,0,0,0,0,0,0
4,4,4,4,4,4,4,3,3,3,0,0,0,0,0,0
4,4,4,4,4,4,4,3,3,3,2,0,0,0,1,0
4,4,4,4,4,4,4,3,3,3,0,0,0,0,0,0
3,3,3,3,3,3,3,3,3,3,0,0,0,0,0,0
3,3,3,3,3,3,3,3,3,3,0,0,0,0,0,0
3,3,3,3,3,3,3,3,3,3,0,0,0,0,0,0
2,0,0,0,0,2,0,0,0,0,2,0,0,0,1,0
0,0,0,0,0,0,0,0,0,0,0,0,0,0,0,0
0,0,0,0,0,0,0,0,0,0,0,0,0,0,0,0
0,0,0,0,0,0,0,0,0,0,0,0,0,0,0,0
1,0,0,0,0,1,0,0,0,0,1,0,0,0,1,0
0,0,0,0,0,0,0,0,0,0,0,0,0,0,0,0
:endlayer
layer: 1
4,4,4,4,4,4,4,3,3,3,2,0,0,0,1,0
4,4,4,4,4,4,4,3,3,3,0,0,0,0,0,0
4,4,4,4,4,4,4,3,3,3,0,0,0,0,0,0
4,4,4,4,4,4,4,3,3,3,0,0,0,0,0,0
4,4,4,4,4,4,4,3,3,3,0,0,0,0,0,0
4,4,4,4,4,4,4,3,3,3,2,0,0,0,1,0
4,4,4,4,4,4,4,3,3,3,0,0,0,0,0,0
3,3,3,3,3,3,3,3,3,3,0,0,0,0,0,0
3,3,3,3,3,3,3,3,3,3,0,0,0,0,0,0
3,3,3,3,3,3,3,3,3,3,0,0,0,0,0,0
2,0,0,0,0,2,0,0,0,0,2,0,0,0,1,0
0,0,0,0,0,0,0,0,0,0,0,0,0,0,0,0
0,0,0,0,0,0,0,0,0,0,0,0,0,0,0,0
0,0,0,0,0,0,0,0,0,0,0,0,0,0,0,0
1,0,0,0,0,1,0,0,0,0,1,0,0,0,1,0
0,0,0,0,0,0,0,0,0,0,0,0,0,0,0,0
:endlayer
layer: 2
4,4,4,4,4,4,4,3,3,3,2,0,0,0,1,0
4,4,4,4,4,4,4,3,3,3,0,0,0,0,0,0
4,4,4,4,4,4,4,3,3,3,0,0,0,0,0,0
4,4,4,4,4,4,4,3,3,3,0,0,0,0,0,0
4,4,4,4,4,4,4,3,3,3,0,0,0,0,0,0
4,4,4,4,4,4,4,3,3,3,2,0,0,0,1,0
4,4,4,4,4,4,4,3,3,3,0,0,0,0,0,0
3,3,3,3,3,3,3,3,3,3,0,0,0,0,0,0
3,3,3,3,3,3,3,3,3,3,0,0,0,0,0,0
3,3,3,3,3,3,3,3,3,3,0,0,0,0,0,0
2,0,0,0,0,2,0,0,0,0,2,0,0,0,1,0
0,0,0,0,0,0,0,0,0,0,0,0,0,0,0,0
0,0,0,0,0,0,0,0,0,0,0,0,0,0,0,0
0,0,0,0,0,0,0,0,0,0,0,0,0,0,0,0
1,0,0,0,0,1,0,0,0,0,1,0,0,0,1,0
0,0,0,0,0,0,0,0,0,0,0,0,0,0,0,0
:endlayer
layer: 3
4,4,4,4,4,4,4,3,3,3,2,0,0,0,1,0
4,4,4,4,4,4,4,3,3,3,0,0,0,0,0,0
4,4,4,4,4,4,4,3,3,3,0,0,0,0,0,0
4,4,4,4,4,4,4,3,3,3,0,0,0,0,0,0
4,4,4,4,4,4,4,3,3,3,0,0,0,0,0,0
4,4,4,4,4,4,4,3,3,3,2,0,0,0,1,0
4,4,4,4,4,4,4,3,3,3,0,0,0,0,0,0
3,3,3,3,3,3,3,3,3,3,0,0,0,0,0,0
3,3,3,3,3,3,3,3,3,3,0,0,0,0,0,0
3,3,3,3,3,3,3,3,3,3,0,0,0,0,0,0
2,0,0,0,0,2,0,0,0,0,2,0,0,0,1,0
0,0,0,0,0,0,0,0,0,0,0,0,0,0,0,0
0,0,0,0,0,0,0,0,0,0,0,0,0,0,0,0
0,0,0,0,0,0,0,0,0,0,0,0,0,0,0,0
1,0,0,0,0,1,0,0,0,0,1,0,0,0,1,0
0,0,0,0,0,0,0,0,0,0,0,0,0,0,0,0
:endlayer
layer: 4
4,4,4,4,4,4,4,3,3,3,2,0,0,0,1,0
4,4,4,4,4,4,4,3,3,3,0,0,0,0,0,0
4,4,4,4,4,4,4,3,3,3,0,0,0,0,0,0
4,4,4,4,4,4,4,3,3,3,0,0,0,0,0,0
4,4,4,4,4,4,4,3,3,3,0,0,0,0,0,0
4,4,4,4,4,4,4,3,3,3,2,0,0,0,1,0
4,4,4,4,4,4,4,3,3,3,0,0,0,0,0,0
3,3,3,3,3,3,3,3,3,3,0,0,0,0,0,0
3,3,3,3,3,3,3,3,3,3,0,0,0,0,0,0
3,3,3,3,3,3,3,3,3,3,0,0,0,0,0,0
2,0,0,0,0,2,0,0,0,0,2,0,0,0,1,0
0,0,0,0,0,0,0,0,0,0,0,0,0,0,0,0
0,0,0,0,0,0,0,0,0,0,0,0,0,0,0,0
0,0,0,0,0,0,0,0,0,0,0,0,0,0,0,0
1,0,0,0,0,1,0,0,0,0,1,0,0,0,1,0
0,0,0,0,0,0,0,0,0,0,0,0,0,0,0,0
:endlayer
layer: 5
4,4,4,4,4,4,4,3,3,3,2,5,5,5,1,0
4,4,4,4,4,4,4,3,3,3,5,5,5,5,5,0
4,4,4,4,4,4,4,3,3,3,5,5,5,5,5,0
4,4,4,4,4,4,4,3,3,3,5,5,5,5,5,0
4,4,4,4,4,4,4,3,3,3,5,5,5,5,5,0
4,4,4,4,4,4,4,3,3,3,2,5,5,5,1,0
4,4,4,4,4,4,4,3,3,3,5,5,5,5,5,0
3,3,3,3,3,3,3,3,3,3,5,5,5,5,5,0
3,3,3,3,3,3,3,3,3,3,5,5,5,5,5,0
3,3,3,3,3,4,3,3,3,3,5,5,5,5,5,0
2,5,5,5,5,2,5,5,5,5,2,5,5,5,1,0
5,5,5,5,5,5,5,5,5,5,5,5,5,5,5,0
5,5,5,5,5,5,5,5,5,5,5,5,5,5,5,0
5,5,5,5,5,5,5,5,5,5,5,5,5,5,5,0
1,5,5,5,5,1,5,5,5,5,1,5,5,5,1,0
0,0,0,0,0,0,0,0,0,0,0,0,0,0,0,0
:endlayer
layer: 6
3,3,3,3,3,3,3,3,3,3,2,0,0,0,1,0
3,3,3,3,3,3,3,3,3,3,0,0,0,0,0,0
3,3,3,3,3,3,3,3,3,3,0,0,0,0,0,0
3,3,3,3,3,3,3,3,3,3,0,0,0,0,0,0
3,3,3,3,3,3,3,3,3,3,0,0,0,0,0,0
3,3,3,3,3,3,3,3,3,3,2,0,0,0,1,0
3,3,3,3,3,3,3,3,3,3,0,0,0,0,0,0
3,3,3,3,3,3,3,3,3,3,0,0,0,0,0,0
3,3,3,3,3,3,3,3,3,3,0,0,0,0,0,0
3,3,3,3,3,4,3,3,3,3,0,0,0,0,0,0
2,0,0,0,0,2,0,0,0,0,2,0,0,0,1,0
0,0,0,0,0,0,0,0,0,0,0,0,0,0,0,0
0,0,0,0,0,0,0,0,0,0,0,0,0,0,0,0
0,0,0,0,0,0,0,0,0,0,0,0,0,0,0,0
1,0,0,0,0,1,0,0,0,0,1,0,0,0,1,0
0,0,0,0,0,0,0,0,0,0,0,0,0,0,0,0
:endlayer
layer: 7
3,3,3,3,3,3,3,3,3,3,2,7,0,0,0,0
3,3,3,3,3,3,3,3,3,3,0,0,0,0,0,0
3,3,3,3,3,3,3,3,3,3,0,0,0,0,0,0
3,3,3,3,3,3,3,3,3,3,0,0,0,0,0,0
3,3,3,3,3,3,3,3,3,3,0,0,0,0,0,0
3,3,3,3,3,3,3,3,3,3,2,7,0,0,0,0
3,3,3,3,3,3,3,3,3,3,0,0,0,0,0,0
3,3,3,3,3,3,3,3,3,3,0,0,0,0,0,0
3,3,3,3,3,3,3,3,3,3,0,0,0,0,0,0
3,3,3,3,3,4,3,3,3,3,0,0,0,0,0,0
2,0,0,0,0,2,0,0,0,0,2,7,0,0,0,0
6,0,0,0,0,6,0,0,0,0,6,0,0,0,0,0
0,0,0,0,0,0,0,0,0,0,0,0,0,0,0,0
0,0,0,0,0,0,0,0,0,0,0,0,0,0,0,0
0,0,0,0,0,0,0,0,0,0,0,0,0,0,8,0
0,0,0,0,0,0,0,0,0,0,0,0,0,0,0,0
:endlayer
layer: 8
3,3,3,3,3,3,3,3,3,3,2,0,0,0,0,0
3,3,3,3,3,3,3,3,3,3,12,0,0,0,0,0
3,3,3,3,3,3,3,3,3,3,0,0,0,0,0,0
3,3,3,3,3,3,3,3,3,3,0,0,0,0,0,0
3,3,3,3,3,3,3,3,3,3,11,0,0,0,0,0
3,3,3,3,3,3,3,3,3,3,2,0,0,0,0,0
3,3,3,3,3,3,3,3,3,3,12,0,0,0,0,0
3,3,3,3,3,3,3,3,3,3,0,0,0,0,0,0
3,3,3,3,3,3,3,3,3,3,0,0,0,0,0,0
3,3,3,3,3,4,3,3,3,3,11,0,0,0,0,0
2,9,0,0,10,2,9,0,0,10,2,0,0,0,0,0
0,0,0,0,0,0,0,0,0,0,0,0,0,0,0,0
0,0,0,0,0,0,0,0,0,0,0,0,0,0,0,0
0,0,0,0,0,0,0,0,0,0,0,0,0,0,0,0
0,0,0,0,0,0,0,0,0,0,0,0,0,0,0,0
0,0,0,0,0,0,0,0,0,0,0,0,0,0,0,0
:endlayer
layer: 9
3,3,3,3,3,3,3,3,3,3,13,0,0,0,0,0
3,3,3,3,3,3,3,3,3,3,13,0,0,0,0,0
3,3,3,3,3,3,3,3,3,3,13,0,0,0,0,0
3,3,3,3,3,3,3,3,3,3,13,0,0,0,0,0
3,3,3,3,3,3,3,3,3,3,13,0,0,0,0,0
3,3,3,3,3,3,3,3,3,3,13,0,0,0,0,0
3,3,3,3,3,3,3,3,3,3,13,0,0,0,0,0
3,3,3,3,3,3,3,3,3,3,13,0,0,0,0,0
3,3,3,3,3,3,3,3,3,3,13,0,0,0,0,0
3,3,3,3,3,3,3,3,3,3,13,0,0,0,0,0
13,13,13,13,13,13,13,13,13,13,13,0,0,0,0,0
0,0,0,0,0,0,0,0,0,0,0,0,0,0,0,0
0,0,0,0,0,0,0,0,0,0,0,0,0,0,0,0
0,0,0,0,0,0,0,0,0,0,0,0,0,0,0,0
0,0,0,0,0,0,0,0,0,0,0,0,0,0,0,0
0,0,0,0,0,0,0,0,0,0,0,0,0,0,0,0
:endlayer
layer: 10
0,0,0,0,0,0,0,0,0,0,13,0,0,0,0,0
0,0,0,0,13,0,0,13,0,0,14,0,0,0,0,0
0,0,13,1,0,0,0,0,1,13,14,0,0,0,0,0
0,0,1,0,0,0,0,0,0,1,14,0,0,0,0,0
0,13,0,0,0,0,0,0,0,0,13,0,0,0,0,0
0,15,0,0,0,17,0,0,0,0,18,0,0,0,0,0
0,15,0,0,0,2,2,0,0,0,18,0,0,0,0,0
0,13,0,0,0,2,2,2,0,0,13,0,0,0,0,0
0,0,1,0,0,0,0,0,0,1,14,0,0,0,0,0
0,0,13,1,0,0,0,0,1,13,14,0,0,0,0,0
13,14,14,14,13,16,16,13,14,14,13,0,0,0,0,0
0,0,0,0,0,0,0,0,0,0,0,0,0,0,0,0
0,0,0,0,0,0,0,0,0,0,0,0,0,0,0,0
0,0,0,0,0,0,0,0,0,0,0,0,0,0,0,0
0,0,0,0,0,0,0,0,0,0,0,0,0,0,0,0
0,0,0,0,0,0,0,0,0,0,0,0,0,0,0,0
:endlayer
layer: 11
0,0,0,0,21,0,0,21,0,0,8,0,0,0,0,0
0,0,0,0,13,0,0,13,0,0,0,0,0,0,0,0
0,0,13,1,0,0,0,0,1,13,0,0,0,0,0,0
0,0,1,0,0,0,0,0,0,1,0,0,0,0,0,0
19,13,0,0,0,0,0,0,0,0,13,7,0,0,0,0
0,20,0,0,0,0,21,0,0,0,20,0,0,0,0,0
0,20,0,0,0,17,2,0,0,0,20,0,0,0,0,0
19,13,0,0,0,2,2,2,0,0,13,7,0,0,0,0
0,0,1,0,0,0,6,0,0,1,0,0,0,0,0,0
0,0,13,1,0,0,0,0,1,13,0,0,0,0,0,0
8,0,0,0,13,20,20,13,0,0,8,0,0,0,0,0
0,0,0,0,6,0,0,6,0,0,0,0,0,0,0,0
0,0,0,0,0,0,0,0,0,0,0,0,0,0,0,0
0,0,0,0,0,0,0,0,0,0,0,0,0,0,0,0
0,0,0,0,0,0,0,0,0,0,0,0,0,0,0,0
0,0,0,0,0,0,0,0,0,0,0,0,0,0,0,0
:endlayer
layer: 12
0,0,0,0,0,0,0,0,0,0,0,0,0,0,0,0
0,0,0,0,13,2,2,13,0,0,0,0,0,0,0,0
0,0,13,1,0,0,0,0,1,13,0,0,0,0,0,0
0,0,1,0,0,0,0,0,0,1,0,0,0,0,0,0
0,13,0,0,0,0,0,0,0,0,13,0,0,0,0,0
0,20,0,0,0,0,0,0,0,0,20,0,0,0,0,0
0,20,0,0,0,0,2,11,0,0,20,0,0,0,0,0
0,13,0,0,0,0,15,2,0,0,13,0,0,0,0,0
0,0,1,0,0,0,0,0,0,1,0,0,0,0,0,0
0,0,13,1,0,0,0,0,1,13,0,0,0,0,0,0
0,0,0,0,13,20,20,13,0,0,0,0,0,0,0,0
0,0,0,0,0,0,0,0,0,0,0,0,0,0,0,0
0,0,0,0,0,0,0,0,0,0,0,0,0,0,0,0
0,0,0,0,0,0,0,0,0,0,0,0,0,0,0,0
0,0,0,0,0,0,0,0,0,0,0,0,0,0,0,0
0,0,0,0,0,0,0,0,0,0,0,0,0,0,0,0
:endlayer
layer: 13
0,0,0,0,0,0,0,0,0,0,0,0,0,0,0,0
0,0,0,0,13,2,2,13,0,0,0,0,0,0,0,0
0,0,13,1,0,0,0,0,1,13,0,0,0,0,0,0
0,0,1,0,0,0,0,0,0,1,0,0,0,0,0,0
0,13,0,0,0,0,0,0,0,0,13,0,0,0,0,0
0,10,0,0,0,0,2,2,0,0,9,0,0,0,0,0
0,10,0,0,0,0,2,16,0,0,9,0,0,0,0,0
0,13,0,0,0,0,0,0,0,0,13,0,0,0,0,0
0,0,1,0,0,0,0,0,0,1,0,0,0,0,0,0
0,0,13,1,0,0,0,0,1,13,0,0,0,0,0,0
0,0,0,0,13,12,12,13,0,0,0,0,0,0,0,0
0,0,0,0,0,0,0,0,0,0,0,0,0,0,0,0
0,0,0,0,0,0,0,0,0,0,0,0,0,0,0,0
0,0,0,0,0,0,0,0,0,0,0,0,0,0,0,0
0,0,0,0,0,0,0,0,0,0,0,0,0,0,0,0
0,0,0,0,0,0,0,0,0,0,0,0,0,0,0,0
:endlayer
layer: 14
0,0,0,0,0,0,0,0,0,0,0,0,0,0,0,0
0,0,0,0,13,13,13,13,0,0,0,0,0,0,0,0
0,0,13,1,5,5,5,5,1,13,0,0,0,0,0,0
0,0,1,5,5,5,5,5,5,1,0,0,0,0,0,0
0,13,5,5,5,5,5,5,5,5,13,0,0,0,0,0
0,13,5,5,5,5,18,0,5,5,13,0,0,0,0,0
0,13,5,5,5,5,2,0,5,5,13,0,0,0,0,0
0,13,5,5,5,0,6,0,5,5,13,0,0,0,0,0
0,0,1,5,5,5,5,5,5,1,0,0,0,0,0,0
0,0,13,1,5,5,5,5,1,13,0,0,0,0,0,0
0,0,0,0,13,13,13,13,0,0,0,0,0,0,0,0
0,0,0,0,0,0,0,0,0,0,0,0,0,0,0,0
0,0,0,0,0,0,0,0,0,0,0,0,0,0,0,0
0,0,0,0,0,0,0,0,0,0,0,0,0,0,0,0
0,0,0,0,0,0,0,0,0,0,0,0,0,0,0,0
0,0,0,0,0,0,0,0,0,0,0,0,0,0,0,0
:endlayer
layer: 15
0,0,0,0,0,0,0,0,0,0,0,0,0,0,0,0
0,0,0,0,13,17,17,13,0,0,0,0,0,0,0,0
0,0,13,1,0,0,0,0,1,13,0,0,0,0,0,0
0,0,1,0,0,0,0,0,0,1,0,0,0,0,0,0
0,13,0,0,0,0,0,0,0,0,13,0,0,0,0,0
0,15,0,0,0,0,0,0,0,0,18,0,0,0,0,0
0,15,0,0,0,17,2,0,0,0,18,0,0,0,0,0
0,13,0,0,0,2,9,0,0,0,13,0,0,0,0,0
0,0,1,0,0,0,0,0,0,1,0,0,0,0,0,0
0,0,13,1,0,0,0,0,1,13,0,0,0,0,0,0
0,0,0,0,13,16,16,13,0,0,0,0,0,0,0,0
0,0,0,0,0,0,0,0,0,0,0,0,0,0,0,0
0,0,0,0,0,0,0,0,0,0,0,0,0,0,0,0
0,0,0,0,0,0,0,0,0,0,0,0,0,0,0,0
0,0,0,0,0,0,0,0,0,0,0,0,0,0,0,0
0,0,0,0,0,0,0,0,0,0,0,0,0,0,0,0
:endlayer
layer: 16
0,0,0,0,0,0,0,0,0,0,0,0,0,0,0,0
0,0,0,0,13,20,20,13,0,0,0,0,0,0,0,0
0,0,13,1,0,0,0,0,1,13,0,0,0,0,0,0
0,0,1,0,0,0,0,0,0,1,0,0,0,0,0,0
0,13,0,0,0,0,0,0,0,0,13,0,0,0,0,0
0,20,0,0,0,0,21,0,0,0,20,0,0,0,0,0
0,20,0,0,0,0,2,11,0,0,20,0,0,0,0,0
0,13,0,0,0,0,15,2,0,0,13,0,0,0,0,0
0,0,1,0,0,0,0,0,0,1,0,0,0,0,0,0
0,0,13,1,0,0,0,0,1,13,0,0,0,0,0,0
0,0,0,0,13,20,20,13,0,0,0,0,0,0,0,0
0,0,0,0,0,0,0,0,0,0,0,0,0,0,0,0
0,0,0,0,0,0,0,0,0,0,0,0,0,0,0,0
0,0,0,0,0,0,0,0,0,0,0,0,0,0,0,0
0,0,0,0,0,0,0,0,0,0,0,0,0,0,0,0
0,0,0,0,0,0,0,0,0,0,0,0,0,0,0,0
:endlayer
layer: 17
0,0,0,0,0,0,0,0,0,0,0,0,0,0,0,0
0,0,0,0,13,20,20,13,0,0,0,0,0,0,0,0
0,0,13,1,0,0,0,0,1,13,0,0,0,0,0,0
0,0,1,0,0,0,0,0,0,1,0,0,0,0,0,0
0,13,0,0,0,0,0,0,0,0,13,0,0,0,0,0
0,20,0,0,0,0,10,2,0,0,20,0,0,0,0,0
0,20,0,0,0,19,2,16,0,0,20,0,0,0,0,0
0,13,0,0,0,0,0,0,0,0,13,0,0,0,0,0
0,0,1,0,0,0,0,0,0,1,0,0,0,0,0,0
0,0,13,1,0,0,0,0,1,13,0,0,0,0,0,0
0,0,0,0,13,20,20,13,0,0,0,0,0,0,0,0
0,0,0,0,0,0,0,0,0,0,0,0,0,0,0,0
0,0,0,0,0,0,0,0,0,0,0,0,0,0,0,0
0,0,0,0,0,0,0,0,0,0,0,0,0,0,0,0
0,0,0,0,0,0,0,0,0,0,0,0,0,0,0,0
0,0,0,0,0,0,0,0,0,0,0,0,0,0,0,0
:endlayer
layer: 18
0,0,0,0,0,0,0,0,0,0,0,0,0,0,0,0
0,0,0,0,13,11,11,13,0,0,0,0,0,0,0,0
0,0,13,1,0,0,0,0,1,13,0,0,0,0,0,0
0,0,1,0,0,0,0,0,0,1,0,0,0,0,0,0
0,13,0,0,0,0,0,0,0,0,13,0,0,0,0,0
0,10,0,0,0,2,18,0,0,0,9,0,0,0,0,0
0,10,0,0,0,12,2,0,0,0,9,0,0,0,0,0
0,13,0,0,0,0,6,0,0,0,13,0,0,0,0,0
0,0,1,0,0,0,0,0,0,1,0,0,0,0,0,0
0,0,13,1,0,0,0,0,1,13,0,0,0,0,0,0
0,0,0,0,13,12,12,13,0,0,0,0,0,0,0,0
0,0,0,0,0,0,0,0,0,0,0,0,0,0,0,0
0,0,0,0,0,0,0,0,0,0,0,0,0,0,0,0
0,0,0,0,0,0,0,0,0,0,0,0,0,0,0,0
0,0,0,0,0,0,0,0,0,0,0,0,0,0,0,0
0,0,0,0,0,0,0,0,0,0,0,0,0,0,0,0
:endlayer
layer: 19
0,0,0,0,0,0,0,0,0,0,0,0,0,0,0,0
0,0,0,0,13,13,13,13,0,0,0,0,0,0,0,0
0,0,13,1,5,5,5,5,1,13,0,0,0,0,0,0
0,0,1,5,5,5,5,5,5,1,0,0,0,0,0,0
0,13,5,5,5,5,5,5,5,5,13,0,0,0,0,0
0,13,5,5,5,0,0,0,5,5,13,0,0,0,0,0
0,13,5,5,5,17,2,0,5,5,13,0,0,0,0,0
0,13,5,5,5,5,5,0,5,5,13,0,0,0,0,0
0,0,1,5,5,5,5,5,5,1,0,0,0,0,0,0
0,0,13,1,5,5,5,5,1,13,0,0,0,0,0,0
0,0,0,0,13,13,13,13,0,0,0,0,0,0,0,0
0,0,0,0,0,0,0,0,0,0,0,0,0,0,0,0
0,0,0,0,0,0,0,0,0,0,0,0,0,0,0,0
0,0,0,0,0,0,0,0,0,0,0,0,0,0,0,0
0,0,0,0,0,0,0,0,0,0,0,0,0,0,0,0
0,0,0,0,0,0,0,0,0,0,0,0,0,0,0,0
:endlayer
layer: 20
0,0,0,0,0,0,0,0,0,0,0,0,0,0,0,0
0,0,0,0,15,17,17,18,0,0,0,0,0,0,0,0
0,0,15,17,13,16,16,13,17,17,0,0,0,0,0,0
0,0,15,1,0,0,0,0,1,18,0,0,0,0,0,0
0,17,13,0,0,0,0,0,0,13,17,0,0,0,0,0
0,15,18,0,0,0,21,0,0,15,18,0,0,0,0,0
0,15,18,0,0,0,2,11,0,15,18,0,0,0,0,0
0,16,13,0,0,0,15,2,0,13,16,0,0,0,0,0
0,0,15,1,0,0,0,0,1,18,0,0,0,0,0,0
0,0,16,16,13,17,17,13,16,16,0,0,0,0,0,0
0,0,0,0,15,16,16,18,0,0,0,0,0,0,0,0
0,0,0,0,0,0,0,0,0,0,0,0,0,0,0,0
0,0,0,0,0,0,0,0,0,0,0,0,0,0,0,0
0,0,0,0,0,0,0,0,0,0,0,0,0,0,0,0
0,0,0,0,0,0,0,0,0,0,0,0,0,0,0,0
0,0,0,0,0,0,0,0,0,0,0,0,0,0,0,0
:endlayer
layer: 21
0,0,0,0,0,0,0,0,0,0,0,0,0,0,0,0
0,0,0,0,0,0,0,0,0,0,0,0,0,0,0,0
0,0,0,0,13,20,20,13,0,0,0,0,0,0,0,0
0,0,0,1,0,0,0,0,1,0,0,0,0,0,0,0
0,0,13,0,0,0,0,0,0,13,0,0,0,0,0,0
0,0,20,0,0,0,2,2,0,20,0,0,0,0,0,0
0,0,20,0,0,0,2,16,0,20,0,0,0,0,0,0
0,0,13,0,0,0,0,0,0,13,0,0,0,0,0,0
0,0,0,1,0,0,0,0,1,0,0,0,0,0,0,0
0,0,0,0,13,20,20,13,0,0,0,0,0,0,0,0
0,0,0,0,0,0,0,0,0,0,0,0,0,0,0,0
0,0,0,0,0,0,0,0,0,0,0,0,0,0,0,0
0,0,0,0,0,0,0,0,0,0,0,0,0,0,0,0
0,0,0,0,0,0,0,0,0,0,0,0,0,0,0,0
0,0,0,0,0,0,0,0,0,0,0,0,0,0,0,0
0,0,0,0,0,0,0,0,0,0,0,0,0,0,0,0
:endlayer
layer: 22
0,0,0,0,0,0,0,0,0,0,0,0,0,0,0,0
0,0,0,0,0,0,0,0,0,0,0,0,0,0,0,0
0,0,0,0,13,20,20,13,0,0,0,0,0,0,0,0
0,0,0,1,0,0,0,0,1,0,0,0,0,0,0,0
0,0,13,0,0,0,0,0,0,13,0,0,0,0,0,0
0,0,20,0,0,2,18,0,0,20,0,0,0,0,0,0
0,0,20,0,0,12,2,0,0,20,0,0,0,0,0,0
0,0,13,0,0,0,6,0,0,13,0,0,0,0,0,0
0,0,0,1,0,0,0,0,1,0,0,0,0,0,0,0
0,0,0,0,13,20,20,13,0,0,0,0,0,0,0,0
0,0,0,0,0,0,0,0,0,0,0,0,0,0,0,0
0,0,0,0,0,0,0,0,0,0,0,0,0,0,0,0
0,0,0,0,0,0,0,0,0,0,0,0,0,0,0,0
0,0,0,0,0,0,0,0,0,0,0,0,0,0,0,0
0,0,0,0,0,0,0,0,0,0,0,0,0,0,0,0
0,0,0,0,0,0,0,0,0,0,0,0,0,0,0,0
:endlayer
layer: 23
0,0,0,0,0,0,0,0,0,0,0,0,0,0,0,0
0,0,0,0,0,0,0,0,0,0,0,0,0,0,0,0
0,0,0,0,13,11,11,13,0,0,0,0,0,0,0,0
0,0,0,1,0,0,0,0,1,0,0,0,0,0,0,0
0,0,13,0,0,0,0,0,0,13,0,0,0,0,0,0
0,0,10,0,0,0,0,0,0,9,0,0,0,0,0,0
0,0,10,0,0,17,2,0,0,9,0,0,0,0,0,0
0,0,13,0,0,2,9,0,0,13,0,0,0,0,0,0
0,0,0,1,0,0,0,0,1,0,0,0,0,0,0,0
0,0,0,0,13,12,12,13,0,0,0,0,0,0,0,0
0,0,0,0,0,0,0,0,0,0,0,0,0,0,0,0
0,0,0,0,0,0,0,0,0,0,0,0,0,0,0,0
0,0,0,0,0,0,0,0,0,0,0,0,0,0,0,0
0,0,0,0,0,0,0,0,0,0,0,0,0,0,0,0
0,0,0,0,0,0,0,0,0,0,0,0,0,0,0,0
0,0,0,0,0,0,0,0,0,0,0,0,0,0,0,0
:endlayer
layer: 24
0,0,0,0,0,0,0,0,0,0,0,0,0,0,0,0
0,0,0,0,0,0,0,0,0,0,0,0,0,0,0,0
0,0,0,0,13,13,13,13,0,0,0,0,0,0,0,0
0,0,0,1,5,5,5,5,1,0,0,0,0,0,0,0
0,0,13,5,5,5,5,5,5,13,0,0,0,0,0,0
0,0,13,5,5,0,21,0,5,13,0,0,0,0,0,0
0,0,13,5,5,0,2,5,5,13,0,0,0,0,0,0
0,0,13,5,5,0,15,5,5,13,0,0,0,0,0,0
0,0,0,1,5,5,5,5,1,0,0,0,0,0,0,0
0,0,0,0,13,13,13,13,0,0,0,0,0,0,0,0
0,0,0,0,0,0,0,0,0,0,0,0,0,0,0,0
0,0,0,0,0,0,0,0,0,0,0,0,0,0,0,0
0,0,0,0,0,0,0,0,0,0,0,0,0,0,0,0
0,0,0,0,0,0,0,0,0,0,0,0,0,0,0,0
0,0,0,0,0,0,0,0,0,0,0,0,0,0,0,0
0,0,0,0,0,0,0,0,0,0,0,0,0,0,0,0
:endlayer
layer: 25
0,0,0,0,0,0,0,0,0,0,0,0,0,0,0,0
0,0,0,0,0,0,0,0,0,0,0,0,0,0,0,0
0,0,0,0,13,17,17,13,0,0,0,0,0,0,0,0
0,0,0,1,0,0,0,0,1,0,0,0,0,0,0,0
0,0,13,0,0,0,0,0,0,13,0,0,0,0,0,0
0,0,15,0,0,0,10,2,0,18,0,0,0,0,0,0
0,0,15,0,0,0,2,16,0,18,0,0,0,0,0,0
0,0,13,0,0,0,0,0,0,13,0,0,0,0,0,0
0,0,0,1,0,0,0,0,1,0,0,0,0,0,0,0
0,0,0,0,13,16,16,13,0,0,0,0,0,0,0,0
0,0,0,0,0,0,0,0,0,0,0,0,0,0,0,0
0,0,0,0,0,0,0,0,0,0,0,0,0,0,0,0
0,0,0,0,0,0,0,0,0,0,0,0,0,0,0,0
0,0,0,0,0,0,0,0,0,0,0,0,0,0,0,0
0,0,0,0,0,0,0,0,0,0,0,0,0,0,0,0
0,0,0,0,0,0,0,0,0,0,0,0,0,0,0,0
:endlayer
layer: 26
0,0,0,0,0,0,0,0,0,0,0,0,0,0,0,0
0,0,0,0,0,0,0,0,0,0,0,0,0,0,0,0
0,0,0,0,13,20,20,13,0,0,0,0,0,0,0,0
0,0,0,1,0,0,0,0,1,0,0,0,0,0,0,0
0,0,13,0,0,0,0,0,0,13,0,0,0,0,0,0
0,0,20,0,0,2,18,0,0,20,0,0,0,0,0,0
0,0,20,0,0,12,2,0,0,20,0,0,0,0,0,0
0,0,13,0,0,0,6,0,0,13,0,0,0,0,0,0
0,0,0,1,0,0,0,0,1,0,0,0,0,0,0,0
0,0,0,0,13,20,20,13,0,0,0,0,0,0,0,0
0,0,0,0,0,0,0,0,0,0,0,0,0,0,0,0
0,0,0,0,0,0,0,0,0,0,0,0,0,0,0,0
0,0,0,0,0,0,0,0,0,0,0,0,0,0,0,0
0,0,0,0,0,0,0,0,0,0,0,0,0,0,0,0
0,0,0,0,0,0,0,0,0,0,0,0,0,0,0,0
0,0,0,0,0,0,0,0,0,0,0,0,0,0,0,0
:endlayer
layer: 27
0,0,0,0,0,0,0,0,0,0,0,0,0,0,0,0
0,0,0,0,0,0,0,0,0,0,0,0,0,0,0,0
0,0,0,0,13,11,11,13,0,0,0,0,0,0,0,0
0,0,0,1,5,5,5,5,1,0,0,0,0,0,0,0
0,0,13,5,5,5,5,5,5,13,0,0,0,0,0,0
0,0,10,5,5,0,0,0,5,9,0,0,0,0,0,0
0,0,10,5,5,17,2,0,5,9,0,0,0,0,0,0
0,0,13,5,5,5,9,5,5,13,0,0,0,0,0,0
0,0,0,1,5,5,5,5,1,0,0,0,0,0,0,0
0,0,0,0,13,12,12,13,0,0,0,0,0,0,0,0
0,0,0,0,0,0,0,0,0,0,0,0,0,0,0,0
0,0,0,0,0,0,0,0,0,0,0,0,0,0,0,0
0,0,0,0,0,0,0,0,0,0,0,0,0,0,0,0
0,0,0,0,0,0,0,0,0,0,0,0,0,0,0,0
0,0,0,0,0,0,0,0,0,0,0,0,0,0,0,0
0,0,0,0,0,0,0,0,0,0,0,0,0,0,0,0
:endlayer
layer: 28
0,0,0,0,0,0,0,0,0,0,0,0,0,0,0,0
0,0,0,0,0,0,0,0,0,0,0,0,0,0,0,0
0,0,0,0,13,2,2,13,0,0,0,0,0,0,0,0
0,0,0,1,0,0,0,0,1,0,0,0,0,0,0,0
0,0,13,0,0,0,0,0,0,13,0,0,0,0,0,0
0,0,2,0,0,0,21,0,0,2,0,0,0,0,0,0
0,0,2,0,0,0,2,11,0,2,0,0,0,0,0,0
0,0,13,0,0,0,15,2,0,13,0,0,0,0,0,0
0,0,0,1,0,0,0,0,1,0,0,0,0,0,0,0
0,0,0,0,13,2,2,13,0,0,0,0,0,0,0,0
0,0,0,0,0,0,0,0,0,0,0,0,0,0,0,0
0,0,0,0,0,0,0,0,0,0,0,0,0,0,0,0
0,0,0,0,0,0,0,0,0,0,0,0,0,0,0,0
0,0,0,0,0,0,0,0,0,0,0,0,0,0,0,0
0,0,0,0,0,0,0,0,0,0,0,0,0,0,0,0
0,0,0,0,0,0,0,0,0,0,0,0,0,0,0,0
:endlayer
layer: 29
0,0,0,0,0,0,0,0,0,0,0,0,0,0,0,0
0,0,0,0,0,0,0,0,0,0,0,0,0,0,0,0
0,0,0,0,13,13,13,13,0,0,0,0,0,0,0,0
0,0,0,1,0,0,0,0,1,0,0,0,0,0,0,0
0,0,13,0,0,0,0,0,0,13,0,0,0,0,0,0
0,0,13,0,0,0,10,2,0,13,0,0,0,0,0,0
0,0,13,0,0,0,2,16,0,13,0,0,0,0,0,0
0,0,13,0,0,0,0,0,0,13,0,0,0,0,0,0
0,0,0,1,0,0,0,0,1,0,0,0,0,0,0,0
0,0,0,0,13,13,13,13,0,0,0,0,0,0,0,0
0,0,0,0,0,0,0,0,0,0,0,0,0,0,0,0
0,0,0,0,0,0,0,0,0,0,0,0,0,0,0,0
0,0,0,0,0,0,0,0,0,0,0,0,0,0,0,0
0,0,0,0,0,0,0,0,0,0,0,0,0,0,0,0
0,0,0,0,0,0,0,0,0,0,0,0,0,0,0,0
0,0,0,0,0,0,0,0,0,0,0,0,0,0,0,0
:endlayer
layer: 30
0,0,0,0,0,0,0,0,0,0,0,0,0,0,0,0
0,0,0,0,0,0,0,0,0,0,0,0,0,0,0,0
0,0,0,0,15,17,17,18,0,0,0,0,0,0,0,0
0,0,0,22,13,2,2,13,22,0,0,0,0,0,0,0
0,0,17,13,5,5,5,5,13,17,0,0,0,0,0,0
0,0,15,2,5,5,18,0,2,18,0,0,0,0,0,0
0,0,15,2,5,5,2,0,2,18,0,0,0,0,0,0
0,0,16,13,5,0,0,0,13,16,0,0,0,0,0,0
0,0,0,22,13,2,2,13,22,0,0,0,0,0,0,0
0,0,0,0,15,16,16,18,0,0,0,0,0,0,0,0
0,0,0,0,0,0,0,0,0,0,0,0,0,0,0,0
0,0,0,0,0,0,0,0,0,0,0,0,0,0,0,0
0,0,0,0,0,0,0,0,0,0,0,0,0,0,0,0
0,0,0,0,0,0,0,0,0,0,0,0,0,0,0,0
0,0,0,0,0,0,0,0,0,0,0,0,0,0,0,0
0,0,0,0,0,0,0,0,0,0,0,0,0,0,0,0
:endlayer
layer: 31
0,0,0,0,0,0,0,0,0,0,0,0,0,0,0,0
0,0,0,0,0,0,0,0,0,0,0,0,0,0,0,0
0,0,0,0,0,0,0,0,0,0,0,0,0,0,0,0
0,0,0,0,13,2,2,13,0,0,0,0,0,0,0,0
0,0,0,13,0,0,0,0,13,0,0,0,0,0,0,0
0,0,0,2,0,0,0,0,2,0,0,0,0,0,0,0
0,0,0,2,0,17,2,0,2,0,0,0,0,0,0,0
0,0,0,13,0,2,5,0,13,0,0,0,0,0,0,0
0,0,0,0,13,2,2,13,0,0,0,0,0,0,0,0
0,0,0,0,0,5,0,0,0,0,0,0,0,0,0,0
0,0,0,0,0,0,0,0,0,0,0,0,0,0,0,0
0,0,0,0,0,0,0,0,0,0,0,0,0,0,0,0
0,0,0,0,0,0,0,0,0,0,0,0,0,0,0,0
0,0,0,0,0,0,0,0,0,0,0,0,0,0,0,0
0,0,0,0,0,0,0,0,0,0,0,0,0,0,0,0
0,0,0,0,0,0,0,0,0,0,0,0,0,0,0,0
:endlayer
layer: 32
0,0,0,0,0,0,0,0,0,0,0,0,0,0,0,0
0,0,0,0,0,0,0,0,0,0,0,0,0,0,0,0
0,0,0,0,0,0,0,0,0,0,0,0,0,0,0,0
0,0,0,0,13,20,20,13,0,0,0,0,0,0,0,0
0,0,0,13,0,0,0,0,13,0,0,0,0,0,0,0
0,0,0,20,0,0,21,0,20,0,0,0,0,0,0,0
0,0,0,20,0,0,2,0,20,0,0,0,0,0,0,0
0,0,0,13,0,0,0,0,13,0,0,0,0,0,0,0
0,0,0,0,13,0,2,13,0,0,0,0,0,0,0,0
0,0,0,0,23,0,25,5,0,0,0,0,0,0,0,0
0,0,0,0,0,24,24,0,0,0,0,0,0,0,0,0
0,0,0,0,0,0,0,0,0,0,0,0,0,0,0,0
0,0,0,0,0,0,0,0,0,0,0,0,0,0,0,0
0,0,0,0,0,0,0,0,0,0,0,0,0,0,0,0
0,0,0,0,0,0,0,0,0,0,0,0,0,0,0,0
0,0,0,0,0,0,0,0,0,0,0,0,0,0,0,0
:endlayer
layer: 33
0,0,0,0,0,0,0,0,0,0,0,0,0,0,0,0
0,0,0,0,0,0,0,0,0,0,0,0,0,0,0,0
0,0,0,0,0,0,0,0,0,0,0,0,0,0,0,0
0,0,0,0,13,2,2,13,0,0,0,0,0,0,0,0
0,0,0,13,0,0,0,0,13,0,0,0,0,0,0,0
0,0,0,2,0,0,0,0,2,0,0,0,0,0,0,0
0,0,0,2,0,0,2,0,2,0,0,0,0,0,0,0
0,0,0,13,0,0,0,0,13,0,0,0,0,0,0,0
0,0,0,0,13,0,2,13,0,0,0,0,0,0,0,0
0,0,0,0,0,0,0,0,25,5,0,0,0,0,0,0
0,0,0,0,0,0,26,26,24,0,0,0,0,0,0,0
0,0,0,0,0,0,0,0,0,0,0,0,0,0,0,0
0,0,0,0,0,0,0,0,0,0,0,0,0,0,0,0
0,0,0,0,0,0,0,0,0,0,0,0,0,0,0,0
0,0,0,0,0,0,0,0,0,0,0,0,0,0,0,0
0,0,0,0,0,0,0,0,0,0,0,0,0,0,0,0
:endlayer
layer: 34
0,0,0,0,0,0,0,0,0,0,0,0,0,0,0,0
0,0,0,0,5,5,5,5,0,0,0,0,0,0,0,0
0,0,5,5,5,5,5,5,5,5,0,0,0,0,0,0
0,0,5,5,1,28,28,1,5,5,0,0,0,0,0,0
0,5,5,1,5,5,5,5,1,5,5,0,0,0,0,0
0,5,5,27,5,2,2,5,27,5,5,0,0,0,0,0
0,5,5,27,5,2,2,5,27,5,5,0,0,0,0,0
0,5,5,1,5,5,5,5,1,5,5,0,0,0,0,0
0,0,5,5,1,28,28,1,5,25,29,0,0,0,0,0
0,0,5,5,5,5,0,0,0,0,29,0,0,0,0,0
0,0,0,0,5,5,5,5,24,24,0,0,0,0,0,0
0,0,0,0,0,0,0,0,0,0,0,0,0,0,0,0
0,0,0,0,0,0,0,0,0,0,0,0,0,0,0,0
0,0,0,0,0,0,0,0,0,0,0,0,0,0,0,0
0,0,0,0,0,0,0,0,0,0,0,0,0,0,0,0
0,0,0,0,0,0,0,0,0,0,0,0,0,0,0,0
:endlayer
layer: 35
0,0,0,0,30,30,30,30,0,0,0,0,0,0,0,0
0,0,30,30,29,0,0,23,0,0,0,0,0,0,0,0
0,0,29,0,0,0,0,0,24,24,29,0,0,0,0,0
0,0,29,0,0,31,31,0,0,0,29,0,0,0,0,0
23,24,0,0,1,32,32,1,0,0,24,29,0,0,0,0
23,0,0,31,32,2,2,32,31,0,0,29,0,0,0,0
23,0,0,31,32,2,2,32,31,0,0,29,0,0,0,0
23,30,0,0,1,32,32,1,0,0,30,29,0,0,0,0
0,23,0,0,0,31,31,0,0,0,29,0,0,0,0,0
0,23,30,30,0,0,0,0,0,0,0,0,0,0,0,0
0,0,0,23,30,30,30,30,29,0,0,0,0,0,0,0
0,0,0,0,0,0,0,0,0,0,0,0,0,0,0,0
0,0,0,0,0,0,0,0,0,0,0,0,0,0,0,0
0,0,0,0,0,0,0,0,0,0,0,0,0,0,0,0
0,0,0,0,0,0,0,0,0,0,0,0,0,0,0,0
0,0,0,0,0,0,0,0,0,0,0,0,0,0,0,0
:endlayer
layer: 36
0,0,0,0,0,0,0,0,0,0,0,0,0,0,0,0
0,0,0,0,0,0,0,0,0,0,0,0,0,0,0,0
0,0,0,0,0,0,0,0,0,0,0,0,0,0,0,0
0,0,0,0,0,31,31,0,0,0,0,0,0,0,0,0
0,0,0,0,1,32,32,1,0,0,0,0,0,0,0,0
0,0,0,31,32,2,2,32,31,0,0,0,0,0,0,0
0,0,0,31,32,2,2,32,31,0,0,0,0,0,0,0
0,0,0,0,1,32,32,1,0,0,0,0,0,0,0,0
0,0,0,0,0,31,31,0,0,0,0,0,0,0,0,0
0,0,0,0,0,0,0,0,0,0,0,0,0,0,0,0
0,0,0,0,0,0,0,0,0,0,0,0,0,0,0,0
0,0,0,0,0,0,0,0,0,0,0,0,0,0,0,0
0,0,0,0,0,0,0,0,0,0,0,0,0,0,0,0
0,0,0,0,0,0,0,0,0,0,0,0,0,0,0,0
0,0,0,0,0,0,0,0,0,0,0,0,0,0,0,0
0,0,0,0,0,0,0,0,0,0,0,0,0,0,0,0
:endlayer
layer: 37
0,0,0,0,0,0,0,0,0,0,0,0,0,0,0,0
0,0,0,0,0,0,0,0,0,0,0,0,0,0,0,0
0,0,0,0,0,0,0,0,0,0,0,0,0,0,0,0
0,0,0,0,0,31,31,0,0,0,0,0,0,0,0,0
0,0,0,0,1,32,32,1,0,0,0,0,0,0,0,0
0,0,0,31,32,2,2,32,31,0,0,0,0,0,0,0
0,0,0,31,32,2,2,32,31,0,0,0,0,0,0,0
0,0,0,0,1,32,32,1,0,0,0,0,0,0,0,0
0,0,0,0,0,31,31,0,0,0,0,0,0,0,0,0
0,0,0,0,0,0,0,0,0,0,0,0,0,0,0,0
0,0,0,0,0,0,0,0,0,0,0,0,0,0,0,0
0,0,0,0,0,0,0,0,0,0,0,0,0,0,0,0
0,0,0,0,0,0,0,0,0,0,0,0,0,0,0,0
0,0,0,0,0,0,0,0,0,0,0,0,0,0,0,0
0,0,0,0,0,0,0,0,0,0,0,0,0,0,0,0
0,0,0,0,0,0,0,0,0,0,0,0,0,0,0,0
:endlayer
layer: 38
0,0,0,0,0,0,0,0,0,0,0,0,0,0,0,0
0,0,0,0,0,0,0,0,0,0,0,0,0,0,0,0
0,0,0,0,0,0,0,0,0,0,0,0,0,0,0,0
0,0,0,0,0,31,31,0,0,0,0,0,0,0,0,0
0,0,0,0,1,32,32,1,0,0,0,0,0,0,0,0
0,0,0,31,32,2,2,32,31,0,0,0,0,0,0,0
0,0,0,31,32,2,2,32,31,0,0,0,0,0,0,0
0,0,0,0,1,32,32,1,0,0,0,0,0,0,0,0
0,0,0,0,0,31,31,0,0,0,0,0,0,0,0,0
0,0,0,0,0,0,0,0,0,0,0,0,0,0,0,0
0,0,0,0,0,0,0,0,0,0,0,0,0,0,0,0
0,0,0,0,0,0,0,0,0,0,0,0,0,0,0,0
0,0,0,0,0,0,0,0,0,0,0,0,0,0,0,0
0,0,0,0,0,0,0,0,0,0,0,0,0,0,0,0
0,0,0,0,0,0,0,0,0,0,0,0,0,0,0,0
0,0,0,0,0,0,0,0,0,0,0,0,0,0,0,0
:endlayer
layer: 39
0,0,0,0,0,0,0,0,0,0,0,0,0,0,0,0
0,0,0,0,0,0,0,0,0,0,0,0,0,0,0,0
0,0,0,15,17,17,17,17,17,0,0,0,0,0,0,0
0,0,17,15,27,27,27,27,18,17,0,0,0,0,0,0
0,0,15,28,1,28,28,1,28,18,0,0,0,0,0,0
0,0,15,28,27,2,2,27,28,18,0,0,0,0,0,0
0,0,15,28,27,2,2,27,28,18,0,0,0,0,0,0
0,0,15,28,1,28,28,1,28,18,0,0,0,0,0,0
0,0,15,16,27,27,27,27,16,18,0,0,0,0,0,0
0,0,0,15,16,16,16,16,18,0,0,0,0,0,0,0
0,0,0,0,0,0,0,0,0,0,0,0,0,0,0,0
0,0,0,0,0,0,0,0,0,0,0,0,0,0,0,0
0,0,0,0,0,0,0,0,0,0,0,0,0,0,0,0
0,0,0,0,0,0,0,0,0,0,0,0,0,0,0,0
0,0,0,0,0,0,0,0,0,0,0,0,0,0,0,0
0,0,0,0,0,0,0,0,0,0,0,0,0,0,0,0
:endlayer
layer: 40
0,0,0,0,0,0,0,0,0,0,0,0,0,0,0,0
0,0,0,0,0,0,0,0,0,0,0,0,0,0,0,0
0,0,0,0,0,0,0,0,0,0,0,0,0,0,0,0
0,0,0,0,15,17,17,18,0,0,0,0,0,0,0,0
0,0,0,15,17,2,2,17,17,0,0,0,0,0,0,0
0,0,0,15,2,2,2,2,18,0,0,0,0,0,0,0
0,0,0,15,2,2,2,2,18,0,0,0,0,0,0,0
0,0,0,16,15,2,2,16,18,0,0,0,0,0,0,0
0,0,0,0,16,16,16,18,0,0,0,0,0,0,0,0
0,0,0,0,0,0,0,0,0,0,0,0,0,0,0,0
0,0,0,0,0,0,0,0,0,0,0,0,0,0,0,0
0,0,0,0,0,0,0,0,0,0,0,0,0,0,0,0
0,0,0,0,0,0,0,0,0,0,0,0,0,0,0,0
0,0,0,0,0,0,0,0,0,0,0,0,0,0,0,0
0,0,0,0,0,0,0,0,0,0,0,0,0,0,0,0
0,0,0,0,0,0,0,0,0,0,0,0,0,0,0,0
:endlayer
layer: 41
0,0,0,0,0,0,0,0,0,0,0,0,0,0,0,0
0,0,0,0,0,0,0,0,0,0,0,0,0,0,0,0
0,0,0,0,0,0,0,0,0,0,0,0,0,0,0,0
0,0,0,0,0,0,0,0,0,0,0,0,0,0,0,0
0,0,0,0,0,15,18,0,0,0,0,0,0,0,0,0
0,0,0,0,17,17,18,17,0,0,0,0,0,0,0,0
0,0,0,0,16,15,16,16,0,0,0,0,0,0,0,0
0,0,0,0,0,15,18,0,0,0,0,0,0,0,0,0
0,0,0,0,0,0,0,0,0,0,0,0,0,0,0,0
0,0,0,0,0,0,0,0,0,0,0,0,0,0,0,0
0,0,0,0,0,0,0,0,0,0,0,0,0,0,0,0
0,0,0,0,0,0,0,0,0,0,0,0,0,0,0,0
0,0,0,0,0,0,0,0,0,0,0,0,0,0,0,0
0,0,0,0,0,0,0,0,0,0,0,0,0,0,0,0
0,0,0,0,0,0,0,0,0,0,0,0,0,0,0,0
0,0,0,0,0,0,0,0,0,0,0,0,0,0,0,0
:endlayer

#### RULES ####
rule:
plugin=vanillaBlocks
number=1
data:
JSON:{blockState:{blockName:"minecraft:log",properties:{variant:"spruce",axis:"y"}}}
:enddata
:endrule

rule:
plugin=vanillaBlocks
number=2
data:
JSON:{blockState:{blockName:"minecraft:stonebrick",properties:{variant:"stonebrick"}}}
:enddata
:endrule

rule:
plugin=vanillaBlocks
number=3
data:
JSON:{blockState:{blockName:"minecraft:cobblestone"}}
:enddata
:endrule

rule:
plugin=vanillaBlocks
number=4
data:
JSON:{blockState:{blockName:"minecraft:dirt",properties:{variant:"dirt",snowy:"false"}}}
:enddata
:endrule

rule:
plugin=vanillaBlocks
number=5
data:
JSON:{blockState:{blockName:"minecraft:wooden_slab",properties:{half:"top",variant:"spruce"}}}
:enddata
:endrule

rule:
plugin=vanillaBlocks
number=6
data:
JSON:{blockState:{blockName:"minecraft:torch",properties:{facing:"south"}}}
:enddata
:endrule

rule:
plugin=vanillaBlocks
number=7
data:
JSON:{blockState:{blockName:"minecraft:torch",properties:{facing:"east"}}}
:enddata
:endrule

rule:
plugin=vanillaBlocks
number=8
data:
JSON:{blockState:{blockName:"minecraft:torch",properties:{facing:"up"}}}
:enddata
:endrule

rule:
plugin=vanillaBlocks
number=9
data:
JSON:{blockState:{blockName:"minecraft:stone_brick_stairs",properties:{half:"top",shape:"straight",facing:"west"}}}
:enddata
:endrule

rule:
plugin=vanillaBlocks
number=10
data:
JSON:{blockState:{blockName:"minecraft:stone_brick_stairs",properties:{half:"top",shape:"straight",facing:"east"}}}
:enddata
:endrule

rule:
plugin=vanillaBlocks
number=11
data:
JSON:{blockState:{blockName:"minecraft:stone_brick_stairs",properties:{half:"top",shape:"straight",facing:"south"}}}
:enddata
:endrule

rule:
plugin=vanillaBlocks
number=12
data:
JSON:{blockState:{blockName:"minecraft:stone_brick_stairs",properties:{half:"top",shape:"straight",facing:"north"}}}
:enddata
:endrule

rule:
plugin=vanillaBlocks
number=13
data:
JSON:{blockState:{blockName:"minecraft:stone",properties:{variant:"smooth_andesite"}}}
:enddata
:endrule

rule:
plugin=vanillaBlocks
number=14
data:
JSON:{blockState:{blockName:"minecraft:spruce_fence",properties:{east:"false",south:"false",north:"false",west:"false"}}}
:enddata
:endrule

rule:
plugin=vanillaBlocks
number=15
data:
JSON:{blockState:{blockName:"minecraft:stone_brick_stairs",properties:{half:"bottom",shape:"straight",facing:"east"}}}
:enddata
:endrule

rule:
plugin=vanillaBlocks
number=16
data:
JSON:{blockState:{blockName:"minecraft:stone_brick_stairs",properties:{half:"bottom",shape:"straight",facing:"north"}}}
:enddata
:endrule

rule:
plugin=vanillaBlocks
number=17
data:
JSON:{blockState:{blockName:"minecraft:stone_brick_stairs",properties:{half:"bottom",shape:"straight",facing:"south"}}}
:enddata
:endrule

rule:
plugin=vanillaBlocks
number=18
data:
JSON:{blockState:{blockName:"minecraft:stone_brick_stairs",properties:{half:"bottom",shape:"straight",facing:"west"}}}
:enddata
:endrule

rule:
plugin=vanillaBlocks
number=19
data:
JSON:{blockState:{blockName:"minecraft:torch",properties:{facing:"west"}}}
:enddata
:endrule

rule:
plugin=vanillaBlocks
number=20
data:
JSON:{blockState:{blockName:"minecraft:glass_pane",properties:{east:"false",south:"false",north:"false",west:"false"}}}
:enddata
:endrule

rule:
plugin=vanillaBlocks
number=21
data:
JSON:{blockState:{blockName:"minecraft:torch",properties:{facing:"north"}}}
:enddata
:endrule

rule:
plugin=vanillaBlocks
number=22
data:
JSON:{blockState:{blockName:"minecraft:stone_slab",properties:{half:"bottom",variant:"stone_brick"}}}
:enddata
:endrule

rule:
plugin=vanillaBlocks
number=23
data:
JSON:{blockState:{blockName:"minecraft:trapdoor",properties:{half:"bottom",facing:"west",open:"true"}}}
:enddata
:endrule

rule:
plugin=vanillaBlocks
number=24
data:
JSON:{blockState:{blockName:"minecraft:trapdoor",properties:{half:"bottom",facing:"south",open:"true"}}}
:enddata
:endrule

rule:
plugin=vanillaBlocks
number=25
data:
JSON:{blockState:{blockName:"minecraft:wooden_slab",properties:{half:"bottom",variant:"spruce"}}}
:enddata
:endrule

rule:
plugin=vanillaBlocks
number=26
data:
JSON:{blockState:{blockName:"minecraft:trapdoor",properties:{half:"top",facing:"south",open:"true"}}}
:enddata
:endrule

rule:
plugin=vanillaBlocks
number=27
data:
JSON:{blockState:{blockName:"minecraft:log",properties:{variant:"spruce",axis:"z"}}}
:enddata
:endrule

rule:
plugin=vanillaBlocks
number=28
data:
JSON:{blockState:{blockName:"minecraft:log",properties:{variant:"spruce",axis:"x"}}}
:enddata
:endrule

rule:
plugin=vanillaBlocks
number=29
data:
JSON:{blockState:{blockName:"minecraft:trapdoor",properties:{half:"bottom",facing:"east",open:"true"}}}
:enddata
:endrule

rule:
plugin=vanillaBlocks
number=30
data:
JSON:{blockState:{blockName:"minecraft:trapdoor",properties:{half:"bottom",facing:"north",open:"true"}}}
:enddata
:endrule

rule:
plugin=vanillaBlocks
number=31
data:
JSON:{blockState:{blockName:"minecraft:glass"}}
:enddata
:endrule

rule:
plugin=vanillaBlocks
number=32
data:
JSON:{blockState:{blockName:"minecraft:glowstone"}}
:enddata
:endrule

#### ENTITIES ####
