# Ancient Warfare Structure Template File
# Auto-generated structure template file. created on: 2/26/2021 at: 13:49:27
# Lines beginning with # denote comments

header:
version=2.11
name=NorskaTownGenFillerWarehouseClosed1
mods=
size=11,14,20
offset=5,5,19
:endheader

#### VALIDATION ####
validation:
type=ground
structureAuthor=TheOddlySeagull
worldGenEnabled=true
unique=false
preserveBlocks=false
preventNaturalHostileSpawns=false
selectionWeight=0
clusterValue=0
minDuplicateDistance=0
dimensionWhiteList=true
dimensionList=
biomeGroupList=
biomeWhiteList=false
biomeList=
leveling=0
fill=0
border=0
blockSwap=false
territoryName=
biomeReplacement=minecraft:
minGenerationHeight=0
maxGenerationHeight=0
:endvalidation

#### LAYERS ####
layer: 0
1,1,1,1,1,1,1,1,1,1,1
1,1,1,1,1,1,1,1,1,1,1
1,1,1,1,1,1,1,1,1,1,1
1,1,1,1,1,1,1,1,1,1,1
1,1,1,1,1,1,1,1,1,1,1
1,1,1,1,1,1,1,1,1,1,1
1,1,1,1,1,1,1,1,1,1,1
1,1,1,1,1,1,1,1,1,1,1
1,1,1,1,1,1,1,1,1,1,1
1,1,1,1,1,1,1,1,1,1,1
1,1,1,1,1,1,1,1,1,1,1
1,1,1,1,1,1,1,1,1,1,1
1,1,1,1,1,1,1,1,1,1,1
1,1,1,1,1,1,1,1,1,1,1
1,1,1,1,1,1,1,1,1,1,1
1,1,1,1,1,1,1,1,1,1,1
1,1,1,1,1,1,1,1,1,1,1
1,1,1,1,1,1,1,1,1,1,1
1,1,1,1,1,1,1,1,1,1,1
1,1,1,1,1,1,1,1,1,1,1
:endlayer
layer: 1
1,1,1,1,1,1,1,1,1,1,1
1,1,1,1,1,1,1,1,1,1,1
1,1,1,1,1,1,1,1,1,1,1
1,1,1,1,1,1,1,1,1,1,1
1,1,1,1,1,1,1,1,1,1,1
1,1,1,1,1,1,1,1,1,1,1
1,1,1,1,1,1,1,1,1,1,1
1,1,1,1,1,1,1,1,1,1,1
1,1,1,1,1,1,1,1,1,1,1
1,1,1,1,1,1,1,1,1,1,1
1,1,1,1,1,1,1,1,1,1,1
1,1,1,1,1,1,1,1,1,1,1
1,1,1,1,1,1,1,1,1,1,1
1,1,1,1,1,1,1,1,1,1,1
1,1,1,1,1,1,1,1,1,1,1
1,1,1,1,1,1,1,1,1,1,1
1,1,1,1,1,1,1,1,1,1,1
1,1,1,1,1,1,1,1,1,1,1
1,1,1,1,1,1,1,1,1,1,1
1,1,1,1,1,1,1,1,1,1,1
:endlayer
layer: 2
1,1,1,1,1,1,1,1,1,1,1
1,1,1,1,1,1,1,1,1,1,1
1,1,1,1,1,1,1,1,1,1,1
1,1,1,1,1,1,1,1,1,1,1
1,1,1,1,1,1,1,1,1,1,1
1,1,1,1,1,1,1,1,1,1,1
1,1,1,1,1,1,1,1,1,1,1
1,1,1,1,1,1,1,1,1,1,1
1,1,1,1,1,1,1,1,1,1,1
1,1,1,1,1,1,1,1,1,1,1
1,1,1,1,1,1,1,1,1,1,1
1,1,1,1,1,1,1,1,1,1,1
1,1,1,1,1,1,1,1,1,1,1
1,1,1,1,1,1,1,1,1,1,1
1,1,1,1,1,1,1,1,1,1,1
1,1,1,1,1,1,1,1,1,1,1
1,1,1,1,1,1,1,1,1,1,1
1,1,1,1,1,1,1,1,1,1,1
1,1,1,1,1,1,1,1,1,1,1
1,1,1,1,1,1,1,1,1,1,1
:endlayer
layer: 3
2,2,2,2,2,2,2,2,2,2,2
2,2,2,2,2,2,2,2,2,2,2
2,2,3,4,4,3,4,4,3,2,2
2,2,4,2,2,2,2,2,4,2,2
2,2,4,2,2,2,2,2,4,2,2
2,2,3,2,2,2,2,2,3,2,2
2,2,4,2,2,2,2,2,4,2,2
2,2,4,2,2,2,2,2,4,2,2
2,2,3,2,2,2,2,2,3,2,2
2,2,4,2,2,2,2,2,4,2,2
2,2,4,2,2,2,2,2,4,2,2
2,2,3,2,2,2,2,2,3,2,2
2,2,4,2,2,2,2,2,4,2,2
2,2,4,2,2,2,2,2,4,2,2
2,2,3,2,2,2,2,2,3,2,2
2,2,4,2,2,2,2,2,4,2,2
2,2,4,2,2,2,2,2,4,2,2
2,2,3,4,4,4,4,4,3,2,2
2,2,2,2,2,2,2,2,2,2,2
2,2,2,2,2,2,2,2,2,2,2
:endlayer
layer: 4
5,5,5,5,5,5,5,5,5,5,5
5,5,5,5,5,5,5,5,5,5,5
5,5,3,4,4,3,4,4,3,5,5
5,5,4,8,5,5,8,6,4,5,5
5,5,4,5,6,6,8,5,4,5,5
5,5,3,5,8,5,8,7,3,5,5
5,5,4,7,6,8,7,5,4,5,5
5,5,4,5,8,6,5,8,4,5,5
5,5,3,8,6,6,5,5,3,5,5
5,5,4,8,7,5,7,8,4,5,5
5,5,4,5,6,5,5,7,4,5,5
5,5,3,6,7,8,7,8,3,5,5
5,5,4,5,5,7,5,5,4,5,5
5,5,4,7,8,7,5,5,4,5,5
5,5,3,7,6,5,8,8,3,5,5
5,5,4,8,6,6,5,8,4,5,5
5,5,4,8,7,5,7,6,4,5,5
5,5,3,9,9,9,9,9,3,5,5
5,5,5,5,5,5,5,5,5,5,5
5,5,5,5,5,5,5,5,5,5,5
:endlayer
layer: 5
0,0,0,0,0,0,0,0,0,0,0
0,0,0,0,0,0,0,0,0,0,0
0,0,3,4,4,3,4,4,3,0,0
0,0,4,0,0,0,0,0,4,0,0
0,0,4,0,0,0,0,0,4,0,0
0,0,3,0,0,0,0,0,3,0,0
0,0,4,0,0,0,0,0,4,0,0
0,0,4,0,0,0,0,0,4,0,0
0,0,3,0,0,0,0,0,3,0,0
0,0,4,0,0,0,0,0,4,0,0
0,0,4,0,0,0,0,0,4,0,0
0,0,3,0,0,0,0,0,3,0,0
0,0,4,0,0,0,0,0,4,0,0
0,0,4,0,0,0,0,0,4,0,0
0,0,3,0,0,0,0,0,3,0,0
0,0,4,0,0,0,0,0,4,0,0
0,0,4,0,0,0,0,0,4,0,0
0,0,3,4,12,11,10,4,3,0,0
0,0,0,0,0,0,0,0,0,0,0
0,0,0,0,0,0,0,0,0,0,0
:endlayer
layer: 6
0,0,0,0,0,0,0,0,0,0,0
0,0,0,0,0,0,0,0,0,0,0
0,0,3,4,4,3,4,4,3,0,0
0,0,4,0,0,0,0,0,4,0,0
0,0,4,0,0,0,0,0,4,0,0
0,0,3,0,0,0,0,0,3,0,0
0,0,13,0,0,0,0,0,13,0,0
0,0,13,0,0,0,0,0,13,0,0
0,0,3,0,0,0,0,0,3,0,0
0,0,4,0,0,0,0,0,4,0,0
0,0,4,0,0,0,0,0,4,0,0
0,0,3,0,0,0,0,0,3,0,0
0,0,13,0,0,0,0,0,13,0,0
0,0,13,0,0,0,0,0,13,0,0
0,0,3,0,0,0,0,0,3,0,0
0,0,4,0,0,0,0,0,4,0,0
0,0,4,0,0,0,0,0,4,0,0
0,0,3,4,16,15,14,4,3,0,0
0,0,0,0,0,0,0,0,0,0,0
0,0,0,0,0,0,0,0,0,0,0
:endlayer
layer: 7
0,0,0,0,0,0,0,0,0,0,0
0,0,0,0,0,0,0,0,0,0,0
0,0,3,9,9,3,9,9,3,0,0
0,0,13,0,0,0,0,0,13,0,0
0,0,13,0,0,0,0,0,13,0,0
0,0,3,0,0,0,0,0,3,0,0
0,0,4,0,0,0,0,0,4,0,0
0,0,4,0,0,0,0,0,4,0,0
0,0,3,0,0,0,0,0,3,0,0
0,0,13,0,0,0,0,0,13,0,0
0,0,13,0,0,0,0,0,13,0,0
0,0,3,0,0,0,0,0,3,0,0
0,0,4,0,0,0,0,0,4,0,0
0,0,4,0,0,0,0,0,4,0,0
0,0,3,0,0,0,0,0,3,0,0
0,0,13,0,0,0,0,0,13,0,0
0,0,13,0,0,0,0,0,13,0,0
0,0,3,4,19,18,17,4,3,0,0
0,0,0,0,0,0,0,0,0,0,0
0,0,0,0,0,0,0,0,0,0,0
:endlayer
layer: 8
0,0,0,0,0,0,0,0,0,0,0
0,0,0,0,0,0,0,0,0,0,0
0,0,3,4,4,3,4,4,3,0,0
0,0,4,0,0,0,0,0,4,0,0
0,0,4,0,0,0,0,0,4,0,0
0,0,3,21,0,0,0,20,3,0,0
0,0,4,0,0,0,0,0,4,0,0
0,0,4,0,0,0,0,0,4,0,0
0,0,3,21,0,0,0,20,3,0,0
0,0,4,0,0,0,0,0,4,0,0
0,0,4,0,0,0,0,0,4,0,0
0,0,3,21,0,0,0,20,3,0,0
0,0,4,0,0,0,0,0,4,0,0
0,0,4,0,0,0,0,0,4,0,0
0,0,3,21,0,0,0,20,3,0,0
0,0,4,0,0,0,0,0,4,0,0
0,0,4,0,0,0,0,0,4,0,0
0,0,3,4,4,4,4,4,3,0,0
0,0,0,0,0,0,0,0,0,0,0
0,0,0,0,0,0,0,0,0,0,0
:endlayer
layer: 9
0,0,0,0,0,0,0,0,0,0,0
0,27,26,0,0,0,0,0,23,22,0
0,27,3,9,9,9,9,9,3,22,0
0,27,13,0,0,24,0,0,13,22,0
0,27,13,0,0,0,0,0,13,22,0
0,27,13,0,0,0,0,0,13,22,0
0,27,13,0,0,0,0,0,13,22,0
0,27,13,0,0,0,0,0,13,22,0
0,27,13,0,0,0,0,0,13,22,0
0,27,13,0,0,0,0,0,13,22,0
0,27,13,0,0,0,0,0,13,22,0
0,27,13,0,0,0,0,0,13,22,0
0,27,13,0,0,0,0,0,13,22,0
0,27,13,0,0,0,0,0,13,22,0
0,27,13,0,0,0,0,0,13,22,0
0,27,13,0,0,0,0,0,13,22,0
0,27,13,0,0,25,0,0,13,22,0
0,27,3,9,9,9,9,9,3,22,0
0,27,26,0,0,0,0,0,23,22,0
0,0,0,0,0,0,0,0,0,0,0
:endlayer
layer: 10
0,0,0,0,0,0,0,0,0,0,0
0,0,27,26,0,0,0,23,22,0,0
0,28,5,3,4,4,4,3,5,28,0
0,28,5,26,0,0,0,23,5,28,0
0,28,5,26,0,0,0,23,5,28,0
0,28,5,3,0,0,0,3,5,28,0
0,28,5,26,0,0,0,23,5,28,0
0,28,5,26,0,0,0,23,5,0,0
0,28,5,3,0,0,0,3,5,0,0
0,28,5,26,0,0,0,23,5,0,0
0,28,5,26,0,0,0,23,5,28,0
0,28,5,3,0,0,0,3,5,0,0
0,0,5,26,0,0,0,23,5,28,0
0,29,5,26,0,0,0,23,5,28,0
0,29,5,3,0,0,0,3,5,28,0
0,29,5,26,0,0,0,23,5,0,0
0,0,5,26,0,0,0,23,5,28,0
0,29,5,3,4,4,4,3,5,28,0
0,0,27,26,0,0,0,23,22,0,0
0,0,0,0,0,0,0,0,0,0,0
:endlayer
layer: 11
0,0,0,0,0,0,0,0,0,0,0
0,0,0,27,26,0,23,22,0,0,0
0,0,28,5,3,4,3,5,28,0,0
0,0,0,5,26,0,23,5,29,0,0
0,0,29,5,26,0,23,5,0,0,0
0,0,29,5,3,0,3,5,29,0,0
0,0,29,5,26,0,23,5,29,0,0
0,0,29,5,26,0,23,5,29,0,0
0,0,0,5,3,0,3,5,28,0,0
0,0,0,5,26,0,23,5,0,0,0
0,0,29,5,26,0,23,5,0,0,0
0,0,29,5,3,0,3,5,29,0,0
0,0,29,5,26,0,23,5,29,0,0
0,0,0,5,26,0,23,5,29,0,0
0,0,29,5,3,0,3,5,29,0,0
0,0,0,5,26,0,23,5,0,0,0
0,0,29,5,26,0,23,5,29,0,0
0,0,0,5,3,4,3,5,28,0,0
0,0,0,27,26,0,23,22,0,0,0
0,0,0,0,0,0,0,0,0,0,0
:endlayer
layer: 12
0,0,0,0,0,0,0,0,0,0,0
0,0,0,0,27,30,22,0,0,0,0
0,0,0,28,5,3,5,28,0,0,0
0,0,0,0,5,13,5,0,0,0,0
0,0,0,29,5,13,5,0,0,0,0
0,0,0,29,5,13,5,0,0,0,0
0,0,0,0,5,13,5,0,0,0,0
0,0,0,28,5,13,5,0,0,0,0
0,0,0,28,5,13,5,28,0,0,0
0,0,0,0,5,13,5,28,0,0,0
0,0,0,0,5,13,5,28,0,0,0
0,0,0,28,5,13,5,28,0,0,0
0,0,0,28,5,13,5,28,0,0,0
0,0,0,29,5,13,5,0,0,0,0
0,0,0,29,5,13,5,29,0,0,0
0,0,0,29,5,13,5,0,0,0,0
0,0,0,29,5,13,5,29,0,0,0
0,0,0,29,5,3,5,28,0,0,0
0,0,0,0,27,31,22,0,0,0,0
0,0,0,0,0,0,0,0,0,0,0
:endlayer
layer: 13
0,0,0,0,0,0,0,0,0,0,0
0,0,0,0,23,32,26,0,0,0,0
0,0,0,0,28,32,0,0,0,0,0
0,0,0,0,29,32,0,0,0,0,0
0,0,0,0,29,32,29,0,0,0,0
0,0,0,0,0,32,29,0,0,0,0
0,0,0,0,29,32,29,0,0,0,0
0,0,0,0,0,32,28,0,0,0,0
0,0,0,0,28,32,28,0,0,0,0
0,0,0,0,0,32,0,0,0,0,0
0,0,0,0,28,32,28,0,0,0,0
0,0,0,0,28,32,28,0,0,0,0
0,0,0,0,0,32,28,0,0,0,0
0,0,0,0,29,32,29,0,0,0,0
0,0,0,0,0,32,29,0,0,0,0
0,0,0,0,29,32,29,0,0,0,0
0,0,0,0,29,32,29,0,0,0,0
0,0,0,0,0,32,0,0,0,0,0
0,0,0,0,23,32,26,0,0,0,0
0,0,0,0,0,0,0,0,0,0,0
:endlayer

#### RULES ####
rule:
plugin=vanillaBlocks
number=1
data:
JSON:{blockState:{blockName:"minecraft:stone",properties:{variant:"stone"}}}
:enddata
:endrule

rule:
plugin=vanillaBlocks
number=2
data:
JSON:{blockState:{blockName:"minecraft:dirt",properties:{variant:"dirt",snowy:"false"}}}
:enddata
:endrule

rule:
plugin=vanillaBlocks
number=3
data:
JSON:{blockState:{blockName:"minecraft:log",properties:{variant:"spruce",axis:"y"}}}
:enddata
:endrule

rule:
plugin=vanillaBlocks
number=4
data:
JSON:{blockState:{blockName:"minecraft:planks",properties:{variant:"spruce"}}}
:enddata
:endrule

rule:
plugin=vanillaBlocks
number=5
data:
JSON:{blockState:{blockName:"minecraft:grass",properties:{snowy:"false"}}}
:enddata
:endrule

rule:
plugin=vanillaBlocks
number=6
data:
JSON:{blockState:{blockName:"minecraft:dirt",properties:{variant:"coarse_dirt",snowy:"false"}}}
:enddata
:endrule

rule:
plugin=vanillaBlocks
number=7
data:
JSON:{blockState:{blockName:"minecraft:gravel"}}
:enddata
:endrule

rule:
plugin=vanillaBlocks
number=8
data:
JSON:{blockState:{blockName:"minecraft:cobblestone"}}
:enddata
:endrule

rule:
plugin=vanillaBlocks
number=9
data:
JSON:{blockState:{blockName:"minecraft:log",properties:{variant:"spruce",axis:"x"}}}
:enddata
:endrule

rule:
plugin=blockTile
number=10
data:
JSON:{blockState:{blockName:"ancientwarfarestructure:gate_proxy"},teData:{lsb:-6494687540380568576L,id:"ancientwarfarestructure:gate_proxy_tile",msb:6837415448624251860L,render:1b}}
:enddata
:endrule

rule:
plugin=blockTile
number=11
data:
JSON:{blockState:{blockName:"ancientwarfarestructure:gate_proxy"},teData:{lsb:-6494687540380568576L,id:"ancientwarfarestructure:gate_proxy_tile",msb:6837415448624251860L,render:0b}}
:enddata
:endrule

rule:
plugin=blockTile
number=12
data:
JSON:{blockState:{blockName:"ancientwarfarestructure:gate_proxy"},teData:{lsb:-6494687540380568576L,id:"ancientwarfarestructure:gate_proxy_tile",msb:6837415448624251860L,render:0b}}
:enddata
:endrule

rule:
plugin=vanillaBlocks
number=13
data:
JSON:{blockState:{blockName:"minecraft:log",properties:{variant:"spruce",axis:"z"}}}
:enddata
:endrule

rule:
plugin=blockTile
number=14
data:
JSON:{blockState:{blockName:"ancientwarfarestructure:gate_proxy"},teData:{lsb:-6494687540380568576L,id:"ancientwarfarestructure:gate_proxy_tile",msb:6837415448624251860L,render:0b}}
:enddata
:endrule

rule:
plugin=blockTile
number=15
data:
JSON:{blockState:{blockName:"ancientwarfarestructure:gate_proxy"},teData:{lsb:-6494687540380568576L,id:"ancientwarfarestructure:gate_proxy_tile",msb:6837415448624251860L,render:0b}}
:enddata
:endrule

rule:
plugin=blockTile
number=16
data:
JSON:{blockState:{blockName:"ancientwarfarestructure:gate_proxy"},teData:{lsb:-6494687540380568576L,id:"ancientwarfarestructure:gate_proxy_tile",msb:6837415448624251860L,render:0b}}
:enddata
:endrule

rule:
plugin=blockTile
number=17
data:
JSON:{blockState:{blockName:"ancientwarfarestructure:gate_proxy"},teData:{lsb:-6494687540380568576L,id:"ancientwarfarestructure:gate_proxy_tile",msb:6837415448624251860L,render:0b}}
:enddata
:endrule

rule:
plugin=blockTile
number=18
data:
JSON:{blockState:{blockName:"ancientwarfarestructure:gate_proxy"},teData:{lsb:-6494687540380568576L,id:"ancientwarfarestructure:gate_proxy_tile",msb:6837415448624251860L,render:0b}}
:enddata
:endrule

rule:
plugin=blockTile
number=19
data:
JSON:{blockState:{blockName:"ancientwarfarestructure:gate_proxy"},teData:{lsb:-6494687540380568576L,id:"ancientwarfarestructure:gate_proxy_tile",msb:6837415448624251860L,render:0b}}
:enddata
:endrule

rule:
plugin=vanillaBlocks
number=20
data:
JSON:{blockState:{blockName:"minecraft:torch",properties:{facing:"west"}}}
:enddata
:endrule

rule:
plugin=vanillaBlocks
number=21
data:
JSON:{blockState:{blockName:"minecraft:torch",properties:{facing:"east"}}}
:enddata
:endrule

rule:
plugin=vanillaBlocks
number=22
data:
JSON:{blockState:{blockName:"minecraft:spruce_stairs",properties:{half:"bottom",shape:"straight",facing:"west"}}}
:enddata
:endrule

rule:
plugin=vanillaBlocks
number=23
data:
JSON:{blockState:{blockName:"minecraft:spruce_stairs",properties:{half:"top",shape:"straight",facing:"east"}}}
:enddata
:endrule

rule:
plugin=vanillaBlocks
number=24
data:
JSON:{blockState:{blockName:"minecraft:torch",properties:{facing:"south"}}}
:enddata
:endrule

rule:
plugin=vanillaBlocks
number=25
data:
JSON:{blockState:{blockName:"minecraft:torch",properties:{facing:"north"}}}
:enddata
:endrule

rule:
plugin=vanillaBlocks
number=26
data:
JSON:{blockState:{blockName:"minecraft:spruce_stairs",properties:{half:"top",shape:"straight",facing:"west"}}}
:enddata
:endrule

rule:
plugin=vanillaBlocks
number=27
data:
JSON:{blockState:{blockName:"minecraft:spruce_stairs",properties:{half:"bottom",shape:"straight",facing:"east"}}}
:enddata
:endrule

rule:
plugin=vanillaBlocks
number=28
data:
JSON:{blockState:{blockName:"minecraft:leaves",properties:{check_decay:"false",decayable:"false",variant:"spruce"}}}
:enddata
:endrule

rule:
plugin=vanillaBlocks
number=29
data:
JSON:{blockState:{blockName:"minecraft:leaves",properties:{check_decay:"true",decayable:"false",variant:"spruce"}}}
:enddata
:endrule

rule:
plugin=vanillaBlocks
number=30
data:
JSON:{blockState:{blockName:"minecraft:spruce_stairs",properties:{half:"top",shape:"straight",facing:"south"}}}
:enddata
:endrule

rule:
plugin=vanillaBlocks
number=31
data:
JSON:{blockState:{blockName:"minecraft:spruce_stairs",properties:{half:"top",shape:"straight",facing:"north"}}}
:enddata
:endrule

rule:
plugin=vanillaBlocks
number=32
data:
JSON:{blockState:{blockName:"minecraft:wooden_slab",properties:{half:"bottom",variant:"spruce"}}}
:enddata
:endrule

#### ENTITIES ####
entity:
plugin=awGate
number=0
data:
JSON:{owner:"",orientation:2b,pos1:{x:1,y:0,z:0},pos2:{x:-1,y:2,z:0},position:1374725079057L,gateType:"gate.verticalWooden"}
:enddata
:endentity

