# Ancient Warfare Structure Template File
# Auto-generated structure template file. created on: 2/26/2021 at: 13:49:40
# Lines beginning with # denote comments

header:
version=2.11
name=NorskaTownGenFillerWarehouseClosed2
mods=
size=11,13,17
offset=5,5,16
:endheader

#### VALIDATION ####
validation:
type=ground
structureAuthor=TheOddlySeagull
worldGenEnabled=true
unique=false
preserveBlocks=false
preventNaturalHostileSpawns=false
selectionWeight=0
clusterValue=0
minDuplicateDistance=0
dimensionWhiteList=true
dimensionList=
biomeGroupList=
biomeWhiteList=false
biomeList=
leveling=0
fill=0
border=0
blockSwap=false
territoryName=
biomeReplacement=minecraft:
minGenerationHeight=0
maxGenerationHeight=0
:endvalidation

#### LAYERS ####
layer: 0
1,1,1,1,1,1,1,1,1,1,1
1,1,1,1,1,1,1,1,1,1,1
1,1,1,1,1,1,1,1,1,1,1
1,1,1,1,1,1,1,1,1,1,1
1,1,1,1,1,1,1,1,1,1,1
1,1,1,1,1,1,1,1,1,1,1
1,1,1,1,1,1,1,1,1,1,1
1,1,1,1,1,1,1,1,1,1,1
1,1,1,1,1,1,1,1,1,1,1
1,1,1,1,1,1,1,1,1,1,1
1,1,1,1,1,1,1,1,1,1,1
1,1,1,1,1,1,1,1,1,1,1
1,1,1,1,1,1,1,1,1,1,1
1,1,1,1,1,1,1,1,1,1,1
1,1,1,1,1,1,1,1,1,1,1
1,1,1,1,1,1,1,1,1,1,1
1,1,1,1,1,1,1,1,1,1,1
:endlayer
layer: 1
1,1,1,1,1,1,1,1,1,1,1
1,1,1,1,1,1,1,1,1,1,1
1,1,1,1,1,1,1,1,1,1,1
1,1,1,1,1,1,1,1,1,1,1
1,1,1,1,1,1,1,1,1,1,1
1,1,1,1,1,1,1,1,1,1,1
1,1,1,1,1,1,1,1,1,1,1
1,1,1,1,1,1,1,1,1,1,1
1,1,1,1,1,1,1,1,1,1,1
1,1,1,1,1,1,1,1,1,1,1
1,1,1,1,1,1,1,1,1,1,1
1,1,1,1,1,1,1,1,1,1,1
1,1,1,1,1,1,1,1,1,1,1
1,1,1,1,1,1,1,1,1,1,1
1,1,1,1,1,1,1,1,1,1,1
1,1,1,1,1,1,1,1,1,1,1
1,1,1,1,1,1,1,1,1,1,1
:endlayer
layer: 2
1,1,1,1,1,1,1,1,1,1,1
1,1,1,1,1,1,1,1,1,1,1
1,1,1,1,1,1,1,1,1,1,1
1,1,1,1,1,1,1,1,1,1,1
1,1,1,1,1,1,1,1,1,1,1
1,1,1,1,1,1,1,1,1,1,1
1,1,1,1,1,1,1,1,1,1,1
1,1,1,1,1,1,1,1,1,1,1
1,1,1,1,1,1,1,1,1,1,1
1,1,1,1,1,1,1,1,1,1,1
1,1,1,1,1,1,1,1,1,1,1
1,1,1,1,1,1,1,1,1,1,1
1,1,1,1,1,1,1,1,1,1,1
1,1,1,1,1,1,1,1,1,1,1
1,1,1,1,1,1,1,1,1,1,1
1,1,1,1,1,1,1,1,1,1,1
1,1,1,1,1,1,1,1,1,1,1
:endlayer
layer: 3
2,2,2,2,2,2,2,2,2,2,2
2,2,2,2,2,2,2,2,2,2,2
2,2,3,4,4,3,4,4,3,2,2
2,2,4,2,2,2,2,2,4,2,2
2,2,4,2,2,2,2,2,4,2,2
2,2,3,2,2,2,2,2,3,2,2
2,2,4,2,2,2,2,2,4,2,2
2,2,4,2,2,2,2,2,4,2,2
2,2,3,2,2,2,2,2,3,2,2
2,2,4,2,2,2,2,2,4,2,2
2,2,4,2,2,2,2,2,4,2,2
2,2,3,2,2,2,2,2,3,2,2
2,2,4,2,2,2,2,2,4,2,2
2,2,4,2,2,2,2,2,4,2,2
2,2,3,4,4,4,4,4,3,2,2
2,2,2,2,2,2,2,2,2,2,2
2,2,2,2,2,2,2,2,2,2,2
:endlayer
layer: 4
5,5,5,5,5,5,5,5,5,5,5
5,5,5,5,5,5,5,5,5,5,5
5,5,3,4,4,3,4,4,3,5,5
5,5,4,5,5,6,7,6,4,5,5
5,5,4,5,5,5,8,7,4,5,5
5,5,3,6,8,5,8,8,3,5,5
5,5,4,8,8,8,5,8,4,5,5
5,5,4,7,7,7,6,6,4,5,5
5,5,3,8,8,5,7,7,3,5,5
5,5,4,5,5,7,7,8,4,5,5
5,5,4,7,7,7,5,7,4,5,5
5,5,3,6,5,8,7,5,3,5,5
5,5,4,6,5,8,8,6,4,5,5
5,5,4,6,8,8,8,8,4,5,5
5,5,3,9,9,9,9,9,3,5,5
5,5,5,5,5,5,5,5,5,5,5
5,5,5,5,5,5,5,5,5,5,5
:endlayer
layer: 5
0,0,0,0,0,0,0,0,0,0,0
0,0,0,0,0,0,0,0,0,0,0
0,0,3,4,4,3,4,4,3,0,0
0,0,4,0,0,0,0,0,4,0,0
0,0,4,0,0,0,0,0,4,0,0
0,0,3,0,0,0,0,0,3,0,0
0,0,4,0,0,0,0,0,4,0,0
0,0,4,0,0,0,0,0,4,0,0
0,0,3,0,0,0,0,0,3,0,0
0,0,4,0,0,0,0,0,4,0,0
0,0,4,0,0,0,0,0,4,0,0
0,0,3,0,0,0,0,0,3,0,0
0,0,4,0,0,0,0,0,4,0,0
0,0,4,0,0,0,0,0,4,0,0
0,0,3,4,12,11,10,4,3,0,0
0,0,0,0,0,0,0,0,0,0,0
0,0,0,0,0,0,0,0,0,0,0
:endlayer
layer: 6
0,0,0,0,0,0,0,0,0,0,0
0,0,0,0,0,0,0,0,0,0,0
0,0,3,4,4,3,4,4,3,0,0
0,0,4,0,0,0,0,0,4,0,0
0,0,4,0,0,0,0,0,4,0,0
0,0,3,0,0,0,0,0,3,0,0
0,0,4,0,0,0,0,0,4,0,0
0,0,4,0,0,0,0,0,4,0,0
0,0,3,0,0,0,0,0,3,0,0
0,0,4,0,0,0,0,0,4,0,0
0,0,4,0,0,0,0,0,4,0,0
0,0,3,0,0,0,0,0,3,0,0
0,0,4,0,0,0,0,0,4,0,0
0,0,4,0,0,0,0,0,4,0,0
0,0,3,4,15,14,13,4,3,0,0
0,0,0,0,0,0,0,0,0,0,0
0,0,0,0,0,0,0,0,0,0,0
:endlayer
layer: 7
0,0,0,0,0,0,0,0,0,0,0
0,0,0,0,0,0,0,0,0,0,0
0,0,3,4,4,3,4,4,3,0,0
0,0,4,0,0,0,0,0,4,0,0
0,0,4,0,0,0,0,0,4,0,0
0,0,3,0,0,0,0,0,3,0,0
0,0,4,0,0,0,0,0,4,0,0
0,0,4,0,0,0,0,0,4,0,0
0,0,3,0,0,0,0,0,3,0,0
0,0,4,0,0,0,0,0,4,0,0
0,0,4,0,0,0,0,0,4,0,0
0,0,3,0,0,0,0,0,3,0,0
0,0,4,0,0,0,0,0,4,0,0
0,0,4,0,0,0,0,0,4,0,0
0,0,3,4,18,17,16,4,3,0,0
0,0,0,0,0,0,0,0,0,0,0
0,0,0,0,0,0,0,0,0,0,0
:endlayer
layer: 8
0,0,0,0,0,0,0,0,0,0,0
0,25,24,0,0,0,0,0,20,19,0
0,25,3,9,9,9,9,9,3,19,0
0,25,21,0,0,0,0,0,21,19,0
0,25,21,0,0,0,0,0,21,19,0
0,25,21,23,0,0,0,22,21,19,0
0,25,21,0,0,0,0,0,21,19,0
0,25,21,0,0,0,0,0,21,19,0
0,25,21,23,0,0,0,22,21,19,0
0,25,21,0,0,0,0,0,21,19,0
0,25,21,0,0,0,0,0,21,19,0
0,25,21,23,0,0,0,22,21,19,0
0,25,21,0,0,0,0,0,21,19,0
0,25,21,0,0,0,0,0,21,19,0
0,25,3,9,9,9,9,9,3,19,0
0,25,24,0,0,0,0,0,20,19,0
0,0,0,0,0,0,0,0,0,0,0
:endlayer
layer: 9
0,0,0,0,0,0,0,0,0,0,0
0,0,25,24,0,0,0,20,19,0,0
0,29,5,3,4,4,4,3,5,26,0
0,29,5,24,0,27,0,20,5,26,0
0,0,5,24,0,0,0,20,5,26,0
0,0,5,3,0,0,0,3,5,26,0
0,26,5,24,0,0,0,20,5,26,0
0,26,5,24,0,0,0,20,5,26,0
0,26,5,3,0,0,0,3,5,0,0
0,26,5,24,0,0,0,20,5,26,0
0,26,5,24,0,0,0,20,5,0,0
0,26,5,3,0,0,0,3,5,26,0
0,26,5,24,0,0,0,20,5,26,0
0,26,5,24,0,28,0,20,5,26,0
0,26,5,3,4,4,4,3,5,26,0
0,0,25,24,0,0,0,20,19,0,0
0,0,0,0,0,0,0,0,0,0,0
:endlayer
layer: 10
0,0,0,0,0,0,0,0,0,0,0
0,0,0,25,24,0,20,19,0,0,0
0,0,29,5,3,4,3,5,0,0,0
0,0,29,5,24,0,20,5,0,0,0
0,0,26,5,24,0,20,5,26,0,0
0,0,26,5,3,0,3,5,26,0,0
0,0,26,5,24,0,20,5,0,0,0
0,0,26,5,24,0,20,5,26,0,0
0,0,26,5,3,0,3,5,0,0,0
0,0,0,5,24,0,20,5,26,0,0
0,0,26,5,24,0,20,5,26,0,0
0,0,26,5,3,0,3,5,0,0,0
0,0,26,5,24,0,20,5,0,0,0
0,0,26,5,24,0,20,5,26,0,0
0,0,26,5,3,4,3,5,26,0,0
0,0,0,25,24,0,20,19,0,0,0
0,0,0,0,0,0,0,0,0,0,0
:endlayer
layer: 11
0,0,0,0,0,0,0,0,0,0,0
0,0,0,0,25,30,19,0,0,0,0
0,0,0,26,5,3,5,26,0,0,0
0,0,0,0,5,21,5,26,0,0,0
0,0,0,0,5,21,5,26,0,0,0
0,0,0,26,5,21,5,26,0,0,0
0,0,0,26,5,21,5,0,0,0,0
0,0,0,0,5,21,5,0,0,0,0
0,0,0,26,5,21,5,0,0,0,0
0,0,0,26,5,21,5,0,0,0,0
0,0,0,26,5,21,5,0,0,0,0
0,0,0,0,5,21,5,26,0,0,0
0,0,0,26,5,21,5,26,0,0,0
0,0,0,26,5,21,5,26,0,0,0
0,0,0,26,5,3,5,0,0,0,0
0,0,0,0,25,31,19,0,0,0,0
0,0,0,0,0,0,0,0,0,0,0
:endlayer
layer: 12
0,0,0,0,0,0,0,0,0,0,0
0,0,0,0,20,32,24,0,0,0,0
0,0,0,0,26,32,26,0,0,0,0
0,0,0,0,0,32,0,0,0,0,0
0,0,0,0,0,32,26,0,0,0,0
0,0,0,0,26,32,26,0,0,0,0
0,0,0,0,26,32,0,0,0,0,0
0,0,0,0,26,32,26,0,0,0,0
0,0,0,0,26,32,0,0,0,0,0
0,0,0,0,26,32,26,0,0,0,0
0,0,0,0,26,32,0,0,0,0,0
0,0,0,0,0,32,26,0,0,0,0
0,0,0,0,26,32,26,0,0,0,0
0,0,0,0,0,32,26,0,0,0,0
0,0,0,0,26,32,26,0,0,0,0
0,0,0,0,20,32,24,0,0,0,0
0,0,0,0,0,0,0,0,0,0,0
:endlayer

#### RULES ####
rule:
plugin=vanillaBlocks
number=1
data:
JSON:{blockState:{blockName:"minecraft:stone",properties:{variant:"stone"}}}
:enddata
:endrule

rule:
plugin=vanillaBlocks
number=2
data:
JSON:{blockState:{blockName:"minecraft:dirt",properties:{variant:"dirt",snowy:"false"}}}
:enddata
:endrule

rule:
plugin=vanillaBlocks
number=3
data:
JSON:{blockState:{blockName:"minecraft:log",properties:{variant:"spruce",axis:"y"}}}
:enddata
:endrule

rule:
plugin=vanillaBlocks
number=4
data:
JSON:{blockState:{blockName:"minecraft:planks",properties:{variant:"spruce"}}}
:enddata
:endrule

rule:
plugin=vanillaBlocks
number=5
data:
JSON:{blockState:{blockName:"minecraft:grass",properties:{snowy:"false"}}}
:enddata
:endrule

rule:
plugin=vanillaBlocks
number=6
data:
JSON:{blockState:{blockName:"minecraft:cobblestone"}}
:enddata
:endrule

rule:
plugin=vanillaBlocks
number=7
data:
JSON:{blockState:{blockName:"minecraft:gravel"}}
:enddata
:endrule

rule:
plugin=vanillaBlocks
number=8
data:
JSON:{blockState:{blockName:"minecraft:dirt",properties:{variant:"coarse_dirt",snowy:"false"}}}
:enddata
:endrule

rule:
plugin=vanillaBlocks
number=9
data:
JSON:{blockState:{blockName:"minecraft:log",properties:{variant:"spruce",axis:"x"}}}
:enddata
:endrule

rule:
plugin=blockTile
number=10
data:
JSON:{blockState:{blockName:"ancientwarfarestructure:gate_proxy"},teData:{lsb:-4883272979644852580L,id:"ancientwarfarestructure:gate_proxy_tile",msb:-6664349458812350683L,render:1b}}
:enddata
:endrule

rule:
plugin=blockTile
number=11
data:
JSON:{blockState:{blockName:"ancientwarfarestructure:gate_proxy"},teData:{lsb:-4883272979644852580L,id:"ancientwarfarestructure:gate_proxy_tile",msb:-6664349458812350683L,render:0b}}
:enddata
:endrule

rule:
plugin=blockTile
number=12
data:
JSON:{blockState:{blockName:"ancientwarfarestructure:gate_proxy"},teData:{lsb:-4883272979644852580L,id:"ancientwarfarestructure:gate_proxy_tile",msb:-6664349458812350683L,render:0b}}
:enddata
:endrule

rule:
plugin=blockTile
number=13
data:
JSON:{blockState:{blockName:"ancientwarfarestructure:gate_proxy"},teData:{lsb:-4883272979644852580L,id:"ancientwarfarestructure:gate_proxy_tile",msb:-6664349458812350683L,render:0b}}
:enddata
:endrule

rule:
plugin=blockTile
number=14
data:
JSON:{blockState:{blockName:"ancientwarfarestructure:gate_proxy"},teData:{lsb:-4883272979644852580L,id:"ancientwarfarestructure:gate_proxy_tile",msb:-6664349458812350683L,render:0b}}
:enddata
:endrule

rule:
plugin=blockTile
number=15
data:
JSON:{blockState:{blockName:"ancientwarfarestructure:gate_proxy"},teData:{lsb:-4883272979644852580L,id:"ancientwarfarestructure:gate_proxy_tile",msb:-6664349458812350683L,render:0b}}
:enddata
:endrule

rule:
plugin=blockTile
number=16
data:
JSON:{blockState:{blockName:"ancientwarfarestructure:gate_proxy"},teData:{lsb:-4883272979644852580L,id:"ancientwarfarestructure:gate_proxy_tile",msb:-6664349458812350683L,render:0b}}
:enddata
:endrule

rule:
plugin=blockTile
number=17
data:
JSON:{blockState:{blockName:"ancientwarfarestructure:gate_proxy"},teData:{lsb:-4883272979644852580L,id:"ancientwarfarestructure:gate_proxy_tile",msb:-6664349458812350683L,render:0b}}
:enddata
:endrule

rule:
plugin=blockTile
number=18
data:
JSON:{blockState:{blockName:"ancientwarfarestructure:gate_proxy"},teData:{lsb:-4883272979644852580L,id:"ancientwarfarestructure:gate_proxy_tile",msb:-6664349458812350683L,render:0b}}
:enddata
:endrule

rule:
plugin=vanillaBlocks
number=19
data:
JSON:{blockState:{blockName:"minecraft:spruce_stairs",properties:{half:"bottom",shape:"straight",facing:"west"}}}
:enddata
:endrule

rule:
plugin=vanillaBlocks
number=20
data:
JSON:{blockState:{blockName:"minecraft:spruce_stairs",properties:{half:"top",shape:"straight",facing:"east"}}}
:enddata
:endrule

rule:
plugin=vanillaBlocks
number=21
data:
JSON:{blockState:{blockName:"minecraft:log",properties:{variant:"spruce",axis:"z"}}}
:enddata
:endrule

rule:
plugin=vanillaBlocks
number=22
data:
JSON:{blockState:{blockName:"minecraft:torch",properties:{facing:"west"}}}
:enddata
:endrule

rule:
plugin=vanillaBlocks
number=23
data:
JSON:{blockState:{blockName:"minecraft:torch",properties:{facing:"east"}}}
:enddata
:endrule

rule:
plugin=vanillaBlocks
number=24
data:
JSON:{blockState:{blockName:"minecraft:spruce_stairs",properties:{half:"top",shape:"straight",facing:"west"}}}
:enddata
:endrule

rule:
plugin=vanillaBlocks
number=25
data:
JSON:{blockState:{blockName:"minecraft:spruce_stairs",properties:{half:"bottom",shape:"straight",facing:"east"}}}
:enddata
:endrule

rule:
plugin=vanillaBlocks
number=26
data:
JSON:{blockState:{blockName:"minecraft:leaves",properties:{check_decay:"false",decayable:"false",variant:"spruce"}}}
:enddata
:endrule

rule:
plugin=vanillaBlocks
number=27
data:
JSON:{blockState:{blockName:"minecraft:torch",properties:{facing:"south"}}}
:enddata
:endrule

rule:
plugin=vanillaBlocks
number=28
data:
JSON:{blockState:{blockName:"minecraft:torch",properties:{facing:"north"}}}
:enddata
:endrule

rule:
plugin=vanillaBlocks
number=29
data:
JSON:{blockState:{blockName:"minecraft:leaves",properties:{check_decay:"true",decayable:"false",variant:"spruce"}}}
:enddata
:endrule

rule:
plugin=vanillaBlocks
number=30
data:
JSON:{blockState:{blockName:"minecraft:spruce_stairs",properties:{half:"top",shape:"straight",facing:"south"}}}
:enddata
:endrule

rule:
plugin=vanillaBlocks
number=31
data:
JSON:{blockState:{blockName:"minecraft:spruce_stairs",properties:{half:"top",shape:"straight",facing:"north"}}}
:enddata
:endrule

rule:
plugin=vanillaBlocks
number=32
data:
JSON:{blockState:{blockName:"minecraft:wooden_slab",properties:{half:"bottom",variant:"spruce"}}}
:enddata
:endrule

#### ENTITIES ####
entity:
plugin=awGate
number=0
data:
JSON:{owner:"",orientation:2b,pos1:{x:1,y:0,z:0},pos2:{x:-1,y:2,z:0},position:1374725079054L,gateType:"gate.verticalWooden"}
:enddata
:endentity

