# Ancient Warfare Structure Template File
# Auto-generated structure template file. created on: 5/12/2021 at: 11:48:26
# Lines beginning with # denote comments

header:
version=2.11
name=SurvivalBuildManorA
mods=
size=18,15,20
offset=17,1,19
:endheader

#### VALIDATION ####
validation:
type=ground
structureAuthor=Loki61089
survival=true
worldGenEnabled=false
unique=false
preserveBlocks=false
preventNaturalHostileSpawns=false
selectionWeight=1
clusterValue=1
minDuplicateDistance=1
dimensionWhiteList=true
dimensionList=
biomeGroupList=
biomeWhiteList=true
biomeList=
leveling=0
fill=0
border=0
blockSwap=false
territoryName=
biomeReplacement=minecraft:
minGenerationHeight=0
maxGenerationHeight=255
:endvalidation

#### LAYERS ####
layer: 0
1,1,1,1,1,1,1,1,1,1,1,1,1,1,1,1,1,1
1,2,2,2,2,2,2,2,1,2,2,2,2,2,2,2,2,1
1,2,4,4,4,4,4,0,3,3,3,3,3,3,3,3,2,1
1,2,4,4,4,4,4,2,3,3,3,3,3,3,3,3,2,1
1,2,4,4,4,4,4,2,3,3,3,3,3,3,3,3,2,1
1,2,4,4,4,4,4,2,3,3,3,3,3,5,3,3,2,1
1,2,4,4,4,4,4,2,3,3,3,3,3,3,3,3,2,1
1,2,2,2,2,2,4,4,3,3,3,3,3,3,3,3,2,1
1,2,2,2,2,2,4,2,3,3,3,3,3,3,3,3,2,1
1,2,4,4,4,4,4,2,3,3,3,3,3,2,3,3,2,1
1,2,4,4,4,4,4,2,3,3,3,3,3,3,3,3,2,1
1,2,4,4,4,4,4,2,3,3,3,3,3,3,3,3,2,1
1,2,4,4,4,4,4,2,2,3,3,3,3,2,3,3,2,1
1,2,2,2,2,2,4,2,2,2,2,3,3,2,2,2,2,1
1,2,4,4,4,4,4,4,4,4,4,3,3,2,3,3,2,1
1,2,4,4,4,2,4,4,4,4,2,3,3,3,3,3,2,1
1,2,4,4,4,2,4,4,4,4,2,3,3,2,3,3,2,1
1,2,2,2,2,2,4,4,4,4,2,3,3,2,2,2,2,1
1,1,1,1,1,2,2,2,2,2,2,1,1,1,1,1,1,1
1,1,1,1,1,1,1,1,1,1,1,1,1,1,1,1,1,1
:endlayer
layer: 1
0,0,0,0,0,0,0,0,0,0,0,0,0,0,0,0,0,0
0,5,6,6,6,6,6,5,7,6,6,6,6,6,6,6,5,0
0,6,0,0,0,0,0,6,0,0,0,0,0,0,0,0,6,0
0,6,0,0,0,0,0,6,0,0,0,0,0,0,0,0,14,0
0,6,0,0,0,0,0,6,0,0,0,0,0,0,0,0,6,0
0,6,0,0,0,0,0,5,6,6,6,7,6,5,6,6,5,0
0,6,0,0,0,0,0,6,0,0,0,0,0,6,0,0,6,0
0,6,6,13,6,6,0,7,0,0,0,0,0,7,0,0,6,0
0,5,6,12,6,6,7,5,11,0,0,0,0,7,0,0,6,0
0,6,0,0,0,0,0,6,10,0,0,0,0,5,6,6,5,0
0,6,0,0,0,0,0,6,0,0,0,0,0,7,0,0,6,0
0,6,0,0,0,0,0,6,0,0,0,0,0,7,0,0,6,0
0,6,0,0,0,0,0,6,9,0,0,0,0,6,0,0,6,0
0,5,6,6,6,5,7,5,8,6,5,7,7,5,6,6,5,0
0,6,0,0,0,7,0,0,0,0,7,0,0,6,0,0,6,0
0,6,0,0,0,6,0,0,0,0,6,0,0,7,0,0,6,0
0,6,0,0,0,6,0,0,0,0,6,0,0,6,0,0,6,0
0,5,6,6,6,5,0,0,0,0,5,7,7,5,6,6,5,0
0,0,0,0,0,5,6,6,6,6,5,0,0,0,0,0,0,0
0,0,0,0,0,0,0,0,0,0,0,0,0,0,0,0,0,0
:endlayer
layer: 2
0,19,0,0,0,0,0,19,0,0,0,0,0,0,0,0,19,0
0,5,3,3,16,3,3,5,17,3,16,3,3,16,3,3,5,0
0,3,0,0,0,0,0,3,0,0,0,0,0,0,0,0,3,0
0,3,0,0,0,0,0,3,0,0,0,0,0,0,0,0,3,0
0,3,0,0,0,0,0,3,0,0,0,0,0,0,0,0,3,0
0,3,0,0,0,0,0,5,3,3,3,17,3,5,3,3,5,0
0,3,0,0,0,0,0,3,0,0,0,0,0,3,0,0,3,0
0,3,3,3,3,3,0,17,0,0,0,0,0,18,0,0,3,0
0,5,3,3,3,3,18,5,0,0,0,0,0,17,0,0,3,0
0,3,0,0,0,0,0,16,11,0,0,0,0,5,3,3,5,0
0,3,0,0,0,0,0,3,10,0,0,0,0,18,0,0,3,0
0,3,0,0,0,0,0,3,0,0,0,0,0,17,0,0,3,0
0,3,0,0,0,0,0,3,0,0,0,0,0,3,0,0,3,0
0,5,3,3,3,5,18,5,3,3,5,17,18,5,3,3,5,0
0,3,0,0,0,17,0,0,0,0,17,0,0,3,0,0,3,0
0,3,0,0,0,3,0,0,0,0,3,0,0,18,0,0,3,0
0,3,0,0,0,3,0,0,0,0,3,0,0,3,0,0,3,0
0,5,3,16,3,5,0,0,0,0,5,18,17,5,3,3,5,0
0,15,0,0,0,5,3,16,16,3,5,0,0,15,0,0,15,0
0,0,0,0,0,15,0,0,0,0,15,0,0,0,0,0,0,0
:endlayer
layer: 3
0,0,0,0,0,0,0,0,0,0,0,0,0,0,0,0,0,0
0,5,3,3,3,3,3,5,3,3,3,3,3,3,3,3,5,0
0,3,0,0,15,0,0,3,0,0,15,0,0,15,0,0,3,0
0,3,0,0,0,0,0,3,0,0,0,0,0,0,0,0,3,0
0,3,0,0,0,0,0,3,0,0,19,0,0,19,0,0,3,0
0,3,0,0,0,0,0,5,3,3,3,3,3,5,3,3,5,0
0,3,0,0,19,0,0,3,0,0,0,0,0,3,0,0,3,0
0,3,3,3,3,3,0,3,0,0,0,0,0,3,0,20,3,0
0,5,3,3,3,3,3,5,0,0,0,0,0,3,0,0,3,0
0,3,0,0,15,0,0,3,0,0,0,0,0,5,3,3,5,0
0,3,0,0,0,0,0,3,11,0,0,0,0,3,0,0,3,0
0,3,0,0,0,0,0,3,10,0,0,0,0,3,0,20,3,0
0,3,0,0,19,0,0,3,0,0,0,0,0,3,0,0,3,0
0,5,3,3,3,5,3,5,3,3,5,3,3,5,3,3,5,0
0,3,0,15,0,3,0,0,15,0,3,0,0,3,0,0,3,0
0,3,0,0,0,3,0,0,0,0,3,0,20,3,0,20,3,0
0,3,0,0,0,3,0,0,0,0,3,0,0,3,0,0,3,0
0,5,3,3,3,5,0,0,0,0,5,3,3,5,3,3,5,0
0,0,0,0,0,5,3,3,3,3,5,0,0,0,0,0,0,0
0,0,0,0,0,0,0,0,0,0,0,0,0,0,0,0,0,0
:endlayer
layer: 4
0,0,0,0,0,0,0,29,9,9,9,9,9,9,9,9,9,9
0,5,21,21,21,21,21,5,21,21,21,21,21,21,21,21,5,27
0,25,24,23,23,23,22,25,32,32,32,32,32,32,32,32,25,27
0,25,24,23,23,23,22,25,23,23,23,23,23,23,23,23,25,27
0,25,24,23,23,23,22,25,28,28,28,28,28,28,28,28,25,27
0,25,24,23,23,23,22,5,21,21,21,21,21,5,21,21,5,27
0,25,24,23,23,23,22,25,26,26,26,26,29,25,32,32,25,27
0,25,4,4,4,4,22,25,0,0,0,0,29,25,23,23,25,27
0,5,21,21,21,21,21,5,0,0,0,0,29,25,28,28,25,27
0,25,32,32,32,32,32,25,0,0,0,0,29,5,21,21,5,27
0,25,23,23,23,23,23,25,0,0,0,0,29,25,32,32,25,27
0,25,23,23,23,23,23,25,11,0,0,0,29,25,23,23,25,27
0,25,28,28,28,28,28,25,10,31,31,30,29,25,28,28,25,27
0,5,21,21,21,5,21,5,21,21,5,21,21,5,21,21,5,26
0,25,24,23,22,25,24,23,23,22,4,24,22,4,24,22,25,0
0,25,24,23,22,25,24,23,23,22,4,24,22,4,24,22,25,0
0,25,24,23,22,25,24,23,23,22,4,24,22,4,24,22,25,0
0,5,21,21,21,5,24,23,23,22,5,21,21,5,21,21,5,0
0,0,0,0,0,5,21,21,21,21,5,0,0,0,0,0,0,0
0,0,0,0,0,0,0,0,0,0,0,0,0,0,0,0,0,0
:endlayer
layer: 5
0,0,0,0,0,0,0,0,0,0,0,0,0,0,0,0,0,0
0,5,33,33,33,33,33,5,9,9,9,9,9,9,9,9,9,0
0,33,0,0,0,0,0,33,4,4,4,4,4,4,4,4,27,0
0,33,0,0,0,0,0,33,4,4,4,4,4,4,4,4,3,0
0,33,0,0,0,0,0,33,4,4,4,4,4,4,4,4,27,0
0,33,0,0,0,0,0,5,26,26,26,26,26,26,4,4,27,0
0,33,0,0,0,0,0,33,0,0,0,0,0,29,4,4,27,0
0,33,3,38,3,4,0,33,0,0,0,0,0,29,4,4,27,0
0,5,3,37,3,4,7,5,0,0,0,0,0,29,4,4,27,0
0,33,0,0,0,0,0,33,0,0,0,0,0,29,4,4,27,0
0,33,0,0,0,0,0,33,0,0,0,0,0,29,4,4,27,0
0,33,0,0,0,0,0,33,0,36,36,36,0,29,4,4,27,0
0,33,0,0,0,0,0,7,0,0,0,0,35,29,4,4,27,0
0,5,4,4,4,5,7,5,34,33,5,7,33,5,33,33,5,0
0,33,0,0,0,7,0,0,0,0,0,0,0,0,0,0,33,0
0,33,0,0,0,4,0,0,0,0,0,0,0,0,0,0,33,0
0,33,0,0,0,4,0,0,0,0,0,0,0,0,0,0,33,0
0,5,33,33,33,5,0,0,0,0,5,33,33,5,33,33,5,0
0,0,0,0,0,5,33,33,33,33,5,0,0,0,0,0,0,0
0,0,0,0,0,0,0,0,0,0,0,0,0,0,0,0,0,0
:endlayer
layer: 6
0,0,0,0,0,0,0,0,0,0,0,0,0,0,0,0,0,0
0,5,33,33,16,33,33,5,0,0,0,0,0,0,0,0,0,0
0,33,0,0,0,0,0,33,9,9,9,9,9,9,9,27,0,0
0,33,0,0,0,0,0,33,4,4,4,4,4,4,4,27,3,0
0,33,0,0,0,0,0,33,26,26,26,26,26,26,26,27,0,0
0,33,0,0,0,0,0,5,0,0,0,0,0,0,29,27,0,0
0,16,0,0,0,0,0,16,0,0,0,0,0,0,29,27,0,0
0,33,3,3,3,4,0,33,0,0,0,0,0,0,29,27,0,0
0,5,3,3,3,4,17,5,0,0,0,0,0,0,29,27,0,0
0,33,0,0,0,0,0,33,0,0,0,0,0,0,29,27,0,0
0,33,0,0,0,0,0,16,0,0,0,0,0,0,29,27,0,0
0,33,0,0,0,0,0,33,0,0,0,0,0,0,29,27,0,0
0,33,0,0,0,0,0,17,0,0,0,0,0,0,29,27,0,0
0,5,4,4,4,5,18,5,3,33,5,18,33,5,33,33,5,0
0,33,0,0,0,17,0,0,0,0,0,0,0,0,0,0,33,0
0,33,0,0,0,4,0,0,0,0,0,0,0,0,0,0,33,0
0,33,0,0,0,4,0,0,0,0,0,0,0,0,0,0,33,0
0,5,33,16,33,5,0,0,0,0,5,16,16,5,33,33,5,0
0,0,0,0,0,5,33,16,16,33,5,0,0,0,0,0,0,0
0,0,0,0,0,0,0,0,0,0,0,0,0,0,0,0,0,0
:endlayer
layer: 7
0,0,0,0,0,0,0,0,0,0,0,0,0,0,0,0,0,0
0,5,33,33,33,33,33,5,0,0,0,0,0,0,0,0,0,0
0,33,0,0,0,0,0,33,0,0,0,0,0,0,0,0,0,0
0,33,0,0,0,0,0,33,39,39,39,39,39,39,39,0,3,0
0,33,0,0,0,0,0,33,0,0,0,0,0,0,0,0,0,0
0,33,0,0,0,0,0,5,0,0,0,0,0,0,0,0,0,0
0,33,0,0,19,0,0,33,0,0,0,0,0,0,0,0,0,0
0,33,3,3,3,4,0,33,0,0,0,0,0,0,0,0,0,0
0,5,3,3,3,4,4,5,0,0,0,0,0,0,0,0,0,0
0,33,0,0,15,0,0,33,0,0,0,0,0,0,0,0,0,0
0,33,0,0,0,0,0,33,0,0,0,0,0,0,0,0,0,0
0,33,0,0,0,0,0,33,0,0,0,0,0,0,0,0,0,0
0,33,0,0,19,0,0,33,0,0,0,0,0,0,0,0,0,0
0,5,4,4,4,5,4,5,3,33,5,33,33,5,33,33,5,0
0,33,0,0,0,4,0,15,0,0,0,0,0,15,0,0,33,0
0,33,0,0,20,4,0,0,0,0,0,0,0,0,0,0,33,0
0,33,0,0,0,4,0,0,0,0,0,0,0,0,0,0,33,0
0,5,33,33,33,5,0,0,0,0,5,33,33,5,33,33,5,0
0,0,0,0,0,5,33,33,33,33,5,0,0,0,0,0,0,0
0,0,0,0,0,0,0,0,0,0,0,0,0,0,0,0,0,0
:endlayer
layer: 8
29,40,0,0,0,0,0,44,27,0,0,0,0,0,0,0,0,0
29,5,21,21,21,21,21,5,27,0,0,0,0,0,0,0,0,0
29,25,0,0,0,0,0,25,27,0,0,0,0,0,0,0,0,0
29,25,0,0,0,0,0,25,27,0,0,0,0,0,0,0,43,0
29,25,0,0,0,0,0,25,27,0,0,0,0,0,0,0,0,0
29,25,0,0,0,0,0,5,27,0,0,0,0,0,0,0,0,0
29,25,0,0,0,0,0,25,27,0,0,0,0,0,0,0,0,0
29,25,3,3,3,4,22,25,27,0,0,0,0,0,0,0,0,0
29,5,21,21,21,21,21,5,27,0,0,0,0,0,0,0,0,0
29,25,0,0,0,0,0,25,27,0,0,0,0,0,0,0,0,0
29,25,0,0,0,0,0,25,27,0,0,0,0,0,0,0,0,0
29,25,0,0,0,0,0,25,27,0,0,0,0,0,0,0,0,0
9,25,0,0,0,0,0,25,9,9,9,9,9,9,9,9,9,9
42,5,21,21,21,5,21,5,21,21,5,21,21,5,21,21,5,42
0,25,0,0,0,25,0,0,0,0,0,0,0,0,0,0,25,0
0,25,0,0,0,25,0,0,0,0,0,0,0,0,0,0,25,0
0,25,0,0,0,25,0,0,0,0,0,0,0,0,0,0,25,0
41,5,21,21,21,5,0,0,0,0,5,21,21,5,21,21,5,41
26,40,0,0,29,5,21,21,21,21,5,27,26,26,26,26,26,26
0,0,0,0,26,26,26,26,26,26,26,27,0,0,0,0,0,0
:endlayer
layer: 9
0,29,40,0,0,0,44,27,0,0,0,0,0,0,0,0,0,0
0,29,33,33,5,33,33,27,0,0,0,0,0,0,0,0,0,0
0,29,24,0,0,0,22,27,0,0,0,0,0,0,0,0,0,0
0,29,24,0,0,0,22,27,0,0,0,0,0,0,0,0,0,0
0,29,24,0,0,0,22,27,0,0,0,0,0,0,0,0,0,0
0,29,24,0,0,0,22,27,0,0,0,0,0,0,0,0,0,0
0,29,24,0,0,0,22,27,0,0,0,0,0,0,0,0,0,0
0,29,3,3,3,4,4,27,0,0,0,0,0,0,0,0,0,0
0,29,3,3,3,4,4,27,0,0,0,0,0,0,0,0,0,0
0,29,24,0,0,0,22,27,0,0,0,0,0,0,0,0,0,0
0,29,24,0,0,0,22,27,0,0,0,0,0,0,0,0,0,0
0,29,24,0,0,0,22,27,0,0,0,0,0,0,0,0,0,0
0,29,24,0,0,0,22,27,0,0,0,0,0,0,0,0,0,0
9,9,4,4,5,4,4,9,3,9,9,9,9,9,9,9,9,9
42,46,24,0,0,4,32,32,32,32,32,32,32,32,32,32,33,42
0,5,24,0,0,5,0,0,0,0,0,0,0,0,0,0,5,0
41,46,24,0,0,4,0,0,0,22,28,28,28,28,28,28,33,41
26,26,33,33,33,33,28,28,28,28,27,26,26,26,26,26,26,26
0,29,40,0,0,39,45,27,26,26,26,0,0,0,0,0,0,0
0,0,0,0,0,0,0,0,0,0,0,0,0,0,0,0,0,0
:endlayer
layer: 10
0,0,29,40,0,44,27,0,0,0,0,0,0,0,0,0,0,0
0,0,29,33,5,33,27,0,0,0,0,0,0,0,0,0,0,0
0,0,29,24,0,22,27,0,0,0,0,0,0,0,0,0,0,0
0,0,29,24,0,22,27,0,0,0,0,0,0,0,0,0,0,0
0,0,29,24,0,22,27,0,0,0,0,0,0,0,0,0,0,0
0,0,29,24,0,22,27,0,0,0,0,0,0,0,0,0,0,0
0,0,29,24,0,22,27,0,0,0,0,0,0,0,0,0,0,0
0,0,29,3,3,4,27,0,0,0,0,0,0,0,0,0,0,0
0,0,29,3,3,4,27,0,0,0,0,0,0,0,0,0,0,0
0,0,29,24,0,22,27,0,0,0,0,0,0,0,0,0,0,0
0,0,29,24,0,22,27,0,0,0,0,0,0,0,0,0,0,0
0,0,29,24,0,22,27,0,0,0,0,0,0,0,0,0,0,0
0,0,29,24,0,22,27,0,0,0,0,0,0,0,0,0,0,0
0,0,29,4,5,4,27,0,3,0,0,0,0,0,0,0,0,0
9,9,9,4,4,4,9,9,9,9,9,9,9,9,9,9,9,9
21,21,21,21,21,5,21,21,21,21,21,21,21,21,21,21,5,21
26,26,26,4,4,4,4,4,4,27,26,26,26,26,26,26,26,26
0,0,29,33,33,33,27,26,26,27,0,0,0,0,0,0,0,0
0,0,29,40,0,44,27,0,0,0,0,0,0,0,0,0,0,0
0,0,0,0,0,0,0,0,0,0,0,0,0,0,0,0,0,0
:endlayer
layer: 11
0,0,0,29,25,27,0,0,0,0,0,0,0,0,0,0,0,0
0,0,0,29,25,27,0,0,0,0,0,0,0,0,0,0,0,0
0,0,0,29,25,27,0,0,0,0,0,0,0,0,0,0,0,0
0,0,0,29,25,27,0,0,0,0,0,0,0,0,0,0,0,0
0,0,0,29,25,27,0,0,0,0,0,0,0,0,0,0,0,0
0,0,0,29,25,27,0,0,0,0,0,0,0,0,0,0,0,0
0,0,0,29,25,27,0,0,0,0,0,0,0,0,0,0,0,0
0,0,0,29,3,27,0,0,0,0,0,0,0,0,0,0,0,0
0,0,0,29,3,27,0,0,0,0,0,0,0,0,0,0,0,0
0,0,0,29,25,27,0,0,0,0,0,0,0,0,0,0,0,0
0,0,0,29,25,27,0,0,0,0,0,0,0,0,0,0,0,0
0,0,0,29,25,27,0,0,0,0,0,0,0,0,0,0,0,0
0,0,0,29,25,27,0,0,0,0,0,0,0,0,0,0,0,0
0,0,0,29,5,27,0,0,3,0,0,0,0,0,0,0,0,0
0,0,0,29,25,27,0,0,0,0,0,0,0,0,0,0,0,0
39,39,39,29,25,27,9,9,9,39,39,39,39,39,39,39,39,39
0,0,0,29,25,26,26,26,27,0,0,0,0,0,0,0,0,0
0,0,0,29,25,27,0,0,0,0,0,0,0,0,0,0,0,0
0,0,0,29,25,27,0,0,0,0,0,0,0,0,0,0,0,0
0,0,0,0,0,0,0,0,0,0,0,0,0,0,0,0,0,0
:endlayer
layer: 12
0,0,0,0,39,0,0,0,0,0,0,0,0,0,0,0,0,0
0,0,0,0,39,0,0,0,0,0,0,0,0,0,0,0,0,0
0,0,0,0,39,0,0,0,0,0,0,0,0,0,0,0,0,0
0,0,0,0,39,0,0,0,0,0,0,0,0,0,0,0,0,0
0,0,0,0,39,0,0,0,0,0,0,0,0,0,0,0,0,0
0,0,0,0,39,0,0,0,0,0,0,0,0,0,0,0,0,0
0,0,0,0,39,0,0,0,0,0,0,0,0,0,0,0,0,0
0,0,0,0,3,0,0,0,0,0,0,0,0,0,0,0,0,0
0,0,0,0,39,0,0,0,0,0,0,0,0,0,0,0,0,0
0,0,0,0,39,0,0,0,0,0,0,0,0,0,0,0,0,0
0,0,0,0,39,0,0,0,0,0,0,0,0,0,0,0,0,0
0,0,0,0,39,0,0,0,0,0,0,0,0,0,0,0,0,0
0,0,0,0,39,0,0,0,0,0,0,0,0,0,0,0,0,0
0,0,0,0,39,0,0,0,43,0,0,0,0,0,0,0,0,0
0,0,0,0,39,0,0,0,0,0,0,0,0,0,0,0,0,0
0,0,0,0,39,0,0,0,0,0,0,0,0,0,0,0,0,0
0,0,0,0,39,0,0,0,0,0,0,0,0,0,0,0,0,0
0,0,0,0,39,0,0,0,0,0,0,0,0,0,0,0,0,0
0,0,0,0,39,0,0,0,0,0,0,0,0,0,0,0,0,0
0,0,0,0,0,0,0,0,0,0,0,0,0,0,0,0,0,0
:endlayer
layer: 13
0,0,0,0,0,0,0,0,0,0,0,0,0,0,0,0,0,0
0,0,0,0,0,0,0,0,0,0,0,0,0,0,0,0,0,0
0,0,0,0,0,0,0,0,0,0,0,0,0,0,0,0,0,0
0,0,0,0,0,0,0,0,0,0,0,0,0,0,0,0,0,0
0,0,0,0,0,0,0,0,0,0,0,0,0,0,0,0,0,0
0,0,0,0,0,0,0,0,0,0,0,0,0,0,0,0,0,0
0,0,0,0,0,0,0,0,0,0,0,0,0,0,0,0,0,0
0,0,0,0,3,0,0,0,0,0,0,0,0,0,0,0,0,0
0,0,0,0,0,0,0,0,0,0,0,0,0,0,0,0,0,0
0,0,0,0,0,0,0,0,0,0,0,0,0,0,0,0,0,0
0,0,0,0,0,0,0,0,0,0,0,0,0,0,0,0,0,0
0,0,0,0,0,0,0,0,0,0,0,0,0,0,0,0,0,0
0,0,0,0,0,0,0,0,0,0,0,0,0,0,0,0,0,0
0,0,0,0,0,0,0,0,0,0,0,0,0,0,0,0,0,0
0,0,0,0,0,0,0,0,0,0,0,0,0,0,0,0,0,0
0,0,0,0,0,0,0,0,0,0,0,0,0,0,0,0,0,0
0,0,0,0,0,0,0,0,0,0,0,0,0,0,0,0,0,0
0,0,0,0,0,0,0,0,0,0,0,0,0,0,0,0,0,0
0,0,0,0,0,0,0,0,0,0,0,0,0,0,0,0,0,0
0,0,0,0,0,0,0,0,0,0,0,0,0,0,0,0,0,0
:endlayer
layer: 14
0,0,0,0,0,0,0,0,0,0,0,0,0,0,0,0,0,0
0,0,0,0,0,0,0,0,0,0,0,0,0,0,0,0,0,0
0,0,0,0,0,0,0,0,0,0,0,0,0,0,0,0,0,0
0,0,0,0,0,0,0,0,0,0,0,0,0,0,0,0,0,0
0,0,0,0,0,0,0,0,0,0,0,0,0,0,0,0,0,0
0,0,0,0,0,0,0,0,0,0,0,0,0,0,0,0,0,0
0,0,0,0,0,0,0,0,0,0,0,0,0,0,0,0,0,0
0,0,0,0,43,0,0,0,0,0,0,0,0,0,0,0,0,0
0,0,0,0,0,0,0,0,0,0,0,0,0,0,0,0,0,0
0,0,0,0,0,0,0,0,0,0,0,0,0,0,0,0,0,0
0,0,0,0,0,0,0,0,0,0,0,0,0,0,0,0,0,0
0,0,0,0,0,0,0,0,0,0,0,0,0,0,0,0,0,0
0,0,0,0,0,0,0,0,0,0,0,0,0,0,0,0,0,0
0,0,0,0,0,0,0,0,0,0,0,0,0,0,0,0,0,0
0,0,0,0,0,0,0,0,0,0,0,0,0,0,0,0,0,0
0,0,0,0,0,0,0,0,0,0,0,0,0,0,0,0,0,0
0,0,0,0,0,0,0,0,0,0,0,0,0,0,0,0,0,0
0,0,0,0,0,0,0,0,0,0,0,0,0,0,0,0,0,0
0,0,0,0,0,0,0,0,0,0,0,0,0,0,0,0,0,0
0,0,0,0,0,0,0,0,0,0,0,0,0,0,0,0,0,0
:endlayer

#### RULES ####
rule:
plugin=vanillaBlocks
number=1
data:
JSON:{blockState:{blockName:"minecraft:grass",properties:{snowy:"false"}}}
:enddata
:endrule

rule:
plugin=vanillaBlocks
number=2
data:
JSON:{blockState:{blockName:"minecraft:dirt",properties:{variant:"dirt",snowy:"false"}}}
:enddata
:endrule

rule:
plugin=vanillaBlocks
number=3
data:
JSON:{blockState:{blockName:"minecraft:cobblestone"}}
:enddata
:endrule

rule:
plugin=vanillaBlocks
number=4
data:
JSON:{blockState:{blockName:"minecraft:planks",properties:{variant:"oak"}}}
:enddata
:endrule

rule:
plugin=vanillaBlocks
number=5
data:
JSON:{blockState:{blockName:"minecraft:log",properties:{variant:"oak",axis:"y"}}}
:enddata
:endrule

rule:
plugin=vanillaBlocks
number=6
data:
JSON:{blockState:{blockName:"minecraft:stonebrick",properties:{variant:"stonebrick"}}}
:enddata
:endrule

rule:
plugin=doors
number=7
data:
JSON:{blockState:{blockName:"minecraft:wooden_door",properties:{hinge:"left",half:"lower",powered:"false",facing:"west",open:"false"}}}
:enddata
:endrule

rule:
plugin=inventory
number=8
data:
JSON:{blockState:{blockName:"minecraft:furnace",properties:{facing:"south"}},lootLevel:0,teData:{CookTime:0,ForgeData:{generatedInventory:1b},BurnTime:0,Items:[],id:"minecraft:furnace",CookTimeTotal:0,Lock:""},inventoryData:{length:0,inventoryContents:[]},legacyFeatures:0b}
:enddata
:endrule

rule:
plugin=vanillaBlocks
number=9
data:
JSON:{blockState:{blockName:"minecraft:stone_brick_stairs",properties:{half:"bottom",shape:"straight",facing:"south"}}}
:enddata
:endrule

rule:
plugin=vanillaBlocks
number=10
data:
JSON:{blockState:{blockName:"minecraft:birch_stairs",properties:{half:"top",shape:"straight",facing:"north"}}}
:enddata
:endrule

rule:
plugin=vanillaBlocks
number=11
data:
JSON:{blockState:{blockName:"minecraft:birch_stairs",properties:{half:"bottom",shape:"straight",facing:"south"}}}
:enddata
:endrule

rule:
plugin=inventory
number=12
data:
JSON:{blockState:{blockName:"minecraft:furnace",properties:{facing:"south"}},lootLevel:0,teData:{CookTime:0,ForgeData:{generatedInventory:1b},BurnTime:0,Items:[],id:"minecraft:furnace",CookTimeTotal:0,Lock:""},inventoryData:{length:0,inventoryContents:[]},legacyFeatures:0b}
:enddata
:endrule

rule:
plugin=inventory
number=13
data:
JSON:{blockState:{blockName:"minecraft:furnace",properties:{facing:"north"}},lootLevel:0,teData:{CookTime:0,ForgeData:{generatedInventory:1b},BurnTime:0,Items:[],id:"minecraft:furnace",CookTimeTotal:0,Lock:""},inventoryData:{length:0,inventoryContents:[]},legacyFeatures:0b}
:enddata
:endrule

rule:
plugin=inventory
number=14
data:
JSON:{blockState:{blockName:"minecraft:furnace",properties:{facing:"west"}},lootLevel:0,teData:{CookTime:0,ForgeData:{generatedInventory:1b},BurnTime:0,Items:[],id:"minecraft:furnace",CookTimeTotal:0,Lock:""},inventoryData:{length:0,inventoryContents:[]},legacyFeatures:0b}
:enddata
:endrule

rule:
plugin=vanillaBlocks
number=15
data:
JSON:{blockState:{blockName:"minecraft:torch",properties:{facing:"south"}}}
:enddata
:endrule

rule:
plugin=vanillaBlocks
number=16
data:
JSON:{blockState:{blockName:"minecraft:stained_glass_pane",properties:{east:"false",color:"green",south:"false",north:"false",west:"false"}}}
:enddata
:endrule

rule:
plugin=doors
number=17
data:
JSON:{blockState:{blockName:"minecraft:wooden_door",properties:{hinge:"right",half:"upper",powered:"false",facing:"south",open:"false"}}}
:enddata
:endrule

rule:
plugin=doors
number=18
data:
JSON:{blockState:{blockName:"minecraft:wooden_door",properties:{hinge:"left",half:"upper",powered:"false",facing:"south",open:"false"}}}
:enddata
:endrule

rule:
plugin=vanillaBlocks
number=19
data:
JSON:{blockState:{blockName:"minecraft:torch",properties:{facing:"north"}}}
:enddata
:endrule

rule:
plugin=vanillaBlocks
number=20
data:
JSON:{blockState:{blockName:"minecraft:torch",properties:{facing:"west"}}}
:enddata
:endrule

rule:
plugin=vanillaBlocks
number=21
data:
JSON:{blockState:{blockName:"minecraft:log",properties:{variant:"oak",axis:"x"}}}
:enddata
:endrule

rule:
plugin=vanillaBlocks
number=22
data:
JSON:{blockState:{blockName:"minecraft:oak_stairs",properties:{half:"top",shape:"straight",facing:"east"}}}
:enddata
:endrule

rule:
plugin=vanillaBlocks
number=23
data:
JSON:{blockState:{blockName:"minecraft:wooden_slab",properties:{half:"top",variant:"oak"}}}
:enddata
:endrule

rule:
plugin=vanillaBlocks
number=24
data:
JSON:{blockState:{blockName:"minecraft:oak_stairs",properties:{half:"top",shape:"straight",facing:"west"}}}
:enddata
:endrule

rule:
plugin=vanillaBlocks
number=25
data:
JSON:{blockState:{blockName:"minecraft:log",properties:{variant:"oak",axis:"z"}}}
:enddata
:endrule

rule:
plugin=vanillaBlocks
number=26
data:
JSON:{blockState:{blockName:"minecraft:stone_brick_stairs",properties:{half:"bottom",shape:"straight",facing:"north"}}}
:enddata
:endrule

rule:
plugin=vanillaBlocks
number=27
data:
JSON:{blockState:{blockName:"minecraft:stone_brick_stairs",properties:{half:"bottom",shape:"straight",facing:"west"}}}
:enddata
:endrule

rule:
plugin=vanillaBlocks
number=28
data:
JSON:{blockState:{blockName:"minecraft:oak_stairs",properties:{half:"top",shape:"straight",facing:"south"}}}
:enddata
:endrule

rule:
plugin=vanillaBlocks
number=29
data:
JSON:{blockState:{blockName:"minecraft:stone_brick_stairs",properties:{half:"bottom",shape:"straight",facing:"east"}}}
:enddata
:endrule

rule:
plugin=vanillaBlocks
number=30
data:
JSON:{blockState:{blockName:"minecraft:birch_stairs",properties:{half:"top",shape:"straight",facing:"west"}}}
:enddata
:endrule

rule:
plugin=vanillaBlocks
number=31
data:
JSON:{blockState:{blockName:"minecraft:birch_stairs",properties:{half:"top",shape:"straight",facing:"south"}}}
:enddata
:endrule

rule:
plugin=vanillaBlocks
number=32
data:
JSON:{blockState:{blockName:"minecraft:oak_stairs",properties:{half:"top",shape:"straight",facing:"north"}}}
:enddata
:endrule

rule:
plugin=vanillaBlocks
number=33
data:
JSON:{blockState:{blockName:"minecraft:stained_hardened_clay",properties:{color:"white"}}}
:enddata
:endrule

rule:
plugin=inventory
number=34
data:
JSON:{blockState:{blockName:"minecraft:furnace",properties:{facing:"south"}},lootLevel:0,teData:{CookTime:0,ForgeData:{generatedInventory:1b},BurnTime:0,Items:[],id:"minecraft:furnace",CookTimeTotal:0,Lock:""},inventoryData:{length:0,inventoryContents:[]},legacyFeatures:0b}
:enddata
:endrule

rule:
plugin=vanillaBlocks
number=35
data:
JSON:{blockState:{blockName:"minecraft:trapdoor",properties:{half:"bottom",facing:"east",open:"true"}}}
:enddata
:endrule

rule:
plugin=vanillaBlocks
number=36
data:
JSON:{blockState:{blockName:"minecraft:trapdoor",properties:{half:"bottom",facing:"north",open:"true"}}}
:enddata
:endrule

rule:
plugin=inventory
number=37
data:
JSON:{blockState:{blockName:"minecraft:furnace",properties:{facing:"south"}},lootLevel:0,teData:{CookTime:0,ForgeData:{generatedInventory:1b},BurnTime:0,Items:[],id:"minecraft:furnace",CookTimeTotal:0,Lock:""},inventoryData:{length:0,inventoryContents:[]},legacyFeatures:0b}
:enddata
:endrule

rule:
plugin=inventory
number=38
data:
JSON:{blockState:{blockName:"minecraft:furnace",properties:{facing:"north"}},lootLevel:0,teData:{CookTime:0,ForgeData:{generatedInventory:1b},BurnTime:0,Items:[],id:"minecraft:furnace",CookTimeTotal:0,Lock:""},inventoryData:{length:0,inventoryContents:[]},legacyFeatures:0b}
:enddata
:endrule

rule:
plugin=vanillaBlocks
number=39
data:
JSON:{blockState:{blockName:"minecraft:stone_slab",properties:{half:"bottom",variant:"stone_brick"}}}
:enddata
:endrule

rule:
plugin=vanillaBlocks
number=40
data:
JSON:{blockState:{blockName:"minecraft:stone_brick_stairs",properties:{half:"top",shape:"straight",facing:"west"}}}
:enddata
:endrule

rule:
plugin=vanillaBlocks
number=41
data:
JSON:{blockState:{blockName:"minecraft:stone_brick_stairs",properties:{half:"top",shape:"straight",facing:"south"}}}
:enddata
:endrule

rule:
plugin=vanillaBlocks
number=42
data:
JSON:{blockState:{blockName:"minecraft:stone_brick_stairs",properties:{half:"top",shape:"straight",facing:"north"}}}
:enddata
:endrule

rule:
plugin=vanillaBlocks
number=43
data:
JSON:{blockState:{blockName:"minecraft:cobblestone_wall",properties:{east:"false",south:"false",north:"false",variant:"cobblestone",west:"false",up:"false"}}}
:enddata
:endrule

rule:
plugin=vanillaBlocks
number=44
data:
JSON:{blockState:{blockName:"minecraft:stone_brick_stairs",properties:{half:"top",shape:"straight",facing:"east"}}}
:enddata
:endrule

rule:
plugin=vanillaBlocks
number=45
data:
JSON:{blockState:{blockName:"minecraft:double_stone_slab",properties:{seamless:"false",variant:"stone_brick"}}}
:enddata
:endrule

rule:
plugin=vanillaBlocks
number=46
data:
JSON:{blockState:{blockName:"minecraft:wool",properties:{color:"white"}}}
:enddata
:endrule

#### ENTITIES ####
