# Ancient Warfare Structure Template File
# Auto-generated structure template file. created on: 5/12/2021 at: 11:56:57
# Lines beginning with # denote comments

header:
version=2.11
name=SurvivalBuildTownhouseD
mods=
size=16,10,15
offset=15,1,14
:endheader

#### VALIDATION ####
validation:
type=ground
structureAuthor=Loki61089
survival=true
worldGenEnabled=false
unique=false
preserveBlocks=false
preventNaturalHostileSpawns=false
selectionWeight=1
clusterValue=1
minDuplicateDistance=1
dimensionWhiteList=true
dimensionList=
biomeGroupList=
biomeWhiteList=true
biomeList=
leveling=0
fill=0
border=0
blockSwap=false
territoryName=
biomeReplacement=minecraft:
minGenerationHeight=0
maxGenerationHeight=255
:endvalidation

#### LAYERS ####
layer: 0
1,1,1,1,1,1,1,1,1,1,1,1,1,1,1,1
1,2,2,2,2,2,1,1,1,1,1,1,1,1,1,1
1,2,4,2,2,2,1,1,1,1,1,1,1,1,1,1
1,2,4,4,4,1,1,1,1,1,1,1,1,1,1,1
1,2,4,4,4,2,1,1,1,1,1,1,1,1,1,1
1,2,2,2,2,2,1,1,1,1,2,2,2,2,2,1
1,1,1,1,1,1,1,1,1,1,2,2,2,2,2,1
1,1,1,1,1,1,1,1,1,1,2,2,2,2,2,1
1,2,3,3,2,2,2,2,1,2,2,2,2,2,2,1
1,3,6,6,5,5,5,2,4,4,2,4,4,4,2,1
1,3,0,6,5,5,5,5,4,4,2,4,4,4,2,1
1,3,0,6,5,5,5,5,4,4,4,4,4,4,2,1
1,3,6,6,5,5,5,2,4,4,2,4,4,4,2,1
1,2,3,3,2,2,2,2,1,2,2,2,2,2,2,1
1,1,1,1,1,1,1,1,1,1,1,1,1,1,1,1
:endlayer
layer: 1
0,0,0,0,0,0,0,0,0,0,0,0,0,0,0,0
0,7,3,3,3,7,0,0,0,0,0,0,0,0,0,0
0,3,0,3,10,3,0,0,0,0,0,0,0,0,0,0
0,3,0,0,0,8,0,0,0,0,0,0,0,0,0,0
0,3,0,0,0,3,0,0,0,0,0,0,0,0,0,0
0,7,3,3,3,7,0,0,0,0,7,3,3,3,7,0
0,0,0,0,0,0,0,0,0,0,3,5,5,5,3,0
0,0,0,0,0,0,0,0,0,0,3,5,7,5,3,0
0,7,3,3,3,3,3,7,8,3,7,9,7,3,3,0
0,3,0,0,0,0,0,3,0,0,3,0,0,0,3,0
0,3,0,0,0,0,0,0,0,0,3,0,0,0,3,0
0,3,0,0,0,0,0,0,0,0,8,0,0,0,3,0
0,3,0,0,0,0,0,3,0,0,3,0,0,0,3,0
0,7,3,3,3,3,3,7,8,3,7,3,3,3,7,0
0,0,0,0,0,0,0,0,0,0,0,0,0,0,0,0
:endlayer
layer: 2
0,0,0,0,0,0,0,0,0,0,0,0,0,0,0,0
0,7,5,5,5,7,18,0,0,0,0,0,0,0,0,0
0,5,0,5,5,5,0,0,0,0,0,0,0,0,0,0
0,5,0,0,0,15,0,0,0,0,0,0,0,0,0,0
0,5,0,0,0,5,0,0,0,0,16,0,0,0,16,0
0,7,5,12,5,7,18,0,0,14,7,5,5,5,7,0
0,0,0,0,0,0,0,0,0,0,5,17,5,5,5,0
0,16,0,0,0,0,0,16,0,0,5,9,7,5,5,0
0,7,5,5,5,5,5,7,13,5,7,0,7,5,5,0
0,5,0,0,0,0,14,5,0,0,5,0,11,0,5,0
0,5,0,0,0,0,0,0,0,14,5,0,0,0,5,0
0,5,0,0,0,0,0,0,0,0,15,0,0,0,5,0
0,5,0,0,0,0,14,5,0,0,5,0,0,0,5,0
0,7,5,5,5,5,5,7,13,5,7,5,12,5,7,0
0,11,0,0,0,0,0,11,0,0,11,0,0,0,11,0
:endlayer
layer: 3
26,26,26,26,26,26,26,0,0,0,0,0,0,0,0,0
25,7,5,5,5,7,25,0,0,0,0,0,0,0,0,0
0,5,0,5,5,5,0,0,0,0,0,0,0,0,0,0
0,5,0,11,0,5,0,0,0,0,0,0,0,0,0,0
0,5,0,0,0,5,0,0,0,0,0,0,0,0,0,0
24,7,5,5,5,7,24,0,0,0,7,5,5,5,7,0
23,23,23,23,23,23,23,0,0,0,5,0,22,17,5,0
0,0,0,0,0,0,0,0,0,0,12,0,7,21,5,0
0,7,5,5,5,5,5,7,5,5,7,0,7,5,5,0
0,5,0,0,0,0,0,5,0,0,5,0,0,0,5,0
0,5,0,0,0,0,0,20,0,0,5,0,0,0,5,0
0,5,0,0,0,0,0,19,0,0,5,0,0,0,5,0
0,5,0,0,0,0,0,5,0,0,5,0,0,0,5,0
0,7,5,5,5,5,5,7,5,5,7,5,5,5,7,0
0,0,0,0,0,0,0,0,0,0,0,0,0,0,0,0
:endlayer
layer: 4
0,0,0,0,0,0,0,0,0,0,0,0,0,0,0,0
26,26,26,26,26,26,26,0,0,0,0,0,0,0,0,0
25,28,20,5,5,28,25,0,0,0,0,0,0,0,0,0
0,28,0,0,0,28,0,0,0,0,0,0,0,0,0,0
24,28,19,19,19,28,24,0,0,0,0,0,0,0,0,0
23,23,23,23,23,23,23,0,0,0,7,27,27,27,7,0
0,0,0,0,0,0,0,0,0,0,28,0,0,0,28,0
0,0,0,0,0,0,0,0,0,0,28,0,33,32,28,0
0,7,27,27,27,27,27,7,27,27,7,0,7,4,28,0
0,28,0,0,0,0,0,28,31,29,4,30,30,29,28,0
0,28,0,0,0,0,0,28,31,29,4,31,30,29,28,0
0,28,0,0,0,0,0,28,31,29,4,31,30,29,28,0
0,28,0,0,0,0,0,28,31,29,4,31,30,29,28,0
0,7,27,27,27,27,27,7,27,27,7,27,27,27,7,0
0,0,0,0,0,0,0,0,0,0,0,0,0,0,0,0
:endlayer
layer: 5
0,0,0,0,0,0,0,0,0,0,0,0,0,0,0,0
0,0,0,0,0,0,0,0,0,0,0,0,0,0,0,0
26,26,26,26,5,26,26,0,0,0,0,0,0,0,0,0
27,27,27,27,27,27,27,0,0,0,0,0,0,0,0,0
23,23,23,23,23,23,23,0,0,0,0,0,0,0,0,0
0,0,0,0,0,0,0,0,0,0,7,4,4,4,7,0
0,0,0,0,0,0,0,0,0,0,4,0,0,0,4,0
0,0,0,0,0,0,0,0,0,0,4,0,33,0,4,0
0,7,4,4,4,4,4,7,4,4,7,0,33,0,4,0
0,4,0,0,0,0,0,33,0,0,33,33,33,0,4,0
0,4,0,0,0,0,0,33,0,0,0,0,0,0,4,0
0,4,0,0,0,0,0,33,0,0,0,0,0,0,4,0
0,4,0,0,0,0,0,33,0,0,0,0,0,0,4,0
0,7,34,12,12,12,34,7,34,34,7,34,34,34,7,0
0,0,0,0,0,0,0,0,0,0,0,0,0,0,0,0
:endlayer
layer: 6
0,0,0,0,0,0,0,0,0,0,0,0,0,0,0,0
0,0,0,0,0,0,0,0,0,0,0,0,0,0,0,0
0,0,0,0,5,0,0,0,0,0,0,0,0,0,0,0
39,39,39,39,39,39,39,0,0,0,0,0,0,0,0,0
0,0,0,0,0,0,0,0,0,38,37,0,0,0,36,35
0,0,0,0,0,0,0,0,0,38,7,4,4,4,7,35
0,0,0,0,0,0,0,0,0,38,4,0,0,0,4,35
26,26,26,26,26,26,26,26,26,26,4,0,0,0,4,26
25,7,4,4,4,4,4,7,4,4,7,0,0,0,4,25
0,4,0,0,0,0,0,11,0,0,11,0,0,0,4,0
0,4,0,0,0,0,0,0,0,0,0,0,0,14,4,0
0,4,0,0,0,0,0,0,0,0,0,0,0,0,4,0
0,4,0,0,0,0,0,16,0,0,16,0,0,0,4,0
24,7,34,34,34,34,34,7,34,34,7,34,12,34,7,24
23,23,38,37,0,36,35,23,23,38,37,0,0,0,36,35
:endlayer
layer: 7
0,0,0,0,0,0,0,0,0,0,0,0,0,0,0,0
0,0,0,0,0,0,0,0,0,0,0,0,0,0,0,0
0,0,0,0,40,0,0,0,0,0,0,0,0,0,0,0
0,0,0,0,0,0,0,0,0,0,0,0,0,0,0,0
0,0,0,0,0,0,0,0,0,0,38,37,0,36,35,0
0,0,0,0,0,0,0,0,0,0,38,4,4,4,35,0
0,0,0,0,0,0,0,0,0,0,38,31,0,29,35,0
0,0,0,0,0,0,0,0,0,0,38,31,0,29,35,0
26,26,26,26,26,26,26,26,26,26,26,31,0,29,35,26
25,4,20,20,20,20,20,20,20,20,20,31,0,20,4,25
0,4,0,0,0,0,0,0,0,0,0,0,0,0,4,0
0,4,0,0,0,0,0,0,0,0,0,0,0,0,4,0
24,4,19,19,19,19,19,19,19,19,19,19,19,19,4,24
23,23,23,23,28,35,23,23,23,23,23,34,34,34,23,23
0,0,0,38,28,35,0,0,0,0,38,37,0,36,35,0
:endlayer
layer: 8
0,0,0,0,0,0,0,0,0,0,0,0,0,0,0,0
0,0,0,0,0,0,0,0,0,0,0,0,0,0,0,0
0,0,0,0,0,0,0,0,0,0,0,0,0,0,0,0
0,0,0,0,0,0,0,0,0,0,0,0,0,0,0,0
0,0,0,0,0,0,0,0,0,0,0,38,28,35,0,0
0,0,0,0,0,0,0,0,0,0,0,38,28,35,0,0
0,0,0,0,0,0,0,0,0,0,0,38,28,35,0,0
0,0,0,0,0,0,0,0,0,0,0,38,28,35,0,0
0,0,0,0,0,0,0,0,0,0,0,38,28,35,0,0
26,26,26,26,26,26,26,26,26,26,26,38,28,35,26,26
25,4,20,20,20,20,20,20,20,20,20,20,28,20,4,25
24,4,19,19,19,19,19,19,19,19,19,19,28,19,4,24
23,23,23,23,23,23,23,23,23,23,23,38,28,23,23,23
0,0,0,0,39,0,0,0,0,0,0,38,28,35,0,0
0,0,0,0,39,0,0,0,0,0,0,38,28,35,0,0
:endlayer
layer: 9
0,0,0,0,0,0,0,0,0,0,0,0,0,0,0,0
0,0,0,0,0,0,0,0,0,0,0,0,0,0,0,0
0,0,0,0,0,0,0,0,0,0,0,0,0,0,0,0
0,0,0,0,0,0,0,0,0,0,0,0,0,0,0,0
0,0,0,0,0,0,0,0,0,0,0,0,39,0,0,0
0,0,0,0,0,0,0,0,0,0,0,0,39,0,0,0
0,0,0,0,0,0,0,0,0,0,0,0,39,0,0,0
0,0,0,0,0,0,0,0,0,0,0,0,39,0,0,0
0,0,0,0,0,0,0,0,0,0,0,0,39,0,0,0
0,0,0,0,0,0,0,0,0,0,0,0,39,0,0,0
26,26,26,26,26,26,26,26,26,26,26,26,26,26,26,26
23,23,23,23,23,23,23,23,23,23,23,23,23,23,23,23
0,0,0,0,0,0,0,0,0,0,0,0,39,0,0,0
0,0,0,0,0,0,0,0,0,0,0,0,39,0,0,0
0,0,0,0,0,0,0,0,0,0,0,0,39,0,0,0
:endlayer

#### RULES ####
rule:
plugin=vanillaBlocks
number=1
data:
JSON:{blockState:{blockName:"minecraft:grass",properties:{snowy:"false"}}}
:enddata
:endrule

rule:
plugin=vanillaBlocks
number=2
data:
JSON:{blockState:{blockName:"minecraft:dirt",properties:{variant:"dirt",snowy:"false"}}}
:enddata
:endrule

rule:
plugin=vanillaBlocks
number=3
data:
JSON:{blockState:{blockName:"minecraft:stonebrick",properties:{variant:"stonebrick"}}}
:enddata
:endrule

rule:
plugin=vanillaBlocks
number=4
data:
JSON:{blockState:{blockName:"minecraft:planks",properties:{variant:"oak"}}}
:enddata
:endrule

rule:
plugin=vanillaBlocks
number=5
data:
JSON:{blockState:{blockName:"minecraft:cobblestone"}}
:enddata
:endrule

rule:
plugin=vanillaBlocks
number=6
data:
JSON:{blockState:{blockName:"minecraft:stone_slab",properties:{half:"bottom",variant:"cobblestone"}}}
:enddata
:endrule

rule:
plugin=vanillaBlocks
number=7
data:
JSON:{blockState:{blockName:"minecraft:log",properties:{variant:"oak",axis:"y"}}}
:enddata
:endrule

rule:
plugin=doors
number=8
data:
JSON:{blockState:{blockName:"minecraft:wooden_door",properties:{hinge:"left",half:"lower",powered:"false",facing:"east",open:"false"}}}
:enddata
:endrule

rule:
plugin=vanillaBlocks
number=9
data:
JSON:{blockState:{blockName:"minecraft:birch_stairs",properties:{half:"bottom",shape:"straight",facing:"north"}}}
:enddata
:endrule

rule:
plugin=inventory
number=10
data:
JSON:{blockState:{blockName:"minecraft:furnace",properties:{facing:"south"}},lootLevel:0,teData:{CookTime:0,ForgeData:{generatedInventory:1b},BurnTime:0,Items:[],id:"minecraft:furnace",CookTimeTotal:0,Lock:""},inventoryData:{length:0,inventoryContents:[]},legacyFeatures:0b}
:enddata
:endrule

rule:
plugin=vanillaBlocks
number=11
data:
JSON:{blockState:{blockName:"minecraft:torch",properties:{facing:"south"}}}
:enddata
:endrule

rule:
plugin=vanillaBlocks
number=12
data:
JSON:{blockState:{blockName:"minecraft:stained_glass_pane",properties:{east:"false",color:"green",south:"false",north:"false",west:"false"}}}
:enddata
:endrule

rule:
plugin=doors
number=13
data:
JSON:{blockState:{blockName:"minecraft:wooden_door",properties:{hinge:"right",half:"upper",powered:"false",facing:"south",open:"false"}}}
:enddata
:endrule

rule:
plugin=vanillaBlocks
number=14
data:
JSON:{blockState:{blockName:"minecraft:torch",properties:{facing:"west"}}}
:enddata
:endrule

rule:
plugin=doors
number=15
data:
JSON:{blockState:{blockName:"minecraft:wooden_door",properties:{hinge:"left",half:"upper",powered:"false",facing:"south",open:"false"}}}
:enddata
:endrule

rule:
plugin=vanillaBlocks
number=16
data:
JSON:{blockState:{blockName:"minecraft:torch",properties:{facing:"north"}}}
:enddata
:endrule

rule:
plugin=vanillaBlocks
number=17
data:
JSON:{blockState:{blockName:"minecraft:birch_stairs",properties:{half:"top",shape:"straight",facing:"west"}}}
:enddata
:endrule

rule:
plugin=vanillaBlocks
number=18
data:
JSON:{blockState:{blockName:"minecraft:torch",properties:{facing:"east"}}}
:enddata
:endrule

rule:
plugin=vanillaBlocks
number=19
data:
JSON:{blockState:{blockName:"minecraft:oak_stairs",properties:{half:"top",shape:"straight",facing:"south"}}}
:enddata
:endrule

rule:
plugin=vanillaBlocks
number=20
data:
JSON:{blockState:{blockName:"minecraft:oak_stairs",properties:{half:"top",shape:"straight",facing:"north"}}}
:enddata
:endrule

rule:
plugin=vanillaBlocks
number=21
data:
JSON:{blockState:{blockName:"minecraft:birch_stairs",properties:{half:"top",shape:"straight",facing:"north"}}}
:enddata
:endrule

rule:
plugin=vanillaBlocks
number=22
data:
JSON:{blockState:{blockName:"minecraft:birch_stairs",properties:{half:"bottom",shape:"straight",facing:"east"}}}
:enddata
:endrule

rule:
plugin=vanillaBlocks
number=23
data:
JSON:{blockState:{blockName:"minecraft:stone_brick_stairs",properties:{half:"bottom",shape:"straight",facing:"north"}}}
:enddata
:endrule

rule:
plugin=vanillaBlocks
number=24
data:
JSON:{blockState:{blockName:"minecraft:stone_brick_stairs",properties:{half:"top",shape:"straight",facing:"south"}}}
:enddata
:endrule

rule:
plugin=vanillaBlocks
number=25
data:
JSON:{blockState:{blockName:"minecraft:stone_brick_stairs",properties:{half:"top",shape:"straight",facing:"north"}}}
:enddata
:endrule

rule:
plugin=vanillaBlocks
number=26
data:
JSON:{blockState:{blockName:"minecraft:stone_brick_stairs",properties:{half:"bottom",shape:"straight",facing:"south"}}}
:enddata
:endrule

rule:
plugin=vanillaBlocks
number=27
data:
JSON:{blockState:{blockName:"minecraft:log",properties:{variant:"oak",axis:"x"}}}
:enddata
:endrule

rule:
plugin=vanillaBlocks
number=28
data:
JSON:{blockState:{blockName:"minecraft:log",properties:{variant:"oak",axis:"z"}}}
:enddata
:endrule

rule:
plugin=vanillaBlocks
number=29
data:
JSON:{blockState:{blockName:"minecraft:oak_stairs",properties:{half:"top",shape:"straight",facing:"east"}}}
:enddata
:endrule

rule:
plugin=vanillaBlocks
number=30
data:
JSON:{blockState:{blockName:"minecraft:wooden_slab",properties:{half:"top",variant:"oak"}}}
:enddata
:endrule

rule:
plugin=vanillaBlocks
number=31
data:
JSON:{blockState:{blockName:"minecraft:oak_stairs",properties:{half:"top",shape:"straight",facing:"west"}}}
:enddata
:endrule

rule:
plugin=vanillaBlocks
number=32
data:
JSON:{blockState:{blockName:"minecraft:birch_stairs",properties:{half:"bottom",shape:"straight",facing:"south"}}}
:enddata
:endrule

rule:
plugin=vanillaBlocks
number=33
data:
JSON:{blockState:{blockName:"minecraft:birch_fence",properties:{east:"false",south:"false",north:"false",west:"false"}}}
:enddata
:endrule

rule:
plugin=vanillaBlocks
number=34
data:
JSON:{blockState:{blockName:"minecraft:stained_hardened_clay",properties:{color:"white"}}}
:enddata
:endrule

rule:
plugin=vanillaBlocks
number=35
data:
JSON:{blockState:{blockName:"minecraft:stone_brick_stairs",properties:{half:"bottom",shape:"straight",facing:"west"}}}
:enddata
:endrule

rule:
plugin=vanillaBlocks
number=36
data:
JSON:{blockState:{blockName:"minecraft:stone_brick_stairs",properties:{half:"top",shape:"straight",facing:"east"}}}
:enddata
:endrule

rule:
plugin=vanillaBlocks
number=37
data:
JSON:{blockState:{blockName:"minecraft:stone_brick_stairs",properties:{half:"top",shape:"straight",facing:"west"}}}
:enddata
:endrule

rule:
plugin=vanillaBlocks
number=38
data:
JSON:{blockState:{blockName:"minecraft:stone_brick_stairs",properties:{half:"bottom",shape:"straight",facing:"east"}}}
:enddata
:endrule

rule:
plugin=vanillaBlocks
number=39
data:
JSON:{blockState:{blockName:"minecraft:stone_slab",properties:{half:"bottom",variant:"stone_brick"}}}
:enddata
:endrule

rule:
plugin=vanillaBlocks
number=40
data:
JSON:{blockState:{blockName:"minecraft:cobblestone_wall",properties:{east:"false",south:"false",north:"false",variant:"cobblestone",west:"false",up:"false"}}}
:enddata
:endrule

#### ENTITIES ####
