# Ancient Warfare Structure Template File
# Auto-generated structure template file. created on: 4/1/2023 at: 18:42:44
# Lines beginning with # denote comments

header:
version=2.11
name=SurvivalBuild_GuardTower_oak
mods=
size=16,31,16
offset=9,1,11
:endheader

#### VALIDATION ####
validation:
type=ground
structureAuthor=Loki61089
survival=true
worldGenEnabled=false
unique=false
preserveBlocks=false
preventNaturalHostileSpawns=false
selectionWeight=1
clusterValue=1
minDuplicateDistance=1
dimensionWhiteList=true
dimensionList=
biomeGroupList=
biomeWhiteList=true
biomeList=
leveling=0
fill=0
border=0
blockSwap=false
territoryName=
biomeReplacement=minecraft:
minGenerationHeight=0
maxGenerationHeight=255
:endvalidation

#### LAYERS ####
layer: 0
1,1,1,1,1,1,1,1,1,1,1,1,1,1,1,1
1,1,1,1,1,1,1,1,2,2,2,2,2,2,2,1
1,1,1,1,4,4,4,4,2,3,3,3,3,3,2,1
1,1,1,4,3,3,3,3,4,3,3,3,3,3,2,1
1,1,2,2,3,3,3,3,4,3,3,3,3,3,2,1
1,1,4,3,3,3,3,3,4,3,3,3,3,3,2,1
1,1,4,3,3,3,3,3,3,3,3,3,3,3,2,1
1,1,4,3,3,2,3,3,3,3,3,3,3,3,2,1
1,1,1,4,3,2,3,3,4,3,3,3,3,3,2,1
1,1,1,1,4,4,4,4,2,3,3,3,3,3,2,1
1,1,1,1,1,1,1,1,2,3,3,2,2,2,2,1
1,1,1,1,1,1,1,1,1,1,1,1,1,1,1,1
1,1,2,1,1,2,1,1,1,1,1,1,1,1,1,1
1,1,1,1,1,1,1,1,1,1,1,1,1,1,1,1
1,1,1,1,1,1,1,1,1,1,1,1,1,1,1,1
1,1,1,1,1,1,1,1,1,1,1,1,1,1,1,1
:endlayer
layer: 1
0,0,0,0,0,0,0,0,0,0,0,0,0,0,0,0
0,0,0,0,0,0,0,0,5,4,4,4,4,4,5,0
0,0,0,0,4,4,4,4,4,0,0,0,0,0,4,0
0,0,0,4,0,0,0,0,4,0,0,0,0,0,4,0
0,0,4,4,0,0,0,0,4,0,0,0,0,0,4,0
0,0,4,0,0,0,0,0,4,0,0,0,0,0,4,0
0,0,4,0,0,5,0,0,0,0,0,0,0,0,4,0
0,0,4,10,10,8,0,0,0,0,0,0,0,0,4,0
0,0,9,4,10,8,0,0,4,0,0,0,0,0,4,0
0,0,9,0,4,4,4,4,4,0,0,0,0,0,4,0
0,0,9,0,0,9,0,0,5,7,6,4,4,4,5,0
0,0,9,0,0,9,0,0,0,0,0,0,0,0,0,0
0,0,5,11,11,5,0,0,0,0,0,0,0,0,0,0
0,0,0,0,0,0,0,0,0,0,0,0,0,0,0,0
0,0,0,0,0,0,0,0,0,0,0,0,0,0,0,0
0,0,0,0,0,0,0,0,0,0,0,0,0,0,0,0
:endlayer
layer: 2
0,0,0,0,0,0,0,0,13,0,0,0,0,0,13,0
0,0,0,0,13,0,0,16,5,3,14,3,14,3,5,12
0,0,0,0,4,4,4,4,4,0,0,0,0,0,3,0
0,0,0,4,0,0,0,0,4,0,0,0,0,0,3,0
0,16,4,4,10,0,0,0,4,0,0,0,0,0,3,0
0,0,4,10,10,0,0,0,4,12,0,0,0,0,14,0
0,0,4,8,8,5,12,0,0,0,0,0,0,0,14,0
0,16,4,0,0,0,0,0,0,0,0,0,0,0,3,0
0,0,0,4,0,0,0,0,4,12,0,0,0,16,3,0
0,0,0,0,4,4,4,4,4,0,0,0,0,0,3,0
0,0,0,0,0,0,0,0,5,17,17,3,14,3,5,12
0,0,0,0,0,0,0,0,15,0,0,0,0,0,15,0
0,16,5,0,0,5,0,0,0,0,0,0,0,0,0,0
0,0,15,0,0,15,0,0,0,0,0,0,0,0,0,0
0,0,0,0,0,0,0,0,0,0,0,0,0,0,0,0
0,0,0,0,0,0,0,0,0,0,0,0,0,0,0,0
:endlayer
layer: 3
0,0,0,0,0,0,0,0,0,0,0,0,0,0,0,0
0,0,0,0,0,0,0,0,5,3,3,3,3,3,5,0
0,0,0,0,4,4,4,4,4,0,15,0,15,0,3,0
0,0,0,4,4,4,4,4,4,0,0,0,0,0,3,0
0,0,4,0,0,8,10,4,4,0,0,0,0,0,3,0
0,0,4,0,0,8,10,10,4,0,0,0,0,0,3,0
0,0,4,0,0,5,0,0,4,0,0,0,0,0,3,0
0,0,4,0,0,0,0,0,4,0,0,0,0,0,3,0
0,0,9,4,0,0,0,0,4,0,0,0,0,0,3,0
0,0,9,0,4,4,4,4,4,0,0,0,0,0,3,0
0,0,9,0,0,9,0,0,5,3,3,3,3,3,5,0
0,0,9,0,0,9,0,0,0,0,0,0,0,0,0,0
0,0,5,0,0,5,0,0,0,0,0,0,0,0,0,0
0,0,0,0,0,0,0,0,0,0,0,0,0,0,0,0
0,0,0,0,0,0,0,0,0,0,0,0,0,0,0,0
0,0,0,0,0,0,0,0,0,0,0,0,0,0,0,0
:endlayer
layer: 4
0,0,0,0,0,0,0,18,18,18,18,18,18,18,18,18
0,0,0,0,0,0,0,18,5,20,20,20,20,20,5,18
0,0,0,0,4,4,4,4,19,0,0,0,0,0,19,0
0,0,0,4,4,4,4,4,4,0,0,0,0,0,19,0
0,0,4,0,0,0,0,0,4,0,0,0,0,0,19,0
0,0,4,0,0,0,0,0,4,0,0,0,0,0,19,0
0,0,4,0,16,5,8,8,4,0,0,0,0,0,19,0
0,18,4,0,0,0,10,10,4,0,0,0,0,0,19,0
0,18,19,4,0,0,10,0,4,0,0,0,0,0,19,0
0,18,19,0,4,4,4,4,19,0,0,0,0,0,19,0
0,18,19,0,0,19,18,18,5,20,20,20,20,20,5,18
0,18,19,0,0,19,18,18,18,18,18,18,18,18,18,18
0,18,19,20,20,19,18,0,0,0,0,0,0,0,0,0
0,18,18,0,0,18,18,0,0,0,0,0,0,0,0,0
0,0,0,0,0,0,0,0,0,0,0,0,0,0,0,0
0,0,0,0,0,0,0,0,0,0,0,0,0,0,0,0
:endlayer
layer: 5
0,0,0,0,0,0,0,0,0,0,0,0,0,0,0,0
0,0,0,0,0,0,0,21,21,21,21,21,21,21,21,21
0,0,0,0,4,4,4,4,22,18,18,18,18,18,22,22
0,0,0,4,4,4,4,4,4,0,0,0,0,0,23,18
0,0,4,0,0,0,0,0,4,0,0,0,0,0,23,0
0,0,4,0,0,0,0,0,4,0,0,0,0,0,23,0
0,0,4,0,0,5,0,0,4,0,0,0,0,0,23,0
0,0,4,10,10,8,0,0,4,0,0,0,0,0,23,0
0,0,21,4,10,8,0,4,4,0,0,0,0,0,22,18
0,0,21,18,4,4,4,4,22,18,18,18,18,18,22,22
0,24,21,18,18,21,24,21,21,21,21,21,21,21,21,21
0,0,21,18,18,21,0,0,0,0,0,0,0,0,0,0
0,0,21,22,22,21,0,0,0,0,0,0,0,0,0,0
0,0,21,22,22,21,0,0,0,0,0,0,0,0,0,0
0,0,0,0,0,0,0,0,0,0,0,0,0,0,0,0
0,0,0,0,0,0,0,0,0,0,0,0,0,0,0,0
:endlayer
layer: 6
0,0,0,0,0,0,0,0,0,0,0,0,0,0,0,0
0,0,0,0,0,0,0,0,0,0,0,0,0,0,0,0
0,0,0,0,4,4,4,4,0,24,0,0,0,0,24,0
0,0,0,4,4,4,4,4,4,21,21,21,21,21,21,21
0,0,4,4,10,0,0,0,4,18,18,18,18,18,22,22
0,0,4,10,10,0,0,0,4,0,0,0,0,0,23,18
0,0,4,4,8,5,12,0,4,0,0,0,0,0,23,18
0,0,4,4,0,0,0,0,4,18,18,18,18,18,22,22
0,0,0,4,0,0,0,4,4,21,21,21,21,21,21,21
0,0,0,0,4,4,4,4,0,24,0,0,0,0,24,0
0,0,0,0,0,0,0,0,0,0,0,0,0,0,0,0
0,0,0,0,0,0,0,0,0,0,0,0,0,0,0,0
0,0,0,0,0,0,0,0,0,0,0,0,0,0,0,0
0,0,0,0,0,0,0,0,0,0,0,0,0,0,0,0
0,0,0,0,0,0,0,0,0,0,0,0,0,0,0,0
0,0,0,0,0,0,0,0,0,0,0,0,0,0,0,0
:endlayer
layer: 7
0,0,0,0,0,0,0,0,0,0,0,0,0,0,0,0
0,0,0,0,0,0,0,0,0,0,0,0,0,0,0,0
0,0,0,0,4,4,4,4,0,0,0,0,0,0,0,0
0,0,0,4,4,4,4,4,4,0,0,0,0,0,0,0
0,0,4,4,0,8,18,18,4,4,0,0,0,0,0,0
0,0,4,4,0,8,18,18,4,4,21,21,21,21,21,21
0,0,4,4,0,5,18,18,4,4,21,21,21,21,21,21
0,0,4,4,0,0,0,0,4,4,0,0,0,0,0,0
0,0,0,4,0,0,0,4,4,0,0,0,0,0,0,0
0,0,0,0,4,4,4,4,0,0,0,0,0,0,0,0
0,0,0,0,0,0,0,0,0,0,0,0,0,0,0,0
0,0,0,0,0,0,0,0,0,0,0,0,0,0,0,0
0,0,0,0,0,0,0,0,0,0,0,0,0,0,0,0
0,0,0,0,0,0,0,0,0,0,0,0,0,0,0,0
0,0,0,0,0,0,0,0,0,0,0,0,0,0,0,0
0,0,0,0,0,0,0,0,0,0,0,0,0,0,0,0
:endlayer
layer: 8
0,0,0,0,0,0,0,0,0,0,0,0,0,0,0,0
0,0,0,0,0,0,0,0,0,0,0,0,0,0,0,0
0,0,0,0,28,25,25,26,0,0,0,0,0,0,0,0
0,0,0,8,4,4,4,4,8,0,0,0,0,0,0,0
0,0,25,4,0,0,0,0,4,25,0,0,0,0,0,0
0,0,28,4,0,0,0,0,4,26,0,0,0,0,0,0
0,0,28,4,16,5,21,21,4,26,0,0,0,0,0,0
0,0,27,4,0,18,21,21,4,27,0,0,0,0,0,0
0,0,0,8,4,4,4,4,8,0,0,0,0,0,0,0
0,0,0,0,28,27,27,26,0,0,0,0,0,0,0,0
0,0,0,0,0,0,0,0,0,0,0,0,0,0,0,0
0,0,0,0,0,0,0,0,0,0,0,0,0,0,0,0
0,0,0,0,0,0,0,0,0,0,0,0,0,0,0,0
0,0,0,0,0,0,0,0,0,0,0,0,0,0,0,0
0,0,0,0,0,0,0,0,0,0,0,0,0,0,0,0
0,0,0,0,0,0,0,0,0,0,0,0,0,0,0,0
:endlayer
layer: 9
0,0,0,0,0,0,0,0,0,0,0,0,0,0,0,0
0,0,0,0,0,0,0,0,0,0,0,0,0,0,0,0
0,0,0,0,0,0,0,0,0,0,0,0,0,0,0,0
0,0,0,0,4,4,4,4,0,0,0,0,0,0,0,0
0,0,0,4,0,0,0,0,4,0,0,0,0,0,0,0
0,0,0,4,0,0,0,0,4,0,0,0,0,0,0,0
0,0,0,4,18,5,0,0,4,0,0,0,0,0,0,0
0,0,0,4,21,0,0,0,4,0,0,0,0,0,0,0
0,0,0,0,4,4,4,4,0,0,0,0,0,0,0,0
0,0,0,0,0,0,0,0,0,0,0,0,0,0,0,0
0,0,0,0,0,0,0,0,0,0,0,0,0,0,0,0
0,0,0,0,0,0,0,0,0,0,0,0,0,0,0,0
0,0,0,0,0,0,0,0,0,0,0,0,0,0,0,0
0,0,0,0,0,0,0,0,0,0,0,0,0,0,0,0
0,0,0,0,0,0,0,0,0,0,0,0,0,0,0,0
0,0,0,0,0,0,0,0,0,0,0,0,0,0,0,0
:endlayer
layer: 10
0,0,0,0,0,0,0,0,0,0,0,0,0,0,0,0
0,0,0,0,0,0,0,0,0,0,0,0,0,0,0,0
0,0,0,0,0,0,0,0,0,0,0,0,0,0,0,0
0,0,0,0,4,4,4,4,0,0,0,0,0,0,0,0
0,0,0,4,23,23,0,0,4,0,0,0,0,0,0,0
0,0,0,4,21,18,0,0,4,0,0,0,0,0,0,0
0,0,0,4,0,5,0,0,4,0,0,0,0,0,0,0
0,0,0,4,0,0,0,0,4,0,0,0,0,0,0,0
0,0,0,0,4,4,4,4,0,0,0,0,0,0,0,0
0,0,0,0,0,0,0,0,0,0,0,0,0,0,0,0
0,0,0,0,0,0,0,0,0,0,0,0,0,0,0,0
0,0,0,0,0,0,0,0,0,0,0,0,0,0,0,0
0,0,0,0,0,0,0,0,0,0,0,0,0,0,0,0
0,0,0,0,0,0,0,0,0,0,0,0,0,0,0,0
0,0,0,0,0,0,0,0,0,0,0,0,0,0,0,0
0,0,0,0,0,0,0,0,0,0,0,0,0,0,0,0
:endlayer
layer: 11
0,0,0,0,0,0,0,0,0,0,0,0,0,0,0,0
0,0,0,0,0,0,0,0,0,0,0,0,0,0,0,0
0,0,0,0,0,0,0,0,0,0,0,0,0,0,0,0
0,0,0,0,4,4,4,4,0,0,0,0,0,0,0,0
0,0,0,4,23,23,23,23,4,0,0,0,0,0,0,0
0,0,0,4,0,0,21,23,4,0,0,0,0,0,0,0
0,0,0,4,0,5,18,0,4,0,0,0,0,0,0,0
0,0,0,4,0,0,0,0,4,0,0,0,0,0,0,0
0,0,0,0,4,4,4,4,0,0,0,0,0,0,0,0
0,0,0,0,0,0,0,0,0,0,0,0,0,0,0,0
0,0,0,0,0,0,0,0,0,0,0,0,0,0,0,0
0,0,0,0,0,0,0,0,0,0,0,0,0,0,0,0
0,0,0,0,0,0,0,0,0,0,0,0,0,0,0,0
0,0,0,0,0,0,0,0,0,0,0,0,0,0,0,0
0,0,0,0,0,0,0,0,0,0,0,0,0,0,0,0
0,0,0,0,0,0,0,0,0,0,0,0,0,0,0,0
:endlayer
layer: 12
0,0,0,0,0,0,0,0,0,0,0,0,0,0,0,0
0,0,0,0,0,0,0,0,0,0,0,0,0,0,0,0
0,0,0,0,0,0,0,0,0,0,0,0,0,0,0,0
0,0,0,0,4,4,4,4,0,0,0,0,0,0,0,0
0,0,0,4,23,23,23,23,4,0,0,0,0,0,0,0
0,0,0,4,0,0,0,23,4,0,0,0,0,0,0,0
0,0,0,4,16,5,0,23,4,0,0,0,0,0,0,0
0,0,0,4,0,18,21,23,4,0,0,0,0,0,0,0
0,0,0,0,4,4,4,4,0,0,0,0,0,0,0,0
0,0,0,0,0,0,0,0,0,0,0,0,0,0,0,0
0,0,0,0,0,0,0,0,0,0,0,0,0,0,0,0
0,0,0,0,0,0,0,0,0,0,0,0,0,0,0,0
0,0,0,0,0,0,0,0,0,0,0,0,0,0,0,0
0,0,0,0,0,0,0,0,0,0,0,0,0,0,0,0
0,0,0,0,0,0,0,0,0,0,0,0,0,0,0,0
0,0,0,0,0,0,0,0,0,0,0,0,0,0,0,0
:endlayer
layer: 13
0,0,0,0,0,0,0,0,0,0,0,0,0,0,0,0
0,0,0,0,0,0,0,0,0,0,0,0,0,0,0,0
0,0,0,0,0,0,0,0,0,0,0,0,0,0,0,0
0,0,0,0,4,4,4,4,0,0,0,0,0,0,0,0
0,0,0,4,23,23,23,23,4,0,0,0,0,0,0,0
0,0,0,4,0,0,0,23,4,0,0,0,0,0,0,0
0,0,0,4,18,5,0,23,4,0,0,0,0,0,0,0
0,0,0,4,21,0,0,23,4,0,0,0,0,0,0,0
0,0,0,0,4,4,4,4,0,0,0,0,0,0,0,0
0,0,0,0,0,0,0,0,0,0,0,0,0,0,0,0
0,0,0,0,0,0,0,0,0,0,0,0,0,0,0,0
0,0,0,0,0,0,0,0,0,0,0,0,0,0,0,0
0,0,0,0,0,0,0,0,0,0,0,0,0,0,0,0
0,0,0,0,0,0,0,0,0,0,0,0,0,0,0,0
0,0,0,0,0,0,0,0,0,0,0,0,0,0,0,0
0,0,0,0,0,0,0,0,0,0,0,0,0,0,0,0
:endlayer
layer: 14
0,0,0,0,0,0,0,0,0,0,0,0,0,0,0,0
0,0,0,0,0,0,0,0,0,0,0,0,0,0,0,0
0,0,0,0,0,30,30,0,0,0,0,0,0,0,0,0
0,0,0,0,4,4,4,4,0,0,0,0,0,0,0,0
0,0,0,4,23,23,23,23,4,0,0,0,0,0,0,0
0,0,32,4,21,18,0,23,4,29,0,0,0,0,0,0
0,0,32,4,0,5,0,23,4,29,0,0,0,0,0,0
0,0,0,4,0,0,0,23,4,0,0,0,0,0,0,0
0,0,0,0,4,4,4,4,0,0,0,0,0,0,0,0
0,0,0,0,0,31,31,0,0,0,0,0,0,0,0,0
0,0,0,0,0,0,0,0,0,0,0,0,0,0,0,0
0,0,0,0,0,0,0,0,0,0,0,0,0,0,0,0
0,0,0,0,0,0,0,0,0,0,0,0,0,0,0,0
0,0,0,0,0,0,0,0,0,0,0,0,0,0,0,0
0,0,0,0,0,0,0,0,0,0,0,0,0,0,0,0
0,0,0,0,0,0,0,0,0,0,0,0,0,0,0,0
:endlayer
layer: 15
0,0,0,0,0,0,0,0,0,0,0,0,0,0,0,0
0,0,0,0,32,34,34,29,0,0,0,0,0,0,0,0
0,0,0,18,30,4,4,30,18,0,0,0,0,0,0,0
0,0,18,32,4,4,4,4,29,18,0,0,0,0,0,0
0,30,32,4,23,23,23,23,4,29,30,0,0,0,0,0
0,36,4,4,0,0,21,23,4,4,33,0,0,0,0,0
0,36,4,4,16,5,18,23,4,4,33,0,0,0,0,0
0,31,32,4,0,0,0,23,4,29,31,0,0,0,0,0
0,0,18,31,4,4,4,4,29,18,0,0,0,0,0,0
0,0,0,18,31,4,4,31,18,0,0,0,0,0,0,0
0,0,0,0,32,35,35,29,0,0,0,0,0,0,0,0
0,0,0,0,0,0,0,0,0,0,0,0,0,0,0,0
0,0,0,0,0,0,0,0,0,0,0,0,0,0,0,0
0,0,0,0,0,0,0,0,0,0,0,0,0,0,0,0
0,0,0,0,0,0,0,0,0,0,0,0,0,0,0,0
0,0,0,0,0,0,0,0,0,0,0,0,0,0,0,0
:endlayer
layer: 16
0,0,0,0,0,0,0,0,0,0,0,0,0,0,0,0
0,0,0,0,5,0,0,5,0,0,0,0,0,0,0,0
0,0,0,0,21,21,21,21,0,0,0,0,0,0,0,0
0,0,0,21,21,21,21,21,21,0,0,0,0,0,0,0
0,5,21,21,21,21,21,21,21,21,5,0,0,0,0,0
0,0,21,21,0,0,0,21,21,21,0,0,0,0,0,0
0,0,21,21,0,5,37,21,21,21,0,0,0,0,0,0
0,5,21,21,21,21,21,21,21,21,5,0,0,0,0,0
0,0,0,21,21,21,21,21,21,0,0,0,0,0,0,0
0,0,0,0,21,21,21,21,0,0,0,0,0,0,0,0
0,0,0,0,5,0,0,5,0,0,0,0,0,0,0,0
0,0,0,0,0,0,0,0,0,0,0,0,0,0,0,0
0,0,0,0,0,0,0,0,0,0,0,0,0,0,0,0
0,0,0,0,0,0,0,0,0,0,0,0,0,0,0,0
0,0,0,0,0,0,0,0,0,0,0,0,0,0,0,0
0,0,0,0,0,0,0,0,0,0,0,0,0,0,0,0
:endlayer
layer: 17
0,0,0,0,0,0,0,0,0,0,0,0,0,0,0,0
0,0,0,0,5,0,0,5,0,0,0,0,0,0,0,0
0,0,0,0,0,0,0,0,0,0,0,0,0,0,0,0
0,0,0,0,0,0,0,0,0,0,0,0,0,0,0,0
0,5,0,0,0,0,0,0,0,0,5,0,0,0,0,0
0,0,0,0,0,0,0,0,0,0,0,0,0,0,0,0
0,0,0,0,0,5,37,0,0,0,0,0,0,0,0,0
0,5,0,0,0,0,0,0,0,0,5,0,0,0,0,0
0,0,0,0,0,0,0,0,0,0,0,0,0,0,0,0
0,0,0,0,0,0,0,0,0,0,0,0,0,0,0,0
0,0,0,0,5,0,0,5,0,0,0,0,0,0,0,0
0,0,0,0,0,0,0,0,0,0,0,0,0,0,0,0
0,0,0,0,0,0,0,0,0,0,0,0,0,0,0,0
0,0,0,0,0,0,0,0,0,0,0,0,0,0,0,0
0,0,0,0,0,0,0,0,0,0,0,0,0,0,0,0
0,0,0,0,0,0,0,0,0,0,0,0,0,0,0,0
:endlayer
layer: 18
0,0,0,0,0,0,0,0,0,0,0,0,0,0,0,0
0,0,0,0,5,39,39,5,0,0,0,0,0,0,0,0
0,0,0,22,15,0,0,15,22,0,0,0,0,0,0,0
0,0,22,0,0,0,0,0,0,22,0,0,0,0,0,0
0,5,12,0,0,0,0,0,0,16,5,0,0,0,0,0
0,41,0,0,0,0,0,0,0,0,38,0,0,0,0,0
0,41,0,0,0,5,37,0,0,0,38,0,0,0,0,0
0,5,12,0,0,0,0,0,0,16,5,0,0,0,0,0
0,0,22,0,0,0,0,0,0,22,0,0,0,0,0,0
0,0,0,22,13,0,0,13,22,0,0,0,0,0,0,0
0,0,0,0,5,40,40,5,0,0,0,0,0,0,0,0
0,0,0,0,0,0,0,0,0,0,0,0,0,0,0,0
0,0,0,0,0,0,0,0,0,0,0,0,0,0,0,0
0,0,0,0,0,0,0,0,0,0,0,0,0,0,0,0
0,0,0,0,0,0,0,0,0,0,0,0,0,0,0,0
0,0,0,0,0,0,0,0,0,0,0,0,0,0,0,0
:endlayer
layer: 19
0,0,0,0,18,18,18,18,0,0,0,0,0,0,0,0
0,0,0,18,5,20,20,5,18,0,0,0,0,0,0,0
0,0,18,23,19,23,23,19,23,18,0,0,0,0,0,0
0,18,23,23,19,23,23,19,23,23,18,0,0,0,0,0
18,5,20,20,20,20,20,20,20,20,5,18,0,0,0,0
18,19,23,23,19,23,23,19,23,23,19,18,0,0,0,0
18,19,23,23,19,5,37,19,23,23,19,18,0,0,0,0
18,5,20,20,20,20,20,20,20,20,5,18,0,0,0,0
0,18,23,23,19,23,23,19,23,23,18,0,0,0,0,0
0,0,18,23,19,23,23,19,23,18,0,0,0,0,0,0
0,0,0,18,5,20,20,5,18,0,0,0,0,0,0,0
0,0,0,0,18,18,18,18,0,0,0,0,0,0,0,0
0,0,0,0,0,0,0,0,0,0,0,0,0,0,0,0
0,0,0,0,0,0,0,0,0,0,0,0,0,0,0,0
0,0,0,0,0,0,0,0,0,0,0,0,0,0,0,0
0,0,0,0,0,0,0,0,0,0,0,0,0,0,0,0
:endlayer
layer: 20
0,0,0,0,0,0,0,0,0,0,0,0,0,0,0,0
0,0,0,0,21,21,21,21,0,0,0,0,0,0,0,0
0,0,0,21,23,23,23,23,21,0,0,0,0,0,0,0
0,0,21,23,23,23,23,23,23,21,0,0,0,0,0,0
0,21,23,23,23,23,23,23,23,23,21,0,0,0,0,0
0,21,23,23,23,23,23,23,23,23,21,0,0,0,0,0
0,21,23,23,23,5,37,23,23,23,21,0,0,0,0,0
0,21,23,23,23,23,23,23,23,23,21,0,0,0,0,0
0,0,21,23,23,23,23,23,23,21,0,0,0,0,0,0
0,0,0,21,23,23,23,23,21,0,0,0,0,0,0,0
0,0,0,0,21,21,21,21,0,0,0,0,0,0,0,0
0,0,0,0,0,0,0,0,0,0,0,0,0,0,0,0
0,0,0,0,0,0,0,0,0,0,0,0,0,0,0,0
0,0,0,0,0,0,0,0,0,0,0,0,0,0,0,0
0,0,0,0,0,0,0,0,0,0,0,0,0,0,0,0
0,0,0,0,0,0,0,0,0,0,0,0,0,0,0,0
:endlayer
layer: 21
0,0,0,0,0,0,0,0,0,0,0,0,0,0,0,0
0,0,0,0,0,0,0,0,0,0,0,0,0,0,0,0
0,0,0,0,0,0,0,0,0,0,0,0,0,0,0,0
0,0,0,24,21,21,21,21,24,0,0,0,0,0,0,0
0,0,0,21,23,23,23,23,21,0,0,0,0,0,0,0
0,0,0,21,23,23,23,23,21,0,0,0,0,0,0,0
0,0,0,21,23,5,37,23,21,0,0,0,0,0,0,0
0,0,0,21,23,23,23,23,21,0,0,0,0,0,0,0
0,0,0,24,21,21,21,21,24,0,0,0,0,0,0,0
0,0,0,0,0,0,0,0,0,0,0,0,0,0,0,0
0,0,0,0,0,0,0,0,0,0,0,0,0,0,0,0
0,0,0,0,0,0,0,0,0,0,0,0,0,0,0,0
0,0,0,0,0,0,0,0,0,0,0,0,0,0,0,0
0,0,0,0,0,0,0,0,0,0,0,0,0,0,0,0
0,0,0,0,0,0,0,0,0,0,0,0,0,0,0,0
0,0,0,0,0,0,0,0,0,0,0,0,0,0,0,0
:endlayer
layer: 22
0,0,0,0,0,0,0,0,0,0,0,0,0,0,0,0
0,0,0,0,0,0,0,0,0,0,0,0,0,0,0,0
0,0,0,0,0,0,0,0,0,0,0,0,0,0,0,0
0,0,0,0,0,0,0,0,0,0,0,0,0,0,0,0
0,0,0,0,0,0,0,0,0,0,0,0,0,0,0,0
0,0,0,0,0,21,21,0,0,0,0,0,0,0,0,0
0,0,0,0,0,5,42,0,0,0,0,0,0,0,0,0
0,0,0,0,0,0,0,0,0,0,0,0,0,0,0,0
0,0,0,0,0,0,0,0,0,0,0,0,0,0,0,0
0,0,0,0,0,0,0,0,0,0,0,0,0,0,0,0
0,0,0,0,0,0,0,0,0,0,0,0,0,0,0,0
0,0,0,0,0,0,0,0,0,0,0,0,0,0,0,0
0,0,0,0,0,0,0,0,0,0,0,0,0,0,0,0
0,0,0,0,0,0,0,0,0,0,0,0,0,0,0,0
0,0,0,0,0,0,0,0,0,0,0,0,0,0,0,0
0,0,0,0,0,0,0,0,0,0,0,0,0,0,0,0
:endlayer
layer: 23
0,0,0,0,0,0,0,0,0,0,0,0,0,0,0,0
0,0,0,0,0,0,0,0,0,0,0,0,0,0,0,0
0,0,0,0,0,0,0,0,0,0,0,0,0,0,0,0
0,0,0,0,0,0,0,0,0,0,0,0,0,0,0,0
0,0,0,0,0,0,0,0,0,0,0,0,0,0,0,0
0,0,0,0,0,0,0,0,0,0,0,0,0,0,0,0
0,0,0,0,0,5,0,0,0,0,0,0,0,0,0,0
0,0,0,0,0,0,0,0,0,0,0,0,0,0,0,0
0,0,0,0,0,0,0,0,0,0,0,0,0,0,0,0
0,0,0,0,0,0,0,0,0,0,0,0,0,0,0,0
0,0,0,0,0,0,0,0,0,0,0,0,0,0,0,0
0,0,0,0,0,0,0,0,0,0,0,0,0,0,0,0
0,0,0,0,0,0,0,0,0,0,0,0,0,0,0,0
0,0,0,0,0,0,0,0,0,0,0,0,0,0,0,0
0,0,0,0,0,0,0,0,0,0,0,0,0,0,0,0
0,0,0,0,0,0,0,0,0,0,0,0,0,0,0,0
:endlayer
layer: 24
0,0,0,0,0,0,0,0,0,0,0,0,0,0,0,0
0,0,0,0,0,0,0,0,0,0,0,0,0,0,0,0
0,0,0,0,0,0,0,0,0,0,0,0,0,0,0,0
0,0,0,0,0,0,0,0,0,0,0,0,0,0,0,0
0,0,0,0,0,0,0,0,0,0,0,0,0,0,0,0
0,0,0,0,0,0,0,0,0,0,0,0,0,0,0,0
0,0,0,0,0,5,0,0,0,0,0,0,0,0,0,0
0,0,0,0,0,0,0,0,0,0,0,0,0,0,0,0
0,0,0,0,0,0,0,0,0,0,0,0,0,0,0,0
0,0,0,0,0,0,0,0,0,0,0,0,0,0,0,0
0,0,0,0,0,0,0,0,0,0,0,0,0,0,0,0
0,0,0,0,0,0,0,0,0,0,0,0,0,0,0,0
0,0,0,0,0,0,0,0,0,0,0,0,0,0,0,0
0,0,0,0,0,0,0,0,0,0,0,0,0,0,0,0
0,0,0,0,0,0,0,0,0,0,0,0,0,0,0,0
0,0,0,0,0,0,0,0,0,0,0,0,0,0,0,0
:endlayer
layer: 25
0,0,0,0,0,0,0,0,0,0,0,0,0,0,0,0
0,0,0,0,0,0,0,0,0,0,0,0,0,0,0,0
0,0,0,0,0,0,0,0,0,0,0,0,0,0,0,0
0,0,0,0,0,0,0,0,0,0,0,0,0,0,0,0
0,0,0,0,0,0,0,0,0,0,0,0,0,0,0,0
0,0,0,0,0,0,0,0,0,0,0,0,0,0,0,0
0,0,0,0,0,5,0,0,0,0,0,0,0,0,0,0
0,0,0,0,0,0,0,0,0,0,0,0,0,0,0,0
0,0,0,0,0,0,0,0,0,0,0,0,0,0,0,0
0,0,0,0,0,0,0,0,0,0,0,0,0,0,0,0
0,0,0,0,0,0,0,0,0,0,0,0,0,0,0,0
0,0,0,0,0,0,0,0,0,0,0,0,0,0,0,0
0,0,0,0,0,0,0,0,0,0,0,0,0,0,0,0
0,0,0,0,0,0,0,0,0,0,0,0,0,0,0,0
0,0,0,0,0,0,0,0,0,0,0,0,0,0,0,0
0,0,0,0,0,0,0,0,0,0,0,0,0,0,0,0
:endlayer
layer: 26
0,0,0,0,0,0,0,0,0,0,0,0,0,0,0,0
0,0,0,0,0,0,0,0,0,0,0,0,0,0,0,0
0,0,0,0,0,0,0,0,0,0,0,0,0,0,0,0
0,0,0,0,0,0,0,0,0,0,0,0,0,0,0,0
0,0,0,0,0,0,0,0,0,0,0,0,0,0,0,0
0,0,0,0,0,0,0,0,0,0,0,0,0,0,0,0
0,0,0,0,0,43,0,0,0,0,0,0,0,0,0,0
0,0,0,0,0,0,0,0,0,0,0,0,0,0,0,0
0,0,0,0,0,0,0,0,0,0,0,0,0,0,0,0
0,0,0,0,0,0,0,0,0,0,0,0,0,0,0,0
0,0,0,0,0,0,0,0,0,0,0,0,0,0,0,0
0,0,0,0,0,0,0,0,0,0,0,0,0,0,0,0
0,0,0,0,0,0,0,0,0,0,0,0,0,0,0,0
0,0,0,0,0,0,0,0,0,0,0,0,0,0,0,0
0,0,0,0,0,0,0,0,0,0,0,0,0,0,0,0
0,0,0,0,0,0,0,0,0,0,0,0,0,0,0,0
:endlayer
layer: 27
0,0,0,0,0,0,0,0,0,0,0,0,0,0,0,0
0,0,0,0,0,0,0,0,0,0,0,0,0,0,0,0
0,0,0,0,0,0,0,0,0,0,0,0,0,0,0,0
0,0,0,0,0,0,0,0,0,0,0,0,0,0,0,0
0,0,0,0,0,0,0,0,0,0,0,0,0,0,0,0
0,0,0,0,0,0,0,0,0,0,0,0,0,0,0,0
0,0,0,0,0,43,0,0,0,0,0,0,0,0,0,0
0,0,0,0,0,0,0,0,0,0,0,0,0,0,0,0
0,0,0,0,0,0,0,0,0,0,0,0,0,0,0,0
0,0,0,0,0,0,0,0,0,0,0,0,0,0,0,0
0,0,0,0,0,0,0,0,0,0,0,0,0,0,0,0
0,0,0,0,0,0,0,0,0,0,0,0,0,0,0,0
0,0,0,0,0,0,0,0,0,0,0,0,0,0,0,0
0,0,0,0,0,0,0,0,0,0,0,0,0,0,0,0
0,0,0,0,0,0,0,0,0,0,0,0,0,0,0,0
0,0,0,0,0,0,0,0,0,0,0,0,0,0,0,0
:endlayer
layer: 28
0,0,0,0,0,0,0,0,0,0,0,0,0,0,0,0
0,0,0,0,0,0,0,0,0,0,0,0,0,0,0,0
0,0,0,0,0,0,0,0,0,0,0,0,0,0,0,0
0,0,0,0,0,0,0,0,0,0,0,0,0,0,0,0
0,0,0,0,0,0,0,0,0,0,0,0,0,0,0,0
0,0,0,0,0,0,0,0,0,0,0,0,0,0,0,0
0,0,0,0,0,43,0,0,0,0,0,0,0,0,0,0
0,0,0,0,0,0,0,0,0,0,0,0,0,0,0,0
0,0,0,0,0,0,0,0,0,0,0,0,0,0,0,0
0,0,0,0,0,0,0,0,0,0,0,0,0,0,0,0
0,0,0,0,0,0,0,0,0,0,0,0,0,0,0,0
0,0,0,0,0,0,0,0,0,0,0,0,0,0,0,0
0,0,0,0,0,0,0,0,0,0,0,0,0,0,0,0
0,0,0,0,0,0,0,0,0,0,0,0,0,0,0,0
0,0,0,0,0,0,0,0,0,0,0,0,0,0,0,0
0,0,0,0,0,0,0,0,0,0,0,0,0,0,0,0
:endlayer
layer: 29
0,0,0,0,0,0,0,0,0,0,0,0,0,0,0,0
0,0,0,0,0,0,0,0,0,0,0,0,0,0,0,0
0,0,0,0,0,0,0,0,0,0,0,0,0,0,0,0
0,0,0,0,0,0,0,0,0,0,0,0,0,0,0,0
0,0,0,0,0,0,0,0,0,0,0,0,0,0,0,0
0,0,0,0,0,0,0,0,0,0,0,0,0,0,0,0
0,0,0,0,0,43,0,0,0,0,0,0,0,0,0,0
0,0,0,0,0,0,0,0,0,0,0,0,0,0,0,0
0,0,0,0,0,0,0,0,0,0,0,0,0,0,0,0
0,0,0,0,0,0,0,0,0,0,0,0,0,0,0,0
0,0,0,0,0,0,0,0,0,0,0,0,0,0,0,0
0,0,0,0,0,0,0,0,0,0,0,0,0,0,0,0
0,0,0,0,0,0,0,0,0,0,0,0,0,0,0,0
0,0,0,0,0,0,0,0,0,0,0,0,0,0,0,0
0,0,0,0,0,0,0,0,0,0,0,0,0,0,0,0
0,0,0,0,0,0,0,0,0,0,0,0,0,0,0,0
:endlayer
layer: 30
0,0,0,0,0,0,0,0,0,0,0,0,0,0,0,0
0,0,0,0,0,0,0,0,0,0,0,0,0,0,0,0
0,0,0,0,0,0,0,0,0,0,0,0,0,0,0,0
0,0,0,0,0,0,0,0,0,0,0,0,0,0,0,0
0,0,0,0,0,0,0,0,0,0,0,0,0,0,0,0
0,0,0,0,0,0,0,0,0,0,0,0,0,0,0,0
0,0,0,0,0,43,0,0,0,0,0,0,0,0,0,0
0,0,0,0,0,0,0,0,0,0,0,0,0,0,0,0
0,0,0,0,0,0,0,0,0,0,0,0,0,0,0,0
0,0,0,0,0,0,0,0,0,0,0,0,0,0,0,0
0,0,0,0,0,0,0,0,0,0,0,0,0,0,0,0
0,0,0,0,0,0,0,0,0,0,0,0,0,0,0,0
0,0,0,0,0,0,0,0,0,0,0,0,0,0,0,0
0,0,0,0,0,0,0,0,0,0,0,0,0,0,0,0
0,0,0,0,0,0,0,0,0,0,0,0,0,0,0,0
0,0,0,0,0,0,0,0,0,0,0,0,0,0,0,0
:endlayer

#### RULES ####
rule:
plugin=vanillaBlocks
number=1
data:
JSON:{blockState:{blockName:"minecraft:grass",properties:{snowy:"false"}}}
:enddata
:endrule

rule:
plugin=vanillaBlocks
number=2
data:
JSON:{blockState:{blockName:"minecraft:dirt",properties:{variant:"dirt",snowy:"false"}}}
:enddata
:endrule

rule:
plugin=vanillaBlocks
number=3
data:
JSON:{blockState:{blockName:"minecraft:cobblestone"}}
:enddata
:endrule

rule:
plugin=vanillaBlocks
number=4
data:
JSON:{blockState:{blockName:"minecraft:stonebrick",properties:{variant:"stonebrick"}}}
:enddata
:endrule

rule:
plugin=vanillaBlocks
number=5
data:
JSON:{blockState:{blockName:"minecraft:log",properties:{variant:"oak",axis:"y"}}}
:enddata
:endrule

rule:
plugin=doors
number=6
data:
JSON:{blockState:{blockName:"minecraft:wooden_door",properties:{hinge:"left",half:"lower",powered:"false",facing:"west",open:"true"}}}
:enddata
:endrule

rule:
plugin=doors
number=7
data:
JSON:{blockState:{blockName:"minecraft:wooden_door",properties:{hinge:"left",half:"lower",powered:"false",facing:"north",open:"false"}}}
:enddata
:endrule

rule:
plugin=vanillaBlocks
number=8
data:
JSON:{blockState:{blockName:"minecraft:stone_slab",properties:{half:"bottom",variant:"stone_brick"}}}
:enddata
:endrule

rule:
plugin=vanillaBlocks
number=9
data:
JSON:{blockState:{blockName:"minecraft:fence",properties:{east:"false",south:"false",north:"false",west:"false"}}}
:enddata
:endrule

rule:
plugin=vanillaBlocks
number=10
data:
JSON:{blockState:{blockName:"minecraft:stone_slab",properties:{half:"top",variant:"stone_brick"}}}
:enddata
:endrule

rule:
plugin=vanillaBlocks
number=11
data:
JSON:{blockState:{blockName:"minecraft:fence_gate",properties:{in_wall:"false",powered:"false",facing:"north",open:"false"}}}
:enddata
:endrule

rule:
plugin=vanillaBlocks
number=12
data:
JSON:{blockState:{blockName:"minecraft:torch",properties:{facing:"east"}}}
:enddata
:endrule

rule:
plugin=vanillaBlocks
number=13
data:
JSON:{blockState:{blockName:"minecraft:torch",properties:{facing:"north"}}}
:enddata
:endrule

rule:
plugin=vanillaBlocks
number=14
data:
JSON:{blockState:{blockName:"minecraft:stained_glass_pane",properties:{east:"false",color:"green",south:"false",north:"false",west:"false"}}}
:enddata
:endrule

rule:
plugin=vanillaBlocks
number=15
data:
JSON:{blockState:{blockName:"minecraft:torch",properties:{facing:"south"}}}
:enddata
:endrule

rule:
plugin=vanillaBlocks
number=16
data:
JSON:{blockState:{blockName:"minecraft:torch",properties:{facing:"west"}}}
:enddata
:endrule

rule:
plugin=doors
number=17
data:
JSON:{blockState:{blockName:"minecraft:wooden_door",properties:{hinge:"left",half:"upper",powered:"false",facing:"east",open:"false"}}}
:enddata
:endrule

rule:
plugin=vanillaBlocks
number=18
data:
JSON:{blockState:{blockName:"minecraft:wooden_slab",properties:{half:"top",variant:"oak"}}}
:enddata
:endrule

rule:
plugin=vanillaBlocks
number=19
data:
JSON:{blockState:{blockName:"minecraft:log",properties:{variant:"oak",axis:"z"}}}
:enddata
:endrule

rule:
plugin=vanillaBlocks
number=20
data:
JSON:{blockState:{blockName:"minecraft:log",properties:{variant:"oak",axis:"x"}}}
:enddata
:endrule

rule:
plugin=vanillaBlocks
number=21
data:
JSON:{blockState:{blockName:"minecraft:wooden_slab",properties:{half:"bottom",variant:"oak"}}}
:enddata
:endrule

rule:
plugin=vanillaBlocks
number=22
data:
JSON:{blockState:{blockName:"minecraft:double_wooden_slab",properties:{variant:"oak"}}}
:enddata
:endrule

rule:
plugin=vanillaBlocks
number=23
data:
JSON:{blockState:{blockName:"minecraft:planks",properties:{variant:"oak"}}}
:enddata
:endrule

rule:
plugin=vanillaBlocks
number=24
data:
JSON:{blockState:{blockName:"minecraft:torch",properties:{facing:"up"}}}
:enddata
:endrule

rule:
plugin=vanillaBlocks
number=25
data:
JSON:{blockState:{blockName:"minecraft:stone_brick_stairs",properties:{half:"bottom",shape:"straight",facing:"south"}}}
:enddata
:endrule

rule:
plugin=vanillaBlocks
number=26
data:
JSON:{blockState:{blockName:"minecraft:stone_brick_stairs",properties:{half:"bottom",shape:"straight",facing:"west"}}}
:enddata
:endrule

rule:
plugin=vanillaBlocks
number=27
data:
JSON:{blockState:{blockName:"minecraft:stone_brick_stairs",properties:{half:"bottom",shape:"straight",facing:"north"}}}
:enddata
:endrule

rule:
plugin=vanillaBlocks
number=28
data:
JSON:{blockState:{blockName:"minecraft:stone_brick_stairs",properties:{half:"bottom",shape:"straight",facing:"east"}}}
:enddata
:endrule

rule:
plugin=vanillaBlocks
number=29
data:
JSON:{blockState:{blockName:"minecraft:stone_brick_stairs",properties:{half:"top",shape:"straight",facing:"west"}}}
:enddata
:endrule

rule:
plugin=vanillaBlocks
number=30
data:
JSON:{blockState:{blockName:"minecraft:stone_brick_stairs",properties:{half:"top",shape:"straight",facing:"south"}}}
:enddata
:endrule

rule:
plugin=vanillaBlocks
number=31
data:
JSON:{blockState:{blockName:"minecraft:stone_brick_stairs",properties:{half:"top",shape:"straight",facing:"north"}}}
:enddata
:endrule

rule:
plugin=vanillaBlocks
number=32
data:
JSON:{blockState:{blockName:"minecraft:stone_brick_stairs",properties:{half:"top",shape:"straight",facing:"east"}}}
:enddata
:endrule

rule:
plugin=vanillaBlocks
number=33
data:
JSON:{blockState:{blockName:"minecraft:oak_stairs",properties:{half:"bottom",shape:"straight",facing:"west"}}}
:enddata
:endrule

rule:
plugin=vanillaBlocks
number=34
data:
JSON:{blockState:{blockName:"minecraft:oak_stairs",properties:{half:"bottom",shape:"straight",facing:"south"}}}
:enddata
:endrule

rule:
plugin=vanillaBlocks
number=35
data:
JSON:{blockState:{blockName:"minecraft:oak_stairs",properties:{half:"bottom",shape:"straight",facing:"north"}}}
:enddata
:endrule

rule:
plugin=vanillaBlocks
number=36
data:
JSON:{blockState:{blockName:"minecraft:oak_stairs",properties:{half:"bottom",shape:"straight",facing:"east"}}}
:enddata
:endrule

rule:
plugin=vanillaBlocks
number=37
data:
JSON:{blockState:{blockName:"minecraft:ladder",properties:{facing:"east"}}}
:enddata
:endrule

rule:
plugin=vanillaBlocks
number=38
data:
JSON:{blockState:{blockName:"minecraft:oak_stairs",properties:{half:"top",shape:"straight",facing:"west"}}}
:enddata
:endrule

rule:
plugin=vanillaBlocks
number=39
data:
JSON:{blockState:{blockName:"minecraft:oak_stairs",properties:{half:"top",shape:"straight",facing:"south"}}}
:enddata
:endrule

rule:
plugin=vanillaBlocks
number=40
data:
JSON:{blockState:{blockName:"minecraft:oak_stairs",properties:{half:"top",shape:"straight",facing:"north"}}}
:enddata
:endrule

rule:
plugin=vanillaBlocks
number=41
data:
JSON:{blockState:{blockName:"minecraft:oak_stairs",properties:{half:"top",shape:"straight",facing:"east"}}}
:enddata
:endrule

rule:
plugin=vanillaBlocks
number=42
data:
JSON:{blockState:{blockName:"minecraft:trapdoor",properties:{half:"bottom",facing:"east",open:"false"}}}
:enddata
:endrule

rule:
plugin=vanillaBlocks
number=43
data:
JSON:{blockState:{blockName:"minecraft:birch_fence",properties:{east:"false",south:"false",north:"false",west:"false"}}}
:enddata
:endrule

#### ENTITIES ####
