# Ancient Warfare Structure Template File
# Auto-generated structure template file. created on: 2/24/2024 at: 23:40:39
# Lines beginning with # denote comments

header:
version=2.11
name=NoggLeviathanBattleshipTheSeaGuardian
mods=
size=19,53,63
offset=9,3,44
:endheader

#### VALIDATION ####
validation:
type=water
structureAuthor=TheOddlySeagull
survival=false
worldGenEnabled=true
unique=false
preserveBlocks=false
preventNaturalHostileSpawns=true
selectionWeight=5
clusterValue=60
minDuplicateDistance=20000
dimensionWhiteList=true
dimensionList=0
biomeGroupList=
biomeWhiteList=true
biomeList=minecraft:deep_ocean
leveling=0
fill=0
border=0
blockSwap=false
territoryName=noggfleet
biomeReplacement=minecraft:
:endvalidation

#### LAYERS ####
layer: 0
1,1,1,1,1,1,1,1,1,1,1,1,1,1,1,1,1,1,1
1,1,1,1,1,1,1,1,1,1,1,1,1,1,1,1,1,1,1
1,1,1,1,1,1,1,1,1,1,1,1,1,1,1,1,1,1,1
1,1,1,1,1,1,1,1,1,1,1,1,1,1,1,1,1,1,1
1,1,1,1,1,1,1,1,1,1,1,1,1,1,1,1,1,1,1
1,1,1,1,1,1,1,1,1,1,1,1,1,1,1,1,1,1,1
1,1,1,1,1,1,1,1,1,1,1,1,1,1,1,1,1,1,1
1,1,1,1,1,1,1,1,1,1,1,1,1,1,1,1,1,1,1
1,1,1,1,1,1,1,1,1,2,1,1,1,1,1,1,1,1,1
1,1,1,1,1,1,1,1,1,2,1,1,1,1,1,1,1,1,1
1,1,1,1,1,1,1,1,1,2,1,1,1,1,1,1,1,1,1
1,1,1,1,1,1,1,1,1,2,1,1,1,1,1,1,1,1,1
1,1,1,1,1,1,1,1,1,2,1,1,1,1,1,1,1,1,1
1,1,1,1,1,1,1,1,1,2,1,1,1,1,1,1,1,1,1
1,1,1,1,1,1,1,1,1,2,1,1,1,1,1,1,1,1,1
1,1,1,1,1,1,1,1,1,2,1,1,1,1,1,1,1,1,1
1,1,1,1,1,1,1,1,1,2,1,1,1,1,1,1,1,1,1
1,1,1,1,1,1,1,1,1,2,1,1,1,1,1,1,1,1,1
1,1,1,1,1,1,1,1,1,2,1,1,1,1,1,1,1,1,1
1,1,1,1,1,1,1,1,1,2,1,1,1,1,1,1,1,1,1
1,1,1,1,1,1,1,1,1,2,1,1,1,1,1,1,1,1,1
1,1,1,1,1,1,1,1,1,2,1,1,1,1,1,1,1,1,1
1,1,1,1,1,1,1,1,1,2,1,1,1,1,1,1,1,1,1
1,1,1,1,1,1,1,1,1,2,1,1,1,1,1,1,1,1,1
1,1,1,1,1,1,1,1,1,2,1,1,1,1,1,1,1,1,1
1,1,1,1,1,1,1,1,1,2,1,1,1,1,1,1,1,1,1
1,1,1,1,1,1,1,1,1,2,1,1,1,1,1,1,1,1,1
1,1,1,1,1,1,1,1,1,2,1,1,1,1,1,1,1,1,1
1,1,1,1,1,1,1,1,1,2,1,1,1,1,1,1,1,1,1
1,1,1,1,1,1,1,1,1,2,1,1,1,1,1,1,1,1,1
1,1,1,1,1,1,1,1,1,2,1,1,1,1,1,1,1,1,1
1,1,1,1,1,1,1,1,1,2,1,1,1,1,1,1,1,1,1
1,1,1,1,1,1,1,1,1,2,1,1,1,1,1,1,1,1,1
1,1,1,1,1,1,1,1,1,2,1,1,1,1,1,1,1,1,1
1,1,1,1,1,1,1,1,1,2,1,1,1,1,1,1,1,1,1
1,1,1,1,1,1,1,1,1,2,1,1,1,1,1,1,1,1,1
1,1,1,1,1,1,1,1,1,2,1,1,1,1,1,1,1,1,1
1,1,1,1,1,1,1,1,1,2,1,1,1,1,1,1,1,1,1
1,1,1,1,1,1,1,1,1,1,1,1,1,1,1,1,1,1,1
1,1,1,1,1,1,1,1,1,1,1,1,1,1,1,1,1,1,1
1,1,1,1,1,1,1,1,1,1,1,1,1,1,1,1,1,1,1
1,1,1,1,1,1,1,1,1,1,1,1,1,1,1,1,1,1,1
1,1,1,1,1,1,1,1,1,1,1,1,1,1,1,1,1,1,1
1,1,1,1,1,1,1,1,1,1,1,1,1,1,1,1,1,1,1
1,1,1,1,1,1,1,1,1,1,1,1,1,1,1,1,1,1,1
1,1,1,1,1,1,1,1,1,1,1,1,1,1,1,1,1,1,1
1,1,1,1,1,1,1,1,1,1,1,1,1,1,1,1,1,1,1
1,1,1,1,1,1,1,1,1,1,1,1,1,1,1,1,1,1,1
1,1,1,1,1,1,1,1,1,1,1,1,1,1,1,1,1,1,1
1,1,1,1,1,1,1,1,1,1,1,1,1,1,1,1,1,1,1
1,1,1,1,1,1,1,1,1,1,1,1,1,1,1,1,1,1,1
1,1,1,1,1,1,1,1,1,1,1,1,1,1,1,1,1,1,1
1,1,1,1,1,1,1,1,1,1,1,1,1,1,1,1,1,1,1
1,1,1,1,1,1,1,1,1,1,1,1,1,1,1,1,1,1,1
1,1,1,1,1,1,1,1,1,1,1,1,1,1,1,1,1,1,1
1,1,1,1,1,1,1,1,1,1,1,1,1,1,1,1,1,1,1
1,1,1,1,1,1,1,1,1,1,1,1,1,1,1,1,1,1,1
1,1,1,1,1,1,1,1,1,1,1,1,1,1,1,1,1,1,1
1,1,1,1,1,1,1,1,1,1,1,1,1,1,1,1,1,1,1
1,1,1,1,1,1,1,1,1,1,1,1,1,1,1,1,1,1,1
1,1,1,1,1,1,1,1,1,1,1,1,1,1,1,1,1,1,1
1,1,1,1,1,1,1,1,1,1,1,1,1,1,1,1,1,1,1
1,1,1,1,1,1,1,1,1,1,1,1,1,1,1,1,1,1,1
:endlayer
layer: 1
1,1,1,1,1,1,1,1,1,1,1,1,1,1,1,1,1,1,1
1,1,1,1,1,1,1,1,1,1,1,1,1,1,1,1,1,1,1
1,1,1,1,1,1,1,1,1,1,1,1,1,1,1,1,1,1,1
1,1,1,1,1,1,1,1,1,1,1,1,1,1,1,1,1,1,1
1,1,1,1,1,1,1,1,1,1,1,1,1,1,1,1,1,1,1
1,1,1,1,1,1,1,1,1,1,1,1,1,1,1,1,1,1,1
1,1,1,1,1,1,1,1,1,1,1,1,1,1,1,1,1,1,1
1,1,1,1,1,1,1,1,1,1,1,1,1,1,1,1,1,1,1
1,1,1,1,1,1,1,1,1,2,1,1,1,1,1,1,1,1,1
1,1,1,1,1,1,1,1,2,2,2,1,1,1,1,1,1,1,1
1,1,1,1,1,1,1,2,2,2,2,2,1,1,1,1,1,1,1
1,1,1,1,1,1,1,2,2,2,2,2,1,1,1,1,1,1,1
1,1,1,1,1,1,1,2,2,2,2,2,1,1,1,1,1,1,1
1,1,1,1,1,1,1,2,2,2,2,2,1,1,1,1,1,1,1
1,1,1,1,1,1,1,2,2,2,2,2,1,1,1,1,1,1,1
1,1,1,1,1,1,1,2,2,2,2,2,1,1,1,1,1,1,1
1,1,1,1,1,1,1,2,2,2,2,2,1,1,1,1,1,1,1
1,1,1,1,1,1,1,2,2,2,2,2,1,1,1,1,1,1,1
1,1,1,1,1,1,1,2,2,2,2,2,1,1,1,1,1,1,1
1,1,1,1,1,1,1,2,2,2,2,2,1,1,1,1,1,1,1
1,1,1,1,1,1,1,2,2,2,2,2,1,1,1,1,1,1,1
1,1,1,1,1,1,1,2,2,2,2,2,1,1,1,1,1,1,1
1,1,1,1,1,1,1,2,2,2,2,2,1,1,1,1,1,1,1
1,1,1,1,1,1,1,2,2,2,2,2,1,1,1,1,1,1,1
1,1,1,1,1,1,1,2,2,2,2,2,1,1,1,1,1,1,1
1,1,1,1,1,1,1,2,2,2,2,2,1,1,1,1,1,1,1
1,1,1,1,1,1,1,2,2,2,2,2,1,1,1,1,1,1,1
1,1,1,1,1,1,1,2,2,2,2,2,1,1,1,1,1,1,1
1,1,1,1,1,1,1,2,2,2,2,2,1,1,1,1,1,1,1
1,1,1,1,1,1,1,2,2,2,2,2,1,1,1,1,1,1,1
1,1,1,1,1,1,1,2,2,2,2,2,1,1,1,1,1,1,1
1,1,1,1,1,1,1,2,2,2,2,2,1,1,1,1,1,1,1
1,1,1,1,1,1,1,2,2,2,2,2,1,1,1,1,1,1,1
1,1,1,1,1,1,1,2,2,2,2,2,1,1,1,1,1,1,1
1,1,1,1,1,1,1,2,2,2,2,2,1,1,1,1,1,1,1
1,1,1,1,1,1,1,2,2,2,2,2,1,1,1,1,1,1,1
1,1,1,1,1,1,1,1,2,2,2,1,1,1,1,1,1,1,1
1,1,1,1,1,1,1,1,2,2,2,1,1,1,1,1,1,1,1
1,1,1,1,1,1,1,1,1,2,1,1,1,1,1,1,1,1,1
1,1,1,1,1,1,1,1,1,2,1,1,1,1,1,1,1,1,1
1,1,1,1,1,1,1,1,1,1,1,1,1,1,1,1,1,1,1
1,1,1,1,1,1,1,1,1,1,1,1,1,1,1,1,1,1,1
1,1,1,1,1,1,1,1,1,1,1,1,1,1,1,1,1,1,1
1,1,1,1,1,1,1,1,1,1,1,1,1,1,1,1,1,1,1
1,1,1,1,1,1,1,1,1,1,1,1,1,1,1,1,1,1,1
1,1,1,1,1,1,1,1,1,1,1,1,1,1,1,1,1,1,1
1,1,1,1,1,1,1,1,1,1,1,1,1,1,1,1,1,1,1
1,1,1,1,1,1,1,1,1,1,1,1,1,1,1,1,1,1,1
1,1,1,1,1,1,1,1,1,1,1,1,1,1,1,1,1,1,1
1,1,1,1,1,1,1,1,1,1,1,1,1,1,1,1,1,1,1
1,1,1,1,1,1,1,1,1,1,1,1,1,1,1,1,1,1,1
1,1,1,1,1,1,1,1,1,1,1,1,1,1,1,1,1,1,1
1,1,1,1,1,1,1,1,1,1,1,1,1,1,1,1,1,1,1
1,1,1,1,1,1,1,1,1,1,1,1,1,1,1,1,1,1,1
1,1,1,1,1,1,1,1,1,1,1,1,1,1,1,1,1,1,1
1,1,1,1,1,1,1,1,1,1,1,1,1,1,1,1,1,1,1
1,1,1,1,1,1,1,1,1,1,1,1,1,1,1,1,1,1,1
1,1,1,1,1,1,1,1,1,1,1,1,1,1,1,1,1,1,1
1,1,1,1,1,1,1,1,1,1,1,1,1,1,1,1,1,1,1
1,1,1,1,1,1,1,1,1,1,1,1,1,1,1,1,1,1,1
1,1,1,1,1,1,1,1,1,1,1,1,1,1,1,1,1,1,1
1,1,1,1,1,1,1,1,1,1,1,1,1,1,1,1,1,1,1
1,1,1,1,1,1,1,1,1,1,1,1,1,1,1,1,1,1,1
:endlayer
layer: 2
1,1,1,1,1,1,1,1,1,1,1,1,1,1,1,1,1,1,1
1,1,1,1,1,1,1,1,1,1,1,1,1,1,1,1,1,1,1
1,1,1,1,1,1,1,1,1,1,1,1,1,1,1,1,1,1,1
1,1,1,1,1,1,1,1,1,1,1,1,1,1,1,1,1,1,1
1,1,1,1,1,1,1,1,1,1,1,1,1,1,1,1,1,1,1
1,1,1,1,1,1,1,1,1,1,1,1,1,1,1,1,1,1,1
1,1,1,1,1,1,1,1,1,1,1,1,1,1,1,1,1,1,1
1,1,1,1,1,1,1,1,1,1,1,1,1,1,1,1,1,1,1
1,1,1,1,1,1,1,1,1,2,1,1,1,1,1,1,1,1,1
1,1,1,1,1,1,1,2,2,2,2,2,1,1,1,1,1,1,1
1,1,1,1,1,1,2,45,34,2,16,5,2,1,1,1,1,1,1
1,1,1,1,1,1,2,46,35,0,0,6,2,1,1,1,1,1,1
1,1,1,1,1,1,2,47,0,27,17,7,2,1,1,1,1,1,1
1,1,1,1,1,1,2,0,36,6,18,8,2,1,1,1,1,1,1
1,1,1,1,1,1,2,0,37,28,19,9,2,1,1,1,1,1,1
1,1,1,1,1,1,2,13,2,2,2,2,2,1,1,1,1,1,1
1,1,1,1,1,1,2,0,12,0,0,10,2,1,1,1,1,1,1
1,1,1,1,1,1,2,48,38,0,20,0,2,1,1,1,1,1,1
1,1,1,1,1,1,2,0,12,0,0,11,2,1,1,1,1,1,1
1,1,1,1,1,1,2,13,2,29,2,2,2,1,1,1,1,1,1
1,1,1,1,1,1,23,0,12,0,0,11,3,1,1,1,1,1,1
1,1,1,1,1,1,23,0,39,0,21,0,3,1,1,1,1,1,1
1,1,1,1,1,1,2,0,12,0,0,10,2,1,1,1,1,1,1
1,1,1,1,1,1,23,0,12,30,0,0,3,1,1,1,1,1,1
1,1,1,1,1,1,2,0,12,12,22,12,2,1,1,1,1,1,1
1,1,1,1,1,1,23,0,0,31,0,0,3,1,1,1,1,1,1
1,1,1,1,1,1,23,49,0,11,11,0,3,1,1,1,1,1,1
1,1,1,1,1,1,2,11,40,2,2,13,2,1,1,1,1,1,1
1,1,1,1,1,1,2,41,41,29,23,0,3,1,1,1,1,1,1
1,1,1,1,1,1,2,2,2,29,2,14,2,1,1,1,1,1,1
1,1,1,1,1,1,2,50,2,2,23,15,3,1,1,1,1,1,1
1,1,1,1,1,1,2,51,0,32,23,0,3,1,1,1,1,1,1
1,1,1,1,1,1,2,0,23,24,24,0,3,1,1,1,1,1,1
1,1,1,1,1,1,2,52,23,0,0,0,3,1,1,1,1,1,1
1,1,1,1,1,1,2,2,2,0,0,0,3,1,1,1,1,1,1
1,1,1,1,1,1,2,42,42,14,2,4,4,1,1,1,1,1,1
1,1,1,1,1,1,1,2,43,0,25,2,1,1,1,1,1,1,1
1,1,1,1,1,1,1,2,44,0,26,2,1,1,1,1,1,1,1
1,1,1,1,1,1,1,1,2,33,2,1,1,1,1,1,1,1,1
1,1,1,1,1,1,1,1,2,29,2,1,1,1,1,1,1,1,1
1,1,1,1,1,1,1,1,1,2,1,1,1,1,1,1,1,1,1
1,1,1,1,1,1,1,1,1,2,1,1,1,1,1,1,1,1,1
1,1,1,1,1,1,1,1,1,1,1,1,1,1,1,1,1,1,1
1,1,1,1,1,1,1,1,1,1,1,1,1,1,1,1,1,1,1
1,1,1,1,1,1,1,1,1,1,1,1,1,1,1,1,1,1,1
1,1,1,1,1,1,1,1,1,1,1,1,1,1,1,1,1,1,1
1,1,1,1,1,1,1,1,1,1,1,1,1,1,1,1,1,1,1
1,1,1,1,1,1,1,1,1,1,1,1,1,1,1,1,1,1,1
1,1,1,1,1,1,1,1,1,1,1,1,1,1,1,1,1,1,1
1,1,1,1,1,1,1,1,1,1,1,1,1,1,1,1,1,1,1
1,1,1,1,1,1,1,1,1,1,1,1,1,1,1,1,1,1,1
1,1,1,1,1,1,1,1,1,1,1,1,1,1,1,1,1,1,1
1,1,1,1,1,1,1,1,1,1,1,1,1,1,1,1,1,1,1
1,1,1,1,1,1,1,1,1,1,1,1,1,1,1,1,1,1,1
1,1,1,1,1,1,1,1,1,1,1,1,1,1,1,1,1,1,1
1,1,1,1,1,1,1,1,1,1,1,1,1,1,1,1,1,1,1
1,1,1,1,1,1,1,1,1,1,1,1,1,1,1,1,1,1,1
1,1,1,1,1,1,1,1,1,1,1,1,1,1,1,1,1,1,1
1,1,1,1,1,1,1,1,1,1,1,1,1,1,1,1,1,1,1
1,1,1,1,1,1,1,1,1,1,1,1,1,1,1,1,1,1,1
1,1,1,1,1,1,1,1,1,1,1,1,1,1,1,1,1,1,1
1,1,1,1,1,1,1,1,1,1,1,1,1,1,1,1,1,1,1
1,1,1,1,1,1,1,1,1,1,1,1,1,1,1,1,1,1,1
:endlayer
layer: 3
0,0,0,0,0,0,0,0,0,0,0,0,0,0,0,0,0,0,0
0,0,0,0,0,0,0,0,0,0,0,0,0,0,0,0,0,0,0
0,0,0,0,0,0,0,0,0,0,0,0,0,0,0,0,0,0,0
0,0,0,0,0,0,0,0,0,0,0,0,0,0,0,0,0,0,0
0,0,0,0,0,0,0,0,0,0,0,0,0,0,0,0,0,0,0
0,0,0,0,0,0,0,0,0,0,0,0,0,0,0,0,0,0,0
0,0,0,0,0,0,0,0,0,0,0,0,0,0,0,0,0,0,0
0,0,0,0,0,0,0,0,0,0,0,0,0,0,0,0,0,0,0
0,0,0,0,0,0,66,2,2,2,2,2,54,0,0,0,0,0,0
0,0,0,0,0,66,2,92,88,29,75,67,2,54,0,0,0,0,0
0,0,0,0,0,2,2,68,68,2,68,68,2,2,0,0,0,0,0
0,0,0,0,0,2,6,93,0,81,0,0,56,2,0,0,0,0,0
0,0,0,0,0,2,100,0,0,0,0,0,6,2,0,0,0,0,0
0,0,0,0,0,2,101,0,0,82,0,69,57,2,0,0,0,0,0
0,0,0,0,0,2,6,0,0,78,0,0,58,2,0,0,0,0,0
0,0,0,0,0,2,2,70,2,2,2,2,2,2,0,0,0,0,0
0,0,0,0,0,2,102,0,12,0,0,0,0,2,0,0,0,0,0
0,0,0,0,0,2,95,0,0,0,0,0,59,2,0,0,0,0,0
0,0,0,0,0,2,103,0,12,78,0,0,11,2,0,0,0,0,0
0,0,0,0,0,2,2,94,2,29,2,2,2,2,0,0,0,0,0
0,0,0,0,0,2,104,0,12,81,0,0,60,2,0,0,0,0,0
0,0,0,0,0,2,105,0,0,0,0,0,61,2,0,0,0,0,0
0,0,0,0,0,2,2,95,12,0,0,59,2,2,0,0,0,0,0
0,0,0,0,0,2,106,0,12,0,0,0,62,2,0,0,0,0,0
0,0,0,0,0,2,2,95,12,12,0,12,2,2,0,0,0,0,0
0,0,0,0,0,2,107,0,0,0,0,0,63,2,0,0,0,0,0
0,0,0,0,0,2,108,0,0,78,49,0,64,2,0,0,0,0,0
0,0,0,0,0,2,2,95,0,2,2,70,2,2,0,0,0,0,0
0,0,0,0,0,2,41,96,0,29,76,0,65,2,0,0,0,0,0
0,0,0,109,2,2,2,2,2,29,2,71,2,2,2,53,0,0,0
0,0,0,0,0,2,2,0,89,83,54,0,66,2,0,0,0,0,0
0,0,0,0,0,2,2,97,0,0,54,0,66,2,0,0,0,0,0
0,0,0,0,0,2,2,0,54,77,77,0,66,2,0,0,0,0,0
0,0,0,0,0,2,2,2,54,0,0,0,66,2,0,0,0,0,0
0,0,0,0,0,2,2,2,2,84,78,0,66,2,0,0,0,0,0
0,0,0,0,0,2,2,77,77,71,2,72,66,2,0,0,0,0,0
0,0,0,0,0,55,2,98,0,0,0,73,2,55,0,0,0,0,0
0,0,0,0,0,0,2,99,0,0,0,74,2,0,0,0,0,0,0
0,0,0,0,0,0,55,2,90,85,79,2,55,0,0,0,0,0,0
0,0,0,0,0,0,0,2,91,29,80,2,0,0,0,0,0,0,0
0,0,0,0,0,0,0,55,2,86,2,55,0,0,0,0,0,0,0
0,0,0,0,0,0,0,0,2,87,2,0,0,0,0,0,0,0,0
0,0,0,0,0,0,0,0,55,2,55,0,0,0,0,0,0,0,0
0,0,0,0,0,0,0,0,0,2,0,0,0,0,0,0,0,0,0
0,0,0,0,0,0,0,0,0,55,0,0,0,0,0,0,0,0,0
0,0,0,0,0,0,0,0,0,0,0,0,0,0,0,0,0,0,0
0,0,0,0,0,0,0,0,0,0,0,0,0,0,0,0,0,0,0
0,0,0,0,0,0,0,0,0,0,0,0,0,0,0,0,0,0,0
0,0,0,0,0,0,0,0,0,0,0,0,0,0,0,0,0,0,0
0,0,0,0,0,0,0,0,0,0,0,0,0,0,0,0,0,0,0
0,0,0,0,0,0,0,0,0,0,0,0,0,0,0,0,0,0,0
0,0,0,0,0,0,0,0,0,0,0,0,0,0,0,0,0,0,0
0,0,0,0,0,0,0,0,0,0,0,0,0,0,0,0,0,0,0
0,0,0,0,0,0,0,0,0,0,0,0,0,0,0,0,0,0,0
0,0,0,0,0,0,0,0,0,0,0,0,0,0,0,0,0,0,0
0,0,0,0,0,0,0,0,0,0,0,0,0,0,0,0,0,0,0
0,0,0,0,0,0,0,0,0,0,0,0,0,0,0,0,0,0,0
0,0,0,0,0,0,0,0,0,0,0,0,0,0,0,0,0,0,0
0,0,0,0,0,0,0,0,0,0,0,0,0,0,0,0,0,0,0
0,0,0,0,0,0,0,0,0,0,0,0,0,0,0,0,0,0,0
0,0,0,0,0,0,0,0,0,0,0,0,0,0,0,0,0,0,0
0,0,0,0,0,0,0,0,0,0,0,0,0,0,0,0,0,0,0
0,0,0,0,0,0,0,0,0,0,0,0,0,0,0,0,0,0,0
:endlayer
layer: 4
0,0,0,0,0,0,0,0,0,0,0,0,0,0,0,0,0,0,0
0,0,0,0,0,0,0,0,0,0,0,0,0,0,0,0,0,0,0
0,0,0,0,0,0,0,0,0,0,0,0,0,0,0,0,0,0,0
0,0,0,0,0,0,0,0,0,0,0,0,0,0,0,0,0,0,0
0,0,0,0,0,0,0,0,0,0,0,0,0,0,0,0,0,0,0
0,0,0,0,0,0,0,0,0,0,0,0,0,0,0,0,0,0,0
0,0,0,0,0,0,0,0,0,0,0,0,0,0,0,0,0,0,0
0,0,0,0,0,0,0,55,2,2,2,55,0,0,0,0,0,0,0
0,0,0,0,0,66,2,2,41,41,41,2,2,54,0,0,0,0,0
0,0,0,0,0,2,41,114,114,29,114,114,41,2,0,0,0,0,0
0,0,0,0,0,2,41,114,114,41,114,114,41,2,0,0,0,0,0
0,0,0,0,0,2,110,110,110,110,110,110,110,2,0,0,0,0,0
0,0,0,0,0,2,110,110,110,110,110,110,110,2,0,0,0,0,0
0,0,0,0,0,2,110,110,110,110,110,110,110,2,0,0,0,0,0
0,0,0,0,0,2,110,110,110,110,110,110,110,2,0,0,0,0,0
0,0,0,0,0,2,41,41,41,41,41,41,41,2,0,0,0,0,0
0,0,0,0,0,2,110,110,110,110,110,110,110,2,0,0,0,0,0
0,0,0,0,0,2,110,110,110,110,110,110,110,2,0,0,0,0,0
0,0,0,0,0,2,110,110,110,110,110,110,110,2,0,0,0,0,0
0,0,0,0,0,2,41,41,41,29,41,41,41,2,0,0,0,0,0
0,0,0,0,0,2,126,110,110,110,110,110,111,2,0,0,0,0,0
0,0,0,0,0,2,126,110,110,110,110,110,111,2,0,0,0,0,0
0,0,0,0,0,2,41,110,110,110,110,110,41,2,0,0,0,0,0
0,0,0,0,0,2,126,110,110,110,110,110,111,2,0,0,0,0,0
0,0,0,0,0,2,41,110,110,110,110,110,41,2,0,0,0,0,0
0,0,0,0,0,2,126,110,110,110,110,110,111,2,0,0,0,0,0
0,0,0,0,0,2,126,110,0,110,110,110,111,2,0,0,0,0,0
0,0,0,0,0,2,41,110,0,41,41,41,41,2,0,0,0,0,0
0,0,0,0,0,2,96,0,0,29,110,110,110,2,0,0,0,0,0
0,0,0,109,2,2,2,2,2,29,2,2,2,2,2,53,0,0,0
0,0,0,0,0,2,2,2,110,41,41,41,41,2,0,0,0,0,0
0,0,0,0,0,2,2,2,110,41,41,41,41,2,0,0,0,0,0
0,0,0,0,0,2,2,2,41,41,41,41,41,2,0,0,0,0,0
0,0,0,0,0,2,2,2,41,41,41,41,41,2,0,0,0,0,0
0,0,0,0,0,2,127,123,2,41,41,41,41,2,0,0,0,0,0
0,0,0,0,0,2,2,2,2,2,2,2,2,2,0,0,0,0,0
0,0,0,0,0,2,128,0,0,0,0,0,112,2,0,0,0,0,0
0,0,0,0,0,2,129,0,0,0,0,0,113,2,0,0,0,0,0
0,0,0,0,0,55,2,124,0,0,0,115,2,55,0,0,0,0,0
0,0,0,0,0,0,2,125,0,29,0,116,2,0,0,0,0,0,0
0,0,0,0,0,0,55,2,121,0,117,2,55,0,0,0,0,0,0
0,0,0,0,0,0,0,2,122,0,118,2,0,0,0,0,0,0,0
0,0,0,0,0,0,0,55,2,119,2,55,0,0,0,0,0,0,0
0,0,0,0,0,0,0,0,2,120,2,0,0,0,0,0,0,0,0
0,0,0,0,0,0,0,0,55,2,55,0,0,0,0,0,0,0,0
0,0,0,0,0,0,0,0,0,2,0,0,0,0,0,0,0,0,0
0,0,0,0,0,0,0,0,0,55,0,0,0,0,0,0,0,0,0
0,0,0,0,0,0,0,0,0,0,0,0,0,0,0,0,0,0,0
0,0,0,0,0,0,0,0,0,0,0,0,0,0,0,0,0,0,0
0,0,0,0,0,0,0,0,0,0,0,0,0,0,0,0,0,0,0
0,0,0,0,0,0,0,0,0,0,0,0,0,0,0,0,0,0,0
0,0,0,0,0,0,0,0,0,0,0,0,0,0,0,0,0,0,0
0,0,0,0,0,0,0,0,0,0,0,0,0,0,0,0,0,0,0
0,0,0,0,0,0,0,0,0,0,0,0,0,0,0,0,0,0,0
0,0,0,0,0,0,0,0,0,0,0,0,0,0,0,0,0,0,0
0,0,0,0,0,0,0,0,0,0,0,0,0,0,0,0,0,0,0
0,0,0,0,0,0,0,0,0,0,0,0,0,0,0,0,0,0,0
0,0,0,0,0,0,0,0,0,0,0,0,0,0,0,0,0,0,0
0,0,0,0,0,0,0,0,0,0,0,0,0,0,0,0,0,0,0
0,0,0,0,0,0,0,0,0,0,0,0,0,0,0,0,0,0,0
0,0,0,0,0,0,0,0,0,0,0,0,0,0,0,0,0,0,0
0,0,0,0,0,0,0,0,0,0,0,0,0,0,0,0,0,0,0
0,0,0,0,0,0,0,0,0,0,0,0,0,0,0,0,0,0,0
:endlayer
layer: 5
0,0,0,0,0,0,0,0,0,0,0,0,0,0,0,0,0,0,0
0,0,0,0,0,0,0,0,0,0,0,0,0,0,0,0,0,0,0
0,0,0,0,0,0,0,0,0,0,0,0,0,0,0,0,0,0,0
0,0,0,0,0,0,0,0,0,0,0,0,0,0,0,0,0,0,0
0,0,0,0,0,0,0,0,0,0,0,0,0,0,0,0,0,0,0
0,0,0,0,0,0,0,0,0,0,0,0,0,0,0,0,0,0,0
0,0,0,0,0,0,0,0,0,0,0,0,0,0,0,0,0,0,0
0,0,0,0,0,66,2,2,2,2,2,2,2,54,0,0,0,0,0
0,0,0,0,66,2,205,194,2,2,6,143,143,24,54,0,0,0,0
0,0,0,0,2,152,0,0,143,29,0,144,144,130,2,0,0,0,0
0,0,0,0,2,152,0,195,144,2,161,0,0,131,2,0,0,0,0
0,0,0,0,2,214,182,182,182,173,0,149,0,132,2,0,0,0,0
0,0,0,0,2,215,182,182,182,173,0,150,0,133,2,0,0,0,0
0,0,0,0,2,215,182,182,182,2,0,0,0,0,2,0,0,0,0
0,0,0,0,2,216,206,2,183,29,162,151,140,134,2,0,0,0,0
0,0,0,0,2,2,2,2,40,2,2,2,2,2,2,0,0,0,0
0,0,0,0,2,217,207,196,2,2,152,152,0,135,2,0,0,0,0
0,0,0,0,2,218,208,197,2,2,152,153,0,136,2,0,0,0,0
0,0,0,0,2,219,209,0,184,2,152,0,0,137,2,0,0,0,0
0,0,0,0,2,29,2,13,2,29,2,13,2,2,2,0,0,0,0
0,0,0,0,2,220,210,0,143,143,143,0,145,138,2,0,0,0,0
0,0,0,0,2,220,210,0,144,144,144,0,145,138,2,0,0,0,0
0,0,0,0,2,220,210,0,185,174,163,0,145,138,2,0,0,0,0
0,0,0,0,2,220,210,0,186,175,164,0,145,138,2,0,0,0,0
0,0,0,0,2,220,210,0,187,40,165,154,145,138,2,0,0,0,0
0,0,0,0,2,220,210,0,188,114,166,0,145,138,2,0,0,0,0
0,0,0,0,2,220,210,0,189,176,0,0,145,138,2,0,0,0,0
0,0,0,0,2,220,210,198,189,177,0,0,145,138,2,0,0,0,0
0,0,0,0,2,0,199,199,189,29,167,155,145,138,2,0,0,0,0
0,0,0,109,2,2,2,2,2,29,2,13,2,2,2,53,0,0,0
0,0,0,0,2,221,211,200,2,178,168,0,146,139,2,0,0,0,0
0,0,0,0,2,222,0,201,2,179,168,156,140,140,2,0,0,0,0
0,0,0,0,2,182,182,182,2,152,168,0,146,139,2,0,0,0,0
0,0,0,0,2,182,182,182,190,68,0,0,140,140,2,0,0,0,0
0,0,0,0,2,223,199,199,2,180,169,157,146,139,2,0,0,0,0
0,0,0,0,2,2,2,2,2,2,2,2,2,2,2,0,0,0,0
0,0,0,0,2,224,0,202,191,81,170,158,0,141,2,0,0,0,0
0,0,0,0,2,225,0,0,0,0,0,0,0,142,2,0,0,0,0
0,0,0,0,55,2,212,0,0,78,0,0,147,2,55,0,0,0,0
0,0,0,0,0,2,213,0,59,29,95,0,148,2,0,0,0,0,0
0,0,0,0,0,55,2,203,0,81,0,159,2,55,0,0,0,0,0
0,0,0,0,0,0,2,204,0,0,0,160,2,0,0,0,0,0,0
0,0,0,0,0,0,55,2,192,0,171,2,55,0,0,0,0,0,0
0,0,0,0,0,0,0,2,193,0,172,2,0,0,0,0,0,0,0
0,0,0,0,0,0,0,55,2,181,2,55,0,0,0,0,0,0,0
0,0,0,0,0,0,0,0,2,2,2,0,0,0,0,0,0,0,0
0,0,0,0,0,0,0,0,55,2,55,0,0,0,0,0,0,0,0
0,0,0,0,0,0,0,0,0,2,0,0,0,0,0,0,0,0,0
0,0,0,0,0,0,0,0,0,55,0,0,0,0,0,0,0,0,0
0,0,0,0,0,0,0,0,0,0,0,0,0,0,0,0,0,0,0
0,0,0,0,0,0,0,0,0,0,0,0,0,0,0,0,0,0,0
0,0,0,0,0,0,0,0,0,0,0,0,0,0,0,0,0,0,0
0,0,0,0,0,0,0,0,0,0,0,0,0,0,0,0,0,0,0
0,0,0,0,0,0,0,0,0,0,0,0,0,0,0,0,0,0,0
0,0,0,0,0,0,0,0,0,0,0,0,0,0,0,0,0,0,0
0,0,0,0,0,0,0,0,0,0,0,0,0,0,0,0,0,0,0
0,0,0,0,0,0,0,0,0,0,0,0,0,0,0,0,0,0,0
0,0,0,0,0,0,0,0,0,0,0,0,0,0,0,0,0,0,0
0,0,0,0,0,0,0,0,0,0,0,0,0,0,0,0,0,0,0
0,0,0,0,0,0,0,0,0,0,0,0,0,0,0,0,0,0,0
0,0,0,0,0,0,0,0,0,0,0,0,0,0,0,0,0,0,0
0,0,0,0,0,0,0,0,0,0,0,0,0,0,0,0,0,0,0
0,0,0,0,0,0,0,0,0,0,0,0,0,0,0,0,0,0,0
:endlayer
layer: 6
0,0,0,0,0,0,0,0,0,0,0,0,0,0,0,0,0,0,0
0,0,0,0,0,0,0,0,0,0,0,0,0,0,0,0,0,0,0
0,0,0,0,0,0,0,0,0,0,0,0,0,0,0,0,0,0,0
0,0,0,0,0,0,0,0,0,0,0,0,0,0,0,0,0,0,0
0,0,0,0,0,0,0,0,0,0,0,0,0,0,0,0,0,0,0
0,0,0,0,0,0,0,0,0,0,0,0,0,0,0,0,0,0,0
0,0,0,0,0,0,0,55,2,2,2,55,0,0,0,0,0,0,0
0,0,0,0,66,24,24,24,24,2,24,24,24,24,54,0,0,0,0
0,0,0,0,2,246,0,0,0,2,0,0,0,0,2,0,0,0,0
0,0,0,0,2,0,0,0,0,29,0,0,0,0,2,0,0,0,0
0,0,0,0,226,0,0,0,0,2,0,0,0,228,226,0,0,0,0
0,0,0,0,2,0,0,0,0,236,0,0,0,0,2,0,0,0,0
0,0,0,0,226,0,0,0,0,237,0,0,0,229,226,0,0,0,0
0,0,0,0,2,0,0,0,0,2,0,0,0,0,2,0,0,0,0
0,0,0,0,226,0,0,2,242,29,233,231,140,0,226,0,0,0,0
0,0,0,0,2,2,2,2,0,2,2,2,2,2,2,0,0,0,0
0,0,0,0,226,247,0,66,40,2,234,232,0,0,226,0,0,0,0
0,0,0,0,2,248,0,66,2,2,0,0,0,0,2,0,0,0,0
0,0,0,0,226,249,0,0,243,2,235,0,0,0,226,0,0,0,0
0,0,0,0,2,29,2,70,2,29,2,70,2,2,2,0,0,0,0
0,0,0,0,226,220,210,0,143,143,143,0,145,138,226,0,0,0,0
0,0,0,0,2,220,210,0,144,144,144,0,145,138,2,0,0,0,0
0,0,0,0,226,220,210,0,0,0,0,0,145,138,226,0,0,0,0
0,0,0,0,2,220,210,0,0,0,0,0,145,138,2,0,0,0,0
0,0,0,0,226,220,210,0,0,0,0,0,145,138,226,0,0,0,0
0,0,0,0,2,220,210,0,0,40,0,0,145,138,2,0,0,0,0
0,0,0,0,226,220,210,0,0,114,0,0,145,138,226,0,0,0,0
0,0,0,0,2,220,210,0,0,0,0,0,145,138,2,0,0,0,0
0,0,0,0,226,0,0,0,0,29,0,0,145,138,226,0,0,0,0
0,0,0,109,2,2,2,2,2,29,2,70,2,2,2,53,0,0,0
0,0,0,0,226,0,0,0,2,238,0,0,0,230,226,0,0,0,0
0,0,0,0,2,0,0,0,2,239,0,0,140,140,2,0,0,0,0
0,0,0,0,226,0,0,0,2,0,0,0,0,230,226,0,0,0,0
0,0,0,0,2,0,245,0,244,0,0,0,140,140,2,0,0,0,0
0,0,0,0,226,0,0,0,2,240,0,0,0,230,226,0,0,0,0
0,0,0,0,2,2,2,2,2,2,2,2,2,2,2,0,0,0,0
0,0,0,0,227,126,110,110,110,110,110,110,110,111,227,0,0,0,0
0,0,0,0,2,126,110,110,110,110,110,110,110,111,2,0,0,0,0
0,0,0,0,2,41,126,110,110,110,110,110,111,41,2,0,0,0,0
0,0,0,0,2,41,126,110,110,29,110,110,111,41,2,0,0,0,0
0,0,0,0,55,2,41,126,110,110,110,111,41,2,55,0,0,0,0
0,0,0,0,0,2,41,126,110,110,110,111,41,2,0,0,0,0,0
0,0,0,0,0,55,2,41,126,110,111,41,2,55,0,0,0,0,0
0,0,0,0,0,0,2,41,126,110,111,41,2,0,0,0,0,0,0
0,0,0,0,0,0,55,2,41,241,41,2,55,0,0,0,0,0,0
0,0,0,0,0,0,0,2,41,41,41,2,0,0,0,0,0,0,0
0,0,0,0,0,0,0,55,2,41,2,55,0,0,0,0,0,0,0
0,0,0,0,0,0,0,0,2,41,2,0,0,0,0,0,0,0,0
0,0,0,0,0,0,0,0,55,2,55,0,0,0,0,0,0,0,0
0,0,0,0,0,0,0,0,0,2,0,0,0,0,0,0,0,0,0
0,0,0,0,0,0,0,0,0,55,0,0,0,0,0,0,0,0,0
0,0,0,0,0,0,0,0,0,0,0,0,0,0,0,0,0,0,0
0,0,0,0,0,0,0,0,0,0,0,0,0,0,0,0,0,0,0
0,0,0,0,0,0,0,0,0,0,0,0,0,0,0,0,0,0,0
0,0,0,0,0,0,0,0,0,0,0,0,0,0,0,0,0,0,0
0,0,0,0,0,0,0,0,0,0,0,0,0,0,0,0,0,0,0
0,0,0,0,0,0,0,0,0,0,0,0,0,0,0,0,0,0,0
0,0,0,0,0,0,0,0,0,0,0,0,0,0,0,0,0,0,0
0,0,0,0,0,0,0,0,0,0,0,0,0,0,0,0,0,0,0
0,0,0,0,0,0,0,0,0,0,0,0,0,0,0,0,0,0,0
0,0,0,0,0,0,0,0,0,0,0,0,0,0,0,0,0,0,0
0,0,0,0,0,0,0,0,0,0,0,0,0,0,0,0,0,0,0
0,0,0,0,0,0,0,0,0,0,0,0,0,0,0,0,0,0,0
:endlayer
layer: 7
0,0,0,0,0,0,0,0,0,0,0,0,0,0,0,0,0,0,0
0,0,0,0,0,0,0,0,0,0,0,0,0,0,0,0,0,0,0
0,0,0,0,0,0,0,0,0,0,0,0,0,0,0,0,0,0,0
0,0,0,0,0,0,0,0,0,0,0,0,0,0,0,0,0,0,0
0,0,0,0,0,0,0,0,0,0,0,0,0,0,0,0,0,0,0
0,0,0,0,0,0,72,55,55,55,55,55,72,0,0,0,0,0,0
0,0,0,0,72,227,227,227,227,227,227,227,227,227,72,0,0,0,0
0,0,0,0,250,95,0,0,0,250,0,0,0,0,250,0,0,0,0
0,0,0,0,250,0,0,0,0,250,0,0,0,0,250,0,0,0,0
0,0,0,0,250,95,0,0,59,29,95,0,0,59,250,0,0,0,0
0,0,0,66,250,0,0,0,0,250,0,0,0,0,250,54,0,0,0
0,0,0,0,250,95,0,0,0,250,95,0,0,59,250,0,0,0,0
0,0,0,0,250,0,0,0,0,250,0,0,0,0,250,0,0,0,0
0,0,0,0,250,95,0,78,0,250,0,0,0,59,250,0,0,0,0
0,0,0,0,250,0,0,2,267,29,241,241,140,0,250,0,0,0,0
0,0,0,0,250,227,227,2,0,250,227,227,227,227,250,0,0,0,0
0,0,0,0,250,275,0,2,268,250,0,0,0,0,250,0,0,0,0
0,0,0,0,250,95,0,2,40,250,95,0,0,59,250,0,0,0,0
0,0,0,0,250,0,0,77,77,250,0,0,0,0,250,0,0,0,0
0,0,0,0,250,29,227,227,227,29,227,227,227,227,250,0,0,0,0
0,0,0,0,250,220,210,0,0,81,0,0,145,138,250,0,0,0,0
0,0,0,0,250,220,210,0,0,0,0,0,145,138,250,0,0,0,0
0,0,0,0,250,220,210,0,0,0,0,0,145,138,250,0,0,0,0
0,0,0,0,250,220,210,0,0,0,0,0,145,138,250,0,0,0,0
0,0,0,0,250,220,210,0,0,0,0,0,145,138,250,0,0,0,0
0,0,0,0,250,220,210,0,0,0,0,0,145,138,250,0,0,0,0
0,0,0,0,250,220,210,0,0,40,0,0,145,138,250,0,0,0,0
0,0,0,0,250,220,210,0,0,114,0,0,145,138,250,0,0,0,0
0,0,0,0,250,95,0,0,0,29,0,0,145,138,250,0,0,0,0
0,0,0,109,250,227,227,227,227,29,227,227,227,227,250,53,0,0,0
0,0,0,0,250,0,81,0,250,0,0,0,0,59,250,0,0,0,0
0,0,0,0,250,0,0,0,250,0,0,0,140,140,250,0,0,0,0
0,0,0,0,250,95,0,0,250,95,0,0,0,59,250,0,0,0,0
0,0,0,0,250,0,0,0,250,0,0,0,140,140,250,0,0,0,0
0,0,0,0,250,0,78,0,250,0,0,0,0,59,250,0,0,0,0
0,0,0,140,250,227,227,227,227,227,227,227,227,227,250,140,0,0,0
0,0,0,250,24,24,2,24,24,2,24,2,254,252,24,250,0,0,0
0,0,0,250,0,274,271,0,0,140,258,0,255,253,0,250,0,0,0
0,0,0,250,276,274,271,272,0,0,0,256,255,253,251,250,0,0,0
0,0,0,250,0,274,271,273,0,29,0,257,255,253,0,250,0,0,0
0,0,0,250,4,0,274,271,0,263,0,255,253,0,4,250,0,0,0
0,0,0,140,250,4,274,271,269,0,259,255,253,4,250,140,0,0,0
0,0,0,0,55,250,274,271,270,0,260,255,253,250,55,0,0,0,0
0,0,0,0,0,250,4,274,271,0,255,253,4,250,0,0,0,0,0
0,0,0,0,0,55,250,0,261,264,261,0,250,55,0,0,0,0,0
0,0,0,0,0,0,250,4,262,265,262,4,250,0,0,0,0,0,0
0,0,0,0,0,0,55,250,0,261,0,250,55,0,0,0,0,0,0
0,0,0,0,0,0,0,250,4,262,4,250,0,0,0,0,0,0,0
0,0,0,0,0,0,0,55,250,266,250,55,0,0,0,0,0,0,0
0,0,0,0,0,0,0,0,250,29,250,0,0,0,0,0,0,0,0
0,0,0,0,0,0,0,0,55,2,55,0,0,0,0,0,0,0,0
0,0,0,0,0,0,0,0,0,2,0,0,0,0,0,0,0,0,0
0,0,0,0,0,0,0,0,0,55,0,0,0,0,0,0,0,0,0
0,0,0,0,0,0,0,0,0,0,0,0,0,0,0,0,0,0,0
0,0,0,0,0,0,0,0,0,0,0,0,0,0,0,0,0,0,0
0,0,0,0,0,0,0,0,0,0,0,0,0,0,0,0,0,0,0
0,0,0,0,0,0,0,0,0,0,0,0,0,0,0,0,0,0,0
0,0,0,0,0,0,0,0,0,0,0,0,0,0,0,0,0,0,0
0,0,0,0,0,0,0,0,0,0,0,0,0,0,0,0,0,0,0
0,0,0,0,0,0,0,0,0,0,0,0,0,0,0,0,0,0,0
0,0,0,0,0,0,0,0,0,0,0,0,0,0,0,0,0,0,0
0,0,0,0,0,0,0,0,0,0,0,0,0,0,0,0,0,0,0
0,0,0,0,0,0,0,0,0,0,0,0,0,0,0,0,0,0,0
:endlayer
layer: 8
0,0,0,0,0,0,0,0,0,0,0,0,0,0,0,0,0,0,0
0,0,0,0,0,0,0,0,0,0,0,0,0,0,0,0,0,0,0
0,0,0,0,0,0,0,0,0,0,0,0,0,0,0,0,0,0,0
0,0,0,0,0,0,0,0,0,0,0,0,0,0,0,0,0,0,0
0,0,0,0,0,0,0,72,55,55,55,72,0,0,0,0,0,0,0
0,0,0,0,0,0,2,2,2,2,2,2,2,0,0,0,0,0,0
0,0,0,0,2,2,2,41,41,41,41,41,2,2,2,0,0,0,0
0,0,0,66,2,41,41,41,41,41,41,41,41,41,2,54,0,0,0
0,0,0,66,2,41,41,41,41,41,41,41,41,41,2,54,0,0,0
0,0,0,2,2,41,41,41,41,29,41,41,41,41,2,2,0,0,0
0,0,0,2,2,41,41,41,41,41,41,41,41,41,2,2,0,0,0
0,0,0,2,2,41,41,41,41,41,41,41,41,41,2,2,0,0,0
0,0,0,66,2,41,41,41,41,41,41,41,41,41,2,54,0,0,0
0,0,0,66,2,41,41,41,41,41,41,41,41,41,2,54,0,0,0
0,0,0,55,2,41,41,2,77,29,41,41,41,41,2,55,0,0,0
0,0,0,55,2,41,41,2,0,2,41,41,41,41,2,55,0,0,0
0,0,0,55,2,114,114,2,0,2,41,41,41,41,2,55,0,0,0
0,0,0,55,2,110,110,2,0,2,41,41,41,41,2,55,0,0,0
0,0,0,55,2,241,241,2,40,2,41,41,41,41,2,55,0,0,0
0,0,0,66,2,41,41,41,41,29,41,41,41,41,2,54,0,0,0
0,0,0,0,2,41,41,41,41,41,41,41,41,41,2,0,0,0,0
0,0,0,0,2,41,41,41,0,0,0,41,41,41,2,0,0,0,0
0,0,0,66,2,41,41,41,0,0,0,41,41,41,2,54,0,0,0
0,0,0,55,2,41,41,41,0,0,0,41,41,41,2,55,0,0,0
0,0,0,55,2,41,41,41,0,0,0,41,41,41,2,55,0,0,0
0,0,0,55,2,41,41,41,0,0,0,41,41,41,2,55,0,0,0
0,0,0,55,2,41,41,41,0,0,0,41,41,41,2,55,0,0,0
0,0,0,66,2,41,41,41,0,40,0,41,41,41,2,54,0,0,0
0,0,0,0,24,41,41,41,41,29,41,41,41,41,24,0,0,0,0
0,0,0,0,3,41,41,41,29,29,29,41,41,41,23,0,0,0,0
0,0,0,0,4,41,41,41,41,41,41,41,41,41,4,0,0,0,0
0,0,0,66,2,41,41,41,41,41,41,41,41,41,2,54,0,0,0
0,0,0,55,2,41,41,41,41,41,41,41,41,41,2,55,0,0,0
0,0,0,55,2,41,41,41,41,41,41,41,41,41,2,55,0,0,0
0,0,0,55,2,41,41,41,41,41,41,41,41,41,2,55,0,0,0
0,0,0,29,2,2,2,2,2,2,24,2,2,2,2,29,0,0,0
0,0,0,2,291,289,2,286,284,2,0,2,279,277,0,2,0,0,0
0,0,0,226,0,0,0,0,0,283,0,0,0,0,0,226,0,0,0
0,0,0,2,95,0,0,0,0,78,0,0,0,0,59,2,0,0,0
0,0,0,226,0,0,0,0,59,29,95,0,0,0,0,226,0,0,0
0,0,0,2,0,0,0,0,0,81,0,0,0,0,0,2,0,0,0
0,0,0,29,2,95,0,0,0,0,0,0,0,59,2,29,0,0,0
0,0,0,0,250,290,0,0,0,0,0,0,0,278,250,0,0,0,0
0,0,0,0,250,4,0,0,0,0,0,0,0,4,250,0,0,0,0
0,0,0,0,55,250,288,0,0,0,0,0,280,250,55,0,0,0,0
0,0,0,0,0,250,4,0,0,0,0,0,4,250,0,0,0,0,0
0,0,0,0,0,55,250,287,0,0,0,281,250,55,0,0,0,0,0
0,0,0,0,0,0,250,4,0,0,0,4,250,0,0,0,0,0,0
0,0,0,0,0,0,55,250,285,78,282,250,55,0,0,0,0,0,0
0,0,0,0,0,0,0,250,4,29,4,250,0,0,0,0,0,0,0
0,0,0,0,0,0,0,55,250,2,250,55,0,0,0,0,0,0,0
0,0,0,0,0,0,0,0,250,2,250,0,0,0,0,0,0,0,0
0,0,0,0,0,0,0,0,55,250,55,0,0,0,0,0,0,0,0
0,0,0,0,0,0,0,0,0,250,0,0,0,0,0,0,0,0,0
0,0,0,0,0,0,0,0,0,55,0,0,0,0,0,0,0,0,0
0,0,0,0,0,0,0,0,0,0,0,0,0,0,0,0,0,0,0
0,0,0,0,0,0,0,0,0,0,0,0,0,0,0,0,0,0,0
0,0,0,0,0,0,0,0,0,0,0,0,0,0,0,0,0,0,0
0,0,0,0,0,0,0,0,0,0,0,0,0,0,0,0,0,0,0
0,0,0,0,0,0,0,0,0,0,0,0,0,0,0,0,0,0,0
0,0,0,0,0,0,0,0,0,0,0,0,0,0,0,0,0,0,0
0,0,0,0,0,0,0,0,0,0,0,0,0,0,0,0,0,0,0
0,0,0,0,0,0,0,0,0,0,0,0,0,0,0,0,0,0,0
:endlayer
layer: 9
0,0,0,0,0,0,0,0,0,0,0,0,0,0,0,0,0,0,0
0,0,0,0,0,0,0,0,0,0,0,0,0,0,0,0,0,0,0
0,0,0,0,0,0,0,0,0,0,0,0,0,0,0,0,0,0,0
0,0,0,0,0,0,0,0,0,0,0,0,0,0,0,0,0,0,0
0,0,0,0,0,0,0,140,140,140,140,140,0,0,0,0,0,0,0
0,0,0,0,0,0,2,29,226,226,226,29,2,0,0,0,0,0,0
0,0,0,140,2,227,2,323,200,200,313,309,2,227,2,140,0,0,0
0,0,0,2,336,0,0,324,200,200,314,0,300,0,0,2,0,0,0
0,0,0,250,337,0,0,0,0,0,0,310,300,0,0,250,0,0,0
0,0,0,2,2,2,13,2,2,29,2,2,2,182,182,2,0,0,0
0,0,0,250,338,331,0,0,319,2,315,0,301,182,182,250,0,0,0
0,0,0,2,338,331,0,0,200,2,0,201,302,182,182,2,0,0,0
0,0,0,250,6,0,325,0,320,2,0,201,303,294,0,250,0,0,0
0,0,0,2,339,0,0,0,321,2,0,0,304,0,292,2,0,0,0
0,0,0,2,2,13,13,2,227,29,13,13,29,227,2,2,0,0,0
0,0,0,2,2,332,326,2,81,2,316,0,140,0,2,2,0,0,0
0,0,0,24,2,41,41,2,0,140,0,0,0,0,2,24,0,0,0
0,0,0,0,2,327,327,2,0,2,0,311,0,0,2,0,0,0,0
0,0,0,0,2,0,0,24,322,312,0,0,305,3,2,0,0,0,0
0,0,0,0,140,0,0,0,0,29,0,0,0,295,140,0,0,0,0
0,0,0,0,2,0,0,312,312,312,312,312,0,0,2,0,0,0,0
0,0,0,0,140,0,0,312,317,317,189,312,0,0,140,0,0,0,0
0,0,0,4,2,23,328,312,317,317,189,312,306,3,2,4,0,0,0
0,0,0,12,140,333,0,312,317,317,189,312,0,296,140,12,0,0,0
0,0,0,12,2,95,0,312,317,317,189,312,0,59,2,12,0,0,0
0,0,0,0,140,0,0,312,317,317,189,312,0,0,140,0,0,0,0
0,0,0,0,2,334,0,312,317,317,189,312,0,297,2,0,0,0,0
0,0,0,0,2,23,329,312,317,317,189,312,307,3,2,0,0,0,0
0,0,0,0,81,0,0,312,4,29,4,312,0,0,81,0,0,0,0
0,0,0,0,340,0,0,109,29,29,29,53,0,0,293,0,0,0,0
0,0,0,0,78,0,0,0,140,29,140,0,0,0,78,0,0,0,0
0,0,0,4,2,23,330,0,0,0,0,0,308,3,2,4,0,0,0
0,0,0,2,2,335,0,0,0,318,0,0,0,298,2,2,0,0,0
0,0,0,12,140,0,0,0,0,78,0,0,0,0,140,12,0,0,0
0,0,0,12,2,299,299,2,40,2,0,2,299,299,2,12,0,0,0
0,0,0,66,2,41,41,2,2,2,0,2,41,41,2,54,0,0,0
0,0,0,250,114,111,41,114,114,2,0,2,126,114,114,250,0,0,0
0,0,0,250,126,111,114,126,111,55,0,55,126,110,111,250,0,0,0
0,0,0,250,126,110,110,110,111,55,55,55,126,110,111,250,0,0,0
0,0,0,250,126,110,110,110,114,29,114,114,126,110,111,250,0,0,0
0,0,0,250,126,241,110,110,110,110,110,110,110,241,111,250,0,0,0
0,0,0,66,2,126,110,110,110,110,110,110,110,111,2,54,0,0,0
0,0,0,55,2,126,110,110,110,110,110,110,110,111,2,55,0,0,0
0,0,0,66,2,126,241,110,110,110,110,110,241,111,2,54,0,0,0
0,0,0,0,2,41,126,110,110,110,110,110,111,41,2,0,0,0,0
0,0,0,0,2,41,241,241,110,110,110,241,111,41,2,0,0,0,0
0,0,0,0,55,2,41,126,110,110,110,111,41,2,55,0,0,0,0
0,0,0,0,0,2,41,126,241,110,241,111,41,2,0,0,0,0,0
0,0,0,0,0,55,2,41,126,110,111,41,2,55,0,0,0,0,0
0,0,0,0,0,0,2,41,241,29,241,41,2,0,0,0,0,0,0
0,0,0,0,0,0,55,2,41,250,41,2,55,0,0,0,0,0,0
0,0,0,0,0,0,0,2,41,250,41,2,0,0,0,0,0,0,0
0,0,0,0,0,0,0,55,2,41,2,55,0,0,0,0,0,0,0
0,0,0,0,0,0,0,0,2,41,2,0,0,0,0,0,0,0,0
0,0,0,0,0,0,0,0,55,250,55,0,0,0,0,0,0,0,0
0,0,0,0,0,0,0,0,0,250,0,0,0,0,0,0,0,0,0
0,0,0,0,0,0,0,0,0,55,0,0,0,0,0,0,0,0,0
0,0,0,0,0,0,0,0,0,0,0,0,0,0,0,0,0,0,0
0,0,0,0,0,0,0,0,0,0,0,0,0,0,0,0,0,0,0
0,0,0,0,0,0,0,0,0,0,0,0,0,0,0,0,0,0,0
0,0,0,0,0,0,0,0,0,0,0,0,0,0,0,0,0,0,0
0,0,0,0,0,0,0,0,0,0,0,0,0,0,0,0,0,0,0
0,0,0,0,0,0,0,0,0,0,0,0,0,0,0,0,0,0,0
:endlayer
layer: 10
0,0,0,0,0,0,0,0,0,0,0,0,0,0,0,0,0,0,0
0,0,0,0,0,0,0,0,0,0,0,0,0,0,0,0,0,0,0
0,0,0,0,0,0,0,0,0,0,0,0,0,0,0,0,0,0,0
0,0,0,0,0,0,0,0,0,0,0,0,0,0,0,0,0,0,0
0,0,0,0,0,0,0,0,0,0,0,0,0,0,0,0,0,0,0
0,0,0,0,0,0,2,29,226,226,226,29,2,0,0,0,0,0,0
0,0,0,140,2,226,2,367,182,182,358,0,2,226,2,140,0,0,0
0,0,0,2,385,0,0,368,182,182,359,0,345,0,0,2,0,0,0
0,0,0,226,385,0,0,0,0,0,0,0,70,0,0,226,0,0,0
0,0,0,2,2,2,70,2,2,29,2,2,2,0,0,2,0,0,0
0,0,0,226,0,0,0,0,364,2,0,0,0,0,0,226,0,0,0
0,0,0,2,0,0,0,0,0,2,0,0,346,341,0,2,0,0,0
0,0,0,226,386,0,0,0,365,2,0,0,0,342,0,226,0,0,0
0,0,0,2,0,382,379,0,0,2,0,0,347,0,0,2,0,0,0
0,0,12,12,2,70,345,2,226,29,70,345,29,226,2,12,12,0,0
0,0,12,12,226,241,241,226,0,24,0,0,140,0,226,12,12,0,0
0,0,0,59,2,327,327,2,0,312,0,0,0,0,2,95,0,0,0
0,0,0,0,24,0,0,24,0,312,0,0,0,0,24,0,0,0,0
0,0,0,0,312,0,0,0,0,361,0,0,0,0,0,0,0,0,0
0,0,0,0,312,0,0,0,0,29,0,0,0,0,312,0,0,0,0
0,0,0,0,312,0,0,0,0,0,0,0,0,0,312,0,0,0,0
0,0,0,0,312,0,0,369,0,0,0,350,0,0,312,0,0,0,0
0,0,0,0,0,0,0,0,0,0,0,0,0,0,0,0,0,0,0
0,0,0,0,312,0,0,370,0,0,0,351,0,0,312,0,0,0,0
0,0,12,12,312,0,0,0,0,0,0,0,0,0,312,12,12,0,0
0,0,12,12,312,0,0,371,0,0,0,352,0,0,312,12,12,0,0
0,0,0,0,312,0,0,0,0,0,0,0,0,0,312,0,0,0,0
0,0,0,0,0,0,0,372,0,0,0,353,0,0,0,0,0,0,0
0,0,0,0,0,0,0,0,140,29,140,0,0,0,0,0,0,0,0
0,0,0,0,0,0,0,109,29,29,29,53,0,0,0,0,0,0,0
0,0,0,0,0,0,0,0,140,29,140,0,0,0,0,0,0,0,0
0,0,0,0,0,0,0,0,0,0,0,0,0,0,0,0,0,0,0
0,0,0,0,312,0,0,0,0,0,0,0,0,0,312,0,0,0,0
0,0,0,0,312,0,0,0,0,0,0,0,0,0,312,0,0,0,0
0,0,12,12,4,0,0,4,0,4,0,4,0,0,4,12,12,0,0
0,0,12,12,24,0,0,2,40,2,0,2,0,0,24,12,12,0,0
0,0,0,2,312,0,0,373,2,2,0,2,0,0,312,2,0,0,0
0,0,0,140,0,383,0,374,2,2,72,2,0,343,0,140,0,0,0
0,0,0,140,0,0,0,2,2,2,2,2,0,0,0,140,0,0,0
0,0,0,140,0,0,0,140,2,29,2,140,0,0,0,140,0,0,0
0,0,0,140,4,0,0,375,0,81,0,354,0,0,4,140,0,0,0
0,0,0,2,2,384,380,0,0,362,0,0,348,344,2,2,0,0,0
0,0,0,12,2,0,0,0,360,360,360,0,0,0,2,12,0,0,0
0,0,0,12,2,0,0,376,180,180,180,355,0,0,2,12,0,0,0
0,0,0,0,140,0,0,0,180,180,180,0,0,0,140,0,0,0,0
0,0,0,0,140,0,0,0,360,360,360,0,0,0,140,0,0,0,0
0,0,0,0,24,140,0,377,0,363,0,356,0,140,24,0,0,0,0
0,0,0,0,0,140,381,2,23,0,3,2,349,140,0,0,0,0,0
0,0,0,0,0,24,140,0,0,361,0,0,140,24,0,0,0,0,0
0,0,0,0,0,0,140,378,0,29,0,357,140,0,0,0,0,0,0
0,0,0,0,0,0,24,140,0,0,0,140,24,0,0,0,0,0,0
0,0,0,0,0,0,0,140,366,4,0,140,0,0,0,0,0,0,0
0,0,0,0,0,0,0,24,4,250,4,24,0,0,0,0,0,0,0
0,0,0,0,0,0,0,0,2,250,2,0,0,0,0,0,0,0,0
0,0,0,0,0,0,0,0,24,250,24,0,0,0,0,0,0,0,0
0,0,0,0,0,0,0,0,312,250,312,0,0,0,0,0,0,0,0
0,0,0,0,0,0,0,0,312,250,312,0,0,0,0,0,0,0,0
0,0,0,0,0,0,0,0,55,250,55,0,0,0,0,0,0,0,0
0,0,0,0,0,0,0,0,55,250,55,0,0,0,0,0,0,0,0
0,0,0,0,0,0,0,0,0,55,0,0,0,0,0,0,0,0,0
0,0,0,0,0,0,0,0,0,0,0,0,0,0,0,0,0,0,0
0,0,0,0,0,0,0,0,0,0,0,0,0,0,0,0,0,0,0
0,0,0,0,0,0,0,0,0,0,0,0,0,0,0,0,0,0,0
:endlayer
layer: 11
0,0,0,0,0,0,0,0,0,0,0,0,0,0,0,0,0,0,0
0,0,0,0,0,0,0,0,0,0,0,0,0,0,0,0,0,0,0
0,0,0,0,0,0,0,0,0,0,0,0,0,0,0,0,0,0,0
0,0,0,0,0,0,0,0,0,0,0,0,0,0,0,0,0,0,0
0,0,0,0,0,0,0,0,0,0,0,0,0,0,0,0,0,0,0
0,0,0,0,0,0,2,29,226,226,226,29,2,0,0,0,0,0,0
0,0,0,72,2,226,2,81,0,0,0,81,2,226,2,72,0,0,0
0,0,0,2,95,0,0,0,0,0,0,0,2,0,59,2,0,0,0
0,0,0,226,0,0,78,0,396,78,390,0,2,0,0,226,0,0,0
0,0,0,2,2,2,2,2,2,29,2,2,2,54,66,2,0,0,0
0,0,0,226,0,399,0,398,0,2,95,388,0,0,0,226,0,0,0
0,0,0,2,95,0,0,0,59,2,391,0,0,0,59,2,0,0,0
0,0,0,226,0,0,0,0,0,2,392,0,0,0,0,226,0,0,0
0,0,0,2,95,0,0,0,0,2,95,0,0,0,59,2,0,0,0
0,0,0,140,2,2,2,2,226,29,389,389,29,226,2,140,0,0,0
0,0,12,0,2,327,327,2,0,140,0,0,140,0,2,0,12,0,0
0,0,12,0,24,0,0,24,0,0,0,0,0,0,24,0,12,0,0
0,0,0,0,0,0,0,0,0,0,0,0,0,0,0,0,0,0,0
0,0,0,0,0,0,0,0,0,361,0,0,0,0,0,0,0,0,0
0,0,0,0,0,0,0,0,59,29,95,0,0,0,0,0,0,0,0
0,0,0,0,0,0,0,0,0,81,0,0,0,0,0,0,0,0,0
0,0,0,0,0,0,0,0,0,0,0,0,0,0,0,0,0,0,0
0,0,0,0,0,0,0,0,0,0,0,0,0,0,0,0,0,0,0
0,0,0,0,0,0,0,0,0,0,0,0,0,0,0,0,0,0,0
0,0,0,0,0,0,0,0,0,0,0,0,0,0,0,0,0,0,0
0,0,12,0,0,0,0,0,0,0,0,0,0,0,0,0,12,0,0
0,0,12,0,0,0,0,0,0,0,0,0,0,0,0,0,12,0,0
0,0,0,0,0,0,0,0,0,0,0,0,0,0,0,0,0,0,0
0,0,0,0,0,0,0,0,140,29,140,0,0,0,0,0,0,0,0
0,0,0,0,0,0,0,109,29,29,29,53,0,0,0,0,0,0,0
0,0,0,0,0,0,0,0,140,29,140,0,0,0,0,0,0,0,0
0,0,0,0,0,0,0,0,0,0,0,0,0,0,0,0,0,0,0
0,0,0,0,0,0,0,0,0,0,0,0,0,0,0,0,0,0,0
0,0,0,0,0,0,0,0,0,0,0,0,0,0,0,0,0,0,0
0,0,0,0,400,0,0,0,0,0,0,0,0,0,387,0,0,0,0
0,0,12,0,0,0,0,4,0,4,0,4,0,0,0,0,12,0,0
0,0,12,175,0,0,0,66,40,2,72,2,0,0,0,175,12,0,0
0,0,0,0,0,0,0,66,41,41,41,2,0,0,0,0,0,0,0
0,0,0,0,0,0,0,2,41,41,41,2,0,0,0,0,0,0,0
0,0,0,0,0,0,0,140,2,29,2,140,0,0,0,0,0,0,0
0,0,0,0,0,0,0,0,0,0,0,0,0,0,0,0,0,0,0
0,0,0,175,0,0,0,0,0,0,0,0,0,0,0,175,0,0,0
0,0,0,12,0,0,0,0,0,0,0,0,0,0,0,12,0,0,0
0,0,0,12,0,0,0,0,0,0,0,0,0,0,0,12,0,0,0
0,0,0,12,0,0,0,0,0,0,0,0,0,0,0,12,0,0,0
0,0,0,0,0,0,0,0,0,0,0,0,0,0,0,0,0,0,0
0,0,0,0,0,175,0,0,0,0,0,0,0,175,0,0,0,0,0
0,0,0,0,0,0,0,0,0,0,0,0,0,0,0,0,0,0,0
0,0,0,0,0,0,0,0,0,361,0,0,0,0,0,0,0,0,0
0,0,0,0,0,0,0,0,0,29,0,0,0,0,0,0,0,0,0
0,0,0,0,0,0,0,175,0,0,0,175,0,0,0,0,0,0,0
0,0,0,0,0,0,0,0,0,394,0,0,0,0,0,0,0,0,0
0,0,0,0,0,0,0,0,397,0,393,0,0,0,0,0,0,0,0
0,0,0,0,0,0,0,0,0,0,0,0,0,0,0,0,0,0,0
0,0,0,0,0,0,0,0,312,4,312,0,0,0,0,0,0,0,0
0,0,0,0,0,0,0,0,312,250,312,0,0,0,0,0,0,0,0
0,0,0,0,0,0,0,0,55,250,55,0,0,0,0,0,0,0,0
0,0,0,0,0,0,0,0,55,250,55,0,0,0,0,0,0,0,0
0,0,0,0,0,0,0,0,0,395,0,0,0,0,0,0,0,0,0
0,0,0,0,0,0,0,0,312,250,312,0,0,0,0,0,0,0,0
0,0,0,0,0,0,0,0,55,250,55,0,0,0,0,0,0,0,0
0,0,0,0,0,0,0,0,0,77,0,0,0,0,0,0,0,0,0
0,0,0,0,0,0,0,0,0,55,0,0,0,0,0,0,0,0,0
:endlayer
layer: 12
0,0,0,0,0,0,0,0,0,0,0,0,0,0,0,0,0,0,0
0,0,0,0,0,0,0,0,0,0,0,0,0,0,0,0,0,0,0
0,0,0,0,0,0,0,0,0,0,0,0,0,0,0,0,0,0,0
0,0,0,0,0,0,0,0,0,0,0,0,0,0,0,0,0,0,0
0,0,0,0,0,0,72,55,55,72,55,55,72,0,0,0,0,0,0
0,0,0,72,72,55,2,2,2,2,2,2,2,55,72,72,0,0,0
0,0,0,2,2,2,2,41,41,41,41,41,2,2,2,2,0,0,0
0,0,66,2,41,41,41,41,41,41,41,41,41,41,41,2,54,0,0
0,0,55,2,41,41,41,41,41,41,41,41,41,41,41,2,55,0,0
0,0,66,2,41,41,41,41,41,29,41,41,41,41,41,2,54,0,0
0,0,55,2,41,41,41,41,41,41,41,41,41,41,41,2,55,0,0
0,0,66,2,41,41,41,41,41,41,41,41,41,41,41,2,54,0,0
0,0,55,2,41,41,41,41,41,41,41,41,41,41,41,2,55,0,0
0,0,66,2,41,41,41,41,41,41,41,41,41,41,41,2,54,0,0
0,0,0,77,2,327,327,2,227,227,227,227,227,227,2,77,0,0,0
0,0,0,0,24,0,0,24,55,24,55,55,24,55,24,0,0,0,0
0,0,12,0,0,0,0,0,0,0,0,0,0,0,0,0,12,0,0
0,0,12,0,0,0,0,0,0,0,0,0,0,0,0,0,12,0,0
0,0,0,0,0,0,0,0,0,361,0,0,0,0,0,0,0,0,0
0,0,0,0,0,0,0,0,0,29,0,0,0,0,0,0,0,0,0
0,0,0,0,0,0,0,0,0,0,0,0,0,0,0,0,0,0,0
0,0,0,0,0,0,0,0,0,0,0,0,0,0,0,0,0,0,0
0,0,0,0,0,0,0,0,0,0,0,0,0,0,0,0,0,0,0
0,0,0,0,0,0,0,0,0,0,0,0,0,0,0,0,0,0,0
0,0,0,0,0,0,0,0,0,0,0,0,0,0,0,0,0,0,0
0,0,0,0,0,0,0,0,0,0,0,0,0,0,0,0,0,0,0
0,0,12,0,0,0,0,0,0,0,0,0,0,0,0,0,12,0,0
0,0,12,0,0,0,0,0,0,78,0,0,0,0,0,0,12,0,0
0,0,0,0,0,0,0,0,140,29,140,0,0,0,0,0,0,0,0
0,0,0,0,0,0,0,109,29,29,29,53,0,0,0,0,0,0,0
0,0,0,0,0,0,0,0,140,29,140,0,0,0,0,0,0,0,0
0,0,0,0,0,0,0,0,0,81,0,0,0,0,0,0,0,0,0
0,0,0,0,0,0,0,0,0,0,0,0,0,0,0,0,0,0,0
0,0,0,0,0,0,0,0,0,0,0,0,0,0,0,0,0,0,0
0,0,0,0,0,0,0,0,0,0,0,0,0,0,0,0,0,0,0
0,0,0,0,0,0,0,0,0,0,0,0,0,0,0,0,0,0,0
0,0,12,0,0,0,0,140,0,140,140,140,0,0,0,0,12,0,0
0,0,12,0,0,0,0,140,0,401,0,140,0,0,0,0,12,0,0
0,0,0,0,0,0,0,140,0,361,0,140,0,0,0,0,0,0,0
0,0,0,0,0,0,0,140,140,29,140,140,0,0,0,0,0,0,0
0,0,0,0,0,0,0,0,0,0,0,0,0,0,0,0,0,0,0
0,0,0,0,0,0,0,0,0,0,0,0,0,0,0,0,0,0,0
0,0,0,0,0,0,0,0,0,0,0,0,0,0,0,0,0,0,0
0,0,0,0,0,0,0,0,0,0,0,0,0,0,0,0,0,0,0
0,0,0,12,0,0,0,0,0,0,0,0,0,0,0,12,0,0,0
0,0,0,12,0,0,0,0,0,0,0,0,0,0,0,12,0,0,0
0,0,0,12,0,0,0,0,0,0,0,0,0,0,0,12,0,0,0
0,0,0,0,0,0,0,0,0,0,0,0,0,0,0,0,0,0,0
0,0,0,0,0,0,0,0,0,361,0,0,0,0,0,0,0,0,0
0,0,0,0,0,0,0,0,59,29,95,0,0,0,0,0,0,0,0
0,0,0,0,0,0,0,0,0,81,0,0,0,0,0,0,0,0,0
0,0,0,0,0,0,0,0,0,0,0,0,0,0,0,0,0,0,0
0,0,0,0,0,0,0,0,0,0,0,0,0,0,0,0,0,0,0
0,0,0,0,0,0,0,0,0,0,0,0,0,0,0,0,0,0,0
0,0,0,0,0,0,0,0,0,0,0,0,0,0,0,0,0,0,0
0,0,0,0,0,0,0,0,0,312,0,0,0,0,0,0,0,0,0
0,0,0,0,0,0,0,0,0,312,0,0,0,0,0,0,0,0,0
0,0,0,0,0,0,0,0,0,4,0,0,0,0,0,0,0,0,0
0,0,0,0,0,0,0,0,312,250,312,0,0,0,0,0,0,0,0
0,0,0,0,0,0,0,0,312,250,312,0,0,0,0,0,0,0,0
0,0,0,0,0,0,0,0,0,24,0,0,0,0,0,0,0,0,0
0,0,0,0,0,0,0,0,0,0,0,0,0,0,0,0,0,0,0
0,0,0,0,0,0,0,0,0,0,0,0,0,0,0,0,0,0,0
:endlayer
layer: 13
0,0,0,0,0,0,0,0,0,0,0,0,0,0,0,0,0,0,0
0,0,0,0,0,0,0,0,0,0,0,0,0,0,0,0,0,0,0
0,0,0,0,0,0,0,0,0,0,0,0,0,0,0,0,0,0,0
0,0,0,0,0,0,0,0,0,0,0,0,0,0,0,0,0,0,0
0,0,0,0,0,0,3,140,140,140,140,140,23,0,0,0,0,0,0
0,0,0,4,140,140,2,0,417,0,411,0,2,140,140,4,0,0,0
0,0,0,12,140,422,24,418,0,412,0,408,24,406,140,12,0,0,0
0,0,4,12,423,0,0,0,0,0,0,0,0,0,404,12,4,0,0
0,0,140,425,0,0,0,419,4,413,4,409,0,0,0,402,140,0,0
0,0,3,2,2,23,0,0,2,29,2,0,0,3,2,2,23,0,0
0,0,3,2,2,23,421,0,3,414,23,0,407,3,2,2,23,0,0
0,0,3,2,2,23,0,0,3,415,23,0,0,3,2,2,23,0,0
0,0,140,426,424,0,0,0,2,2,2,0,0,0,405,403,140,0,0
0,0,24,140,0,0,0,420,24,2,24,410,0,0,0,140,24,0,0
0,0,0,24,312,0,0,312,0,81,0,0,0,0,312,24,0,0,0
0,0,0,0,0,0,0,0,3,140,140,140,140,23,0,0,0,0,0
0,0,0,0,0,0,0,0,0,0,0,0,0,0,0,0,0,0,0
0,12,12,0,0,0,0,0,0,0,0,0,0,0,0,0,12,12,0
0,12,12,0,0,0,0,0,0,361,0,0,0,0,0,0,12,12,0
0,0,0,0,0,0,0,0,0,29,0,0,0,0,0,0,0,0,0
0,0,0,0,0,0,0,0,0,0,0,0,0,0,0,0,0,0,0
0,0,0,0,0,0,0,0,0,0,0,0,0,0,0,0,0,0,0
0,0,0,0,0,0,0,0,0,0,0,0,0,0,0,0,0,0,0
0,0,0,0,0,0,0,0,0,0,0,0,0,0,0,0,0,0,0
0,0,0,0,0,0,0,0,0,0,0,0,0,0,0,0,0,0,0
0,0,0,0,0,0,0,0,0,0,0,0,0,0,0,0,0,0,0
0,0,0,0,0,0,0,0,0,0,0,0,0,0,0,0,0,0,0
0,12,12,0,0,0,0,0,0,0,0,0,0,0,0,0,12,12,0
0,12,12,0,0,0,0,0,140,29,140,0,0,0,0,0,12,12,0
0,0,0,0,0,0,0,109,29,29,29,53,0,0,0,0,0,0,0
0,0,0,0,0,0,0,0,140,29,140,0,0,0,0,0,0,0,0
0,0,0,0,0,0,0,0,0,0,0,0,0,0,0,0,0,0,0
0,0,0,0,0,0,0,0,0,0,0,0,0,0,0,0,0,0,0
0,0,0,0,0,0,0,0,0,0,0,0,0,0,0,0,0,0,0
0,0,0,0,0,0,0,0,0,0,0,0,0,0,0,0,0,0,0
0,0,0,0,0,0,0,0,0,0,0,0,0,0,0,0,0,0,0
0,0,0,0,0,0,0,0,0,0,0,0,0,0,0,0,0,0,0
0,12,12,0,0,0,0,0,0,0,0,0,0,0,0,0,12,12,0
0,12,12,0,0,0,0,0,0,361,0,0,0,0,0,0,12,12,0
0,0,0,0,0,0,0,0,0,29,0,0,0,0,0,0,0,0,0
0,0,0,0,0,0,0,0,0,0,0,0,0,0,0,0,0,0,0
0,0,0,0,0,0,0,0,0,0,0,0,0,0,0,0,0,0,0
0,0,0,0,0,0,0,0,0,0,0,0,0,0,0,0,0,0,0
0,0,0,0,0,0,0,0,0,0,0,0,0,0,0,0,0,0,0
0,0,0,0,0,0,0,0,0,0,0,0,0,0,0,0,0,0,0
0,0,0,0,0,0,0,0,0,0,0,0,0,0,0,0,0,0,0
0,0,0,12,0,0,0,0,0,0,0,0,0,0,0,12,0,0,0
0,0,0,12,0,0,0,0,0,0,0,0,0,0,0,12,0,0,0
0,0,0,12,0,0,0,0,0,361,0,0,0,0,0,12,0,0,0
0,0,0,0,0,0,0,0,0,29,0,0,0,0,0,0,0,0,0
0,0,0,0,0,0,0,0,0,0,0,0,0,0,0,0,0,0,0
0,0,0,0,0,0,0,0,0,0,0,0,0,0,0,0,0,0,0
0,0,0,0,0,0,0,0,0,0,0,0,0,0,0,0,0,0,0
0,0,0,0,0,0,0,0,0,0,0,0,0,0,0,0,0,0,0
0,0,0,0,0,0,0,0,0,0,0,0,0,0,0,0,0,0,0
0,0,0,0,0,0,0,0,0,0,0,0,0,0,0,0,0,0,0
0,0,0,0,0,0,0,0,0,0,0,0,0,0,0,0,0,0,0
0,0,0,0,0,0,0,0,0,416,0,0,0,0,0,0,0,0,0
0,0,0,0,0,0,0,0,0,0,0,0,0,0,0,0,0,0,0
0,0,0,0,0,0,0,0,0,0,0,0,0,0,0,0,0,0,0
0,0,0,0,0,0,0,0,0,0,0,0,0,0,0,0,0,0,0
0,0,0,0,0,0,0,0,0,0,0,0,0,0,0,0,0,0,0
0,0,0,0,0,0,0,0,0,0,0,0,0,0,0,0,0,0,0
:endlayer
layer: 14
0,0,0,0,0,0,0,0,0,0,0,0,0,0,0,0,0,0,0
0,0,0,0,0,0,0,0,0,0,0,0,0,0,0,0,0,0,0
0,0,0,0,0,0,0,0,0,0,0,0,0,0,0,0,0,0,0
0,0,0,0,0,0,0,0,0,0,0,0,0,0,0,0,0,0,0
0,0,0,0,0,0,0,175,0,175,0,175,0,0,0,0,0,0,0
0,0,0,0,0,0,0,0,0,0,0,0,0,0,0,0,0,0,0
0,0,0,12,175,0,0,0,0,0,0,0,0,0,175,12,0,0,0
0,0,0,12,0,0,0,0,0,0,0,0,0,0,0,12,0,0,0
0,0,0,0,0,0,0,0,0,0,0,0,0,0,0,0,0,0,0
0,0,0,0,0,0,0,0,109,29,0,0,0,0,0,0,0,0,0
0,0,0,0,0,0,0,0,0,182,0,0,0,0,0,0,0,0,0
0,0,0,0,0,0,0,0,0,182,0,0,0,0,0,0,0,0,0
0,0,0,0,0,0,0,0,0,428,0,0,0,0,0,0,0,0,0
0,0,0,175,0,0,0,0,140,24,140,0,0,0,0,175,0,0,0
0,0,0,0,429,0,0,0,0,0,0,0,0,0,427,0,0,0,0
0,0,0,0,0,0,0,0,0,0,0,0,0,0,0,0,0,0,0
0,0,0,0,0,0,0,0,0,0,0,0,0,0,0,0,0,0,0
0,0,0,0,0,0,0,0,0,0,0,0,0,0,0,0,0,0,0
0,12,0,0,0,0,0,0,0,361,0,0,0,0,0,0,0,12,0
0,12,0,0,0,0,0,0,0,29,0,0,0,0,0,0,0,12,0
0,0,0,0,0,0,0,0,0,0,0,0,0,0,0,0,0,0,0
0,0,0,0,0,0,0,0,0,0,0,0,0,0,0,0,0,0,0
0,0,0,0,0,0,0,0,0,0,0,0,0,0,0,0,0,0,0
0,0,0,0,0,0,0,0,0,0,0,0,0,0,0,0,0,0,0
0,0,0,0,0,0,0,0,0,0,0,0,0,0,0,0,0,0,0
0,0,0,0,0,0,0,0,0,0,0,0,0,0,0,0,0,0,0
0,0,0,0,0,0,0,0,0,0,0,0,0,0,0,0,0,0,0
0,0,0,0,0,0,0,0,0,0,0,0,0,0,0,0,0,0,0
0,12,0,0,0,0,0,0,140,29,140,0,0,0,0,0,0,12,0
0,12,0,0,0,0,0,109,29,29,29,53,0,0,0,0,0,12,0
0,0,0,0,0,0,0,0,140,29,140,0,0,0,0,0,0,0,0
0,0,0,0,0,0,0,0,0,0,0,0,0,0,0,0,0,0,0
0,0,0,0,0,0,0,0,0,0,0,0,0,0,0,0,0,0,0
0,0,0,0,0,0,0,0,0,0,0,0,0,0,0,0,0,0,0
0,0,0,0,0,0,0,0,0,0,0,0,0,0,0,0,0,0,0
0,0,0,0,0,0,0,0,0,0,0,0,0,0,0,0,0,0,0
0,0,0,0,0,0,0,0,0,0,0,0,0,0,0,0,0,0,0
0,0,0,0,0,0,0,0,0,0,0,0,0,0,0,0,0,0,0
0,12,0,0,0,0,0,0,0,361,0,0,0,0,0,0,0,12,0
0,12,0,0,0,0,0,0,59,29,95,0,0,0,0,0,0,12,0
0,0,0,0,0,0,0,0,0,81,0,0,0,0,0,0,0,0,0
0,0,0,0,0,0,0,0,0,0,0,0,0,0,0,0,0,0,0
0,0,0,0,0,0,0,0,0,0,0,0,0,0,0,0,0,0,0
0,0,0,0,0,0,0,0,0,0,0,0,0,0,0,0,0,0,0
0,0,0,0,0,0,0,0,0,0,0,0,0,0,0,0,0,0,0
0,0,0,0,0,0,0,0,0,0,0,0,0,0,0,0,0,0,0
0,0,0,0,0,0,0,0,0,0,0,0,0,0,0,0,0,0,0
0,0,0,0,0,0,0,0,0,0,0,0,0,0,0,0,0,0,0
0,0,0,12,0,0,0,0,0,361,0,0,0,0,0,12,0,0,0
0,0,0,12,0,0,0,0,0,29,0,0,0,0,0,12,0,0,0
0,0,0,12,0,0,0,0,0,0,0,0,0,0,0,12,0,0,0
0,0,0,0,0,0,0,0,0,0,0,0,0,0,0,0,0,0,0
0,0,0,0,0,0,0,0,0,0,0,0,0,0,0,0,0,0,0
0,0,0,0,0,0,0,0,0,0,0,0,0,0,0,0,0,0,0
0,0,0,0,0,0,0,0,0,0,0,0,0,0,0,0,0,0,0
0,0,0,0,0,0,0,0,0,0,0,0,0,0,0,0,0,0,0
0,0,0,0,0,0,0,0,0,0,0,0,0,0,0,0,0,0,0
0,0,0,0,0,0,0,0,0,0,0,0,0,0,0,0,0,0,0
0,0,0,0,0,0,0,0,0,0,0,0,0,0,0,0,0,0,0
0,0,0,0,0,0,0,0,0,0,0,0,0,0,0,0,0,0,0
0,0,0,0,0,0,0,0,0,0,0,0,0,0,0,0,0,0,0
0,0,0,0,0,0,0,0,0,0,0,0,0,0,0,0,0,0,0
0,0,0,0,0,0,0,0,0,0,0,0,0,0,0,0,0,0,0
:endlayer
layer: 15
0,0,0,0,0,0,0,0,0,0,0,0,0,0,0,0,0,0,0
0,0,0,0,0,0,0,0,0,0,0,0,0,0,0,0,0,0,0
0,0,0,0,0,0,0,0,0,0,0,0,0,0,0,0,0,0,0
0,0,0,0,0,0,0,0,0,0,0,0,0,0,0,0,0,0,0
0,0,0,0,0,0,0,0,0,0,0,0,0,0,0,0,0,0,0
0,0,0,0,0,0,0,0,0,0,0,0,0,0,0,0,0,0,0
0,0,0,0,0,0,0,0,0,0,0,0,0,0,0,0,0,0,0
0,0,0,12,0,0,0,0,0,0,0,0,0,0,0,12,0,0,0
0,0,0,12,0,0,0,0,0,78,0,0,0,0,0,12,0,0,0
0,0,0,0,0,0,0,0,109,29,95,0,0,0,0,0,0,0,0
0,0,0,0,0,0,0,0,0,81,0,0,0,0,0,0,0,0,0
0,0,0,0,0,0,0,0,0,432,0,0,0,0,0,0,0,0,0
0,0,0,0,0,0,0,0,0,0,0,0,0,0,0,0,0,0,0
0,0,0,0,0,0,0,0,0,0,0,0,0,0,0,0,0,0,0
0,0,0,0,0,0,0,0,0,0,0,0,0,0,0,0,0,0,0
0,0,0,0,0,0,0,0,0,0,0,0,0,0,0,0,0,0,0
0,0,0,0,0,0,0,0,0,0,0,0,0,0,0,0,0,0,0
0,0,0,0,0,0,0,0,0,0,0,0,0,0,0,0,0,0,0
0,0,0,0,0,0,0,0,0,361,0,0,0,0,0,0,0,0,0
0,12,0,0,0,0,0,0,0,29,0,0,0,0,0,0,0,12,0
0,12,0,0,0,0,0,0,0,0,0,0,0,0,0,0,0,12,0
0,0,0,0,0,0,0,0,0,0,0,0,0,0,0,0,0,0,0
0,0,0,0,0,0,0,0,0,0,0,0,0,0,0,0,0,0,0
0,0,0,0,0,0,0,0,0,0,0,0,0,0,0,0,0,0,0
0,0,0,0,0,0,0,0,0,0,0,0,0,0,0,0,0,0,0
0,0,0,0,0,0,0,0,0,0,0,0,0,0,0,0,0,0,0
0,0,0,0,0,0,0,0,0,0,0,0,0,0,0,0,0,0,0
0,0,0,0,0,0,0,0,0,0,0,0,0,0,0,0,0,0,0
0,0,0,0,0,0,0,0,0,29,0,0,0,0,0,0,0,0,0
0,12,0,0,0,0,0,109,29,29,29,53,0,0,0,0,0,12,0
0,12,0,0,0,0,0,0,0,29,0,0,0,0,0,0,0,12,0
0,0,0,0,0,0,0,0,0,0,0,0,0,0,0,0,0,0,0
0,0,0,0,0,0,0,0,0,0,0,0,0,0,0,0,0,0,0
0,0,0,0,0,0,0,0,0,0,0,0,0,0,0,0,0,0,0
0,0,0,0,0,0,0,0,0,0,0,0,0,0,0,0,0,0,0
0,0,0,0,0,0,0,0,0,0,0,0,0,0,0,0,0,0,0
0,0,0,0,0,0,0,0,0,0,0,0,0,0,0,0,0,0,0
0,0,0,0,0,0,0,0,0,0,0,0,0,0,0,0,0,0,0
0,0,0,0,0,0,0,0,0,361,0,0,0,0,0,0,0,0,0
0,12,0,0,0,0,0,0,0,29,0,0,0,0,0,0,0,12,0
0,12,0,0,0,0,0,0,0,0,0,0,0,0,0,0,0,12,0
0,0,0,0,0,0,0,0,0,0,0,0,0,0,0,0,0,0,0
0,0,0,0,0,0,0,0,0,0,0,0,0,0,0,0,0,0,0
0,0,0,0,0,0,0,0,0,0,0,0,0,0,0,0,0,0,0
0,0,0,0,0,0,0,0,0,0,0,0,0,0,0,0,0,0,0
0,0,0,0,0,0,0,0,0,0,0,0,0,0,0,0,0,0,0
0,0,0,0,0,0,0,0,0,0,0,0,0,0,0,0,0,0,0
0,0,0,0,0,0,0,0,0,0,0,0,0,0,0,0,0,0,0
0,0,0,0,0,0,0,0,0,361,0,0,0,0,0,0,0,0,0
0,0,0,12,0,0,0,0,0,29,0,0,0,0,0,12,0,0,0
0,0,0,430,0,0,0,0,0,0,0,0,0,0,0,430,0,0,0
0,0,0,0,430,431,431,431,431,430,431,431,431,431,430,0,0,0,0
0,0,0,0,0,0,0,0,0,0,0,0,0,0,0,0,0,0,0
0,0,0,0,0,0,0,0,0,0,0,0,0,0,0,0,0,0,0
0,0,0,0,0,0,0,0,0,0,0,0,0,0,0,0,0,0,0
0,0,0,0,0,0,0,0,0,0,0,0,0,0,0,0,0,0,0
0,0,0,0,0,0,0,0,0,0,0,0,0,0,0,0,0,0,0
0,0,0,0,0,0,0,0,0,0,0,0,0,0,0,0,0,0,0
0,0,0,0,0,0,0,0,0,0,0,0,0,0,0,0,0,0,0
0,0,0,0,0,0,0,0,0,0,0,0,0,0,0,0,0,0,0
0,0,0,0,0,0,0,0,0,0,0,0,0,0,0,0,0,0,0
0,0,0,0,0,0,0,0,0,0,0,0,0,0,0,0,0,0,0
0,0,0,0,0,0,0,0,0,0,0,0,0,0,0,0,0,0,0
:endlayer
layer: 16
0,0,0,0,0,0,0,0,0,0,0,0,0,0,0,0,0,0,0
0,0,0,0,0,0,0,0,0,0,0,0,0,0,0,0,0,0,0
0,0,0,0,0,0,0,0,0,0,0,0,0,0,0,0,0,0,0
0,0,0,0,0,0,0,0,0,0,0,0,0,0,0,0,0,0,0
0,0,0,0,0,0,0,0,0,0,0,0,0,0,0,0,0,0,0
0,0,0,0,0,0,0,0,0,0,0,0,0,0,0,0,0,0,0
0,0,0,0,0,0,0,0,0,55,0,0,0,0,0,0,0,0,0
0,0,0,12,0,0,0,0,0,250,0,0,0,0,0,12,0,0,0
0,0,0,12,0,0,0,0,0,250,0,0,0,0,0,12,0,0,0
0,0,0,0,0,0,0,0,109,29,0,0,0,0,0,0,0,0,0
0,0,0,0,0,0,0,0,0,0,0,0,0,0,0,0,0,0,0
0,0,0,0,0,0,0,0,0,0,0,0,0,0,0,0,0,0,0
0,0,0,0,0,0,0,0,0,0,0,0,0,0,0,0,0,0,0
0,0,0,0,0,0,0,0,0,0,0,0,0,0,0,0,0,0,0
0,0,0,0,0,0,0,0,0,0,0,0,0,0,0,0,0,0,0
0,0,0,0,0,0,0,0,0,0,0,0,0,0,0,0,0,0,0
0,0,0,0,0,0,0,0,0,0,0,0,0,0,0,0,0,0,0
0,0,0,0,0,0,0,0,0,0,0,0,0,0,0,0,0,0,0
0,0,0,0,0,0,0,0,0,361,0,0,0,0,0,0,0,0,0
0,12,0,0,0,0,0,0,0,29,0,0,0,0,0,0,0,12,0
0,430,430,0,0,0,0,0,0,0,0,0,0,0,0,0,430,430,0
0,0,0,431,431,431,430,430,431,430,431,430,430,431,431,431,0,0,0
0,0,0,0,0,0,0,0,0,0,0,0,0,0,0,0,0,0,0
0,0,0,0,0,0,0,0,0,0,0,0,0,0,0,0,0,0,0
0,0,0,0,0,0,0,0,0,0,0,0,0,0,0,0,0,0,0
0,0,0,0,0,0,0,0,0,0,0,0,0,0,0,0,0,0,0
0,0,0,0,0,0,0,0,0,0,0,0,0,0,0,0,0,0,0
0,0,0,0,0,0,0,0,0,0,0,0,0,0,0,0,0,0,0
0,0,0,0,0,0,0,0,0,29,0,0,0,0,0,0,0,0,0
0,12,0,0,0,0,0,109,29,29,29,53,0,0,0,0,0,12,0
0,430,430,0,0,0,0,0,0,29,0,0,0,0,0,0,430,430,0
0,0,0,431,431,431,430,430,431,430,431,430,430,431,431,431,0,0,0
0,0,0,0,0,0,0,0,0,0,0,0,0,0,0,0,0,0,0
0,0,0,0,0,0,0,0,0,0,0,0,0,0,0,0,0,0,0
0,0,0,0,0,0,0,0,0,0,0,0,0,0,0,0,0,0,0
0,0,0,0,0,0,0,0,0,0,0,0,0,0,0,0,0,0,0
0,0,0,0,0,0,0,0,0,0,0,0,0,0,0,0,0,0,0
0,0,0,0,0,0,0,0,0,0,0,0,0,0,0,0,0,0,0
0,0,0,0,0,0,0,0,0,361,0,0,0,0,0,0,0,0,0
0,12,0,0,0,0,0,0,0,29,0,0,0,0,0,0,0,12,0
0,430,430,0,0,0,0,0,0,0,0,0,0,0,0,0,430,430,0
0,0,0,431,431,431,430,430,431,430,431,430,430,431,431,431,0,0,0
0,0,0,0,0,0,0,0,0,0,0,0,0,0,0,0,0,0,0
0,0,0,0,0,0,0,0,0,0,0,0,0,0,0,0,0,0,0
0,0,0,0,0,0,0,0,0,0,0,0,0,0,0,0,0,0,0
0,0,0,0,0,0,0,0,0,0,0,0,0,0,0,0,0,0,0
0,0,0,0,0,0,0,0,0,0,0,0,0,0,0,0,0,0,0
0,0,0,0,0,0,0,0,0,0,0,0,0,0,0,0,0,0,0
0,0,0,0,0,0,0,0,0,361,0,0,0,0,0,0,0,0,0
0,0,0,0,0,0,0,0,0,29,0,0,0,0,0,0,0,0,0
0,0,0,12,0,0,0,0,0,81,0,0,0,0,0,12,0,0,0
0,0,0,431,431,430,12,0,0,0,0,0,12,430,431,431,0,0,0
0,0,0,0,0,0,430,431,431,430,431,431,430,0,0,0,0,0,0
0,0,0,0,0,0,0,0,0,0,0,0,0,0,0,0,0,0,0
0,0,0,0,0,0,0,0,0,0,0,0,0,0,0,0,0,0,0
0,0,0,0,0,0,0,0,0,0,0,0,0,0,0,0,0,0,0
0,0,0,0,0,0,0,0,0,0,0,0,0,0,0,0,0,0,0
0,0,0,0,0,0,0,0,0,0,0,0,0,0,0,0,0,0,0
0,0,0,0,0,0,0,0,0,0,0,0,0,0,0,0,0,0,0
0,0,0,0,0,0,0,0,0,0,0,0,0,0,0,0,0,0,0
0,0,0,0,0,0,0,0,0,0,0,0,0,0,0,0,0,0,0
0,0,0,0,0,0,0,0,0,0,0,0,0,0,0,0,0,0,0
0,0,0,0,0,0,0,0,0,0,0,0,0,0,0,0,0,0,0
:endlayer
layer: 17
0,0,0,0,0,0,0,0,0,0,0,0,0,0,0,0,0,0,0
0,0,0,0,0,0,0,0,0,0,0,0,0,0,0,0,0,0,0
0,0,0,0,0,0,0,0,0,0,0,0,0,0,0,0,0,0,0
0,0,0,0,0,0,0,0,0,0,0,0,0,0,0,0,0,0,0
0,0,0,0,0,0,0,0,0,55,0,0,0,0,0,0,0,0,0
0,0,0,0,0,0,0,0,0,250,0,0,0,0,0,0,0,0,0
0,0,0,0,0,0,0,0,0,250,0,0,0,0,0,0,0,0,0
0,0,0,0,0,0,0,0,0,431,0,0,0,0,0,0,0,0,0
0,0,0,12,0,0,0,0,0,431,0,0,0,0,0,12,0,0,0
0,0,0,12,0,0,0,0,109,29,0,0,0,0,0,12,0,0,0
0,0,0,0,0,0,0,0,0,0,0,0,0,0,0,0,0,0,0
0,0,0,0,0,0,0,0,0,0,0,0,0,0,0,0,0,0,0
0,0,0,0,0,0,0,0,0,0,0,0,0,0,0,0,0,0,0
0,0,0,0,0,0,0,0,0,0,0,0,0,0,0,0,0,0,0
0,0,0,0,0,0,0,0,0,0,0,0,0,0,0,0,0,0,0
0,0,0,0,0,0,0,0,0,0,0,0,0,0,0,0,0,0,0
0,0,0,0,0,0,0,0,0,0,0,0,0,0,0,0,0,0,0
0,0,0,0,0,0,0,0,0,0,0,0,0,0,0,0,0,0,0
0,0,0,0,0,0,0,0,0,361,0,0,0,0,0,0,0,0,0
0,0,0,0,0,0,0,0,0,29,0,0,0,0,0,0,0,0,0
0,0,12,0,0,0,0,0,0,81,0,0,0,0,0,0,12,0,0
0,431,431,430,430,431,12,0,0,0,0,0,12,431,430,430,431,431,0
0,0,0,0,0,0,431,431,431,430,431,431,431,0,0,0,0,0,0
0,0,0,0,0,0,0,0,0,0,0,0,0,0,0,0,0,0,0
0,0,0,0,0,0,0,0,0,0,0,0,0,0,0,0,0,0,0
0,0,0,0,0,0,0,0,0,0,0,0,0,0,0,0,0,0,0
0,0,0,0,0,0,0,0,0,0,0,0,0,0,0,0,0,0,0
0,0,0,0,0,0,0,0,0,0,0,0,0,0,0,0,0,0,0
0,0,0,0,0,0,0,0,0,29,0,0,0,0,0,0,0,0,0
0,0,0,0,0,0,0,109,29,29,29,53,0,0,0,0,0,0,0
0,0,12,0,0,0,0,0,0,29,0,0,0,0,0,0,12,0,0
0,431,431,430,430,431,12,0,0,81,0,0,12,431,430,430,431,431,0
0,0,0,0,0,0,431,431,431,430,431,431,431,0,0,0,0,0,0
0,0,0,0,0,0,0,0,0,0,0,0,0,0,0,0,0,0,0
0,0,0,0,0,0,0,0,0,0,0,0,0,0,0,0,0,0,0
0,0,0,0,0,0,0,0,0,0,0,0,0,0,0,0,0,0,0
0,0,0,0,0,0,0,0,0,0,0,0,0,0,0,0,0,0,0
0,0,0,0,0,0,0,0,0,0,0,0,0,0,0,0,0,0,0
0,0,0,0,0,0,0,0,0,361,0,0,0,0,0,0,0,0,0
0,0,0,0,0,0,0,0,0,29,0,0,0,0,0,0,0,0,0
0,0,12,0,0,0,0,0,0,81,0,0,0,0,0,0,12,0,0
0,431,431,430,430,431,12,0,0,0,0,0,12,431,430,430,431,431,0
0,0,0,0,0,0,431,431,431,430,431,431,431,0,0,0,0,0,0
0,0,0,0,0,0,0,0,0,0,0,0,0,0,0,0,0,0,0
0,0,0,0,0,0,0,0,0,0,0,0,0,0,0,0,0,0,0
0,0,0,0,0,0,0,0,0,0,0,0,0,0,0,0,0,0,0
0,0,0,0,0,0,0,0,0,0,0,0,0,0,0,0,0,0,0
0,0,0,0,0,0,0,0,0,0,0,0,0,0,0,0,0,0,0
0,0,0,0,0,0,0,0,0,361,0,0,0,0,0,0,0,0,0
0,0,0,0,0,0,0,0,0,29,0,0,0,0,0,0,0,0,0
0,0,0,0,0,0,0,0,0,0,0,0,0,0,0,0,0,0,0
0,0,0,431,0,0,0,0,0,0,0,0,0,0,0,431,0,0,0
0,0,0,0,431,431,431,430,0,0,0,430,431,431,431,0,0,0,0
0,0,0,0,0,0,0,0,430,431,430,0,0,0,0,0,0,0,0
0,0,0,0,0,0,0,0,0,0,0,0,0,0,0,0,0,0,0
0,0,0,0,0,0,0,0,0,0,0,0,0,0,0,0,0,0,0
0,0,0,0,0,0,0,0,0,0,0,0,0,0,0,0,0,0,0
0,0,0,0,0,0,0,0,0,0,0,0,0,0,0,0,0,0,0
0,0,0,0,0,0,0,0,0,0,0,0,0,0,0,0,0,0,0
0,0,0,0,0,0,0,0,0,0,0,0,0,0,0,0,0,0,0
0,0,0,0,0,0,0,0,0,0,0,0,0,0,0,0,0,0,0
0,0,0,0,0,0,0,0,0,0,0,0,0,0,0,0,0,0,0
0,0,0,0,0,0,0,0,0,0,0,0,0,0,0,0,0,0,0
:endlayer
layer: 18
0,0,0,0,0,0,0,0,0,0,0,0,0,0,0,0,0,0,0
0,0,0,0,0,0,0,0,0,0,0,0,0,0,0,0,0,0,0
0,0,0,0,0,0,0,0,0,55,0,0,0,0,0,0,0,0,0
0,0,0,0,0,0,0,0,0,250,0,0,0,0,0,0,0,0,0
0,0,0,0,0,0,0,0,0,250,0,0,0,0,0,0,0,0,0
0,0,0,0,0,0,0,0,0,431,0,0,0,0,0,0,0,0,0
0,0,0,0,0,0,0,0,0,431,0,0,0,0,0,0,0,0,0
0,0,0,0,0,0,0,0,0,0,431,0,0,0,0,0,0,0,0
0,0,0,12,0,0,0,0,0,12,431,0,0,0,0,12,0,0,0
0,0,0,12,0,0,0,0,109,29,0,0,0,0,0,12,0,0,0
0,0,0,0,0,0,0,0,0,0,0,0,0,0,0,0,0,0,0
0,0,0,0,0,0,0,0,0,0,0,0,0,0,0,0,0,0,0
0,0,0,0,0,0,0,0,0,0,0,0,0,0,0,0,0,0,0
0,0,0,0,0,0,0,0,0,0,0,0,0,0,0,0,0,0,0
0,0,0,0,0,0,0,0,0,0,0,0,0,0,0,0,0,0,0
0,0,0,0,0,0,0,0,0,0,0,0,0,0,0,0,0,0,0
0,0,0,0,0,0,0,0,0,0,0,0,0,0,0,0,0,0,0
0,0,0,0,0,0,0,0,0,0,0,0,0,0,0,0,0,0,0
0,0,0,0,0,0,0,0,0,361,0,0,0,0,0,0,0,0,0
0,0,0,0,0,0,0,0,0,29,0,0,0,0,0,0,0,0,0
0,0,0,0,0,0,0,0,0,0,0,0,0,0,0,0,0,0,0
0,430,431,431,0,0,0,0,0,0,0,0,0,0,0,431,431,430,0
0,0,0,0,431,430,430,431,12,0,12,431,430,430,431,0,0,0,0
0,0,0,0,0,0,0,0,431,430,431,0,0,0,0,0,0,0,0
0,0,0,0,0,0,0,0,0,0,0,0,0,0,0,0,0,0,0
0,0,0,0,0,0,0,0,0,0,0,0,0,0,0,0,0,0,0
0,0,0,0,0,0,0,0,0,0,0,0,0,0,0,0,0,0,0
0,0,0,0,0,0,0,0,0,0,0,0,0,0,0,0,0,0,0
0,0,0,0,0,0,0,0,0,29,0,0,0,0,0,0,0,0,0
0,0,0,0,0,0,0,109,29,29,29,53,0,0,0,0,0,0,0
0,0,0,0,0,0,0,0,0,29,0,0,0,0,0,0,0,0,0
0,430,431,431,0,0,0,0,0,0,0,0,0,0,0,431,431,430,0
0,0,0,0,431,430,430,431,12,0,12,431,430,430,431,0,0,0,0
0,0,0,0,0,0,0,0,431,430,431,0,0,0,0,0,0,0,0
0,0,0,0,0,0,0,0,0,0,0,0,0,0,0,0,0,0,0
0,0,0,0,0,0,0,0,0,0,0,0,0,0,0,0,0,0,0
0,0,0,0,0,0,0,0,0,0,0,0,0,0,0,0,0,0,0
0,0,0,0,0,0,0,0,0,0,0,0,0,0,0,0,0,0,0
0,0,0,0,0,0,0,0,0,361,0,0,0,0,0,0,0,0,0
0,0,0,0,0,0,0,0,0,29,0,0,0,0,0,0,0,0,0
0,0,0,0,0,0,0,0,0,0,0,0,0,0,0,0,0,0,0
0,430,431,431,0,0,0,0,0,0,0,0,0,0,0,431,431,430,0
0,0,0,0,431,430,430,431,12,0,12,431,430,430,431,0,0,0,0
0,0,0,0,0,0,0,0,431,430,431,0,0,0,0,0,0,0,0
0,0,0,0,0,0,0,0,0,0,0,0,0,0,0,0,0,0,0
0,0,0,0,0,0,0,0,0,0,0,0,0,0,0,0,0,0,0
0,0,0,0,0,0,0,0,0,0,0,0,0,0,0,0,0,0,0
0,0,0,0,0,0,0,0,0,0,0,0,0,0,0,0,0,0,0
0,0,0,0,0,0,0,0,0,361,0,0,0,0,0,0,0,0,0
0,0,0,0,0,0,0,0,0,29,0,0,0,0,0,0,0,0,0
0,0,0,0,0,0,0,0,0,0,0,0,0,0,0,0,0,0,0
0,0,0,431,0,0,0,0,0,0,0,0,0,0,0,431,0,0,0
0,0,0,0,431,430,12,0,0,0,0,0,12,430,431,0,0,0,0
0,0,0,0,0,0,430,431,431,430,431,431,430,0,0,0,0,0,0
0,0,0,0,0,0,0,0,0,0,0,0,0,0,0,0,0,0,0
0,0,0,0,0,0,0,0,0,0,0,0,0,0,0,0,0,0,0
0,0,0,0,0,0,0,0,0,0,0,0,0,0,0,0,0,0,0
0,0,0,0,0,0,0,0,0,0,0,0,0,0,0,0,0,0,0
0,0,0,0,0,0,0,0,0,0,0,0,0,0,0,0,0,0,0
0,0,0,0,0,0,0,0,0,0,0,0,0,0,0,0,0,0,0
0,0,0,0,0,0,0,0,0,0,0,0,0,0,0,0,0,0,0
0,0,0,0,0,0,0,0,0,0,0,0,0,0,0,0,0,0,0
0,0,0,0,0,0,0,0,0,0,0,0,0,0,0,0,0,0,0
:endlayer
layer: 19
0,0,0,0,0,0,0,0,0,55,0,0,0,0,0,0,0,0,0
0,0,0,0,0,0,0,0,0,250,0,0,0,0,0,0,0,0,0
0,0,0,0,0,0,0,0,0,250,0,0,0,0,0,0,0,0,0
0,0,0,0,0,0,0,0,0,431,0,0,0,0,0,0,0,0,0
0,0,0,0,0,0,0,0,0,431,0,0,0,0,0,0,0,0,0
0,0,0,0,0,0,0,0,0,12,431,0,0,0,0,0,0,0,0
0,0,0,0,0,0,0,0,0,0,431,0,0,0,0,0,0,0,0
0,0,0,0,0,0,0,0,0,0,431,0,0,0,0,0,0,0,0
0,0,0,0,0,0,0,0,0,0,431,0,0,0,0,0,0,0,0
0,0,0,12,0,0,0,0,109,29,0,0,0,0,0,12,0,0,0
0,0,0,12,0,0,0,0,0,0,0,0,0,0,0,12,0,0,0
0,0,0,0,0,0,0,0,0,0,0,0,0,0,0,0,0,0,0
0,0,0,0,0,0,0,0,0,0,0,0,0,0,0,0,0,0,0
0,0,0,0,0,0,0,0,0,0,0,0,0,0,0,0,0,0,0
0,0,0,0,0,0,0,0,0,0,0,0,0,0,0,0,0,0,0
0,0,0,0,0,0,0,0,0,0,0,0,0,0,0,0,0,0,0
0,0,0,0,0,0,0,0,0,0,0,0,0,0,0,0,0,0,0
0,0,0,0,0,0,0,0,0,0,0,0,0,0,0,0,0,0,0
0,0,0,0,0,0,0,0,0,361,0,0,0,0,0,0,0,0,0
0,0,0,0,0,0,0,0,0,29,0,0,0,0,0,0,0,0,0
0,0,0,0,0,0,0,0,0,0,0,0,0,0,0,0,0,0,0
0,431,0,0,0,0,0,0,0,0,0,0,0,0,0,0,0,431,0
0,0,431,431,431,431,0,0,0,0,0,0,0,431,431,431,431,0,0
0,0,0,0,0,0,431,430,430,431,430,430,431,0,0,0,0,0,0
0,0,0,0,0,0,0,0,0,0,0,0,0,0,0,0,0,0,0
0,0,0,0,0,0,0,0,0,0,0,0,0,0,0,0,0,0,0
0,0,0,0,0,0,0,0,0,0,0,0,0,0,0,0,0,0,0
0,0,0,0,0,0,0,0,0,0,0,0,0,0,0,0,0,0,0
0,0,0,0,0,0,0,0,0,29,0,0,0,0,0,0,0,0,0
0,0,0,0,0,0,0,109,29,29,29,53,0,0,0,0,0,0,0
0,0,0,0,0,0,0,0,0,29,0,0,0,0,0,0,0,0,0
0,431,0,0,0,0,0,0,0,0,0,0,0,0,0,0,0,431,0
0,0,431,431,431,431,0,0,0,0,0,0,0,431,431,431,431,0,0
0,0,0,0,0,0,431,430,430,431,430,430,431,0,0,0,0,0,0
0,0,0,0,0,0,0,0,0,0,0,0,0,0,0,0,0,0,0
0,0,0,0,0,0,0,0,0,0,0,0,0,0,0,0,0,0,0
0,0,0,0,0,0,0,0,0,0,0,0,0,0,0,0,0,0,0
0,0,0,0,0,0,0,0,0,0,0,0,0,0,0,0,0,0,0
0,0,0,0,0,0,0,0,0,361,0,0,0,0,0,0,0,0,0
0,0,0,0,0,0,0,0,0,29,0,0,0,0,0,0,0,0,0
0,0,0,0,0,0,0,0,0,0,0,0,0,0,0,0,0,0,0
0,431,0,0,0,0,0,0,0,0,0,0,0,0,0,0,0,431,0
0,0,431,431,431,431,0,0,0,0,0,0,0,431,431,431,431,0,0
0,0,0,0,0,0,431,430,430,431,430,430,431,0,0,0,0,0,0
0,0,0,0,0,0,0,0,0,0,0,0,0,0,0,0,0,0,0
0,0,0,0,0,0,0,0,0,0,0,0,0,0,0,0,0,0,0
0,0,0,0,0,0,0,0,0,0,0,0,0,0,0,0,0,0,0
0,0,0,0,0,0,0,0,0,0,0,0,0,0,0,0,0,0,0
0,0,0,0,0,0,0,0,0,361,0,0,0,0,0,0,0,0,0
0,0,0,0,0,0,0,0,0,29,0,0,0,0,0,0,0,0,0
0,0,0,0,0,0,0,0,0,0,0,0,0,0,0,0,0,0,0
0,0,0,431,0,0,0,0,0,0,0,0,0,0,0,431,0,0,0
0,0,0,0,431,431,431,430,0,0,0,430,431,431,431,0,0,0,0
0,0,0,0,0,0,0,0,430,431,430,0,0,0,0,0,0,0,0
0,0,0,0,0,0,0,0,0,0,0,0,0,0,0,0,0,0,0
0,0,0,0,0,0,0,0,0,0,0,0,0,0,0,0,0,0,0
0,0,0,0,0,0,0,0,0,0,0,0,0,0,0,0,0,0,0
0,0,0,0,0,0,0,0,0,0,0,0,0,0,0,0,0,0,0
0,0,0,0,0,0,0,0,0,0,0,0,0,0,0,0,0,0,0
0,0,0,0,0,0,0,0,0,0,0,0,0,0,0,0,0,0,0
0,0,0,0,0,0,0,0,0,0,0,0,0,0,0,0,0,0,0
0,0,0,0,0,0,0,0,0,0,0,0,0,0,0,0,0,0,0
0,0,0,0,0,0,0,0,0,0,0,0,0,0,0,0,0,0,0
:endlayer
layer: 20
0,0,0,0,0,0,0,0,0,175,0,0,0,0,0,0,0,0,0
0,0,0,0,0,0,0,0,0,431,0,0,0,0,0,0,0,0,0
0,0,0,0,0,0,0,0,0,431,0,0,0,0,0,0,0,0,0
0,0,0,0,0,0,0,0,0,12,431,0,0,0,0,0,0,0,0
0,0,0,0,0,0,0,0,0,0,431,0,0,0,0,0,0,0,0
0,0,0,0,0,0,0,0,0,0,431,0,0,0,0,0,0,0,0
0,0,0,0,0,0,0,0,0,0,0,431,0,0,0,0,0,0,0
0,0,0,0,0,0,0,0,0,0,0,431,0,0,0,0,0,0,0
0,0,0,0,0,0,0,0,0,0,431,0,0,0,0,0,0,0,0
0,0,0,12,0,0,0,0,109,29,0,0,0,0,0,12,0,0,0
0,0,0,430,0,0,0,0,0,0,0,0,0,0,0,430,0,0,0
0,0,0,0,430,431,431,431,431,430,431,431,431,431,430,0,0,0,0
0,0,0,0,0,0,0,0,0,0,0,0,0,0,0,0,0,0,0
0,0,0,0,0,0,0,0,0,0,0,0,0,0,0,0,0,0,0
0,0,0,0,0,0,0,0,0,0,0,0,0,0,0,0,0,0,0
0,0,0,0,0,0,0,0,0,0,0,0,0,0,0,0,0,0,0
0,0,0,0,0,0,0,0,0,0,0,0,0,0,0,0,0,0,0
0,0,0,0,0,0,0,0,0,0,0,0,0,0,0,0,0,0,0
0,0,0,0,0,0,0,0,0,361,0,0,0,0,0,0,0,0,0
0,0,0,0,0,0,0,0,0,29,0,0,0,0,0,0,0,0,0
0,0,0,0,0,0,0,0,0,0,0,0,0,0,0,0,0,0,0
0,430,12,0,0,0,0,0,0,0,0,0,0,0,0,0,12,430,0
0,0,430,430,12,0,0,0,0,0,0,0,0,0,12,430,430,0,0
0,0,0,0,430,430,430,431,431,430,431,431,430,430,430,0,0,0,0
0,0,0,0,0,0,0,0,0,0,0,0,0,0,0,0,0,0,0
0,0,0,0,0,0,0,0,0,0,0,0,0,0,0,0,0,0,0
0,0,0,0,0,0,0,0,0,0,0,0,0,0,0,0,0,0,0
0,0,0,0,0,0,0,0,0,0,0,0,0,0,0,0,0,0,0
0,0,0,0,0,0,0,0,140,29,140,0,0,0,0,0,0,0,0
0,0,0,0,0,0,0,109,29,29,29,53,0,0,0,0,0,0,0
0,0,0,0,0,0,0,0,140,29,140,0,0,0,0,0,0,0,0
0,430,12,0,0,0,0,0,0,0,0,0,0,0,0,0,12,430,0
0,0,430,430,12,0,0,0,0,0,0,0,0,0,12,430,430,0,0
0,0,0,0,430,430,430,431,431,430,431,431,430,430,430,0,0,0,0
0,0,0,0,0,0,0,0,0,0,0,0,0,0,0,0,0,0,0
0,0,0,0,0,0,0,0,0,0,0,0,0,0,0,0,0,0,0
0,0,0,0,0,0,0,0,0,0,0,0,0,0,0,0,0,0,0
0,0,0,0,0,0,0,0,0,0,0,0,0,0,0,0,0,0,0
0,0,0,0,0,0,0,0,0,361,0,0,0,0,0,0,0,0,0
0,0,0,0,0,0,0,0,0,29,0,0,0,0,0,0,0,0,0
0,0,0,0,0,0,0,0,0,0,0,0,0,0,0,0,0,0,0
0,430,12,0,0,0,0,0,0,0,0,0,0,0,0,0,12,430,0
0,0,430,430,12,0,0,0,0,0,0,0,0,0,12,430,430,0,0
0,0,0,0,430,430,430,431,431,430,431,431,430,430,430,0,0,0,0
0,0,0,0,0,0,0,0,0,0,0,0,0,0,0,0,0,0,0
0,0,0,0,0,0,0,0,0,0,0,0,0,0,0,0,0,0,0
0,0,0,0,0,0,0,0,0,0,0,0,0,0,0,0,0,0,0
0,0,0,0,0,0,0,0,0,0,0,0,0,0,0,0,0,0,0
0,0,0,0,0,0,0,0,0,361,0,0,0,0,0,0,0,0,0
0,0,0,0,0,0,0,0,0,29,0,0,0,0,0,0,0,0,0
0,0,0,12,0,0,0,0,0,0,0,0,0,0,0,12,0,0,0
0,0,0,431,431,430,12,0,0,0,0,0,12,430,431,431,0,0,0
0,0,0,0,0,0,430,431,431,430,431,431,430,0,0,0,0,0,0
0,0,0,0,0,0,0,0,0,0,0,0,0,0,0,0,0,0,0
0,0,0,0,0,0,0,0,0,0,0,0,0,0,0,0,0,0,0
0,0,0,0,0,0,0,0,0,0,0,0,0,0,0,0,0,0,0
0,0,0,0,0,0,0,0,0,0,0,0,0,0,0,0,0,0,0
0,0,0,0,0,0,0,0,0,0,0,0,0,0,0,0,0,0,0
0,0,0,0,0,0,0,0,0,0,0,0,0,0,0,0,0,0,0
0,0,0,0,0,0,0,0,0,0,0,0,0,0,0,0,0,0,0
0,0,0,0,0,0,0,0,0,0,0,0,0,0,0,0,0,0,0
0,0,0,0,0,0,0,0,0,0,0,0,0,0,0,0,0,0,0
0,0,0,0,0,0,0,0,0,0,0,0,0,0,0,0,0,0,0
:endlayer
layer: 21
0,0,0,0,0,0,0,0,0,0,0,0,0,0,0,0,0,0,0
0,0,0,0,0,0,0,0,0,12,431,0,0,0,0,0,0,0,0
0,0,0,0,0,0,0,0,0,0,431,0,0,0,0,0,0,0,0
0,0,0,0,0,0,0,0,0,0,431,0,0,0,0,0,0,0,0
0,0,0,0,0,0,0,0,0,0,0,431,0,0,0,0,0,0,0
0,0,0,0,0,0,0,0,0,0,0,431,0,0,0,0,0,0,0
0,0,0,0,0,0,0,0,0,0,0,431,0,0,0,0,0,0,0
0,0,0,0,0,0,0,0,0,0,12,431,0,0,0,0,0,0,0
0,0,0,0,0,0,0,0,0,0,431,0,0,0,0,0,0,0,0
0,0,0,0,0,0,0,0,109,29,0,0,0,0,0,0,0,0,0
0,0,0,12,0,0,0,0,0,81,0,0,0,0,0,12,0,0,0
0,0,0,431,431,430,12,0,0,0,0,0,12,430,431,431,0,0,0
0,0,0,0,0,0,430,431,431,430,431,431,430,0,0,0,0,0,0
0,0,0,0,0,0,0,0,0,0,0,0,0,0,0,0,0,0,0
0,0,0,0,0,0,0,0,0,0,0,0,0,0,0,0,0,0,0
0,0,0,0,0,0,0,0,0,0,0,0,0,0,0,0,0,0,0
0,0,0,0,0,0,0,0,0,0,0,0,0,0,0,0,0,0,0
0,0,0,0,0,0,0,0,0,0,0,0,0,0,0,0,0,0,0
0,0,0,0,0,0,0,0,0,361,0,0,0,0,0,0,0,0,0
0,0,0,0,0,0,0,0,0,29,0,0,0,0,0,0,0,0,0
0,0,0,0,0,0,0,0,0,0,0,0,0,0,0,0,0,0,0
0,431,0,0,0,0,0,0,0,0,0,0,0,0,0,0,0,431,0
0,0,431,431,431,431,0,0,0,0,0,0,0,431,431,431,431,0,0
0,0,0,0,0,0,431,430,430,431,430,430,431,0,0,0,0,0,0
0,0,0,0,0,0,0,0,0,0,0,0,0,0,0,0,0,0,0
0,0,0,0,0,0,0,0,0,0,0,0,0,0,0,0,0,0,0
0,0,0,0,0,0,0,0,0,0,0,0,0,0,0,0,0,0,0
0,0,0,0,0,0,0,0,55,55,55,0,0,0,0,0,0,0,0
0,0,0,0,0,0,0,55,66,250,54,55,0,0,0,0,0,0,0
0,0,0,0,0,0,0,109,227,29,227,53,0,0,0,0,0,0,0
0,0,0,0,0,0,0,55,66,250,54,55,0,0,0,0,0,0,0
0,431,0,0,0,0,0,0,55,55,55,0,0,0,0,0,0,431,0
0,0,431,431,431,431,0,0,0,0,0,0,0,431,431,431,431,0,0
0,0,0,0,0,0,431,430,430,431,430,430,431,0,0,0,0,0,0
0,0,0,0,0,0,0,0,0,0,0,0,0,0,0,0,0,0,0
0,0,0,0,0,0,0,0,0,0,0,0,0,0,0,0,0,0,0
0,0,0,0,0,0,0,0,0,0,0,0,0,0,0,0,0,0,0
0,0,0,0,0,0,0,0,0,0,0,0,0,0,0,0,0,0,0
0,0,0,0,0,0,0,0,0,361,0,0,0,0,0,0,0,0,0
0,0,0,0,0,0,0,0,0,29,0,0,0,0,0,0,0,0,0
0,0,0,0,0,0,0,0,0,0,0,0,0,0,0,0,0,0,0
0,431,0,0,0,0,0,0,0,0,0,0,0,0,0,0,0,431,0
0,0,431,431,431,431,0,0,0,0,0,0,0,431,431,431,431,0,0
0,0,0,0,0,0,431,430,430,431,430,430,431,0,0,0,0,0,0
0,0,0,0,0,0,0,0,0,0,0,0,0,0,0,0,0,0,0
0,0,0,0,0,0,0,0,0,0,0,0,0,0,0,0,0,0,0
0,0,0,0,0,0,0,0,0,0,0,0,0,0,0,0,0,0,0
0,0,0,0,0,0,0,0,0,0,0,0,0,0,0,0,0,0,0
0,0,0,0,0,0,0,0,0,361,0,0,0,0,0,0,0,0,0
0,0,0,0,0,0,0,0,0,29,0,0,0,0,0,0,0,0,0
0,0,0,430,0,0,0,0,0,0,0,0,0,0,0,430,0,0,0
0,0,0,0,430,431,431,431,431,430,431,431,431,431,430,0,0,0,0
0,0,0,0,0,0,0,0,0,0,0,0,0,0,0,0,0,0,0
0,0,0,0,0,0,0,0,0,0,0,0,0,0,0,0,0,0,0
0,0,0,0,0,0,0,0,0,0,0,0,0,0,0,0,0,0,0
0,0,0,0,0,0,0,0,0,0,0,0,0,0,0,0,0,0,0
0,0,0,0,0,0,0,0,0,0,0,0,0,0,0,0,0,0,0
0,0,0,0,0,0,0,0,0,0,0,0,0,0,0,0,0,0,0
0,0,0,0,0,0,0,0,0,0,0,0,0,0,0,0,0,0,0
0,0,0,0,0,0,0,0,0,0,0,0,0,0,0,0,0,0,0
0,0,0,0,0,0,0,0,0,0,0,0,0,0,0,0,0,0,0
0,0,0,0,0,0,0,0,0,0,0,0,0,0,0,0,0,0,0
0,0,0,0,0,0,0,0,0,0,0,0,0,0,0,0,0,0,0
:endlayer
layer: 22
0,0,0,0,0,0,0,0,0,0,0,0,0,0,0,0,0,0,0
0,0,0,0,0,0,0,0,0,0,431,0,0,0,0,0,0,0,0
0,0,0,0,0,0,0,0,0,0,0,430,0,0,0,0,0,0,0
0,0,0,0,0,0,0,0,0,0,0,431,0,0,0,0,0,0,0
0,0,0,0,0,0,0,0,0,0,0,430,0,0,0,0,0,0,0
0,0,0,0,0,0,0,0,0,0,0,431,0,0,0,0,0,0,0
0,0,0,0,0,0,0,0,0,0,0,430,0,0,0,0,0,0,0
0,0,0,0,0,0,0,0,0,0,0,431,0,0,0,0,0,0,0
0,0,0,0,0,0,0,0,0,0,431,0,0,0,0,0,0,0,0
0,0,0,0,0,0,0,0,109,29,0,0,0,0,0,0,0,0,0
0,0,0,0,0,0,0,0,0,0,0,0,0,0,0,0,0,0,0
0,0,0,431,0,0,0,0,0,0,0,0,0,0,0,431,0,0,0
0,0,0,0,431,431,431,430,0,0,0,430,431,431,431,0,0,0,0
0,0,0,0,0,0,0,0,430,431,430,0,0,0,0,0,0,0,0
0,0,0,0,0,0,0,0,0,0,0,0,0,0,0,0,0,0,0
0,0,0,0,0,0,0,0,0,0,0,0,0,0,0,0,0,0,0
0,0,0,0,0,0,0,0,0,0,0,0,0,0,0,0,0,0,0
0,0,0,0,0,0,0,0,0,0,0,0,0,0,0,0,0,0,0
0,0,0,0,0,0,0,0,0,361,0,0,0,0,0,0,0,0,0
0,0,0,0,0,0,0,0,0,29,0,0,0,0,0,0,0,0,0
0,0,0,0,0,0,0,0,0,0,0,0,0,0,0,0,0,0,0
0,430,431,431,0,0,0,0,0,0,0,0,0,0,0,431,431,430,0
0,0,0,0,431,430,430,431,12,0,12,431,430,430,431,0,0,0,0
0,0,0,0,0,0,0,0,431,430,431,0,0,0,0,0,0,0,0
0,0,0,0,0,0,0,0,0,0,0,0,0,0,0,0,0,0,0
0,0,0,0,0,0,0,0,0,0,0,0,0,0,0,0,0,0,0
0,0,0,0,0,0,0,0,0,0,0,0,0,0,0,0,0,0,0
0,0,0,0,0,0,0,433,68,68,68,168,0,0,0,0,0,0,0
0,0,0,0,0,0,433,68,0,361,0,68,168,0,0,0,0,0,0
0,0,0,0,0,0,433,0,0,29,0,0,168,0,0,0,0,0,0
0,0,0,0,0,0,433,428,0,0,0,428,168,0,0,0,0,0,0
0,430,431,431,0,0,0,433,428,428,428,168,0,0,0,431,431,430,0
0,0,0,0,431,430,430,431,12,0,12,431,430,430,431,0,0,0,0
0,0,0,0,0,0,0,0,431,430,431,0,0,0,0,0,0,0,0
0,0,0,0,0,0,0,0,0,0,0,0,0,0,0,0,0,0,0
0,0,0,0,0,0,0,0,0,0,0,0,0,0,0,0,0,0,0
0,0,0,0,0,0,0,0,0,0,0,0,0,0,0,0,0,0,0
0,0,0,0,0,0,0,0,0,0,0,0,0,0,0,0,0,0,0
0,0,0,0,0,0,0,0,0,361,0,0,0,0,0,0,0,0,0
0,0,0,0,0,0,0,0,0,29,0,0,0,0,0,0,0,0,0
0,0,0,0,0,0,0,0,0,0,0,0,0,0,0,0,0,0,0
0,430,431,431,0,0,0,0,0,0,0,0,0,0,0,431,431,430,0
0,0,0,0,431,430,430,431,12,0,12,431,430,430,431,0,0,0,0
0,0,0,0,0,0,0,0,431,430,431,0,0,0,0,0,0,0,0
0,0,0,0,0,0,0,0,0,0,0,0,0,0,0,0,0,0,0
0,0,0,0,0,0,0,0,0,0,0,0,0,0,0,0,0,0,0
0,0,0,0,0,0,0,0,0,0,0,0,0,0,0,0,0,0,0
0,0,0,12,0,0,0,0,0,0,0,0,0,0,0,12,0,0,0
0,0,0,12,0,0,0,0,0,361,0,0,0,0,0,12,0,0,0
0,0,0,12,0,0,0,0,0,29,0,0,0,0,0,12,0,0,0
0,0,66,227,227,227,227,227,227,227,227,227,227,227,227,227,54,0,0
0,0,0,0,0,0,0,0,0,77,0,0,0,0,0,0,0,0,0
0,0,0,0,0,0,0,0,0,0,0,0,0,0,0,0,0,0,0
0,0,0,0,0,0,0,0,0,0,0,0,0,0,0,0,0,0,0
0,0,0,0,0,0,0,0,0,0,0,0,0,0,0,0,0,0,0
0,0,0,0,0,0,0,0,0,0,0,0,0,0,0,0,0,0,0
0,0,0,0,0,0,0,0,0,0,0,0,0,0,0,0,0,0,0
0,0,0,0,0,0,0,0,0,0,0,0,0,0,0,0,0,0,0
0,0,0,0,0,0,0,0,0,0,0,0,0,0,0,0,0,0,0
0,0,0,0,0,0,0,0,0,0,0,0,0,0,0,0,0,0,0
0,0,0,0,0,0,0,0,0,0,0,0,0,0,0,0,0,0,0
0,0,0,0,0,0,0,0,0,0,0,0,0,0,0,0,0,0,0
0,0,0,0,0,0,0,0,0,0,0,0,0,0,0,0,0,0,0
:endlayer
layer: 23
0,0,0,0,0,0,0,0,0,0,431,0,0,0,0,0,0,0,0
0,0,0,0,0,0,0,0,0,0,431,0,0,0,0,0,0,0,0
0,0,0,0,0,0,0,0,0,0,12,431,0,0,0,0,0,0,0
0,0,0,0,0,0,0,0,0,0,0,431,0,0,0,0,0,0,0
0,0,0,0,0,0,0,0,0,0,0,430,0,0,0,0,0,0,0
0,0,0,0,0,0,0,0,0,0,0,431,0,0,0,0,0,0,0
0,0,0,0,0,0,0,0,0,0,0,431,0,0,0,0,0,0,0
0,0,0,0,0,0,0,0,0,0,431,0,0,0,0,0,0,0,0
0,0,0,0,0,0,0,0,0,12,431,0,0,0,0,0,0,0,0
0,0,0,0,0,0,0,0,109,29,0,0,0,0,0,0,0,0,0
0,0,0,0,0,0,0,0,0,0,0,0,0,0,0,0,0,0,0
0,0,0,431,0,0,0,0,0,0,0,0,0,0,0,431,0,0,0
0,0,0,0,431,430,12,0,0,0,0,0,12,430,431,0,0,0,0
0,0,0,0,0,0,430,431,431,430,431,431,430,0,0,0,0,0,0
0,0,0,0,0,0,0,0,0,0,0,0,0,0,0,0,0,0,0
0,0,0,0,0,0,0,0,0,0,0,0,0,0,0,0,0,0,0
0,0,0,0,0,0,0,0,0,0,0,0,0,0,0,0,0,0,0
0,0,0,0,0,0,0,0,0,0,0,0,0,0,0,0,0,0,0
0,0,0,0,0,0,0,0,0,361,0,0,0,0,0,0,0,0,0
0,0,0,0,0,0,0,0,0,29,0,0,0,0,0,0,0,0,0
0,0,12,0,0,0,0,0,0,0,0,0,0,0,0,0,12,0,0
0,431,431,430,430,431,12,0,0,0,0,0,12,431,430,430,431,431,0
0,0,0,0,0,0,431,431,431,430,431,431,431,0,0,0,0,0,0
0,0,0,0,0,0,0,0,0,0,0,0,0,0,0,0,0,0,0
0,0,0,0,0,0,0,0,0,0,0,0,0,0,0,0,0,0,0
0,0,0,0,0,0,0,0,0,0,0,0,0,0,0,0,0,0,0
0,0,0,0,0,0,0,0,0,0,0,0,0,0,0,0,0,0,0
0,0,0,0,0,0,0,0,0,0,0,0,0,0,0,0,0,0,0
0,0,0,0,0,0,0,0,0,361,0,0,0,0,0,0,0,0,0
0,0,0,0,0,0,0,0,0,29,0,0,0,0,0,0,0,0,0
0,0,12,0,0,0,0,0,0,0,0,0,0,0,0,0,12,0,0
0,431,431,430,430,431,12,0,0,0,0,0,12,431,430,430,431,431,0
0,0,0,0,0,0,431,431,431,430,431,431,431,0,0,0,0,0,0
0,0,0,0,0,0,0,0,0,0,0,0,0,0,0,0,0,0,0
0,0,0,0,0,0,0,0,0,0,0,0,0,0,0,0,0,0,0
0,0,0,0,0,0,0,0,0,0,0,0,0,0,0,0,0,0,0
0,0,0,0,0,0,0,0,0,0,0,0,0,0,0,0,0,0,0
0,0,0,0,0,0,0,0,0,0,0,0,0,0,0,0,0,0,0
0,0,0,0,0,0,0,0,0,361,0,0,0,0,0,0,0,0,0
0,0,0,0,0,0,0,0,0,29,0,0,0,0,0,0,0,0,0
0,0,12,0,0,0,0,0,0,0,0,0,0,0,0,0,12,0,0
0,431,431,430,430,431,12,0,0,0,0,0,12,431,430,430,431,431,0
0,0,0,0,0,0,431,431,431,430,431,431,431,0,0,0,0,0,0
0,0,0,0,0,0,0,0,0,0,0,0,0,0,0,0,0,0,0
0,0,0,0,0,0,0,0,0,0,0,0,0,0,0,0,0,0,0
0,0,12,12,0,0,0,0,0,0,0,0,0,0,0,12,12,0,0
0,0,12,12,0,0,0,0,0,0,0,0,0,0,0,12,12,0,0
0,0,12,12,0,0,0,0,0,0,0,0,0,0,0,12,12,0,0
0,0,0,0,0,0,0,0,0,361,0,0,0,0,0,0,0,0,0
0,0,0,0,0,0,0,0,0,29,0,0,0,0,0,0,0,0,0
0,0,0,175,0,0,0,0,0,24,0,0,0,0,0,175,0,0,0
0,0,0,0,0,0,0,0,0,312,0,0,0,0,0,0,0,0,0
0,0,0,0,0,0,0,0,0,0,0,0,0,0,0,0,0,0,0
0,0,0,0,0,0,0,0,0,0,0,0,0,0,0,0,0,0,0
0,0,0,0,0,0,0,0,0,0,0,0,0,0,0,0,0,0,0
0,0,0,0,0,0,0,0,0,0,0,0,0,0,0,0,0,0,0
0,0,0,0,0,0,0,0,0,0,0,0,0,0,0,0,0,0,0
0,0,0,0,0,0,0,0,0,0,0,0,0,0,0,0,0,0,0
0,0,0,0,0,0,0,0,0,0,0,0,0,0,0,0,0,0,0
0,0,0,0,0,0,0,0,0,0,0,0,0,0,0,0,0,0,0
0,0,0,0,0,0,0,0,0,0,0,0,0,0,0,0,0,0,0
0,0,0,0,0,0,0,0,0,0,0,0,0,0,0,0,0,0,0
0,0,0,0,0,0,0,0,0,0,0,0,0,0,0,0,0,0,0
:endlayer
layer: 24
0,0,0,0,0,0,0,0,0,0,431,0,0,0,0,0,0,0,0
0,0,0,0,0,0,0,0,0,0,0,431,0,0,0,0,0,0,0
0,0,0,0,0,0,0,0,0,0,0,430,0,0,0,0,0,0,0
0,0,0,0,0,0,0,0,0,0,0,430,0,0,0,0,0,0,0
0,0,0,0,0,0,0,0,0,0,0,431,0,0,0,0,0,0,0
0,0,0,0,0,0,0,0,0,0,0,430,0,0,0,0,0,0,0
0,0,0,0,0,0,0,0,0,0,430,0,0,0,0,0,0,0,0
0,0,0,0,0,0,0,0,0,12,431,0,0,0,0,0,0,0,0
0,0,0,0,0,0,0,0,0,431,0,0,0,0,0,0,0,0,0
0,0,0,0,0,0,0,0,109,29,0,0,0,0,0,0,0,0,0
0,0,0,0,0,0,0,0,0,0,0,0,0,0,0,0,0,0,0
0,0,0,431,0,0,0,0,0,0,0,0,0,0,0,431,0,0,0
0,0,0,0,431,431,431,430,0,0,0,430,431,431,431,0,0,0,0
0,0,0,0,0,0,0,0,430,431,430,0,0,0,0,0,0,0,0
0,0,0,0,0,0,0,0,0,0,0,0,0,0,0,0,0,0,0
0,0,0,0,0,0,0,0,0,0,0,0,0,0,0,0,0,0,0
0,0,0,0,0,0,0,0,0,0,0,0,0,0,0,0,0,0,0
0,0,0,0,0,0,0,0,0,0,0,0,0,0,0,0,0,0,0
0,0,0,0,0,0,0,0,0,361,0,0,0,0,0,0,0,0,0
0,0,0,0,0,0,0,0,0,29,0,0,0,0,0,0,0,0,0
0,430,430,0,0,0,0,0,0,0,0,0,0,0,0,0,430,430,0
0,0,0,431,431,431,430,430,431,430,431,430,430,431,431,431,0,0,0
0,0,0,0,0,0,0,0,0,0,0,0,0,0,0,0,0,0,0
0,12,0,0,0,0,0,0,0,0,0,0,0,0,0,0,0,12,0
0,12,0,0,0,0,0,0,0,0,0,0,0,0,0,0,0,12,0
0,12,0,0,0,0,0,0,0,0,0,0,0,0,0,0,0,12,0
0,12,0,0,0,0,0,0,0,0,0,0,0,0,0,0,0,12,0
0,12,0,0,0,0,0,0,0,0,0,0,0,0,0,0,0,12,0
0,0,0,0,0,0,0,0,0,361,0,0,0,0,0,0,0,0,0
0,0,0,0,0,0,0,0,59,29,95,0,0,0,0,0,0,0,0
0,430,430,0,0,0,0,0,0,81,0,0,0,0,0,0,430,430,0
0,0,0,431,431,431,430,430,431,430,431,430,430,431,431,431,0,0,0
0,0,0,0,0,0,0,0,0,0,0,0,0,0,0,0,0,0,0
0,12,0,0,0,0,0,0,0,0,0,0,0,0,0,0,0,12,0
0,12,0,0,0,0,0,0,0,0,0,0,0,0,0,0,0,12,0
0,12,0,0,0,0,0,0,0,0,0,0,0,0,0,0,0,12,0
0,12,0,0,0,0,0,0,0,0,0,0,0,0,0,0,0,12,0
0,12,0,0,0,0,0,0,0,0,0,0,0,0,0,0,0,12,0
0,0,0,0,0,0,0,0,0,361,0,0,0,0,0,0,0,0,0
0,0,0,0,0,0,0,0,0,29,0,0,0,0,0,0,0,0,0
0,430,430,0,0,0,0,0,0,0,0,0,0,0,0,0,430,430,0
0,0,0,431,431,431,430,430,431,430,431,430,430,431,431,431,0,0,0
0,0,0,0,0,0,0,0,0,0,0,0,0,0,0,0,0,0,0
0,12,12,0,0,0,0,0,0,0,0,0,0,0,0,0,12,12,0
0,12,12,0,0,0,0,0,0,0,0,0,0,0,0,0,12,12,0
0,12,12,0,0,0,0,0,0,0,0,0,0,0,0,0,12,12,0
0,0,0,0,0,0,0,0,0,0,0,0,0,0,0,0,0,0,0
0,0,0,0,0,0,0,0,0,0,0,0,0,0,0,0,0,0,0
0,0,0,0,0,0,0,0,55,361,55,0,0,0,0,0,0,0,0
0,0,0,0,0,0,0,0,66,29,54,0,0,0,0,0,0,0,0
0,0,0,0,0,0,0,0,55,77,55,0,0,0,0,0,0,0,0
0,0,0,0,0,0,0,0,0,0,0,0,0,0,0,0,0,0,0
0,0,0,0,0,0,0,0,0,0,0,0,0,0,0,0,0,0,0
0,0,0,0,0,0,0,0,0,0,0,0,0,0,0,0,0,0,0
0,0,0,0,0,0,0,0,0,0,0,0,0,0,0,0,0,0,0
0,0,0,0,0,0,0,0,0,0,0,0,0,0,0,0,0,0,0
0,0,0,0,0,0,0,0,0,0,0,0,0,0,0,0,0,0,0
0,0,0,0,0,0,0,0,0,0,0,0,0,0,0,0,0,0,0
0,0,0,0,0,0,0,0,0,0,0,0,0,0,0,0,0,0,0
0,0,0,0,0,0,0,0,0,0,0,0,0,0,0,0,0,0,0
0,0,0,0,0,0,0,0,0,0,0,0,0,0,0,0,0,0,0
0,0,0,0,0,0,0,0,0,0,0,0,0,0,0,0,0,0,0
0,0,0,0,0,0,0,0,0,0,0,0,0,0,0,0,0,0,0
:endlayer
layer: 25
0,0,0,0,0,0,0,0,0,0,431,0,0,0,0,0,0,0,0
0,0,0,0,0,0,0,0,0,0,0,431,0,0,0,0,0,0,0
0,0,0,0,0,0,0,0,0,0,0,431,0,0,0,0,0,0,0
0,0,0,0,0,0,0,0,0,0,0,431,0,0,0,0,0,0,0
0,0,0,0,0,0,0,0,0,0,0,430,0,0,0,0,0,0,0
0,0,0,0,0,0,0,0,0,0,431,0,0,0,0,0,0,0,0
0,0,0,0,0,0,0,0,0,12,431,0,0,0,0,0,0,0,0
0,0,0,0,0,0,0,0,0,431,0,0,0,0,0,0,0,0,0
0,0,0,0,0,0,0,0,0,250,0,0,0,0,0,0,0,0,0
0,0,0,0,0,0,0,0,109,29,0,0,0,0,0,0,0,0,0
0,0,0,12,0,0,0,0,0,0,0,0,0,0,0,12,0,0,0
0,0,0,431,431,430,12,0,0,0,0,0,12,430,431,431,0,0,0
0,0,0,0,0,0,430,431,431,430,431,431,430,0,0,0,0,0,0
0,0,0,0,0,0,0,0,0,0,0,0,0,0,0,0,0,0,0
0,0,0,0,0,0,0,0,0,0,0,0,0,0,0,0,0,0,0
0,0,0,0,0,0,0,0,0,0,0,0,0,0,0,0,0,0,0
0,12,12,0,0,0,0,0,0,0,0,0,0,0,0,0,12,12,0
0,12,0,0,0,0,0,0,0,0,0,0,0,0,0,0,0,12,0
0,12,0,0,0,0,0,0,0,361,0,0,0,0,0,0,0,12,0
0,12,0,0,0,0,0,0,0,29,0,0,0,0,0,0,0,12,0
66,227,227,227,227,227,227,227,227,227,227,227,227,227,227,227,227,227,54
0,12,0,0,0,0,0,0,0,77,0,0,0,0,0,0,0,12,0
0,12,0,0,0,0,0,0,0,0,0,0,0,0,0,0,0,12,0
0,12,0,0,0,0,0,0,0,0,0,0,0,0,0,0,0,12,0
0,0,0,0,0,0,0,0,0,0,0,0,0,0,0,0,0,0,0
0,0,0,0,0,0,0,0,0,0,0,0,0,0,0,0,0,0,0
0,0,0,0,0,0,0,0,0,0,0,0,0,0,0,0,0,0,0
0,12,0,0,0,0,0,0,0,0,0,0,0,0,0,0,0,12,0
0,12,0,0,0,0,0,0,0,361,0,0,0,0,0,0,0,12,0
0,12,0,0,0,0,0,0,0,29,0,0,0,0,0,0,0,12,0
66,227,227,227,227,227,227,227,227,227,227,227,227,227,227,227,227,227,54
0,12,0,0,0,0,0,0,0,77,0,0,0,0,0,0,0,12,0
0,12,0,0,0,0,0,0,0,0,0,0,0,0,0,0,0,12,0
0,12,0,0,0,0,0,0,0,0,0,0,0,0,0,0,0,12,0
0,0,0,0,0,0,0,0,0,0,0,0,0,0,0,0,0,0,0
0,0,0,0,0,0,0,0,0,0,0,0,0,0,0,0,0,0,0
0,0,0,0,0,0,0,0,0,0,0,0,0,0,0,0,0,0,0
0,12,0,0,0,0,0,0,0,0,0,0,0,0,0,0,0,12,0
0,12,0,0,0,0,0,0,0,361,0,0,0,0,0,0,0,12,0
0,12,0,0,0,0,0,0,0,29,0,0,0,0,0,0,0,12,0
66,227,227,227,227,227,227,227,227,227,227,227,227,227,227,227,227,227,54
0,12,0,0,0,0,0,0,0,77,0,0,0,0,0,0,0,12,0
0,12,0,0,0,0,0,0,0,0,0,0,0,0,0,0,0,12,0
0,12,0,0,0,0,0,0,0,0,0,0,0,0,0,0,0,12,0
0,0,0,0,0,0,0,0,0,0,0,0,0,0,0,0,0,0,0
0,0,0,0,0,0,0,0,0,0,0,0,0,0,0,0,0,0,0
0,0,0,0,0,0,0,0,0,0,0,0,0,0,0,0,0,0,0
0,0,0,0,0,0,0,0,428,428,428,0,0,0,0,0,0,0,0
0,0,0,0,0,0,0,433,434,361,434,168,0,0,0,0,0,0,0
0,0,0,0,0,0,0,433,434,29,434,168,0,0,0,0,0,0,0
0,0,0,0,0,0,0,433,434,434,434,168,0,0,0,0,0,0,0
0,0,0,0,0,0,0,0,68,68,68,0,0,0,0,0,0,0,0
0,0,0,0,0,0,0,0,0,0,0,0,0,0,0,0,0,0,0
0,0,0,0,0,0,0,0,0,0,0,0,0,0,0,0,0,0,0
0,0,0,0,0,0,0,0,0,0,0,0,0,0,0,0,0,0,0
0,0,0,0,0,0,0,0,0,0,0,0,0,0,0,0,0,0,0
0,0,0,0,0,0,0,0,0,0,0,0,0,0,0,0,0,0,0
0,0,0,0,0,0,0,0,0,0,0,0,0,0,0,0,0,0,0
0,0,0,0,0,0,0,0,0,0,0,0,0,0,0,0,0,0,0
0,0,0,0,0,0,0,0,0,0,0,0,0,0,0,0,0,0,0
0,0,0,0,0,0,0,0,0,0,0,0,0,0,0,0,0,0,0
0,0,0,0,0,0,0,0,0,0,0,0,0,0,0,0,0,0,0
0,0,0,0,0,0,0,0,0,0,0,0,0,0,0,0,0,0,0
:endlayer
layer: 26
0,0,0,0,0,0,0,0,0,0,431,0,0,0,0,0,0,0,0
0,0,0,0,0,0,0,0,0,0,431,0,0,0,0,0,0,0,0
0,0,0,0,0,0,0,0,0,0,0,430,0,0,0,0,0,0,0
0,0,0,0,0,0,0,0,0,0,12,431,0,0,0,0,0,0,0
0,0,0,0,0,0,0,0,0,0,430,0,0,0,0,0,0,0,0
0,0,0,0,0,0,0,0,0,12,431,0,0,0,0,0,0,0,0
0,0,0,0,0,0,0,0,0,430,0,0,0,0,0,0,0,0,0
0,0,0,0,0,0,0,0,0,250,0,0,0,0,0,0,0,0,0
0,0,0,0,0,0,0,0,0,24,0,0,0,0,0,0,0,0,0
0,0,0,0,0,0,0,0,109,29,0,0,0,0,0,0,0,0,0
0,0,0,430,0,0,0,0,0,0,0,0,0,0,0,430,0,0,0
0,0,0,0,430,431,431,431,431,430,431,431,431,431,430,0,0,0,0
0,0,0,0,0,0,0,0,0,0,0,0,0,0,0,0,0,0,0
0,0,12,12,0,0,0,0,0,0,0,0,0,0,0,12,12,0,0
0,0,12,0,0,0,0,0,0,0,0,0,0,0,0,0,12,0,0
0,0,12,0,0,0,0,0,0,0,0,0,0,0,0,0,12,0,0
0,0,12,0,0,0,0,0,0,0,0,0,0,0,0,0,12,0,0
0,0,0,0,0,0,0,0,0,0,0,0,0,0,0,0,0,0,0
0,0,0,0,0,0,0,0,0,361,0,0,0,0,0,0,0,0,0
0,0,0,0,0,0,0,0,0,29,0,0,0,0,0,0,0,0,0
0,175,0,430,0,0,0,0,0,0,0,0,0,0,0,430,0,175,0
0,0,0,0,430,431,431,431,431,430,431,431,431,431,430,0,0,0,0
0,0,0,0,0,0,0,0,0,0,0,0,0,0,0,0,0,0,0
0,0,0,0,0,0,0,0,0,0,0,0,0,0,0,0,0,0,0
0,0,0,0,0,0,0,0,0,0,0,0,0,0,0,0,0,0,0
0,0,0,0,0,0,0,0,0,0,0,0,0,0,0,0,0,0,0
0,0,0,0,0,0,0,0,0,0,0,0,0,0,0,0,0,0,0
0,0,0,0,0,0,0,0,0,0,0,0,0,0,0,0,0,0,0
0,0,0,0,0,0,0,0,0,361,0,0,0,0,0,0,0,0,0
0,0,0,0,0,0,0,0,0,29,0,0,0,0,0,0,0,0,0
0,430,430,0,0,0,0,0,0,0,0,0,0,0,0,0,430,430,0
0,0,0,431,431,431,430,430,431,430,431,430,430,431,431,431,0,0,0
0,0,0,0,0,0,0,0,0,0,0,0,0,0,0,0,0,0,0
0,0,0,0,0,0,0,0,0,0,0,0,0,0,0,0,0,0,0
0,0,0,0,0,0,0,0,0,0,0,0,0,0,0,0,0,0,0
0,0,0,0,0,0,0,0,0,0,0,0,0,0,0,0,0,0,0
0,0,0,0,0,0,0,0,0,0,0,0,0,0,0,0,0,0,0
0,0,0,0,0,0,0,0,0,0,0,0,0,0,0,0,0,0,0
0,0,0,0,0,0,0,0,0,361,0,0,0,0,0,0,0,0,0
0,0,0,0,0,0,0,0,0,29,0,0,0,0,0,0,0,0,0
0,175,0,430,0,0,0,0,0,0,0,0,0,0,0,430,0,175,0
0,0,0,0,430,431,431,431,431,430,431,431,431,431,430,0,0,0,0
0,0,0,0,0,0,0,0,0,0,0,0,0,0,0,0,0,0,0
0,0,0,0,0,0,0,0,0,0,0,0,0,0,0,0,0,0,0
0,0,0,0,0,0,0,0,0,0,0,0,0,0,0,0,0,0,0
0,0,0,0,0,0,0,0,0,0,0,0,0,0,0,0,0,0,0
0,0,0,0,0,0,0,0,0,0,0,0,0,0,0,0,0,0,0
0,0,0,0,0,0,0,0,0,0,0,0,0,0,0,0,0,0,0
0,0,0,0,0,0,0,0,0,361,0,0,0,0,0,0,0,0,0
0,0,0,0,0,0,0,0,437,29,435,0,0,0,0,0,0,0,0
0,0,0,0,0,0,0,0,0,436,0,0,0,0,0,0,0,0,0
0,0,0,0,0,0,0,0,0,0,0,0,0,0,0,0,0,0,0
0,0,0,0,0,0,0,0,0,0,0,0,0,0,0,0,0,0,0
0,0,0,0,0,0,0,0,0,0,0,0,0,0,0,0,0,0,0
0,0,0,0,0,0,0,0,0,0,0,0,0,0,0,0,0,0,0
0,0,0,0,0,0,0,0,0,0,0,0,0,0,0,0,0,0,0
0,0,0,0,0,0,0,0,0,0,0,0,0,0,0,0,0,0,0
0,0,0,0,0,0,0,0,0,0,0,0,0,0,0,0,0,0,0
0,0,0,0,0,0,0,0,0,0,0,0,0,0,0,0,0,0,0
0,0,0,0,0,0,0,0,0,0,0,0,0,0,0,0,0,0,0
0,0,0,0,0,0,0,0,0,0,0,0,0,0,0,0,0,0,0
0,0,0,0,0,0,0,0,0,0,0,0,0,0,0,0,0,0,0
0,0,0,0,0,0,0,0,0,0,0,0,0,0,0,0,0,0,0
:endlayer
layer: 27
0,0,0,0,0,0,0,0,0,0,0,0,0,0,0,0,0,0,0
0,0,0,0,0,0,0,0,0,0,431,0,0,0,0,0,0,0,0
0,0,0,0,0,0,0,0,0,0,0,431,0,0,0,0,0,0,0
0,0,0,0,0,0,0,0,0,0,431,0,0,0,0,0,0,0,0
0,0,0,0,0,0,0,0,0,12,431,0,0,0,0,0,0,0,0
0,0,0,0,0,0,0,0,0,431,0,0,0,0,0,0,0,0,0
0,0,0,0,0,0,0,0,0,250,0,0,0,0,0,0,0,0,0
0,0,0,12,0,0,0,0,0,24,0,0,0,0,0,12,0,0,0
0,0,0,12,0,0,0,0,0,0,0,0,0,0,0,12,0,0,0
0,0,0,12,0,0,0,0,109,29,0,0,0,0,0,12,0,0,0
0,0,66,227,227,227,227,227,227,227,227,227,227,227,227,227,54,0,0
0,0,0,12,0,0,0,0,0,77,0,0,0,0,0,12,0,0,0
0,0,0,12,0,0,0,0,0,0,0,0,0,0,0,12,0,0,0
0,0,0,12,0,0,0,0,0,0,0,0,0,0,0,12,0,0,0
0,0,0,0,0,0,0,0,0,0,0,0,0,0,0,0,0,0,0
0,0,0,0,0,0,0,0,0,0,0,0,0,0,0,0,0,0,0
0,0,0,0,0,0,0,0,0,0,0,0,0,0,0,0,0,0,0
0,0,0,0,0,0,0,0,0,0,0,0,0,0,0,0,0,0,0
0,0,0,0,0,0,0,0,0,361,0,0,0,0,0,0,0,0,0
0,0,0,0,0,0,0,0,0,29,0,0,0,0,0,0,0,0,0
0,0,0,12,0,0,0,0,0,81,0,0,0,0,0,12,0,0,0
0,0,0,431,431,430,12,0,0,0,0,0,12,430,431,431,0,0,0
0,0,0,0,0,0,430,431,431,430,431,431,430,0,0,0,0,0,0
0,0,0,0,0,0,0,0,0,0,0,0,0,0,0,0,0,0,0
0,0,0,0,0,0,0,0,0,0,0,0,0,0,0,0,0,0,0
0,0,0,0,0,0,0,0,0,0,0,0,0,0,0,0,0,0,0
0,0,0,0,0,0,0,0,0,0,0,0,0,0,0,0,0,0,0
0,0,0,0,0,0,0,0,0,0,0,0,0,0,0,0,0,0,0
0,0,0,0,0,0,0,0,0,361,0,0,0,0,0,0,0,0,0
0,0,0,0,0,0,0,0,0,29,0,0,0,0,0,0,0,0,0
0,0,12,0,0,0,0,0,0,81,0,0,0,0,0,0,12,0,0
0,431,431,430,430,431,12,0,0,0,0,0,12,431,430,430,431,431,0
0,0,0,0,0,0,431,431,431,430,431,431,431,0,0,0,0,0,0
0,0,0,0,0,0,0,0,0,0,0,0,0,0,0,0,0,0,0
0,0,0,0,0,0,0,0,0,0,0,0,0,0,0,0,0,0,0
0,0,0,0,0,0,0,0,0,0,0,0,0,0,0,0,0,0,0
0,0,0,0,0,0,0,0,0,0,0,0,0,0,0,0,0,0,0
0,0,0,0,0,0,0,0,0,0,0,0,0,0,0,0,0,0,0
0,0,0,0,0,0,0,0,0,361,0,0,0,0,0,0,0,0,0
0,0,0,0,0,0,0,0,0,29,0,0,0,0,0,0,0,0,0
0,0,0,12,0,0,0,0,0,81,0,0,0,0,0,12,0,0,0
0,0,0,431,431,430,12,0,0,0,0,0,12,430,431,431,0,0,0
0,0,0,0,0,0,430,431,431,430,431,431,430,0,0,0,0,0,0
0,0,0,0,0,0,0,0,0,0,0,0,0,0,0,0,0,0,0
0,0,0,0,0,0,0,0,0,0,0,0,0,0,0,0,0,0,0
0,0,0,0,0,0,0,0,0,0,0,0,0,0,0,0,0,0,0
0,0,0,0,0,0,0,0,0,0,0,0,0,0,0,0,0,0,0
0,0,0,0,0,0,0,0,0,0,0,0,0,0,0,0,0,0,0
0,0,0,0,0,0,0,0,0,361,0,0,0,0,0,0,0,0,0
0,0,0,0,0,0,0,0,59,29,95,0,0,0,0,0,0,0,0
0,0,0,0,0,0,0,0,0,81,0,0,0,0,0,0,0,0,0
0,0,0,0,0,0,0,0,0,0,0,0,0,0,0,0,0,0,0
0,0,0,0,0,0,0,0,0,0,0,0,0,0,0,0,0,0,0
0,0,0,0,0,0,0,0,0,0,0,0,0,0,0,0,0,0,0
0,0,0,0,0,0,0,0,0,0,0,0,0,0,0,0,0,0,0
0,0,0,0,0,0,0,0,0,0,0,0,0,0,0,0,0,0,0
0,0,0,0,0,0,0,0,0,0,0,0,0,0,0,0,0,0,0
0,0,0,0,0,0,0,0,0,0,0,0,0,0,0,0,0,0,0
0,0,0,0,0,0,0,0,0,0,0,0,0,0,0,0,0,0,0
0,0,0,0,0,0,0,0,0,0,0,0,0,0,0,0,0,0,0
0,0,0,0,0,0,0,0,0,0,0,0,0,0,0,0,0,0,0
0,0,0,0,0,0,0,0,0,0,0,0,0,0,0,0,0,0,0
0,0,0,0,0,0,0,0,0,0,0,0,0,0,0,0,0,0,0
:endlayer
layer: 28
0,0,0,0,0,0,0,0,0,0,0,0,0,0,0,0,0,0,0
0,0,0,0,0,0,0,0,0,0,431,0,0,0,0,0,0,0,0
0,0,0,0,0,0,0,0,0,0,431,0,0,0,0,0,0,0,0
0,0,0,0,0,0,0,0,0,12,431,0,0,0,0,0,0,0,0
0,0,0,0,0,0,0,0,0,431,0,0,0,0,0,0,0,0,0
0,0,0,0,0,12,0,0,0,250,0,0,0,12,0,0,0,0,0
0,0,0,0,12,12,0,0,0,24,0,0,0,12,12,0,0,0,0
0,0,0,12,12,0,0,0,0,0,0,0,0,0,12,12,0,0,0
0,0,0,12,0,0,0,0,0,0,0,0,0,0,0,12,0,0,0
0,0,0,0,0,0,0,0,109,29,0,0,0,0,0,0,0,0,0
0,0,0,175,0,0,0,0,0,24,0,0,0,0,0,175,0,0,0
0,0,0,0,0,0,0,0,0,312,0,0,0,0,0,0,0,0,0
0,0,0,0,0,0,0,0,0,0,0,0,0,0,0,0,0,0,0
0,0,0,0,0,0,0,0,0,0,0,0,0,0,0,0,0,0,0
0,0,0,0,0,0,0,0,0,0,0,0,0,0,0,0,0,0,0
0,0,0,0,0,0,0,0,0,0,0,0,0,0,0,0,0,0,0
0,0,0,0,0,0,0,0,0,0,0,0,0,0,0,0,0,0,0
0,0,0,0,0,0,0,0,0,0,0,0,0,0,0,0,0,0,0
0,0,0,0,0,0,0,0,0,361,0,0,0,0,0,0,0,0,0
0,0,0,0,0,0,0,0,0,29,0,0,0,0,0,0,0,0,0
0,0,0,0,0,0,0,0,0,0,0,0,0,0,0,0,0,0,0
0,0,0,431,0,0,0,0,0,0,0,0,0,0,0,431,0,0,0
0,0,0,0,431,431,431,430,0,0,0,430,431,431,431,0,0,0,0
0,0,0,0,0,0,0,0,430,431,430,0,0,0,0,0,0,0,0
0,0,0,0,0,0,0,0,0,0,0,0,0,0,0,0,0,0,0
0,0,0,0,0,0,0,0,0,0,0,0,0,0,0,0,0,0,0
0,0,0,0,0,0,0,0,0,0,0,0,0,0,0,0,0,0,0
0,0,0,0,0,0,0,0,0,0,0,0,0,0,0,0,0,0,0
0,0,0,0,0,0,0,0,0,361,0,0,0,0,0,0,0,0,0
0,0,0,0,0,0,0,0,0,29,0,0,0,0,0,0,0,0,0
0,0,0,0,0,0,0,0,0,0,0,0,0,0,0,0,0,0,0
0,430,431,431,0,0,0,0,0,0,0,0,0,0,0,431,431,430,0
0,0,0,0,431,430,430,431,12,0,12,431,430,430,431,0,0,0,0
0,0,0,0,0,0,0,0,431,430,431,0,0,0,0,0,0,0,0
0,0,0,0,0,0,0,0,0,0,0,0,0,0,0,0,0,0,0
0,0,0,0,0,0,0,0,0,0,0,0,0,0,0,0,0,0,0
0,0,0,0,0,0,0,0,0,0,0,0,0,0,0,0,0,0,0
0,0,0,0,0,0,0,0,0,0,0,0,0,0,0,0,0,0,0
0,0,0,0,0,0,0,0,0,361,0,0,0,0,0,0,0,0,0
0,0,0,0,0,0,0,0,0,29,0,0,0,0,0,0,0,0,0
0,0,0,0,0,0,0,0,0,0,0,0,0,0,0,0,0,0,0
0,0,0,431,0,0,0,0,0,0,0,0,0,0,0,431,0,0,0
0,0,0,0,431,431,431,430,0,0,0,430,431,431,431,0,0,0,0
0,0,0,0,0,0,0,0,430,431,430,0,0,0,0,0,0,0,0
0,0,0,0,0,0,0,0,0,0,0,0,0,0,0,0,0,0,0
0,0,0,0,0,0,0,0,0,0,0,0,0,0,0,0,0,0,0
0,0,0,0,0,0,0,0,0,0,0,0,0,0,0,0,0,0,0
0,0,0,0,0,0,0,0,0,0,0,0,0,0,0,0,0,0,0
0,0,0,0,0,0,0,0,0,0,0,0,0,0,0,0,0,0,0
0,0,0,0,0,0,0,0,0,140,0,0,0,0,0,0,0,0,0
0,0,0,0,0,0,0,0,0,0,0,0,0,0,0,0,0,0,0
0,0,0,0,0,0,0,0,0,0,0,0,0,0,0,0,0,0,0
0,0,0,0,0,0,0,0,0,0,0,0,0,0,0,0,0,0,0
0,0,0,0,0,0,0,0,0,0,0,0,0,0,0,0,0,0,0
0,0,0,0,0,0,0,0,0,0,0,0,0,0,0,0,0,0,0
0,0,0,0,0,0,0,0,0,0,0,0,0,0,0,0,0,0,0
0,0,0,0,0,0,0,0,0,0,0,0,0,0,0,0,0,0,0
0,0,0,0,0,0,0,0,0,0,0,0,0,0,0,0,0,0,0
0,0,0,0,0,0,0,0,0,0,0,0,0,0,0,0,0,0,0
0,0,0,0,0,0,0,0,0,0,0,0,0,0,0,0,0,0,0
0,0,0,0,0,0,0,0,0,0,0,0,0,0,0,0,0,0,0
0,0,0,0,0,0,0,0,0,0,0,0,0,0,0,0,0,0,0
0,0,0,0,0,0,0,0,0,0,0,0,0,0,0,0,0,0,0
:endlayer
layer: 29
0,0,0,0,0,0,0,0,0,0,0,0,0,0,0,0,0,0,0
0,0,0,0,0,0,0,0,0,0,0,0,0,0,0,0,0,0,0
0,0,0,0,0,0,0,0,0,12,431,0,0,0,0,0,0,0,0
0,0,0,0,0,0,0,0,0,431,0,0,0,0,0,0,0,0,0
0,0,0,0,0,0,12,0,0,250,0,0,12,0,0,0,0,0,0
0,0,0,0,0,12,12,0,0,24,0,0,12,12,0,0,0,0,0
0,0,0,0,0,12,0,0,0,0,0,0,0,12,0,0,0,0,0
0,0,0,0,0,0,0,0,0,0,0,0,0,0,0,0,0,0,0
0,0,0,0,0,0,0,0,55,72,55,0,0,0,0,0,0,0,0
0,0,0,0,0,0,0,0,109,29,54,0,0,0,0,0,0,0,0
0,0,0,0,0,0,0,0,55,77,55,0,0,0,0,0,0,0,0
0,0,0,0,0,0,0,0,0,0,0,0,0,0,0,0,0,0,0
0,0,0,0,0,0,0,0,0,0,0,0,0,0,0,0,0,0,0
0,0,0,0,0,0,0,0,0,0,0,0,0,0,0,0,0,0,0
0,0,0,0,0,0,0,0,0,0,0,0,0,0,0,0,0,0,0
0,0,0,0,0,0,0,0,0,0,0,0,0,0,0,0,0,0,0
0,0,0,0,0,0,0,0,0,0,0,0,0,0,0,0,0,0,0
0,0,0,0,0,0,0,0,0,0,0,0,0,0,0,0,0,0,0
0,0,0,0,0,0,0,0,0,361,0,0,0,0,0,0,0,0,0
0,0,0,0,0,0,0,0,0,29,0,0,0,0,0,0,0,0,0
0,0,0,0,0,0,0,0,0,0,0,0,0,0,0,0,0,0,0
0,0,0,431,0,0,0,0,0,0,0,0,0,0,0,431,0,0,0
0,0,0,0,431,430,12,0,0,0,0,0,12,430,431,0,0,0,0
0,0,0,0,0,0,430,431,431,430,431,431,430,0,0,0,0,0,0
0,0,0,0,0,0,0,0,0,0,0,0,0,0,0,0,0,0,0
0,0,0,0,0,0,0,0,0,0,0,0,0,0,0,0,0,0,0
0,0,0,0,0,0,0,0,0,0,0,0,0,0,0,0,0,0,0
0,0,0,0,0,0,0,0,0,0,0,0,0,0,0,0,0,0,0
0,0,0,0,0,0,0,0,0,361,0,0,0,0,0,0,0,0,0
0,0,0,0,0,0,0,0,0,29,0,0,0,0,0,0,0,0,0
0,0,0,0,0,0,0,0,0,0,0,0,0,0,0,0,0,0,0
0,431,0,0,0,0,0,0,0,0,0,0,0,0,0,0,0,431,0
0,0,431,431,431,431,0,0,0,0,0,0,0,431,431,431,431,0,0
0,0,0,0,0,0,431,430,430,431,430,430,431,0,0,0,0,0,0
0,0,0,0,0,0,0,0,0,0,0,0,0,0,0,0,0,0,0
0,0,0,0,0,0,0,0,0,0,0,0,0,0,0,0,0,0,0
0,0,0,0,0,0,0,0,0,0,0,0,0,0,0,0,0,0,0
0,0,0,0,0,0,0,0,0,0,0,0,0,0,0,0,0,0,0
0,0,0,0,0,0,0,0,0,361,0,0,0,0,0,0,0,0,0
0,0,0,0,0,0,0,0,0,29,0,0,0,0,0,0,0,0,0
0,0,0,0,0,0,0,0,0,0,0,0,0,0,0,0,0,0,0
0,0,0,431,0,0,0,0,0,0,0,0,0,0,0,431,0,0,0
0,0,0,0,431,430,12,0,0,0,0,0,12,430,431,0,0,0,0
0,0,0,0,0,0,430,431,431,430,431,431,430,0,0,0,0,0,0
0,0,0,0,0,0,0,0,0,0,0,0,0,0,0,0,0,0,0
0,0,0,0,0,0,0,0,0,431,0,0,0,0,0,0,0,0,0
0,0,0,0,0,0,0,0,0,431,0,0,0,0,0,0,0,0,0
0,0,0,0,0,0,0,0,0,431,0,0,0,0,0,0,0,0,0
0,0,0,0,0,0,0,0,0,431,0,0,0,0,0,0,0,0,0
0,0,0,0,0,0,0,0,0,140,0,0,0,0,0,0,0,0,0
0,0,0,0,0,0,0,0,0,0,0,0,0,0,0,0,0,0,0
0,0,0,0,0,0,0,0,0,0,0,0,0,0,0,0,0,0,0
0,0,0,0,0,0,0,0,0,0,0,0,0,0,0,0,0,0,0
0,0,0,0,0,0,0,0,0,0,0,0,0,0,0,0,0,0,0
0,0,0,0,0,0,0,0,0,0,0,0,0,0,0,0,0,0,0
0,0,0,0,0,0,0,0,0,0,0,0,0,0,0,0,0,0,0
0,0,0,0,0,0,0,0,0,0,0,0,0,0,0,0,0,0,0
0,0,0,0,0,0,0,0,0,0,0,0,0,0,0,0,0,0,0
0,0,0,0,0,0,0,0,0,0,0,0,0,0,0,0,0,0,0
0,0,0,0,0,0,0,0,0,0,0,0,0,0,0,0,0,0,0
0,0,0,0,0,0,0,0,0,0,0,0,0,0,0,0,0,0,0
0,0,0,0,0,0,0,0,0,0,0,0,0,0,0,0,0,0,0
0,0,0,0,0,0,0,0,0,0,0,0,0,0,0,0,0,0,0
:endlayer
layer: 30
0,0,0,0,0,0,0,0,0,0,0,0,0,0,0,0,0,0,0
0,0,0,0,0,0,0,0,0,0,0,0,0,0,0,0,0,0,0
0,0,0,0,0,0,0,0,0,431,0,0,0,0,0,0,0,0,0
0,0,0,0,0,0,0,12,12,250,12,12,0,0,0,0,0,0,0
0,0,0,0,0,0,12,12,0,24,0,12,12,0,0,0,0,0,0
0,0,0,0,0,0,0,0,0,0,0,0,0,0,0,0,0,0,0
0,0,0,0,0,0,0,0,0,0,0,0,0,0,0,0,0,0,0
0,0,0,0,0,0,0,0,428,428,428,0,0,0,0,0,0,0,0
0,0,0,0,0,0,0,433,434,434,434,168,0,0,0,0,0,0,0
0,0,0,0,0,0,0,433,109,29,434,168,0,0,0,0,0,0,0
0,0,0,0,0,0,0,433,434,434,434,168,0,0,0,0,0,0,0
0,0,0,0,0,0,0,0,68,68,68,0,0,0,0,0,0,0,0
0,0,0,0,0,0,0,0,0,0,0,0,0,0,0,0,0,0,0
0,0,0,0,0,0,0,0,0,0,0,0,0,0,0,0,0,0,0
0,0,0,0,0,0,0,0,0,0,0,0,0,0,0,0,0,0,0
0,0,0,0,0,0,0,0,0,0,0,0,0,0,0,0,0,0,0
0,0,0,0,0,0,0,0,0,0,0,0,0,0,0,0,0,0,0
0,0,0,0,0,0,0,0,0,0,0,0,0,0,0,0,0,0,0
0,0,0,0,0,0,0,0,0,361,0,0,0,0,0,0,0,0,0
0,0,0,0,0,0,0,0,0,29,0,0,0,0,0,0,0,0,0
0,0,0,0,0,0,0,0,0,0,0,0,0,0,0,0,0,0,0
0,0,0,431,0,0,0,0,0,0,0,0,0,0,0,431,0,0,0
0,0,0,0,431,431,431,430,0,0,0,430,431,431,431,0,0,0,0
0,0,0,0,0,0,0,0,430,431,430,0,0,0,0,0,0,0,0
0,0,0,0,0,0,0,0,0,0,0,0,0,0,0,0,0,0,0
0,0,0,0,0,0,0,0,0,0,0,0,0,0,0,0,0,0,0
0,0,0,0,0,0,0,0,0,0,0,0,0,0,0,0,0,0,0
0,0,0,0,0,0,0,0,0,0,0,0,0,0,0,0,0,0,0
0,0,0,0,0,0,0,0,0,361,0,0,0,0,0,0,0,0,0
0,0,0,0,0,0,0,0,0,29,0,0,0,0,0,0,0,0,0
0,0,0,0,0,0,0,0,0,0,0,0,0,0,0,0,0,0,0
0,430,12,0,0,0,0,0,0,0,0,0,0,0,0,0,12,430,0
0,0,430,430,12,0,0,0,0,0,0,0,0,0,12,430,430,0,0
0,0,0,0,430,430,430,431,431,430,431,431,430,430,430,0,0,0,0
0,0,0,0,0,0,0,0,0,0,0,0,0,0,0,0,0,0,0
0,0,0,0,0,0,0,0,0,0,0,0,0,0,0,0,0,0,0
0,0,0,0,0,0,0,0,0,0,0,0,0,0,0,0,0,0,0
0,0,0,0,0,0,0,0,0,0,0,0,0,0,0,0,0,0,0
0,0,0,0,0,0,0,0,0,361,0,0,0,0,0,0,0,0,0
0,0,0,0,0,0,0,0,0,29,0,0,0,0,0,0,0,0,0
0,0,0,0,0,0,0,0,0,0,0,0,0,0,0,0,0,0,0
0,0,0,431,0,0,0,0,0,0,0,0,0,0,0,431,0,0,0
0,0,0,0,431,431,431,430,0,0,0,430,431,431,431,0,0,0,0
0,0,0,0,0,0,0,0,430,431,430,0,0,0,0,0,0,0,0
0,0,0,0,0,0,0,0,0,0,0,0,0,0,0,0,0,0,0
0,0,0,0,0,0,0,0,0,0,0,0,0,0,0,0,0,0,0
0,0,0,0,0,0,0,0,0,0,0,0,0,0,0,0,0,0,0
0,0,0,0,0,0,0,0,0,431,0,0,0,0,0,0,0,0,0
0,0,0,0,0,0,0,0,0,431,0,0,0,0,0,0,0,0,0
0,0,0,0,0,0,0,0,0,140,0,0,0,0,0,0,0,0,0
0,0,0,0,0,0,0,0,0,0,0,0,0,0,0,0,0,0,0
0,0,0,0,0,0,0,0,0,0,0,0,0,0,0,0,0,0,0
0,0,0,0,0,0,0,0,0,0,0,0,0,0,0,0,0,0,0
0,0,0,0,0,0,0,0,0,0,0,0,0,0,0,0,0,0,0
0,0,0,0,0,0,0,0,0,0,0,0,0,0,0,0,0,0,0
0,0,0,0,0,0,0,0,0,0,0,0,0,0,0,0,0,0,0
0,0,0,0,0,0,0,0,0,0,0,0,0,0,0,0,0,0,0
0,0,0,0,0,0,0,0,0,0,0,0,0,0,0,0,0,0,0
0,0,0,0,0,0,0,0,0,0,0,0,0,0,0,0,0,0,0
0,0,0,0,0,0,0,0,0,0,0,0,0,0,0,0,0,0,0
0,0,0,0,0,0,0,0,0,0,0,0,0,0,0,0,0,0,0
0,0,0,0,0,0,0,0,0,0,0,0,0,0,0,0,0,0,0
0,0,0,0,0,0,0,0,0,0,0,0,0,0,0,0,0,0,0
:endlayer
layer: 31
0,0,0,0,0,0,0,0,0,0,0,0,0,0,0,0,0,0,0
0,0,0,0,0,0,0,0,0,72,0,0,0,0,0,0,0,0,0
0,0,0,0,0,0,0,0,12,250,12,0,0,0,0,0,0,0,0
0,0,0,0,0,0,0,0,12,24,12,0,0,0,0,0,0,0,0
0,0,0,0,0,0,0,0,0,0,0,0,0,0,0,0,0,0,0
0,0,0,0,0,0,0,0,0,0,0,0,0,0,0,0,0,0,0
0,0,0,0,0,0,0,0,0,0,0,0,0,0,0,0,0,0,0
0,0,0,0,0,0,0,0,0,0,0,0,0,0,0,0,0,0,0
0,0,0,0,0,0,0,0,0,438,0,0,0,0,0,0,0,0,0
0,0,0,0,0,0,0,0,109,29,0,0,0,0,0,0,0,0,0
0,0,0,0,0,0,0,0,0,439,0,0,0,0,0,0,0,0,0
0,0,0,0,0,0,0,0,0,0,0,0,0,0,0,0,0,0,0
0,0,0,0,0,0,0,0,0,0,0,0,0,0,0,0,0,0,0
0,0,0,0,0,0,0,0,0,0,0,0,0,0,0,0,0,0,0
0,0,0,0,0,0,0,0,0,0,0,0,0,0,0,0,0,0,0
0,0,0,0,0,0,0,0,0,0,0,0,0,0,0,0,0,0,0
0,0,0,0,0,0,0,0,0,0,0,0,0,0,0,0,0,0,0
0,0,0,0,0,0,0,0,0,0,0,0,0,0,0,0,0,0,0
0,0,0,0,0,0,0,0,0,361,0,0,0,0,0,0,0,0,0
0,0,0,0,0,0,0,0,0,29,0,0,0,0,0,0,0,0,0
0,0,0,12,0,0,0,0,0,0,0,0,0,0,0,12,0,0,0
0,0,0,431,431,430,12,0,0,0,0,0,12,430,431,431,0,0,0
0,0,0,0,0,0,430,431,431,430,431,431,430,0,0,0,0,0,0
0,0,0,0,0,0,0,0,0,0,0,0,0,0,0,0,0,0,0
0,0,0,0,0,0,0,0,0,0,0,0,0,0,0,0,0,0,0
0,0,0,0,0,0,0,0,0,0,0,0,0,0,0,0,0,0,0
0,0,0,0,0,0,0,0,0,0,0,0,0,0,0,0,0,0,0
0,0,0,0,0,0,0,0,0,0,0,0,0,0,0,0,0,0,0
0,0,0,0,0,0,0,0,0,361,0,0,0,0,0,0,0,0,0
0,0,0,0,0,0,0,0,0,29,0,0,0,0,0,0,0,0,0
0,0,0,0,0,0,0,0,0,0,0,0,0,0,0,0,0,0,0
0,431,0,0,0,0,0,0,0,0,0,0,0,0,0,0,0,431,0
0,0,431,431,431,431,0,0,0,0,0,0,0,431,431,431,431,0,0
0,0,0,0,0,0,431,430,430,431,430,430,431,0,0,0,0,0,0
0,0,0,0,0,0,0,0,0,0,0,0,0,0,0,0,0,0,0
0,0,0,0,0,0,0,0,0,0,0,0,0,0,0,0,0,0,0
0,0,0,0,0,0,0,0,0,0,0,0,0,0,0,0,0,0,0
0,0,0,0,0,0,0,0,0,0,0,0,0,0,0,0,0,0,0
0,0,0,0,0,0,0,0,0,361,0,0,0,0,0,0,0,0,0
0,0,0,0,0,0,0,0,0,29,0,0,0,0,0,0,0,0,0
0,0,0,12,0,0,0,0,0,0,0,0,0,0,0,12,0,0,0
0,0,0,431,431,430,12,0,0,0,0,0,12,430,431,431,0,0,0
0,0,0,0,0,0,430,431,431,430,431,431,430,0,0,0,0,0,0
0,0,0,0,0,0,0,0,0,0,0,0,0,0,0,0,0,0,0
0,0,0,0,0,0,0,0,0,0,0,0,0,0,0,0,0,0,0
0,0,0,0,0,0,0,0,0,0,0,0,0,0,0,0,0,0,0
0,0,0,0,0,0,0,0,0,0,0,0,0,0,0,0,0,0,0
0,0,0,0,0,0,0,0,0,0,0,0,0,0,0,0,0,0,0
0,0,0,0,0,0,0,0,0,0,0,0,0,0,0,0,0,0,0
0,0,0,0,0,0,0,0,0,175,0,0,0,0,0,0,0,0,0
0,0,0,0,0,0,0,0,0,0,0,0,0,0,0,0,0,0,0
0,0,0,0,0,0,0,0,0,0,0,0,0,0,0,0,0,0,0
0,0,0,0,0,0,0,0,0,0,0,0,0,0,0,0,0,0,0
0,0,0,0,0,0,0,0,0,0,0,0,0,0,0,0,0,0,0
0,0,0,0,0,0,0,0,0,0,0,0,0,0,0,0,0,0,0
0,0,0,0,0,0,0,0,0,0,0,0,0,0,0,0,0,0,0
0,0,0,0,0,0,0,0,0,0,0,0,0,0,0,0,0,0,0
0,0,0,0,0,0,0,0,0,0,0,0,0,0,0,0,0,0,0
0,0,0,0,0,0,0,0,0,0,0,0,0,0,0,0,0,0,0
0,0,0,0,0,0,0,0,0,0,0,0,0,0,0,0,0,0,0
0,0,0,0,0,0,0,0,0,0,0,0,0,0,0,0,0,0,0
0,0,0,0,0,0,0,0,0,0,0,0,0,0,0,0,0,0,0
0,0,0,0,0,0,0,0,0,0,0,0,0,0,0,0,0,0,0
:endlayer
layer: 32
0,0,0,0,0,0,0,0,0,0,0,0,0,0,0,0,0,0,0
0,0,0,0,0,0,0,0,0,0,0,0,0,0,0,0,0,0,0
0,0,0,0,0,0,0,0,0,175,0,0,0,0,0,0,0,0,0
0,0,0,0,0,0,0,0,0,0,0,0,0,0,0,0,0,0,0
0,0,0,0,0,0,0,0,0,0,0,0,0,0,0,0,0,0,0
0,0,0,0,0,0,0,0,0,0,0,0,0,0,0,0,0,0,0
0,0,0,0,0,0,0,0,0,0,0,0,0,0,0,0,0,0,0
0,0,0,0,0,0,0,0,0,0,0,0,0,0,0,0,0,0,0
0,0,0,0,0,0,0,0,0,78,0,0,0,0,0,0,0,0,0
0,0,0,0,0,0,0,0,109,29,95,0,0,0,0,0,0,0,0
0,0,0,0,0,0,0,0,0,81,0,0,0,0,0,0,0,0,0
0,0,0,0,0,0,0,0,0,0,0,0,0,0,0,0,0,0,0
0,0,0,0,0,0,0,0,0,0,0,0,0,0,0,0,0,0,0
0,0,0,0,0,0,0,0,0,0,0,0,0,0,0,0,0,0,0
0,0,0,0,0,0,0,0,0,0,0,0,0,0,0,0,0,0,0
0,0,0,0,0,0,0,0,0,0,0,0,0,0,0,0,0,0,0
0,0,0,0,0,0,0,0,0,0,0,0,0,0,0,0,0,0,0
0,0,0,0,0,0,0,0,0,0,0,0,0,0,0,0,0,0,0
0,0,0,0,0,0,0,0,0,361,0,0,0,0,0,0,0,0,0
0,0,0,0,0,0,0,0,0,29,0,0,0,0,0,0,0,0,0
0,0,0,430,0,0,0,0,0,0,0,0,0,0,0,430,0,0,0
0,0,0,0,430,431,431,431,431,430,431,431,431,431,430,0,0,0,0
0,0,0,0,0,0,0,0,0,0,0,0,0,0,0,0,0,0,0
0,0,0,0,0,0,0,0,0,0,0,0,0,0,0,0,0,0,0
0,0,0,0,0,0,0,0,0,0,0,0,0,0,0,0,0,0,0
0,0,0,0,0,0,0,0,0,0,0,0,0,0,0,0,0,0,0
0,0,0,0,0,0,0,0,0,0,0,0,0,0,0,0,0,0,0
0,0,0,0,0,0,0,0,0,0,0,0,0,0,0,0,0,0,0
0,0,0,0,0,0,0,0,0,361,0,0,0,0,0,0,0,0,0
0,0,0,0,0,0,0,0,0,29,0,0,0,0,0,0,0,0,0
0,0,0,0,0,0,0,0,0,0,0,0,0,0,0,0,0,0,0
0,430,431,431,0,0,0,0,0,0,0,0,0,0,0,431,431,430,0
0,0,0,0,431,430,430,431,12,0,12,431,430,430,431,0,0,0,0
0,0,0,0,0,0,0,0,431,430,431,0,0,0,0,0,0,0,0
0,0,0,0,0,0,0,0,0,0,0,0,0,0,0,0,0,0,0
0,0,0,0,0,0,0,0,0,0,0,0,0,0,0,0,0,0,0
0,0,0,0,0,0,0,0,0,0,0,0,0,0,0,0,0,0,0
0,0,0,0,0,0,0,0,0,0,0,0,0,0,0,0,0,0,0
0,0,0,0,0,0,0,0,0,361,0,0,0,0,0,0,0,0,0
0,0,0,0,0,0,0,0,0,29,0,0,0,0,0,0,0,0,0
0,0,0,430,0,0,0,0,0,0,0,0,0,0,0,430,0,0,0
0,0,0,0,430,431,431,431,431,430,431,431,431,431,430,0,0,0,0
0,0,0,0,0,0,0,0,0,0,0,0,0,0,0,0,0,0,0
0,0,0,0,0,0,0,0,0,0,0,0,0,0,0,0,0,0,0
0,0,0,0,0,0,0,0,0,0,0,0,0,0,0,0,0,0,0
0,0,0,0,0,0,0,0,0,0,0,0,0,0,0,0,0,0,0
0,0,0,0,0,0,0,0,0,0,0,0,0,0,0,0,0,0,0
0,0,0,0,0,0,0,0,0,0,0,0,0,0,0,0,0,0,0
0,0,0,0,0,0,0,0,0,0,0,0,0,0,0,0,0,0,0
0,0,0,0,0,0,0,0,0,0,0,0,0,0,0,0,0,0,0
0,0,0,0,0,0,0,0,0,0,0,0,0,0,0,0,0,0,0
0,0,0,0,0,0,0,0,0,0,0,0,0,0,0,0,0,0,0
0,0,0,0,0,0,0,0,0,0,0,0,0,0,0,0,0,0,0
0,0,0,0,0,0,0,0,0,0,0,0,0,0,0,0,0,0,0
0,0,0,0,0,0,0,0,0,0,0,0,0,0,0,0,0,0,0
0,0,0,0,0,0,0,0,0,0,0,0,0,0,0,0,0,0,0
0,0,0,0,0,0,0,0,0,0,0,0,0,0,0,0,0,0,0
0,0,0,0,0,0,0,0,0,0,0,0,0,0,0,0,0,0,0
0,0,0,0,0,0,0,0,0,0,0,0,0,0,0,0,0,0,0
0,0,0,0,0,0,0,0,0,0,0,0,0,0,0,0,0,0,0
0,0,0,0,0,0,0,0,0,0,0,0,0,0,0,0,0,0,0
0,0,0,0,0,0,0,0,0,0,0,0,0,0,0,0,0,0,0
0,0,0,0,0,0,0,0,0,0,0,0,0,0,0,0,0,0,0
:endlayer
layer: 33
0,0,0,0,0,0,0,0,0,0,0,0,0,0,0,0,0,0,0
0,0,0,0,0,0,0,0,0,0,0,0,0,0,0,0,0,0,0
0,0,0,0,0,0,0,0,0,0,0,0,0,0,0,0,0,0,0
0,0,0,0,0,0,0,0,0,0,0,0,0,0,0,0,0,0,0
0,0,0,0,0,0,0,0,0,0,0,0,0,0,0,0,0,0,0
0,0,0,0,0,0,0,0,0,0,0,0,0,0,0,0,0,0,0
0,0,0,0,0,0,0,0,0,0,0,0,0,0,0,0,0,0,0
0,0,0,0,0,0,0,0,0,0,0,0,0,0,0,0,0,0,0
0,0,0,0,0,0,0,0,0,0,0,0,0,0,0,0,0,0,0
0,0,0,0,0,0,0,0,0,140,0,0,0,0,0,0,0,0,0
0,0,0,0,0,0,0,0,0,0,0,0,0,0,0,0,0,0,0
0,0,0,0,0,0,0,0,0,0,0,0,0,0,0,0,0,0,0
0,0,0,0,0,0,0,0,0,0,0,0,0,0,0,0,0,0,0
0,0,0,0,0,0,0,0,0,0,0,0,0,0,0,0,0,0,0
0,0,0,0,0,0,0,0,0,0,0,0,0,0,0,0,0,0,0
0,0,0,0,0,0,0,0,0,0,0,0,0,0,0,0,0,0,0
0,0,0,0,0,0,0,0,0,0,0,0,0,0,0,0,0,0,0
0,0,0,0,0,0,0,0,0,0,0,0,0,0,0,0,0,0,0
0,0,0,0,0,0,0,0,0,361,0,0,0,0,0,0,0,0,0
0,0,0,0,0,0,0,0,0,29,0,0,0,0,0,0,0,0,0
0,0,66,227,227,227,227,227,227,227,227,227,227,227,227,227,54,0,0
0,0,0,12,0,0,0,0,0,77,0,0,0,0,0,12,0,0,0
0,0,0,12,0,0,0,0,0,0,0,0,0,0,0,12,0,0,0
0,0,12,12,0,0,0,0,0,0,0,0,0,0,0,12,12,0,0
0,0,12,12,0,0,0,0,0,0,0,0,0,0,0,12,12,0,0
0,0,12,0,0,0,0,0,0,0,0,0,0,0,0,0,12,0,0
0,0,0,0,0,0,0,0,0,0,0,0,0,0,0,0,0,0,0
0,0,0,0,0,0,0,0,0,0,0,0,0,0,0,0,0,0,0
0,0,0,0,0,0,0,0,0,361,0,0,0,0,0,0,0,0,0
0,0,0,0,0,0,0,0,0,29,0,0,0,0,0,0,0,0,0
0,0,12,0,0,0,0,0,0,0,0,0,0,0,0,0,12,0,0
0,431,431,430,430,431,12,0,0,0,0,0,12,431,430,430,431,431,0
0,0,0,0,0,0,431,431,431,430,431,431,431,0,0,0,0,0,0
0,0,0,0,0,0,0,0,0,0,0,0,0,0,0,0,0,0,0
0,0,12,0,0,0,0,0,0,0,0,0,0,0,0,0,0,0,0
0,0,12,12,0,0,0,0,0,0,0,0,0,0,0,0,12,0,0
0,0,12,12,0,0,0,0,0,0,0,0,0,0,0,12,12,0,0
0,0,0,12,0,0,0,0,0,0,0,0,0,0,0,12,12,0,0
0,0,0,12,0,0,0,0,0,361,0,0,0,0,0,12,0,0,0
0,0,0,12,0,0,0,0,0,29,0,0,0,0,0,12,0,0,0
0,0,66,227,227,227,227,227,227,227,227,227,227,227,227,227,54,0,0
0,0,0,0,0,0,0,0,0,77,0,0,0,0,0,0,0,0,0
0,0,0,0,0,0,0,0,0,0,0,0,0,0,0,0,0,0,0
0,0,0,0,0,0,0,0,0,0,0,0,0,0,0,0,0,0,0
0,0,0,0,0,0,0,0,0,0,0,0,0,0,0,0,0,0,0
0,0,0,0,0,0,0,0,0,0,0,0,0,0,0,0,0,0,0
0,0,0,0,0,0,0,0,0,0,0,0,0,0,0,0,0,0,0
0,0,0,0,0,0,0,0,0,0,0,0,0,0,0,0,0,0,0
0,0,0,0,0,0,0,0,0,0,0,0,0,0,0,0,0,0,0
0,0,0,0,0,0,0,0,0,0,0,0,0,0,0,0,0,0,0
0,0,0,0,0,0,0,0,0,0,0,0,0,0,0,0,0,0,0
0,0,0,0,0,0,0,0,0,0,0,0,0,0,0,0,0,0,0
0,0,0,0,0,0,0,0,0,0,0,0,0,0,0,0,0,0,0
0,0,0,0,0,0,0,0,0,0,0,0,0,0,0,0,0,0,0
0,0,0,0,0,0,0,0,0,0,0,0,0,0,0,0,0,0,0
0,0,0,0,0,0,0,0,0,0,0,0,0,0,0,0,0,0,0
0,0,0,0,0,0,0,0,0,0,0,0,0,0,0,0,0,0,0
0,0,0,0,0,0,0,0,0,0,0,0,0,0,0,0,0,0,0
0,0,0,0,0,0,0,0,0,0,0,0,0,0,0,0,0,0,0
0,0,0,0,0,0,0,0,0,0,0,0,0,0,0,0,0,0,0
0,0,0,0,0,0,0,0,0,0,0,0,0,0,0,0,0,0,0
0,0,0,0,0,0,0,0,0,0,0,0,0,0,0,0,0,0,0
0,0,0,0,0,0,0,0,0,0,0,0,0,0,0,0,0,0,0
:endlayer
layer: 34
0,0,0,0,0,0,0,0,0,0,0,0,0,0,0,0,0,0,0
0,0,0,0,0,0,0,0,0,0,0,0,0,0,0,0,0,0,0
0,0,0,0,0,0,0,0,0,0,0,0,0,0,0,0,0,0,0
0,0,0,0,0,0,0,0,0,0,0,0,0,0,0,0,0,0,0
0,0,0,0,0,0,0,0,0,0,0,0,0,0,0,0,0,0,0
0,0,0,0,0,0,0,0,0,431,0,0,0,0,0,0,0,0,0
0,0,0,0,0,0,0,0,0,431,0,0,0,0,0,0,0,0,0
0,0,0,0,0,0,0,0,0,431,0,0,0,0,0,0,0,0,0
0,0,0,0,0,0,0,0,0,431,0,0,0,0,0,0,0,0,0
0,0,0,0,0,0,0,0,0,140,0,0,0,0,0,0,0,0,0
0,0,0,0,0,0,0,0,0,0,0,0,0,0,0,0,0,0,0
0,0,0,0,0,0,0,0,0,0,0,0,0,0,0,0,0,0,0
0,0,0,0,0,0,0,0,0,0,0,0,0,0,0,0,0,0,0
0,0,0,0,0,0,0,0,0,0,0,0,0,0,0,0,0,0,0
0,0,0,0,0,0,0,0,0,0,0,0,0,0,0,0,0,0,0
0,0,0,0,0,0,0,0,0,0,0,0,0,0,0,0,0,0,0
0,0,0,0,0,0,0,0,0,0,0,0,0,0,0,0,0,0,0
0,0,0,0,0,0,0,0,0,0,0,0,0,0,0,0,0,0,0
0,0,0,0,0,0,0,0,0,361,0,0,0,0,0,0,0,0,0
0,0,0,0,0,0,0,0,0,29,0,0,0,0,0,0,0,0,0
0,0,0,175,0,0,0,0,0,24,0,0,0,0,0,175,0,0,0
0,0,0,0,0,0,0,0,0,312,0,0,0,0,0,0,0,0,0
0,0,0,0,0,0,0,0,0,0,0,0,0,0,0,0,0,0,0
0,0,0,0,0,0,0,0,0,0,0,0,0,0,0,0,0,0,0
0,0,12,0,0,0,0,0,0,0,0,0,0,0,0,0,12,0,0
0,12,12,0,0,0,0,0,0,0,0,0,0,0,0,0,12,12,0
0,12,12,0,0,0,0,0,0,0,0,0,0,0,0,0,12,12,0
0,12,12,0,0,0,0,0,0,0,0,0,0,0,0,0,12,12,0
0,0,0,0,0,0,0,0,0,361,0,0,0,0,0,0,0,0,0
0,0,0,0,0,0,0,0,0,29,0,0,0,0,0,0,0,0,0
0,430,430,0,0,0,0,0,0,0,0,0,0,0,0,0,430,430,0
0,0,0,431,431,431,430,430,431,430,431,430,430,431,431,431,0,0,0
0,0,0,0,0,0,0,0,0,0,0,0,0,0,0,0,0,0,0
0,12,12,0,0,0,0,0,0,0,0,0,0,0,0,0,12,12,0
0,12,12,0,0,0,0,0,0,0,0,0,0,0,0,0,12,12,0
0,12,12,0,0,0,0,0,0,0,0,0,0,0,0,0,12,12,0
0,0,0,0,0,0,0,0,0,0,0,0,0,0,0,0,12,0,0
0,0,0,0,0,0,0,0,0,0,0,0,0,0,0,0,0,0,0
0,0,0,0,0,0,0,0,0,361,0,0,0,0,0,0,0,0,0
0,0,0,0,0,0,0,0,0,29,0,0,0,0,0,0,0,0,0
0,0,0,175,0,0,0,0,0,24,0,0,0,0,0,175,0,0,0
0,0,0,0,0,0,0,0,0,312,0,0,0,0,0,0,0,0,0
0,0,0,0,0,0,0,0,0,0,0,0,0,0,0,0,0,0,0
0,0,0,0,0,0,0,0,0,0,0,0,0,0,0,0,0,0,0
0,0,0,0,0,0,0,0,0,0,0,0,0,0,0,0,0,0,0
0,0,0,0,0,0,0,0,0,0,0,0,0,0,0,0,0,0,0
0,0,0,0,0,0,0,0,0,0,0,0,0,0,0,0,0,0,0
0,0,0,0,0,0,0,0,0,0,0,0,0,0,0,0,0,0,0
0,0,0,0,0,0,0,0,0,0,0,0,0,0,0,0,0,0,0
0,0,0,0,0,0,0,0,0,0,0,0,0,0,0,0,0,0,0
0,0,0,0,0,0,0,0,0,0,0,0,0,0,0,0,0,0,0
0,0,0,0,0,0,0,0,0,0,0,0,0,0,0,0,0,0,0
0,0,0,0,0,0,0,0,0,0,0,0,0,0,0,0,0,0,0
0,0,0,0,0,0,0,0,0,0,0,0,0,0,0,0,0,0,0
0,0,0,0,0,0,0,0,0,0,0,0,0,0,0,0,0,0,0
0,0,0,0,0,0,0,0,0,0,0,0,0,0,0,0,0,0,0
0,0,0,0,0,0,0,0,0,0,0,0,0,0,0,0,0,0,0
0,0,0,0,0,0,0,0,0,0,0,0,0,0,0,0,0,0,0
0,0,0,0,0,0,0,0,0,0,0,0,0,0,0,0,0,0,0
0,0,0,0,0,0,0,0,0,0,0,0,0,0,0,0,0,0,0
0,0,0,0,0,0,0,0,0,0,0,0,0,0,0,0,0,0,0
0,0,0,0,0,0,0,0,0,0,0,0,0,0,0,0,0,0,0
0,0,0,0,0,0,0,0,0,0,0,0,0,0,0,0,0,0,0
:endlayer
layer: 35
0,0,0,0,0,0,0,0,0,0,0,0,0,0,0,0,0,0,0
0,0,0,0,0,0,0,0,0,0,0,0,0,0,0,0,0,0,0
0,0,0,0,0,0,0,0,0,0,0,0,0,0,0,0,0,0,0
0,0,0,0,0,0,0,0,0,0,0,0,0,0,0,0,0,0,0
0,0,0,0,0,0,0,0,0,0,0,0,0,0,0,0,0,0,0
0,0,0,0,0,0,0,0,0,0,0,0,0,0,0,0,0,0,0
0,0,0,0,0,0,0,0,0,0,0,0,0,0,0,0,0,0,0
0,0,0,0,0,0,0,0,0,431,0,0,0,0,0,0,0,0,0
0,0,0,0,0,0,0,0,0,431,0,0,0,0,0,0,0,0,0
0,0,0,0,0,0,0,0,0,140,0,0,0,0,0,0,0,0,0
0,0,0,0,0,0,0,0,0,0,0,0,0,0,0,0,0,0,0
0,0,0,0,0,0,0,0,0,0,0,0,0,0,0,0,0,0,0
0,0,0,0,0,0,0,0,0,0,0,0,0,0,0,0,0,0,0
0,0,0,0,0,0,0,0,0,0,0,0,0,0,0,0,0,0,0
0,0,0,0,0,0,0,0,0,0,0,0,0,0,0,0,0,0,0
0,0,0,0,0,0,0,0,0,0,0,0,0,0,0,0,0,0,0
0,0,0,0,0,0,0,0,0,0,0,0,0,0,0,0,0,0,0
0,0,0,0,0,0,0,0,0,0,0,0,0,0,0,0,0,0,0
0,0,0,0,0,0,0,0,55,361,55,0,0,0,0,0,0,0,0
0,0,0,0,0,0,0,0,66,29,54,0,0,0,0,0,0,0,0
0,0,0,0,0,0,0,0,55,77,55,0,0,0,0,0,0,0,0
0,0,0,0,0,0,0,0,0,0,0,0,0,0,0,0,0,0,0
0,0,0,0,0,0,0,0,0,0,0,0,0,0,0,0,0,0,0
0,0,0,0,0,0,0,0,0,0,0,0,0,0,0,0,0,0,0
0,0,0,0,0,0,0,0,0,0,0,0,0,0,0,0,0,0,0
0,0,0,0,0,0,0,0,0,0,0,0,0,0,0,0,0,0,0
0,0,0,0,0,0,0,0,0,0,0,0,0,0,0,0,0,0,0
0,12,0,0,0,0,0,0,0,0,0,0,0,0,0,0,0,12,0
0,12,0,0,0,0,0,0,0,361,0,0,0,0,0,0,0,12,0
0,12,0,0,0,0,0,0,0,29,0,0,0,0,0,0,0,12,0
66,227,227,227,227,227,227,227,227,227,227,227,227,227,227,227,227,227,54
0,12,0,0,0,0,0,0,0,77,0,0,0,0,0,0,0,12,0
0,12,0,0,0,0,0,0,0,0,0,0,0,0,0,0,0,12,0
0,12,0,0,0,0,0,0,0,0,0,0,0,0,0,0,0,12,0
0,0,0,0,0,0,0,0,0,0,0,0,0,0,0,0,0,0,0
0,0,0,0,0,0,0,0,0,0,0,0,0,0,0,0,0,0,0
0,0,0,0,0,0,0,0,0,0,0,0,0,0,0,0,0,0,0
0,0,0,0,0,0,0,0,0,0,0,0,0,0,0,0,0,0,0
0,0,0,0,0,0,0,0,55,361,55,0,0,0,0,0,0,0,0
0,0,0,0,0,0,0,0,66,29,54,0,0,0,0,0,0,0,0
0,0,0,0,0,0,0,0,55,77,55,0,0,0,0,0,0,0,0
0,0,0,0,0,0,0,0,0,0,0,0,0,0,0,0,0,0,0
0,0,0,0,0,0,0,0,0,0,0,0,0,0,0,0,0,0,0
0,0,0,0,0,0,0,0,0,0,0,0,0,0,0,0,0,0,0
0,0,0,0,0,0,0,0,0,0,0,0,0,0,0,0,0,0,0
0,0,0,0,0,0,0,0,0,0,0,0,0,0,0,0,0,0,0
0,0,0,0,0,0,0,0,0,0,0,0,0,0,0,0,0,0,0
0,0,0,0,0,0,0,0,0,0,0,0,0,0,0,0,0,0,0
0,0,0,0,0,0,0,0,0,0,0,0,0,0,0,0,0,0,0
0,0,0,0,0,0,0,0,0,0,0,0,0,0,0,0,0,0,0
0,0,0,0,0,0,0,0,0,0,0,0,0,0,0,0,0,0,0
0,0,0,0,0,0,0,0,0,0,0,0,0,0,0,0,0,0,0
0,0,0,0,0,0,0,0,0,0,0,0,0,0,0,0,0,0,0
0,0,0,0,0,0,0,0,0,0,0,0,0,0,0,0,0,0,0
0,0,0,0,0,0,0,0,0,0,0,0,0,0,0,0,0,0,0
0,0,0,0,0,0,0,0,0,0,0,0,0,0,0,0,0,0,0
0,0,0,0,0,0,0,0,0,0,0,0,0,0,0,0,0,0,0
0,0,0,0,0,0,0,0,0,0,0,0,0,0,0,0,0,0,0
0,0,0,0,0,0,0,0,0,0,0,0,0,0,0,0,0,0,0
0,0,0,0,0,0,0,0,0,0,0,0,0,0,0,0,0,0,0
0,0,0,0,0,0,0,0,0,0,0,0,0,0,0,0,0,0,0
0,0,0,0,0,0,0,0,0,0,0,0,0,0,0,0,0,0,0
0,0,0,0,0,0,0,0,0,0,0,0,0,0,0,0,0,0,0
:endlayer
layer: 36
0,0,0,0,0,0,0,0,0,0,0,0,0,0,0,0,0,0,0
0,0,0,0,0,0,0,0,0,0,0,0,0,0,0,0,0,0,0
0,0,0,0,0,0,0,0,0,0,0,0,0,0,0,0,0,0,0
0,0,0,0,0,0,0,0,0,0,0,0,0,0,0,0,0,0,0
0,0,0,0,0,0,0,0,0,0,0,0,0,0,0,0,0,0,0
0,0,0,0,0,0,0,0,0,0,0,0,0,0,0,0,0,0,0
0,0,0,0,0,0,0,0,0,0,0,0,0,0,0,0,0,0,0
0,0,0,0,0,0,0,0,0,0,0,0,0,0,0,0,0,0,0
0,0,0,0,0,0,0,0,0,0,0,0,0,0,0,0,0,0,0
0,0,0,0,0,0,0,0,0,175,0,0,0,0,0,0,0,0,0
0,0,0,0,0,0,0,0,0,0,0,0,0,0,0,0,0,0,0
0,0,0,0,0,0,0,0,0,0,0,0,0,0,0,0,0,0,0
0,0,0,0,0,0,0,0,0,0,0,0,0,0,0,0,0,0,0
0,0,0,0,0,0,0,0,0,0,0,0,0,0,0,0,0,0,0
0,0,0,0,0,0,0,0,0,0,0,0,0,0,0,0,0,0,0
0,0,0,0,0,0,0,0,0,0,0,0,0,0,0,0,0,0,0
0,0,0,0,0,0,0,0,0,0,0,0,0,0,0,0,0,0,0
0,0,0,0,0,0,0,0,428,428,428,0,0,0,0,0,0,0,0
0,0,0,0,0,0,0,433,434,361,434,168,0,0,0,0,0,0,0
0,0,0,0,0,0,0,433,434,29,434,168,0,0,0,0,0,0,0
0,0,0,0,0,0,0,433,434,434,434,168,0,0,0,0,0,0,0
0,0,0,0,0,0,0,0,68,68,68,0,0,0,0,0,0,0,0
0,0,0,0,0,0,0,0,0,0,0,0,0,0,0,0,0,0,0
0,0,0,0,0,0,0,0,0,0,0,0,0,0,0,0,0,0,0
0,0,0,0,0,0,0,0,0,0,0,0,0,0,0,0,0,0,0
0,0,0,0,0,0,0,0,0,0,0,0,0,0,0,0,0,0,0
0,0,0,0,0,0,0,0,0,0,0,0,0,0,0,0,0,0,0
0,0,0,0,0,0,0,0,0,0,0,0,0,0,0,0,0,0,0
0,0,0,0,0,0,0,0,0,361,0,0,0,0,0,0,0,0,0
0,0,0,0,0,0,0,0,0,29,0,0,0,0,0,0,0,0,0
0,175,0,430,0,0,0,0,0,0,0,0,0,0,0,430,0,175,0
0,0,0,0,430,431,431,431,431,430,431,431,431,431,430,0,0,0,0
0,0,0,0,0,0,0,0,0,0,0,0,0,0,0,0,0,0,0
0,0,0,0,0,0,0,0,0,0,0,0,0,0,0,0,0,0,0
0,0,0,0,0,0,0,0,0,0,0,0,0,0,0,0,0,0,0
0,0,0,0,0,0,0,0,0,0,0,0,0,0,0,0,0,0,0
0,0,0,0,0,0,0,0,0,0,0,0,0,0,0,0,0,0,0
0,0,0,0,0,0,0,0,428,428,428,0,0,0,0,0,0,0,0
0,0,0,0,0,0,0,433,434,361,434,168,0,0,0,0,0,0,0
0,0,0,0,0,0,0,433,434,29,434,168,0,0,0,0,0,0,0
0,0,0,0,0,0,0,433,434,434,434,168,0,0,0,0,0,0,0
0,0,0,0,0,0,0,0,68,68,68,0,0,0,0,0,0,0,0
0,0,0,0,0,0,0,0,0,0,0,0,0,0,0,0,0,0,0
0,0,0,0,0,0,0,0,0,0,0,0,0,0,0,0,0,0,0
0,0,0,0,0,0,0,0,0,0,0,0,0,0,0,0,0,0,0
0,0,0,0,0,0,0,0,0,0,0,0,0,0,0,0,0,0,0
0,0,0,0,0,0,0,0,0,0,0,0,0,0,0,0,0,0,0
0,0,0,0,0,0,0,0,0,0,0,0,0,0,0,0,0,0,0
0,0,0,0,0,0,0,0,0,0,0,0,0,0,0,0,0,0,0
0,0,0,0,0,0,0,0,0,0,0,0,0,0,0,0,0,0,0
0,0,0,0,0,0,0,0,0,0,0,0,0,0,0,0,0,0,0
0,0,0,0,0,0,0,0,0,0,0,0,0,0,0,0,0,0,0
0,0,0,0,0,0,0,0,0,0,0,0,0,0,0,0,0,0,0
0,0,0,0,0,0,0,0,0,0,0,0,0,0,0,0,0,0,0
0,0,0,0,0,0,0,0,0,0,0,0,0,0,0,0,0,0,0
0,0,0,0,0,0,0,0,0,0,0,0,0,0,0,0,0,0,0
0,0,0,0,0,0,0,0,0,0,0,0,0,0,0,0,0,0,0
0,0,0,0,0,0,0,0,0,0,0,0,0,0,0,0,0,0,0
0,0,0,0,0,0,0,0,0,0,0,0,0,0,0,0,0,0,0
0,0,0,0,0,0,0,0,0,0,0,0,0,0,0,0,0,0,0
0,0,0,0,0,0,0,0,0,0,0,0,0,0,0,0,0,0,0
0,0,0,0,0,0,0,0,0,0,0,0,0,0,0,0,0,0,0
0,0,0,0,0,0,0,0,0,0,0,0,0,0,0,0,0,0,0
:endlayer
layer: 37
0,0,0,0,0,0,0,0,0,0,0,0,0,0,0,0,0,0,0
0,0,0,0,0,0,0,0,0,0,0,0,0,0,0,0,0,0,0
0,0,0,0,0,0,0,0,0,0,0,0,0,0,0,0,0,0,0
0,0,0,0,0,0,0,0,0,0,0,0,0,0,0,0,0,0,0
0,0,0,0,0,0,0,0,0,0,0,0,0,0,0,0,0,0,0
0,0,0,0,0,0,0,0,0,0,0,0,0,0,0,0,0,0,0
0,0,0,0,0,0,0,0,0,0,0,0,0,0,0,0,0,0,0
0,0,0,0,0,0,0,0,0,0,0,0,0,0,0,0,0,0,0
0,0,0,0,0,0,0,0,0,0,0,0,0,0,0,0,0,0,0
0,0,0,0,0,0,0,0,0,0,0,0,0,0,0,0,0,0,0
0,0,0,0,0,0,0,0,0,0,0,0,0,0,0,0,0,0,0
0,0,0,0,0,0,0,0,0,0,0,0,0,0,0,0,0,0,0
0,0,0,0,0,0,0,0,0,0,0,0,0,0,0,0,0,0,0
0,0,0,0,0,0,0,0,0,0,0,0,0,0,0,0,0,0,0
0,0,0,0,0,0,0,0,0,0,0,0,0,0,0,0,0,0,0
0,0,0,0,0,0,0,0,0,0,0,0,0,0,0,0,0,0,0
0,0,0,0,0,0,0,0,0,0,0,0,0,0,0,0,0,0,0
0,0,0,0,0,0,0,0,0,0,0,0,0,0,0,0,0,0,0
0,0,0,0,0,0,0,0,0,361,0,0,0,0,0,0,0,0,0
0,0,0,0,0,0,0,0,443,29,440,0,0,0,0,0,0,0,0
0,0,0,0,0,0,0,0,0,0,0,0,0,0,0,0,0,0,0
0,0,0,0,0,0,0,0,0,0,0,0,0,0,0,0,0,0,0
0,0,0,0,0,0,0,0,0,0,0,0,0,0,0,0,0,0,0
0,0,0,0,0,0,0,0,0,0,0,0,0,0,0,0,0,0,0
0,0,0,0,0,0,0,0,0,0,0,0,0,0,0,0,0,0,0
0,0,0,0,0,0,0,0,0,0,0,0,0,0,0,0,0,0,0
0,0,0,0,0,0,0,0,0,0,0,0,0,0,0,0,0,0,0
0,0,0,0,0,0,0,0,0,0,0,0,0,0,0,0,0,0,0
0,0,0,0,0,0,0,0,0,361,0,0,0,0,0,0,0,0,0
0,0,0,0,0,0,0,0,0,29,0,0,0,0,0,0,0,0,0
0,0,0,12,0,0,0,0,0,81,0,0,0,0,0,12,0,0,0
0,0,0,431,431,430,12,0,0,0,0,0,12,430,431,431,0,0,0
0,0,0,0,0,0,430,431,431,430,431,431,430,0,0,0,0,0,0
0,0,0,0,0,0,0,0,0,0,0,0,0,0,0,0,0,0,0
0,0,0,0,0,0,0,0,0,0,0,0,0,0,0,0,0,0,0
0,0,0,0,0,0,0,0,0,0,0,0,0,0,0,0,0,0,0
0,0,0,0,0,0,0,0,0,0,0,0,0,0,0,0,0,0,0
0,0,0,0,0,0,0,0,0,0,0,0,0,0,0,0,0,0,0
0,0,0,0,0,0,0,0,0,361,0,0,0,0,0,0,0,0,0
0,0,0,0,0,0,0,0,444,29,441,0,0,0,0,0,0,0,0
0,0,0,0,0,0,0,0,0,442,0,0,0,0,0,0,0,0,0
0,0,0,0,0,0,0,0,0,0,0,0,0,0,0,0,0,0,0
0,0,0,0,0,0,0,0,0,0,0,0,0,0,0,0,0,0,0
0,0,0,0,0,0,0,0,0,0,0,0,0,0,0,0,0,0,0
0,0,0,0,0,0,0,0,0,0,0,0,0,0,0,0,0,0,0
0,0,0,0,0,0,0,0,0,0,0,0,0,0,0,0,0,0,0
0,0,0,0,0,0,0,0,0,0,0,0,0,0,0,0,0,0,0
0,0,0,0,0,0,0,0,0,0,0,0,0,0,0,0,0,0,0
0,0,0,0,0,0,0,0,0,0,0,0,0,0,0,0,0,0,0
0,0,0,0,0,0,0,0,0,0,0,0,0,0,0,0,0,0,0
0,0,0,0,0,0,0,0,0,0,0,0,0,0,0,0,0,0,0
0,0,0,0,0,0,0,0,0,0,0,0,0,0,0,0,0,0,0
0,0,0,0,0,0,0,0,0,0,0,0,0,0,0,0,0,0,0
0,0,0,0,0,0,0,0,0,0,0,0,0,0,0,0,0,0,0
0,0,0,0,0,0,0,0,0,0,0,0,0,0,0,0,0,0,0
0,0,0,0,0,0,0,0,0,0,0,0,0,0,0,0,0,0,0
0,0,0,0,0,0,0,0,0,0,0,0,0,0,0,0,0,0,0
0,0,0,0,0,0,0,0,0,0,0,0,0,0,0,0,0,0,0
0,0,0,0,0,0,0,0,0,0,0,0,0,0,0,0,0,0,0
0,0,0,0,0,0,0,0,0,0,0,0,0,0,0,0,0,0,0
0,0,0,0,0,0,0,0,0,0,0,0,0,0,0,0,0,0,0
0,0,0,0,0,0,0,0,0,0,0,0,0,0,0,0,0,0,0
0,0,0,0,0,0,0,0,0,0,0,0,0,0,0,0,0,0,0
:endlayer
layer: 38
0,0,0,0,0,0,0,0,0,0,0,0,0,0,0,0,0,0,0
0,0,0,0,0,0,0,0,0,0,0,0,0,0,0,0,0,0,0
0,0,0,0,0,0,0,0,0,0,0,0,0,0,0,0,0,0,0
