# Ancient Warfare Structure Template File
# Auto-generated structure template file. created on: 2/25/2024 at: 0:3:21
# Lines beginning with # denote comments

header:
version=2.11
name=NoggWoolMerchantGalleon
mods=
size=21,33,50
offset=10,3,36
:endheader

#### VALIDATION ####
validation:
type=water
structureAuthor=TheOddlySeagull
survival=false
worldGenEnabled=true
unique=false
preserveBlocks=false
preventNaturalHostileSpawns=true
selectionWeight=40
clusterValue=50
minDuplicateDistance=1000
dimensionWhiteList=true
dimensionList=0
biomeGroupList=
biomeWhiteList=true
biomeList=minecraft:ocean,minecraft:deep_ocean
leveling=0
fill=0
border=0
blockSwap=false
territoryName=noggfleet
biomeReplacement=minecraft:
:endvalidation

#### LAYERS ####
layer: 0
1,1,1,1,1,1,1,1,1,1,1,1,1,1,1,1,1,1,1,1,1
1,1,1,1,1,1,1,1,1,1,1,1,1,1,1,1,1,1,1,1,1
1,1,1,1,1,1,1,1,1,1,1,1,1,1,1,1,1,1,1,1,1
1,1,1,1,1,1,1,1,1,1,1,1,1,1,1,1,1,1,1,1,1
1,1,1,1,1,1,1,1,1,1,1,1,1,1,1,1,1,1,1,1,1
1,1,1,1,1,1,1,1,1,1,1,1,1,1,1,1,1,1,1,1,1
1,1,1,1,1,1,1,1,1,1,1,1,1,1,1,1,1,1,1,1,1
1,1,1,1,1,1,1,1,1,1,1,1,1,1,1,1,1,1,1,1,1
1,1,1,1,1,1,1,1,1,1,1,1,1,1,1,1,1,1,1,1,1
1,1,1,1,1,1,1,1,1,1,1,1,1,1,1,1,1,1,1,1,1
1,1,1,1,1,1,1,1,1,1,1,1,1,1,1,1,1,1,1,1,1
1,1,1,1,1,1,1,1,1,1,1,1,1,1,1,1,1,1,1,1,1
1,1,1,1,1,1,1,1,1,1,1,1,1,1,1,1,1,1,1,1,1
1,1,1,1,1,1,1,1,1,1,1,1,1,1,1,1,1,1,1,1,1
1,1,1,1,1,1,1,1,1,1,1,1,1,1,1,1,1,1,1,1,1
1,1,1,1,1,1,1,1,1,1,1,1,1,1,1,1,1,1,1,1,1
1,1,1,1,1,1,1,1,1,1,1,1,1,1,1,1,1,1,1,1,1
1,1,1,1,1,1,1,1,1,1,1,1,1,1,1,1,1,1,1,1,1
1,1,1,1,1,1,1,1,1,1,1,1,1,1,1,1,1,1,1,1,1
1,1,1,1,1,1,1,1,1,1,1,1,1,1,1,1,1,1,1,1,1
1,1,1,1,1,1,1,1,1,1,1,1,1,1,1,1,1,1,1,1,1
1,1,1,1,1,1,1,1,1,1,1,1,1,1,1,1,1,1,1,1,1
1,1,1,1,1,1,1,1,1,1,1,1,1,1,1,1,1,1,1,1,1
1,1,1,1,1,1,1,1,1,1,1,1,1,1,1,1,1,1,1,1,1
1,1,1,1,1,1,1,1,1,1,1,1,1,1,1,1,1,1,1,1,1
1,1,1,1,1,1,1,1,1,1,1,1,1,1,1,1,1,1,1,1,1
1,1,1,1,1,1,1,1,1,1,1,1,1,1,1,1,1,1,1,1,1
1,1,1,1,1,1,1,1,1,1,1,1,1,1,1,1,1,1,1,1,1
1,1,1,1,1,1,1,1,1,1,1,1,1,1,1,1,1,1,1,1,1
1,1,1,1,1,1,1,1,1,1,1,1,1,1,1,1,1,1,1,1,1
1,1,1,1,1,1,1,1,1,1,1,1,1,1,1,1,1,1,1,1,1
1,1,1,1,1,1,1,1,1,1,1,1,1,1,1,1,1,1,1,1,1
1,1,1,1,1,1,1,1,1,1,1,1,1,1,1,1,1,1,1,1,1
1,1,1,1,1,1,1,1,1,1,1,1,1,1,1,1,1,1,1,1,1
1,1,1,1,1,1,1,1,1,1,1,1,1,1,1,1,1,1,1,1,1
1,1,1,1,1,1,1,1,1,1,1,1,1,1,1,1,1,1,1,1,1
1,1,1,1,1,1,1,1,1,1,1,1,1,1,1,1,1,1,1,1,1
1,1,1,1,1,1,1,1,1,1,1,1,1,1,1,1,1,1,1,1,1
1,1,1,1,1,1,1,1,1,1,1,1,1,1,1,1,1,1,1,1,1
1,1,1,1,1,1,1,1,1,1,1,1,1,1,1,1,1,1,1,1,1
1,1,1,1,1,1,1,1,1,1,1,1,1,1,1,1,1,1,1,1,1
1,1,1,1,1,1,1,1,1,1,1,1,1,1,1,1,1,1,1,1,1
1,1,1,1,1,1,1,1,1,1,1,1,1,1,1,1,1,1,1,1,1
1,1,1,1,1,1,1,1,1,1,1,1,1,1,1,1,1,1,1,1,1
1,1,1,1,1,1,1,1,1,1,1,1,1,1,1,1,1,1,1,1,1
1,1,1,1,1,1,1,1,1,1,1,1,1,1,1,1,1,1,1,1,1
1,1,1,1,1,1,1,1,1,1,1,1,1,1,1,1,1,1,1,1,1
1,1,1,1,1,1,1,1,1,1,1,1,1,1,1,1,1,1,1,1,1
1,1,1,1,1,1,1,1,1,1,1,1,1,1,1,1,1,1,1,1,1
1,1,1,1,1,1,1,1,1,1,1,1,1,1,1,1,1,1,1,1,1
:endlayer
layer: 1
1,1,1,1,1,1,1,1,1,1,1,1,1,1,1,1,1,1,1,1,1
1,1,1,1,1,1,1,1,1,1,1,1,1,1,1,1,1,1,1,1,1
1,1,1,1,1,1,1,1,1,1,1,1,1,1,1,1,1,1,1,1,1
1,1,1,1,1,1,1,1,1,1,1,1,1,1,1,1,1,1,1,1,1
1,1,1,1,1,1,1,1,1,1,1,1,1,1,1,1,1,1,1,1,1
1,1,1,1,1,1,1,1,1,1,1,1,1,1,1,1,1,1,1,1,1
1,1,1,1,1,1,1,1,1,1,1,1,1,1,1,1,1,1,1,1,1
1,1,1,1,1,1,1,1,1,1,1,1,1,1,1,1,1,1,1,1,1
1,1,1,1,1,1,1,1,1,1,1,1,1,1,1,1,1,1,1,1,1
1,1,1,1,1,1,1,1,1,1,1,1,1,1,1,1,1,1,1,1,1
1,1,1,1,1,1,1,1,1,2,2,2,1,1,1,1,1,1,1,1,1
1,1,1,1,1,1,1,1,2,2,2,2,2,1,1,1,1,1,1,1,1
1,1,1,1,1,1,1,1,2,2,2,2,2,1,1,1,1,1,1,1,1
1,1,1,1,1,1,1,1,2,2,2,2,2,1,1,1,1,1,1,1,1
1,1,1,1,1,1,1,1,2,2,2,2,2,1,1,1,1,1,1,1,1
1,1,1,1,1,1,1,1,2,2,2,2,2,1,1,1,1,1,1,1,1
1,1,1,1,1,1,1,1,2,2,2,2,2,1,1,1,1,1,1,1,1
1,1,1,1,1,1,1,1,2,2,2,2,2,1,1,1,1,1,1,1,1
1,1,1,1,1,1,1,1,2,2,2,2,2,1,1,1,1,1,1,1,1
1,1,1,1,1,1,1,1,2,2,2,2,2,1,1,1,1,1,1,1,1
1,1,1,1,1,1,1,1,2,2,2,2,2,1,1,1,1,1,1,1,1
1,1,1,1,1,1,1,1,2,2,2,2,2,1,1,1,1,1,1,1,1
1,1,1,1,1,1,1,1,2,2,2,2,2,1,1,1,1,1,1,1,1
1,1,1,1,1,1,1,1,2,2,2,2,2,1,1,1,1,1,1,1,1
1,1,1,1,1,1,1,1,2,2,2,2,2,1,1,1,1,1,1,1,1
1,1,1,1,1,1,1,1,2,2,2,2,2,1,1,1,1,1,1,1,1
1,1,1,1,1,1,1,1,2,2,2,2,2,1,1,1,1,1,1,1,1
1,1,1,1,1,1,1,1,2,2,2,2,2,1,1,1,1,1,1,1,1
1,1,1,1,1,1,1,1,1,2,2,2,1,1,1,1,1,1,1,1,1
1,1,1,1,1,1,1,1,1,2,2,2,1,1,1,1,1,1,1,1,1
1,1,1,1,1,1,1,1,1,1,2,1,1,1,1,1,1,1,1,1,1
1,1,1,1,1,1,1,1,1,1,2,1,1,1,1,1,1,1,1,1,1
1,1,1,1,1,1,1,1,1,1,1,1,1,1,1,1,1,1,1,1,1
1,1,1,1,1,1,1,1,1,1,1,1,1,1,1,1,1,1,1,1,1
1,1,1,1,1,1,1,1,1,1,1,1,1,1,1,1,1,1,1,1,1
1,1,1,1,1,1,1,1,1,1,1,1,1,1,1,1,1,1,1,1,1
1,1,1,1,1,1,1,1,1,1,1,1,1,1,1,1,1,1,1,1,1
1,1,1,1,1,1,1,1,1,1,1,1,1,1,1,1,1,1,1,1,1
1,1,1,1,1,1,1,1,1,1,1,1,1,1,1,1,1,1,1,1,1
1,1,1,1,1,1,1,1,1,1,1,1,1,1,1,1,1,1,1,1,1
1,1,1,1,1,1,1,1,1,1,1,1,1,1,1,1,1,1,1,1,1
1,1,1,1,1,1,1,1,1,1,1,1,1,1,1,1,1,1,1,1,1
1,1,1,1,1,1,1,1,1,1,1,1,1,1,1,1,1,1,1,1,1
1,1,1,1,1,1,1,1,1,1,1,1,1,1,1,1,1,1,1,1,1
1,1,1,1,1,1,1,1,1,1,1,1,1,1,1,1,1,1,1,1,1
1,1,1,1,1,1,1,1,1,1,1,1,1,1,1,1,1,1,1,1,1
1,1,1,1,1,1,1,1,1,1,1,1,1,1,1,1,1,1,1,1,1
1,1,1,1,1,1,1,1,1,1,1,1,1,1,1,1,1,1,1,1,1
1,1,1,1,1,1,1,1,1,1,1,1,1,1,1,1,1,1,1,1,1
1,1,1,1,1,1,1,1,1,1,1,1,1,1,1,1,1,1,1,1,1
:endlayer
layer: 2
1,1,1,1,1,1,1,1,1,1,1,1,1,1,1,1,1,1,1,1,1
1,1,1,1,1,1,1,1,1,1,1,1,1,1,1,1,1,1,1,1,1
1,1,1,1,1,1,1,1,1,1,1,1,1,1,1,1,1,1,1,1,1
1,1,1,1,1,1,1,1,1,1,1,1,1,1,1,1,1,1,1,1,1
1,1,1,1,1,1,1,1,1,1,1,1,1,1,1,1,1,1,1,1,1
1,1,1,1,1,1,1,1,1,1,1,1,1,1,1,1,1,1,1,1,1
1,1,1,1,1,1,1,1,1,1,1,1,1,1,1,1,1,1,1,1,1
1,1,1,1,1,1,1,1,1,1,1,1,1,1,1,1,1,1,1,1,1
1,1,1,1,1,1,1,1,1,1,1,1,1,1,1,1,1,1,1,1,1
1,1,1,1,1,1,1,1,1,1,1,1,1,1,1,1,1,1,1,1,1
1,1,1,1,1,1,1,1,2,2,2,2,2,1,1,1,1,1,1,1,1
1,1,1,1,1,1,1,2,2,2,2,2,2,2,1,1,1,1,1,1,1
1,1,1,1,1,1,1,2,2,2,2,3,3,2,1,1,1,1,1,1,1
1,1,1,1,1,1,1,2,0,18,2,0,0,2,1,1,1,1,1,1,1
1,1,1,1,1,1,1,2,0,19,2,0,0,2,1,1,1,1,1,1,1
1,1,1,1,1,1,1,2,0,0,2,9,2,2,1,1,1,1,1,1,1
1,1,1,1,1,1,1,2,26,20,2,0,4,2,1,1,1,1,1,1,1
1,1,1,1,1,1,1,2,27,21,2,10,4,2,1,1,1,1,1,1,1
1,1,1,1,1,1,1,2,28,0,2,0,4,2,1,1,1,1,1,1,1
1,1,1,1,1,1,1,2,2,9,13,9,2,2,1,1,1,1,1,1,1
1,1,1,1,1,1,1,2,14,0,14,0,5,2,1,1,1,1,1,1,1
1,1,1,1,1,1,1,2,15,0,15,0,6,2,1,1,1,1,1,1,1
1,1,1,1,1,1,1,2,29,0,16,11,7,2,1,1,1,1,1,1,1
1,1,1,1,1,1,1,30,0,22,0,0,8,2,1,1,1,1,1,1,1
1,1,1,1,1,1,1,2,0,23,7,7,2,2,1,1,1,1,1,1,1
1,1,1,1,1,1,1,2,24,24,8,8,2,2,1,1,1,1,1,1,1
1,1,1,1,1,1,1,2,25,25,17,12,2,2,1,1,1,1,1,1,1
1,1,1,1,1,1,1,2,2,2,2,2,2,2,1,1,1,1,1,1,1
1,1,1,1,1,1,1,1,2,2,2,2,2,1,1,1,1,1,1,1,1
1,1,1,1,1,1,1,1,2,2,13,2,2,1,1,1,1,1,1,1,1
1,1,1,1,1,1,1,1,1,2,2,2,1,1,1,1,1,1,1,1,1
1,1,1,1,1,1,1,1,1,2,2,2,1,1,1,1,1,1,1,1,1
1,1,1,1,1,1,1,1,1,1,2,1,1,1,1,1,1,1,1,1,1
1,1,1,1,1,1,1,1,1,1,2,1,1,1,1,1,1,1,1,1,1
1,1,1,1,1,1,1,1,1,1,1,1,1,1,1,1,1,1,1,1,1
1,1,1,1,1,1,1,1,1,1,1,1,1,1,1,1,1,1,1,1,1
1,1,1,1,1,1,1,1,1,1,1,1,1,1,1,1,1,1,1,1,1
1,1,1,1,1,1,1,1,1,1,1,1,1,1,1,1,1,1,1,1,1
1,1,1,1,1,1,1,1,1,1,1,1,1,1,1,1,1,1,1,1,1
1,1,1,1,1,1,1,1,1,1,1,1,1,1,1,1,1,1,1,1,1
1,1,1,1,1,1,1,1,1,1,1,1,1,1,1,1,1,1,1,1,1
1,1,1,1,1,1,1,1,1,1,1,1,1,1,1,1,1,1,1,1,1
1,1,1,1,1,1,1,1,1,1,1,1,1,1,1,1,1,1,1,1,1
1,1,1,1,1,1,1,1,1,1,1,1,1,1,1,1,1,1,1,1,1
1,1,1,1,1,1,1,1,1,1,1,1,1,1,1,1,1,1,1,1,1
1,1,1,1,1,1,1,1,1,1,1,1,1,1,1,1,1,1,1,1,1
1,1,1,1,1,1,1,1,1,1,1,1,1,1,1,1,1,1,1,1,1
1,1,1,1,1,1,1,1,1,1,1,1,1,1,1,1,1,1,1,1,1
1,1,1,1,1,1,1,1,1,1,1,1,1,1,1,1,1,1,1,1,1
1,1,1,1,1,1,1,1,1,1,1,1,1,1,1,1,1,1,1,1,1
:endlayer
layer: 3
0,0,0,0,0,0,0,0,0,0,0,0,0,0,0,0,0,0,0,0,0
0,0,0,0,0,0,0,0,0,0,0,0,0,0,0,0,0,0,0,0,0
0,0,0,0,0,0,0,0,0,0,0,0,0,0,0,0,0,0,0,0,0
0,0,0,0,0,0,0,0,0,0,0,0,0,0,0,0,0,0,0,0,0
0,0,0,0,0,0,0,0,0,0,0,0,0,0,0,0,0,0,0,0,0
0,0,0,0,0,0,0,0,0,0,0,0,0,0,0,0,0,0,0,0,0
0,0,0,0,0,0,0,0,0,0,0,0,0,0,0,0,0,0,0,0,0
0,0,0,0,0,0,0,0,0,0,0,0,0,0,0,0,0,0,0,0,0
0,0,0,0,0,0,0,0,0,0,0,0,0,0,0,0,0,0,0,0,0
0,0,0,0,0,0,0,0,58,2,2,2,40,0,0,0,0,0,0,0,0
0,0,0,0,0,0,0,31,30,55,3,44,41,31,0,0,0,0,0,0,0
0,0,0,0,0,0,31,3,59,0,0,0,42,3,31,0,0,0,0,0,0
0,0,0,0,0,0,2,2,2,2,50,0,0,33,2,0,0,0,0,0,0
0,0,0,0,0,0,30,61,0,0,2,0,0,34,2,0,0,0,0,0,0
0,0,0,0,0,0,2,62,0,0,2,0,0,35,2,0,0,0,0,0,0
0,0,0,0,0,0,30,63,0,0,2,45,2,2,2,0,0,0,0,0,0
0,0,0,0,0,0,2,64,0,0,2,0,0,36,2,0,0,0,0,0,0
0,0,0,0,0,0,30,0,0,0,2,0,0,37,2,0,0,0,0,0,0
0,0,0,0,0,0,2,65,0,0,2,0,0,38,2,0,0,0,0,0,0
0,0,0,0,0,0,2,2,2,45,13,46,2,2,2,0,0,0,0,0,0
0,0,0,0,0,0,2,66,60,0,14,0,43,39,2,0,0,0,0,0,0
0,0,0,0,0,0,2,66,60,0,15,0,43,39,2,0,0,0,0,0,0
0,0,0,0,0,0,2,66,60,0,0,0,43,39,2,0,0,0,0,0,0
0,0,0,0,0,0,2,67,0,0,0,0,43,39,2,0,0,0,0,0,0
0,0,0,0,0,0,2,7,0,0,0,0,2,0,2,0,0,0,0,0,0
0,0,0,0,0,0,2,8,0,0,0,0,2,2,2,0,0,0,0,0,0
0,0,0,0,0,0,2,2,24,24,47,47,2,2,2,0,0,0,0,0,0
0,0,0,0,0,0,2,2,25,25,25,25,2,2,2,0,0,0,0,0,0
0,0,0,0,0,0,32,2,25,25,25,25,2,2,32,0,0,0,0,0,0
0,0,0,0,0,0,0,2,13,2,13,2,13,2,0,0,0,0,0,0,0
0,0,0,0,0,0,0,32,2,56,51,48,2,32,0,0,0,0,0,0,0
0,0,0,0,0,0,0,0,2,57,52,49,2,0,0,0,0,0,0,0,0
0,0,0,0,0,0,0,0,32,2,53,2,32,0,0,0,0,0,0,0,0
0,0,0,0,0,0,0,0,0,2,54,2,0,0,0,0,0,0,0,0,0
0,0,0,0,0,0,0,0,0,32,2,32,0,0,0,0,0,0,0,0,0
0,0,0,0,0,0,0,0,0,0,2,0,0,0,0,0,0,0,0,0,0
0,0,0,0,0,0,0,0,0,0,32,0,0,0,0,0,0,0,0,0,0
0,0,0,0,0,0,0,0,0,0,0,0,0,0,0,0,0,0,0,0,0
0,0,0,0,0,0,0,0,0,0,0,0,0,0,0,0,0,0,0,0,0
0,0,0,0,0,0,0,0,0,0,0,0,0,0,0,0,0,0,0,0,0
0,0,0,0,0,0,0,0,0,0,0,0,0,0,0,0,0,0,0,0,0
0,0,0,0,0,0,0,0,0,0,0,0,0,0,0,0,0,0,0,0,0
0,0,0,0,0,0,0,0,0,0,0,0,0,0,0,0,0,0,0,0,0
0,0,0,0,0,0,0,0,0,0,0,0,0,0,0,0,0,0,0,0,0
0,0,0,0,0,0,0,0,0,0,0,0,0,0,0,0,0,0,0,0,0
0,0,0,0,0,0,0,0,0,0,0,0,0,0,0,0,0,0,0,0,0
0,0,0,0,0,0,0,0,0,0,0,0,0,0,0,0,0,0,0,0,0
0,0,0,0,0,0,0,0,0,0,0,0,0,0,0,0,0,0,0,0,0
0,0,0,0,0,0,0,0,0,0,0,0,0,0,0,0,0,0,0,0,0
0,0,0,0,0,0,0,0,0,0,0,0,0,0,0,0,0,0,0,0,0
:endlayer
layer: 4
0,0,0,0,0,0,0,0,0,0,0,0,0,0,0,0,0,0,0,0,0
0,0,0,0,0,0,0,0,0,0,0,0,0,0,0,0,0,0,0,0,0
0,0,0,0,0,0,0,0,0,0,0,0,0,0,0,0,0,0,0,0,0
0,0,0,0,0,0,0,0,0,0,0,0,0,0,0,0,0,0,0,0,0
0,0,0,0,0,0,0,0,0,0,0,0,0,0,0,0,0,0,0,0,0
0,0,0,0,0,0,0,0,0,0,0,0,0,0,0,0,0,0,0,0,0
0,0,0,0,0,0,0,0,0,0,0,0,0,0,0,0,0,0,0,0,0
0,0,0,0,0,0,0,0,0,0,0,0,0,0,0,0,0,0,0,0,0
0,0,0,0,0,0,0,0,0,31,31,31,0,0,0,0,0,0,0,0,0
0,0,0,0,0,0,0,31,3,3,13,3,3,31,0,0,0,0,0,0,0
0,0,0,0,0,0,31,3,0,0,0,0,0,3,31,0,0,0,0,0,0
0,0,0,0,0,0,2,98,0,0,0,0,0,69,2,0,0,0,0,0,0
0,0,0,0,0,0,2,2,2,2,84,0,0,33,2,0,0,0,0,0,0
0,0,0,0,0,0,68,0,93,0,2,0,0,70,68,0,0,0,0,0,0
0,0,0,0,0,32,2,0,0,0,2,0,0,71,2,32,0,0,0,0,0
0,0,0,0,0,0,68,0,0,0,2,2,2,2,2,32,0,0,0,0,0
0,0,0,0,0,32,2,0,0,0,2,0,0,0,2,32,0,0,0,0,0
0,0,0,0,0,0,68,0,0,0,2,77,0,0,68,0,0,0,0,0,0
0,0,0,0,0,32,2,0,94,0,2,0,0,0,2,32,0,0,0,0,0
0,0,0,0,0,32,2,2,2,2,13,2,2,2,2,32,0,0,0,0,0
0,0,0,0,0,32,2,66,60,0,14,0,43,39,2,32,0,0,0,0,0
0,0,0,0,0,0,68,66,60,0,15,0,43,39,68,0,0,0,0,0,0
0,0,0,0,0,32,2,66,60,0,0,0,43,39,2,32,0,0,0,0,0
0,0,0,0,0,0,68,0,0,0,0,0,43,39,68,0,0,0,0,0,0
0,0,0,0,0,32,2,7,0,0,0,78,2,31,2,32,0,0,0,0,0
0,0,0,0,0,0,68,8,0,0,47,47,2,72,2,32,0,0,0,0,0
0,0,0,0,0,32,2,2,0,0,79,79,2,73,2,32,0,0,0,0,0
0,0,0,0,0,0,2,99,0,0,85,0,2,0,2,0,0,0,0,0,0
0,0,0,0,0,0,2,100,95,0,86,80,74,0,2,0,0,0,0,0,0
0,0,0,0,0,0,2,2,13,2,13,2,13,2,2,0,0,0,0,0,0
0,0,0,0,0,0,32,2,96,0,51,81,75,2,32,0,0,0,0,0,0
0,0,0,0,0,0,0,2,97,90,87,52,76,2,0,0,0,0,0,0,0
0,0,0,0,0,0,0,32,2,91,53,82,2,32,0,0,0,0,0,0,0
0,0,0,0,0,0,0,0,2,92,53,83,2,0,0,0,0,0,0,0,0
0,0,0,0,0,0,0,0,32,2,88,2,32,0,0,0,0,0,0,0,0
0,0,0,0,0,0,0,0,0,2,89,2,0,0,0,0,0,0,0,0,0
0,0,0,0,0,0,0,0,0,32,2,32,0,0,0,0,0,0,0,0,0
0,0,0,0,0,0,0,0,0,0,2,0,0,0,0,0,0,0,0,0,0
0,0,0,0,0,0,0,0,0,0,32,0,0,0,0,0,0,0,0,0,0
0,0,0,0,0,0,0,0,0,0,0,0,0,0,0,0,0,0,0,0,0
0,0,0,0,0,0,0,0,0,0,0,0,0,0,0,0,0,0,0,0,0
0,0,0,0,0,0,0,0,0,0,0,0,0,0,0,0,0,0,0,0,0
0,0,0,0,0,0,0,0,0,0,0,0,0,0,0,0,0,0,0,0,0
0,0,0,0,0,0,0,0,0,0,0,0,0,0,0,0,0,0,0,0,0
0,0,0,0,0,0,0,0,0,0,0,0,0,0,0,0,0,0,0,0,0
0,0,0,0,0,0,0,0,0,0,0,0,0,0,0,0,0,0,0,0,0
0,0,0,0,0,0,0,0,0,0,0,0,0,0,0,0,0,0,0,0,0
0,0,0,0,0,0,0,0,0,0,0,0,0,0,0,0,0,0,0,0,0
0,0,0,0,0,0,0,0,0,0,0,0,0,0,0,0,0,0,0,0,0
0,0,0,0,0,0,0,0,0,0,0,0,0,0,0,0,0,0,0,0,0
:endlayer
layer: 5
0,0,0,0,0,0,0,0,0,0,0,0,0,0,0,0,0,0,0,0,0
0,0,0,0,0,0,0,0,0,0,0,0,0,0,0,0,0,0,0,0,0
0,0,0,0,0,0,0,0,0,0,0,0,0,0,0,0,0,0,0,0,0
0,0,0,0,0,0,0,0,0,0,0,0,0,0,0,0,0,0,0,0,0
0,0,0,0,0,0,0,0,0,0,0,0,0,0,0,0,0,0,0,0,0
0,0,0,0,0,0,0,0,0,0,0,0,0,0,0,0,0,0,0,0,0
0,0,0,0,0,0,0,0,0,0,0,0,0,0,0,0,0,0,0,0,0
0,0,0,0,0,0,0,0,0,0,0,0,0,0,0,0,0,0,0,0,0
0,0,0,0,0,0,0,58,2,2,2,2,2,40,0,0,0,0,0,0,0
0,0,0,0,0,0,31,2,126,122,13,116,111,2,31,0,0,0,0,0,0
0,0,0,0,0,31,2,129,0,0,93,0,0,104,2,31,0,0,0,0,0
0,0,0,0,0,2,2,130,94,0,0,0,0,105,2,2,0,0,0,0,0
0,0,0,0,0,2,2,2,2,2,40,0,0,33,2,2,0,0,0,0,0
0,0,0,0,0,2,2,40,108,108,2,0,0,106,2,2,0,0,0,0,0
0,0,0,0,0,2,2,40,32,58,2,0,94,107,2,2,0,0,0,0,0
0,0,0,0,0,2,2,40,32,58,2,2,2,2,2,2,0,0,0,0,0
0,0,0,0,0,2,2,40,32,58,2,108,108,108,2,2,0,0,0,0,0
0,0,0,0,0,2,2,40,32,58,2,40,32,58,2,2,0,0,0,0,0
0,0,0,0,0,2,2,40,31,58,2,40,31,31,2,2,0,0,0,0,0
0,0,0,0,0,2,2,2,2,2,13,2,2,2,2,2,0,0,0,0,0
0,0,0,0,0,2,2,108,108,108,108,108,108,108,2,2,0,0,0,0,0
0,0,0,0,0,2,40,0,0,0,0,0,0,0,58,2,0,0,0,0,0
0,0,0,0,0,2,2,77,0,0,0,0,0,78,2,2,0,0,0,0,0
0,0,0,0,0,2,40,0,0,0,0,0,0,0,58,2,0,0,0,0,0
0,0,0,0,0,2,2,7,0,0,47,47,2,2,2,2,0,0,0,0,0
0,0,0,0,0,2,40,8,0,0,79,79,2,0,101,2,0,0,0,0,0
0,0,0,0,0,2,2,2,0,0,0,0,2,77,102,2,0,0,0,0,0
0,0,0,0,0,2,2,40,0,0,0,0,2,0,0,2,0,0,0,0,0
0,0,0,0,0,2,2,40,0,94,86,0,45,0,103,2,0,0,0,0,0
0,0,0,0,0,2,2,2,13,2,13,2,13,2,2,2,0,0,0,0,0
0,0,0,0,0,32,2,131,117,0,51,0,112,109,2,32,0,0,0,0,0
0,0,0,0,0,0,2,132,54,123,0,87,113,110,2,0,0,0,0,0,0
0,0,0,0,0,0,32,2,127,117,53,117,114,2,32,0,0,0,0,0,0
0,0,0,0,0,0,0,2,128,123,113,53,115,2,0,0,0,0,0,0,0
0,0,0,0,0,0,0,32,2,124,81,118,2,32,0,0,0,0,0,0,0
0,0,0,0,0,0,0,0,2,125,120,119,2,0,0,0,0,0,0,0,0
0,0,0,0,0,0,0,0,32,2,121,2,32,0,0,0,0,0,0,0,0
0,0,0,0,0,0,0,0,0,2,2,2,0,0,0,0,0,0,0,0,0
0,0,0,0,0,0,0,0,0,32,2,32,0,0,0,0,0,0,0,0,0
0,0,0,0,0,0,0,0,0,0,2,0,0,0,0,0,0,0,0,0,0
0,0,0,0,0,0,0,0,0,0,32,0,0,0,0,0,0,0,0,0,0
0,0,0,0,0,0,0,0,0,0,0,0,0,0,0,0,0,0,0,0,0
0,0,0,0,0,0,0,0,0,0,0,0,0,0,0,0,0,0,0,0,0
0,0,0,0,0,0,0,0,0,0,0,0,0,0,0,0,0,0,0,0,0
0,0,0,0,0,0,0,0,0,0,0,0,0,0,0,0,0,0,0,0,0
0,0,0,0,0,0,0,0,0,0,0,0,0,0,0,0,0,0,0,0,0
0,0,0,0,0,0,0,0,0,0,0,0,0,0,0,0,0,0,0,0,0
0,0,0,0,0,0,0,0,0,0,0,0,0,0,0,0,0,0,0,0,0
0,0,0,0,0,0,0,0,0,0,0,0,0,0,0,0,0,0,0,0,0
0,0,0,0,0,0,0,0,0,0,0,0,0,0,0,0,0,0,0,0,0
:endlayer
layer: 6
0,0,0,0,0,0,0,0,0,0,0,0,0,0,0,0,0,0,0,0,0
0,0,0,0,0,0,0,0,0,0,0,0,0,0,0,0,0,0,0,0,0
0,0,0,0,0,0,0,0,0,0,0,0,0,0,0,0,0,0,0,0,0
0,0,0,0,0,0,0,0,0,0,0,0,0,0,0,0,0,0,0,0,0
0,0,0,0,0,0,0,0,0,0,0,0,0,0,0,0,0,0,0,0,0
0,0,0,0,0,0,0,0,0,0,0,0,0,0,0,0,0,0,0,0,0
0,0,0,0,0,0,0,0,0,0,0,0,0,0,0,0,0,0,0,0,0
0,0,0,0,0,0,0,31,32,31,32,31,32,31,0,0,0,0,0,0,0
0,0,0,0,0,0,31,135,135,135,135,135,135,135,31,0,0,0,0,0,0
0,0,0,0,0,58,25,25,141,138,13,138,134,25,25,40,0,0,0,0,0
0,0,0,0,58,133,25,138,138,134,138,141,138,134,25,133,40,0,0,0,0
0,0,0,0,32,133,146,141,47,47,47,47,139,134,25,133,32,0,0,0,0
0,0,0,0,58,133,147,25,25,25,25,141,139,134,25,133,40,0,0,0,0
0,0,0,0,32,133,25,25,25,25,25,141,139,134,25,133,32,0,0,0,0
0,0,0,0,58,133,25,25,25,25,25,141,47,47,25,133,40,0,0,0,0
0,0,0,0,32,133,25,25,25,25,25,25,25,25,25,133,32,0,0,0,0
0,0,0,0,58,133,25,25,13,25,13,25,25,25,25,133,40,0,0,0,0
0,0,0,0,0,133,25,25,144,25,142,25,140,136,25,133,0,0,0,0,0
0,0,0,0,0,133,25,25,145,25,143,25,140,137,25,133,0,0,0,0,0
0,0,0,0,0,133,25,25,25,25,13,25,25,25,25,133,0,0,0,0,0
0,0,0,0,0,133,25,25,25,25,25,25,25,25,25,133,0,0,0,0,0
0,0,0,0,58,133,25,25,25,25,25,25,25,25,25,133,40,0,0,0,0
0,0,0,0,32,133,25,25,25,25,25,25,25,25,25,133,32,0,0,0,0
0,0,0,0,32,133,25,25,25,25,25,25,25,25,25,133,32,0,0,0,0
0,0,0,0,32,133,25,25,25,25,79,79,2,25,25,133,32,0,0,0,0
0,0,0,0,32,133,25,25,25,141,0,0,2,138,134,133,32,0,0,0,0
0,0,0,0,58,133,25,25,25,141,0,0,2,139,134,133,40,0,0,0,0
0,0,0,0,0,133,25,25,25,141,0,0,2,139,134,133,0,0,0,0,0
0,0,0,0,0,133,25,25,25,141,86,0,2,139,134,133,0,0,0,0,0
0,0,0,0,0,133,2,2,13,135,13,135,13,2,2,133,0,0,0,0,0
0,0,0,0,0,2,2,40,32,32,51,32,32,58,2,2,0,0,0,0,0
0,0,0,0,0,108,2,40,32,32,32,32,32,58,2,108,0,0,0,0,0
0,0,0,0,0,0,2,2,40,32,32,32,58,2,2,0,0,0,0,0,0
0,0,0,0,0,0,108,2,40,32,32,32,58,2,108,0,0,0,0,0,0
0,0,0,0,0,0,0,2,2,40,32,58,2,2,0,0,0,0,0,0,0
0,0,0,0,0,0,0,108,2,40,32,58,2,108,0,0,0,0,0,0,0
0,0,0,0,0,0,0,0,2,2,31,2,2,0,0,0,0,0,0,0,0
0,0,0,0,0,0,0,0,108,2,2,2,108,0,0,0,0,0,0,0,0
0,0,0,0,0,0,0,0,0,2,2,2,0,0,0,0,0,0,0,0,0
0,0,0,0,0,0,0,0,0,108,2,108,0,0,0,0,0,0,0,0,0
0,0,0,0,0,0,0,0,0,0,2,0,0,0,0,0,0,0,0,0,0
0,0,0,0,0,0,0,0,0,0,108,0,0,0,0,0,0,0,0,0,0
0,0,0,0,0,0,0,0,0,0,0,0,0,0,0,0,0,0,0,0,0
0,0,0,0,0,0,0,0,0,0,0,0,0,0,0,0,0,0,0,0,0
0,0,0,0,0,0,0,0,0,0,0,0,0,0,0,0,0,0,0,0,0
0,0,0,0,0,0,0,0,0,0,0,0,0,0,0,0,0,0,0,0,0
0,0,0,0,0,0,0,0,0,0,0,0,0,0,0,0,0,0,0,0,0
0,0,0,0,0,0,0,0,0,0,0,0,0,0,0,0,0,0,0,0,0
0,0,0,0,0,0,0,0,0,0,0,0,0,0,0,0,0,0,0,0,0
0,0,0,0,0,0,0,0,0,0,0,0,0,0,0,0,0,0,0,0,0
:endlayer
layer: 7
0,0,0,0,0,0,0,0,0,0,0,0,0,0,0,0,0,0,0,0,0
0,0,0,0,0,0,0,0,0,0,0,0,0,0,0,0,0,0,0,0,0
0,0,0,0,0,0,0,0,0,0,0,0,0,0,0,0,0,0,0,0,0
0,0,0,0,0,0,0,0,0,0,0,0,0,0,0,0,0,0,0,0,0
0,0,0,0,0,0,0,0,0,0,0,0,0,0,0,0,0,0,0,0,0
0,0,0,0,0,0,0,0,0,0,0,0,0,0,0,0,0,0,0,0,0
0,0,0,0,0,0,0,0,0,0,0,0,0,0,0,0,0,0,0,0,0
0,0,0,0,0,0,0,2,154,2,154,2,154,2,0,0,0,0,0,0,0
0,0,0,0,0,0,13,185,183,13,171,0,0,0,13,0,0,0,0,0,0
0,0,0,0,0,2,192,0,0,181,13,167,0,0,155,2,0,0,0,0,0
0,0,0,0,2,193,13,2,9,2,172,0,0,0,156,150,2,0,0,0,0
0,0,0,0,41,0,173,186,0,182,172,168,164,0,156,150,30,0,0,0,0
0,0,0,0,2,0,174,0,184,0,172,2,2,9,2,2,2,0,0,0,0
0,0,0,0,41,0,157,157,157,0,172,0,0,0,0,0,30,0,0,0,0
0,0,0,0,2,194,0,155,155,0,74,0,165,157,157,151,2,0,0,0,0
0,0,0,0,41,0,0,0,0,0,172,0,166,157,157,152,30,0,0,0,0
0,0,0,0,2,13,9,187,13,2,13,2,13,159,158,13,2,0,0,0,0
0,0,0,0,0,2,0,0,173,0,173,0,108,138,25,2,0,0,0,0,0
0,0,0,0,0,2,0,0,174,0,174,0,31,47,25,2,0,0,0,0,0
0,0,0,0,0,133,77,0,0,0,13,78,133,79,79,133,0,0,0,0,0
0,0,0,0,0,3,0,188,0,0,175,0,3,160,0,3,0,0,0,0,0
0,0,0,0,0,153,0,0,0,0,176,0,0,0,0,153,0,0,0,0,0
0,0,0,0,0,153,0,189,0,0,0,0,0,161,0,153,0,0,0,0,0
0,0,0,0,148,153,0,0,0,0,177,0,0,0,0,153,148,0,0,0,0
0,0,0,0,149,153,0,190,0,0,0,0,153,162,0,153,149,0,0,0,0
0,0,0,0,149,153,0,0,0,0,0,0,153,0,0,153,149,0,0,0,0
0,0,0,0,149,153,0,191,0,0,0,0,153,163,0,153,149,0,0,0,0
0,0,0,0,0,154,0,0,154,0,0,0,154,0,0,154,0,0,0,0,0
0,0,0,0,0,2,24,24,2,0,86,0,2,24,24,2,0,0,0,0,0
0,0,0,0,0,2,25,25,13,9,13,2,13,25,25,2,0,0,0,0,0
0,0,0,0,0,133,25,25,2,0,51,169,2,25,25,133,0,0,0,0,0
0,0,0,0,0,133,133,25,2,0,178,169,2,25,133,133,0,0,0,0,0
0,0,0,0,0,108,133,25,2,0,179,170,2,25,133,108,0,0,0,0,0
0,0,0,0,0,0,133,133,25,30,180,41,25,133,133,0,0,0,0,0,0
0,0,0,0,0,0,108,133,25,2,2,2,25,133,108,0,0,0,0,0,0
0,0,0,0,0,0,0,133,133,25,25,25,133,133,0,0,0,0,0,0,0
0,0,0,0,0,0,0,108,133,25,25,25,133,108,0,0,0,0,0,0,0
0,0,0,0,0,0,0,0,133,133,25,133,133,0,0,0,0,0,0,0,0
0,0,0,0,0,0,0,0,108,133,25,133,108,0,0,0,0,0,0,0,0
0,0,0,0,0,0,0,0,0,133,13,133,0,0,0,0,0,0,0,0,0
0,0,0,0,0,0,0,0,0,108,133,108,0,0,0,0,0,0,0,0,0
0,0,0,0,0,0,0,0,0,0,133,0,0,0,0,0,0,0,0,0,0
0,0,0,0,0,0,0,0,0,0,108,0,0,0,0,0,0,0,0,0,0
0,0,0,0,0,0,0,0,0,0,0,0,0,0,0,0,0,0,0,0,0
0,0,0,0,0,0,0,0,0,0,0,0,0,0,0,0,0,0,0,0,0
0,0,0,0,0,0,0,0,0,0,0,0,0,0,0,0,0,0,0,0,0
0,0,0,0,0,0,0,0,0,0,0,0,0,0,0,0,0,0,0,0,0
0,0,0,0,0,0,0,0,0,0,0,0,0,0,0,0,0,0,0,0,0
0,0,0,0,0,0,0,0,0,0,0,0,0,0,0,0,0,0,0,0,0
0,0,0,0,0,0,0,0,0,0,0,0,0,0,0,0,0,0,0,0,0
:endlayer
layer: 8
0,0,0,0,0,0,0,0,0,0,0,0,0,0,0,0,0,0,0,0,0
0,0,0,0,0,0,0,0,0,0,0,0,0,0,0,0,0,0,0,0,0
0,0,0,0,0,0,0,0,0,0,0,0,0,0,0,0,0,0,0,0,0
0,0,0,0,0,0,0,0,0,0,0,0,0,0,0,0,0,0,0,0,0
0,0,0,0,0,0,0,0,0,0,0,0,0,0,0,0,0,0,0,0,0
0,0,0,0,0,0,0,0,0,0,0,0,0,0,0,0,0,0,0,0,0
0,0,0,0,0,0,0,0,0,0,0,0,0,0,0,0,0,0,0,0,0
0,0,0,0,0,0,0,2,68,2,68,2,68,2,0,0,0,0,0,0,0
0,0,0,0,0,0,13,0,0,13,0,0,0,0,13,0,0,0,0,0,0
0,0,0,0,0,2,0,0,0,0,13,0,0,0,0,2,0,0,0,0,0
0,0,0,0,2,0,13,2,45,2,172,0,0,0,0,0,2,0,0,0,0
0,0,0,0,68,0,0,208,0,203,172,203,0,0,0,0,68,0,0,0,0
0,0,0,0,2,0,0,0,0,0,172,2,2,45,2,2,2,0,0,0,0
0,0,0,0,68,0,0,0,0,0,172,0,0,0,0,0,68,0,0,0,0
0,0,0,0,2,0,0,0,0,0,205,0,201,0,0,195,2,0,0,0,0
0,0,0,0,68,0,0,0,0,0,172,0,202,0,0,196,68,0,0,0,0
0,0,0,0,2,13,45,205,13,68,13,68,13,199,198,13,2,0,0,0,0
0,0,0,0,0,2,0,0,0,0,0,0,2,25,25,2,0,0,0,0,0
0,0,0,0,0,133,0,0,0,0,86,0,133,79,79,133,0,0,0,0,0
0,0,0,0,0,3,0,0,0,0,13,0,3,0,0,3,0,0,0,0,0
0,0,0,0,0,0,0,0,0,0,0,0,0,0,0,0,0,0,0,0,0
0,0,0,0,0,0,0,0,0,0,0,0,0,0,0,0,0,0,0,0,0
0,0,0,0,0,210,0,0,0,0,0,0,0,0,0,197,0,0,0,0,0
0,0,0,0,0,0,0,0,0,0,0,0,0,0,0,0,0,0,0,0,0
0,0,0,0,0,0,0,0,0,0,0,0,0,0,0,0,0,0,0,0,0
0,0,0,0,149,0,0,0,0,0,0,0,0,0,0,0,149,0,0,0,0
0,0,0,0,149,0,0,0,0,0,0,0,0,0,0,0,149,0,0,0,0
0,0,0,0,0,0,0,0,0,0,0,0,0,0,0,0,0,0,0,0,0
0,0,0,0,0,154,0,0,154,0,86,0,154,0,0,154,0,0,0,0,0
0,0,0,0,0,33,0,78,13,45,13,2,13,77,0,33,0,0,0,0,0
0,0,0,0,0,33,0,0,2,0,51,169,2,0,0,33,0,0,0,0,0
0,0,0,0,0,33,0,209,2,0,0,169,2,200,0,33,0,0,0,0,0
0,0,0,0,0,3,33,0,2,77,0,78,2,0,33,3,0,0,0,0,0
0,0,0,0,0,0,33,0,0,40,31,58,0,0,33,0,0,0,0,0,0
0,0,0,0,0,0,3,33,0,2,79,2,0,33,3,0,0,0,0,0,0
0,0,0,0,0,0,0,33,0,0,0,0,0,33,0,0,0,0,0,0,0
0,0,0,0,0,0,0,3,154,0,206,0,154,3,0,0,0,0,0,0,0
0,0,0,0,0,0,0,0,133,207,0,204,133,0,0,0,0,0,0,0,0
0,0,0,0,0,0,0,0,3,33,86,33,3,0,0,0,0,0,0,0,0
0,0,0,0,0,0,0,0,0,33,13,33,0,0,0,0,0,0,0,0,0
0,0,0,0,0,0,0,0,0,3,133,3,0,0,0,0,0,0,0,0,0
0,0,0,0,0,0,0,0,0,153,133,153,0,0,0,0,0,0,0,0,0
0,0,0,0,0,0,0,0,0,0,133,0,0,0,0,0,0,0,0,0,0
0,0,0,0,0,0,0,0,0,0,133,0,0,0,0,0,0,0,0,0,0
0,0,0,0,0,0,0,0,0,0,108,0,0,0,0,0,0,0,0,0,0
0,0,0,0,0,0,0,0,0,0,0,0,0,0,0,0,0,0,0,0,0
0,0,0,0,0,0,0,0,0,0,0,0,0,0,0,0,0,0,0,0,0
0,0,0,0,0,0,0,0,0,0,0,0,0,0,0,0,0,0,0,0,0
0,0,0,0,0,0,0,0,0,0,0,0,0,0,0,0,0,0,0,0,0
0,0,0,0,0,0,0,0,0,0,0,0,0,0,0,0,0,0,0,0,0
:endlayer
layer: 9
0,0,0,0,0,0,0,0,0,0,0,0,0,0,0,0,0,0,0,0,0
0,0,0,0,0,0,0,0,0,0,0,0,0,0,0,0,0,0,0,0,0
0,0,0,0,0,0,0,0,0,0,0,0,0,0,0,0,0,0,0,0,0
0,0,0,0,0,0,0,0,0,0,0,0,0,0,0,0,0,0,0,0,0
0,0,0,0,0,0,0,0,0,0,0,0,0,0,0,0,0,0,0,0,0
0,0,0,0,0,0,0,0,0,0,0,0,0,0,0,0,0,0,0,0,0
0,0,0,0,0,0,0,0,0,94,0,94,0,0,0,0,0,0,0,0,0
0,0,0,0,0,0,0,2,68,2,68,2,68,2,0,0,0,0,0,0,0
0,0,0,0,31,31,13,108,0,13,0,93,0,58,13,31,40,0,0,0,0
0,0,0,0,58,2,40,0,0,78,13,0,0,0,108,2,40,0,0,0,0
0,0,0,0,2,108,13,2,2,2,172,0,0,0,0,108,2,0,0,0,0
0,0,0,0,68,0,93,0,0,203,172,203,0,94,0,0,68,0,0,0,0
0,0,0,0,2,77,0,0,0,0,172,2,2,2,2,2,2,0,0,0,0
0,0,0,0,68,0,0,0,0,0,172,0,0,0,0,0,68,0,0,0,0
0,0,0,0,2,77,0,0,0,0,172,0,0,0,0,0,2,0,0,0,0
0,0,0,0,68,31,0,0,94,0,172,0,94,0,0,94,68,0,0,0,0
0,0,0,0,2,13,2,2,13,68,13,68,13,47,47,13,2,0,0,0,0
0,0,0,0,0,133,0,0,93,0,93,0,133,79,79,133,0,0,0,0,0
0,0,0,0,0,3,0,0,0,0,86,0,3,0,0,3,0,0,0,0,0
0,0,0,0,0,0,0,0,0,78,13,77,0,0,0,0,0,0,0,0,0
0,0,0,0,0,0,0,0,0,0,93,0,0,0,0,0,0,0,0,0,0
0,0,0,0,0,0,0,0,0,0,0,0,0,0,0,0,0,0,0,0,0
0,0,0,0,0,0,0,0,0,0,0,0,0,0,0,0,0,0,0,0,0
0,0,0,0,0,0,0,0,0,0,0,0,0,0,0,0,0,0,0,0,0
0,0,0,0,0,0,0,0,0,0,0,0,0,0,0,0,0,0,0,0,0
0,0,0,0,0,0,0,0,0,0,0,0,0,0,0,0,0,0,0,0,0
0,0,0,149,149,0,0,0,0,0,0,0,0,0,0,0,149,149,0,0,0
0,0,0,149,0,0,0,0,0,0,0,0,0,0,0,0,0,149,0,0,0
0,0,0,0,0,0,0,0,213,0,86,0,212,0,0,0,0,0,0,0,0
0,0,0,0,0,0,0,0,41,135,13,135,30,0,0,0,0,0,0,0,0
0,0,0,0,0,0,0,0,41,139,139,139,30,0,0,0,0,0,0,0,0
0,0,0,0,0,0,0,0,41,139,139,139,30,0,0,0,0,0,0,0,0
0,0,0,0,0,214,0,0,41,47,47,47,30,0,0,211,0,0,0,0,0
0,0,0,0,0,0,0,0,78,2,79,2,77,0,0,0,0,0,0,0,0
0,0,0,0,0,0,0,0,0,3,0,3,0,0,0,0,0,0,0,0,0
0,0,0,0,0,0,0,0,0,0,0,0,0,0,0,0,0,0,0,0,0
0,0,0,0,0,0,0,0,149,0,0,0,149,0,0,0,0,0,0,0,0
0,0,0,0,0,0,0,0,149,0,0,0,149,0,0,0,0,0,0,0,0
0,0,0,0,0,0,0,0,0,0,86,0,0,0,0,0,0,0,0,0,0
0,0,0,0,0,0,0,0,0,0,13,0,0,0,0,0,0,0,0,0,0
0,0,0,0,0,0,0,0,0,0,153,0,0,0,0,0,0,0,0,0,0
0,0,0,0,0,0,0,0,0,0,153,0,0,0,0,0,0,0,0,0,0
0,0,0,0,0,0,0,0,0,0,154,0,0,0,0,0,0,0,0,0,0
0,0,0,0,0,0,0,0,0,32,133,32,0,0,0,0,0,0,0,0,0
0,0,0,0,0,0,0,0,0,153,133,153,0,0,0,0,0,0,0,0,0
0,0,0,0,0,0,0,0,0,32,133,32,0,0,0,0,0,0,0,0,0
0,0,0,0,0,0,0,0,0,0,108,0,0,0,0,0,0,0,0,0,0
0,0,0,0,0,0,0,0,0,0,32,0,0,0,0,0,0,0,0,0,0
0,0,0,0,0,0,0,0,0,0,0,0,0,0,0,0,0,0,0,0,0
0,0,0,0,0,0,0,0,0,0,0,0,0,0,0,0,0,0,0,0,0
:endlayer
layer: 10
0,0,0,0,0,0,0,0,0,0,0,0,0,0,0,0,0,0,0,0,0
0,0,0,0,0,0,0,0,0,0,0,0,0,0,0,0,0,0,0,0,0
0,0,0,0,0,0,0,0,0,0,0,0,0,0,0,0,0,0,0,0,0
0,0,0,0,0,0,0,0,0,0,0,0,0,0,0,0,0,0,0,0,0
0,0,0,0,0,0,0,0,0,0,0,0,0,0,0,0,0,0,0,0,0
0,0,0,0,0,0,0,0,0,0,0,0,0,0,0,0,0,0,0,0,0
0,0,0,0,0,0,0,0,32,31,32,31,32,0,0,0,0,0,0,0,0
0,0,0,0,0,0,0,41,135,135,135,135,135,30,0,0,0,0,0,0,0
0,0,0,0,149,148,154,13,25,25,25,25,25,13,154,148,149,0,0,0,0
0,0,0,0,149,154,2,25,25,25,13,25,25,25,2,154,149,0,0,0,0
0,0,0,0,154,13,25,25,25,25,25,25,25,25,25,13,154,0,0,0,0
0,0,0,0,133,25,25,25,25,25,25,25,25,25,25,25,133,0,0,0,0
0,0,0,58,133,25,25,25,25,25,25,25,25,25,25,25,133,40,0,0,0
0,0,0,32,133,25,25,25,25,25,25,25,25,25,25,25,133,32,0,0,0
0,0,0,58,133,25,25,25,25,25,25,25,25,25,25,25,133,40,0,0,0
0,0,0,0,133,25,25,25,25,25,25,25,25,25,25,25,133,0,0,0,0
0,0,0,0,3,133,135,135,135,135,135,135,133,79,79,133,3,0,0,0,0
0,0,0,0,0,3,0,0,0,0,0,0,3,0,0,3,0,0,0,0,0
0,0,0,0,0,0,0,0,0,0,86,0,0,0,0,0,0,0,0,0,0
0,0,0,0,0,0,0,0,0,0,13,0,0,0,0,0,0,0,0,0,0
0,0,0,0,0,0,0,0,0,0,0,0,0,0,0,0,0,0,0,0,0
0,0,0,0,0,0,0,0,0,0,0,0,0,0,0,0,0,0,0,0,0
0,0,0,0,0,0,0,0,0,0,0,0,0,0,0,0,0,0,0,0,0
0,0,0,0,0,0,0,0,0,0,0,0,0,0,0,0,0,0,0,0,0
0,0,0,0,0,0,0,0,0,0,0,0,0,0,0,0,0,0,0,0,0
0,0,0,0,0,0,0,0,0,0,0,0,0,0,0,0,0,0,0,0,0
0,0,0,0,0,0,0,0,0,0,0,0,0,0,0,0,0,0,0,0,0
0,0,0,149,0,0,0,0,0,0,0,0,0,0,0,0,0,149,0,0,0
0,0,149,149,0,0,0,0,0,0,86,0,0,0,0,0,0,149,149,0,0
0,0,0,0,0,0,0,0,33,33,13,33,33,0,0,0,0,0,0,0,0
0,0,0,0,0,0,0,0,33,0,215,0,33,0,0,0,0,0,0,0,0
0,0,0,0,0,0,0,0,33,0,216,0,33,0,0,0,0,0,0,0,0
0,0,0,0,0,0,0,0,33,33,0,33,33,0,0,0,0,0,0,0,0
0,0,0,0,0,0,0,0,0,33,0,33,0,0,0,0,0,0,0,0,0
0,0,0,0,0,0,0,0,0,0,0,0,0,0,0,0,0,0,0,0,0
0,0,0,0,0,0,0,0,0,0,0,0,0,0,0,0,0,0,0,0,0
0,0,0,0,0,0,0,0,149,0,0,0,149,0,0,0,0,0,0,0,0
0,0,0,0,0,0,0,149,149,0,0,0,149,149,0,0,0,0,0,0,0
0,0,0,0,0,0,0,149,0,0,86,0,0,149,0,0,0,0,0,0,0
0,0,0,0,0,0,0,0,0,0,13,0,0,0,0,0,0,0,0,0,0
0,0,0,0,0,0,0,0,0,0,0,0,0,0,0,0,0,0,0,0,0
0,0,0,0,0,0,0,0,0,153,0,153,0,0,0,0,0,0,0,0,0
0,0,0,0,0,0,0,0,0,153,217,153,0,0,0,0,0,0,0,0,0
0,0,0,0,0,0,0,0,0,0,148,0,0,0,0,0,0,0,0,0,0
0,0,0,0,0,0,0,0,0,153,153,153,0,0,0,0,0,0,0,0,0
0,0,0,0,0,0,0,0,0,0,2,0,0,0,0,0,0,0,0,0,0
0,0,0,0,0,0,0,0,0,0,135,0,0,0,0,0,0,0,0,0,0
0,0,0,0,0,0,0,0,0,0,3,0,0,0,0,0,0,0,0,0,0
0,0,0,0,0,0,0,0,0,0,153,0,0,0,0,0,0,0,0,0,0
0,0,0,0,0,0,0,0,0,0,153,0,0,0,0,0,0,0,0,0,0
:endlayer
layer: 11
0,0,0,0,0,0,0,0,0,0,0,0,0,0,0,0,0,0,0,0,0
0,0,0,0,0,0,0,0,0,0,0,0,0,0,0,0,0,0,0,0,0
0,0,0,0,0,0,0,0,0,0,0,0,0,0,0,0,0,0,0,0,0
0,0,0,0,0,0,0,0,0,0,0,0,0,0,0,0,0,0,0,0,0
0,0,0,0,0,0,0,0,0,0,0,0,0,0,0,0,0,0,0,0,0
0,0,0,0,0,0,0,0,0,0,0,0,0,0,0,0,0,0,0,0,0
0,0,0,0,0,0,0,0,0,0,223,0,0,0,0,0,0,0,0,0,0
0,0,0,0,0,0,0,33,33,33,13,33,33,33,0,0,0,0,0,0,0
0,0,0,0,149,0,33,13,0,0,0,0,0,13,33,0,149,0,0,0,0
0,0,0,0,149,0,33,230,228,153,13,153,221,220,33,0,149,0,0,0,0
0,0,0,0,0,13,33,0,0,2,2,2,0,0,33,13,0,0,0,0,0
0,0,0,0,13,0,0,0,0,41,224,30,0,0,0,0,13,0,0,0,0
0,0,0,149,33,0,231,0,0,41,225,30,0,0,218,0,33,149,0,0,0
0,0,0,149,33,0,0,0,229,2,2,2,222,0,0,0,33,149,0,0,0
0,0,0,149,33,0,232,0,0,153,2,153,0,0,219,0,33,149,0,0,0
0,0,0,0,13,94,0,0,94,0,226,0,94,0,0,94,13,0,0,0,0
0,0,0,0,0,13,33,33,13,33,33,33,13,0,0,13,0,0,0,0,0
0,0,0,0,0,0,0,0,0,0,0,0,0,0,0,0,0,0,0,0,0
0,0,0,0,0,0,0,0,0,0,86,0,0,0,0,0,0,0,0,0,0
0,0,0,0,0,0,0,0,0,0,13,0,0,0,0,0,0,0,0,0,0
0,0,0,0,0,0,0,0,0,0,0,0,0,0,0,0,0,0,0,0,0
0,0,0,0,0,0,0,0,0,0,0,0,0,0,0,0,0,0,0,0,0
0,0,0,0,0,0,0,0,0,0,0,0,0,0,0,0,0,0,0,0,0
0,0,0,0,0,0,0,0,0,0,0,0,0,0,0,0,0,0,0,0,0
0,0,0,0,0,0,0,0,0,0,0,0,0,0,0,0,0,0,0,0,0
0,0,0,0,0,0,0,0,0,0,0,0,0,0,0,0,0,0,0,0,0
0,0,0,0,0,0,0,0,0,0,0,0,0,0,0,0,0,0,0,0,0
0,0,0,0,0,0,0,0,0,0,0,0,0,0,0,0,0,0,0,0,0
0,0,149,0,0,0,0,0,0,0,86,0,0,0,0,0,0,0,149,0,0
0,0,149,0,0,0,0,0,0,0,13,0,0,0,0,0,0,0,149,0,0
0,0,0,0,0,0,0,0,148,0,0,0,148,0,0,0,0,0,0,0,0
0,0,0,0,0,0,0,0,0,0,0,0,0,0,0,0,0,0,0,0,0
0,0,0,0,0,0,0,0,0,0,0,0,0,0,0,0,0,0,0,0,0
0,0,0,0,0,0,0,0,0,0,0,0,0,0,0,0,0,0,0,0,0
0,0,0,0,0,0,0,0,0,0,0,0,0,0,0,0,0,0,0,0,0
0,0,0,0,0,0,0,0,0,0,0,0,0,0,0,0,0,0,0,0,0
0,0,0,0,0,0,0,0,0,0,0,0,0,0,0,0,0,0,0,0,0
0,0,0,0,0,0,0,149,0,0,0,0,0,149,0,0,0,0,0,0,0
0,0,0,0,0,0,0,149,0,0,86,0,0,149,0,0,0,0,0,0,0
0,0,0,0,0,0,0,0,0,78,13,77,0,0,0,0,0,0,0,0,0
0,0,0,0,0,0,0,0,0,0,93,0,0,0,0,0,0,0,0,0,0
0,0,0,0,0,0,0,0,0,0,0,0,0,0,0,0,0,0,0,0,0
0,0,0,0,0,0,0,0,0,0,0,0,0,0,0,0,0,0,0,0,0
0,0,0,0,0,0,0,0,0,0,0,0,0,0,0,0,0,0,0,0,0
0,0,0,0,0,0,0,0,0,0,227,0,0,0,0,0,0,0,0,0,0
0,0,0,0,0,0,0,0,0,0,0,0,0,0,0,0,0,0,0,0,0
0,0,0,0,0,0,0,0,0,0,153,0,0,0,0,0,0,0,0,0,0
0,0,0,0,0,0,0,0,0,0,0,0,0,0,0,0,0,0,0,0,0
0,0,0,0,0,0,0,0,0,0,0,0,0,0,0,0,0,0,0,0,0
0,0,0,0,0,0,0,0,0,0,0,0,0,0,0,0,0,0,0,0,0
:endlayer
layer: 12
0,0,0,0,0,0,0,0,0,0,0,0,0,0,0,0,0,0,0,0,0
0,0,0,0,0,0,0,0,0,0,0,0,0,0,0,0,0,0,0,0,0
0,0,0,0,0,0,0,0,0,0,0,0,0,0,0,0,0,0,0,0,0
0,0,0,0,0,0,0,0,0,0,0,0,0,0,0,0,0,0,0,0,0
0,0,0,0,0,0,0,0,0,0,0,0,0,0,0,0,0,0,0,0,0
0,0,0,0,0,0,0,0,0,0,0,0,0,0,0,0,0,0,0,0,0
0,0,0,0,0,0,0,0,0,0,0,0,0,0,0,0,0,0,0,0,0
0,0,0,0,0,0,0,0,0,0,153,0,0,0,0,0,0,0,0,0,0
0,0,0,0,149,0,0,153,0,0,0,0,0,153,0,0,149,0,0,0,0
0,0,0,0,149,0,0,0,0,0,13,0,0,0,0,0,149,0,0,0,0
0,0,0,0,0,153,0,0,0,236,108,233,0,0,0,153,0,0,0,0,0
0,0,0,0,153,0,0,0,0,0,234,0,0,0,0,0,153,0,0,0,0
0,0,0,0,0,0,0,0,0,0,234,0,0,0,0,0,0,0,0,0,0
0,0,0,0,0,0,0,0,0,0,235,0,0,0,0,0,0,0,0,0,0
0,0,0,149,0,0,0,0,0,0,3,0,0,0,0,0,0,149,0,0,0
0,0,0,149,153,0,0,0,0,0,0,0,0,0,0,0,153,149,0,0,0
0,0,0,149,0,153,0,0,153,0,0,0,153,0,0,153,0,149,0,0,0
0,0,149,149,0,0,0,0,0,0,0,0,0,0,0,0,0,149,149,0,0
0,0,149,0,0,0,0,0,0,0,86,0,0,0,0,0,0,0,149,0,0
0,149,149,0,0,0,0,0,0,0,13,0,0,0,0,0,0,0,149,149,0
0,120,149,0,0,0,0,0,0,0,0,0,0,0,0,0,0,0,149,120,0
0,0,120,120,53,53,120,120,120,120,120,120,120,120,120,53,53,120,120,0,0
0,0,0,0,0,0,0,0,0,0,0,0,0,0,0,0,0,0,0,0,0
0,0,0,0,0,0,0,0,0,0,0,0,0,0,0,0,0,0,0,0,0
0,0,0,0,0,0,0,0,0,0,0,0,0,0,0,0,0,0,0,0,0
0,0,0,0,0,0,0,0,0,0,0,0,0,0,0,0,0,0,0,0,0
0,0,0,0,0,0,0,0,0,0,0,0,0,0,0,0,0,0,0,0,0
0,0,0,0,0,0,0,0,0,0,0,0,0,0,0,0,0,0,0,0,0
0,0,0,0,0,0,0,0,0,0,86,0,0,0,0,0,0,0,0,0,0
0,149,149,0,0,0,0,0,0,78,13,77,0,0,0,0,0,0,149,149,0
0,120,149,0,0,0,0,0,0,0,0,0,0,0,0,0,0,0,149,120,0
0,0,120,120,53,53,120,120,120,120,120,120,120,120,120,53,53,120,120,0,0
0,0,0,0,0,0,0,0,0,0,0,0,0,0,0,0,0,0,0,0,0
0,0,0,0,0,0,0,0,0,0,0,0,0,0,0,0,0,0,0,0,0
0,0,0,0,0,0,0,0,0,0,0,0,0,0,0,0,0,0,0,0,0
0,0,0,0,0,0,0,0,0,0,0,0,0,0,0,0,0,0,0,0,0
0,0,0,0,0,0,0,0,0,0,0,0,0,0,0,0,0,0,0,0,0
0,0,0,0,0,0,0,149,0,0,0,0,0,149,0,0,0,0,0,0,0
0,0,0,0,0,0,149,149,0,0,86,0,0,149,149,0,0,0,0,0,0
0,0,0,0,0,0,149,0,0,0,13,0,0,0,149,0,0,0,0,0,0
0,0,0,0,0,0,0,0,0,0,0,0,0,0,0,0,0,0,0,0,0
0,0,0,0,0,0,0,0,0,0,0,0,0,0,0,0,0,0,0,0,0
0,0,0,0,0,0,0,0,0,0,0,0,0,0,0,0,0,0,0,0,0
0,0,0,0,0,0,0,0,0,0,0,0,0,0,0,0,0,0,0,0,0
0,0,0,0,0,0,0,0,0,0,0,0,0,0,0,0,0,0,0,0,0
0,0,0,0,0,0,0,0,0,0,0,0,0,0,0,0,0,0,0,0,0
0,0,0,0,0,0,0,0,0,0,0,0,0,0,0,0,0,0,0,0,0
0,0,0,0,0,0,0,0,0,0,0,0,0,0,0,0,0,0,0,0,0
0,0,0,0,0,0,0,0,0,0,0,0,0,0,0,0,0,0,0,0,0
0,0,0,0,0,0,0,0,0,0,0,0,0,0,0,0,0,0,0,0,0
:endlayer
layer: 13
0,0,0,0,0,0,0,0,0,0,0,0,0,0,0,0,0,0,0,0,0
0,0,0,0,0,0,0,0,0,0,0,0,0,0,0,0,0,0,0,0,0
0,0,0,0,0,0,0,0,0,0,0,0,0,0,0,0,0,0,0,0,0
0,0,0,0,0,0,0,0,0,0,0,0,0,0,0,0,0,0,0,0,0
0,0,0,0,0,0,0,0,0,0,0,0,0,0,0,0,0,0,0,0,0
0,0,0,0,0,0,0,0,0,0,0,0,0,0,0,0,0,0,0,0,0
0,0,0,0,0,0,0,0,0,0,0,0,0,0,0,0,0,0,0,0,0
0,0,0,0,0,0,0,0,0,0,0,0,0,0,0,0,0,0,0,0,0
0,0,0,0,149,0,0,0,0,0,0,0,0,0,0,0,149,0,0,0,0
0,0,0,0,149,0,0,0,0,0,13,0,0,0,0,0,149,0,0,0,0
0,0,0,0,0,0,0,0,0,0,237,0,0,0,0,0,0,0,0,0,0
0,0,0,0,0,0,0,0,0,0,0,0,0,0,0,0,0,0,0,0,0
0,0,0,0,0,0,0,0,0,0,238,0,0,0,0,0,0,0,0,0,0
0,0,0,0,0,0,0,0,0,0,0,0,0,0,0,0,0,0,0,0,0
0,0,0,0,0,0,0,0,0,0,0,0,0,0,0,0,0,0,0,0,0
0,0,0,149,0,0,0,0,0,0,0,0,0,0,0,0,0,149,0,0,0
0,0,0,149,0,0,0,0,0,0,0,0,0,0,0,0,0,149,0,0,0
0,0,0,0,0,0,0,0,0,0,0,0,0,0,0,0,0,0,0,0,0
0,0,0,0,0,0,0,0,0,0,86,0,0,0,0,0,0,0,0,0,0
0,0,0,0,0,0,0,0,0,0,13,0,0,0,0,0,0,0,0,0,0
0,0,0,0,0,0,0,0,0,0,0,0,0,0,0,0,0,0,0,0,0
0,120,53,53,120,0,0,0,0,0,0,0,0,0,0,0,120,53,53,120,0
0,0,0,0,0,120,53,53,120,120,120,120,120,53,53,120,0,0,0,0,0
0,0,0,0,0,0,0,0,0,0,0,0,0,0,0,0,0,0,0,0,0
0,0,0,0,0,0,0,0,0,0,0,0,0,0,0,0,0,0,0,0,0
0,0,0,0,0,0,0,0,0,0,0,0,0,0,0,0,0,0,0,0,0
0,0,0,0,0,0,0,0,0,0,0,0,0,0,0,0,0,0,0,0,0
0,0,0,0,0,0,0,0,0,0,0,0,0,0,0,0,0,0,0,0,0
0,0,0,0,0,0,0,0,0,0,86,0,0,0,0,0,0,0,0,0,0
0,0,0,0,0,0,0,0,0,0,13,0,0,0,0,0,0,0,0,0,0
0,0,0,0,0,0,0,0,0,0,0,0,0,0,0,0,0,0,0,0,0
0,120,53,53,120,0,0,0,0,0,0,0,0,0,0,0,120,53,53,120,0
0,0,0,0,0,120,53,53,120,120,120,120,120,53,53,120,0,0,0,0,0
0,0,0,0,0,0,0,0,0,0,0,0,0,0,0,0,0,0,0,0,0
0,0,0,0,0,0,0,0,0,0,0,0,0,0,0,0,0,0,0,0,0
0,0,0,0,0,0,0,0,0,0,0,0,0,0,0,0,0,0,0,0,0
0,0,0,0,0,0,0,0,0,0,0,0,0,0,0,0,0,0,0,0,0
0,0,0,0,0,0,0,0,0,0,0,0,0,0,0,0,0,0,0,0,0
0,0,0,0,0,0,149,0,0,0,86,0,0,0,149,0,0,0,0,0,0
0,0,0,0,0,0,149,0,0,0,13,0,0,0,149,0,0,0,0,0,0
0,0,0,0,0,0,0,0,0,0,0,0,0,0,0,0,0,0,0,0,0
0,0,0,0,0,0,0,0,0,0,0,0,0,0,0,0,0,0,0,0,0
0,0,0,0,0,0,0,0,0,0,0,0,0,0,0,0,0,0,0,0,0
0,0,0,0,0,0,0,0,0,0,0,0,0,0,0,0,0,0,0,0,0
0,0,0,0,0,0,0,0,0,0,0,0,0,0,0,0,0,0,0,0,0
0,0,0,0,0,0,0,0,0,0,0,0,0,0,0,0,0,0,0,0,0
0,0,0,0,0,0,0,0,0,0,0,0,0,0,0,0,0,0,0,0,0
0,0,0,0,0,0,0,0,0,0,0,0,0,0,0,0,0,0,0,0,0
0,0,0,0,0,0,0,0,0,0,0,0,0,0,0,0,0,0,0,0,0
0,0,0,0,0,0,0,0,0,0,0,0,0,0,0,0,0,0,0,0,0
:endlayer
layer: 14
0,0,0,0,0,0,0,0,0,0,0,0,0,0,0,0,0,0,0,0,0
0,0,0,0,0,0,0,0,0,0,0,0,0,0,0,0,0,0,0,0,0
0,0,0,0,0,0,0,0,0,0,0,0,0,0,0,0,0,0,0,0,0
0,0,0,0,0,0,0,0,0,0,0,0,0,0,0,0,0,0,0,0,0
0,0,0,0,0,0,0,0,0,0,0,0,0,0,0,0,0,0,0,0,0
0,0,0,0,0,0,0,0,0,0,0,0,0,0,0,0,0,0,0,0,0
0,0,0,0,0,0,0,0,0,0,31,0,0,0,0,0,0,0,0,0,0
0,0,0,0,0,0,0,0,0,0,133,0,0,0,0,0,0,0,0,0,0
0,0,0,0,0,0,0,0,0,0,133,0,0,0,0,0,0,0,0,0,0
0,0,0,0,149,0,0,0,0,78,13,77,0,0,0,0,149,0,0,0,0
0,0,0,0,149,0,0,0,0,0,93,0,0,0,0,0,149,0,0,0,0
0,0,0,0,0,0,0,0,0,0,0,0,0,0,0,0,0,0,0,0,0
0,0,0,0,0,0,0,0,0,0,0,0,0,0,0,0,0,0,0,0,0
0,0,0,0,0,0,0,0,0,0,0,0,0,0,0,0,0,0,0,0,0
0,0,0,0,0,0,0,0,0,0,0,0,0,0,0,0,0,0,0,0,0
0,0,0,0,0,0,0,0,0,0,0,0,0,0,0,0,0,0,0,0,0
0,0,0,149,0,0,0,0,0,0,0,0,0,0,0,0,0,149,0,0,0
0,0,0,149,0,0,0,0,0,0,0,0,0,0,0,0,0,149,0,0,0
0,0,0,0,0,0,0,0,0,0,86,0,0,0,0,0,0,0,0,0,0
0,0,0,0,0,0,0,0,0,0,13,0,0,0,0,0,0,0,0,0,0
0,0,0,0,0,0,0,0,0,0,0,0,0,0,0,0,0,0,0,0,0
0,120,120,0,0,0,0,0,0,0,0,0,0,0,0,0,0,0,120,120,0
0,0,0,120,53,53,120,120,0,0,0,0,0,120,120,53,53,120,0,0,0
0,0,0,0,0,0,0,0,53,53,120,53,53,0,0,0,0,0,0,0,0
0,0,0,0,0,0,0,0,0,0,0,0,0,0,0,0,0,0,0,0,0
0,0,0,0,0,0,0,0,0,0,0,0,0,0,0,0,0,0,0,0,0
0,0,0,0,0,0,0,0,0,0,0,0,0,0,0,0,0,0,0,0,0
0,0,0,0,0,0,0,0,0,0,0,0,0,0,0,0,0,0,0,0,0
0,0,0,0,0,0,0,0,0,0,86,0,0,0,0,0,0,0,0,0,0
0,0,0,0,0,0,0,0,0,0,13,0,0,0,0,0,0,0,0,0,0
0,0,0,0,0,0,0,0,0,0,0,0,0,0,0,0,0,0,0,0,0
0,120,120,0,0,0,0,0,0,0,0,0,0,0,0,0,0,0,120,120,0
0,0,0,120,53,53,120,120,0,0,0,0,0,120,120,53,53,120,0,0,0
0,0,0,0,0,0,0,0,53,53,120,53,53,0,0,0,0,0,0,0,0
0,0,0,0,0,0,0,0,0,0,0,0,0,0,0,0,0,0,0,0,0
0,0,0,0,0,0,0,0,0,0,0,0,0,0,0,0,0,0,0,0,0
0,0,0,0,0,0,0,0,0,0,0,0,0,0,0,0,0,0,0,0,0
0,0,0,0,0,0,0,0,0,0,0,0,0,0,0,0,0,0,0,0,0
0,0,0,0,0,0,149,0,0,0,86,0,0,0,149,0,0,0,0,0,0
0,0,0,0,0,149,149,0,0,0,13,0,0,0,149,149,0,0,0,0,0
0,0,0,0,0,149,0,0,0,0,0,0,0,0,0,149,0,0,0,0,0
0,0,0,0,0,0,0,0,0,0,0,0,0,0,0,0,0,0,0,0,0
0,0,0,0,0,0,0,0,0,0,0,0,0,0,0,0,0,0,0,0,0
0,0,0,0,0,0,0,0,0,0,0,0,0,0,0,0,0,0,0,0,0
0,0,0,0,0,0,0,0,0,0,0,0,0,0,0,0,0,0,0,0,0
0,0,0,0,0,0,0,0,0,0,0,0,0,0,0,0,0,0,0,0,0
0,0,0,0,0,0,0,0,0,0,0,0,0,0,0,0,0,0,0,0,0
0,0,0,0,0,0,0,0,0,0,0,0,0,0,0,0,0,0,0,0,0
0,0,0,0,0,0,0,0,0,0,0,0,0,0,0,0,0,0,0,0,0
0,0,0,0,0,0,0,0,0,0,0,0,0,0,0,0,0,0,0,0,0
:endlayer
layer: 15
0,0,0,0,0,0,0,0,0,0,0,0,0,0,0,0,0,0,0,0,0
0,0,0,0,0,0,0,0,0,0,0,0,0,0,0,0,0,0,0,0,0
0,0,0,0,0,0,0,0,0,0,0,0,0,0,0,0,0,0,0,0,0
0,0,0,0,0,0,0,0,0,0,0,0,0,0,0,0,0,0,0,0,0
0,0,0,0,0,0,0,0,0,0,31,0,0,0,0,0,0,0,0,0,0
0,0,0,0,0,0,0,0,0,0,133,0,0,0,0,0,0,0,0,0,0
0,0,0,0,0,0,0,0,0,0,133,0,0,0,0,0,0,0,0,0,0
0,0,0,0,0,0,0,0,0,0,120,0,0,0,0,0,0,0,0,0,0
0,0,0,0,0,0,0,0,0,0,120,0,0,0,0,0,0,0,0,0,0
0,0,0,0,149,0,0,0,0,0,13,0,0,0,0,0,149,0,0,0,0
0,0,0,0,149,0,0,0,0,0,0,0,0,0,0,0,149,0,0,0,0
0,0,0,0,0,0,0,0,0,0,0,0,0,0,0,0,0,0,0,0,0
0,0,0,0,0,0,0,0,0,0,0,0,0,0,0,0,0,0,0,0,0
0,0,0,0,0,0,0,0,0,0,0,0,0,0,0,0,0,0,0,0,0
0,0,0,0,0,0,0,0,0,0,0,0,0,0,0,0,0,0,0,0,0
0,0,0,0,0,0,0,0,0,0,0,0,0,0,0,0,0,0,0,0,0
0,0,0,149,0,0,0,0,0,0,0,0,0,0,0,0,0,149,0,0,0
0,0,0,149,0,0,0,0,0,0,0,0,0,0,0,0,0,149,0,0,0
0,0,0,0,0,0,0,0,0,0,86,0,0,0,0,0,0,0,0,0,0
0,0,0,0,0,0,0,0,0,0,13,0,0,0,0,0,0,0,0,0,0
0,0,0,0,0,0,0,0,0,0,0,0,0,0,0,0,0,0,0,0,0
0,120,53,149,0,0,0,0,0,0,0,0,0,0,0,0,0,149,53,120,0
0,0,0,53,120,120,149,0,0,0,0,0,0,0,149,120,120,53,0,0,0
0,0,0,0,0,0,53,53,120,120,53,120,120,53,53,0,0,0,0,0,0
0,0,0,0,0,0,0,0,0,0,0,0,0,0,0,0,0,0,0,0,0
0,0,0,0,0,0,0,0,0,0,0,0,0,0,0,0,0,0,0,0,0
0,0,0,0,0,0,0,0,0,0,0,0,0,0,0,0,0,0,0,0,0
0,0,0,0,0,0,0,0,0,0,0,0,0,0,0,0,0,0,0,0,0
0,0,0,0,0,0,0,0,0,0,86,0,0,0,0,0,0,0,0,0,0
0,0,0,0,0,0,0,0,0,0,13,0,0,0,0,0,0,0,0,0,0
0,0,0,0,0,0,0,0,0,0,0,0,0,0,0,0,0,0,0,0,0
0,120,53,149,0,0,0,0,0,0,0,0,0,0,0,0,0,149,53,120,0
0,0,0,53,120,120,149,0,0,0,0,0,0,0,149,120,120,53,0,0,0
0,0,0,0,0,0,53,53,120,120,53,120,120,53,53,0,0,0,0,0,0
0,0,0,0,0,0,0,0,0,0,0,0,0,0,0,0,0,0,0,0,0
0,0,0,0,0,0,0,0,0,0,0,0,0,0,0,0,0,0,0,0,0
0,0,0,0,0,0,0,0,0,0,0,0,0,0,0,0,0,0,0,0,0
0,0,0,0,0,0,0,0,0,0,0,0,0,0,0,0,0,0,0,0,0
0,0,0,0,0,0,0,0,0,0,86,0,0,0,0,0,0,0,0,0,0
0,0,0,0,0,149,0,0,0,0,13,0,0,0,0,149,0,0,0,0,0
0,0,0,0,0,149,0,0,0,0,0,0,0,0,0,149,0,0,0,0,0
0,0,0,0,0,0,0,0,0,0,0,0,0,0,0,0,0,0,0,0,0
0,0,0,0,0,0,0,0,0,0,0,0,0,0,0,0,0,0,0,0,0
0,0,0,0,0,0,0,0,0,0,0,0,0,0,0,0,0,0,0,0,0
0,0,0,0,0,0,0,0,0,0,0,0,0,0,0,0,0,0,0,0,0
0,0,0,0,0,0,0,0,0,0,0,0,0,0,0,0,0,0,0,0,0
0,0,0,0,0,0,0,0,0,0,0,0,0,0,0,0,0,0,0,0,0
0,0,0,0,0,0,0,0,0,0,0,0,0,0,0,0,0,0,0,0,0
0,0,0,0,0,0,0,0,0,0,0,0,0,0,0,0,0,0,0,0,0
0,0,0,0,0,0,0,0,0,0,0,0,0,0,0,0,0,0,0,0,0
:endlayer
layer: 16
0,0,0,0,0,0,0,0,0,0,0,0,0,0,0,0,0,0,0,0,0
0,0,0,0,0,0,0,0,0,0,0,0,0,0,0,0,0,0,0,0,0
0,0,0,0,0,0,0,0,0,0,31,0,0,0,0,0,0,0,0,0,0
0,0,0,0,0,0,0,0,0,0,133,0,0,0,0,0,0,0,0,0,0
0,0,0,0,0,0,0,0,0,0,133,0,0,0,0,0,0,0,0,0,0
0,0,0,0,0,0,0,0,0,0,120,0,0,0,0,0,0,0,0,0,0
0,0,0,0,0,0,0,0,0,0,120,0,0,0,0,0,0,0,0,0,0
0,0,0,0,0,0,0,0,0,0,0,120,0,0,0,0,0,0,0,0,0
0,0,0,0,0,0,0,0,0,0,0,120,0,0,0,0,0,0,0,0,0
0,0,0,0,149,0,0,0,0,0,13,0,0,0,0,0,149,0,0,0,0
0,0,0,0,120,149,0,0,0,0,0,0,0,0,0,149,120,0,0,0,0
0,0,0,0,0,120,120,120,53,53,120,53,53,120,120,120,0,0,0,0,0
0,0,0,0,0,0,0,0,0,0,0,0,0,0,0,0,0,0,0,0,0
0,0,0,0,0,0,0,0,0,0,0,0,0,0,0,0,0,0,0,0,0
0,0,0,0,0,0,0,0,0,0,0,0,0,0,0,0,0,0,0,0,0
0,0,0,0,0,0,0,0,0,0,0,0,0,0,0,0,0,0,0,0,0
0,0,0,0,0,0,0,0,0,0,0,0,0,0,0,0,0,0,0,0,0
0,0,0,149,0,0,0,0,0,0,0,0,0,0,0,0,0,149,0,0,0
0,0,0,149,0,0,0,0,0,0,86,0,0,0,0,0,0,149,0,0,0
0,0,0,0,0,0,0,0,0,0,13,0,0,0,0,0,0,0,0,0,0
0,0,0,0,0,0,0,0,0,0,0,0,0,0,0,0,0,0,0,0,0
0,120,120,0,0,0,0,0,0,0,0,0,0,0,0,0,0,0,120,120,0
0,0,0,120,53,53,120,120,0,0,0,0,0,120,120,53,53,120,0,0,0
0,0,0,0,0,0,0,0,53,53,120,53,53,0,0,0,0,0,0,0,0
0,0,0,0,0,0,0,0,0,0,0,0,0,0,0,0,0,0,0,0,0
0,0,0,0,0,0,0,0,0,0,0,0,0,0,0,0,0,0,0,0,0
0,0,0,0,0,0,0,0,0,0,0,0,0,0,0,0,0,0,0,0,0
0,0,0,0,0,0,0,0,0,0,0,0,0,0,0,0,0,0,0,0,0
0,0,0,0,0,0,0,0,0,0,86,0,0,0,0,0,0,0,0,0,0
0,0,0,0,0,0,0,0,0,0,13,0,0,0,0,0,0,0,0,0,0
0,0,0,0,0,0,0,0,0,0,0,0,0,0,0,0,0,0,0,0,0
0,120,120,0,0,0,0,0,0,0,0,0,0,0,0,0,0,0,120,120,0
0,0,0,120,53,53,120,120,0,0,0,0,0,120,120,53,53,120,0,0,0
0,0,0,0,0,0,0,0,53,53,120,53,53,0,0,0,0,0,0,0,0
0,0,0,0,0,0,0,0,0,0,0,0,0,0,0,0,0,0,0,0,0
0,0,0,0,0,0,0,0,0,0,0,0,0,0,0,0,0,0,0,0,0
0,0,0,0,0,0,0,0,0,0,0,0,0,0,0,0,0,0,0,0,0
0,0,0,0,0,0,0,0,0,0,0,0,0,0,0,0,0,0,0,0,0
0,0,0,0,0,0,0,0,0,0,86,0,0,0,0,0,0,0,0,0,0
0,0,0,0,149,149,0,0,0,0,13,0,0,0,0,149,149,0,0,0,0
0,0,0,0,120,149,0,0,0,0,0,0,0,0,0,149,120,0,0,0,0
0,0,0,0,0,120,120,120,53,53,120,53,53,120,120,120,0,0,0,0,0
0,0,0,0,0,0,0,0,0,0,0,0,0,0,0,0,0,0,0,0,0
0,0,0,0,0,0,0,0,0,0,0,0,0,0,0,0,0,0,0,0,0
0,0,0,0,0,0,0,0,0,0,0,0,0,0,0,0,0,0,0,0,0
0,0,0,0,0,0,0,0,0,0,0,0,0,0,0,0,0,0,0,0,0
0,0,0,0,0,0,0,0,0,0,0,0,0,0,0,0,0,0,0,0,0
0,0,0,0,0,0,0,0,0,0,0,0,0,0,0,0,0,0,0,0,0
0,0,0,0,0,0,0,0,0,0,0,0,0,0,0,0,0,0,0,0,0
0,0,0,0,0,0,0,0,0,0,0,0,0,0,0,0,0,0,0,0,0
:endlayer
layer: 17
0,0,0,0,0,0,0,0,0,0,31,0,0,0,0,0,0,0,0,0,0
0,0,0,0,0,0,0,0,0,0,133,0,0,0,0,0,0,0,0,0,0
0,0,0,0,0,0,0,0,0,0,133,0,0,0,0,0,0,0,0,0,0
0,0,0,0,0,0,0,0,0,0,120,0,0,0,0,0,0,0,0,0,0
0,0,0,0,0,0,0,0,0,0,120,0,0,0,0,0,0,0,0,0,0
0,0,0,0,0,0,0,0,0,0,149,120,0,0,0,0,0,0,0,0,0
0,0,0,0,0,0,0,0,0,0,0,120,0,0,0,0,0,0,0,0,0
0,0,0,0,0,0,0,0,0,0,0,120,0,0,0,0,0,0,0,0,0
0,0,0,0,0,0,0,0,0,0,0,120,0,0,0,0,0,0,0,0,0
0,0,0,0,0,0,0,0,0,0,13,0,0,0,0,0,0,0,0,0,0
0,0,0,0,0,0,0,0,0,0,0,0,0,0,0,0,0,0,0,0,0
0,0,0,0,120,120,53,0,0,0,0,0,0,0,53,120,120,0,0,0,0
0,0,0,0,0,0,0,53,120,120,120,120,120,53,0,0,0,0,0,0,0
0,0,0,0,0,0,0,0,0,0,0,0,0,0,0,0,0,0,0,0,0
0,0,0,0,0,0,0,0,0,0,0,0,0,0,0,0,0,0,0,0,0
0,0,0,0,0,0,0,0,0,0,0,0,0,0,0,0,0,0,0,0,0
0,0,0,0,0,0,0,0,0,0,0,0,0,0,0,0,0,0,0,0,0
0,0,0,149,0,0,0,0,0,0,0,0,0,0,0,0,0,149,0,0,0
0,0,0,149,0,0,0,0,0,0,86,0,0,0,0,0,0,149,0,0,0
0,0,0,0,0,0,0,0,0,0,13,0,0,0,0,0,0,0,0,0,0
0,0,0,0,0,0,0,0,0,0,0,0,0,0,0,0,0,0,0,0,0
0,120,53,53,120,0,0,0,0,0,0,0,0,0,0,0,120,53,53,120,0
0,0,0,0,0,120,53,53,120,120,120,120,120,53,53,120,0,0,0,0,0
0,0,0,0,0,0,0,0,0,0,0,0,0,0,0,0,0,0,0,0,0
0,0,0,0,0,0,0,0,0,0,0,0,0,0,0,0,0,0,0,0,0
0,0,0,0,0,0,0,0,0,0,0,0,0,0,0,0,0,0,0,0,0
0,0,0,0,0,0,0,0,0,0,0,0,0,0,0,0,0,0,0,0,0
0,0,0,0,0,0,0,0,0,0,0,0,0,0,0,0,0,0,0,0,0
0,0,0,0,0,0,0,0,0,0,86,0,0,0,0,0,0,0,0,0,0
0,0,0,0,0,0,0,0,0,0,13,0,0,0,0,0,0,0,0,0,0
0,0,0,0,0,0,0,0,0,0,0,0,0,0,0,0,0,0,0,0,0
0,120,53,53,120,0,0,0,0,0,0,0,0,0,0,0,120,53,53,120,0
0,0,0,0,0,120,53,53,120,120,120,120,120,53,53,120,0,0,0,0,0
0,0,0,0,0,0,0,0,0,0,0,0,0,0,0,0,0,0,0,0,0
0,0,0,0,0,0,0,0,0,0,0,0,0,0,0,0,0,0,0,0,0
0,0,0,0,0,0,0,0,0,0,0,0,0,0,0,0,0,0,0,0,0
0,0,0,0,0,0,0,0,0,0,0,0,0,0,0,0,0,0,0,0,0
0,0,0,0,0,0,0,0,0,0,0,0,0,0,0,0,0,0,0,0,0
0,0,0,0,0,0,0,0,0,0,86,0,0,0,0,0,0,0,0,0,0
0,0,0,0,0,0,0,0,0,0,13,0,0,0,0,0,0,0,0,0,0
0,0,0,0,0,0,0,0,0,0,0,0,0,0,0,0,0,0,0,0,0
0,0,0,0,120,120,53,0,0,0,0,0,0,0,53,120,120,0,0,0,0
0,0,0,0,0,0,0,53,120,120,120,120,120,53,0,0,0,0,0,0,0
0,0,0,0,0,0,0,0,0,0,0,0,0,0,0,0,0,0,0,0,0
0,0,0,0,0,0,0,0,0,0,0,0,0,0,0,0,0,0,0,0,0
0,0,0,0,0,0,0,0,0,0,0,0,0,0,0,0,0,0,0,0,0
0,0,0,0,0,0,0,0,0,0,0,0,0,0,0,0,0,0,0,0,0
0,0,0,0,0,0,0,0,0,0,0,0,0,0,0,0,0,0,0,0,0
0,0,0,0,0,0,0,0,0,0,0,0,0,0,0,0,0,0,0,0,0
0,0,0,0,0,0,0,0,0,0,0,0,0,0,0,0,0,0,0,0,0
:endlayer
layer: 18
0,0,0,0,0,0,0,0,0,0,148,0,0,0,0,0,0,0,0,0,0
0,0,0,0,0,0,0,0,0,0,120,0,0,0,0,0,0,0,0,0,0
0,0,0,0,0,0,0,0,0,0,120,0,0,0,0,0,0,0,0,0,0
0,0,0,0,0,0,0,0,0,0,0,120,0,0,0,0,0,0,0,0,0
0,0,0,0,0,0,0,0,0,0,0,120,0,0,0,0,0,0,0,0,0
0,0,0,0,0,0,0,0,0,0,0,120,0,0,0,0,0,0,0,0,0
0,0,0,0,0,0,0,0,0,0,0,120,0,0,0,0,0,0,0,0,0
0,0,0,0,0,0,0,0,0,0,0,120,0,0,0,0,0,0,0,0,0
0,0,0,0,0,0,0,0,0,0,0,120,0,0,0,0,0,0,0,0,0
0,0,0,0,0,0,0,0,0,0,13,0,0,0,0,0,0,0,0,0,0
0,0,0,0,0,0,0,0,0,0,0,0,0,0,0,0,0,0,0,0,0
0,0,0,0,120,53,0,0,0,0,0,0,0,0,0,53,120,0,0,0,0
0,0,0,0,0,0,120,120,53,0,0,0,53,120,120,0,0,0,0,0,0
0,0,0,0,0,0,0,0,0,53,120,53,0,0,0,0,0,0,0,0,0
0,0,0,0,0,0,0,0,0,0,0,0,0,0,0,0,0,0,0,0,0
0,0,0,0,0,0,0,0,0,0,0,0,0,0,0,0,0,0,0,0,0
0,0,0,0,0,0,0,0,0,0,0,0,0,0,0,0,0,0,0,0,0
0,0,0,0,0,0,0,0,0,0,0,0,0,0,0,0,0,0,0,0,0
0,0,0,149,0,0,0,0,0,0,86,0,0,0,0,0,0,149,0,0,0
0,0,0,149,0,0,0,0,0,0,13,0,0,0,0,0,0,149,0,0,0
0,120,149,0,0,0,0,0,0,0,93,0,0,0,0,0,0,0,149,120,0
0,0,120,120,53,53,120,120,120,120,120,120,120,120,120,53,53,120,120,0,0
0,0,0,0,0,0,0,0,0,0,0,0,0,0,0,0,0,0,0,0,0
0,0,0,0,0,0,0,0,0,0,0,0,0,0,0,0,0,0,0,0,0
0,0,0,0,0,0,0,0,0,0,0,0,0,0,0,0,0,0,0,0,0
0,0,0,0,0,0,0,0,0,0,0,0,0,0,0,0,0,0,0,0,0
0,0,0,0,0,0,0,0,0,0,0,0,0,0,0,0,0,0,0,0,0
0,0,0,0,0,0,0,0,0,0,0,0,0,0,0,0,0,0,0,0,0
0,0,0,0,0,0,0,0,0,0,86,0,0,0,0,0,0,0,0,0,0
0,0,0,0,0,0,0,0,0,0,13,0,0,0,0,0,0,0,0,0,0
0,120,149,0,0,0,0,0,0,0,93,0,0,0,0,0,0,0,149,120,0
0,0,120,120,53,53,120,120,120,120,120,120,120,120,120,53,53,120,120,0,0
0,0,0,0,0,0,0,0,0,0,0,0,0,0,0,0,0,0,0,0,0
0,0,0,0,0,0,0,0,0,0,0,0,0,0,0,0,0,0,0,0,0
0,0,0,0,0,0,0,0,0,0,0,0,0,0,0,0,0,0,0,0,0
0,0,0,0,0,0,0,0,0,0,0,0,0,0,0,0,0,0,0,0,0
0,0,0,0,0,0,0,0,0,0,0,0,0,0,0,0,0,0,0,0,0
0,0,0,0,0,0,0,0,0,0,0,0,0,0,0,0,0,0,0,0,0
0,0,0,0,0,0,0,0,0,0,86,0,0,0,0,0,0,0,0,0,0
0,0,0,0,0,0,0,0,0,0,13,0,0,0,0,0,0,0,0,0,0
0,0,0,0,0,0,0,0,0,0,0,0,0,0,0,0,0,0,0,0,0
0,0,0,0,120,53,0,0,0,0,0,0,0,0,0,53,120,0,0,0,0
0,0,0,0,0,0,120,120,53,0,0,0,53,120,120,0,0,0,0,0,0
0,0,0,0,0,0,0,0,0,53,120,53,0,0,0,0,0,0,0,0,0
0,0,0,0,0,0,0,0,0,0,0,0,0,0,0,0,0,0,0,0,0
0,0,0,0,0,0,0,0,0,0,0,0,0,0,0,0,0,0,0,0,0
0,0,0,0,0,0,0,0,0,0,0,0,0,0,0,0,0,0,0,0,0
0,0,0,0,0,0,0,0,0,0,0,0,0,0,0,0,0,0,0,0,0
0,0,0,0,0,0,0,0,0,0,0,0,0,0,0,0,0,0,0,0,0
0,0,0,0,0,0,0,0,0,0,0,0,0,0,0,0,0,0,0,0,0
:endlayer
layer: 19
0,0,0,0,0,0,0,0,0,0,0,0,0,0,0,0,0,0,0,0,0
0,0,0,0,0,0,0,0,0,0,0,120,0,0,0,0,0,0,0,0,0
0,0,0,0,0,0,0,0,0,0,0,120,0,0,0,0,0,0,0,0,0
0,0,0,0,0,0,0,0,0,0,0,120,0,0,0,0,0,0,0,0,0
0,0,0,0,0,0,0,0,0,0,0,53,0,0,0,0,0,0,0,0,0
0,0,0,0,0,0,0,0,0,0,0,120,0,0,0,0,0,0,0,0,0
0,0,0,0,0,0,0,0,0,0,0,120,0,0,0,0,0,0,0,0,0
0,0,0,0,0,0,0,0,0,0,0,120,0,0,0,0,0,0,0,0,0
0,0,0,0,0,0,0,0,0,0,94,120,0,0,0,0,0,0,0,0,0
0,0,0,0,0,0,0,0,0,0,13,0,0,0,0,0,0,0,0,0,0
0,0,0,0,0,0,0,0,0,0,0,0,0,0,0,0,0,0,0,0,0
0,0,0,0,120,120,149,0,0,0,0,0,0,0,149,120,120,0,0,0,0
0,0,0,0,0,0,53,53,149,0,0,0,149,53,53,0,0,0,0,0,0
0,0,0,0,0,0,0,0,120,120,53,120,120,0,0,0,0,0,0,0,0
0,0,0,0,0,0,0,0,0,0,0,0,0,0,0,0,0,0,0,0,0
0,0,0,0,0,0,0,0,0,0,0,0,0,0,0,0,0,0,0,0,0
0,0,0,0,0,0,0,0,0,0,0,0,0,0,0,0,0,0,0,0,0
0,0,0,0,0,0,0,0,0,0,0,0,0,0,0,0,0,0,0,0,0
0,0,0,149,0,0,0,0,0,0,86,0,0,0,0,0,0,149,0,0,0
0,94,0,149,0,0,0,0,0,0,13,0,0,0,0,0,0,149,0,94,0
58,135,135,135,135,135,135,135,135,135,135,135,135,135,135,135,135,135,135,135,40
0,0,0,0,0,0,0,0,0,0,108,0,0,0,0,0,0,0,0,0,0
0,0,0,149,0,0,0,0,0,0,0,0,0,0,0,0,0,149,0,0,0
0,0,0,149,0,0,0,0,0,0,0,0,0,0,0,0,0,149,0,0,0
0,0,0,149,0,0,0,0,0,0,0,0,0,0,0,0,0,149,0,0,0
0,0,0,149,0,0,0,0,0,0,0,0,0,0,0,0,0,149,0,0,0
0,0,0,149,0,0,0,0,0,0,0,0,0,0,0,0,0,149,0,0,0
0,0,0,149,0,0,0,0,0,0,0,0,0,0,0,0,0,149,0,0,0
0,0,0,0,0,0,0,0,0,0,86,0,0,0,0,0,0,0,0,0,0
0,94,0,0,0,0,0,0,0,0,13,0,0,0,0,0,0,0,0,94,0
58,135,135,135,135,135,135,135,135,135,135,135,135,135,135,135,135,135,135,135,40
0,0,0,0,0,0,0,0,0,0,108,0,0,0,0,0,0,0,0,0,0
0,0,0,0,0,0,0,0,0,0,0,0,0,0,0,0,0,0,0,0,0
0,0,0,0,0,0,0,0,0,0,0,0,0,0,0,0,0,0,0,0,0
0,0,0,0,0,0,0,0,0,0,0,0,0,0,0,0,0,0,0,0,0
0,0,0,0,0,0,0,0,0,0,0,0,0,0,0,0,0,0,0,0,0
0,0,0,0,0,0,0,0,0,0,0,0,0,0,0,0,0,0,0,0,0
0,0,0,0,0,0,0,0,0,0,0,0,0,0,0,0,0,0,0,0,0
0,0,0,0,0,0,0,0,0,0,86,0,0,0,0,0,0,0,0,0,0
0,0,0,0,0,0,0,0,0,0,13,0,0,0,0,0,0,0,0,0,0
0,0,0,0,0,0,0,0,0,0,0,0,0,0,0,0,0,0,0,0,0
0,0,0,0,120,120,149,0,0,0,0,0,0,0,149,120,120,0,0,0,0
0,0,0,0,0,0,53,53,149,0,0,0,149,53,53,0,0,0,0,0,0
0,0,0,0,0,0,0,0,120,120,53,120,120,0,0,0,0,0,0,0,0
0,0,0,0,0,0,0,0,0,0,0,0,0,0,0,0,0,0,0,0,0
0,0,0,0,0,0,0,0,0,0,0,0,0,0,0,0,0,0,0,0,0
0,0,0,0,0,0,0,0,0,0,0,0,0,0,0,0,0,0,0,0,0
0,0,0,0,0,0,0,0,0,0,0,0,0,0,0,0,0,0,0,0,0
0,0,0,0,0,0,0,0,0,0,0,0,0,0,0,0,0,0,0,0,0
0,0,0,0,0,0,0,0,0,0,0,0,0,0,0,0,0,0,0,0,0
:endlayer
layer: 20
0,0,0,0,0,0,0,0,0,0,0,0,0,0,0,0,0,0,0,0,0
0,0,0,0,0,0,0,0,0,0,0,0,0,0,0,0,0,0,0,0,0
0,0,0,0,0,0,0,0,0,0,0,120,0,0,0,0,0,0,0,0,0
0,0,0,0,0,0,0,0,0,0,0,53,0,0,0,0,0,0,0,0,0
0,0,0,0,0,0,0,0,0,0,0,120,0,0,0,0,0,0,0,0,0
0,0,0,0,0,0,0,0,0,0,0,53,0,0,0,0,0,0,0,0,0
0,0,0,0,0,0,0,0,0,0,0,120,0,0,0,0,0,0,0,0,0
0,0,0,0,0,0,0,0,0,0,0,120,0,0,0,0,0,0,0,0,0
0,0,0,0,0,0,0,0,0,0,120,0,0,0,0,0,0,0,0,0,0
0,0,0,0,0,0,0,0,0,0,13,0,0,0,0,0,0,0,0,0,0
0,0,0,0,0,0,0,0,0,0,0,0,0,0,0,0,0,0,0,0,0
0,0,0,0,120,53,0,0,0,0,0,0,0,0,0,53,120,0,0,0,0
0,0,0,0,0,0,120,120,53,0,0,0,53,120,120,0,0,0,0,0,0
0,0,0,0,0,0,0,0,0,53,120,53,0,0,0,0,0,0,0,0,0
0,0,0,0,0,0,0,0,0,0,0,0,0,0,0,0,0,0,0,0,0
0,0,0,0,0,0,0,0,0,0,0,0,0,0,0,0,0,0,0,0,0
0,0,0,0,0,0,0,0,0,0,0,0,0,0,0,0,0,0,0,0,0
0,0,0,0,0,0,0,0,0,0,0,0,0,0,0,0,0,0,0,0,0
0,0,0,0,0,0,0,0,0,0,86,0,0,0,0,0,0,0,0,0,0
0,0,0,149,0,0,0,0,0,0,13,0,0,0,0,0,0,149,0,0,0
0,0,0,149,0,0,0,0,0,0,3,0,0,0,0,0,0,149,0,0,0
0,0,0,149,0,0,0,0,0,0,153,0,0,0,0,0,0,149,0,0,0
0,0,0,149,0,0,0,0,0,0,0,0,0,0,0,0,0,149,0,0,0
0,0,0,0,0,0,0,0,0,0,0,0,0,0,0,0,0,0,0,0,0
0,0,0,0,0,0,0,0,0,0,0,0,0,0,0,0,0,0,0,0,0
0,0,0,0,0,0,0,0,0,0,0,0,0,0,0,0,0,0,0,0,0
0,0,0,0,0,0,0,0,0,0,0,0,0,0,0,0,0,0,0,0,0
0,0,0,149,0,0,0,0,0,0,0,0,0,0,0,0,0,149,0,0,0
0,0,0,149,0,0,0,0,0,0,86,0,0,0,0,0,0,149,0,0,0
0,0,0,149,0,0,0,0,0,0,13,0,0,0,0,0,0,149,0,0,0
0,0,0,0,0,0,0,0,0,0,3,0,0,0,0,0,0,0,0,0,0
0,0,0,0,0,0,0,0,0,0,153,0,0,0,0,0,0,0,0,0,0
0,0,0,0,0,0,0,0,0,0,0,0,0,0,0,0,0,0,0,0,0
0,0,0,0,0,0,0,0,0,0,0,0,0,0,0,0,0,0,0,0,0
0,0,0,0,0,0,0,0,0,0,0,0,0,0,0,0,0,0,0,0,0
0,0,0,0,0,0,0,0,0,0,0,0,0,0,0,0,0,0,0,0,0
0,0,0,0,0,0,0,0,0,0,0,0,0,0,0,0,0,0,0,0,0
0,0,0,0,0,0,0,0,0,0,0,0,0,0,0,0,0,0,0,0,0
0,0,0,0,0,0,0,0,0,0,86,0,0,0,0,0,0,0,0,0,0
0,0,0,0,0,0,0,0,0,0,13,0,0,0,0,0,0,0,0,0,0
0,0,0,0,0,0,0,0,0,0,0,0,0,0,0,0,0,0,0,0,0
0,0,0,0,120,53,0,0,0,0,0,0,0,0,0,53,120,0,0,0,0
0,0,0,0,0,0,120,120,53,0,0,0,53,120,120,0,0,0,0,0,0
0,0,0,0,0,0,0,0,0,53,120,53,0,0,0,0,0,0,0,0,0
0,0,0,0,0,0,0,0,0,0,0,0,0,0,0,0,0,0,0,0,0
0,0,0,0,0,0,0,0,0,0,0,0,0,0,0,0,0,0,0,0,0
0,0,0,0,0,0,0,0,0,0,0,0,0,0,0,0,0,0,0,0,0
0,0,0,0,0,0,0,0,0,0,0,0,0,0,0,0,0,0,0,0,0
0,0,0,0,0,0,0,0,0,0,0,0,0,0,0,0,0,0,0,0,0
0,0,0,0,0,0,0,0,0,0,0,0,0,0,0,0,0,0,0,0,0
:endlayer
layer: 21
0,0,0,0,0,0,0,0,0,0,0,0,0,0,0,0,0,0,0,0,0
0,0,0,0,0,0,0,0,0,0,0,0,0,0,0,0,0,0,0,0,0
0,0,0,0,0,0,0,0,0,0,0,120,0,0,0,0,0,0,0,0,0
0,0,0,0,0,0,0,0,0,0,0,120,0,0,0,0,0,0,0,0,0
0,0,0,0,0,0,0,0,0,0,0,53,0,0,0,0,0,0,0,0,0
0,0,0,0,0,0,0,0,0,0,0,120,0,0,0,0,0,0,0,0,0
0,0,0,0,0,0,0,0,0,0,0,120,0,0,0,0,0,0,0,0,0
0,0,0,0,0,0,0,0,0,0,120,0,0,0,0,0,0,0,0,0,0
0,0,0,0,0,0,0,0,0,0,133,0,0,0,0,0,0,0,0,0,0
0,0,0,0,0,0,0,0,0,0,13,0,0,0,0,0,0,0,0,0,0
0,0,0,0,0,0,0,0,0,0,0,0,0,0,0,0,0,0,0,0,0
0,0,0,0,120,120,53,0,0,0,0,0,0,0,53,120,120,0,0,0,0
0,0,0,0,0,0,0,53,120,120,120,120,120,53,0,0,0,0,0,0,0
0,0,0,0,0,0,0,0,0,0,0,0,0,0,0,0,0,0,0,0,0
0,0,0,0,0,0,0,0,0,0,0,0,0,0,0,0,0,0,0,0,0
0,0,0,0,0,0,0,0,0,0,0,0,0,0,0,0,0,0,0,0,0
0,0,0,0,0,0,0,0,0,0,0,0,0,0,0,0,0,0,0,0,0
0,0,0,0,0,0,0,0,0,0,0,0,0,0,0,0,0,0,0,0,0
0,0,0,0,0,0,0,0,0,0,86,0,0,0,0,0,0,0,0,0,0
0,0,0,149,149,0,0,0,0,0,13,0,0,0,0,0,149,149,0,0,0
0,0,0,149,120,149,0,0,0,0,0,0,0,0,0,149,120,149,0,0,0
0,0,0,0,0,120,53,53,120,120,120,120,120,53,53,120,0,0,0,0,0
0,0,0,0,0,0,0,0,0,0,0,0,0,0,0,0,0,0,0,0,0
0,0,0,0,0,0,0,0,0,0,0,0,0,0,0,0,0,0,0,0,0
0,0,0,0,0,0,0,0,0,0,0,0,0,0,0,0,0,0,0,0,0
0,0,0,0,0,0,0,0,0,0,0,0,0,0,0,0,0,0,0,0,0
0,0,0,0,0,0,0,0,0,0,0,0,0,0,0,0,0,0,0,0,0
0,0,0,0,0,0,0,0,0,0,0,0,0,0,0,0,0,0,0,0,0
0,0,0,0,0,0,0,0,0,0,86,0,0,0,0,0,0,0,0,0,0
0,0,0,149,149,0,0,0,0,0,13,0,0,0,0,0,149,149,0,0,0
0,0,0,149,120,149,0,0,0,0,0,0,0,0,0,149,120,149,0,0,0
0,0,0,0,0,120,53,53,120,120,120,120,120,53,53,120,0,0,0,0,0
0,0,0,0,0,0,0,0,0,0,0,0,0,0,0,0,0,0,0,0,0
0,0,0,0,0,0,0,0,0,0,0,0,0,0,0,0,0,0,0,0,0
0,0,0,0,0,0,0,0,0,0,0,0,0,0,0,0,0,0,0,0,0
0,0,0,0,0,0,0,0,0,0,0,0,0,0,0,0,0,0,0,0,0
0,0,0,0,0,0,0,0,0,0,0,0,0,0,0,0,0,0,0,0,0
0,0,0,0,0,0,0,0,0,0,0,0,0,0,0,0,0,0,0,0,0
0,0,0,0,0,0,0,0,0,0,86,0,0,0,0,0,0,0,0,0,0
0,0,0,0,0,0,0,0,0,0,13,0,0,0,0,0,0,0,0,0,0
0,0,0,0,0,0,0,0,0,0,0,0,0,0,0,0,0,0,0,0,0
0,0,0,0,120,120,53,0,0,0,0,0,0,0,53,120,120,0,0,0,0
0,0,0,0,0,0,0,53,120,120,120,120,120,53,0,0,0,0,0,0,0
0,0,0,0,0,0,0,0,0,0,0,0,0,0,0,0,0,0,0,0,0
0,0,0,0,0,0,0,0,0,0,0,0,0,0,0,0,0,0,0,0,0
0,0,0,0,0,0,0,0,0,0,0,0,0,0,0,0,0,0,0,0,0
0,0,0,0,0,0,0,0,0,0,0,0,0,0,0,0,0,0,0,0,0
0,0,0,0,0,0,0,0,0,0,0,0,0,0,0,0,0,0,0,0,0
0,0,0,0,0,0,0,0,0,0,0,0,0,0,0,0,0,0,0,0,0
0,0,0,0,0,0,0,0,0,0,0,0,0,0,0,0,0,0,0,0,0
:endlayer
layer: 22
0,0,0,0,0,0,0,0,0,0,0,0,0,0,0,0,0,0,0,0,0
0,0,0,0,0,0,0,0,0,0,0,0,0,0,0,0,0,0,0,0,0
0,0,0,0,0,0,0,0,0,0,0,120,0,0,0,0,0,0,0,0,0
0,0,0,0,0,0,0,0,0,0,0,120,0,0,0,0,0,0,0,0,0
0,0,0,0,0,0,0,0,0,0,0,120,0,0,0,0,0,0,0,0,0
0,0,0,0,0,0,0,0,0,0,0,120,0,0,0,0,0,0,0,0,0
0,0,0,0,0,0,0,0,0,0,120,0,0,0,0,0,0,0,0,0,0
0,0,0,0,0,0,0,0,0,0,133,0,0,0,0,0,0,0,0,0,0
0,0,0,0,0,0,0,0,0,0,3,0,0,0,0,0,0,0,0,0,0
0,0,0,0,0,0,0,0,0,0,13,0,0,0,0,0,0,0,0,0,0
0,0,0,0,120,149,0,0,0,0,93,0,0,0,0,149,120,0,0,0,0
0,0,0,0,0,120,120,120,53,53,120,53,53,120,120,120,0,0,0,0,0
0,0,0,0,0,0,0,0,0,0,0,0,0,0,0,0,0,0,0,0,0
0,0,0,0,0,0,0,0,0,0,0,0,0,0,0,0,0,0,0,0,0
0,0,0,0,0,0,0,0,0,0,0,0,0,0,0,0,0,0,0,0,0
0,0,0,0,0,0,0,0,0,0,0,0,0,0,0,0,0,0,0,0,0
0,0,0,0,0,0,0,0,0,0,0,0,0,0,0,0,0,0,0,0,0
0,0,0,0,0,0,0,0,0,0,0,0,0,0,0,0,0,0,0,0,0
0,0,0,0,0,0,0,0,0,0,86,0,0,0,0,0,0,0,0,0,0
0,0,0,0,0,0,0,0,0,0,13,0,0,0,0,0,0,0,0,0,0
0,0,0,0,0,0,0,0,0,0,0,0,0,0,0,0,0,0,0,0,0
0,0,0,0,53,53,120,0,0,0,0,0,0,0,120,53,53,0,0,0,0
0,0,0,0,0,0,0,120,53,53,120,53,53,120,0,0,0,0,0,0,0
0,0,0,0,0,0,0,0,0,0,0,0,0,0,0,0,0,0,0,0,0
0,0,0,0,0,0,0,0,0,0,0,0,0,0,0,0,0,0,0,0,0
0,0,0,0,0,0,0,0,0,0,0,0,0,0,0,0,0,0,0,0,0
0,0,0,0,0,0,0,0,0,0,0,0,0,0,0,0,0,0,0,0,0
0,0,0,0,0,0,0,0,0,0,0,0,0,0,0,0,0,0,0,0,0
0,0,0,0,0,0,0,0,0,0,86,0,0,0,0,0,0,0,0,0,0
0,0,0,0,0,0,0,0,0,0,13,0,0,0,0,0,0,0,0,0,0
0,0,0,0,0,0,0,0,0,0,0,0,0,0,0,0,0,0,0,0,0
0,0,0,0,53,53,120,0,0,0,0,0,0,0,120,53,53,0,0,0,0
0,0,0,0,0,0,0,120,53,53,120,53,53,120,0,0,0,0,0,0,0
0,0,0,0,0,0,0,0,0,0,0,0,0,0,0,0,0,0,0,0,0
0,0,0,0,0,0,0,0,0,0,0,0,0,0,0,0,0,0,0,0,0
0,0,0,0,0,0,0,0,0,0,0,0,0,0,0,0,0,0,0,0,0
0,0,0,0,0,0,0,0,0,0,0,0,0,0,0,0,0,0,0,0,0
0,0,0,0,0,0,0,0,0,0,0,0,0,0,0,0,0,0,0,0,0
0,0,0,0,0,0,0,0,0,0,86,0,0,0,0,0,0,0,0,0,0
0,0,0,0,0,0,0,0,0,0,13,0,0,0,0,0,0,0,0,0,0
0,0,0,0,120,149,0,0,0,0,93,0,0,0,0,149,120,0,0,0,0
0,0,0,0,0,120,120,120,53,53,120,53,53,120,120,120,0,0,0,0,0
0,0,0,0,0,0,0,0,0,0,0,0,0,0,0,0,0,0,0,0,0
0,0,0,0,0,0,0,0,0,0,0,0,0,0,0,0,0,0,0,0,0
0,0,0,0,0,0,0,0,0,0,0,0,0,0,0,0,0,0,0,0,0
0,0,0,0,0,0,0,0,0,0,0,0,0,0,0,0,0,0,0,0,0
0,0,0,0,0,0,0,0,0,0,0,0,0,0,0,0,0,0,0,0,0
0,0,0,0,0,0,0,0,0,0,0,0,0,0,0,0,0,0,0,0,0
0,0,0,0,0,0,0,0,0,0,0,0,0,0,0,0,0,0,0,0,0
0,0,0,0,0,0,0,0,0,0,0,0,0,0,0,0,0,0,0,0,0
:endlayer
layer: 23
0,0,0,0,0,0,0,0,0,0,0,0,0,0,0,0,0,0,0,0,0
0,0,0,0,0,0,0,0,0,0,0,0,0,0,0,0,0,0,0,0,0
0,0,0,0,0,0,0,0,0,0,0,120,0,0,0,0,0,0,0,0,0
0,0,0,0,0,0,0,0,0,0,0,120,0,0,0,0,0,0,0,0,0
0,0,0,0,0,0,0,0,0,0,149,120,0,0,0,0,0,0,0,0,0
0,0,0,0,0,0,0,0,0,0,120,0,0,0,0,0,0,0,0,0,0
0,0,0,0,0,0,0,0,0,0,133,0,0,0,0,0,0,0,0,0,0
0,0,0,0,0,0,0,0,0,0,3,0,0,0,0,0,0,0,0,0,0
0,0,0,0,0,0,0,0,0,0,0,0,0,0,0,0,0,0,0,0,0
0,0,0,0,94,0,0,0,0,0,13,0,0,0,0,0,94,0,0,0,0
0,0,0,58,135,135,135,135,135,135,135,135,135,135,135,135,135,40,0,0,0
0,0,0,0,0,0,0,0,0,0,108,0,0,0,0,0,0,0,0,0,0
0,0,0,0,0,0,0,0,0,0,0,0,0,0,0,0,0,0,0,0,0
0,0,0,0,0,0,0,0,0,0,0,0,0,0,0,0,0,0,0,0,0
0,0,0,0,0,0,0,0,0,0,0,0,0,0,0,0,0,0,0,0,0
0,0,0,0,0,0,0,0,0,0,0,0,0,0,0,0,0,0,0,0,0
0,0,0,0,0,0,0,0,0,0,0,0,0,0,0,0,0,0,0,0,0
0,0,0,0,0,0,0,0,0,0,0,0,0,0,0,0,0,0,0,0,0
0,0,0,0,0,0,0,0,0,0,86,0,0,0,0,0,0,0,0,0,0
0,0,0,0,0,0,0,0,0,0,13,0,0,0,0,0,0,0,0,0,0
0,0,0,0,0,0,0,0,0,0,0,0,0,0,0,0,0,0,0,0,0
0,0,0,0,120,149,0,0,0,0,0,0,0,0,0,149,120,0,0,0,0
0,0,0,0,0,120,53,53,120,120,53,120,120,53,53,120,0,0,0,0,0
0,0,0,0,0,0,0,0,0,0,0,0,0,0,0,0,0,0,0,0,0
0,0,0,0,0,0,0,0,0,0,0,0,0,0,0,0,0,0,0,0,0
0,0,0,0,0,0,0,0,0,0,0,0,0,0,0,0,0,0,0,0,0
0,0,0,0,0,0,0,0,0,0,0,0,0,0,0,0,0,0,0,0,0
0,0,0,0,0,0,0,0,0,0,0,0,0,0,0,0,0,0,0,0,0
0,0,0,0,0,0,0,0,0,0,86,0,0,0,0,0,0,0,0,0,0
0,0,0,0,0,0,0,0,0,0,13,0,0,0,0,0,0,0,0,0,0
0,0,0,0,0,0,0,0,0,0,0,0,0,0,0,0,0,0,0,0,0
0,0,0,0,120,149,0,0,0,0,0,0,0,0,0,149,120,0,0,0,0
0,0,0,0,0,120,53,53,120,120,53,120,120,53,53,120,0,0,0,0,0
0,0,0,0,0,0,0,0,0,0,0,0,0,0,0,0,0,0,0,0,0
0,0,0,0,0,0,0,0,0,0,0,0,0,0,0,0,0,0,0,0,0
0,0,0,0,0,0,0,0,0,0,0,0,0,0,0,0,0,0,0,0,0
0,0,0,0,0,0,0,0,0,0,0,0,0,0,0,0,0,0,0,0,0
0,0,0,0,0,0,0,0,0,0,0,0,0,0,0,0,0,0,0,0,0
0,0,0,0,0,0,0,0,0,32,86,32,0,0,0,0,0,0,0,0,0
0,0,0,0,94,0,0,0,0,58,13,40,0,0,0,0,94,0,0,0,0
0,0,0,58,135,135,135,135,135,135,135,135,135,135,135,135,135,40,0,0,0
0,0,0,0,0,0,0,0,0,0,108,0,0,0,0,0,0,0,0,0,0
0,0,0,0,0,0,0,0,0,0,0,0,0,0,0,0,0,0,0,0,0
0,0,0,0,0,0,0,0,0,0,0,0,0,0,0,0,0,0,0,0,0
0,0,0,0,0,0,0,0,0,0,0,0,0,0,0,0,0,0,0,0,0
0,0,0,0,0,0,0,0,0,0,0,0,0,0,0,0,0,0,0,0,0
0,0,0,0,0,0,0,0,0,0,0,0,0,0,0,0,0,0,0,0,0
0,0,0,0,0,0,0,0,0,0,0,0,0,0,0,0,0,0,0,0,0
0,0,0,0,0,0,0,0,0,0,0,0,0,0,0,0,0,0,0,0,0
0,0,0,0,0,0,0,0,0,0,0,0,0,0,0,0,0,0,0,0,0
:endlayer
layer: 24
0,0,0,0,0,0,0,0,0,0,0,0,0,0,0,0,0,0,0,0,0
0,0,0,0,0,0,0,0,0,0,0,0,0,0,0,0,0,0,0,0,0
0,0,0,0,0,0,0,0,0,0,0,120,0,0,0,0,0,0,0,0,0
0,0,0,0,0,0,0,0,0,0,0,120,0,0,0,0,0,0,0,0,0
0,0,0,0,0,0,0,0,0,0,120,0,0,0,0,0,0,0,0,0,0
0,0,0,0,0,0,0,0,0,0,133,0,0,0,0,0,0,0,0,0,0
0,0,0,0,0,0,0,0,0,0,3,0,0,0,0,0,0,0,0,0,0
0,0,0,0,0,0,0,0,0,0,0,0,0,0,0,0,0,0,0,0,0
0,0,0,0,0,0,0,0,0,0,0,0,0,0,0,0,0,0,0,0,0
0,0,0,0,0,0,0,0,0,0,13,0,0,0,0,0,0,0,0,0,0
0,0,0,0,0,0,0,0,0,0,3,0,0,0,0,0,0,0,0,0,0
0,0,0,0,0,0,0,0,0,0,153,0,0,0,0,0,0,0,0,0,0
0,0,0,0,0,0,0,0,0,0,0,0,0,0,0,0,0,0,0,0,0
0,0,0,0,0,0,0,0,0,0,0,0,0,0,0,0,0,0,0,0,0
0,0,0,0,0,0,0,0,0,0,0,0,0,0,0,0,0,0,0,0,0
0,0,0,0,0,0,0,0,0,0,0,0,0,0,0,0,0,0,0,0,0
0,0,0,0,0,0,0,0,0,0,0,0,0,0,0,0,0,0,0,0,0
0,0,0,0,0,0,0,0,0,0,0,0,0,0,0,0,0,0,0,0,0
0,0,0,0,0,0,0,0,0,0,86,0,0,0,0,0,0,0,0,0,0
0,0,0,0,0,0,0,0,0,0,13,0,0,0,0,0,0,0,0,0,0
0,0,0,0,0,0,0,0,0,0,0,0,0,0,0,0,0,0,0,0,0
0,0,0,0,53,53,120,0,0,0,0,0,0,0,120,53,53,0,0,0,0
0,0,0,0,0,0,0,120,53,53,120,53,53,120,0,0,0,0,0,0,0
0,0,0,0,0,0,0,0,0,0,0,0,0,0,0,0,0,0,0,0,0
0,0,0,0,0,0,0,0,0,0,0,0,0,0,0,0,0,0,0,0,0
0,0,0,0,0,0,0,0,0,0,0,0,0,0,0,0,0,0,0,0,0
0,0,0,0,0,0,0,0,0,0,0,0,0,0,0,0,0,0,0,0,0
0,0,0,0,0,0,0,0,0,0,0,0,0,0,0,0,0,0,0,0,0
0,0,0,0,0,0,0,0,0,0,86,0,0,0,0,0,0,0,0,0,0
0,0,0,0,0,0,0,0,0,0,13,0,0,0,0,0,0,0,0,0,0
0,0,0,0,0,0,0,0,0,0,0,0,0,0,0,0,0,0,0,0,0
0,0,0,0,53,53,120,0,0,0,0,0,0,0,120,53,53,0,0,0,0
0,0,0,0,0,0,0,120,53,53,120,53,53,120,0,0,0,0,0,0,0
0,0,0,0,0,0,0,0,0,0,0,0,0,0,0,0,0,0,0,0,0
0,0,0,0,0,0,0,0,0,0,0,0,0,0,0,0,0,0,0,0,0
0,0,0,0,0,0,0,0,0,0,0,0,0,0,0,0,0,0,0,0,0
0,0,0,0,0,0,0,0,0,0,0,0,0,0,0,0,0,0,0,0,0
0,0,0,0,0,0,0,0,0,0,0,0,0,0,0,0,0,0,0,0,0
0,0,0,0,0,0,0,0,0,0,86,0,0,0,0,0,0,0,0,0,0
0,0,0,0,0,0,0,0,0,240,13,239,0,0,0,0,0,0,0,0,0
0,0,0,0,0,0,0,0,0,0,3,0,0,0,0,0,0,0,0,0,0
0,0,0,0,0,0,0,0,0,0,153,0,0,0,0,0,0,0,0,0,0
0,0,0,0,0,0,0,0,0,0,0,0,0,0,0,0,0,0,0,0,0
0,0,0,0,0,0,0,0,0,0,0,0,0,0,0,0,0,0,0,0,0
0,0,0,0,0,0,0,0,0,0,0,0,0,0,0,0,0,0,0,0,0
0,0,0,0,0,0,0,0,0,0,0,0,0,0,0,0,0,0,0,0,0
0,0,0,0,0,0,0,0,0,0,0,0,0,0,0,0,0,0,0,0,0
0,0,0,0,0,0,0,0,0,0,0,0,0,0,0,0,0,0,0,0,0
0,0,0,0,0,0,0,0,0,0,0,0,0,0,0,0,0,0,0,0,0
0,0,0,0,0,0,0,0,0,0,0,0,0,0,0,0,0,0,0,0,0
:endlayer
layer: 25
0,0,0,0,0,0,0,0,0,0,0,0,0,0,0,0,0,0,0,0,0
0,0,0,0,0,0,0,0,0,0,0,120,0,0,0,0,0,0,0,0,0
0,0,0,0,0,0,0,0,0,0,0,120,0,0,0,0,0,0,0,0,0
0,0,0,0,0,0,0,0,0,0,120,0,0,0,0,0,0,0,0,0,0
0,0,0,0,0,0,0,0,0,0,133,0,0,0,0,0,0,0,0,0,0
0,0,0,0,0,0,0,0,0,0,3,0,0,0,0,0,0,0,0,0,0
0,0,0,0,0,0,0,0,0,0,0,0,0,0,0,0,0,0,0,0,0
0,0,0,0,0,0,0,0,0,0,0,0,0,0,0,0,0,0,0,0,0
0,0,0,0,0,0,0,0,0,0,0,0,0,0,0,0,0,0,0,0,0
0,0,0,0,0,0,0,0,0,0,13,0,0,0,0,0,0,0,0,0,0
0,0,0,0,0,0,0,0,0,0,0,0,0,0,0,0,0,0,0,0,0
0,0,0,0,0,0,0,0,0,0,0,0,0,0,0,0,0,0,0,0,0
0,0,0,0,0,0,0,0,0,0,0,0,0,0,0,0,0,0,0,0,0
0,0,0,0,0,0,0,0,0,0,0,0,0,0,0,0,0,0,0,0,0
0,0,0,0,0,0,0,0,0,0,0,0,0,0,0,0,0,0,0,0,0
0,0,0,0,0,0,0,0,0,0,0,0,0,0,0,0,0,0,0,0,0
0,0,0,0,0,0,0,0,0,0,0,0,0,0,0,0,0,0,0,0,0
0,0,0,0,0,0,0,0,0,0,0,0,0,0,0,0,0,0,0,0,0
0,0,0,0,0,0,0,0,0,0,86,0,0,0,0,0,0,0,0,0,0
0,0,0,0,0,0,0,0,0,0,13,0,0,0,0,0,0,0,0,0,0
0,0,0,0,120,149,0,0,0,0,93,0,0,0,0,149,120,0,0,0,0
0,0,0,0,0,120,53,53,120,120,120,120,120,53,53,120,0,0,0,0,0
0,0,0,0,0,0,0,0,0,0,0,0,0,0,0,0,0,0,0,0,0
0,0,0,0,0,0,0,0,0,0,0,0,0,0,0,0,0,0,0,0,0
0,0,0,0,0,0,0,0,0,0,0,0,0,0,0,0,0,0,0,0,0
0,0,0,0,0,0,0,0,0,0,0,0,0,0,0,0,0,0,0,0,0
0,0,0,0,0,0,0,0,0,0,0,0,0,0,0,0,0,0,0,0,0
0,0,0,0,0,0,0,0,0,0,0,0,0,0,0,0,0,0,0,0,0
0,0,0,0,0,0,0,0,0,0,86,0,0,0,0,0,0,0,0,0,0
0,0,0,0,0,0,0,0,0,0,13,0,0,0,0,0,0,0,0,0,0
0,0,0,0,120,149,0,0,0,0,93,0,0,0,0,149,120,0,0,0,0
0,0,0,0,0,120,53,53,120,120,120,120,120,53,53,120,0,0,0,0,0
0,0,0,0,0,0,0,0,0,0,0,0,0,0,0,0,0,0,0,0,0
0,0,0,0,0,0,0,0,0,0,0,0,0,0,0,0,0,0,0,0,0
0,0,0,0,0,0,0,0,0,0,0,0,0,0,0,0,0,0,0,0,0
0,0,0,0,0,0,0,0,0,0,0,0,0,0,0,0,0,0,0,0,0
0,0,0,0,0,0,0,0,0,0,0,0,0,0,0,0,0,0,0,0,0
0,0,0,0,0,0,0,0,0,0,0,0,0,0,0,0,0,0,0,0,0
0,0,0,0,0,0,0,0,0,0,86,0,0,0,0,0,0,0,0,0,0
0,0,0,0,0,0,0,0,0,0,13,0,0,0,0,0,0,0,0,0,0
0,0,0,0,0,0,0,0,0,0,0,0,0,0,0,0,0,0,0,0,0
0,0,0,0,0,0,0,0,0,0,0,0,0,0,0,0,0,0,0,0,0
0,0,0,0,0,0,0,0,0,0,0,0,0,0,0,0,0,0,0,0,0
0,0,0,0,0,0,0,0,0,0,0,0,0,0,0,0,0,0,0,0,0
0,0,0,0,0,0,0,0,0,0,0,0,0,0,0,0,0,0,0,0,0
0,0,0,0,0,0,0,0,0,0,0,0,0,0,0,0,0,0,0,0,0
0,0,0,0,0,0,0,0,0,0,0,0,0,0,0,0,0,0,0,0,0
0,0,0,0,0,0,0,0,0,0,0,0,0,0,0,0,0,0,0,0,0
0,0,0,0,0,0,0,0,0,0,0,0,0,0,0,0,0,0,0,0,0
0,0,0,0,0,0,0,0,0,0,0,0,0,0,0,0,0,0,0,0,0
:endlayer
layer: 26
0,0,0,0,0,0,0,0,0,0,0,0,0,0,0,0,0,0,0,0,0
0,0,0,0,0,0,0,0,0,0,120,0,0,0,0,0,0,0,0,0,0
0,0,0,0,0,0,0,0,0,0,120,0,0,0,0,0,0,0,0,0,0
0,0,0,0,0,0,0,0,0,0,133,0,0,0,0,0,0,0,0,0,0
0,0,0,0,0,0,0,0,0,0,3,0,0,0,0,0,0,0,0,0,0
0,0,0,0,0,0,0,0,0,0,0,0,0,0,0,0,0,0,0,0,0
0,0,0,0,0,0,0,0,0,0,0,0,0,0,0,0,0,0,0,0,0
0,0,0,0,0,0,0,0,0,0,0,0,0,0,0,0,0,0,0,0,0
0,0,0,0,0,0,0,0,0,0,0,0,0,0,0,0,0,0,0,0,0
0,0,0,0,0,0,0,0,0,0,13,0,0,0,0,0,0,0,0,0,0
0,0,0,0,0,0,0,0,0,0,0,0,0,0,0,0,0,0,0,0,0
0,0,0,0,0,0,0,0,0,0,0,0,0,0,0,0,0,0,0,0,0
0,0,0,0,0,0,0,0,0,0,0,0,0,0,0,0,0,0,0,0,0
0,0,0,0,0,0,0,0,0,0,0,0,0,0,0,0,0,0,0,0,0
0,0,0,0,0,0,0,0,0,0,0,0,0,0,0,0,0,0,0,0,0
0,0,0,0,0,0,0,0,0,0,0,0,0,0,0,0,0,0,0,0,0
0,0,0,0,0,0,0,0,0,0,0,0,0,0,0,0,0,0,0,0,0
0,0,0,0,0,0,0,0,0,0,0,0,0,0,0,0,0,0,0,0,0
0,0,0,0,0,0,0,0,0,32,86,32,0,0,0,0,0,0,0,0,0
0,0,0,0,94,0,0,0,0,58,13,40,0,0,0,0,94,0,0,0,0
0,0,0,58,135,135,135,135,135,135,135,135,135,135,135,135,135,40,0,0,0
0,0,0,0,0,0,0,0,0,0,108,0,0,0,0,0,0,0,0,0,0
0,0,0,0,0,0,0,0,0,0,0,0,0,0,0,0,0,0,0,0,0
0,0,0,0,0,0,0,0,0,0,0,0,0,0,0,0,0,0,0,0,0
0,0,0,0,0,0,0,0,0,0,0,0,0,0,0,0,0,0,0,0,0
0,0,0,0,0,0,0,0,0,0,0,0,0,0,0,0,0,0,0,0,0
0,0,0,0,0,0,0,0,0,0,0,0,0,0,0,0,0,0,0,0,0
0,0,0,0,0,0,0,0,0,0,0,0,0,0,0,0,0,0,0,0,0
0,0,0,0,0,0,0,0,0,32,86,32,0,0,0,0,0,0,0,0,0
0,0,0,0,94,0,0,0,0,58,13,40,0,0,0,0,94,0,0,0,0
0,0,0,58,135,135,135,135,135,135,135,135,135,135,135,135,135,40,0,0,0
0,0,0,0,0,0,0,0,0,0,108,0,0,0,0,0,0,0,0,0,0
0,0,0,0,0,0,0,0,0,0,0,0,0,0,0,0,0,0,0,0,0
0,0,0,0,0,0,0,0,0,0,0,0,0,0,0,0,0,0,0,0,0
0,0,0,0,0,0,0,0,0,0,0,0,0,0,0,0,0,0,0,0,0
0,0,0,0,0,0,0,0,0,0,0,0,0,0,0,0,0,0,0,0,0
0,0,0,0,0,0,0,0,0,0,0,0,0,0,0,0,0,0,0,0,0
0,0,0,0,0,0,0,0,0,0,0,0,0,0,0,0,0,0,0,0,0
0,0,0,0,0,0,0,0,0,0,86,0,0,0,0,0,0,0,0,0,0
0,0,0,0,0,0,0,0,0,0,13,0,0,0,0,0,0,0,0,0,0
0,0,0,0,0,0,0,0,0,0,0,0,0,0,0,0,0,0,0,0,0
0,0,0,0,0,0,0,0,0,0,0,0,0,0,0,0,0,0,0,0,0
0,0,0,0,0,0,0,0,0,0,0,0,0,0,0,0,0,0,0,0,0
0,0,0,0,0,0,0,0,0,0,0,0,0,0,0,0,0,0,0,0,0
0,0,0,0,0,0,0,0,0,0,0,0,0,0,0,0,0,0,0,0,0
0,0,0,0,0,0,0,0,0,0,0,0,0,0,0,0,0,0,0,0,0
0,0,0,0,0,0,0,0,0,0,0,0,0,0,0,0,0,0,0,0,0
0,0,0,0,0,0,0,0,0,0,0,0,0,0,0,0,0,0,0,0,0
0,0,0,0,0,0,0,0,0,0,0,0,0,0,0,0,0,0,0,0,0
0,0,0,0,0,0,0,0,0,0,0,0,0,0,0,0,0,0,0,0,0
:endlayer
layer: 27
0,0,0,0,0,0,0,0,0,0,0,0,0,0,0,0,0,0,0,0,0
0,0,0,0,0,0,0,0,0,0,154,0,0,0,0,0,0,0,0,0,0
0,0,0,0,0,0,0,0,0,0,133,0,0,0,0,0,0,0,0,0,0
0,0,0,0,0,0,0,0,0,0,3,0,0,0,0,0,0,0,0,0,0
0,0,0,0,0,0,0,0,0,0,0,0,0,0,0,0,0,0,0,0,0
0,0,0,0,0,0,0,0,0,0,0,0,0,0,0,0,0,0,0,0,0
0,0,0,0,0,0,0,0,0,0,0,0,0,0,0,0,0,0,0,0,0
0,0,0,0,0,0,0,0,0,0,0,0,0,0,0,0,0,0,0,0,0
0,0,0,0,0,0,0,0,0,0,0,0,0,0,0,0,0,0,0,0,0
0,0,0,0,0,0,0,0,0,0,33,0,0,0,0,0,0,0,0,0,0
0,0,0,0,0,0,0,0,0,0,0,0,0,0,0,0,0,0,0,0,0
0,0,0,0,0,0,0,0,0,0,0,0,0,0,0,0,0,0,0,0,0
0,0,0,0,0,0,0,0,0,0,0,0,0,0,0,0,0,0,0,0,0
0,0,0,0,0,0,0,0,0,0,0,0,0,0,0,0,0,0,0,0,0
0,0,0,0,0,0,0,0,0,0,0,0,0,0,0,0,0,0,0,0,0
0,0,0,0,0,0,0,0,0,0,0,0,0,0,0,0,0,0,0,0,0
0,0,0,0,0,0,0,0,0,0,0,0,0,0,0,0,0,0,0,0,0
0,0,0,0,0,0,0,0,0,0,0,0,0,0,0,0,0,0,0,0,0
0,0,0,0,0,0,0,0,0,0,86,0,0,0,0,0,0,0,0,0,0
0,0,0,0,0,0,0,0,0,243,13,241,0,0,0,0,0,0,0,0,0
0,0,0,0,0,0,0,0,0,0,3,0,0,0,0,0,0,0,0,0,0
0,0,0,0,0,0,0,0,0,0,153,0,0,0,0,0,0,0,0,0,0
0,0,0,0,0,0,0,0,0,0,0,0,0,0,0,0,0,0,0,0,0
0,0,0,0,0,0,0,0,0,0,0,0,0,0,0,0,0,0,0,0,0
0,0,0,0,0,0,0,0,0,0,0,0,0,0,0,0,0,0,0,0,0
0,0,0,0,0,0,0,0,0,0,0,0,0,0,0,0,0,0,0,0,0
0,0,0,0,0,0,0,0,0,0,0,0,0,0,0,0,0,0,0,0,0
0,0,0,0,0,0,0,0,0,0,0,0,0,0,0,0,0,0,0,0,0
0,0,0,0,0,0,0,0,0,0,86,0,0,0,0,0,0,0,0,0,0
0,0,0,0,0,0,0,0,0,244,13,242,0,0,0,0,0,0,0,0,0
0,0,0,0,0,0,0,0,0,0,3,0,0,0,0,0,0,0,0,0,0
0,0,0,0,0,0,0,0,0,0,153,0,0,0,0,0,0,0,0,0,0
0,0,0,0,0,0,0,0,0,0,0,0,0,0,0,0,0,0,0,0,0
0,0,0,0,0,0,0,0,0,0,0,0,0,0,0,0,0,0,0,0,0
0,0,0,0,0,0,0,0,0,0,0,0,0,0,0,0,0,0,0,0,0
0,0,0,0,0,0,0,0,0,0,0,0,0,0,0,0,0,0,0,0,0
0,0,0,0,0,0,0,0,0,0,0,0,0,0,0,0,0,0,0,0,0
0,0,0,0,0,0,0,0,0,0,0,0,0,0,0,0,0,0,0,0,0
0,0,0,0,0,0,0,0,0,0,0,0,0,0,0,0,0,0,0,0,0
0,0,0,0,0,0,0,0,0,0,33,0,0,0,0,0,0,0,0,0,0
0,0,0,0,0,0,0,0,0,0,0,0,0,0,0,0,0,0,0,0,0
0,0,0,0,0,0,0,0,0,0,0,0,0,0,0,0,0,0,0,0,0
0,0,0,0,0,0,0,0,0,0,0,0,0,0,0,0,0,0,0,0,0
0,0,0,0,0,0,0,0,0,0,0,0,0,0,0,0,0,0,0,0,0
0,0,0,0,0,0,0,0,0,0,0,0,0,0,0,0,0,0,0,0,0
0,0,0,0,0,0,0,0,0,0,0,0,0,0,0,0,0,0,0,0,0
0,0,0,0,0,0,0,0,0,0,0,0,0,0,0,0,0,0,0,0,0
0,0,0,0,0,0,0,0,0,0,0,0,0,0,0,0,0,0,0,0,0
0,0,0,0,0,0,0,0,0,0,0,0,0,0,0,0,0,0,0,0,0
0,0,0,0,0,0,0,0,0,0,0,0,0,0,0,0,0,0,0,0,0
:endlayer
layer: 28
0,0,0,0,0,0,0,0,0,0,0,0,0,0,0,0,0,0,0,0,0
0,0,0,0,0,0,0,0,0,0,0,0,0,0,0,0,0,0,0,0,0
0,0,0,0,0,0,0,0,0,0,148,0,0,0,0,0,0,0,0,0,0
0,0,0,0,0,0,0,0,0,0,0,0,0,0,0,0,0,0,0,0,0
0,0,0,0,0,0,0,0,0,0,0,0,0,0,0,0,0,0,0,0,0
0,0,0,0,0,0,0,0,0,0,120,0,0,0,0,0,0,0,0,0,0
0,0,0,0,0,0,0,0,0,0,120,0,0,0,0,0,0,0,0,0,0
0,0,0,0,0,0,0,0,0,0,120,0,0,0,0,0,0,0,0,0,0
0,0,0,0,0,0,0,0,0,0,120,0,0,0,0,0,0,0,0,0,0
0,0,0,0,0,0,0,0,0,0,33,0,0,0,0,0,0,0,0,0,0
0,0,0,0,0,0,0,0,0,0,0,0,0,0,0,0,0,0,0,0,0
0,0,0,0,0,0,0,0,0,0,0,0,0,0,0,0,0,0,0,0,0
0,0,0,0,0,0,0,0,0,0,0,0,0,0,0,0,0,0,0,0,0
0,0,0,0,0,0,0,0,0,0,0,0,0,0,0,0,0,0,0,0,0
0,0,0,0,0,0,0,0,0,0,0,0,0,0,0,0,0,0,0,0,0
0,0,0,0,0,0,0,0,0,0,0,0,0,0,0,0,0,0,0,0,0
0,0,0,0,0,0,0,0,0,0,0,0,0,0,0,0,0,0,0,0,0
0,0,0,0,0,0,0,0,0,0,0,0,0,0,0,0,0,0,0,0,0
0,0,0,0,0,0,0,0,0,0,86,0,0,0,0,0,0,0,0,0,0
0,0,0,0,0,0,0,0,0,0,13,0,0,0,0,0,0,0,0,0,0
0,0,0,0,0,0,0,0,0,0,0,0,0,0,0,0,0,0,0,0,0
0,0,0,0,0,0,0,0,0,0,0,0,0,0,0,0,0,0,0,0,0
0,0,0,0,0,0,0,0,0,0,0,0,0,0,0,0,0,0,0,0,0
0,0,0,0,0,0,0,0,0,0,0,0,0,0,0,0,0,0,0,0,0
0,0,0,0,0,0,0,0,0,0,0,0,0,0,0,0,0,0,0,0,0
0,0,0,0,0,0,0,0,0,0,0,0,0,0,0,0,0,0,0,0,0
0,0,0,0,0,0,0,0,0,0,0,0,0,0,0,0,0,0,0,0,0
0,0,0,0,0,0,0,0,0,0,0,0,0,0,0,0,0,0,0,0,0
0,0,0,0,0,0,0,0,0,0,86,0,0,0,0,0,0,0,0,0,0
0,0,0,0,0,0,0,0,0,0,13,0,0,0,0,0,0,0,0,0,0
0,0,0,0,0,0,0,0,0,0,0,0,0,0,0,0,0,0,0,0,0
0,0,0,0,0,0,0,0,0,0,0,0,0,0,0,0,0,0,0,0,0
0,0,0,0,0,0,0,0,0,0,0,0,0,0,0,0,0,0,0,0,0
0,0,0,0,0,0,0,0,0,0,0,0,0,0,0,0,0,0,0,0,0
0,0,0,0,0,0,0,0,0,0,0,0,0,0,0,0,0,0,0,0,0
0,0,0,0,0,0,0,0,0,0,120,0,0,0,0,0,0,0,0,0,0
0,0,0,0,0,0,0,0,0,0,120,0,0,0,0,0,0,0,0,0,0
0,0,0,0,0,0,0,0,0,0,120,0,0,0,0,0,0,0,0,0,0
0,0,0,0,0,0,0,0,0,0,120,0,0,0,0,0,0,0,0,0,0
0,0,0,0,0,0,0,0,0,0,33,0,0,0,0,0,0,0,0,0,0
0,0,0,0,0,0,0,0,0,0,0,0,0,0,0,0,0,0,0,0,0
0,0,0,0,0,0,0,0,0,0,0,0,0,0,0,0,0,0,0,0,0
0,0,0,0,0,0,0,0,0,0,0,0,0,0,0,0,0,0,0,0,0
0,0,0,0,0,0,0,0,0,0,0,0,0,0,0,0,0,0,0,0,0
0,0,0,0,0,0,0,0,0,0,0,0,0,0,0,0,0,0,0,0,0
0,0,0,0,0,0,0,0,0,0,0,0,0,0,0,0,0,0,0,0,0
0,0,0,0,0,0,0,0,0,0,0,0,0,0,0,0,0,0,0,0,0
0,0,0,0,0,0,0,0,0,0,0,0,0,0,0,0,0,0,0,0,0
0,0,0,0,0,0,0,0,0,0,0,0,0,0,0,0,0,0,0,0,0
0,0,0,0,0,0,0,0,0,0,0,0,0,0,0,0,0,0,0,0,0
:endlayer
layer: 29
0,0,0,0,0,0,0,0,0,0,0,0,0,0,0,0,0,0,0,0,0
0,0,0,0,0,0,0,0,0,0,0,0,0,0,0,0,0,0,0,0,0
0,0,0,0,0,0,0,0,0,0,0,0,0,0,0,0,0,0,0,0,0
0,0,0,0,0,0,0,0,0,0,0,0,0,0,0,0,0,0,0,0,0
0,0,0,0,0,0,0,0,0,0,0,0,0,0,0,0,0,0,0,0,0
0,0,0,0,0,0,0,0,0,0,0,0,0,0,0,0,0,0,0,0,0
0,0,0,0,0,0,0,0,0,0,0,0,0,0,0,0,0,0,0,0,0
0,0,0,0,0,0,0,0,0,0,120,0,0,0,0,0,0,0,0,0,0
0,0,0,0,0,0,0,0,0,0,120,0,0,0,0,0,0,0,0,0,0
0,0,0,0,0,0,0,0,0,0,33,0,0,0,0,0,0,0,0,0,0
0,0,0,0,0,0,0,0,0,0,0,0,0,0,0,0,0,0,0,0,0
0,0,0,0,0,0,0,0,0,0,0,0,0,0,0,0,0,0,0,0,0
0,0,0,0,0,0,0,0,0,0,0,0,0,0,0,0,0,0,0,0,0
0,0,0,0,0,0,0,0,0,0,0,0,0,0,0,0,0,0,0,0,0
0,0,0,0,0,0,0,0,0,0,0,0,0,0,0,0,0,0,0,0,0
0,0,0,0,0,0,0,0,0,0,0,0,0,0,0,0,0,0,0,0,0
0,0,0,0,0,0,0,0,0,0,0,0,0,0,0,0,0,0,0,0,0
0,0,0,0,0,0,0,0,0,0,0,0,0,0,0,0,0,0,0,0,0
0,0,0,0,0,0,0,0,0,0,0,0,0,0,0,0,0,0,0,0,0
0,0,0,0,0,0,0,0,0,0,33,0,0,0,0,0,0,0,0,0,0
0,0,0,0,0,0,0,0,0,0,0,0,0,0,0,0,0,0,0,0,0
0,0,0,0,0,0,0,0,0,0,0,0,0,0,0,0,0,0,0,0,0
0,0,0,0,0,0,0,0,0,0,0,0,0,0,0,0,0,0,0,0,0
0,0,0,0,0,0,0,0,0,0,0,0,0,0,0,0,0,0,0,0,0
0,0,0,0,0,0,0,0,0,0,0,0,0,0,0,0,0,0,0,0,0
0,0,0,0,0,0,0,0,0,0,0,0,0,0,0,0,0,0,0,0,0
0,0,0,0,0,0,0,0,0,0,0,0,0,0,0,0,0,0,0,0,0
0,0,0,0,0,0,0,0,0,0,0,0,0,0,0,0,0,0,0,0,0
0,0,0,0,0,0,0,0,0,0,0,0,0,0,0,0,0,0,0,0,0
0,0,0,0,0,0,0,0,0,0,33,0,0,0,0,0,0,0,0,0,0
0,0,0,0,0,0,0,0,0,0,0,0,0,0,0,0,0,0,0,0,0
0,0,0,0,0,0,0,0,0,0,0,0,0,0,0,0,0,0,0,0,0
0,0,0,0,0,0,0,0,0,0,0,0,0,0,0,0,0,0,0,0,0
0,0,0,0,0,0,0,0,0,0,0,0,0,0,0,0,0,0,0,0,0
0,0,0,0,0,0,0,0,0,0,0,0,0,0,0,0,0,0,0,0,0
0,0,0,0,0,0,0,0,0,0,0,0,0,0,0,0,0,0,0,0,0
0,0,0,0,0,0,0,0,0,0,0,0,0,0,0,0,0,0,0,0,0
0,0,0,0,0,0,0,0,0,0,120,0,0,0,0,0,0,0,0,0,0
0,0,0,0,0,0,0,0,0,0,120,0,0,0,0,0,0,0,0,0,0
0,0,0,0,0,0,0,0,0,0,33,0,0,0,0,0,0,0,0,0,0
0,0,0,0,0,0,0,0,0,0,0,0,0,0,0,0,0,0,0,0,0
0,0,0,0,0,0,0,0,0,0,0,0,0,0,0,0,0,0,0,0,0
0,0,0,0,0,0,0,0,0,0,0,0,0,0,0,0,0,0,0,0,0
0,0,0,0,0,0,0,0,0,0,0,0,0,0,0,0,0,0,0,0,0
0,0,0,0,0,0,0,0,0,0,0,0,0,0,0,0,0,0,0,0,0
0,0,0,0,0,0,0,0,0,0,0,0,0,0,0,0,0,0,0,0,0
0,0,0,0,0,0,0,0,0,0,0,0,0,0,0,0,0,0,0,0,0
0,0,0,0,0,0,0,0,0,0,0,0,0,0,0,0,0,0,0,0,0
0,0,0,0,0,0,0,0,0,0,0,0,0,0,0,0,0,0,0,0,0
0,0,0,0,0,0,0,0,0,0,0,0,0,0,0,0,0,0,0,0,0
:endlayer
layer: 30
0,0,0,0,0,0,0,0,0,0,0,0,0,0,0,0,0,0,0,0,0
0,0,0,0,0,0,0,0,0,0,0,0,0,0,0,0,0,0,0,0,0
0,0,0,0,0,0,0,0,0,0,0,0,0,0,0,0,0,0,0,0,0
0,0,0,0,0,0,0,0,0,0,0,0,0,0,0,0,0,0,0,0,0
0,0,0,0,0,0,0,0,0,0,0,0,0,0,0,0,0,0,0,0,0
0,0,0,0,0,0,0,0,0,0,0,0,0,0,0,0,0,0,0,0,0
0,0,0,0,0,0,0,0,0,0,0,0,0,0,0,0,0,0,0,0,0
0,0,0,0,0,0,0,0,0,0,0,0,0,0,0,0,0,0,0,0,0
0,0,0,0,0,0,0,0,0,0,0,0,0,0,0,0,0,0,0,0,0
0,0,0,0,0,0,0,0,0,0,148,0,0,0,0,0,0,0,0,0,0
0,0,0,0,0,0,0,0,0,0,0,0,0,0,0,0,0,0,0,0,0
0,0,0,0,0,0,0,0,0,0,0,0,0,0,0,0,0,0,0,0,0
0,0,0,0,0,0,0,0,0,0,0,0,0,0,0,0,0,0,0,0,0
0,0,0,0,0,0,0,0,0,0,0,0,0,0,0,0,0,0,0,0,0
0,0,0,0,0,0,0,0,0,0,0,0,0,0,0,0,0,0,0,0,0
0,0,0,0,0,0,0,0,0,0,120,0,0,0,0,0,0,0,0,0,0
0,0,0,0,0,0,0,0,0,0,120,0,0,0,0,0,0,0,0,0,0
0,0,0,0,0,0,0,0,0,0,120,0,0,0,0,0,0,0,0,0,0
0,0,0,0,0,0,0,0,0,0,120,0,0,0,0,0,0,0,0,0,0
0,0,0,0,0,0,0,0,0,0,33,0,0,0,0,0,0,0,0,0,0
0,0,0,0,0,0,0,0,0,0,0,0,0,0,0,0,0,0,0,0,0
0,0,0,0,0,0,0,0,0,0,0,0,0,0,0,0,0,0,0,0,0
0,0,0,0,0,0,0,0,0,0,0,0,0,0,0,0,0,0,0,0,0
0,0,0,0,0,0,0,0,0,0,0,0,0,0,0,0,0,0,0,0,0
0,0,0,0,0,0,0,0,0,0,0,0,0,0,0,0,0,0,0,0,0
0,0,0,0,0,0,0,0,0,0,0,0,0,0,0,0,0,0,0,0,0
0,0,0,0,0,0,0,0,0,0,0,0,0,0,0,0,0,0,0,0,0
0,0,0,0,0,0,0,0,0,0,120,0,0,0,0,0,0,0,0,0,0
0,0,0,0,0,0,0,0,0,0,120,0,0,0,0,0,0,0,0,0,0
0,0,0,0,0,0,0,0,0,0,33,0,0,0,0,0,0,0,0,0,0
0,0,0,0,0,0,0,0,0,0,0,0,0,0,0,0,0,0,0,0,0
0,0,0,0,0,0,0,0,0,0,0,0,0,0,0,0,0,0,0,0,0
0,0,0,0,0,0,0,0,0,0,0,0,0,0,0,0,0,0,0,0,0
0,0,0,0,0,0,0,0,0,0,0,0,0,0,0,0,0,0,0,0,0
0,0,0,0,0,0,0,0,0,0,0,0,0,0,0,0,0,0,0,0,0
0,0,0,0,0,0,0,0,0,0,0,0,0,0,0,0,0,0,0,0,0
0,0,0,0,0,0,0,0,0,0,0,0,0,0,0,0,0,0,0,0,0
0,0,0,0,0,0,0,0,0,0,0,0,0,0,0,0,0,0,0,0,0
0,0,0,0,0,0,0,0,0,0,0,0,0,0,0,0,0,0,0,0,0
0,0,0,0,0,0,0,0,0,0,148,0,0,0,0,0,0,0,0,0,0
0,0,0,0,0,0,0,0,0,0,0,0,0,0,0,0,0,0,0,0,0
0,0,0,0,0,0,0,0,0,0,0,0,0,0,0,0,0,0,0,0,0
0,0,0,0,0,0,0,0,0,0,0,0,0,0,0,0,0,0,0,0,0
0,0,0,0,0,0,0,0,0,0,0,0,0,0,0,0,0,0,0,0,0
0,0,0,0,0,0,0,0,0,0,0,0,0,0,0,0,0,0,0,0,0
0,0,0,0,0,0,0,0,0,0,0,0,0,0,0,0,0,0,0,0,0
0,0,0,0,0,0,0,0,0,0,0,0,0,0,0,0,0,0,0,0,0
0,0,0,0,0,0,0,0,0,0,0,0,0,0,0,0,0,0,0,0,0
0,0,0,0,0,0,0,0,0,0,0,0,0,0,0,0,0,0,0,0,0
0,0,0,0,0,0,0,0,0,0,0,0,0,0,0,0,0,0,0,0,0
:endlayer
layer: 31
0,0,0,0,0,0,0,0,0,0,0,0,0,0,0,0,0,0,0,0,0
0,0,0,0,0,0,0,0,0,0,0,0,0,0,0,0,0,0,0,0,0
0,0,0,0,0,0,0,0,0,0,0,0,0,0,0,0,0,0,0,0,0
0,0,0,0,0,0,0,0,0,0,0,0,0,0,0,0,0,0,0,0,0
0,0,0,0,0,0,0,0,0,0,0,0,0,0,0,0,0,0,0,0,0
0,0,0,0,0,0,0,0,0,0,0,0,0,0,0,0,0,0,0,0,0
0,0,0,0,0,0,0,0,0,0,0,0,0,0,0,0,0,0,0,0,0
0,0,0,0,0,0,0,0,0,0,0,0,0,0,0,0,0,0,0,0,0
0,0,0,0,0,0,0,0,0,0,0,0,0,0,0,0,0,0,0,0,0
0,0,0,0,0,0,0,0,0,0,0,0,0,0,0,0,0,0,0,0,0
0,0,0,0,0,0,0,0,0,0,0,0,0,0,0,0,0,0,0,0,0
0,0,0,0,0,0,0,0,0,0,0,0,0,0,0,0,0,0,0,0,0
0,0,0,0,0,0,0,0,0,0,0,0,0,0,0,0,0,0,0,0,0
0,0,0,0,0,0,0,0,0,0,0,0,0,0,0,0,0,0,0,0,0
0,0,0,0,0,0,0,0,0,0,0,0,0,0,0,0,0,0,0,0,0
0,0,0,0,0,0,0,0,0,0,0,0,0,0,0,0,0,0,0,0,0
0,0,0,0,0,0,0,0,0,0,0,0,0,0,0,0,0,0,0,0,0
0,0,0,0,0,0,0,0,0,0,120,0,0,0,0,0,0,0,0,0,0
0,0,0,0,0,0,0,0,0,0,120,0,0,0,0,0,0,0,0,0,0
0,0,0,0,0,0,0,0,0,0,33,0,0,0,0,0,0,0,0,0,0
0,0,0,0,0,0,0,0,0,0,0,0,0,0,0,0,0,0,0,0,0
0,0,0,0,0,0,0,0,0,0,0,0,0,0,0,0,0,0,0,0,0
0,0,0,0,0,0,0,0,0,0,0,0,0,0,0,0,0,0,0,0,0
0,0,0,0,0,0,0,0,0,0,0,0,0,0,0,0,0,0,0,0,0
0,0,0,0,0,0,0,0,0,0,0,0,0,0,0,0,0,0,0,0,0
0,0,0,0,0,0,0,0,0,0,120,0,0,0,0,0,0,0,0,0,0
0,0,0,0,0,0,0,0,0,0,120,0,0,0,0,0,0,0,0,0,0
0,0,0,0,0,0,0,0,0,0,120,0,0,0,0,0,0,0,0,0,0
0,0,0,0,0,0,0,0,0,0,120,0,0,0,0,0,0,0,0,0,0
0,0,0,0,0,0,0,0,0,0,33,0,0,0,0,0,0,0,0,0,0
0,0,0,0,0,0,0,0,0,0,0,0,0,0,0,0,0,0,0,0,0
0,0,0,0,0,0,0,0,0,0,0,0,0,0,0,0,0,0,0,0,0
0,0,0,0,0,0,0,0,0,0,0,0,0,0,0,0,0,0,0,0,0
0,0,0,0,0,0,0,0,0,0,0,0,0,0,0,0,0,0,0,0,0
0,0,0,0,0,0,0,0,0,0,0,0,0,0,0,0,0,0,0,0,0
0,0,0,0,0,0,0,0,0,0,0,0,0,0,0,0,0,0,0,0,0
0,0,0,0,0,0,0,0,0,0,0,0,0,0,0,0,0,0,0,0,0
0,0,0,0,0,0,0,0,0,0,0,0,0,0,0,0,0,0,0,0,0
0,0,0,0,0,0,0,0,0,0,0,0,0,0,0,0,0,0,0,0,0
0,0,0,0,0,0,0,0,0,0,0,0,0,0,0,0,0,0,0,0,0
0,0,0,0,0,0,0,0,0,0,0,0,0,0,0,0,0,0,0,0,0
0,0,0,0,0,0,0,0,0,0,0,0,0,0,0,0,0,0,0,0,0
0,0,0,0,0,0,0,0,0,0,0,0,0,0,0,0,0,0,0,0,0
0,0,0,0,0,0,0,0,0,0,0,0,0,0,0,0,0,0,0,0,0
0,0,0,0,0,0,0,0,0,0,0,0,0,0,0,0,0,0,0,0,0
0,0,0,0,0,0,0,0,0,0,0,0,0,0,0,0,0,0,0,0,0
0,0,0,0,0,0,0,0,0,0,0,0,0,0,0,0,0,0,0,0,0
0,0,0,0,0,0,0,0,0,0,0,0,0,0,0,0,0,0,0,0,0
0,0,0,0,0,0,0,0,0,0,0,0,0,0,0,0,0,0,0,0,0
0,0,0,0,0,0,0,0,0,0,0,0,0,0,0,0,0,0,0,0,0
:endlayer
layer: 32
0,0,0,0,0,0,0,0,0,0,0,0,0,0,0,0,0,0,0,0,0
0,0,0,0,0,0,0,0,0,0,0,0,0,0,0,0,0,0,0,0,0
0,0,0,0,0,0,0,0,0,0,0,0,0,0,0,0,0,0,0,0,0
0,0,0,0,0,0,0,0,0,0,0,0,0,0,0,0,0,0,0,0,0
0,0,0,0,0,0,0,0,0,0,0,0,0,0,0,0,0,0,0,0,0
0,0,0,0,0,0,0,0,0,0,0,0,0,0,0,0,0,0,0,0,0
0,0,0,0,0,0,0,0,0,0,0,0,0,0,0,0,0,0,0,0,0
0,0,0,0,0,0,0,0,0,0,0,0,0,0,0,0,0,0,0,0,0
0,0,0,0,0,0,0,0,0,0,0,0,0,0,0,0,0,0,0,0,0
0,0,0,0,0,0,0,0,0,0,0,0,0,0,0,0,0,0,0,0,0
0,0,0,0,0,0,0,0,0,0,0,0,0,0,0,0,0,0,0,0,0
0,0,0,0,0,0,0,0,0,0,0,0,0,0,0,0,0,0,0,0,0
0,0,0,0,0,0,0,0,0,0,0,0,0,0,0,0,0,0,0,0,0
0,0,0,0,0,0,0,0,0,0,0,0,0,0,0,0,0,0,0,0,0
0,0,0,0,0,0,0,0,0,0,0,0,0,0,0,0,0,0,0,0,0
0,0,0,0,0,0,0,0,0,0,0,0,0,0,0,0,0,0,0,0,0
0,0,0,0,0,0,0,0,0,0,0,0,0,0,0,0,0,0,0,0,0
0,0,0,0,0,0,0,0,0,0,0,0,0,0,0,0,0,0,0,0,0
0,0,0,0,0,0,0,0,0,0,0,0,0,0,0,0,0,0,0,0,0
0,0,0,0,0,0,0,0,0,0,148,0,0,0,0,0,0,0,0,0,0
0,0,0,0,0,0,0,0,0,0,0,0,0,0,0,0,0,0,0,0,0
0,0,0,0,0,0,0,0,0,0,0,0,0,0,0,0,0,0,0,0,0
0,0,0,0,0,0,0,0,0,0,0,0,0,0,0,0,0,0,0,0,0
0,0,0,0,0,0,0,0,0,0,0,0,0,0,0,0,0,0,0,0,0
0,0,0,0,0,0,0,0,0,0,0,0,0,0,0,0,0,0,0,0,0
0,0,0,0,0,0,0,0,0,0,0,0,0,0,0,0,0,0,0,0,0
0,0,0,0,0,0,0,0,0,0,0,0,0,0,0,0,0,0,0,0,0
0,0,0,0,0,0,0,0,0,0,0,0,0,0,0,0,0,0,0,0,0
0,0,0,0,0,0,0,0,0,0,0,0,0,0,0,0,0,0,0,0,0
0,0,0,0,0,0,0,0,0,0,148,0,0,0,0,0,0,0,0,0,0
0,0,0,0,0,0,0,0,0,0,0,0,0,0,0,0,0,0,0,0,0
0,0,0,0,0,0,0,0,0,0,0,0,0,0,0,0,0,0,0,0,0
0,0,0,0,0,0,0,0,0,0,0,0,0,0,0,0,0,0,0,0,0
0,0,0,0,0,0,0,0,0,0,0,0,0,0,0,0,0,0,0,0,0
0,0,0,0,0,0,0,0,0,0,0,0,0,0,0,0,0,0,0,0,0
0,0,0,0,0,0,0,0,0,0,0,0,0,0,0,0,0,0,0,0,0
0,0,0,0,0,0,0,0,0,0,0,0,0,0,0,0,0,0,0,0,0
0,0,0,0,0,0,0,0,0,0,0,0,0,0,0,0,0,0,0,0,0
0,0,0,0,0,0,0,0,0,0,0,0,0,0,0,0,0,0,0,0,0
0,0,0,0,0,0,0,0,0,0,0,0,0,0,0,0,0,0,0,0,0
0,0,0,0,0,0,0,0,0,0,0,0,0,0,0,0,0,0,0,0,0
0,0,0,0,0,0,0,0,0,0,0,0,0,0,0,0,0,0,0,0,0
0,0,0,0,0,0,0,0,0,0,0,0,0,0,0,0,0,0,0,0,0
0,0,0,0,0,0,0,0,0,0,0,0,0,0,0,0,0,0,0,0,0
0,0,0,0,0,0,0,0,0,0,0,0,0,0,0,0,0,0,0,0,0
0,0,0,0,0,0,0,0,0,0,0,0,0,0,0,0,0,0,0,0,0
0,0,0,0,0,0,0,0,0,0,0,0,0,0,0,0,0,0,0,0,0
0,0,0,0,0,0,0,0,0,0,0,0,0,0,0,0,0,0,0,0,0
0,0,0,0,0,0,0,0,0,0,0,0,0,0,0,0,0,0,0,0,0
0,0,0,0,0,0,0,0,0,0,0,0,0,0,0,0,0,0,0,0,0
:endlayer

#### RULES ####
rule:
plugin=fluid
number=1
data:
JSON:{blockState:{blockName:"minecraft:water",properties:{level:"0"}}}
:enddata
:endrule

rule:
plugin=vanillaBlocks
number=2
data:
JSON:{blockState:{blockName:"minecraft:planks",properties:{variant:"birch"}}}
:enddata
:endrule

rule:
plugin=vanillaBlocks
number=3
data:
JSON:{blockState:{blockName:"minecraft:birch_stairs",properties:{half:"bottom",shape:"straight",facing:"north"}}}
:enddata
:endrule

rule:
plugin=vanillaBlocks
number=4
data:
JSON:{blockState:{blockName:"minecraft:stone",properties:{variant:"smooth_andesite"}}}
:enddata
:endrule

rule:
plugin=blockTile
number=5
data:
JSON:{blockState:{blockName:"ancientwarfarestructure:advanced_loot_chest",properties:{facing:"west"}},teData:{lootSettings:{lootRolls:1,splashPotion:0b,hasMessage:0b,hasLoot:1b,lootTableName:"ancientwarfare:chests/citizen_low_value",spawnEntity:0b,entity:"minecraft:"},Items:[],id:"ancientwarfarestructure:advanced_loot_chest_tile",Lock:""}}
:enddata
:endrule

rule:
plugin=blockTile
number=6
data:
JSON:{blockState:{blockName:"ancientwarfarestructure:advanced_loot_chest",properties:{facing:"west"}},teData:{lootSettings:{lootRolls:1,splashPotion:0b,hasMessage:0b,hasLoot:1b,lootTableName:"ancientwarfare:chests/citizen_low_value",spawnEntity:0b,entity:"minecraft:"},Items:[],id:"ancientwarfarestructure:advanced_loot_chest_tile",Lock:""}}
:enddata
:endrule

rule:
plugin=bed
number=7
data:
JSON:{blockState:{blockName:"minecraft:bed",properties:{part:"foot",facing:"south",occupied:"false"}},bedColor:9}
:enddata
:endrule

rule:
plugin=bed
number=8
data:
JSON:{blockState:{blockName:"minecraft:bed",properties:{part:"head",facing:"south",occupied:"false"}},bedColor:9}
:enddata
:endrule

rule:
plugin=doors
number=9
data:
JSON:{blockState:{blockName:"minecraft:birch_door",properties:{hinge:"left",half:"lower",powered:"false",facing:"north",open:"false"}}}
:enddata
:endrule

rule:
plugin=blockTile
number=10
data:
JSON:{blockState:{blockName:"ancientwarfarestructure:advanced_spawner",properties:{transparent:"true"}},teData:{id:"ancientwarfarestructure:advanced_spawner_tile",spawnerSettings:{minDelay:10,spawnDelay:10,lightSensitive:0b,spawnGroups:[{settingsList:[{remainingSpawnCount:1,hostile:1b,customTag:{ArmorDropChances:[0.085f,0.085f,0.085f,0.085f],CustomName:"Nogg Soldier",hasCustomEquipment:0b,ArmorItems:[{},{},{},{}],skinSettings:{npcTypeName:"custom",skinTypeSelected:"default"},HandDropChances:[0.085f,0.085f],factionName:"nogg",HandItems:[{id:"ancientwarfarenpc:iron_halberd",Count:1b,Damage:0s},{}]},maxToSpawn:1,entityId:"ancientwarfarenpc:faction.soldier",minToSpawn:1}],groupWeight:1}],playerRange:16,respondToRedstone:0b,inventory:{Size:9,Items:[]},spawnRange:0,transparent:1b,maxDelay:10,spawnYOffset:0,xpToDrop:0,mobRange:0,debugMode:0b,maxNearbyMonsters:0}}}
:enddata
:endrule

rule:
plugin=blockTile
number=11
data:
JSON:{blockState:{blockName:"ancientwarfarestructure:advanced_spawner",properties:{transparent:"true"}},teData:{id:"ancientwarfarestructure:advanced_spawner_tile",spawnerSettings:{minDelay:10,spawnDelay:1,lightSensitive:0b,spawnGroups:[{settingsList:[{remainingSpawnCount:1,hostile:1b,customTag:{ArmorDropChances:[0.085f,0.085f,0.085f,0.085f],CustomName:"Nogg Soldier",hasCustomEquipment:0b,ArmorItems:[{},{},{},{}],skinSettings:{npcTypeName:"custom",skinTypeSelected:"default"},HandDropChances:[0.085f,0.085f],factionName:"nogg",HandItems:[{id:"ancientwarfarenpc:iron_halberd",Count:1b,Damage:0s},{}]},maxToSpawn:1,entityId:"ancientwarfarenpc:faction.soldier",minToSpawn:1}],groupWeight:1}],playerRange:16,respondToRedstone:0b,inventory:{Size:9,Items:[]},spawnRange:0,transparent:1b,maxDelay:10,spawnYOffset:0,xpToDrop:0,mobRange:0,debugMode:0b,maxNearbyMonsters:0}}}
:enddata
:endrule

rule:
plugin=blockTile
number=12
data:
JSON:{blockState:{blockName:"ancientwarfarestructure:advanced_loot_chest",properties:{facing:"north"}},teData:{lootSettings:{lootRolls:1,splashPotion:0b,hasMessage:0b,hasLoot:1b,lootTableName:"ancientwarfare:chests/citizen_low_value",spawnEntity:0b,entity:"minecraft:"},Items:[],id:"ancientwarfarestructure:advanced_loot_chest_tile",Lock:""}}
:enddata
:endrule

rule:
plugin=vanillaBlocks
number=13
data:
JSON:{blockState:{blockName:"minecraft:log",properties:{variant:"birch",axis:"y"}}}
:enddata
:endrule

rule:
plugin=bed
number=14
data:
JSON:{blockState:{blockName:"minecraft:bed",properties:{part:"head",facing:"north",occupied:"false"}},bedColor:9}
:enddata
:endrule

rule:
plugin=bed
number=15
data:
JSON:{blockState:{blockName:"minecraft:bed",properties:{part:"foot",facing:"north",occupied:"false"}},bedColor:9}
:enddata
:endrule

rule:
plugin=blockTile
number=16
data:
JSON:{blockState:{blockName:"ancientwarfarestructure:advanced_spawner",properties:{transparent:"true"}},teData:{id:"ancientwarfarestructure:advanced_spawner_tile",spawnerSettings:{minDelay:10,spawnDelay:6,lightSensitive:0b,spawnGroups:[{settingsList:[{remainingSpawnCount:1,hostile:1b,customTag:{ArmorDropChances:[0.085f,0.085f,0.085f,0.085f],CustomName:"Nogg Trained Soldier",hasCustomEquipment:0b,ArmorItems:[{},{},{},{}],skinSettings:{npcTypeName:"custom",skinTypeSelected:"default"},HandDropChances:[0.085f,0.085f],factionName:"nogg",HandItems:[{id:"minecraft:iron_sword",Count:1b,Damage:0s},{id:"ancientwarfarenpc:iron_shield",Count:1b,Damage:0s}]},maxToSpawn:1,entityId:"ancientwarfarenpc:faction.soldier.elite",minToSpawn:1}],groupWeight:1}],playerRange:16,respondToRedstone:0b,inventory:{Size:9,Items:[]},spawnRange:0,transparent:1b,maxDelay:10,spawnYOffset:0,xpToDrop:0,mobRange:0,debugMode:0b,maxNearbyMonsters:0}}}
:enddata
:endrule

rule:
plugin=blockTile
number=17
data:
JSON:{blockState:{blockName:"ancientwarfarestructure:advanced_loot_chest",properties:{facing:"north"}},teData:{lootSettings:{lootRolls:1,splashPotion:0b,hasMessage:0b,hasLoot:1b,lootTableName:"ancientwarfare:chests/citizen_low_value",spawnEntity:0b,entity:"minecraft:"},Items:[],id:"ancientwarfarestructure:advanced_loot_chest_tile",Lock:""}}
:enddata
:endrule

rule:
plugin=bed
number=18
data:
JSON:{blockState:{blockName:"minecraft:bed",properties:{part:"head",facing:"north",occupied:"false"}},bedColor:12}
:enddata
:endrule

rule:
plugin=bed
number=19
data:
JSON:{blockState:{blockName:"minecraft:bed",properties:{part:"foot",facing:"north",occupied:"false"}},bedColor:12}
:enddata
:endrule

rule:
plugin=blockTile
number=20
data:
JSON:{blockState:{blockName:"ancientwarfarestructure:advanced_spawner",properties:{transparent:"true"}},teData:{id:"ancientwarfarestructure:advanced_spawner_tile",spawnerSettings:{minDelay:10,spawnDelay:5,lightSensitive:0b,spawnGroups:[{settingsList:[{remainingSpawnCount:1,hostile:1b,customTag:{ArmorDropChances:[0.085f,0.085f,0.085f,0.085f],hasCustomEquipment:0b,ArmorItems:[{},{},{},{}],skinSettings:{npcTypeName:"custom",skinTypeSelected:"default"},HandDropChances:[0.085f,0.085f],factionName:"nogg",HandItems:[{id:"minecraft:book",Count:1b,Damage:0s},{}]},maxToSpawn:1,entityId:"ancientwarfarenpc:faction.priest",minToSpawn:1}],groupWeight:1}],playerRange:16,respondToRedstone:0b,inventory:{Size:9,Items:[]},spawnRange:0,transparent:1b,maxDelay:10,spawnYOffset:0,xpToDrop:0,mobRange:0,debugMode:0b,maxNearbyMonsters:0}}}
:enddata
:endrule

rule:
plugin=blockTile
number=21
data:
JSON:{blockState:{blockName:"ancientwarfarestructure:advanced_spawner",properties:{transparent:"true"}},teData:{id:"ancientwarfarestructure:advanced_spawner_tile",spawnerSettings:{minDelay:10,spawnDelay:9,lightSensitive:0b,spawnGroups:[{settingsList:[{remainingSpawnCount:1,hostile:1b,customTag:{ArmorDropChances:[0.085f,0.085f,0.085f,0.085f],CustomName:"Nogg Soldier",hasCustomEquipment:0b,ArmorItems:[{},{},{},{}],skinSettings:{npcTypeName:"custom",skinTypeSelected:"default"},HandDropChances:[0.085f,0.085f],factionName:"nogg",HandItems:[{id:"ancientwarfarenpc:iron_halberd",Count:1b,Damage:0s},{}]},maxToSpawn:1,entityId:"ancientwarfarenpc:faction.soldier",minToSpawn:1}],groupWeight:1}],playerRange:16,respondToRedstone:0b,inventory:{Size:9,Items:[]},spawnRange:0,transparent:1b,maxDelay:10,spawnYOffset:0,xpToDrop:0,mobRange:0,debugMode:0b,maxNearbyMonsters:0}}}
:enddata
:endrule

rule:
plugin=blockTile
number=22
data:
JSON:{blockState:{blockName:"ancientwarfarestructure:advanced_spawner",properties:{transparent:"true"}},teData:{id:"ancientwarfarestructure:advanced_spawner_tile",spawnerSettings:{minDelay:10,spawnDelay:5,lightSensitive:0b,spawnGroups:[{settingsList:[{remainingSpawnCount:1,hostile:1b,customTag:{ArmorDropChances:[0.085f,0.085f,0.085f,0.085f],CustomName:"Nogg Soldier",hasCustomEquipment:0b,ArmorItems:[{},{},{},{}],skinSettings:{npcTypeName:"custom",skinTypeSelected:"default"},HandDropChances:[0.085f,0.085f],factionName:"nogg",HandItems:[{id:"ancientwarfarenpc:iron_halberd",Count:1b,Damage:0s},{}]},maxToSpawn:1,entityId:"ancientwarfarenpc:faction.soldier",minToSpawn:1}],groupWeight:1}],playerRange:16,respondToRedstone:0b,inventory:{Size:9,Items:[]},spawnRange:0,transparent:1b,maxDelay:10,spawnYOffset:0,xpToDrop:0,mobRange:0,debugMode:0b,maxNearbyMonsters:0}}}
:enddata
:endrule

rule:
plugin=blockTile
number=23
data:
JSON:{blockState:{blockName:"ancientwarfarestructure:advanced_spawner",properties:{transparent:"true"}},teData:{id:"ancientwarfarestructure:advanced_spawner_tile",spawnerSettings:{minDelay:10,spawnDelay:8,lightSensitive:0b,spawnGroups:[{settingsList:[{remainingSpawnCount:1,hostile:1b,customTag:{ArmorDropChances:[0.085f,0.085f,0.085f,0.085f],CustomName:"Nogg Soldier",hasCustomEquipment:0b,ArmorItems:[{},{},{},{}],skinSettings:{npcTypeName:"custom",skinTypeSelected:"default"},HandDropChances:[0.085f,0.085f],factionName:"nogg",HandItems:[{id:"ancientwarfarenpc:iron_halberd",Count:1b,Damage:0s},{}]},maxToSpawn:1,entityId:"ancientwarfarenpc:faction.soldier",minToSpawn:1}],groupWeight:1}],playerRange:16,respondToRedstone:0b,inventory:{Size:9,Items:[]},spawnRange:0,transparent:1b,maxDelay:10,spawnYOffset:0,xpToDrop:0,mobRange:0,debugMode:0b,maxNearbyMonsters:0}}}
:enddata
:endrule

rule:
plugin=vanillaBlocks
number=24
data:
JSON:{blockState:{blockName:"minecraft:spruce_stairs",properties:{half:"bottom",shape:"straight",facing:"south"}}}
:enddata
:endrule

rule:
plugin=vanillaBlocks
number=25
data:
JSON:{blockState:{blockName:"minecraft:planks",properties:{variant:"spruce"}}}
:enddata
:endrule

rule:
plugin=vanillaBlocks
number=26
data:
JSON:{blockState:{blockName:"ancientwarfarestructure:stool",properties:{variant:"spruce"}}}
:enddata
:endrule

rule:
plugin=bed
number=27
data:
JSON:{blockState:{blockName:"minecraft:bed",properties:{part:"foot",facing:"south",occupied:"false"}},bedColor:12}
:enddata
:endrule

rule:
plugin=bed
number=28
data:
JSON:{blockState:{blockName:"minecraft:bed",properties:{part:"head",facing:"south",occupied:"false"}},bedColor:12}
:enddata
:endrule

rule:
plugin=blockTile
number=29
data:
JSON:{blockState:{blockName:"ancientwarfarestructure:advanced_loot_chest",properties:{facing:"east"}},teData:{lootSettings:{lootRolls:1,splashPotion:0b,hasMessage:0b,hasLoot:1b,lootTableName:"ancientwarfare:chests/citizen_low_value",spawnEntity:0b,entity:"minecraft:"},Items:[],id:"ancientwarfarestructure:advanced_loot_chest_tile",Lock:""}}
:enddata
:endrule

rule:
plugin=vanillaBlocks
number=30
data:
JSON:{blockState:{blockName:"minecraft:birch_stairs",properties:{half:"bottom",shape:"straight",facing:"west"}}}
:enddata
:endrule

rule:
plugin=vanillaBlocks
number=31
data:
JSON:{blockState:{blockName:"minecraft:birch_stairs",properties:{half:"top",shape:"straight",facing:"south"}}}
:enddata
:endrule

rule:
plugin=vanillaBlocks
number=32
data:
JSON:{blockState:{blockName:"minecraft:wooden_slab",properties:{half:"top",variant:"birch"}}}
:enddata
:endrule

rule:
plugin=vanillaBlocks
number=33
data:
JSON:{blockState:{blockName:"minecraft:birch_fence",properties:{east:"false",south:"false",north:"false",west:"false"}}}
:enddata
:endrule

rule:
plugin=blockTile
number=34
data:
JSON:{blockState:{blockName:"ancientwarfarestructure:advanced_loot_chest",properties:{facing:"west"}},teData:{lootSettings:{lootRolls:1,splashPotion:0b,hasMessage:0b,hasLoot:1b,lootTableName:"ancientwarfare:chests/castle_pantry_vegetable",spawnEntity:0b,entity:"minecraft:"},Items:[],id:"ancientwarfarestructure:advanced_loot_chest_tile",Lock:""}}
:enddata
:endrule

rule:
plugin=blockTile
number=35
data:
JSON:{blockState:{blockName:"ancientwarfarestructure:advanced_loot_chest",properties:{facing:"west"}},teData:{lootSettings:{lootRolls:1,splashPotion:0b,hasMessage:0b,hasLoot:1b,lootTableName:"ancientwarfare:chests/castle_pantry_vegetable",spawnEntity:0b,entity:"minecraft:"},Items:[],id:"ancientwarfarestructure:advanced_loot_chest_tile",Lock:""}}
:enddata
:endrule

rule:
plugin=inventory
number=36
data:
JSON:{blockState:{blockName:"minecraft:furnace",properties:{facing:"west"}},lootLevel:0,teData:{CookTime:0,ForgeData:{generatedInventory:1b},BurnTime:0,Items:[],id:"minecraft:furnace",CookTimeTotal:0,Lock:""},inventoryData:{length:0,inventoryContents:[]},legacyFeatures:0b}
:enddata
:endrule

rule:
plugin=inventory
number=37
data:
JSON:{blockState:{blockName:"minecraft:furnace",properties:{facing:"west"}},lootLevel:0,teData:{CookTime:0,ForgeData:{generatedInventory:1b},BurnTime:0,Items:[],id:"minecraft:furnace",CookTimeTotal:0,Lock:""},inventoryData:{length:0,inventoryContents:[]},legacyFeatures:0b}
:enddata
:endrule

rule:
plugin=inventory
number=38
data:
JSON:{blockState:{blockName:"minecraft:furnace",properties:{facing:"west"}},lootLevel:0,teData:{CookTime:0,ForgeData:{generatedInventory:1b},BurnTime:0,Items:[],id:"minecraft:furnace",CookTimeTotal:0,Lock:""},inventoryData:{length:0,inventoryContents:[]},legacyFeatures:0b}
:enddata
:endrule

rule:
plugin=bed
number=39
data:
JSON:{blockState:{blockName:"minecraft:bed",properties:{part:"head",facing:"east",occupied:"false"}},bedColor:9}
:enddata
:endrule

rule:
plugin=vanillaBlocks
number=40
data:
JSON:{blockState:{blockName:"minecraft:birch_stairs",properties:{half:"top",shape:"straight",facing:"west"}}}
:enddata
:endrule

rule:
plugin=vanillaBlocks
number=41
data:
JSON:{blockState:{blockName:"minecraft:birch_stairs",properties:{half:"bottom",shape:"straight",facing:"east"}}}
:enddata
:endrule

rule:
plugin=blockTile
number=42
data:
JSON:{blockState:{blockName:"ancientwarfarestructure:advanced_loot_chest",properties:{facing:"south"}},teData:{lootSettings:{lootRolls:1,splashPotion:0b,hasMessage:0b,hasLoot:1b,lootTableName:"ancientwarfare:chests/castle_pantry_mixed",spawnEntity:0b,entity:"minecraft:"},Items:[],id:"ancientwarfarestructure:advanced_loot_chest_tile",Lock:""}}
:enddata
:endrule

rule:
plugin=bed
number=43
data:
JSON:{blockState:{blockName:"minecraft:bed",properties:{part:"foot",facing:"east",occupied:"false"}},bedColor:9}
:enddata
:endrule

rule:
plugin=blockTile
number=44
data:
JSON:{blockState:{blockName:"ancientwarfarestructure:advanced_loot_chest",properties:{facing:"south"}},teData:{lootSettings:{lootRolls:1,splashPotion:0b,hasMessage:0b,hasLoot:1b,lootTableName:"ancientwarfare:chests/castle_pantry_meat_raw",spawnEntity:0b,entity:"minecraft:"},Items:[],id:"ancientwarfarestructure:advanced_loot_chest_tile",Lock:""}}
:enddata
:endrule

rule:
plugin=doors
number=45
data:
JSON:{blockState:{blockName:"minecraft:birch_door",properties:{hinge:"left",half:"upper",powered:"false",facing:"east",open:"false"}}}
:enddata
:endrule

rule:
plugin=doors
number=46
data:
JSON:{blockState:{blockName:"minecraft:birch_door",properties:{hinge:"right",half:"upper",powered:"true",facing:"east",open:"false"}}}
:enddata
:endrule

rule:
plugin=vanillaBlocks
number=47
data:
JSON:{blockState:{blockName:"minecraft:spruce_stairs",properties:{half:"top",shape:"straight",facing:"south"}}}
:enddata
:endrule

rule:
plugin=blockTile
number=48
data:
JSON:{blockState:{blockName:"ancientwarfarestructure:advanced_loot_chest",properties:{facing:"west"}},teData:{lootSettings:{lootRolls:1,splashPotion:0b,hasMessage:0b,hasLoot:1b,lootTableName:"ancientwarfare:chests/shop_wool_carpet",spawnEntity:0b,entity:"minecraft:"},Items:[],id:"ancientwarfarestructure:advanced_loot_chest_tile",Lock:""}}
:enddata
:endrule

rule:
plugin=blockTile
number=49
data:
JSON:{blockState:{blockName:"ancientwarfarestructure:advanced_loot_chest",properties:{facing:"west"}},teData:{lootSettings:{lootRolls:1,splashPotion:0b,hasMessage:0b,hasLoot:1b,lootTableName:"ancientwarfare:chests/shop_wool_carpet",spawnEntity:0b,entity:"minecraft:"},Items:[],id:"ancientwarfarestructure:advanced_loot_chest_tile",Lock:""}}
:enddata
:endrule

rule:
plugin=blockTile
number=50
data:
JSON:{blockState:{blockName:"ancientwarfarestructure:advanced_loot_chest",properties:{facing:"east"}},teData:{lootSettings:{lootRolls:1,splashPotion:0b,hasMessage:0b,hasLoot:1b,lootTableName:"ancientwarfare:chests/castle_pantry_meat_raw",spawnEntity:0b,entity:"minecraft:"},Items:[],id:"ancientwarfarestructure:advanced_loot_chest_tile",Lock:""}}
:enddata
:endrule

rule:
plugin=vanillaBlocks
number=51
data:
JSON:{blockState:{blockName:"minecraft:ladder",properties:{facing:"south"}}}
:enddata
:endrule

rule:
plugin=vanillaBlocks
number=52
data:
JSON:{blockState:{blockName:"minecraft:wool",properties:{color:"light_blue"}}}
:enddata
:endrule

rule:
plugin=vanillaBlocks
number=53
data:
JSON:{blockState:{blockName:"minecraft:wool",properties:{color:"silver"}}}
:enddata
:endrule

rule:
plugin=vanillaBlocks
number=54
data:
JSON:{blockState:{blockName:"minecraft:wool",properties:{color:"gray"}}}
:enddata
:endrule

rule:
plugin=blockTile
number=55
data:
JSON:{blockState:{blockName:"ancientwarfarestructure:advanced_loot_chest",properties:{facing:"south"}},teData:{lootSettings:{lootRolls:1,splashPotion:0b,hasMessage:0b,hasLoot:1b,lootTableName:"ancientwarfare:chests/castle_pantry_meat_raw",spawnEntity:0b,entity:"minecraft:"},Items:[],id:"ancientwarfarestructure:advanced_loot_chest_tile",Lock:""}}
:enddata
:endrule

rule:
plugin=blockTile
number=56
data:
JSON:{blockState:{blockName:"ancientwarfarestructure:advanced_loot_chest",properties:{facing:"east"}},teData:{lootSettings:{lootRolls:1,splashPotion:0b,hasMessage:0b,hasLoot:1b,lootTableName:"ancientwarfare:chests/shop_wool_carpet",spawnEntity:0b,entity:"minecraft:"},Items:[],id:"ancientwarfarestructure:advanced_loot_chest_tile",Lock:""}}
:enddata
:endrule

rule:
plugin=blockTile
number=57
data:
JSON:{blockState:{blockName:"ancientwarfarestructure:advanced_loot_chest",properties:{facing:"east"}},teData:{lootSettings:{lootRolls:1,splashPotion:0b,hasMessage:0b,hasLoot:1b,lootTableName:"ancientwarfare:chests/shop_wool_carpet",spawnEntity:0b,entity:"minecraft:"},Items:[],id:"ancientwarfarestructure:advanced_loot_chest_tile",Lock:""}}
:enddata
:endrule

rule:
plugin=vanillaBlocks
number=58
data:
JSON:{blockState:{blockName:"minecraft:birch_stairs",properties:{half:"top",shape:"straight",facing:"east"}}}
:enddata
:endrule

rule:
plugin=blockTile
number=59
data:
JSON:{blockState:{blockName:"ancientwarfarestructure:advanced_loot_chest",properties:{facing:"east"}},teData:{lootSettings:{lootRolls:1,splashPotion:0b,hasMessage:0b,hasLoot:1b,lootTableName:"ancientwarfare:chests/castle_pantry_vegetable",spawnEntity:0b,entity:"minecraft:"},Items:[],id:"ancientwarfarestructure:advanced_loot_chest_tile",Lock:""}}
:enddata
:endrule

rule:
plugin=bed
number=60
data:
JSON:{blockState:{blockName:"minecraft:bed",properties:{part:"foot",facing:"west",occupied:"false"}},bedColor:9}
:enddata
:endrule

rule:
plugin=inventory
number=61
data:
JSON:{blockState:{blockName:"minecraft:brewing_stand",properties:{has_bottle_0:"false",has_bottle_1:"false",has_bottle_2:"false"}},lootLevel:0,teData:{ForgeData:{generatedInventory:1b},Fuel:0b,Items:[],id:"minecraft:brewing_stand",BrewTime:0s,Lock:""},inventoryData:{length:0,inventoryContents:[]},legacyFeatures:0b}
:enddata
:endrule

rule:
plugin=blockTile
number=62
data:
JSON:{blockState:{blockName:"ancientwarfarestructure:advanced_loot_chest",properties:{facing:"east"}},teData:{lootSettings:{lootRolls:5,splashPotion:0b,hasMessage:0b,hasLoot:1b,lootTableName:"ancientwarfare:chests/potion_beneficial",spawnEntity:0b,entity:"minecraft:"},Items:[],id:"ancientwarfarestructure:advanced_loot_chest_tile",Lock:""}}
:enddata
:endrule

rule:
plugin=vanillaSkull
number=63
data:
JSON:{blockState:{blockName:"minecraft:skull",properties:{nodrop:"false",facing:"up"}},skullRotation:5,teData:{Owner:{Id:"f32f4e87-9fb0-48b0-8cc4-56eebf3c6f82",Properties:{textures:[{Value:"eyJ0ZXh0dXJlcyI6eyJTS0lOIjp7InVybCI6Imh0dHA6Ly90ZXh0dXJlcy5taW5lY3JhZnQubmV0L3RleHR1cmUvZjdjN2RmNTJiNWU1MGJhZGI2MWZlZDcyMTJkOTc5ZTYzZmU5NGYxYmRlMDJiMjk2OGM2YjE1NmE3NzAxMjZjIn19fQ=="}]}},Rot:1b,id:"minecraft:skull",SkullType:3b}}
:enddata
:endrule

rule:
plugin=inventory
number=64
data:
JSON:{blockState:{blockName:"minecraft:brewing_stand",properties:{has_bottle_0:"false",has_bottle_1:"false",has_bottle_2:"false"}},lootLevel:0,teData:{ForgeData:{generatedInventory:1b},Fuel:0b,Items:[],id:"minecraft:brewing_stand",BrewTime:0s,Lock:""},inventoryData:{length:0,inventoryContents:[]},legacyFeatures:0b}
:enddata
:endrule

rule:
plugin=blockTile
number=65
data:
JSON:{blockState:{blockName:"ancientwarfarestructure:advanced_loot_chest",properties:{facing:"east"}},teData:{lootSettings:{lootRolls:5,splashPotion:0b,hasMessage:0b,hasLoot:1b,lootTableName:"ancientwarfare:chests/potion_beneficial",spawnEntity:0b,entity:"minecraft:"},Items:[],id:"ancientwarfarestructure:advanced_loot_chest_tile",Lock:""}}
:enddata
:endrule

rule:
plugin=bed
number=66
data:
JSON:{blockState:{blockName:"minecraft:bed",properties:{part:"head",facing:"west",occupied:"false"}},bedColor:9}
:enddata
:endrule

rule:
plugin=blockTile
number=67
data:
JSON:{blockState:{blockName:"ancientwarfarestructure:advanced_loot_chest",properties:{facing:"east"}},teData:{lootSettings:{lootRolls:1,splashPotion:0b,hasMessage:0b,hasLoot:1b,lootTableName:"ancientwarfare:chests/citizen_low_value",spawnEntity:0b,entity:"minecraft:"},Items:[],id:"ancientwarfarestructure:advanced_loot_chest_tile",Lock:""}}
:enddata
:endrule

rule:
plugin=vanillaBlocks
number=68
data:
JSON:{blockState:{blockName:"minecraft:glass_pane",properties:{east:"false",south:"false",north:"false",west:"false"}}}
:enddata
:endrule

rule:
plugin=blockTile
number=69
data:
JSON:{blockState:{blockName:"ancientwarfarestructure:advanced_loot_chest",properties:{facing:"west"}},teData:{lootSettings:{lootRolls:1,splashPotion:0b,hasMessage:0b,hasLoot:1b,lootTableName:"ancientwarfare:chests/castle_pantry_mixed",spawnEntity:0b,entity:"minecraft:"},Items:[],id:"ancientwarfarestructure:advanced_loot_chest_tile",Lock:""}}
:enddata
:endrule

rule:
plugin=blockTile
number=70
data:
JSON:{blockState:{blockName:"ancientwarfarestructure:advanced_loot_chest",properties:{facing:"west"}},teData:{lootSettings:{lootRolls:1,splashPotion:0b,hasMessage:0b,hasLoot:1b,lootTableName:"ancientwarfare:chests/castle_pantry_mixed",spawnEntity:0b,entity:"minecraft:"},Items:[],id:"ancientwarfarestructure:advanced_loot_chest_tile",Lock:""}}
:enddata
:endrule

rule:
plugin=blockTile
number=71
data:
JSON:{blockState:{blockName:"ancientwarfarestructure:advanced_loot_chest",properties:{facing:"west"}},teData:{lootSettings:{lootRolls:1,splashPotion:0b,hasMessage:0b,hasLoot:1b,lootTableName:"ancientwarfare:chests/castle_pantry_mixed",spawnEntity:0b,entity:"minecraft:"},Items:[],id:"ancientwarfarestructure:advanced_loot_chest_tile",Lock:""}}
:enddata
:endrule

rule:
plugin=blockTile
number=72
data:
JSON:{blockState:{blockName:"ancientwarfarestructure:advanced_loot_chest",properties:{facing:"east"}},teData:{lootSettings:{lootRolls:0,splashPotion:0b,hasMessage:0b,hasLoot:0b,lootTableName:"minecraft:",spawnEntity:0b,entity:"minecraft:"},Items:[],id:"ancientwarfarestructure:advanced_loot_chest_tile",Lock:""}}
:enddata
:endrule

rule:
plugin=blockTile
number=73
data:
JSON:{blockState:{blockName:"ancientwarfarestructure:advanced_loot_chest",properties:{facing:"east"}},teData:{lootSettings:{lootRolls:2,splashPotion:0b,hasMessage:0b,hasLoot:1b,lootTableName:"ancientwarfare:chests/shop_wool_carpet",spawnEntity:0b,entity:"minecraft:"},Items:[],id:"ancientwarfarestructure:advanced_loot_chest_tile",Lock:""}}
:enddata
:endrule

rule:
plugin=doors
number=74
data:
JSON:{blockState:{blockName:"minecraft:birch_door",properties:{hinge:"left",half:"lower",powered:"false",facing:"north",open:"true"}}}
:enddata
:endrule

rule:
plugin=blockTile
number=75
data:
JSON:{blockState:{blockName:"ancientwarfarestructure:advanced_loot_chest",properties:{facing:"west"}},teData:{lootSettings:{lootRolls:1,splashPotion:0b,hasMessage:0b,hasLoot:1b,lootTableName:"ancientwarfare:chests/shop_wool_carpet",spawnEntity:0b,entity:"minecraft:"},Items:[],id:"ancientwarfarestructure:advanced_loot_chest_tile",Lock:""}}
:enddata
:endrule

rule:
plugin=blockTile
number=76
data:
JSON:{blockState:{blockName:"ancientwarfarestructure:advanced_loot_chest",properties:{facing:"west"}},teData:{lootSettings:{lootRolls:1,splashPotion:0b,hasMessage:0b,hasLoot:1b,lootTableName:"ancientwarfare:chests/shop_wool_carpet",spawnEntity:0b,entity:"minecraft:"},Items:[],id:"ancientwarfarestructure:advanced_loot_chest_tile",Lock:""}}
:enddata
:endrule

rule:
plugin=vanillaBlocks
number=77
data:
JSON:{blockState:{blockName:"minecraft:torch",properties:{facing:"east"}}}
:enddata
:endrule

rule:
plugin=vanillaBlocks
number=78
data:
JSON:{blockState:{blockName:"minecraft:torch",properties:{facing:"west"}}}
:enddata
:endrule

rule:
plugin=vanillaBlocks
number=79
data:
